Workbook
Name _DLX1.INC: HAVERD!$B$2:$BD$7
Name cdids: [2]Data!$A$2:$A$10
Name data: [2]Data!$B$2:$EZ$10
Name Data: [1]sheet0!$C$2
Name dates: [2]Data!$B$1:$EZ$1

Sheet Chart Data
A1: Existing - 2019=100 | R1: New - 2019=100 | AA1: New - 2019=100 | AQ1: Annual - 2019=100 | BA1: Annual - levels | BK1: Sectors - retail (2019=100) | BP1: Sectors - health (2019=100) | BU1: Sectors - manufacturing (2019=100) | BZ1: Equity prices - last week | CL1: Equity prices - since August 1
B2: UK | C2: US | D2: Japan | E2: Germany | F2: France | G2: Italy | H2: Canada | J2: UK | K2: US | L2: Japan | M2: Germany | N2: France | O2: Italy | P2: Canada | S2: UK | T2: US | U2: Japan | V2: Germany | W2: France | X2: Italy | Y2: Canada | AB2: UK (current) | AC2: UK (new) | AD2: G7 median | AE2: Bottom of range | AF2: G7 range | AG2: 100 LINE | AI2: UK | AJ2: US | AK2: Japan | AL2: Germany | AM2: France | AN2: Italy | AO2: Canada | AR2: UK (current) | AS2: UK (new) | AT2: US | AU2: Japan | AV2: Germany | AW2: France | AX2: Italy | AY2: Canada | BB2: UK (current) | BC2: UK (new) | BD2: US | BE2: Japan | BF2: Germany | BG2: France | BH2: Italy | BI2: Canada | BL2: Current | BM2: New | BN2: 100 LINE | BQ2: Current | BR2: New | BS2: 100 LINE | BV2: Current | BW2: New | BX2: 100 LINE | CA2: =HAVERD!C1 -> US | CB2: =HAVERD!D1 -> Japan | CC2: =HAVERD!E1 -> Eurozone | CD2: =HAVERD!F1 -> UK | CE2: =HAVERD!M1 -> Canada | CF2: =HAVERD!T1 -> France | CG2: =HAVERD!U1 -> Germany | CH2: =HAVERD!Y1 -> India | CI2: =HAVERD!AB1 -> Italy | CJ2: =HAVERD!AZ1 -> Global | CM2: UK | CN2: Global | CO2: US | CP2: Eurozone | CQ2: Japan | CR2: Canada | CS2: 100 LINE
A3: 2019 | B3: =100*(Data!C191/AVERAGE(Data!C$191:C$194)) -> 99.402083 | C3: =100*(Data!D191/AVERAGE(Data!D$191:D$194)) -> 98.661808 | D3: =100*(Data!E191/AVERAGE(Data!E$191:E$194)) -> 100.30738 | E3: =100*(Data!F191/AVERAGE(Data!F$191:F$194)) -> 99.80617 | F3: =100*(Data!G191/AVERAGE(Data!G$191:G$194)) -> 99.672108 | G3: =100*(Data!H191/AVERAGE(Data!H$191:H$194)) -> 99.88523 | H3: =100*(Data!I191/AVERAGE(Data!I$191:I$194)) -> 98.975819 | J3: =RANK(B3,$B3:$H3) -> 5 | K3: =RANK(C3,$B3:$H3) -> 7 | L3: =RANK(D3,$B3:$H3) -> 1 | M3: =RANK(E3,$B3:$H3) -> 3 | N3: =RANK(F3,$B3:$H3) -> 4 | O3: =RANK(G3,$B3:$H3) -> 2 | P3: =RANK(H3,$B3:$H3) -> 6 | R3: 2019 | S3: =100*('ONS - Annex F'!C94/AVERAGE('ONS - Annex F'!$C$94:$C$97)) -> 99.413922 | T3: =C3 -> 98.661808 | U3: =D3 -> 100.30738 | V3: =E3 -> 99.80617 | W3: =F3 -> 99.672108 | X3: =G3 -> 99.88523 | Y3: =H3 -> 98.975819 | AA3: 2019 | AB3: =B3 -> 99.402083 | AC3: =S3 -> 99.413922 | AD3: =MEDIAN($S3:$Y3) -> 99.672108 | AE3: =MIN($S3:$Y3) -> 98.661808 | AF3: =MAX($S3:$Y3)-AE3 -> 1.6455682 | AG3: 100 | AI3: =RANK(S3,$S3:$Y3) -> 5 | AJ3: =RANK(T3,$S3:$Y3) -> 7 | AK3: =RANK(U3,$S3:$Y3) -> 1 | AL3: =RANK(V3,$S3:$Y3) -> 3 | AM3: =RANK(W3,$S3:$Y3) -> 4 | AN3: =RANK(X3,$S3:$Y3) -> 2 | AO3: =RANK(Y3,$S3:$Y3) -> 6 | AQ3: 2019 | AR3: =100*(BB3/BB$3) -> 100 | AS3: =100*(BC3/BC$3) -> 100 | AT3: =100*(BD3/BD$3) -> 100 | AU3: =100*(BE3/BE$3) -> 100 | AV3: =100*(BF3/BF$3) -> 100 | AW3: =100*(BG3/BG$3) -> 100 | AX3: =100*(BH3/BH$3) -> 100 | AY3: =100*(BI3/BI$3) -> 100 | BA3: 2019 | BB3: =SUMIF(Data!$A:$A,'Chart Data'!$BA3,Data!C:C) -> 2233921 | BC3: =SUM('ONS - Annex F'!C94:C97) -> 2474245 | BD3: =SUMIF(Data!$A:$A,'Chart Data'!$BA3,Data!D:D) -> 20692.1 | BE3: =SUMIF(Data!$A:$A,'Chart Data'!$BA3,Data!E:E) -> 552514.9 | BF3: =SUMIF(Data!$A:$A,'Chart Data'!$BA3,Data!F:F) -> 3309.2443 | BG3: =SUMIF(Data!$A:$A,'Chart Data'!$BA3,Data!G:G) -> 2507.53 | BH3: =SUMIF(Data!$A:$A,'Chart Data'!$BA3,Data!H:H) -> 1728.668 | BI3: =SUMIF(Data!$A:$A,'Chart Data'!$BA3,Data!I:I) -> 2241331.3 | BK3: 43466 | BL3: =100*('ONS - Table 1'!CK270/AVERAGE('ONS - Table 1'!$CK$270:$CK$281)) -> 100.90841 | BM3: =100*('ONS - Table 2'!CK270/AVERAGE('ONS - Table 2'!$CK$270:$CK$281)) -> 101.11317 | BN3: 100 | BP3: 43466 | BQ3: =100*('ONS - Table 1'!ET270/AVERAGE('ONS - Table 1'!$ET$270:$ET$281)) -> 97.5 | BR3: =100*('ONS - Table 2'!ET270/AVERAGE('ONS - Table 2'!$ET$270:$ET$281)) -> 98.038311 | BS3: 100 | BU3: 43466 | BV3: =100*('ONS - Table 1'!J270/AVERAGE('ONS - Table 1'!$J$270:$J$281)) -> 98.183636 | BW3: =100*('ONS - Table 2'!J270/AVERAGE('ONS - Table 2'!$J$270:$J$281)) -> 98.640904 | BX3: 100 | BZ3: Past week | CA3: =100*((HAVERD!C166/HAVERD!C161)-1) -> -2.3384888 | CB3: =100*((HAVERD!D166/HAVERD!D161)-1) -> -8.9503604 | CC3: =100*((HAVERD!E166/HAVERD!E161)-1) -> -2.0349496 | CD3: =100*((HAVERD!F166/HAVERD!F161)-1) -> -2.0785707 | CE3: =100*((HAVERD!M166/HAVERD!M161)-1) -> -2.1898315 | CF3: =100*((HAVERD!T166/HAVERD!T161)-1) -> -1.6688262 | CG3: =100*((HAVERD!U166/HAVERD!U161)-1) -> -2.2267102 | CH3: =100*((HAVERD!Y166/HAVERD!Y161)-1) -> -3.6416504 | CI3: =100*((HAVERD!AB166/HAVERD!AB161)-1) -> -3.3950312 | CJ3: =100*((HAVERD!AZ166/HAVERD!AZ161)-1) -> -2.8154827 | CL3: 45505 | CM3: =100*(HAVERD!F161/HAVERD!F$161) -> 100 | CN3: =100*(HAVERD!AZ161/HAVERD!AZ$161) -> 100 | CO3: =100*(HAVERD!C161/HAVERD!C$161) -> 100 | CP3: =100*(HAVERD!E161/HAVERD!E$161) -> 100 | CQ3: =100*(HAVERD!D161/HAVERD!D$161) -> 100 | CR3: =100*(HAVERD!M161/HAVERD!M$161) -> 100 | CS3: 100
B4: =100*(Data!C192/AVERAGE(Data!C$191:C$194)) -> 99.722774 | C4: =100*(Data!D192/AVERAGE(Data!D$191:D$194)) -> 99.479995 | D4: =100*(Data!E192/AVERAGE(Data!E$191:E$194)) -> 100.73046 | E4: =100*(Data!F192/AVERAGE(Data!F$191:F$194)) -> 99.91185 | F4: =100*(Data!G192/AVERAGE(Data!G$191:G$194)) -> 100.25276 | G4: =100*(Data!H192/AVERAGE(Data!H$191:H$194)) -> 100.21543 | H4: =100*(Data!I192/AVERAGE(Data!I$191:I$194)) -> 100.05937 | J4: =RANK(B4,$B4:$H4) -> 6 | K4: =RANK(C4,$B4:$H4) -> 7 | L4: =RANK(D4,$B4:$H4) -> 1 | M4: =RANK(E4,$B4:$H4) -> 5 | N4: =RANK(F4,$B4:$H4) -> 2 | O4: =RANK(G4,$B4:$H4) -> 3 | P4: =RANK(H4,$B4:$H4) -> 4 | S4: =100*('ONS - Annex F'!C95/AVERAGE('ONS - Annex F'!$C$94:$C$97)) -> 99.723835 | T4: =C4 -> 99.479995 | U4: =D4 -> 100.73046 | V4: =E4 -> 99.91185 | W4: =F4 -> 100.25276 | X4: =G4 -> 100.21543 | Y4: =H4 -> 100.05937 | AB4: =B4 -> 99.722774 | AC4: =S4 -> 99.723835 | AD4: =MEDIAN($S4:$Y4) -> 100.05937 | AE4: =MIN($S4:$Y4) -> 99.479995 | AF4: =MAX($S4:$Y4)-AE4 -> 1.2504652 | AG4: 100 | AI4: =RANK(S4,$S4:$Y4) -> 6 | AJ4: =RANK(T4,$S4:$Y4) -> 7 | AK4: =RANK(U4,$S4:$Y4) -> 1 | AL4: =RANK(V4,$S4:$Y4) -> 5 | AM4: =RANK(W4,$S4:$Y4) -> 2 | AN4: =RANK(X4,$S4:$Y4) -> 3 | AO4: =RANK(Y4,$S4:$Y4) -> 4 | AQ4: 2020 | AR4: =100*(BB4/BB$3) -> 89.640099 | AS4: =100*(BC4/BC$3) -> 89.703081 | AT4: =100*(BD4/BD$3) -> 97.786474 | AU4: =100*(BE4/BE$3) -> 95.779716 | AV4: =100*(BF4/BF$3) -> 95.543578 | AW4: =100*(BG4/BG$3) -> 92.408187 | AX4: =100*(BH4/BH$3) -> 90.950373 | AY4: =100*(BI4/BI$3) -> 94.961767 | BA4: 2020 | BB4: =SUMIF(Data!$A:$A,'Chart Data'!$BA4,Data!C:C) -> 2002489 | BC4: =SUM('ONS - Annex F'!C98:C101) -> 2219474 | BD4: =SUMIF(Data!$A:$A,'Chart Data'!$BA4,Data!D:D) -> 20234.075 | BE4: =SUMIF(Data!$A:$A,'Chart Data'!$BA4,Data!E:E) -> 529197.2 | BF4: =SUMIF(Data!$A:$A,'Chart Data'!$BA4,Data!F:F) -> 3161.7704 | BG4: =SUMIF(Data!$A:$A,'Chart Data'!$BA4,Data!G:G) -> 2317.163 | BH4: =SUMIF(Data!$A:$A,'Chart Data'!$BA4,Data!H:H) -> 1572.23 | BI4: =SUMIF(Data!$A:$A,'Chart Data'!$BA4,Data!I:I) -> 2128407.8 | BK4: 43497 | BL4: =100*('ONS - Table 1'!CK271/AVERAGE('ONS - Table 1'!$CK$270:$CK$281)) -> 101.10843 | BM4: =100*('ONS - Table 2'!CK271/AVERAGE('ONS - Table 2'!$CK$270:$CK$281)) -> 101.48423 | BN4: 100 | BP4: 43497 | BQ4: =100*('ONS - Table 1'!ET271/AVERAGE('ONS - Table 1'!$ET$270:$ET$281)) -> 99.1 | BR4: =100*('ONS - Table 2'!ET271/AVERAGE('ONS - Table 2'!$ET$270:$ET$281)) -> 99.607662 | BS4: 100 | BU4: 43497 | BV4: =100*('ONS - Table 1'!J271/AVERAGE('ONS - Table 1'!$J$270:$J$281)) -> 99.383436 | BW4: =100*('ONS - Table 2'!J271/AVERAGE('ONS - Table 2'!$J$270:$J$281)) -> 99.328639 | BX4: 100 | CL4: =+CL3+1 -> 45506 | CM4: =100*(HAVERD!F162/HAVERD!F$161) -> 98.447728 | CN4: =100*(HAVERD!AZ162/HAVERD!AZ$161) -> 97.935863 | CO4: =100*(HAVERD!C162/HAVERD!C$161) -> 98.161816 | CP4: =100*(HAVERD!E162/HAVERD!E$161) -> 97.334715 | CQ4: =100*(HAVERD!D162/HAVERD!D$161) -> 93.856914 | CR4: =100*(HAVERD!M162/HAVERD!M$161) -> 97.819058 | CS4: 100
B5: =100*(Data!C193/AVERAGE(Data!C$191:C$194)) -> 100.44885 | C5: =100*(Data!D193/AVERAGE(Data!D$191:D$194)) -> 100.60651 | D5: =100*(Data!E193/AVERAGE(Data!E$191:E$194)) -> 100.9129 | E5: =100*(Data!F193/AVERAGE(Data!F$191:F$194)) -> 100.14099 | F5: =100*(Data!G193/AVERAGE(Data!G$191:G$194)) -> 100.2936 | G5: =100*(Data!H193/AVERAGE(Data!H$191:H$194)) -> 100.27744 | H5: =100*(Data!I193/AVERAGE(Data!I$191:I$194)) -> 100.33917 | J5: =RANK(B5,$B5:$H5) -> 3 | K5: =RANK(C5,$B5:$H5) -> 2 | L5: =RANK(D5,$B5:$H5) -> 1 | M5: =RANK(E5,$B5:$H5) -> 7 | N5: =RANK(F5,$B5:$H5) -> 5 | O5: =RANK(G5,$B5:$H5) -> 6 | P5: =RANK(H5,$B5:$H5) -> 4 | S5: =100*('ONS - Annex F'!C96/AVERAGE('ONS - Annex F'!$C$94:$C$97)) -> 100.43096 | T5: =C5 -> 100.60651 | U5: =D5 -> 100.9129 | V5: =E5 -> 100.14099 | W5: =F5 -> 100.2936 | X5: =G5 -> 100.27744 | Y5: =H5 -> 100.33917 | AB5: =B5 -> 100.44885 | AC5: =S5 -> 100.43096 | AD5: =MEDIAN($S5:$Y5) -> 100.33917 | AE5: =MIN($S5:$Y5) -> 100.14099 | AF5: =MAX($S5:$Y5)-AE5 -> 0.77190856 | AG5: 100 | AI5: =RANK(S5,$S5:$Y5) -> 3 | AJ5: =RANK(T5,$S5:$Y5) -> 2 | AK5: =RANK(U5,$S5:$Y5) -> 1 | AL5: =RANK(V5,$S5:$Y5) -> 7 | AM5: =RANK(W5,$S5:$Y5) -> 5 | AN5: =RANK(X5,$S5:$Y5) -> 6 | AO5: =RANK(Y5,$S5:$Y5) -> 4 | AQ5: 2021 | AR5: =100*(BB5/BB$3) -> 97.416292 | AS5: =100*(BC5/BC$3) -> 97.395973 | AT5: =100*(BD5/BD$3) -> 103.4582 | AU5: =100*(BE5/BE$3) -> 98.435083 | AV5: =100*(BF5/BF$3) -> 98.927408 | AW5: =100*(BG5/BG$3) -> 98.718659 | AX5: =100*(BH5/BH$3) -> 98.479523 | AY5: =100*(BI5/BI$3) -> 99.982359 | BA5: 2021 | BB5: =SUMIF(Data!$A:$A,'Chart Data'!$BA5,Data!C:C) -> 2176203 | BC5: =SUM('ONS - Annex F'!C102:C105) -> 2409815 | BD5: =SUMIF(Data!$A:$A,'Chart Data'!$BA5,Data!D:D) -> 21407.675 | BE5: =SUMIF(Data!$A:$A,'Chart Data'!$BA5,Data!E:E) -> 543868.5 | BF5: =SUMIF(Data!$A:$A,'Chart Data'!$BA5,Data!F:F) -> 3273.7496 | BG5: =SUMIF(Data!$A:$A,'Chart Data'!$BA5,Data!G:G) -> 2475.4 | BH5: =SUMIF(Data!$A:$A,'Chart Data'!$BA5,Data!H:H) -> 1702.384 | BI5: =SUMIF(Data!$A:$A,'Chart Data'!$BA5,Data!I:I) -> 2240935.9 | BK5: 43525 | BL5: =100*('ONS - Table 1'!CK272/AVERAGE('ONS - Table 1'!$CK$270:$CK$281)) -> 101.00842 | BM5: =100*('ONS - Table 2'!CK272/AVERAGE('ONS - Table 2'!$CK$270:$CK$281)) -> 101.11317 | BN5: 100 | BP5: 43525 | BQ5: =100*('ONS - Table 1'!ET272/AVERAGE('ONS - Table 1'!$ET$270:$ET$281)) -> 100.5 | BR5: =100*('ONS - Table 2'!ET272/AVERAGE('ONS - Table 2'!$ET$270:$ET$281)) -> 101.45396 | BS5: 100 | BU5: 43525 | BV5: =100*('ONS - Table 1'!J272/AVERAGE('ONS - Table 1'!$J$270:$J$281)) -> 100.58324 | BW5: =100*('ONS - Table 2'!J272/AVERAGE('ONS - Table 2'!$J$270:$J$281)) -> 100.21287 | BX5: 100 | CL5: =+CL4+3 -> 45509 | CM5: =100*(HAVERD!F163/HAVERD!F$161) -> 96.320972 | CN5: =100*(HAVERD!AZ163/HAVERD!AZ$161) -> 94.712507 | CO5: =100*(HAVERD!C163/HAVERD!C$161) -> 95.220024 | CP5: =100*(HAVERD!E163/HAVERD!E$161) -> 95.926743 | CQ5: =100*(HAVERD!D163/HAVERD!D$161) -> 82.374459 | CR5: =100*(HAVERD!M163/HAVERD!M$161) -> #N/A | CS5: 100
B6: =100*(Data!C194/AVERAGE(Data!C$191:C$194)) -> 100.42629 | C6: =100*(Data!D194/AVERAGE(Data!D$191:D$194)) -> 101.25169 | D6: =100*(Data!E194/AVERAGE(Data!E$191:E$194)) -> 98.049265 | E6: =100*(Data!F194/AVERAGE(Data!F$191:F$194)) -> 100.14099 | F6: =100*(Data!G194/AVERAGE(Data!G$191:G$194)) -> 99.781538 | G6: =100*(Data!H194/AVERAGE(Data!H$191:H$194)) -> 99.621905 | H6: =100*(Data!I194/AVERAGE(Data!I$191:I$194)) -> 100.62564 | J6: =RANK(B6,$B6:$H6) -> 3 | K6: =RANK(C6,$B6:$H6) -> 1 | L6: =RANK(D6,$B6:$H6) -> 7 | M6: =RANK(E6,$B6:$H6) -> 4 | N6: =RANK(F6,$B6:$H6) -> 5 | O6: =RANK(G6,$B6:$H6) -> 6 | P6: =RANK(H6,$B6:$H6) -> 2 | S6: =100*('ONS - Annex F'!C97/AVERAGE('ONS - Annex F'!$C$94:$C$97)) -> 100.43128 | T6: =C6 -> 101.25169 | U6: =D6 -> 98.049265 | V6: =E6 -> 100.14099 | W6: =F6 -> 99.781538 | X6: =G6 -> 99.621905 | Y6: =H6 -> 100.62564 | AB6: =B6 -> 100.42629 | AC6: =S6 -> 100.43128 | AD6: =MEDIAN($S6:$Y6) -> 100.14099 | AE6: =MIN($S6:$Y6) -> 98.049265 | AF6: =MAX($S6:$Y6)-AE6 -> 3.2024201 | AG6: 100 | AI6: =RANK(S6,$S6:$Y6) -> 3 | AJ6: =RANK(T6,$S6:$Y6) -> 1 | AK6: =RANK(U6,$S6:$Y6) -> 7 | AL6: =RANK(V6,$S6:$Y6) -> 4 | AM6: =RANK(W6,$S6:$Y6) -> 5 | AN6: =RANK(X6,$S6:$Y6) -> 6 | AO6: =RANK(Y6,$S6:$Y6) -> 2 | AQ6: 2022 | AR6: =100*(BB6/BB$3) -> 101.64925 | AS6: =100*(BC6/BC$3) -> 102.10905 | AT6: =100*(BD6/BD$3) -> 105.46078 | AU6: =100*(BE6/BE$3) -> 99.603775 | AV6: =100*(BF6/BF$3) -> 100.64629 | AW6: =100*(BG6/BG$3) -> 101.30379 | AX6: =100*(BH6/BH$3) -> 102.56174 | AY6: =100*(BI6/BI$3) -> 103.80155 | BA6: 2022 | BB6: =SUMIF(Data!$A:$A,'Chart Data'!$BA6,Data!C:C) -> 2270764 | BC6: =SUM('ONS - Annex F'!C106:C109) -> 2526428 | BD6: =SUMIF(Data!$A:$A,'Chart Data'!$BA6,Data!D:D) -> 21822.05 | BE6: =SUMIF(Data!$A:$A,'Chart Data'!$BA6,Data!E:E) -> 550325.7 | BF6: =SUMIF(Data!$A:$A,'Chart Data'!$BA6,Data!F:F) -> 3330.6316 | BG6: =SUMIF(Data!$A:$A,'Chart Data'!$BA6,Data!G:G) -> 2540.223 | BH6: =SUMIF(Data!$A:$A,'Chart Data'!$BA6,Data!H:H) -> 1772.952 | BI6: =SUMIF(Data!$A:$A,'Chart Data'!$BA6,Data!I:I) -> 2326536.7 | BK6: 43556 | BL6: =100*('ONS - Table 1'!CK273/AVERAGE('ONS - Table 1'!$CK$270:$CK$281)) -> 100.90841 | BM6: =100*('ONS - Table 2'!CK273/AVERAGE('ONS - Table 2'!$CK$270:$CK$281)) -> 101.02041 | BN6: 100 | BP6: 43556 | BQ6: =100*('ONS - Table 1'!ET273/AVERAGE('ONS - Table 1'!$ET$270:$ET$281)) -> 99.5 | BR6: =100*('ONS - Table 2'!ET273/AVERAGE('ONS - Table 2'!$ET$270:$ET$281)) -> 100.06924 | BS6: 100 | BU6: 43556 | BV6: =100*('ONS - Table 1'!J273/AVERAGE('ONS - Table 1'!$J$270:$J$281)) -> 97.583736 | BW6: =100*('ONS - Table 2'!J273/AVERAGE('ONS - Table 2'!$J$270:$J$281)) -> 97.854921 | BX6: 100 | CL6: =+CL5+1 -> 45510 | CM6: =100*(HAVERD!F164/HAVERD!F$161) -> 96.607663 | CN6: =100*(HAVERD!AZ164/HAVERD!AZ$161) -> 95.865121 | CO6: =100*(HAVERD!C164/HAVERD!C$161) -> 96.205946 | CP6: =100*(HAVERD!E164/HAVERD!E$161) -> 96.002703 | CQ6: =100*(HAVERD!D164/HAVERD!D$161) -> 90.032881 | CR6: =100*(HAVERD!M164/HAVERD!M$161) -> 96.726475 | CS6: 100
A7: 2020 | B7: =100*(Data!C195/AVERAGE(Data!C$191:C$194)) -> 97.693159 | C7: =100*(Data!D195/AVERAGE(Data!D$191:D$194)) -> 99.871932 | D7: =100*(Data!E195/AVERAGE(Data!E$191:E$194)) -> 98.536202 | E7: =100*(Data!F195/AVERAGE(Data!F$191:F$194)) -> 97.900684 | F7: =100*(Data!G195/AVERAGE(Data!G$191:G$194)) -> 94.654261 | G7: =100*(Data!H195/AVERAGE(Data!H$191:H$194)) -> 93.608027 | H7: =100*(Data!I195/AVERAGE(Data!I$191:I$194)) -> 98.663504 | J7: =RANK(B7,$B7:$H7) -> 5 | K7: =RANK(C7,$B7:$H7) -> 1 | L7: =RANK(D7,$B7:$H7) -> 3 | M7: =RANK(E7,$B7:$H7) -> 4 | N7: =RANK(F7,$B7:$H7) -> 6 | O7: =RANK(G7,$B7:$H7) -> 7 | P7: =RANK(H7,$B7:$H7) -> 2 | R7: 2020 | S7: =100*('ONS - Annex F'!C98/AVERAGE('ONS - Annex F'!$C$94:$C$97)) -> 97.762186 | T7: =C7 -> 99.871932 | U7: =D7 -> 98.536202 | V7: =E7 -> 97.900684 | W7: =F7 -> 94.654261 | X7: =G7 -> 93.608027 | Y7: =H7 -> 98.663504 | AA7: 2020 | AB7: =B7 -> 97.693159 | AC7: =S7 -> 97.762186 | AD7: =MEDIAN($S7:$Y7) -> 97.900684 | AE7: =MIN($S7:$Y7) -> 93.608027 | AF7: =MAX($S7:$Y7)-AE7 -> 6.2639053 | AG7: 100 | AI7: =RANK(S7,$S7:$Y7) -> 5 | AJ7: =RANK(T7,$S7:$Y7) -> 1 | AK7: =RANK(U7,$S7:$Y7) -> 3 | AL7: =RANK(V7,$S7:$Y7) -> 4 | AM7: =RANK(W7,$S7:$Y7) -> 6 | AN7: =RANK(X7,$S7:$Y7) -> 7 | AO7: =RANK(Y7,$S7:$Y7) -> 2 | AQ7: 2023 | AR7: =100*(BB7/BB$3) -> 101.75499 | AS7: =100*(BC7/BC$3) -> 0 | AT7: =100*(BD7/BD$3) -> 108.14236 | AU7: =100*(BE7/BE$3) -> 101.40516 | AV7: =100*(BF7/BF$3) -> 100.5865 | AW7: =100*(BG7/BG$3) -> 102.43846 | AX7: =100*(BH7/BH$3) -> 103.60503 | AY7: =100*(BI7/BI$3) -> 105.09795 | BA7: 2023 | BB7: =SUMIF(Data!$A:$A,'Chart Data'!$BA7,Data!C:C) -> 2273126 | BD7: =SUMIF(Data!$A:$A,'Chart Data'!$BA7,Data!D:D) -> 22376.925 | BE7: =SUMIF(Data!$A:$A,'Chart Data'!$BA7,Data!E:E) -> 560278.6 | BF7: =SUMIF(Data!$A:$A,'Chart Data'!$BA7,Data!F:F) -> 3328.6531 | BG7: =SUMIF(Data!$A:$A,'Chart Data'!$BA7,Data!G:G) -> 2568.675 | BH7: =SUMIF(Data!$A:$A,'Chart Data'!$BA7,Data!H:H) -> 1790.987 | BI7: =SUMIF(Data!$A:$A,'Chart Data'!$BA7,Data!I:I) -> 2355593.3 | BK7: 43586 | BL7: =100*('ONS - Table 1'!CK274/AVERAGE('ONS - Table 1'!$CK$270:$CK$281)) -> 100.00833 | BM7: =100*('ONS - Table 2'!CK274/AVERAGE('ONS - Table 2'!$CK$270:$CK$281)) -> 100 | BN7: 100 | BP7: 43586 | BQ7: =100*('ONS - Table 1'!ET274/AVERAGE('ONS - Table 1'!$ET$270:$ET$281)) -> 99.4 | BR7: =100*('ONS - Table 2'!ET274/AVERAGE('ONS - Table 2'!$ET$270:$ET$281)) -> 99.884607 | BS7: 100 | BU7: 43586 | BV7: =100*('ONS - Table 1'!J274/AVERAGE('ONS - Table 1'!$J$270:$J$281)) -> 98.583569 | BW7: =100*('ONS - Table 2'!J274/AVERAGE('ONS - Table 2'!$J$270:$J$281)) -> 98.542656 | BX7: 100 | CL7: =+CL6+1 -> 45511 | CM7: =100*(HAVERD!F165/HAVERD!F$161) -> 98.187659 | CN7: =100*(HAVERD!AZ165/HAVERD!AZ$161) -> 95.871726 | CO7: =100*(HAVERD!C165/HAVERD!C$161) -> 95.461823 | CP7: =100*(HAVERD!E165/HAVERD!E$161) -> 97.950782 | CQ7: =100*(HAVERD!D165/HAVERD!D$161) -> 92.067138 | CR7: =100*(HAVERD!M165/HAVERD!M$161) -> 96.293393 | CS7: 100
B8: =100*(Data!C196/AVERAGE(Data!C$191:C$194)) -> 77.839458 | C8: =100*(Data!D196/AVERAGE(Data!D$191:D$194)) -> 91.990663 | D8: =100*(Data!E196/AVERAGE(Data!E$191:E$194)) -> 90.985564 | E8: =100*(Data!F196/AVERAGE(Data!F$191:F$194)) -> 89.22755 | F8: =100*(Data!G196/AVERAGE(Data!G$191:G$194)) -> 82.956056 | G8: =100*(Data!H196/AVERAGE(Data!H$191:H$194)) -> 82.56114 | H8: =100*(Data!I196/AVERAGE(Data!I$191:I$194)) -> 87.810579 | J8: =RANK(B8,$B8:$H8) -> 7 | K8: =RANK(C8,$B8:$H8) -> 1 | L8: =RANK(D8,$B8:$H8) -> 2 | M8: =RANK(E8,$B8:$H8) -> 3 | N8: =RANK(F8,$B8:$H8) -> 5 | O8: =RANK(G8,$B8:$H8) -> 6 | P8: =RANK(H8,$B8:$H8) -> 4 | S8: =100*('ONS - Annex F'!C99/AVERAGE('ONS - Annex F'!$C$94:$C$97)) -> 77.885416 | T8: =C8 -> 91.990663 | U8: =D8 -> 90.985564 | V8: =E8 -> 89.22755 | W8: =F8 -> 82.956056 | X8: =G8 -> 82.56114 | Y8: =H8 -> 87.810579 | AB8: =B8 -> 77.839458 | AC8: =S8 -> 77.885416 | AD8: =MEDIAN($S8:$Y8) -> 87.810579 | AE8: =MIN($S8:$Y8) -> 77.885416 | AF8: =MAX($S8:$Y8)-AE8 -> 14.105248 | AG8: 100 | AI8: =RANK(S8,$S8:$Y8) -> 7 | AJ8: =RANK(T8,$S8:$Y8) -> 1 | AK8: =RANK(U8,$S8:$Y8) -> 2 | AL8: =RANK(V8,$S8:$Y8) -> 3 | AM8: =RANK(W8,$S8:$Y8) -> 5 | AN8: =RANK(X8,$S8:$Y8) -> 6 | AO8: =RANK(Y8,$S8:$Y8) -> 4 | BK8: 43617 | BL8: =100*('ONS - Table 1'!CK275/AVERAGE('ONS - Table 1'!$CK$270:$CK$281)) -> 100.30836 | BM8: =100*('ONS - Table 2'!CK275/AVERAGE('ONS - Table 2'!$CK$270:$CK$281)) -> 100.37106 | BN8: 100 | BP8: 43617 | BQ8: =100*('ONS - Table 1'!ET275/AVERAGE('ONS - Table 1'!$ET$270:$ET$281)) -> 100 | BR8: =100*('ONS - Table 2'!ET275/AVERAGE('ONS - Table 2'!$ET$270:$ET$281)) -> 100.71544 | BS8: 100 | BU8: 43617 | BV8: =100*('ONS - Table 1'!J275/AVERAGE('ONS - Table 1'!$J$270:$J$281)) -> 99.483419 | BW8: =100*('ONS - Table 2'!J275/AVERAGE('ONS - Table 2'!$J$270:$J$281)) -> 99.328639 | BX8: 100 | CL8: =+CL7+1 -> 45512 | CM8: =100*(HAVERD!F166/HAVERD!F$161) -> 97.921429 | CN8: =100*(HAVERD!AZ166/HAVERD!AZ$161) -> 97.184517 | CO8: =100*(HAVERD!C166/HAVERD!C$161) -> 97.661511 | CP8: =100*(HAVERD!E166/HAVERD!E$161) -> 97.96505 | CQ8: =100*(HAVERD!D166/HAVERD!D$161) -> 91.04964 | CR8: =100*(HAVERD!M166/HAVERD!M$161) -> 97.810169 | CS8: 100
B9: =100*(Data!C197/AVERAGE(Data!C$191:C$194)) -> 90.897216 | C9: =100*(Data!D197/AVERAGE(Data!D$191:D$194)) -> 99.128653 | D9: =100*(Data!E197/AVERAGE(Data!E$191:E$194)) -> 95.957014 | E9: =100*(Data!F197/AVERAGE(Data!F$191:F$194)) -> 96.944055 | F9: =100*(Data!G197/AVERAGE(Data!G$191:G$194)) -> 96.080525 | G9: =100*(Data!H197/AVERAGE(Data!H$191:H$194)) -> 94.048134 | H9: =100*(Data!I197/AVERAGE(Data!I$191:I$194)) -> 95.786875 | J9: =RANK(B9,$B9:$H9) -> 7 | K9: =RANK(C9,$B9:$H9) -> 1 | L9: =RANK(D9,$B9:$H9) -> 4 | M9: =RANK(E9,$B9:$H9) -> 2 | N9: =RANK(F9,$B9:$H9) -> 3 | O9: =RANK(G9,$B9:$H9) -> 6 | P9: =RANK(H9,$B9:$H9) -> 5 | S9: =100*('ONS - Annex F'!C100/AVERAGE('ONS - Annex F'!$C$94:$C$97)) -> 90.960758 | T9: =C9 -> 99.128653 | U9: =D9 -> 95.957014 | V9: =E9 -> 96.944055 | W9: =F9 -> 96.080525 | X9: =G9 -> 94.048134 | Y9: =H9 -> 95.786875 | AB9: =B9 -> 90.897216 | AC9: =S9 -> 90.960758 | AD9: =MEDIAN($S9:$Y9) -> 95.957014 | AE9: =MIN($S9:$Y9) -> 90.960758 | AF9: =MAX($S9:$Y9)-AE9 -> 8.1678952 | AG9: 100 | AI9: =RANK(S9,$S9:$Y9) -> 7 | AJ9: =RANK(T9,$S9:$Y9) -> 1 | AK9: =RANK(U9,$S9:$Y9) -> 4 | AL9: =RANK(V9,$S9:$Y9) -> 2 | AM9: =RANK(W9,$S9:$Y9) -> 3 | AN9: =RANK(X9,$S9:$Y9) -> 6 | AO9: =RANK(Y9,$S9:$Y9) -> 5 | AQ9: 2020 | AR9: =100*((AR4/AR3)-1) -> -10.359901 | AS9: =100*((AS4/AS3)-1) -> -10.296919 | AT9: =100*((AT4/AT3)-1) -> -2.2135259 | AU9: =100*((AU4/AU3)-1) -> -4.2202844 | AV9: =100*((AV4/AV3)-1) -> -4.4564223 | AW9: =100*((AW4/AW3)-1) -> -7.5918135 | AX9: =100*((AX4/AX3)-1) -> -9.0496266 | AY9: =100*((AY4/AY3)-1) -> -5.0382333 | BA9: 2020 | BB9: =100*((BB4/BB3)-1) -> -10.359901 | BC9: =100*((BC4/BC3)-1) -> -10.296919 | BD9: =100*((BD4/BD3)-1) -> -2.2135259 | BE9: =100*((BE4/BE3)-1) -> -4.2202844 | BF9: =100*((BF4/BF3)-1) -> -4.4564223 | BG9: =100*((BG4/BG3)-1) -> -7.5918135 | BH9: =100*((BH4/BH3)-1) -> -9.0496266 | BI9: =100*((BI4/BI3)-1) -> -5.0382333 | BK9: 43647 | BL9: =100*('ONS - Table 1'!CK276/AVERAGE('ONS - Table 1'!$CK$270:$CK$281)) -> 100.60838 | BM9: =100*('ONS - Table 2'!CK276/AVERAGE('ONS - Table 2'!$CK$270:$CK$281)) -> 100.46382 | BN9: 100 | BP9: 43647 | BQ9: =100*('ONS - Table 1'!ET276/AVERAGE('ONS - Table 1'!$ET$270:$ET$281)) -> 102.1 | BR9: =100*('ONS - Table 2'!ET276/AVERAGE('ONS - Table 2'!$ET$270:$ET$281)) -> 102.65405 | BS9: 100 | BU9: 43647 | BV9: =100*('ONS - Table 1'!J276/AVERAGE('ONS - Table 1'!$J$270:$J$281)) -> 100.1833 | BW9: =100*('ONS - Table 2'!J276/AVERAGE('ONS - Table 2'!$J$270:$J$281)) -> 100.21287 | BX9: 100
B10: =100*(Data!C198/AVERAGE(Data!C$191:C$194)) -> 92.130563 | C10: =100*(Data!D198/AVERAGE(Data!D$191:D$194)) -> 100.15465 | D10: =100*(Data!E198/AVERAGE(Data!E$191:E$194)) -> 97.640082 | E10: =100*(Data!F198/AVERAGE(Data!F$191:F$194)) -> 98.102023 | F10: =100*(Data!G198/AVERAGE(Data!G$191:G$194)) -> 95.941903 | G10: =100*(Data!H198/AVERAGE(Data!H$191:H$194)) -> 93.584193 | H10: =100*(Data!I198/AVERAGE(Data!I$191:I$194)) -> 97.586109 | J10: =RANK(B10,$B10:$H10) -> 7 | K10: =RANK(C10,$B10:$H10) -> 1 | L10: =RANK(D10,$B10:$H10) -> 3 | M10: =RANK(E10,$B10:$H10) -> 2 | N10: =RANK(F10,$B10:$H10) -> 5 | O10: =RANK(G10,$B10:$H10) -> 6 | P10: =RANK(H10,$B10:$H10) -> 4 | S10: =100*('ONS - Annex F'!C101/AVERAGE('ONS - Annex F'!$C$94:$C$97)) -> 92.203965 | T10: =C10 -> 100.15465 | U10: =D10 -> 97.640082 | V10: =E10 -> 98.102023 | W10: =F10 -> 95.941903 | X10: =G10 -> 93.584193 | Y10: =H10 -> 97.586109 | AB10: =B10 -> 92.130563 | AC10: =S10 -> 92.203965 | AD10: =MEDIAN($S10:$Y10) -> 97.586109 | AE10: =MIN($S10:$Y10) -> 92.203965 | AF10: =MAX($S10:$Y10)-AE10 -> 7.9506831 | AG10: 100 | AI10: =RANK(S10,$S10:$Y10) -> 7 | AJ10: =RANK(T10,$S10:$Y10) -> 1 | AK10: =RANK(U10,$S10:$Y10) -> 3 | AL10: =RANK(V10,$S10:$Y10) -> 2 | AM10: =RANK(W10,$S10:$Y10) -> 5 | AN10: =RANK(X10,$S10:$Y10) -> 6 | AO10: =RANK(Y10,$S10:$Y10) -> 4 | AQ10: 2021 | AR10: =100*((AR5/AR4)-1) -> 8.6749041 | AS10: =100*((AS5/AS4)-1) -> 8.5759509 | AT10: =100*((AT5/AT4)-1) -> 5.8001169 | AU10: =100*((AU5/AU4)-1) -> 2.7723692 | AV10: =100*((AV5/AV4)-1) -> 3.5416613 | AW10: =100*((AW5/AW4)-1) -> 6.828911 | AX10: =100*((AX5/AX4)-1) -> 8.2783053 | AY10: =100*((AY5/AY4)-1) -> 5.2869615 | BA10: 2021 | BB10: =100*((BB5/BB4)-1) -> 8.6749041 | BC10: =100*((BC5/BC4)-1) -> 8.5759509 | BD10: =100*((BD5/BD4)-1) -> 5.8001169 | BE10: =100*((BE5/BE4)-1) -> 2.7723692 | BF10: =100*((BF5/BF4)-1) -> 3.5416613 | BG10: =100*((BG5/BG4)-1) -> 6.828911 | BH10: =100*((BH5/BH4)-1) -> 8.2783053 | BI10: =100*((BI5/BI4)-1) -> 5.2869615 | BK10: 43678 | BL10: =100*('ONS - Table 1'!CK277/AVERAGE('ONS - Table 1'!$CK$270:$CK$281)) -> 100.00833 | BM10: =100*('ONS - Table 2'!CK277/AVERAGE('ONS - Table 2'!$CK$270:$CK$281)) -> 99.907236 | BN10: 100 | BP10: 43678 | BQ10: =100*('ONS - Table 1'!ET277/AVERAGE('ONS - Table 1'!$ET$270:$ET$281)) -> 100.1 | BR10: =100*('ONS - Table 2'!ET277/AVERAGE('ONS - Table 2'!$ET$270:$ET$281)) -> 100.34618 | BS10: 100 | BU10: 43678 | BV10: =100*('ONS - Table 1'!J277/AVERAGE('ONS - Table 1'!$J$270:$J$281)) -> 99.283453 | BW10: =100*('ONS - Table 2'!J277/AVERAGE('ONS - Table 2'!$J$270:$J$281)) -> 99.525135 | BX10: 100 | CM10: =100*((CM8/CM3)-1) -> -2.0785707 | CN10: =100*((CN8/CN3)-1) -> -2.8154827 | CO10: =100*((CO8/CO3)-1) -> -2.3384888 | CP10: =100*((CP8/CP3)-1) -> -2.0349496 | CQ10: =100*((CQ8/CQ3)-1) -> -8.9503604 | CR10: =100*((CR8/CR3)-1) -> -2.1898315
A11: 2021 | B11: =100*(Data!C199/AVERAGE(Data!C$191:C$194)) -> 91.186931 | C11: =100*(Data!D199/AVERAGE(Data!D$191:D$194)) -> 101.4421 | D11: =100*(Data!E199/AVERAGE(Data!E$191:E$194)) -> 97.930608 | E11: =100*(Data!F199/AVERAGE(Data!F$191:F$194)) -> 96.895113 | F11: =100*(Data!G199/AVERAGE(Data!G$191:G$194)) -> 96.229517 | G11: =100*(Data!H199/AVERAGE(Data!H$191:H$194)) -> 95.007023 | H11: =100*(Data!I199/AVERAGE(Data!I$191:I$194)) -> 98.99122 | J11: =RANK(B11,$B11:$H11) -> 7 | K11: =RANK(C11,$B11:$H11) -> 1 | L11: =RANK(D11,$B11:$H11) -> 3 | M11: =RANK(E11,$B11:$H11) -> 4 | N11: =RANK(F11,$B11:$H11) -> 5 | O11: =RANK(G11,$B11:$H11) -> 6 | P11: =RANK(H11,$B11:$H11) -> 2 | R11: 2021 | S11: =100*('ONS - Annex F'!C102/AVERAGE('ONS - Annex F'!$C$94:$C$97)) -> 91.245774 | T11: =C11 -> 101.4421 | U11: =D11 -> 97.930608 | V11: =E11 -> 96.895113 | W11: =F11 -> 96.229517 | X11: =G11 -> 95.007023 | Y11: =H11 -> 98.99122 | AA11: 2021 | AB11: =B11 -> 91.186931 | AC11: =S11 -> 91.245774 | AD11: =MEDIAN($S11:$Y11) -> 96.895113 | AE11: =MIN($S11:$Y11) -> 91.245774 | AF11: =MAX($S11:$Y11)-AE11 -> 10.196322 | AG11: 100 | AI11: =RANK(S11,$S11:$Y11) -> 7 | AJ11: =RANK(T11,$S11:$Y11) -> 1 | AK11: =RANK(U11,$S11:$Y11) -> 3 | AL11: =RANK(V11,$S11:$Y11) -> 4 | AM11: =RANK(W11,$S11:$Y11) -> 5 | AN11: =RANK(X11,$S11:$Y11) -> 6 | AO11: =RANK(Y11,$S11:$Y11) -> 2 | AQ11: 2022 | AR11: =100*((AR6/AR5)-1) -> 4.3452288 | AS11: =100*((AS6/AS5)-1) -> 4.8390852 | AT11: =100*((AT6/AT5)-1) -> 1.9356376 | AU11: =100*((AU6/AU5)-1) -> 1.1872723 | AV11: =100*((AV6/AV5)-1) -> 1.7375183 | AW11: =100*((AW6/AW5)-1) -> 2.6186879 | AX11: =100*((AX6/AX5)-1) -> 4.1452457 | AY11: =100*((AY6/AY5)-1) -> 3.8198683 | BA11: 2022 | BB11: =100*((BB6/BB5)-1) -> 4.3452288 | BC11: =100*((BC6/BC5)-1) -> 4.8390852 | BD11: =100*((BD6/BD5)-1) -> 1.9356376 | BE11: =100*((BE6/BE5)-1) -> 1.1872723 | BF11: =100*((BF6/BF5)-1) -> 1.7375183 | BG11: =100*((BG6/BG5)-1) -> 2.6186879 | BH11: =100*((BH6/BH5)-1) -> 4.1452457 | BI11: =100*((BI6/BI5)-1) -> 3.8198683 | BK11: 43709 | BL11: =100*('ONS - Table 1'!CK278/AVERAGE('ONS - Table 1'!$CK$270:$CK$281)) -> 98.708226 | BM11: =100*('ONS - Table 2'!CK278/AVERAGE('ONS - Table 2'!$CK$270:$CK$281)) -> 99.443414 | BN11: 100 | BP11: 43709 | BQ11: =100*('ONS - Table 1'!ET278/AVERAGE('ONS - Table 1'!$ET$270:$ET$281)) -> 100.9 | BR11: =100*('ONS - Table 2'!ET278/AVERAGE('ONS - Table 2'!$ET$270:$ET$281)) -> 101.17701 | BS11: 100 | BU11: 43709 | BV11: =100*('ONS - Table 1'!J278/AVERAGE('ONS - Table 1'!$J$270:$J$281)) -> 100.7832 | BW11: =100*('ONS - Table 2'!J278/AVERAGE('ONS - Table 2'!$J$270:$J$281)) -> 100.90061 | BX11: 100
B12: =100*(Data!C200/AVERAGE(Data!C$191:C$194)) -> 97.868994 | C12: =100*(Data!D200/AVERAGE(Data!D$191:D$194)) -> 102.98375 | D12: =100*(Data!E200/AVERAGE(Data!E$191:E$194)) -> 98.415228 | E12: =100*(Data!F200/AVERAGE(Data!F$191:F$194)) -> 99.317841 | F12: =100*(Data!G200/AVERAGE(Data!G$191:G$194)) -> 97.491954 | G12: =100*(Data!H200/AVERAGE(Data!H$191:H$194)) -> 97.51832 | H12: =100*(Data!I200/AVERAGE(Data!I$191:I$194)) -> 98.682511 | J12: =RANK(B12,$B12:$H12) -> 5 | K12: =RANK(C12,$B12:$H12) -> 1 | L12: =RANK(D12,$B12:$H12) -> 4 | M12: =RANK(E12,$B12:$H12) -> 2 | N12: =RANK(F12,$B12:$H12) -> 7 | O12: =RANK(G12,$B12:$H12) -> 6 | P12: =RANK(H12,$B12:$H12) -> 3 | S12: =100*('ONS - Annex F'!C103/AVERAGE('ONS - Annex F'!$C$94:$C$97)) -> 97.864682 | T12: =C12 -> 102.98375 | U12: =D12 -> 98.415228 | V12: =E12 -> 99.317841 | W12: =F12 -> 97.491954 | X12: =G12 -> 97.51832 | Y12: =H12 -> 98.682511 | AB12: =B12 -> 97.868994 | AC12: =S12 -> 97.864682 | AD12: =MEDIAN($S12:$Y12) -> 98.415228 | AE12: =MIN($S12:$Y12) -> 97.491954 | AF12: =MAX($S12:$Y12)-AE12 -> 5.4917932 | AG12: 100 | AI12: =RANK(S12,$S12:$Y12) -> 5 | AJ12: =RANK(T12,$S12:$Y12) -> 1 | AK12: =RANK(U12,$S12:$Y12) -> 4 | AL12: =RANK(V12,$S12:$Y12) -> 2 | AM12: =RANK(W12,$S12:$Y12) -> 7 | AN12: =RANK(X12,$S12:$Y12) -> 6 | AO12: =RANK(Y12,$S12:$Y12) -> 3 | AQ12: 2023 | AR12: =100*((AR7/AR6)-1) -> 0.10401785 | AT12: =100*((AT7/AT6)-1) -> 2.5427263 | AU12: =100*((AU7/AU6)-1) -> 1.8085472 | AV12: =100*((AV7/AV6)-1) -> -0.059403147 | AW12: =100*((AW7/AW6)-1) -> 1.1200591 | AX12: =100*((AX7/AX6)-1) -> 1.01723 | AY12: =100*((AY7/AY6)-1) -> 1.2489208 | BA12: 2023 | BB12: =100*((BB7/BB6)-1) -> 0.10401785 | BD12: =100*((BD7/BD6)-1) -> 2.5427263 | BE12: =100*((BE7/BE6)-1) -> 1.8085472 | BF12: =100*((BF7/BF6)-1) -> -0.059403147 | BG12: =100*((BG7/BG6)-1) -> 1.1200591 | BH12: =100*((BH7/BH6)-1) -> 1.01723 | BI12: =100*((BI7/BI6)-1) -> 1.2489208 | BK12: 43739 | BL12: =100*('ONS - Table 1'!CK279/AVERAGE('ONS - Table 1'!$CK$270:$CK$281)) -> 99.508292 | BM12: =100*('ONS - Table 2'!CK279/AVERAGE('ONS - Table 2'!$CK$270:$CK$281)) -> 98.701299 | BN12: 100 | BP12: 43739 | BQ12: =100*('ONS - Table 1'!ET279/AVERAGE('ONS - Table 1'!$ET$270:$ET$281)) -> 99.7 | BR12: =100*('ONS - Table 2'!ET279/AVERAGE('ONS - Table 2'!$ET$270:$ET$281)) -> 100.16155 | BS12: 100 | BU12: 43739 | BV12: =100*('ONS - Table 1'!J279/AVERAGE('ONS - Table 1'!$J$270:$J$281)) -> 101.78304 | BW12: =100*('ONS - Table 2'!J279/AVERAGE('ONS - Table 2'!$J$270:$J$281)) -> 101.49009 | BX12: 100
B13: =100*(Data!C201/AVERAGE(Data!C$191:C$194)) -> 99.548014 | C13: =100*(Data!D201/AVERAGE(Data!D$191:D$194)) -> 103.82271 | D13: =100*(Data!E201/AVERAGE(Data!E$191:E$194)) -> 98.099581 | E13: =100*(Data!F201/AVERAGE(Data!F$191:F$194)) -> 99.451334 | F13: =100*(Data!G201/AVERAGE(Data!G$191:G$194)) -> 100.27637 | G13: =100*(Data!H201/AVERAGE(Data!H$191:H$194)) -> 100.28392 | H13: =100*(Data!I201/AVERAGE(Data!I$191:I$194)) -> 100.34051 | J13: =RANK(B13,$B13:$H13) -> 5 | K13: =RANK(C13,$B13:$H13) -> 1 | L13: =RANK(D13,$B13:$H13) -> 7 | M13: =RANK(E13,$B13:$H13) -> 6 | N13: =RANK(F13,$B13:$H13) -> 4 | O13: =RANK(G13,$B13:$H13) -> 3 | P13: =RANK(H13,$B13:$H13) -> 2 | S13: =100*('ONS - Annex F'!C104/AVERAGE('ONS - Annex F'!$C$94:$C$97)) -> 99.498473 | T13: =C13 -> 103.82271 | U13: =D13 -> 98.099581 | V13: =E13 -> 99.451334 | W13: =F13 -> 100.27637 | X13: =G13 -> 100.28392 | Y13: =H13 -> 100.34051 | AB13: =B13 -> 99.548014 | AC13: =S13 -> 99.498473 | AD13: =MEDIAN($S13:$Y13) -> 100.27637 | AE13: =MIN($S13:$Y13) -> 98.099581 | AF13: =MAX($S13:$Y13)-AE13 -> 5.7231343 | AG13: 100 | AI13: =RANK(S13,$S13:$Y13) -> 5 | AJ13: =RANK(T13,$S13:$Y13) -> 1 | AK13: =RANK(U13,$S13:$Y13) -> 7 | AL13: =RANK(V13,$S13:$Y13) -> 6 | AM13: =RANK(W13,$S13:$Y13) -> 4 | AN13: =RANK(X13,$S13:$Y13) -> 3 | AO13: =RANK(Y13,$S13:$Y13) -> 2 | BK13: 43770 | BL13: =100*('ONS - Table 1'!CK280/AVERAGE('ONS - Table 1'!$CK$270:$CK$281)) -> 98.908242 | BM13: =100*('ONS - Table 2'!CK280/AVERAGE('ONS - Table 2'!$CK$270:$CK$281)) -> 98.51577 | BN13: 100 | BP13: 43770 | BQ13: =100*('ONS - Table 1'!ET280/AVERAGE('ONS - Table 1'!$ET$270:$ET$281)) -> 100.1 | BR13: =100*('ONS - Table 2'!ET280/AVERAGE('ONS - Table 2'!$ET$270:$ET$281)) -> 98.499885 | BS13: 100 | BU13: 43770 | BV13: =100*('ONS - Table 1'!J280/AVERAGE('ONS - Table 1'!$J$270:$J$281)) -> 100.98317 | BW13: =100*('ONS - Table 2'!J280/AVERAGE('ONS - Table 2'!$J$270:$J$281)) -> 100.90061 | BX13: 100
B14: =100*(Data!C202/AVERAGE(Data!C$191:C$194)) -> 101.06123 | C14: =100*(Data!D202/AVERAGE(Data!D$191:D$194)) -> 105.58426 | D14: =100*(Data!E202/AVERAGE(Data!E$191:E$194)) -> 99.294915 | E14: =100*(Data!F202/AVERAGE(Data!F$191:F$194)) -> 100.04534 | F14: =100*(Data!G202/AVERAGE(Data!G$191:G$194)) -> 100.8768 | G14: =100*(Data!H202/AVERAGE(Data!H$191:H$194)) -> 101.10883 | H14: =100*(Data!I202/AVERAGE(Data!I$191:I$194)) -> 101.9152 | J14: =RANK(B14,$B14:$H14) -> 4 | K14: =RANK(C14,$B14:$H14) -> 1 | L14: =RANK(D14,$B14:$H14) -> 7 | M14: =RANK(E14,$B14:$H14) -> 6 | N14: =RANK(F14,$B14:$H14) -> 5 | O14: =RANK(G14,$B14:$H14) -> 3 | P14: =RANK(H14,$B14:$H14) -> 2 | S14: =100*('ONS - Annex F'!C105/AVERAGE('ONS - Annex F'!$C$94:$C$97)) -> 100.97496 | T14: =C14 -> 105.58426 | U14: =D14 -> 99.294915 | V14: =E14 -> 100.04534 | W14: =F14 -> 100.8768 | X14: =G14 -> 101.10883 | Y14: =H14 -> 101.9152 | AB14: =B14 -> 101.06123 | AC14: =S14 -> 100.97496 | AD14: =MEDIAN($S14:$Y14) -> 100.97496 | AE14: =MIN($S14:$Y14) -> 99.294915 | AF14: =MAX($S14:$Y14)-AE14 -> 6.2893419 | AG14: 100 | AI14: =RANK(S14,$S14:$Y14) -> 4 | AJ14: =RANK(T14,$S14:$Y14) -> 1 | AK14: =RANK(U14,$S14:$Y14) -> 7 | AL14: =RANK(V14,$S14:$Y14) -> 6 | AM14: =RANK(W14,$S14:$Y14) -> 5 | AN14: =RANK(X14,$S14:$Y14) -> 3 | AO14: =RANK(Y14,$S14:$Y14) -> 2 | BK14: 43800 | BL14: =100*('ONS - Table 1'!CK281/AVERAGE('ONS - Table 1'!$CK$270:$CK$281)) -> 98.008167 | BM14: =100*('ONS - Table 2'!CK281/AVERAGE('ONS - Table 2'!$CK$270:$CK$281)) -> 97.866419 | BN14: 100 | BP14: 43800 | BQ14: =100*('ONS - Table 1'!ET281/AVERAGE('ONS - Table 1'!$ET$270:$ET$281)) -> 101.1 | BR14: =100*('ONS - Table 2'!ET281/AVERAGE('ONS - Table 2'!$ET$270:$ET$281)) -> 97.392107 | BS14: 100 | BU14: 43800 | BV14: =100*('ONS - Table 1'!J281/AVERAGE('ONS - Table 1'!$J$270:$J$281)) -> 103.1828 | BW14: =100*('ONS - Table 2'!J281/AVERAGE('ONS - Table 2'!$J$270:$J$281)) -> 103.06206 | BX14: 100
A15: 2022 | B15: =100*(Data!C203/AVERAGE(Data!C$191:C$194)) -> 101.59643 | C15: =100*(Data!D203/AVERAGE(Data!D$191:D$194)) -> 105.05894 | D15: =100*(Data!E203/AVERAGE(Data!E$191:E$194)) -> 98.740939 | E15: =100*(Data!F203/AVERAGE(Data!F$191:F$194)) -> 100.46693 | F15: =100*(Data!G203/AVERAGE(Data!G$191:G$194)) -> 100.73323 | G15: =100*(Data!H203/AVERAGE(Data!H$191:H$194)) -> 101.30991 | H15: =100*(Data!I203/AVERAGE(Data!I$191:I$194)) -> 102.89488 | J15: =RANK(B15,$B15:$H15) -> 3 | K15: =RANK(C15,$B15:$H15) -> 1 | L15: =RANK(D15,$B15:$H15) -> 7 | M15: =RANK(E15,$B15:$H15) -> 6 | N15: =RANK(F15,$B15:$H15) -> 5 | O15: =RANK(G15,$B15:$H15) -> 4 | P15: =RANK(H15,$B15:$H15) -> 2 | R15: 2022 | S15: =100*('ONS - Annex F'!C106/AVERAGE('ONS - Annex F'!$C$94:$C$97)) -> 101.71167 | T15: =C15 -> 105.05894 | U15: =D15 -> 98.740939 | V15: =E15 -> 100.46693 | W15: =F15 -> 100.73323 | X15: =G15 -> 101.30991 | Y15: =H15 -> 102.89488 | AA15: 2022 | AB15: =B15 -> 101.59643 | AC15: =S15 -> 101.71167 | AD15: =MEDIAN($S15:$Y15) -> 101.30991 | AE15: =MIN($S15:$Y15) -> 98.740939 | AF15: =MAX($S15:$Y15)-AE15 -> 6.3179966 | AG15: 100 | AI15: =RANK(S15,$S15:$Y15) -> 3 | AJ15: =RANK(T15,$S15:$Y15) -> 1 | AK15: =RANK(U15,$S15:$Y15) -> 7 | AL15: =RANK(V15,$S15:$Y15) -> 6 | AM15: =RANK(W15,$S15:$Y15) -> 5 | AN15: =RANK(X15,$S15:$Y15) -> 4 | AO15: =RANK(Y15,$S15:$Y15) -> 2 | BK15: 43831 | BL15: =100*('ONS - Table 1'!CK282/AVERAGE('ONS - Table 1'!$CK$270:$CK$281)) -> 97.508126 | BM15: =100*('ONS - Table 2'!CK282/AVERAGE('ONS - Table 2'!$CK$270:$CK$281)) -> 97.03154 | BN15: 100 | BP15: 43831 | BQ15: =100*('ONS - Table 1'!ET282/AVERAGE('ONS - Table 1'!$ET$270:$ET$281)) -> 101.8 | BR15: =100*('ONS - Table 2'!ET282/AVERAGE('ONS - Table 2'!$ET$270:$ET$281)) -> 98.22294 | BS15: 100 | BU15: 43831 | BV15: =100*('ONS - Table 1'!J282/AVERAGE('ONS - Table 1'!$J$270:$J$281)) -> 105.88235 | BW15: =100*('ONS - Table 2'!J282/AVERAGE('ONS - Table 2'!$J$270:$J$281)) -> 105.71475 | BX15: 100
B16: =100*(Data!C204/AVERAGE(Data!C$191:C$194)) -> 101.68471 | C16: =100*(Data!D204/AVERAGE(Data!D$191:D$194)) -> 104.91057 | D16: =100*(Data!E204/AVERAGE(Data!E$191:E$194)) -> 99.897396 | E16: =100*(Data!F204/AVERAGE(Data!F$191:F$194)) -> 100.4569 | F16: =100*(Data!G204/AVERAGE(Data!G$191:G$194)) -> 101.11337 | G16: =100*(Data!H204/AVERAGE(Data!H$191:H$194)) -> 102.72696 | H16: =100*(Data!I204/AVERAGE(Data!I$191:I$194)) -> 103.86154 | J16: =RANK(B16,$B16:$H16) -> 4 | K16: =RANK(C16,$B16:$H16) -> 1 | L16: =RANK(D16,$B16:$H16) -> 7 | M16: =RANK(E16,$B16:$H16) -> 6 | N16: =RANK(F16,$B16:$H16) -> 5 | O16: =RANK(G16,$B16:$H16) -> 3 | P16: =RANK(H16,$B16:$H16) -> 2 | S16: =100*('ONS - Annex F'!C107/AVERAGE('ONS - Annex F'!$C$94:$C$97)) -> 102.05263 | T16: =C16 -> 104.91057 | U16: =D16 -> 99.897396 | V16: =E16 -> 100.4569 | W16: =F16 -> 101.11337 | X16: =G16 -> 102.72696 | Y16: =H16 -> 103.86154 | AB16: =B16 -> 101.68471 | AC16: =S16 -> 102.05263 | AD16: =MEDIAN($S16:$Y16) -> 102.05263 | AE16: =MIN($S16:$Y16) -> 99.897396 | AF16: =MAX($S16:$Y16)-AE16 -> 5.0131733 | AG16: 100 | AI16: =RANK(S16,$S16:$Y16) -> 4 | AJ16: =RANK(T16,$S16:$Y16) -> 1 | AK16: =RANK(U16,$S16:$Y16) -> 7 | AL16: =RANK(V16,$S16:$Y16) -> 6 | AM16: =RANK(W16,$S16:$Y16) -> 5 | AN16: =RANK(X16,$S16:$Y16) -> 3 | AO16: =RANK(Y16,$S16:$Y16) -> 2 | BK16: 43862 | BL16: =100*('ONS - Table 1'!CK283/AVERAGE('ONS - Table 1'!$CK$270:$CK$281)) -> 96.608051 | BM16: =100*('ONS - Table 2'!CK283/AVERAGE('ONS - Table 2'!$CK$270:$CK$281)) -> 96.103896 | BN16: 100 | BP16: 43862 | BQ16: =100*('ONS - Table 1'!ET283/AVERAGE('ONS - Table 1'!$ET$270:$ET$281)) -> 102 | BR16: =100*('ONS - Table 2'!ET283/AVERAGE('ONS - Table 2'!$ET$270:$ET$281)) -> 97.022848 | BS16: 100 | BU16: 43862 | BV16: =100*('ONS - Table 1'!J283/AVERAGE('ONS - Table 1'!$J$270:$J$281)) -> 107.68205 | BW16: =100*('ONS - Table 2'!J283/AVERAGE('ONS - Table 2'!$J$270:$J$281)) -> 107.87621 | BX16: 100
B17: =100*(Data!C205/AVERAGE(Data!C$191:C$194)) -> 101.6052 | C17: =100*(Data!D205/AVERAGE(Data!D$191:D$194)) -> 105.60117 | D17: =100*(Data!E205/AVERAGE(Data!E$191:E$194)) -> 99.706488 | E17: =100*(Data!F205/AVERAGE(Data!F$191:F$194)) -> 101.09874 | F17: =100*(Data!G205/AVERAGE(Data!G$191:G$194)) -> 101.65621 | G17: =100*(Data!H205/AVERAGE(Data!H$191:H$194)) -> 103.13328 | H17: =100*(Data!I205/AVERAGE(Data!I$191:I$194)) -> 104.33724 | J17: =RANK(B17,$B17:$H17) -> 5 | K17: =RANK(C17,$B17:$H17) -> 1 | L17: =RANK(D17,$B17:$H17) -> 7 | M17: =RANK(E17,$B17:$H17) -> 6 | N17: =RANK(F17,$B17:$H17) -> 4 | O17: =RANK(G17,$B17:$H17) -> 3 | P17: =RANK(H17,$B17:$H17) -> 2 | S17: =100*('ONS - Annex F'!C108/AVERAGE('ONS - Annex F'!$C$94:$C$97)) -> 102.16886 | T17: =C17 -> 105.60117 | U17: =D17 -> 99.706488 | V17: =E17 -> 101.09874 | W17: =F17 -> 101.65621 | X17: =G17 -> 103.13328 | Y17: =H17 -> 104.33724 | AB17: =B17 -> 101.6052 | AC17: =S17 -> 102.16886 | AD17: =MEDIAN($S17:$Y17) -> 102.16886 | AE17: =MIN($S17:$Y17) -> 99.706488 | AF17: =MAX($S17:$Y17)-AE17 -> 5.8946839 | AG17: 100 | AI17: =RANK(S17,$S17:$Y17) -> 4 | AJ17: =RANK(T17,$S17:$Y17) -> 1 | AK17: =RANK(U17,$S17:$Y17) -> 7 | AL17: =RANK(V17,$S17:$Y17) -> 6 | AM17: =RANK(W17,$S17:$Y17) -> 5 | AN17: =RANK(X17,$S17:$Y17) -> 3 | AO17: =RANK(Y17,$S17:$Y17) -> 2 | BK17: 43891 | BL17: =100*('ONS - Table 1'!CK284/AVERAGE('ONS - Table 1'!$CK$270:$CK$281)) -> 82.806901 | BM17: =100*('ONS - Table 2'!CK284/AVERAGE('ONS - Table 2'!$CK$270:$CK$281)) -> 83.116883 | BN17: 100 | BP17: 43891 | BQ17: =100*('ONS - Table 1'!ET284/AVERAGE('ONS - Table 1'!$ET$270:$ET$281)) -> 86.9 | BR17: =100*('ONS - Table 2'!ET284/AVERAGE('ONS - Table 2'!$ET$270:$ET$281)) -> 83.175629 | BS17: 100 | BU17: 43891 | BV17: =100*('ONS - Table 1'!J284/AVERAGE('ONS - Table 1'!$J$270:$J$281)) -> 97.383769 | BW17: =100*('ONS - Table 2'!J284/AVERAGE('ONS - Table 2'!$J$270:$J$281)) -> 97.756673 | BX17: 100
B18: =100*(Data!C206/AVERAGE(Data!C$191:C$194)) -> 101.71067 | C18: =100*(Data!D206/AVERAGE(Data!D$191:D$194)) -> 106.27244 | D18: =100*(Data!E206/AVERAGE(Data!E$191:E$194)) -> 100.07028 | E18: =100*(Data!F206/AVERAGE(Data!F$191:F$194)) -> 100.56258 | F18: =100*(Data!G206/AVERAGE(Data!G$191:G$194)) -> 101.71236 | G18: =100*(Data!H206/AVERAGE(Data!H$191:H$194)) -> 103.07682 | H18: =100*(Data!I206/AVERAGE(Data!I$191:I$194)) -> 104.11255 | J18: =RANK(B18,$B18:$H18) -> 5 | K18: =RANK(C18,$B18:$H18) -> 1 | L18: =RANK(D18,$B18:$H18) -> 7 | M18: =RANK(E18,$B18:$H18) -> 6 | N18: =RANK(F18,$B18:$H18) -> 4 | O18: =RANK(G18,$B18:$H18) -> 3 | P18: =RANK(H18,$B18:$H18) -> 2 | S18: =100*('ONS - Annex F'!C109/AVERAGE('ONS - Annex F'!$C$94:$C$97)) -> 102.50303 | T18: =C18 -> 106.27244 | U18: =D18 -> 100.07028 | V18: =E18 -> 100.56258 | W18: =F18 -> 101.71236 | X18: =G18 -> 103.07682 | Y18: =H18 -> 104.11255 | AB18: =B18 -> 101.71067 | AC18: =S18 -> 102.50303 | AD18: =MEDIAN($S18:$Y18) -> 102.50303 | AE18: =MIN($S18:$Y18) -> 100.07028 | AF18: =MAX($S18:$Y18)-AE18 -> 6.2021635 | AG18: 100 | AI18: =RANK(S18,$S18:$Y18) -> 4 | AJ18: =RANK(T18,$S18:$Y18) -> 1 | AK18: =RANK(U18,$S18:$Y18) -> 7 | AL18: =RANK(V18,$S18:$Y18) -> 6 | AM18: =RANK(W18,$S18:$Y18) -> 5 | AN18: =RANK(X18,$S18:$Y18) -> 3 | AO18: =RANK(Y18,$S18:$Y18) -> 2 | BK18: 43922 | BL18: =100*('ONS - Table 1'!CK285/AVERAGE('ONS - Table 1'!$CK$270:$CK$281)) -> 64.505375 | BM18: =100*('ONS - Table 2'!CK285/AVERAGE('ONS - Table 2'!$CK$270:$CK$281)) -> 64.471243 | BN18: 100 | BP18: 43922 | BQ18: =100*('ONS - Table 1'!ET285/AVERAGE('ONS - Table 1'!$ET$270:$ET$281)) -> 50.9 | BR18: =100*('ONS - Table 2'!ET285/AVERAGE('ONS - Table 2'!$ET$270:$ET$281)) -> 55.481191 | BS18: 100 | BU18: 43922 | BV18: =100*('ONS - Table 1'!J285/AVERAGE('ONS - Table 1'!$J$270:$J$281)) -> 77.587069 | BW18: =100*('ONS - Table 2'!J285/AVERAGE('ONS - Table 2'!$J$270:$J$281)) -> 77.026363 | BX18: 100
BK19: 43952 | BL19: =100*('ONS - Table 1'!CK286/AVERAGE('ONS - Table 1'!$CK$270:$CK$281)) -> 76.406367 | BM19: =100*('ONS - Table 2'!CK286/AVERAGE('ONS - Table 2'!$CK$270:$CK$281)) -> 76.159555 | BN19: 100 | BP19: 43952 | BQ19: =100*('ONS - Table 1'!ET286/AVERAGE('ONS - Table 1'!$ET$270:$ET$281)) -> 52.3 | BR19: =100*('ONS - Table 2'!ET286/AVERAGE('ONS - Table 2'!$ET$270:$ET$281)) -> 55.204246 | BS19: 100 | BU19: 43952 | BV19: =100*('ONS - Table 1'!J286/AVERAGE('ONS - Table 1'!$J$270:$J$281)) -> 86.385602 | BW19: =100*('ONS - Table 2'!J286/AVERAGE('ONS - Table 2'!$J$270:$J$281)) -> 84.493205 | BX19: 100
BK20: 43983 | BL20: =100*('ONS - Table 1'!CK287/AVERAGE('ONS - Table 1'!$CK$270:$CK$281)) -> 88.507376 | BM20: =100*('ONS - Table 2'!CK287/AVERAGE('ONS - Table 2'!$CK$270:$CK$281)) -> 87.755102 | BN20: 100 | BP20: 43983 | BQ20: =100*('ONS - Table 1'!ET287/AVERAGE('ONS - Table 1'!$ET$270:$ET$281)) -> 57 | BR20: =100*('ONS - Table 2'!ET287/AVERAGE('ONS - Table 2'!$ET$270:$ET$281)) -> 58.250635 | BS20: 100 | BU20: 43983 | BV20: =100*('ONS - Table 1'!J287/AVERAGE('ONS - Table 1'!$J$270:$J$281)) -> 97.883686 | BW20: =100*('ONS - Table 2'!J287/AVERAGE('ONS - Table 2'!$J$270:$J$281)) -> 96.675946 | BX20: 100
BK21: 44013 | BL21: =100*('ONS - Table 1'!CK288/AVERAGE('ONS - Table 1'!$CK$270:$CK$281)) -> 90.707559 | BM21: =100*('ONS - Table 2'!CK288/AVERAGE('ONS - Table 2'!$CK$270:$CK$281)) -> 89.61039 | BN21: 100 | BP21: 44013 | BQ21: =100*('ONS - Table 1'!ET288/AVERAGE('ONS - Table 1'!$ET$270:$ET$281)) -> 60.8 | BR21: =100*('ONS - Table 2'!ET288/AVERAGE('ONS - Table 2'!$ET$270:$ET$281)) -> 62.497115 | BS21: 100 | BU21: 44013 | BV21: =100*('ONS - Table 1'!J288/AVERAGE('ONS - Table 1'!$J$270:$J$281)) -> 104.58257 | BW21: =100*('ONS - Table 2'!J288/AVERAGE('ONS - Table 2'!$J$270:$J$281)) -> 103.65155 | BX21: 100
BK22: 44044 | BL22: =100*('ONS - Table 1'!CK289/AVERAGE('ONS - Table 1'!$CK$270:$CK$281)) -> 91.807651 | BM22: =100*('ONS - Table 2'!CK289/AVERAGE('ONS - Table 2'!$CK$270:$CK$281)) -> 90.630798 | BN22: 100 | BP22: 44044 | BQ22: =100*('ONS - Table 1'!ET289/AVERAGE('ONS - Table 1'!$ET$270:$ET$281)) -> 63 | BR22: =100*('ONS - Table 2'!ET289/AVERAGE('ONS - Table 2'!$ET$270:$ET$281)) -> 65.543503 | BS22: 100 | BU22: 44044 | BV22: =100*('ONS - Table 1'!J289/AVERAGE('ONS - Table 1'!$J$270:$J$281)) -> 108.5819 | BW22: =100*('ONS - Table 2'!J289/AVERAGE('ONS - Table 2'!$J$270:$J$281)) -> 108.36745 | BX22: 100
BK23: 44075 | BL23: =100*('ONS - Table 1'!CK290/AVERAGE('ONS - Table 1'!$CK$270:$CK$281)) -> 93.007751 | BM23: =100*('ONS - Table 2'!CK290/AVERAGE('ONS - Table 2'!$CK$270:$CK$281)) -> 92.022263 | BN23: 100 | BP23: 44075 | BQ23: =100*('ONS - Table 1'!ET290/AVERAGE('ONS - Table 1'!$ET$270:$ET$281)) -> 65.2 | BR23: =100*('ONS - Table 2'!ET290/AVERAGE('ONS - Table 2'!$ET$270:$ET$281)) -> 67.666744 | BS23: 100 | BU23: 44075 | BV23: =100*('ONS - Table 1'!J290/AVERAGE('ONS - Table 1'!$J$270:$J$281)) -> 110.28162 | BW23: =100*('ONS - Table 2'!J290/AVERAGE('ONS - Table 2'!$J$270:$J$281)) -> 111.11839 | BX23: 100
BK24: 44105 | BL24: =100*('ONS - Table 1'!CK291/AVERAGE('ONS - Table 1'!$CK$270:$CK$281)) -> 93.807817 | BM24: =100*('ONS - Table 2'!CK291/AVERAGE('ONS - Table 2'!$CK$270:$CK$281)) -> 92.207792 | BN24: 100 | BP24: 44105 | BQ24: =100*('ONS - Table 1'!ET291/AVERAGE('ONS - Table 1'!$ET$270:$ET$281)) -> 66.5 | BR24: =100*('ONS - Table 2'!ET291/AVERAGE('ONS - Table 2'!$ET$270:$ET$281)) -> 69.32841 | BS24: 100 | BU24: 44105 | BV24: =100*('ONS - Table 1'!J291/AVERAGE('ONS - Table 1'!$J$270:$J$281)) -> 110.28162 | BW24: =100*('ONS - Table 2'!J291/AVERAGE('ONS - Table 2'!$J$270:$J$281)) -> 110.23416 | BX24: 100
BK25: 44136 | BL25: =100*('ONS - Table 1'!CK292/AVERAGE('ONS - Table 1'!$CK$270:$CK$281)) -> 90.207517 | BM25: =100*('ONS - Table 2'!CK292/AVERAGE('ONS - Table 2'!$CK$270:$CK$281)) -> 88.589981 | BN25: 100 | BP25: 44136 | BQ25: =100*('ONS - Table 1'!ET292/AVERAGE('ONS - Table 1'!$ET$270:$ET$281)) -> 66.4 | BR25: =100*('ONS - Table 2'!ET292/AVERAGE('ONS - Table 2'!$ET$270:$ET$281)) -> 69.420725 | BS25: 100 | BU25: 44136 | BV25: =100*('ONS - Table 1'!J292/AVERAGE('ONS - Table 1'!$J$270:$J$281)) -> 111.48142 | BW25: =100*('ONS - Table 2'!J292/AVERAGE('ONS - Table 2'!$J$270:$J$281)) -> 112.59211 | BX25: 100
BK26: 44166 | BL26: =100*('ONS - Table 1'!CK293/AVERAGE('ONS - Table 1'!$CK$270:$CK$281)) -> 91.707642 | BM26: =100*('ONS - Table 2'!CK293/AVERAGE('ONS - Table 2'!$CK$270:$CK$281)) -> 90.352505 | BN26: 100 | BP26: 44166 | BQ26: =100*('ONS - Table 1'!ET293/AVERAGE('ONS - Table 1'!$ET$270:$ET$281)) -> 66.8 | BR26: =100*('ONS - Table 2'!ET293/AVERAGE('ONS - Table 2'!$ET$270:$ET$281)) -> 70.066928 | BS26: 100 | BU26: 44166 | BV26: =100*('ONS - Table 1'!J293/AVERAGE('ONS - Table 1'!$J$270:$J$281)) -> 108.68189 | BW26: =100*('ONS - Table 2'!J293/AVERAGE('ONS - Table 2'!$J$270:$J$281)) -> 111.11839 | BX26: 100
BK27: 44197 | BL27: =100*('ONS - Table 1'!CK294/AVERAGE('ONS - Table 1'!$CK$270:$CK$281)) -> 85.607134 | BM27: =100*('ONS - Table 2'!CK294/AVERAGE('ONS - Table 2'!$CK$270:$CK$281)) -> 83.209647 | BN27: 100 | BP27: 44197 | BQ27: =100*('ONS - Table 1'!ET294/AVERAGE('ONS - Table 1'!$ET$270:$ET$281)) -> 68.4 | BR27: =100*('ONS - Table 2'!ET294/AVERAGE('ONS - Table 2'!$ET$270:$ET$281)) -> 71.267021 | BS27: 100 | BU27: 44197 | BV27: =100*('ONS - Table 1'!J294/AVERAGE('ONS - Table 1'!$J$270:$J$281)) -> 105.38244 | BW27: =100*('ONS - Table 2'!J294/AVERAGE('ONS - Table 2'!$J$270:$J$281)) -> 107.38497 | BX27: 100
BK28: 44228 | BL28: =100*('ONS - Table 1'!CK295/AVERAGE('ONS - Table 1'!$CK$270:$CK$281)) -> 87.707309 | BM28: =100*('ONS - Table 2'!CK295/AVERAGE('ONS - Table 2'!$CK$270:$CK$281)) -> 85.250464 | BN28: 100 | BP28: 44228 | BQ28: =100*('ONS - Table 1'!ET295/AVERAGE('ONS - Table 1'!$ET$270:$ET$281)) -> 70.8 | BR28: =100*('ONS - Table 2'!ET295/AVERAGE('ONS - Table 2'!$ET$270:$ET$281)) -> 74.498038 | BS28: 100 | BU28: 44228 | BV28: =100*('ONS - Table 1'!J295/AVERAGE('ONS - Table 1'!$J$270:$J$281)) -> 105.48242 | BW28: =100*('ONS - Table 2'!J295/AVERAGE('ONS - Table 2'!$J$270:$J$281)) -> 108.17095 | BX28: 100
BK29: 44256 | BL29: =100*('ONS - Table 1'!CK296/AVERAGE('ONS - Table 1'!$CK$270:$CK$281)) -> 92.407701 | BM29: =100*('ONS - Table 2'!CK296/AVERAGE('ONS - Table 2'!$CK$270:$CK$281)) -> 89.703154 | BN29: 100 | BP29: 44256 | BQ29: =100*('ONS - Table 1'!ET296/AVERAGE('ONS - Table 1'!$ET$270:$ET$281)) -> 77.8 | BR29: =100*('ONS - Table 2'!ET296/AVERAGE('ONS - Table 2'!$ET$270:$ET$281)) -> 81.790907 | BS29: 100 | BU29: 44256 | BV29: =100*('ONS - Table 1'!J296/AVERAGE('ONS - Table 1'!$J$270:$J$281)) -> 105.48242 | BW29: =100*('ONS - Table 2'!J296/AVERAGE('ONS - Table 2'!$J$270:$J$281)) -> 108.85869 | BX29: 100
BK30: 44287 | BL30: =100*('ONS - Table 1'!CK297/AVERAGE('ONS - Table 1'!$CK$270:$CK$281)) -> 101.20843 | BM30: =100*('ONS - Table 2'!CK297/AVERAGE('ONS - Table 2'!$CK$270:$CK$281)) -> 97.680891 | BN30: 100 | BP30: 44287 | BQ30: =100*('ONS - Table 1'!ET297/AVERAGE('ONS - Table 1'!$ET$270:$ET$281)) -> 85.1 | BR30: =100*('ONS - Table 2'!ET297/AVERAGE('ONS - Table 2'!$ET$270:$ET$281)) -> 86.683591 | BS30: 100 | BU30: 44287 | BV30: =100*('ONS - Table 1'!J297/AVERAGE('ONS - Table 1'!$J$270:$J$281)) -> 105.08249 | BW30: =100*('ONS - Table 2'!J297/AVERAGE('ONS - Table 2'!$J$270:$J$281)) -> 108.95693 | BX30: 100
... BK50: 44896 | BL50: =100*('ONS - Table 1'!CK317/AVERAGE('ONS - Table 1'!$CK$270:$CK$281)) -> 93.207767 | BM50: =100*('ONS - Table 2'!CK317/AVERAGE('ONS - Table 2'!$CK$270:$CK$281)) -> 90.352505 | BN50: 100 | BP50: 44896 | BQ50: =100*('ONS - Table 1'!ET317/AVERAGE('ONS - Table 1'!$ET$270:$ET$281)) -> 101.3 | BR50: =100*('ONS - Table 2'!ET317/AVERAGE('ONS - Table 2'!$ET$270:$ET$281)) -> 90.468498 | BS50: 100 | BU50: 44896 | BV50: =100*('ONS - Table 1'!J317/AVERAGE('ONS - Table 1'!$J$270:$J$281)) -> 99.983336 | BW50: =100*('ONS - Table 2'!J317/AVERAGE('ONS - Table 2'!$J$270:$J$281)) -> 97.560177 | BX50: 100
BU52: 2019 | BV52: =AVERAGE(BV3:BV14) -> 100 | BW52: =AVERAGE(BW3:BW14) -> 100
BU53: 2020 | BV53: =AVERAGE(BV15:BV26) -> 102.22463 | BW53: =AVERAGE(BW15:BW26) -> 102.21877
BU54: 2021 | BV54: =AVERAGE(BV27:BV38) -> 103.84103 | BW54: =AVERAGE(BW27:BW38) -> 106.09137
BU55: 2022 | BV55: =AVERAGE(BV39:BV50) -> 100.4166 | BW55: =AVERAGE(BW39:BW50) -> 98.2561
BU57: 2020 | BV57: =100*((BV53/BV52)-1) -> 2.2246292 | BW57: =100*((BW53/BW52)-1) -> 2.2187654
BU58: 2021 | BV58: =100*((BV54/BV53)-1) -> 1.581221 | BW58: =100*((BW54/BW53)-1) -> 3.7885463
BU59: 2022 | BV59: =100*((BV55/BV54)-1) -> -3.2977614 | BW59: =100*((BW55/BW54)-1) -> -7.385399

Sheet HAVERD
C1: US | D1: Japan | E1: Eurozone | F1: UK | G1: Argentina | H1: Australia | I1: Austria | J1: Belgium | K1: Brazil | L1: Bulgaria | M1: Canada | N1: Chile | O1: China | P1: Croatia | Q1: Czechia | R1: Denmark | S1: Finland | T1: France | U1: Germany | V1: Greece | W1: Hong Kong | X1: Hungary | Y1: India | Z1: Indonesia | AA1: Ireland | AB1: Italy | AC1: Kenya | AD1: Malaysia | AE1: Mexico | AF1: Netherlands | AG1: New Zealand | AH1: Nigeria | AI1: Norway | AJ1: Philippines | AK1: Poland | AL1: Portugal | AM1: Romania | AN1: Russia | AO1: Singapore | AP1: Slovakia | AQ1: South Africa | AR1: Korea | AS1: Spain | AT1: Sweden | AU1: Taiwan | AV1: Tanzania | AW1: Thailand | AX1: Turkey | AY1: Venezuela | AZ1: Global
B2: 20240101 !D | C2: S111SP5@INTDAILY | D2: S158TPX@INTDAILY | E2: S0235Z@INTDAILY | F2: S112FTA@INTDAILY | G2: SPGENN@DAILY | H2: S193SNP@INTDAILY | I2: S122TRI@INTDAILY | J2: S124B20@INTDAILY | K2: S223BOV@INTDAILY | L2: S918SOF@INTDAILY | M2: S156TOI@INTDAILY | N2: SPIGP@DAILY | O2: S924S@INTDAILY | P2: S960ZCX@INTDAILY | Q2: S935P50@INTDAILY | R2: S128KFX@INTDAILY | S2: S172HEX@INTDAILY | T2: S132CAC@INTDAILY | U2: S134DAP@INTDAILY | V2: S174ASE@INTDAILY | W2: S532HNG@INTDAILY | X2: SPBUX@DAILY | Y2: S534SX@INTDAILY | Z2: S536JKC@INTDAILY | AA2: SPISE@DAILY | AB2: S136MBI@INTDAILY | AC2: S664NS@INTDAILY | AD2: S548KLS@INTDAILY | AE2: S273IPC@INTDAILY | AF2: S138CBS@INTDAILY | AG2: S196K5P@INTDAILY | AH2: S694SEA@INTDAILY | AI2: S142OSE@INTDAILY | AJ2: S566MNC@INTDAILY | AK2: S964WIG@INTDAILY | AL2: S182PSI@INTDAILY | AM2: S968BET@INTDAILY | AN2: S922MXC@INTDAILY | AO2: S576STT@INTDAILY | AP2: S936SAX@INTDAILY | AQ2: S199FJA@INTDAILY | AR2: S542CEX@INTDAILY | AS2: S184MGI@INTDAILY | AT2: S144AFF@INTDAILY | AU2: S528TWN@INTDAILY | AV2: S738DSI@INTDAILY | AW2: S578BST@INTDAILY | AX2: S186IMK@INTDAILY | AY2: SPVEN@DAILY | AZ2: S001DJW@INTDAILY
B3: .DESC | C3: Standard & Poor's 500 Stock Price Index (1941-43=10) | D3: Japan: Tokyo Stock Price Index: Topix Cash Index (Jan-04-68=100) | E3: Euro area: EURO STOXX 50 Price Index: Based in Euro (EOP, Dec-31-91=1000) | F3: UK: Stock Price Index: London Financial Times All Share (Apr-10-62=100) | G3: Stock Price Index: Argentina: Buenos Aires General (Jun-30-00=19570.98) | H3: Australia: Share Price Index: S&P/ASX 200(Dec-31-79=500) | I3: Austria: Stock Price Index: Traded Index (Jan-2-91=1000) | J3: Belgium: Stock Price Index: Bel-20 Index (Jan-1-91=1000) | K3: Brazil: Equity Index: IBovespa [Total Return] (Jan-2-68=0.0000000001) | L3: Bulgaria: Stock Price Index: SOFIX (Oct-20-00=100) | M3: S&P/TSX Composite Index, Close Price (Index) | N3: Stock Price Index: Chile: IGPA General (Dec-31-80=100) | O3: China: Shanghai Stock Price SSE Index (Dec-19-90=100) | P3: Croatia: Stock Price Index: CROBEX (Jul-1-97=1000) | Q3: Czechia: Stock Price Index: PX50 (Apr-4-94=1000) | R3: Denmark: Stock Price Index: OMX Copenhagen C20 (Jul-3-89=100) | S3: Finland: Stock Price Index: OMX Helsinki General (Dec-28-90=100) | T3: France: Stock Price Index: Paris CAC 40 (Dec-31-87=1000) | U3: Germany: Stock Market Indexes: DAX Price Index (Dec-30-87=1000) | V3: Greece: Stock Price Index: Athens, SE (Dec-31-80=100) | W3: Hong Kong: Stock Price Index: Hang Seng (Jul-31-64=100) | X3: Stock Price Index: Hungary: BUX (Jan-2-91=1000) | Y3: India: Stock Price Index: BSE: Sensitive [Sensex] (1978-79=100) | Z3: Indonesia: Stock Price Index: Jakarta Composite (Aug-10-82=100) | AA3: Stock Price Index: Ireland: ISEQ Overall (Jan-4-88=1000) | AB3: Italy: Stock Price Index: FTSE MIB (Dec-31-97=24401.54) | AC3: Kenya: NSE 20-Share Index (1966=100) | AD3: Malaysia: Stock Price Index: FTSE Bursa Malaysia KLCI (Jan-1-77=100) | AE3: Mexico: Stock Price Index: IPC (Nov-78=0.78) | AF3: Netherlands: Stock Price Index: Amsterdam ANP-CBS General (Dec-31-52=13.20) | AG3: New Zealand: Stock Price Index: NZX 50 Price Index (Mar-03-03=1880.85) | AH3: Nigeria: Stock Price Index: All Share Index (Jan-3-84=100) | AI3: Norway: Stock Price Index: Oslo OSE All Share Index (Dec-29-95=100) | AJ3: Philippines: Stock Price Index: Manila Composite (Jan-2-85=100) | AK3: Poland: Stock Price Index: WIG (Apr-16-91=1000) | AL3: Portugal: Stock Price Index: PSI-20 (Dec-31-92=3000) | AM3: Romania: Stock Price Index: BET (Sep-19-97=1000) | AN3: Russia: MOEX Russia Index: Closing Value (Sep-22-97=100) | AO3: Singapore: Stock Price Index: Straits Times (Jan-09-08=3344.53) | AP3: Slovakia: Stock Price Index: SAX (Sep-14-93=100) | AQ3: South Africa: Stock Price Index: FTSE/JSE All Share Index (Jun-21-02=10815.08) | AR3: Korea: Stock Price Index: KOSPI (Jan-4-80=100) | AS3: Spain: Stock Price Index: Madrid General Index (Dec-30-85=100) | AT3: Sweden: Stock Price Index: Stockholm Affarsvarlden (Dec-29-95=100) | AU3: Taiwan Stock Exchange Capitalization Weighted Index (1966=100) | AV3: Tanzania: All Shares Index (Dec-15-06=1000) | AW3: Thailand: Stock Price Index: Bangkok SET (Apr-30-75=100) | AX3: Turkey: BIST 100 Stock Price Index (Jan-01-86=.01) | AY3: Venezuela: Stock Price Index: Bursatil Index (Dec-31-93=0.000000001) | AZ3: Dow Jones Global Index: World (Avg, Dec-31-91=100)
B4: .T1 | C4: 02-Jan-1953 | D4: 04-Jan-1989 | E4: 31-Dec-1986 | F4: 01-Jan-1990 | G4: 02-Jan-1991 | H4: 17-Oct-2001 | I4: 07-Jan-1986 | J4: 08-Apr-1991 | K4: 03-Jan-1994 | L4: 23-Oct-2000 | M4: 03-Jan-1977 | N4: 02-Jan-1990 | O4: 20-Dec-1990 | P4: 02-Sep-1997 | Q4: 07-Sep-1993 | R4: 04-Dec-1989 | S4: 02-Jan-1995 | T4: 31-Dec-1987 | U4: 04-Jan-1999 | V4: 02-Jan-1995 | W4: 24-Nov-1969 | X4: 02-Jan-1991 | Y4: 03-Apr-1979 | Z4: 02-Jan-1995 | AA4: 03-Jan-1995 | AB4: 31-Dec-1997 | AC4: 13-Feb-2008 | AD4: 03-Jan-1995 | AE4: 30-Oct-1978 | AF4: 03-Oct-1988 | AG4: 03-Jan-2003 | AH4: 04-Sep-1997 | AI4: 29-Dec-1995 | AJ4: 02-Jan-1996 | AK4: 16-Apr-1991 | AL4: 31-Dec-1992 | AM4: 19-Sep-1997 | AN4: 22-Sep-1997 | AO4: 02-Jan-1975 | AP4: 04-Sep-1997 | AQ4: 21-Jun-2002 | AR4: 06-Jan-1975 | AS4: 02-Jan-1985 | AT4: 02-Jan-1987 | AU4: 05-Jan-1994 | AV4: 16-May-2013 | AW4: 03-Jan-1995 | AX4: 07-Feb-1986 | AY4: 12-Jun-2017 | AZ4: 31-Dec-1991
B5: .TN | C5: 08-Aug-2024 | D5: 08-Aug-2024 | E5: 08-Aug-2024 | F5: 08-Aug-2024 | G5: 08-Aug-2024 | H5: 08-Aug-2024 | I5: 08-Aug-2024 | J5: 08-Aug-2024 | K5: 08-Aug-2024 | L5: 08-Aug-2024 | M5: 08-Aug-2024 | N5: 08-Aug-2024 | O5: 08-Aug-2024 | P5: 08-Aug-2024 | Q5: 08-Aug-2024 | R5: 08-Aug-2024 | S5: 08-Aug-2024 | T5: 08-Aug-2024 | U5: 08-Aug-2024 | V5: 08-Aug-2024 | W5: 08-Aug-2024 | X5: 08-Aug-2024 | Y5: 08-Aug-2024 | Z5: 08-Aug-2024 | AA5: 08-Aug-2024 | AB5: 08-Aug-2024 | AC5: 08-Aug-2024 | AD5: 08-Aug-2024 | AE5: 08-Aug-2024 | AF5: 08-Aug-2024 | AG5: 08-Aug-2024 | AH5: 08-Aug-2024 | AI5: 08-Aug-2024 | AJ5: 08-Aug-2024 | AK5: 08-Aug-2024 | AL5: 08-Aug-2024 | AM5: 08-Aug-2024 | AN5: 08-Aug-2024 | AO5: 08-Aug-2024 | AP5: 08-Aug-2024 | AQ5: 08-Aug-2024 | AR5: 08-Aug-2024 | AS5: 08-Aug-2024 | AT5: 08-Aug-2024 | AU5: 08-Aug-2024 | AV5: 07-Aug-2024 | AW5: 08-Aug-2024 | AX5: 08-Aug-2024 | AY5: 08-Aug-2024 | AZ5: 08-Aug-2024
B6: .LSOURCE | C6: Standard & Poor's | D6: Financial Times | E6: STOXX Limited | F6: Financial Times | G6: Financial Times | H6: Standard & Poor's | I6: Wall Street Journal | J6: Financial Times | K6: Financial Times | L6: Bulgarian Stock Exchange | M6: Toronto Stock Exchange | N6: Financial Times | O6: Shanghai Stock Exchange | P6: Zagreb Stock Exchange | Q6: Financial Times | R6: OMX Nordic Exchange | S6: OMX Nordic Exchange | T6: Financial Times | U6: Deutsche Bourse | V6: Financial Times | W6: Hang Seng Indexes Company | X6: Financial Times | Y6: Bombay Stock Exchange | Z6: Financial Times | AA6: Wall Street Journal | AB6: Borsa Italiana | AC6: Nairobi Stock Exchange | AD6: Financial Times | AE6: Wall Street Journal | AF6: Financial Times | AG6: Standard & Poor's | AH6: Financial Times | AI6: Oslo Bors ASA | AJ6: Financial Times | AK6: Warsaw Stock Exchange | AL6: Financial Times | AM6: Bucharest Stock Exchange | AN6: Moscow Exchange | AO6: Financial Times | AP6: Financial Times | AQ6: Financial Times | AR6: Korea Stock Exchange | AS6: Bolsa de Madrid | AT6: OMX Nordic Exchange | AU6: Taiwan Stock Exchange | AV6: Dar Es Salaam Stock Exchange | AW6: Financial Times | AX6: Central Bank of the Republic of Turkey | AY6: Wall Street Journal | AZ6: Dow Jones
B7: .DTLM | C7: Aug-08-2024 21:40 | D7: Aug-08-2024 09:04 | E7: Aug-08-2024 18:52 | F7: Aug-08-2024 17:06 | G7: Aug-08-2024 23:08 | H7: Aug-08-2024 09:46 | I7: Aug-08-2024 17:10 | J7: Aug-08-2024 17:10 | K7: Aug-08-2024 22:46 | L7: Aug-08-2024 15:23 | M7: Aug-09-2024 02:22 | N7: Aug-08-2024 23:08 | O7: Aug-08-2024 11:21 | P7: Aug-08-2024 16:01 | Q7: Aug-08-2024 16:17 | R7: Aug-08-2024 16:54 | S7: Aug-08-2024 16:54 | T7: Aug-08-2024 17:10 | U7: Aug-08-2024 17:17 | V7: Aug-08-2024 15:35 | W7: Aug-08-2024 11:15 | X7: Aug-08-2024 17:22 | Y7: Aug-08-2024 11:56 | Z7: Aug-08-2024 13:00 | AA7: Aug-08-2024 23:08 | AB7: Aug-08-2024 17:04 | AC7: Aug-08-2024 16:30 | AD7: Aug-08-2024 11:05 | AE7: Aug-08-2024 22:01 | AF7: Aug-08-2024 17:10 | AG7: Aug-08-2024 09:46 | AH7: Aug-08-2024 18:30 | AI7: Aug-08-2024 17:04 | AJ7: Aug-08-2024 11:05 | AK7: Aug-08-2024 17:53 | AL7: Aug-08-2024 17:10 | AM7: Aug-08-2024 16:43 | AN7: Aug-08-2024 17:30 | AO7: Aug-08-2024 11:05 | AP7: Aug-08-2024 16:45 | AQ7: Aug-08-2024 17:30 | AR7: Aug-08-2024 10:11 | AS7: Aug-08-2024 17:04 | AT7: Aug-08-2024 16:54 | AU7: Aug-08-2024 10:05 | AV7: Aug-07-2024 16:01 | AW7: Aug-08-2024 11:05 | AX7: Aug-08-2024 16:31 | AY7: Aug-08-2024 23:08 | AZ7: Aug-09-2024 05:09
