Workbook
Name _DLX1.INC: HAVERD!$G$3:$BV$8
Name _DLX2.INC: HAVERM!$B$1:$F$6
Name _DLX3.INC: 'Haver Q'!$A$4:$G$9

Sheet Chart Data
B1: November MPR | D1: 15 working days to 28 Oct 2024
B2: Column # | C2: =HAVERD!I1 -> 9 | D2: =HAVERD!J1 -> 10 | E2: =HAVERD!K1 -> 11 | F2: =HAVERD!L1 -> 12 | G2: =HAVERD!M1 -> 13 | H2: =HAVERD!N1 -> 14 | I2: =HAVERD!O1 -> 15 | J2: =HAVERD!P1 -> 16 | ... AY2: =HAVERD!BE1 -> 57
B3: Months | C3: =HAVERD!I2 -> Overnight | D3: =HAVERD!J2 -> 1 | E3: =HAVERD!K2 -> 2 | F3: =HAVERD!L2 -> 3 | G3: =HAVERD!M2 -> 4 | H3: =HAVERD!N2 -> 5 | I3: =HAVERD!O2 -> 6 | J3: =HAVERD!P2 -> 7 | ... AY3: =HAVERD!BE2 -> 48
B4: Days | D4: 30.416667 | E4: =+D4+30.4166667 -> 60.833333 | F4: =+E4+30.4166667 -> 91.25 | G4: =+F4+30.4166667 -> 121.66667 | H4: =+G4+30.4166667 -> 152.08333 | I4: =+H4+30.4166667 -> 182.5 | J4: =+I4+30.4166667 -> 212.91667 | K4: =+J4+30.4166667 -> 243.33333 | L4: =+K4+30.4166667 -> 273.75 | ... AY4: =+AX4+30.4166667 -> 1460
B5: Dates
B6: =B11-7 -> 45574 | C6: =B6 -> 45574 | D6: =$C6+D$4 -> 45604.417 | E6: =$C6+E$4 -> 45634.833 | F6: =$C6+F$4 -> 45665.25 | G6: =$C6+G$4 -> 45695.667 | H6: =$C6+H$4 -> 45726.083 | I6: =$C6+I$4 -> 45756.5 | J6: =$C6+J$4 -> 45786.917 | K6: =$C6+K$4 -> 45817.333 | ... AY6: =$C6+AY$4 -> 47034
B7: =B12-7 -> 45575 | C7: =B7 -> 45575 | D7: =$C7+D$4 -> 45605.417 | E7: =$C7+E$4 -> 45635.833 | F7: =$C7+F$4 -> 45666.25 | G7: =$C7+G$4 -> 45696.667 | H7: =$C7+H$4 -> 45727.083 | I7: =$C7+I$4 -> 45757.5 | J7: =$C7+J$4 -> 45787.917 | K7: =$C7+K$4 -> 45818.333 | ... AY7: =$C7+AY$4 -> 47035
B8: =B13-7 -> 45576 | C8: =B8 -> 45576 | D8: =$C8+D$4 -> 45606.417 | E8: =$C8+E$4 -> 45636.833 | F8: =$C8+F$4 -> 45667.25 | G8: =$C8+G$4 -> 45697.667 | H8: =$C8+H$4 -> 45728.083 | I8: =$C8+I$4 -> 45758.5 | J8: =$C8+J$4 -> 45788.917 | K8: =$C8+K$4 -> 45819.333 | ... AY8: =$C8+AY$4 -> 47036
B9: =B14-7 -> 45579 | C9: =B9 -> 45579 | D9: =$C9+D$4 -> 45609.417 | E9: =$C9+E$4 -> 45639.833 | F9: =$C9+F$4 -> 45670.25 | G9: =$C9+G$4 -> 45700.667 | H9: =$C9+H$4 -> 45731.083 | I9: =$C9+I$4 -> 45761.5 | J9: =$C9+J$4 -> 45791.917 | K9: =$C9+K$4 -> 45822.333 | ... AY9: =$C9+AY$4 -> 47039
B10: =B15-7 -> 45580 | C10: =B10 -> 45580 | D10: =$C10+D$4 -> 45610.417 | E10: =$C10+E$4 -> 45640.833 | F10: =$C10+F$4 -> 45671.25 | G10: =$C10+G$4 -> 45701.667 | H10: =$C10+H$4 -> 45732.083 | I10: =$C10+I$4 -> 45762.5 | J10: =$C10+J$4 -> 45792.917 | K10: =$C10+K$4 -> 45823.333 | ... AY10: =$C10+AY$4 -> 47040
B11: =B16-7 -> 45581 | C11: =B11 -> 45581 | D11: =$C11+D$4 -> 45611.417 | E11: =$C11+E$4 -> 45641.833 | F11: =$C11+F$4 -> 45672.25 | G11: =$C11+G$4 -> 45702.667 | H11: =$C11+H$4 -> 45733.083 | I11: =$C11+I$4 -> 45763.5 | J11: =$C11+J$4 -> 45793.917 | K11: =$C11+K$4 -> 45824.333 | ... AY11: =$C11+AY$4 -> 47041
B12: =B17-7 -> 45582 | C12: =B12 -> 45582 | D12: =$C12+D$4 -> 45612.417 | E12: =$C12+E$4 -> 45642.833 | F12: =$C12+F$4 -> 45673.25 | G12: =$C12+G$4 -> 45703.667 | H12: =$C12+H$4 -> 45734.083 | I12: =$C12+I$4 -> 45764.5 | J12: =$C12+J$4 -> 45794.917 | K12: =$C12+K$4 -> 45825.333 | ... AY12: =$C12+AY$4 -> 47042
B13: =B18-7 -> 45583 | C13: =B13 -> 45583 | D13: =$C13+D$4 -> 45613.417 | E13: =$C13+E$4 -> 45643.833 | F13: =$C13+F$4 -> 45674.25 | G13: =$C13+G$4 -> 45704.667 | H13: =$C13+H$4 -> 45735.083 | I13: =$C13+I$4 -> 45765.5 | J13: =$C13+J$4 -> 45795.917 | K13: =$C13+K$4 -> 45826.333 | ... AY13: =$C13+AY$4 -> 47043
B14: =B19-7 -> 45586 | C14: =B14 -> 45586 | D14: =$C14+D$4 -> 45616.417 | E14: =$C14+E$4 -> 45646.833 | F14: =$C14+F$4 -> 45677.25 | G14: =$C14+G$4 -> 45707.667 | H14: =$C14+H$4 -> 45738.083 | I14: =$C14+I$4 -> 45768.5 | J14: =$C14+J$4 -> 45798.917 | K14: =$C14+K$4 -> 45829.333 | ... AY14: =$C14+AY$4 -> 47046
B15: =B20-7 -> 45587 | C15: =B15 -> 45587 | D15: =$C15+D$4 -> 45617.417 | E15: =$C15+E$4 -> 45647.833 | F15: =$C15+F$4 -> 45678.25 | G15: =$C15+G$4 -> 45708.667 | H15: =$C15+H$4 -> 45739.083 | I15: =$C15+I$4 -> 45769.5 | J15: =$C15+J$4 -> 45799.917 | K15: =$C15+K$4 -> 45830.333 | ... AY15: =$C15+AY$4 -> 47047
A16: =TEXT(B16,"dddd") -> Wednesday | B16: =IF(A17="Monday",B17-3,B17-1) -> 45588 | C16: =B16 -> 45588 | D16: =$C16+D$4 -> 45618.417 | E16: =$C16+E$4 -> 45648.833 | F16: =$C16+F$4 -> 45679.25 | G16: =$C16+G$4 -> 45709.667 | H16: =$C16+H$4 -> 45740.083 | I16: =$C16+I$4 -> 45770.5 | J16: =$C16+J$4 -> 45800.917 | K16: =$C16+K$4 -> 45831.333 | ... AY16: =$C16+AY$4 -> 47048
A17: =TEXT(B17,"dddd") -> Thursday | B17: =IF(A18="Monday",B18-3,B18-1) -> 45589 | C17: =B17 -> 45589 | D17: =$C17+D$4 -> 45619.417 | E17: =$C17+E$4 -> 45649.833 | F17: =$C17+F$4 -> 45680.25 | G17: =$C17+G$4 -> 45710.667 | H17: =$C17+H$4 -> 45741.083 | I17: =$C17+I$4 -> 45771.5 | J17: =$C17+J$4 -> 45801.917 | K17: =$C17+K$4 -> 45832.333 | ... AY17: =$C17+AY$4 -> 47049
A18: =TEXT(B18,"dddd") -> Friday | B18: =IF(A19="Monday",B19-3,B19-1) -> 45590 | C18: =B18 -> 45590 | D18: =$C18+D$4 -> 45620.417 | E18: =$C18+E$4 -> 45650.833 | F18: =$C18+F$4 -> 45681.25 | G18: =$C18+G$4 -> 45711.667 | H18: =$C18+H$4 -> 45742.083 | I18: =$C18+I$4 -> 45772.5 | J18: =$C18+J$4 -> 45802.917 | K18: =$C18+K$4 -> 45833.333 | ... AY18: =$C18+AY$4 -> 47050
A19: =TEXT(B19,"dddd") -> Monday | B19: =IF(A20="Monday",B20-3,B20-1) -> 45593 | C19: =B19 -> 45593 | D19: =$C19+D$4 -> 45623.417 | E19: =$C19+E$4 -> 45653.833 | F19: =$C19+F$4 -> 45684.25 | G19: =$C19+G$4 -> 45714.667 | H19: =$C19+H$4 -> 45745.083 | I19: =$C19+I$4 -> 45775.5 | J19: =$C19+J$4 -> 45805.917 | K19: =$C19+K$4 -> 45836.333 | ... AY19: =$C19+AY$4 -> 47053
A20: =TEXT(B20,"dddd") -> Tuesday | B20: 45594 | C20: =B20 -> 45594 | D20: =$C20+D$4 -> 45624.417 | E20: =$C20+E$4 -> 45654.833 | F20: =$C20+F$4 -> 45685.25 | G20: =$C20+G$4 -> 45715.667 | H20: =$C20+H$4 -> 45746.083 | I20: =$C20+I$4 -> 45776.5 | J20: =$C20+J$4 -> 45806.917 | K20: =$C20+K$4 -> 45837.333 | ... AY20: =$C20+AY$4 -> 47054
B22: Market expectations
B23: =B6 -> 45574 | C23: =VLOOKUP($B23,HAVERD!$A:$BS,C$2,FALSE) -> 4.95 | D23: =VLOOKUP($B23,HAVERD!$A:$BS,D$2,FALSE) -> 4.8392344 | E23: =VLOOKUP($B23,HAVERD!$A:$BS,E$2,FALSE) -> 4.6898294 | F23: =VLOOKUP($B23,HAVERD!$A:$BS,F$2,FALSE) -> 4.5714834 | G23: =VLOOKUP($B23,HAVERD!$A:$BS,G$2,FALSE) -> 4.4638079 | H23: =VLOOKUP($B23,HAVERD!$A:$BS,H$2,FALSE) -> 4.3570305 | I23: =VLOOKUP($B23,HAVERD!$A:$BS,I$2,FALSE) -> 4.253062 | J23: =VLOOKUP($B23,HAVERD!$A:$BS,J$2,FALSE) -> 4.1565231 | ... AY23: =VLOOKUP($B23,HAVERD!$A:$BS,AY$2,FALSE) -> 3.5754092
B24: =B7 -> 45575 | C24: =VLOOKUP($B24,HAVERD!$A:$BS,C$2,FALSE) -> 4.95 | D24: =VLOOKUP($B24,HAVERD!$A:$BS,D$2,FALSE) -> 4.8360175 | E24: =VLOOKUP($B24,HAVERD!$A:$BS,E$2,FALSE) -> 4.6861475 | F24: =VLOOKUP($B24,HAVERD!$A:$BS,F$2,FALSE) -> 4.5642992 | G24: =VLOOKUP($B24,HAVERD!$A:$BS,G$2,FALSE) -> 4.4507986 | H24: =VLOOKUP($B24,HAVERD!$A:$BS,H$2,FALSE) -> 4.3378835 | I24: =VLOOKUP($B24,HAVERD!$A:$BS,I$2,FALSE) -> 4.2286761 | J24: =VLOOKUP($B24,HAVERD!$A:$BS,J$2,FALSE) -> 4.1278571 | ... AY24: =VLOOKUP($B24,HAVERD!$A:$BS,AY$2,FALSE) -> 3.6084418
B25: =B8 -> 45576 | C25: =VLOOKUP($B25,HAVERD!$A:$BS,C$2,FALSE) -> 4.95 | D25: =VLOOKUP($B25,HAVERD!$A:$BS,D$2,FALSE) -> 4.830099 | E25: =VLOOKUP($B25,HAVERD!$A:$BS,E$2,FALSE) -> 4.6749844 | F25: =VLOOKUP($B25,HAVERD!$A:$BS,F$2,FALSE) -> 4.5457742 | G25: =VLOOKUP($B25,HAVERD!$A:$BS,G$2,FALSE) -> 4.423792 | H25: =VLOOKUP($B25,HAVERD!$A:$BS,H$2,FALSE) -> 4.3019174 | I25: =VLOOKUP($B25,HAVERD!$A:$BS,I$2,FALSE) -> 4.1846934 | J25: =VLOOKUP($B25,HAVERD!$A:$BS,J$2,FALSE) -> 4.0786496 | ... AY25: =VLOOKUP($B25,HAVERD!$A:$BS,AY$2,FALSE) -> 3.6001446
B26: =B9 -> 45579 | C26: =VLOOKUP($B26,HAVERD!$A:$BS,C$2,FALSE) -> 4.95 | D26: =VLOOKUP($B26,HAVERD!$A:$BS,D$2,FALSE) -> 4.8075783 | E26: =VLOOKUP($B26,HAVERD!$A:$BS,E$2,FALSE) -> 4.6717311 | F26: =VLOOKUP($B26,HAVERD!$A:$BS,F$2,FALSE) -> 4.5557245 | G26: =VLOOKUP($B26,HAVERD!$A:$BS,G$2,FALSE) -> 4.4414894 | H26: =VLOOKUP($B26,HAVERD!$A:$BS,H$2,FALSE) -> 4.3232448 | I26: =VLOOKUP($B26,HAVERD!$A:$BS,I$2,FALSE) -> 4.2068587 | J26: =VLOOKUP($B26,HAVERD!$A:$BS,J$2,FALSE) -> 4.0999515 | ... AY26: =VLOOKUP($B26,HAVERD!$A:$BS,AY$2,FALSE) -> 3.6176902
B27: =B10 -> 45580 | C27: =VLOOKUP($B27,HAVERD!$A:$BS,C$2,FALSE) -> 4.95 | D27: =VLOOKUP($B27,HAVERD!$A:$BS,D$2,FALSE) -> 4.8042216 | E27: =VLOOKUP($B27,HAVERD!$A:$BS,E$2,FALSE) -> 4.6688134 | F27: =VLOOKUP($B27,HAVERD!$A:$BS,F$2,FALSE) -> 4.5480962 | G27: =VLOOKUP($B27,HAVERD!$A:$BS,G$2,FALSE) -> 4.4272003 | H27: =VLOOKUP($B27,HAVERD!$A:$BS,H$2,FALSE) -> 4.3027498 | I27: =VLOOKUP($B27,HAVERD!$A:$BS,I$2,FALSE) -> 4.181326 | J27: =VLOOKUP($B27,HAVERD!$A:$BS,J$2,FALSE) -> 4.0705947 | ... AY27: =VLOOKUP($B27,HAVERD!$A:$BS,AY$2,FALSE) -> 3.549409
B28: =B11 -> 45581 | C28: =VLOOKUP($B28,HAVERD!$A:$BS,C$2,FALSE) -> 4.95 | D28: =VLOOKUP($B28,HAVERD!$A:$BS,D$2,FALSE) -> 4.7700832 | E28: =VLOOKUP($B28,HAVERD!$A:$BS,E$2,FALSE) -> 4.618622 | F28: =VLOOKUP($B28,HAVERD!$A:$BS,F$2,FALSE) -> 4.4825589 | G28: =VLOOKUP($B28,HAVERD!$A:$BS,G$2,FALSE) -> 4.3493559 | H28: =VLOOKUP($B28,HAVERD!$A:$BS,H$2,FALSE) -> 4.2159912 | I28: =VLOOKUP($B28,HAVERD!$A:$BS,I$2,FALSE) -> 4.0880923 | J28: =VLOOKUP($B28,HAVERD!$A:$BS,J$2,FALSE) -> 3.9724897 | ... AY28: =VLOOKUP($B28,HAVERD!$A:$BS,AY$2,FALSE) -> 3.4714759
B29: =B12 -> 45582 | C29: =VLOOKUP($B29,HAVERD!$A:$BS,C$2,FALSE) -> 4.95 | D29: =VLOOKUP($B29,HAVERD!$A:$BS,D$2,FALSE) -> 4.7696391 | E29: =VLOOKUP($B29,HAVERD!$A:$BS,E$2,FALSE) -> 4.6221703 | F29: =VLOOKUP($B29,HAVERD!$A:$BS,F$2,FALSE) -> 4.4867502 | G29: =VLOOKUP($B29,HAVERD!$A:$BS,G$2,FALSE) -> 4.3528363 | H29: =VLOOKUP($B29,HAVERD!$A:$BS,H$2,FALSE) -> 4.2186078 | I29: =VLOOKUP($B29,HAVERD!$A:$BS,I$2,FALSE) -> 4.0901854 | J29: =VLOOKUP($B29,HAVERD!$A:$BS,J$2,FALSE) -> 3.9742385 | ... AY29: =VLOOKUP($B29,HAVERD!$A:$BS,AY$2,FALSE) -> 3.4871615
B30: =B13 -> 45583 | C30: =VLOOKUP($B30,HAVERD!$A:$BS,C$2,FALSE) -> 4.95 | D30: =VLOOKUP($B30,HAVERD!$A:$BS,D$2,FALSE) -> 4.7565408 | E30: =VLOOKUP($B30,HAVERD!$A:$BS,E$2,FALSE) -> 4.6112876 | F30: =VLOOKUP($B30,HAVERD!$A:$BS,F$2,FALSE) -> 4.4736636 | G30: =VLOOKUP($B30,HAVERD!$A:$BS,G$2,FALSE) -> 4.3371063 | H30: =VLOOKUP($B30,HAVERD!$A:$BS,H$2,FALSE) -> 4.2003865 | I30: =VLOOKUP($B30,HAVERD!$A:$BS,I$2,FALSE) -> 4.0688589 | J30: =VLOOKUP($B30,HAVERD!$A:$BS,J$2,FALSE) -> 3.9476923 | ... AY30: =VLOOKUP($B30,HAVERD!$A:$BS,AY$2,FALSE) -> 3.4528242
B31: =B14 -> 45586 | C31: =VLOOKUP($B31,HAVERD!$A:$BS,C$2,FALSE) -> 4.95 | D31: =VLOOKUP($B31,HAVERD!$A:$BS,D$2,FALSE) -> 4.7245473 | E31: =VLOOKUP($B31,HAVERD!$A:$BS,E$2,FALSE) -> 4.6069933 | F31: =VLOOKUP($B31,HAVERD!$A:$BS,F$2,FALSE) -> 4.4780541 | G31: =VLOOKUP($B31,HAVERD!$A:$BS,G$2,FALSE) -> 4.3408241 | H31: =VLOOKUP($B31,HAVERD!$A:$BS,H$2,FALSE) -> 4.202394 | I31: =VLOOKUP($B31,HAVERD!$A:$BS,I$2,FALSE) -> 4.0715595 | J31: =VLOOKUP($B31,HAVERD!$A:$BS,J$2,FALSE) -> 3.9552244 | ... AY31: =VLOOKUP($B31,HAVERD!$A:$BS,AY$2,FALSE) -> 3.5231036
B32: =B15 -> 45587 | C32: =VLOOKUP($B32,HAVERD!$A:$BS,C$2,FALSE) -> 4.95 | D32: =VLOOKUP($B32,HAVERD!$A:$BS,D$2,FALSE) -> 4.7159403 | E32: =VLOOKUP($B32,HAVERD!$A:$BS,E$2,FALSE) -> 4.605852 | F32: =VLOOKUP($B32,HAVERD!$A:$BS,F$2,FALSE) -> 4.4784973 | G32: =VLOOKUP($B32,HAVERD!$A:$BS,G$2,FALSE) -> 4.3411959 | H32: =VLOOKUP($B32,HAVERD!$A:$BS,H$2,FALSE) -> 4.2037503 | I32: =VLOOKUP($B32,HAVERD!$A:$BS,I$2,FALSE) -> 4.0749352 | J32: =VLOOKUP($B32,HAVERD!$A:$BS,J$2,FALSE) -> 3.9618383 | ... AY32: =VLOOKUP($B32,HAVERD!$A:$BS,AY$2,FALSE) -> 3.5491538
B33: =B16 -> 45588 | C33: =VLOOKUP($B33,HAVERD!$A:$BS,C$2,FALSE) -> 4.95 | D33: =VLOOKUP($B33,HAVERD!$A:$BS,D$2,FALSE) -> 4.7066383 | E33: =VLOOKUP($B33,HAVERD!$A:$BS,E$2,FALSE) -> 4.6034616 | F33: =VLOOKUP($B33,HAVERD!$A:$BS,F$2,FALSE) -> 4.476719 | G33: =VLOOKUP($B33,HAVERD!$A:$BS,G$2,FALSE) -> 4.3384223 | H33: =VLOOKUP($B33,HAVERD!$A:$BS,H$2,FALSE) -> 4.2008419 | I33: =VLOOKUP($B33,HAVERD!$A:$BS,I$2,FALSE) -> 4.0734887 | J33: =VLOOKUP($B33,HAVERD!$A:$BS,J$2,FALSE) -> 3.9631634 | ... AY33: =VLOOKUP($B33,HAVERD!$A:$BS,AY$2,FALSE) -> 3.6087754
B34: =B17 -> 45589 | C34: =VLOOKUP($B34,HAVERD!$A:$BS,C$2,FALSE) -> 4.95 | D34: =VLOOKUP($B34,HAVERD!$A:$BS,D$2,FALSE) -> 4.7055673 | E34: =VLOOKUP($B34,HAVERD!$A:$BS,E$2,FALSE) -> 4.6146926 | F34: =VLOOKUP($B34,HAVERD!$A:$BS,F$2,FALSE) -> 4.4929688 | G34: =VLOOKUP($B34,HAVERD!$A:$BS,G$2,FALSE) -> 4.3555884 | H34: =VLOOKUP($B34,HAVERD!$A:$BS,H$2,FALSE) -> 4.2185595 | I34: =VLOOKUP($B34,HAVERD!$A:$BS,I$2,FALSE) -> 4.093252 | J34: =VLOOKUP($B34,HAVERD!$A:$BS,J$2,FALSE) -> 3.9865325 | ... AY34: =VLOOKUP($B34,HAVERD!$A:$BS,AY$2,FALSE) -> 3.6223193
... B37: =B20 -> 45594 | C37: =VLOOKUP($B37,HAVERD!$A:$BS,C$2,FALSE) -> 4.95 | D37: =VLOOKUP($B37,HAVERD!$A:$BS,D$2,FALSE) -> 4.7010619 | E37: =VLOOKUP($B37,HAVERD!$A:$BS,E$2,FALSE) -> 4.6042869 | F37: =VLOOKUP($B37,HAVERD!$A:$BS,F$2,FALSE) -> 4.484879 | G37: =VLOOKUP($B37,HAVERD!$A:$BS,G$2,FALSE) -> 4.3523008 | H37: =VLOOKUP($B37,HAVERD!$A:$BS,H$2,FALSE) -> 4.2233455 | I37: =VLOOKUP($B37,HAVERD!$A:$BS,I$2,FALSE) -> 4.1088538 | J37: =VLOOKUP($B37,HAVERD!$A:$BS,J$2,FALSE) -> 4.014894 | ... AY37: =VLOOKUP($B37,HAVERD!$A:$BS,AY$2,FALSE) -> 3.7143726
C39: 45566 | D39: 45597 | E39: 45627 | F39: 45658 | G39: 45689 | H39: 45717 | I39: 45748 | J39: 45778 | K39: 45809 | L39: 45839 | M39: 45870 | N39: 45901 | O39: 45931 | P39: 45962 | Q39: 45992 | R39: 46023 | S39: 46054 | T39: 46082 | U39: 46113 | V39: 46143 | W39: 46174 | X39: 46204 | Y39: 46235 | Z39: 46266 | AA39: 46296 | AB39: 46327 | AC39: 46357 | AD39: 46388 | AE39: 46419 | AF39: 46447 | AG39: 46478 | AH39: 46508 | AI39: 46539 | AJ39: 46569 | AK39: 46600 | AL39: 46631 | AM39: 46661 | AN39: 46692 | AO39: 46722 | AP39: 46753 | AQ39: 46784 | AR39: 46813 | AS39: 46844 | AT39: 46874 | AU39: 46905 | AV39: 46935 | AW39: 46966 | AX39: 46997 | AY39: 47027 | AZ39: 47058 | BA39: 47088
B40: November MPR | C40: =AVERAGE(C23:C37) -> 4.95 | D40: =AVERAGE(D23:D37) -> 4.7578202 | E40: =AVERAGE(E23:E37) -> 4.6327906 | F40: =AVERAGE(F23:F37) -> 4.5073895 | G40: =AVERAGE(G23:G37) -> 4.3782999 | H40: =AVERAGE(H23:H37) -> 4.2492232 | I40: =AVERAGE(I23:I37) -> 4.1275689 | J40: =AVERAGE(J23:J37) -> 4.0197837 | ... BA40: =AVERAGE(BA23:BA37) -> #DIV/0!
A41: 45601 | B41: 6th November | C41: =VLOOKUP($A41,HAVERD!$A:$BS,C$2,FALSE) -> 4.95 | D41: =VLOOKUP($A41,HAVERD!$A:$BS,D$2,FALSE) -> 4.705506 | E41: =VLOOKUP($A41,HAVERD!$A:$BS,E$2,FALSE) -> 4.635297 | F41: =VLOOKUP($A41,HAVERD!$A:$BS,F$2,FALSE) -> 4.5488242 | G41: =VLOOKUP($A41,HAVERD!$A:$BS,G$2,FALSE) -> 4.4563583 | H41: =VLOOKUP($A41,HAVERD!$A:$BS,H$2,FALSE) -> 4.3713069 | I41: =VLOOKUP($A41,HAVERD!$A:$BS,I$2,FALSE) -> 4.2991426 | J41: =VLOOKUP($A41,HAVERD!$A:$BS,J$2,FALSE) -> 4.242551 | ... BA41: =VLOOKUP($A41,HAVERD!$A:$BS,BA$2,FALSE) -> #VALUE!
B42: Difference | C42: =C41-C40 -> 0 | D42: =D41-D40 -> -0.052314153 | E42: =E41-E40 -> 0.00250642 | F42: =F41-F40 -> 0.0414347 | G42: =G41-G40 -> 0.07805844 | H42: =H41-H40 -> 0.12208371 | I42: =I41-I40 -> 0.17157372 | J42: =J41-J40 -> 0.22276731 | ... BA42: =BA41-BA40 -> #VALUE!
B44: Chart data
C45: 44562 | D45: 44593 | E45: 44621 | F45: 44652 | G45: 44682 | H45: 44713 | I45: 44743 | J45: 44774 | K45: 44805 | L45: 44835 | M45: 44866 | N45: 44896 | O45: 44927 | P45: 44958 | Q45: 44986 | R45: 45017 | S45: 45047 | T45: 45078 | U45: 45108 | V45: 45139 | W45: 45170 | X45: 45200 | Y45: 45231 | Z45: 45261 | AA45: 45292 | AB45: 45323 | AC45: 45352 | AD45: 45383 | AE45: 45413 | AF45: 45444 | AG45: 45474 | AH45: 45505 | AI45: 45536 | AJ45: 45566 | AK45: 45597 | AL45: 45627 | AM45: 45658 | AN45: 45689 | AO45: 45717 | AP45: 45748 | AQ45: 45778 | AR45: 45809 | AS45: 45839 | AT45: 45870 | AU45: 45901 | AV45: 45931 | AW45: 45962 | AX45: 45992 | AY45: 46023 | AZ45: 46054 | BA45: 46082 | BB45: 46113 | BC45: 46143 | BD45: 46174 | BE45: 46204 | BF45: 46235 | BG45: 46266 | BH45: 46296 | BI45: 46327 | BJ45: 46357
...

Sheet HAVERD
A1: 1 | B1: =+A1+1 -> 2 | C1: =+B1+1 -> 3 | D1: =+C1+1 -> 4 | E1: =+D1+1 -> 5 | F1: =+E1+1 -> 6 | G1: =+F1+1 -> 7 | H1: =+G1+1 -> 8 | I1: =+H1+1 -> 9 | ... BS1: =+BR1+1 -> 71
A2: Date | B2: Month | C2: Year | D2: YYYYMM | E2: Quarter | F2: YYYYQQ | G2: 20240101 !D | H2: Bank Rate | I2: Overnight | J2: 1 | K2: 2 | L2: 3 | M2: 4 | N2: 5 | O2: 6 | P2: 7 | Q2: 8 | R2: 9 | S2: 10 | T2: 11 | U2: 12 | V2: 13 | W2: 14 | X2: 15 | Y2: 16 | Z2: 17 | AA2: 18 | AB2: 19 | AC2: 20 | AD2: 21 | AE2: 22 | AF2: 23 | AG2: 24 | AH2: 25 | AI2: 26 | AJ2: 27 | AK2: 28 | AL2: 29 | AM2: 30 | AN2: 31 | AO2: 32 | AP2: 33 | AQ2: 34 | AR2: 35 | AS2: 36 | AT2: 37 | AU2: 38 | AV2: 39 | AW2: 40 | AX2: 41 | AY2: 42 | AZ2: 43 | BA2: 44 | BB2: 45 | BC2: 46 | BD2: 47 | BE2: 48 | BF2: 49 | BG2: 50 | BH2: 51 | BI2: 52 | BJ2: 53 | BK2: 54 | BL2: 55 | BM2: 56 | BN2: 57 | BO2: 58 | BP2: 59 | BQ2: 60 | BR2: 5.5yrs | BS2: 6yrs
H3: R112RD@INTDAILY | I3: R112LOS@INTDAILY | J3: R11201F@INTDAILY | K3: R11202F@INTDAILY | L3: R11203F@INTDAILY | M3: R11204F@INTDAILY | N3: R11205F@INTDAILY | O3: R11206F@INTDAILY | P3: R11207F@INTDAILY | Q3: R11208F@INTDAILY | R3: R11209F@INTDAILY | S3: R11210F@INTDAILY | T3: R11211F@INTDAILY | U3: R11212F@INTDAILY | V3: R11213F@INTDAILY | W3: R11214F@INTDAILY | X3: R11215F@INTDAILY | Y3: R11216F@INTDAILY | Z3: R11217F@INTDAILY | AA3: R11218F@INTDAILY | AB3: R11219F@INTDAILY | AC3: R11220F@INTDAILY | AD3: R11221F@INTDAILY | AE3: R11222F@INTDAILY | AF3: R11223F@INTDAILY | AG3: R11224F@INTDAILY | AH3: R11225F@INTDAILY | AI3: R11226F@INTDAILY | AJ3: R11227F@INTDAILY | AK3: R11228F@INTDAILY | AL3: R11229F@INTDAILY | AM3: R11230F@INTDAILY | AN3: R11231F@INTDAILY | AO3: R11232F@INTDAILY | AP3: R11233F@INTDAILY | AQ3: R11234F@INTDAILY | AR3: R11235F@INTDAILY | AS3: R11236F@INTDAILY | AT3: R11237F@INTDAILY | AU3: R11238F@INTDAILY | AV3: R11239F@INTDAILY | AW3: R11240F@INTDAILY | AX3: R11241F@INTDAILY | AY3: R11242F@INTDAILY | AZ3: R11243F@INTDAILY | BA3: R11244F@INTDAILY | BB3: R11245F@INTDAILY | BC3: R11246F@INTDAILY | BD3: R11247F@INTDAILY | BE3: R11248F@INTDAILY | BF3: R11249F@INTDAILY | BG3: R11250F@INTDAILY | BH3: R11251F@INTDAILY | BI3: R11252F@INTDAILY | BJ3: R11253F@INTDAILY | BK3: R11254F@INTDAILY | BL3: R11255F@INTDAILY | BM3: R11256F@INTDAILY | BN3: R11257F@INTDAILY | BO3: R11258F@INTDAILY | BP3: R11259F@INTDAILY | BQ3: R11260F@INTDAILY | BR3: R112I5B@INTDAILY | BS3: R112I6A@INTDAILY
G4: .DESC | H4: United Kingdom: Official Bank Rate (%) | I4: UK:Lending Rate: Sterling Overnight Interbank Average [SONIA] (% pa) | J4: UK: Overnight Index Swap: Forward Yields, 1-Month (% p.a.) | K4: UK: Overnight Index Swap: Forward Yields, 2-Month (% p.a.) | L4: UK: Overnight Index Swap: Forward Yields, 3-Month (% p.a.) | M4: UK: Overnight Index Swap: Forward Yields, 4-Month (% p.a.) | N4: UK: Overnight Index Swap: Forward Yields, 5-Month (% p.a.) | O4: UK: Overnight Index Swap: Forward Yields, 6-Month (% p.a.) | P4: UK: Overnight Index Swap: Forward Yields, 7-Month (% p.a.) | Q4: UK: Overnight Index Swap: Forward Yields, 8-Month (% p.a.) | R4: UK: Overnight Index Swap: Forward Yields, 9-Month (% p.a.) | S4: UK: Overnight Index Swap: Forward Yields, 10-Month (% p.a.) | T4: UK: Overnight Index Swap: Forward Yields, 11-Month (% p.a.) | U4: UK: Overnight Index Swap: Forward Yields, 12-Month (% p.a.) | V4: UK: Overnight Index Swap: Forward Yields, 13-Month (% p.a.) | W4: UK: Overnight Index Swap: Forward Yields, 14-Month (% p.a.) | X4: UK: Overnight Index Swap: Forward Yields, 15-Month (% p.a.) | Y4: UK: Overnight Index Swap: Forward Yields, 16-Month (% p.a.) | Z4: UK: Overnight Index Swap: Forward Yields, 17-Month (% p.a.) | AA4: UK: Overnight Index Swap: Forward Yields, 18-Month (% p.a.) | AB4: UK: Overnight Index Swap: Forward Yields, 19-Month (% p.a.) | AC4: UK: Overnight Index Swap: Forward Yields, 20-Month (% p.a.) | AD4: UK: Overnight Index Swap: Forward Yields, 21-Month (% p.a.) | AE4: UK: Overnight Index Swap: Forward Yields, 22-Month (% p.a.) | AF4: UK: Overnight Index Swap: Forward Yields, 23-Month (% p.a.) | AG4: UK: Overnight Index Swap: Forward Yields, 24-Month (% p.a.) | AH4: UK: Overnight Index Swap: Forward Yields, 25-Month (% p.a.) | AI4: UK: Overnight Index Swap: Forward Yields, 26-Month (% p.a.) | AJ4: UK: Overnight Index Swap: Forward Yields, 27-Month (% p.a.) | AK4: UK: Overnight Index Swap: Forward Yields, 28-Month (% p.a.) | AL4: UK: Overnight Index Swap: Forward Yields, 29-Month (% p.a.) | AM4: UK: Overnight Index Swap: Forward Yields, 30-Month (% p.a.) | AN4: UK: Overnight Index Swap: Forward Yields, 31-Month (% p.a.) | AO4: UK: Overnight Index Swap: Forward Yields, 32-Month (% p.a.) | AP4: UK: Overnight Index Swap: Forward Yields, 33-Month (% p.a.) | AQ4: UK: Overnight Index Swap: Forward Yields, 34-Month (% p.a.) | AR4: UK: Overnight Index Swap: Forward Yields, 35-Month (% p.a.) | AS4: UK: Overnight Index Swap: Forward Yields, 36-Month (% p.a.) | AT4: UK: Overnight Index Swap: Forward Yields, 37-Month (% p.a.) | AU4: UK: Overnight Index Swap: Forward Yields, 38-Month (% p.a.) | AV4: UK: Overnight Index Swap: Forward Yields, 39-Month (% p.a.) | AW4: UK: Overnight Index Swap: Forward Yields, 40-Month (% p.a.) | AX4: UK: Overnight Index Swap: Forward Yields, 41-Month (% p.a.) | AY4: UK: Overnight Index Swap: Forward Yields, 42-Month (% p.a.) | AZ4: UK: Overnight Index Swap: Forward Yields, 43-Month (% p.a.) | BA4: UK: Overnight Index Swap: Forward Yields, 44-Month (% p.a.) | BB4: UK: Overnight Index Swap: Forward Yields, 45-Month (% p.a.) | BC4: UK: Overnight Index Swap: Forward Yields, 46-Month (% p.a.) | BD4: UK: Overnight Index Swap: Forward Yields, 47-Month (% p.a.) | BE4: UK: Overnight Index Swap: Forward Yields, 48-Month (% p.a.) | BF4: UK: Overnight Index Swap: Forward Yields, 49-Month (% p.a.) | BG4: UK: Overnight Index Swap: Forward Yields, 50-Month (% p.a.) | BH4: UK: Overnight Index Swap: Forward Yields, 51-Month (% p.a.) | BI4: UK: Overnight Index Swap: Forward Yields, 52-Month (% p.a.) | BJ4: UK: Overnight Index Swap: Forward Yields, 53-Month (% p.a.) | BK4: UK: Overnight Index Swap: Forward Yields, 54-Month (% p.a.) | BL4: UK: Overnight Index Swap: Forward Yields, 55-Month (% p.a.) | BM4: UK: Overnight Index Swap: Forward Yields, 56-Month (% p.a.) | BN4: UK: Overnight Index Swap: Forward Yields, 57-Month (% p.a.) | BO4: UK: Overnight Index Swap: Forward Yields, 58-Month (% p.a.) | BP4: UK: Overnight Index Swap: Forward Yields, 59-Month (% p.a.) | BQ4: UK: Overnight Index Swap: Forward Yields, 60-Month (% p.a.) | BR4: UK: Overnight Index Swap: Forward Yields, 5.5-Year (% p.a.) | BS4: UK: Overnight Index Swap: Forward Yields, 6-Year (% p.a.)
G5: .T1 | H5: 01-Jan-1953 | I5: 02-Jan-1997 | J5: 02-Jan-2009 | K5: 02-Jan-2009 | L5: 02-Jan-2009 | M5: 02-Jan-2009 | N5: 02-Jan-2009 | O5: 02-Jan-2009 | P5: 02-Jan-2009 | Q5: 02-Jan-2009 | R5: 02-Jan-2009 | S5: 02-Jan-2009 | T5: 02-Jan-2009 | U5: 02-Jan-2009 | V5: 02-Jan-2009 | W5: 02-Jan-2009 | X5: 02-Jan-2009 | Y5: 02-Jan-2009 | Z5: 02-Jan-2009 | AA5: 02-Jan-2009 | AB5: 02-Jan-2009 | AC5: 02-Jan-2009 | AD5: 02-Jan-2009 | AE5: 02-Jan-2009 | AF5: 02-Jan-2009 | AG5: 02-Jan-2009 | AH5: 02-Jan-2009 | AI5: 02-Jan-2009 | AJ5: 02-Jan-2009 | AK5: 02-Jan-2009 | AL5: 02-Jan-2009 | AM5: 02-Jan-2009 | AN5: 02-Jan-2009 | AO5: 02-Jan-2009 | AP5: 02-Jan-2009 | AQ5: 02-Jan-2009 | AR5: 02-Jan-2009 | AS5: 02-Jan-2009 | AT5: 02-Jan-2009 | AU5: 02-Jan-2009 | AV5: 02-Jan-2009 | AW5: 02-Jan-2009 | AX5: 02-Jan-2009 | AY5: 02-Jan-2009 | AZ5: 02-Jan-2009 | BA5: 02-Jan-2009 | BB5: 02-Jan-2009 | BC5: 02-Jan-2009 | BD5: 02-Jan-2009 | BE5: 02-Jan-2009 | BF5: 02-Jan-2009 | BG5: 02-Jan-2009 | BH5: 02-Jan-2009 | BI5: 02-Jan-2009 | BJ5: 02-Jan-2009 | BK5: 02-Jan-2009 | BL5: 02-Jan-2009 | BM5: 02-Jan-2009 | BN5: 02-Jan-2009 | BO5: 02-Jan-2009 | BP5: 02-Jan-2009 | BQ5: 02-Jan-2009 | BR5: 01-Dec-2021 | BS5: 01-Dec-2021
G6: .TN | H6: 07-Nov-2024 | I6: 05-Nov-2024 | J6: 06-Nov-2024 | K6: 06-Nov-2024 | L6: 06-Nov-2024 | M6: 06-Nov-2024 | N6: 06-Nov-2024 | O6: 06-Nov-2024 | P6: 06-Nov-2024 | Q6: 06-Nov-2024 | R6: 06-Nov-2024 | S6: 06-Nov-2024 | T6: 06-Nov-2024 | U6: 06-Nov-2024 | V6: 06-Nov-2024 | W6: 06-Nov-2024 | X6: 06-Nov-2024 | Y6: 06-Nov-2024 | Z6: 06-Nov-2024 | AA6: 06-Nov-2024 | AB6: 06-Nov-2024 | AC6: 06-Nov-2024 | AD6: 06-Nov-2024 | AE6: 06-Nov-2024 | AF6: 06-Nov-2024 | AG6: 06-Nov-2024 | AH6: 06-Nov-2024 | AI6: 06-Nov-2024 | AJ6: 06-Nov-2024 | AK6: 06-Nov-2024 | AL6: 06-Nov-2024 | AM6: 06-Nov-2024 | AN6: 06-Nov-2024 | AO6: 06-Nov-2024 | AP6: 06-Nov-2024 | AQ6: 06-Nov-2024 | AR6: 06-Nov-2024 | AS6: 06-Nov-2024 | AT6: 06-Nov-2024 | AU6: 06-Nov-2024 | AV6: 06-Nov-2024 | AW6: 06-Nov-2024 | AX6: 06-Nov-2024 | AY6: 06-Nov-2024 | AZ6: 06-Nov-2024 | BA6: 06-Nov-2024 | BB6: 06-Nov-2024 | BC6: 06-Nov-2024 | BD6: 06-Nov-2024 | BE6: 06-Nov-2024 | BF6: 06-Nov-2024 | BG6: 06-Nov-2024 | BH6: 06-Nov-2024 | BI6: 06-Nov-2024 | BJ6: 06-Nov-2024 | BK6: 06-Nov-2024 | BL6: 06-Nov-2024 | BM6: 06-Nov-2024 | BN6: 06-Nov-2024 | BO6: 06-Nov-2024 | BP6: 06-Nov-2024 | BQ6: 06-Nov-2024 | BR6: 06-Nov-2024 | BS6: 06-Nov-2024
G7: .LSOURCE | H7: Bank of England | I7: Bank of England | J7: Bank of England | K7: Bank of England | L7: Bank of England | M7: Bank of England | N7: Bank of England | O7: Bank of England | P7: Bank of England | Q7: Bank of England | R7: Bank of England | S7: Bank of England | T7: Bank of England | U7: Bank of England | V7: Bank of England | W7: Bank of England | X7: Bank of England | Y7: Bank of England | Z7: Bank of England | AA7: Bank of England | AB7: Bank of England | AC7: Bank of England | AD7: Bank of England | AE7: Bank of England | AF7: Bank of England | AG7: Bank of England | AH7: Bank of England | AI7: Bank of England | AJ7: Bank of England | AK7: Bank of England | AL7: Bank of England | AM7: Bank of England | AN7: Bank of England | AO7: Bank of England | AP7: Bank of England | AQ7: Bank of England | AR7: Bank of England | AS7: Bank of England | AT7: Bank of England | AU7: Bank of England | AV7: Bank of England | AW7: Bank of England | AX7: Bank of England | AY7: Bank of England | AZ7: Bank of England | BA7: Bank of England | BB7: Bank of England | BC7: Bank of England | BD7: Bank of England | BE7: Bank of England | BF7: Bank of England | BG7: Bank of England | BH7: Bank of England | BI7: Bank of England | BJ7: Bank of England | BK7: Bank of England | BL7: Bank of England | BM7: Bank of England | BN7: Bank of England | BO7: Bank of England | BP7: Bank of England | BQ7: Bank of England | BR7: Bank of England | BS7: Bank of England
G8: .DTLM | H8: Nov-07-2024 12:05 | I8: Nov-07-2024 09:31 | J8: Nov-07-2024 12:47 | K8: Nov-07-2024 12:47 | L8: Nov-07-2024 12:47 | M8: Nov-07-2024 12:47 | N8: Nov-07-2024 12:47 | O8: Nov-07-2024 12:47 | P8: Nov-07-2024 12:47 | Q8: Nov-07-2024 12:47 | R8: Nov-07-2024 12:47 | S8: Nov-07-2024 12:47 | T8: Nov-07-2024 12:47 | U8: Nov-07-2024 12:47 | V8: Nov-07-2024 12:47 | W8: Nov-07-2024 12:47 | X8: Nov-07-2024 12:47 | Y8: Nov-07-2024 12:47 | Z8: Nov-07-2024 12:47 | AA8: Nov-07-2024 12:47 | AB8: Nov-07-2024 12:47 | AC8: Nov-07-2024 12:47 | AD8: Nov-07-2024 12:47 | AE8: Nov-07-2024 12:47 | AF8: Nov-07-2024 12:47 | AG8: Nov-07-2024 12:47 | AH8: Nov-07-2024 12:47 | AI8: Nov-07-2024 12:47 | AJ8: Nov-07-2024 12:47 | AK8: Nov-07-2024 12:47 | AL8: Nov-07-2024 12:47 | AM8: Nov-07-2024 12:47 | AN8: Nov-07-2024 12:47 | AO8: Nov-07-2024 12:47 | AP8: Nov-07-2024 12:47 | AQ8: Nov-07-2024 12:47 | AR8: Nov-07-2024 12:47 | AS8: Nov-07-2024 12:47 | AT8: Nov-07-2024 12:47 | AU8: Nov-07-2024 12:47 | AV8: Nov-07-2024 12:47 | AW8: Nov-07-2024 12:47 | AX8: Nov-07-2024 12:47 | AY8: Nov-07-2024 12:47 | AZ8: Nov-07-2024 12:47 | BA8: Nov-07-2024 12:47 | BB8: Nov-07-2024 12:47 | BC8: Nov-07-2024 12:47 | BD8: Nov-07-2024 12:47 | BE8: Nov-07-2024 12:47 | BF8: Nov-07-2024 12:47 | BG8: Nov-07-2024 12:47 | BH8: Nov-07-2024 12:47 | BI8: Nov-07-2024 12:47 | BJ8: Nov-07-2024 12:47 | BK8: Nov-07-2024 12:47 | BL8: Nov-07-2024 12:47 | BM8: Nov-07-2024 12:47 | BN8: Nov-07-2024 12:47 | BO8: Nov-07-2024 12:47 | BP8: Nov-07-2024 12:47 | BQ8: Nov-07-2024 12:47 | BR8: Nov-07-2024 12:47 | BS8: Nov-07-2024 12:47
A9: 45292 | B9: =MONTH(A9) -> 1 | C9: =YEAR(A9) -> 2024 | D9: =C9*100+B9 -> 202401 | E9: =IF(B9<4,1,IF(B9<7,2,IF(B9<10,3,4))) -> 1 | F9: =C9*100+E9 -> 202401 | G9: 20240101 | H9: 5.25 | I9: #N/A | J9: #N/A | K9: #N/A | L9: #N/A | M9: #N/A | N9: #N/A | O9: #N/A | P9: #N/A | Q9: #N/A | R9: #N/A | S9: #N/A | T9: #N/A | U9: #N/A | V9: #N/A | W9: #N/A | X9: #N/A | Y9: #N/A | Z9: #N/A | AA9: #N/A | AB9: #N/A | AC9: #N/A | AD9: #N/A | AE9: #N/A | AF9: #N/A | AG9: #N/A | AH9: #N/A | AI9: #N/A | AJ9: #N/A | AK9: #N/A | AL9: #N/A | AM9: #N/A | AN9: #N/A | AO9: #N/A | AP9: #N/A | AQ9: #N/A | AR9: #N/A | AS9: #N/A | AT9: #N/A | AU9: #N/A | AV9: #N/A | AW9: #N/A | AX9: #N/A | AY9: #N/A | AZ9: #N/A | BA9: #N/A | BB9: #N/A | BC9: #N/A | BD9: #N/A | BE9: #N/A | BF9: #N/A | BG9: #N/A | BH9: #N/A | BI9: #N/A | BJ9: #N/A | BK9: #N/A | BL9: #N/A | BM9: #N/A | BN9: #N/A | BO9: #N/A | BP9: #N/A | BQ9: #N/A | BR9: #N/A | BS9: #N/A
A10: 45293 | B10: =MONTH(A10) -> 1 | C10: =YEAR(A10) -> 2024 | D10: =C10*100+B10 -> 202401 | E10: =IF(B10<4,1,IF(B10<7,2,IF(B10<10,3,4))) -> 1 | F10: =C10*100+E10 -> 202401 | G10: 20240102 | H10: 5.25 | I10: 5.1863 | J10: 5.1869458 | K10: 5.1737152 | L10: 5.1274641 | M10: 5.0330693 | N10: 4.8948084 | O10: 4.7267552 | P10: 4.5455904 | Q10: 4.3673209 | R10: 4.2024467 | S10: 4.0550731 | T10: 3.9257072 | U10: 3.8133507 | V10: 3.7135649 | W10: 3.6243989 | X10: 3.5449015 | Y10: 3.4741183 | Z10: 3.4110951 | AA10: 3.3548802 | AB10: 3.3045933 | AC10: 3.2596362 | AD10: 3.2194791 | AE10: 3.1835906 | AF10: 3.1514396 | AG10: 3.122496 | AH10: 3.0962854 | AI10: 3.0725845 | AJ10: 3.0512401 | AK10: 3.0320982 | AL10: 3.0150048 | AM10: 2.9998064 | AN10: 2.9863491 | AO10: 2.974479 | AP10: 2.9640426 | AQ10: 2.9548859 | AR10: 2.9468551 | AS10: 2.9397965 | AT10: 2.9335733 | AU10: 2.9281397 | AV10: 2.9234809 | AW10: 2.9195818 | AX10: 2.9164273 | AY10: 2.9140026 | AZ10: 2.9122925 | BA10: 2.9112821 | BB10: 2.9109564 | BC10: 2.9113003 | BD10: 2.912299 | BE10: 2.9139373 | BF10: 2.9161996 | BG10: 2.919067 | BH10: 2.9225195 | BI10: 2.9265371 | BJ10: 2.9310997 | BK10: 2.9361872 | BL10: 2.9417797 | BM10: 2.9478571 | BN10: 2.9543994 | BO10: 2.9613864 | BP10: 2.9687984 | BQ10: 2.976615 | BR10: 3.030969 | BS10: 3.0953136
A11: 45294 | B11: =MONTH(A11) -> 1 | C11: =YEAR(A11) -> 2024 | D11: =C11*100+B11 -> 202401 | E11: =IF(B11<4,1,IF(B11<7,2,IF(B11<10,3,4))) -> 1 | F11: =C11*100+E11 -> 202401 | G11: 20240103 | H11: 5.25 | I11: 5.1863 | J11: 5.1879346 | K11: 5.1698623 | L11: 5.1217679 | M11: 5.0292524 | N11: 4.8955915 | O11: 4.7327474 | P11: 4.5561573 | Q11: 4.3801251 | R11: 4.2145866 | S11: 4.0638514 | T11: 3.9292761 | U11: 3.8103909 | V11: 3.7037411 | W11: 3.6077142 | X11: 3.521457 | Y11: 3.4441131 | Z11: 3.3748263 | AA11: 3.3127429 | AB11: 3.2570771 | AC11: 3.2073119 | AD11: 3.1629961 | AE11: 3.1236764 | AF11: 3.0889 | AG11: 3.0582151 | AH11: 3.0311935 | AI11: 3.0075393 | AJ11: 2.9870022 | AK11: 2.969331 | AL11: 2.9542745 | AM11: 2.9415821 | AN11: 2.9310026 | AO11: 2.9222851 | AP11: 2.9151788 | AQ11: 2.9094326 | AR11: 2.9047955 | AS11: 2.9010166 | AT11: 2.8978771 | AU11: 2.895314 | AV11: 2.8933122 | AW11: 2.8918564 | AX11: 2.8909314 | AY11: 2.8905219 | AZ11: 2.8906127 | BA11: 2.8911885 | BB11: 2.8922341 | BC11: 2.8937342 | BD11: 2.8956737 | BE11: 2.8980372 | BF11: 2.9008111 | BG11: 2.9039899 | BH11: 2.9075703 | BI11: 2.9115491 | BJ11: 2.9159234 | BK11: 2.9206896 | BL11: 2.9258448 | BM11: 2.9313858 | BN11: 2.9373093 | BO11: 2.9436122 | BP11: 2.9502914 | BQ11: 2.9573435 | BR11: 3.0068421 | BS11: 3.066086
A12: 45295 | B12: =MONTH(A12) -> 1 | C12: =YEAR(A12) -> 2024 | D12: =C12*100+B12 -> 202401 | E12: =IF(B12<4,1,IF(B12<7,2,IF(B12<10,3,4))) -> 1 | F12: =C12*100+E12 -> 202401 | G12: 20240104 | H12: 5.25 | I12: 5.187 | J12: 5.1847631 | K12: 5.1706678 | L12: 5.1289199 | M12: 5.0490298 | N12: 4.9325416 | O12: 4.7903404 | P12: 4.6344699 | Q12: 4.4767792 | R12: 4.325913 | S12: 4.1861158 | T12: 4.0594066 | U12: 3.9458216 | V12: 3.8430555 | W12: 3.7499596 | X12: 3.6659829 | Y12: 3.5905712 | Z12: 3.5231711 | AA12: 3.4632312 | AB12: 3.4101861 | AC12: 3.3634253 | AD12: 3.3223291 | AE12: 3.2862764 | AF12: 3.2546461 | AG12: 3.2268182 | AH12: 3.202227 | AI12: 3.1805764 | AJ12: 3.1616533 | AK12: 3.1452434 | AL12: 3.1311331 | AM12: 3.1191088 | AN12: 3.1089566 | AO12: 3.1004627 | AP12: 3.0934135 | AQ12: 3.0875952 | AR12: 3.082794 | AS12: 3.0787962 | AT12: 3.0754178 | AU12: 3.0726057 | AV12: 3.0703431 | AW12: 3.0686133 | AX12: 3.0673993 | AY12: 3.0666845 | AZ12: 3.066452 | BA12: 3.0666849 | BB12: 3.0673665 | BC12: 3.0684799 | BD12: 3.0700083 | BE12: 3.071935 | BF12: 3.0742445 | BG12: 3.0769279 | BH12: 3.0799781 | BI12: 3.083388 | BJ12: 3.0871505 | BK12: 3.0912583 | BL12: 3.0957043 | BM12: 3.1004814 | BN12: 3.1055825 | BO12: 3.1110004 | BP12: 3.1167281 | BQ12: 3.1227582 | BR12: 3.164827 | BS12: 3.2155848
A13: 45296 | B13: =MONTH(A13) -> 1 | C13: =YEAR(A13) -> 2024 | D13: =C13*100+B13 -> 202401 | E13: =IF(B13<4,1,IF(B13<7,2,IF(B13<10,3,4))) -> 1 | F13: =C13*100+E13 -> 202401 | G13: 20240105 | H13: 5.25 | I13: 5.1869 | J13: 5.1873271 | K13: 5.1720792 | L13: 5.1334347 | M13: 5.0598045 | N13: 4.9517376 | O13: 4.818767 | P13: 4.6723585 | Q13: 4.5243145 | R13: 4.3831627 | S13: 4.2534108 | T13: 4.1364167 | U13: 4.0318583 | V13: 3.9368302 | W13: 3.85008 | X13: 3.7711019 | Y13: 3.6993871 | Z13: 3.6344272 | AA13: 3.5757159 | AB13: 3.5227608 | AC13: 3.4751452 | AD13: 3.4324758 | AE13: 3.3943576 | AF13: 3.3603956 | AG13: 3.3301963 | AH13: 3.3033905 | AI13: 3.2797228 | AJ13: 3.2589696 | AK13: 3.2409068 | AL13: 3.2253104 | AM13: 3.2119566 | AN13: 3.2006214 | AO13: 3.1910808 | AP13: 3.1831111 | AQ13: 3.1764881 | AR13: 3.1709879 | AS13: 3.1663868 | AT13: 3.1624898 | AU13: 3.1592315 | AV13: 3.156582 | AW13: 3.1545114 | AX13: 3.1529896 | AY13: 3.1519869 | AZ13: 3.1514732 | BA13: 3.1514186 | BB13: 3.1517933 | BC13: 3.1525672 | BD13: 3.1537105 | BE13: 3.1551932 | BF13: 3.1569896 | BG13: 3.1590924 | BH13: 3.1614995 | BI13: 3.1642087 | BJ13: 3.1672179 | BK13: 3.170525 | BL13: 3.1741276 | BM13: 3.1780239 | BN13: 3.1822114 | BO13: 3.1866882 | BP13: 3.191452 | BQ13: 3.1965007 | BR13: 3.2325006 | BS13: 3.2772656
A14: =A9+7 -> 45299 | B14: =MONTH(A14) -> 1 | C14: =YEAR(A14) -> 2024 | D14: =C14*100+B14 -> 202401 | E14: =IF(B14<4,1,IF(B14<7,2,IF(B14<10,3,4))) -> 1 | F14: =C14*100+E14 -> 202401 | G14: 20240108 | H14: 5.25 | I14: 5.1869 | J14: 5.1875371 | K14: 5.1723518 | L14: 5.1318123 | M14: 5.0538828 | N14: 4.940707 | O14: 4.8022983 | P14: 4.6506226 | Q14: 4.4975445 | R14: 4.3519114 | S14: 4.2180825 | T14: 4.0980801 | U14: 3.9915985 | V14: 3.8957127 | W14: 3.8090536 | X14: 3.7309025 | Y14: 3.6605376 | Z14: 3.5972375 | AA14: 3.5402832 | AB14: 3.489008 | AC14: 3.4429542 | AD14: 3.4017156 | AE14: 3.3648842 | AF14: 3.3320521 | AG14: 3.3028128 | AH14: 3.2767879 | AI14: 3.2537295 | AJ14: 3.2334264 | AK14: 3.2156666 | AL14: 3.2002382 | AM14: 3.1869299 | AN14: 3.1755298 | AO14: 3.1658259 | AP14: 3.1576069 | AQ14: 3.1506609 | AR14: 3.1447761 | AS14: 3.1397409 | AT14: 3.135372 | AU14: 3.1316118 | AV14: 3.1284378 | AW14: 3.1258269 | AX14: 3.1237565 | AY14: 3.1222038 | AZ14: 3.1211458 | BA14: 3.12056 | BB14: 3.1204234 | BC14: 3.1207133 | BD14: 3.1214068 | BE14: 3.1224812 | BF14: 3.1239165 | BG14: 3.1257072 | BH14: 3.1278529 | BI14: 3.1303531 | BJ14: 3.1332076 | BK14: 3.1364157 | BL14: 3.139977 | BM14: 3.1438913 | BN14: 3.1481579 | BO14: 3.1527765 | BP14: 3.1577466 | BQ14: 3.1630678 | BR14: 3.2019754 | BS14: 3.2511539
A15: =A10+7 -> 45300 | B15: =MONTH(A15) -> 1 | C15: =YEAR(A15) -> 2024 | D15: =C15*100+B15 -> 202401 | E15: =IF(B15<4,1,IF(B15<7,2,IF(B15<10,3,4))) -> 1 | F15: =C15*100+E15 -> 202401 | G15: 20240109 | H15: 5.25 | I15: 5.1867 | J15: 5.1852612 | K15: 5.1702463 | L15: 5.1298316 | M15: 5.0519415 | N15: 4.9396491 | O15: 4.8037639 | P15: 4.656196 | Q15: 4.5079649 | R15: 4.3668257 | S15: 4.2366576 | T15: 4.1187677 | U15: 4.0132622 | V15: 3.9177742 | W15: 3.8311198 | X15: 3.7526542 | Y15: 3.6817291 | Z15: 3.6176969 | AA15: 3.5599118 | AB15: 3.5077647 | AC15: 3.4607923 | AD15: 3.4185682 | AE15: 3.3806642 | AF15: 3.3466522 | AG15: 3.3161053 | AH15: 3.2886325 | AI15: 3.2640061 | AJ15: 3.2420446 | AK15: 3.2225655 | AL15: 3.2053862 | AM15: 3.190325 | AN15: 3.1771994 | AO15: 3.1658272 | AP15: 3.1560262 | AQ15: 3.1476142 | AR15: 3.1404089 | AS15: 3.1342282 | AT15: 3.1289081 | AU15: 3.1243834 | AV15: 3.1206224 | AW15: 3.1175928 | AX15: 3.1152628 | AY15: 3.1136004 | AZ15: 3.1125735 | BA15: 3.1121503 | BB15: 3.1122987 | BC15: 3.1129868 | BD15: 3.1141825 | BE15: 3.1158539 | BF15: 3.117972 | BG15: 3.1205215 | BH15: 3.1234918 | BI15: 3.1268719 | BJ15: 3.1306511 | BK15: 3.1348186 | BL15: 3.1393635 | BM15: 3.1442751 | BN15: 3.1495424 | BO15: 3.1551547 | BP15: 3.1611013 | BQ15: 3.1673712 | BR15: 3.2111431 | BS15: 3.2636287
A16: =A11+7 -> 45301 | B16: =MONTH(A16) -> 1 | C16: =YEAR(A16) -> 2024 | D16: =C16*100+B16 -> 202401 | E16: =IF(B16<4,1,IF(B16<7,2,IF(B16<10,3,4))) -> 1 | F16: =C16*100+E16 -> 202401 | G16: 20240110 | H16: 5.25 | I16: 5.1872 | J16: 5.1850912 | K16: 5.1708219 | L16: 5.1309503 | M16: 5.0544508 | N16: 4.9451799 | O16: 4.8134886 | P16: 4.6711024 | Q16: 4.5282674 | R16: 4.3923388 | S16: 4.2669033 | T16: 4.1533587 | U16: 4.0516976 | V16: 3.9600377 | W16: 3.8771955 | X16: 3.8023256 | Y16: 3.7345796 | Z16: 3.6731095 | AA16: 3.6170693 | AB16: 3.5657097 | AC16: 3.5186568 | AD16: 3.4756281 | AE16: 3.4363392 | AF16: 3.4005058 | AG16: 3.367845 | AH16: 3.3380884 | AI16: 3.311053 | AJ16: 3.2865854 | AK16: 3.2645311 | AL16: 3.2447358 | AM16: 3.2270459 | AN16: 3.2113071 | AO16: 3.1973651 | AP16: 3.1850661 | AQ16: 3.1742559 | AR16: 3.1647803 | AS16: 3.1564854 | AT16: 3.1492323 | AU16: 3.1429566 | AV16: 3.1376166 | AW16: 3.1331706 | AX16: 3.1295768 | AY16: 3.1267935 | AZ16: 3.124779 | BA16: 3.1234916 | BB16: 3.1228895 | BC16: 3.122931 | BD16: 3.1235745 | BE16: 3.1247781 | BF16: 3.126504 | BG16: 3.1287318 | BH16: 3.1314456 | BI16: 3.1346296 | BJ16: 3.1382682 | BK16: 3.1423454 | BL16: 3.1468455 | BM16: 3.1517528 | BN16: 3.1570515 | BO16: 3.1627257 | BP16: 3.1687597 | BQ16: 3.1751377 | BR16: 3.2197924 | BS16: 3.2731349
A17: =A12+7 -> 45302 | B17: =MONTH(A17) -> 1 | C17: =YEAR(A17) -> 2024 | D17: =C17*100+B17 -> 202401 | E17: =IF(B17<4,1,IF(B17<7,2,IF(B17<10,3,4))) -> 1 | F17: =C17*100+E17 -> 202401 | G17: 20240111 | H17: 5.25 | I17: 5.1876 | J17: 5.1883039 | K17: 5.1673171 | L17: 5.1189594 | M17: 5.0346508 | N17: 4.9187015 | O17: 4.782997 | P17: 4.639412 | Q17: 4.4977175 | R17: 4.3643034 | S17: 4.2417532 | T17: 4.1308656 | U17: 4.0309256 | V17: 3.9389315 | W17: 3.8538379 | X17: 3.7754857 | Y17: 3.7037131 | Z17: 3.6383589 | AA17: 3.579264 | AB17: 3.5262153 | AC17: 3.478802 | AD17: 3.4365684 | AE17: 3.3990568 | AF17: 3.3658098 | AG17: 3.3363711 | AH17: 3.3103155 | AI17: 3.287374 | AJ17: 3.267326 | AK17: 3.2499503 | AL17: 3.2350255 | AM17: 3.222331 | AN17: 3.2116455 | AO17: 3.2027477 | AP17: 3.195417 | AQ17: 3.189432 | AR17: 3.1845717 | AS17: 3.180615 | AT17: 3.1773707 | AU17: 3.1747784 | AV17: 3.1728145 | AW17: 3.1714548 | AX17: 3.1706755 | AY17: 3.1704526 | AZ17: 3.1707622 | BA17: 3.1715805 | BB17: 3.1728834 | BC17: 3.174647 | BD17: 3.1768474 | BE17: 3.1794607 | BF17: 3.1824649 | BG17: 3.1858464 | BH17: 3.1895941 | BI17: 3.1936968 | BJ17: 3.1981434 | BK17: 3.2029227 | BL17: 3.2080234 | BM17: 3.2134345 | BN17: 3.2191448 | BO17: 3.225143 | BP17: 3.2314182 | BQ17: 3.2379589 | BR17: 3.2822065 | BS17: 3.3335096
A18: =A13+7 -> 45303 | B18: =MONTH(A18) -> 1 | C18: =YEAR(A18) -> 2024 | D18: =C18*100+B18 -> 202401 | E18: =IF(B18<4,1,IF(B18<7,2,IF(B18<10,3,4))) -> 1 | F18: =C18*100+E18 -> 202401 | G18: 20240112 | H18: 5.25 | I18: 5.1884 | J18: 5.188735 | K18: 5.1604989 | L18: 5.0990229 | M18: 4.995414 | N18: 4.8574653 | O18: 4.7009555 | P18: 4.5407209 | Q18: 4.3873025 | R18: 4.2463179 | S18: 4.1196492 | T18: 4.0067672 | U18: 3.906338 | V18: 3.8150971 | W18: 3.7317978 | X18: 3.656016 | Y18: 3.5873251 | Z18: 3.5252985 | AA18: 3.4695121 | AB18: 3.4195369 | AC18: 3.374933 | AD18: 3.3352586 | AE18: 3.3000704 | AF18: 3.2689254 | AG18: 3.2413816 | AH18: 3.2170317 | AI18: 3.1956271 | AJ18: 3.1769635 | AK18: 3.1608361 | AL18: 3.14704 | AM18: 3.1353707 | AN18: 3.1256236 | AO18: 3.1175937 | AP18: 3.1110766 | AQ18: 3.1058674 | AR18: 3.1017615 | AS18: 3.0985542 | AT18: 3.0960678 | AU18: 3.0942432 | AV18: 3.0930544 | AW18: 3.0924751 | AX18: 3.0924793 | AY18: 3.0930407 | AZ18: 3.0941333 | BA18: 3.0957309 | BB18: 3.0978072 | BC18: 3.1003363 | BD18: 3.1032919 | BE18: 3.1066479 | BF18: 3.1103807 | BG18: 3.1144784 | BH18: 3.1189321 | BI18: 3.123733 | BJ18: 3.1288724 | BK18: 3.1343415 | BL18: 3.1401313 | BM18: 3.1462333 | BN18: 3.1526384 | BO18: 3.1593379 | BP18: 3.1663232 | BQ18: 3.1735852 | BR18: 3.2224388 | BS18: 3.2788019
A19: =A14+7 -> 45306 | B19: =MONTH(A19) -> 1 | C19: =YEAR(A19) -> 2024 | D19: =C19*100+B19 -> 202401 | E19: =IF(B19<4,1,IF(B19<7,2,IF(B19<10,3,4))) -> 1 | F19: =C19*100+E19 -> 202401 | G19: 20240115 | H19: 5.25 | I19: 5.1874 | J19: 5.1864987 | K19: 5.1613939 | L19: 5.1015345 | M19: 4.9956199 | N19: 4.8521908 | O19: 4.688973 | P19: 4.5229898 | Q19: 4.3655985 | R19: 4.2226677 | S19: 4.0950554 | T19: 3.9821699 | U19: 3.882187 | V19: 3.7914806 | W19: 3.7087614 | X19: 3.6335691 | Y19: 3.5654407 | Z19: 3.5039133 | AA19: 3.4485262 | AB19: 3.3988263 | AC19: 3.3543966 | AD19: 3.3148308 | AE19: 3.2797206 | AF19: 3.2486582 | AG19: 3.2212368 | AH19: 3.1970775 | AI19: 3.1759309 | AJ19: 3.1575841 | AK19: 3.1418233 | AL19: 3.1284346 | AM19: 3.117205 | AN19: 3.1079206 | AO19: 3.1003678 | AP19: 3.0943333 | AQ19: 3.0896034 | AR19: 3.0859646 | AS19: 3.0832033 | AT19: 3.0811348 | AU19: 3.0797022 | AV19: 3.0788836 | AW19: 3.078657 | AX19: 3.0790008 | AY19: 3.0798929 | AZ19: 3.0813115 | BA19: 3.0832348 | BB19: 3.0856409 | BC19: 3.088508 | BD19: 3.0918143 | BE19: 3.0955378 | BF19: 3.0996584 | BG19: 3.1041662 | BH19: 3.109054 | BI19: 3.1143149 | BJ19: 3.1199422 | BK19: 3.1259288 | BL19: 3.1322677 | BM19: 3.1389522 | BN19: 3.1459753 | BO19: 3.15333 | BP19: 3.1610095 | BQ19: 3.1690068 | BR19: 3.2230363 | BS19: 3.2852854
A20: =A15+7 -> 45307 | B20: =MONTH(A20) -> 1 | C20: =YEAR(A20) -> 2024 | D20: =C20*100+B20 -> 202401 | E20: =IF(B20<4,1,IF(B20<7,2,IF(B20<10,3,4))) -> 1 | F20: =C20*100+E20 -> 202401 | G20: 20240116 | H20: 5.25 | I20: 5.1876 | J20: 5.1912832 | K20: 5.1664072 | L20: 5.1080097 | M20: 5.0063493 | N20: 4.867976 | O20: 4.7086042 | P20: 4.5445595 | Q20: 4.38725 | R20: 4.2424888 | S20: 4.1116753 | T20: 3.9942376 | U20: 3.8892679 | V20: 3.7938851 | W20: 3.707063 | X20: 3.6284902 | Y20: 3.557852 | Z20: 3.4948342 | AA20: 3.4391248 | AB20: 3.3903464 | AC20: 3.3478821 | AD20: 3.3110591 | AE20: 3.2792031 | AF20: 3.2516403 | AG20: 3.2276975 | AH20: 3.2067727 | AI20: 3.188581 | AJ20: 3.1729261 | AK20: 3.1596107 | AL20: 3.1484378 | AM20: 3.1392107 | AN20: 3.1317324 | AO20: 3.1258057 | AP20: 3.121234 | AQ20: 3.1178202 | AR20: 3.1153674 | AS20: 3.1136786 | AT20: 3.1125798 | AU20: 3.1120197 | AV20: 3.1119887 | AW20: 3.1124767 | AX20: 3.1134739 | AY20: 3.1149705 | AZ20: 3.1169565 | BA20: 3.1194223 | BB20: 3.1223578 | BC20: 3.1257533 | BD20: 3.1295988 | BE20: 3.1338846 | BF20: 3.1386005 | BG20: 3.1437357 | BH20: 3.1492789 | BI20: 3.155219 | BJ20: 3.1615448 | BK20: 3.168245 | BL20: 3.1753084 | BM20: 3.182724 | BN20: 3.1904803 | BO20: 3.1985663 | BP20: 3.2069709 | BQ20: 3.2156826 | BR20: 3.2737519 | BS20: 3.3398985
A21: =A16+7 -> 45308 | B21: =MONTH(A21) -> 1 | C21: =YEAR(A21) -> 2024 | D21: =C21*100+B21 -> 202401 | E21: =IF(B21<4,1,IF(B21<7,2,IF(B21<10,3,4))) -> 1 | F21: =C21*100+E21 -> 202401 | G21: 20240117 | H21: 5.25 | I21: 5.188 | J21: 5.1870648 | K21: 5.1803458 | L21: 5.1485105 | M21: 5.0809502 | N21: 4.98113 | O21: 4.8598482 | P21: 4.7298052 | Q21: 4.6007117 | R21: 4.4787319 | S21: 4.3664604 | T21: 4.2645357 | U21: 4.1724997 | V21: 4.0877527 | W21: 4.0093645 | X21: 3.9370579 | Y21: 3.8705529 | Z21: 3.8095699 | AA21: 3.7538311 | AB21: 3.7030483 | AC21: 3.6569008 | AD21: 3.6150618 | AE21: 3.5772029 | AF21: 3.5429957 | AG21: 3.5121132 | AH21: 3.4842457 | AI21: 3.4591839 | AJ21: 3.4367527 | AK21: 3.4167765 | AL21: 3.3990794 | AM21: 3.3834865 | AN21: 3.3698221 | AO21: 3.3579105 | AP21: 3.3475765 | AQ21: 3.3386445 | AR21: 3.3309389 | AS21: 3.3242844 | AT21: 3.3185256 | AU21: 3.3136055 | AV21: 3.3094973 | AW21: 3.3061737 | AX21: 3.3036079 | AY21: 3.3017729 | AZ21: 3.3006415 | BA21: 3.3001869 | BB21: 3.3003819 | BC21: 3.3011997 | BD21: 3.3026131 | BE21: 3.3045953 | BF21: 3.3071205 | BG21: 3.3101696 | BH21: 3.3137253 | BI21: 3.31777 | BJ21: 3.3222865 | BK21: 3.3272571 | BL21: 3.3326646 | BM21: 3.3384916 | BN21: 3.3447204 | BO21: 3.3513339 | BP21: 3.3583145 | BQ21: 3.3656448 | BR21: 3.4160227 | BS21: 3.4747675
A22: =A17+7 -> 45309 | B22: =MONTH(A22) -> 1 | C22: =YEAR(A22) -> 2024 | D22: =C22*100+B22 -> 202401 | E22: =IF(B22<4,1,IF(B22<7,2,IF(B22<10,3,4))) -> 1 | F22: =C22*100+E22 -> 202401 | G22: 20240118 | H22: 5.25 | I22: 5.1883 | J22: 5.1869164 | K22: 5.1776901 | L22: 5.1408352 | M22: 5.0663889 | N22: 4.9579612 | O22: 4.8290191 | P22: 4.6930677 | Q22: 4.5596575 | R22: 4.4343029 | S22: 4.3189017 | T22: 4.2137297 | U22: 4.1179306 | V22: 4.0287191 | W22: 3.9452892 | X22: 3.8677035 | Y22: 3.7960222 | Z22: 3.7303058 | AA22: 3.670617 | AB22: 3.6169267 | AC22: 3.5688652 | AD22: 3.5259831 | AE22: 3.4878294 | AF22: 3.4539534 | AG22: 3.4239054 | AH22: 3.3972655 | AI22: 3.3737641 | AJ22: 3.3531784 | AK22: 3.3352845 | AL22: 3.3198589 | AM22: 3.3066783 | AN22: 3.2955192 | AO22: 3.2861579 | AP22: 3.2783713 | AQ22: 3.2719357 | AR22: 3.2666275 | AS22: 3.2622235 | AT22: 3.2585313 | AU22: 3.2554963 | AV22: 3.2531022 | AW22: 3.2513323 | AX22: 3.2501701 | AY22: 3.2495992 | AZ22: 3.249603 | BA22: 3.250165 | BB22: 3.2512688 | BC22: 3.2528977 | BD22: 3.2550354 | BE22: 3.2576652 | BF22: 3.2607713 | BG22: 3.2643408 | BH22: 3.2683613 | BI22: 3.2728207 | BJ22: 3.2777068 | BK22: 3.2830074 | BL22: 3.2887101 | BM22: 3.294803 | BN22: 3.3012737 | BO22: 3.3081099 | BP22: 3.3152996 | BQ22: 3.3228304 | BR22: 3.374397 | BS22: 3.4345602
A23: =A18+7 -> 45310 | B23: =MONTH(A23) -> 1 | C23: =YEAR(A23) -> 2024 | D23: =C23*100+B23 -> 202401 | E23: =IF(B23<4,1,IF(B23<7,2,IF(B23<10,3,4))) -> 1 | F23: =C23*100+E23 -> 202401 | G23: 20240119 | H23: 5.25 | I23: 5.1876 | J23: 5.1887528 | K23: 5.1780003 | L23: 5.1399208 | M23: 5.0660792 | N23: 4.9607851 | O23: 4.8358842 | P23: 4.7040655 | Q23: 4.5747957 | R23: 4.4535067 | S23: 4.342442 | T23: 4.2414709 | U23: 4.1495841 | V23: 4.0640079 | W23: 3.9839484 | X23: 3.9094062 | Y23: 3.8403786 | Z23: 3.7768635 | AA23: 3.718861 | AB23: 3.6663115 | AC23: 3.6188895 | AD23: 3.5761943 | AE23: 3.5378231 | AF23: 3.5033735 | AG23: 3.4724444 | AH23: 3.4446637 | AI23: 3.4197932 | AJ23: 3.3976326 | AK23: 3.3779807 | AL23: 3.3606364 | AM23: 3.3453992 | AN23: 3.332068 | AO23: 3.3204417 | AP23: 3.3103197 | AQ23: 3.3015011 | AR23: 3.2937847 | AS23: 3.2869698 | AT23: 3.2808836 | AU23: 3.2754765 | AV23: 3.2707334 | AW23: 3.2666391 | AX23: 3.2631784 | AY23: 3.260336 | AZ23: 3.2580967 | BA23: 3.2564452 | BB23: 3.2553664 | BC23: 3.2548451 | BD23: 3.2548659 | BE23: 3.2554136 | BF23: 3.2564736 | BG23: 3.258033 | BH23: 3.2600796 | BI23: 3.2626013 | BJ23: 3.2655858 | BK23: 3.269021 | BL23: 3.2728947 | BM23: 3.2771947 | BN23: 3.2819087 | BO23: 3.2870246 | BP23: 3.2925303 | BQ23: 3.2984134 | BR23: 3.3409003 | BS23: 3.3935567
A24: =A19+7 -> 45313 | B24: =MONTH(A24) -> 1 | C24: =YEAR(A24) -> 2024 | D24: =C24*100+B24 -> 202401 | E24: =IF(B24<4,1,IF(B24<7,2,IF(B24<10,3,4))) -> 1 | F24: =C24*100+E24 -> 202401 | G24: 20240122 | H24: 5.25 | I24: 5.1879 | J24: 5.1876758 | K24: 5.1735163 | L24: 5.1304359 | M24: 5.0506997 | N24: 4.9406132 | O24: 4.8124133 | P24: 4.6785996 | Q24: 4.548289 | R24: 4.4266204 | S24: 4.3151828 | T24: 4.2142326 | U24: 4.1228926 | V24: 4.0394159 | W24: 3.9630131 | X24: 3.8932351 | Y24: 3.8296297 | Z24: 3.7717453 | AA24: 3.7191321 | AB24: 3.6713504 | AC24: 3.6280058 | AD24: 3.5887163 | AE24: 3.5530986 | AF24: 3.5207691 | AG24: 3.4913458 | AH24: 3.4644814 | AI24: 3.4399885 | AJ24: 3.4177248 | AK24: 3.3975468 | AL24: 3.3793113 | AM24: 3.3628758 | AN24: 3.3480969 | AO24: 3.3348316 | AP24: 3.322937 | AQ24: 3.31227 | AR24: 3.3026875 | AS24: 3.2940466 | AT24: 3.2862231 | AU24: 3.2791755 | AV24: 3.2728859 | AW24: 3.2673357 | AX24: 3.2625067 | AY24: 3.2583806 | AZ24: 3.2549391 | BA24: 3.2521639 | BB24: 3.2500366 | BC24: 3.2485391 | BD24: 3.2476529 | BE24: 3.2473597 | BF24: 3.247642 | BG24: 3.2484853 | BH24: 3.2498763 | BI24: 3.251802 | BJ24: 3.2542491 | BK24: 3.2572043 | BL24: 3.2606544 | BM24: 3.2645863 | BN24: 3.2689867 | BO24: 3.2738422 | BP24: 3.2791399 | BQ24: 3.2848664 | BR24: 3.3273444 | BS24: 3.3810345
A25: =A20+7 -> 45314 | B25: =MONTH(A25) -> 1 | C25: =YEAR(A25) -> 2024 | D25: =C25*100+B25 -> 202401 | E25: =IF(B25<4,1,IF(B25<7,2,IF(B25<10,3,4))) -> 1 | F25: =C25*100+E25 -> 202401 | G25: 20240123 | H25: 5.25 | I25: 5.1873 | J25: 5.1859941 | K25: 5.174959 | L25: 5.1400496 | M25: 5.0725396 | N25: 4.9760912 | O25: 4.8604414 | P25: 4.7365585 | Q25: 4.6134216 | R25: 4.496681 | S25: 4.3890212 | T25: 4.2910856 | U25: 4.2025817 | V25: 4.1210901 | W25: 4.0457403 | X25: 3.9762845 | Y25: 3.912472 | Z25: 3.8540524 | AA25: 3.8007774 | AB25: 3.752374 | AC25: 3.7084834 | AD25: 3.668728 | AE25: 3.6327287 | AF25: 3.6001064 | AG25: 3.5704832 | AH25: 3.5435145 | AI25: 3.519007 | AJ25: 3.4968103 | AK25: 3.4767731 | AL25: 3.4587441 | AM25: 3.4425727 | AN25: 3.4281076 | AO25: 3.4151976 | AP25: 3.403692 | AQ25: 3.3934397 | AR25: 3.3842894 | AS25: 3.3760902 | AT25: 3.3687072 | AU25: 3.3620912 | AV25: 3.3562225 | AW25: 3.3510809 | AX25: 3.3466465 | AY25: 3.3428994 | AZ25: 3.3398195 | BA25: 3.3373869 | BB25: 3.3355815 | BC25: 3.3343835 | BD25: 3.3337727 | BE25: 3.3337293 | BF25: 3.334234 | BG25: 3.3352711 | BH25: 3.3368259 | BI25: 3.3388839 | BJ25: 3.3414304 | BK25: 3.3444509 | BL25: 3.3479307 | BM25: 3.3518553 | BN25: 3.3562099 | BO25: 3.36098 | BP25: 3.3661511 | BQ25: 3.3717084 | BR25: 3.4123271 | BS25: 3.4630552
... A72: =A67+7 -> 45379 | B72: =MONTH(A72) -> 3 | C72: =YEAR(A72) -> 2024 | D72: =C72*100+B72 -> 202403 | E72: =IF(B72<4,1,IF(B72<7,2,IF(B72<10,3,4))) -> 1 | F72: =C72*100+E72 -> 202401 | G72: 20240328 | H72: 5.25 | I72: 5.1911 | J72: 5.1827949 | K72: 5.1285197 | L72: 5.0548387 | M72: 4.9650427 | N72: 4.8685886 | O72: 4.7708037 | P72: 4.6732194 | Q72: 4.5769532 | R72: 4.4834965 | S72: 4.3944428 | T72: 4.3108747 | U72: 4.2335021 | V72: 4.162811 | W72: 4.0982378 | X72: 4.0389508 | Y72: 3.9841158 | Z72: 3.9328986 | AA72: 3.8844672 | AB72: 3.8381017 | AC72: 3.7936677 | AD72: 3.7512193 | AE72: 3.7108091 | AF72: 3.6724898 | AG72: 3.6363153 | AH72: 3.6023211 | AI72: 3.5704587 | AJ72: 3.5406553 | AK72: 3.5128369 | AL72: 3.4869296 | AM72: 3.4628602 | AN72: 3.440555 | AO72: 3.4199399 | AP72: 3.400942 | AQ72: 3.3834872 | AR72: 3.3675018 | AS72: 3.3529125 | AT72: 3.3396465 | AU72: 3.3276361 | AV72: 3.3168154 | AW72: 3.307118 | AX72: 3.2984779 | AY72: 3.2908291 | AZ72: 3.2841052 | BA72: 3.2782402 | BB72: 3.273168 | BC72: 3.2688225 | BD72: 3.2651374 | BE72: 3.2620468 | BF72: 3.2594922 | BG72: 3.2574503 | BH72: 3.2559073 | BI72: 3.2548493 | BJ72: 3.2542624 | BK72: 3.2541328 | BL72: 3.2544467 | BM72: 3.2551903 | BN72: 3.2563496 | BO72: 3.2579108 | BP72: 3.2598602 | BQ72: 3.2621838 | BR72: 3.2833438 | BS72: 3.3153029
A73: =A68+7 -> 45380 | B73: =MONTH(A73) -> 3 | C73: =YEAR(A73) -> 2024 | D73: =C73*100+B73 -> 202403 | E73: =IF(B73<4,1,IF(B73<7,2,IF(B73<10,3,4))) -> 1 | F73: =C73*100+E73 -> 202401 | G73: 20240329 | H73: 5.25 | I73: #N/A | J73: #N/A | K73: #N/A | L73: #N/A | M73: #N/A | N73: #N/A | O73: #N/A | P73: #N/A | Q73: #N/A | R73: #N/A | S73: #N/A | T73: #N/A | U73: #N/A | V73: #N/A | W73: #N/A | X73: #N/A | Y73: #N/A | Z73: #N/A | AA73: #N/A | AB73: #N/A | AC73: #N/A | AD73: #N/A | AE73: #N/A | AF73: #N/A | AG73: #N/A | AH73: #N/A | AI73: #N/A | AJ73: #N/A | AK73: #N/A | AL73: #N/A | AM73: #N/A | AN73: #N/A | AO73: #N/A | AP73: #N/A | AQ73: #N/A | AR73: #N/A | AS73: #N/A | AT73: #N/A | AU73: #N/A | AV73: #N/A | AW73: #N/A | AX73: #N/A | AY73: #N/A | AZ73: #N/A | BA73: #N/A | BB73: #N/A | BC73: #N/A | BD73: #N/A | BE73: #N/A | BF73: #N/A | BG73: #N/A | BH73: #N/A | BI73: #N/A | BJ73: #N/A | BK73: #N/A | BL73: #N/A | BM73: #N/A | BN73: #N/A | BO73: #N/A | BP73: #N/A | BQ73: #N/A | BR73: #N/A | BS73: #N/A
A74: =A69+7 -> 45383 | B74: =MONTH(A74) -> 4 | C74: =YEAR(A74) -> 2024 | D74: =C74*100+B74 -> 202404 | E74: =IF(B74<4,1,IF(B74<7,2,IF(B74<10,3,4))) -> 2 | F74: =C74*100+E74 -> 202402 | G74: 20240401 | H74: 5.25 | I74: #N/A | J74: #N/A | K74: #N/A | L74: #N/A | M74: #N/A | N74: #N/A | O74: #N/A | P74: #N/A | Q74: #N/A | R74: #N/A | S74: #N/A | T74: #N/A | U74: #N/A | V74: #N/A | W74: #N/A | X74: #N/A | Y74: #N/A | Z74: #N/A | AA74: #N/A | AB74: #N/A | AC74: #N/A | AD74: #N/A | AE74: #N/A | AF74: #N/A | AG74: #N/A | AH74: #N/A | AI74: #N/A | AJ74: #N/A | AK74: #N/A | AL74: #N/A | AM74: #N/A | AN74: #N/A | AO74: #N/A | AP74: #N/A | AQ74: #N/A | AR74: #N/A | AS74: #N/A | AT74: #N/A | AU74: #N/A | AV74: #N/A | AW74: #N/A | AX74: #N/A | AY74: #N/A | AZ74: #N/A | BA74: #N/A | BB74: #N/A | BC74: #N/A | BD74: #N/A | BE74: #N/A | BF74: #N/A | BG74: #N/A | BH74: #N/A | BI74: #N/A | BJ74: #N/A | BK74: #N/A | BL74: #N/A | BM74: #N/A | BN74: #N/A | BO74: #N/A | BP74: #N/A | BQ74: #N/A | BR74: #N/A | BS74: #N/A
A75: =A70+7 -> 45384 | B75: =MONTH(A75) -> 4 | C75: =YEAR(A75) -> 2024 | D75: =C75*100+B75 -> 202404 | E75: =IF(B75<4,1,IF(B75<7,2,IF(B75<10,3,4))) -> 2 | F75: =C75*100+E75 -> 202402 | G75: 20240402 | H75: 5.25 | I75: 5.1956 | J75: 5.1807489 | K75: 5.1199562 | L75: 5.0432068 | M75: 4.9538124 | N75: 4.8601742 | O75: 4.7672807 | P75: 4.6768675 | Q75: 4.5904147 | R75: 4.5095263 | S75: 4.4349691 | T75: 4.3666138 | U75: 4.3040203 | V75: 4.245397 | W75: 4.1899963 | X75: 4.1374546 | Y75: 4.0874062 | Z75: 4.0394856 | AA75: 3.993329 | AB75: 3.9486534 | AC75: 3.9055228 | AD75: 3.8640941 | AE75: 3.8245225 | AF75: 3.7869632 | AG75: 3.751573 | AH75: 3.7184638 | AI75: 3.6875746 | AJ75: 3.6588023 | AK75: 3.6320425 | AL75: 3.6071911 | AM75: 3.5841446 | AN75: 3.5627989 | AO75: 3.5430499 | AP75: 3.5247939 | AQ75: 3.507927 | AR75: 3.4923449 | AS75: 3.4779442 | AT75: 3.4646324 | AU75: 3.4523639 | AV75: 3.4411054 | AW75: 3.430823 | AX75: 3.4214829 | AY75: 3.4130515 | AZ75: 3.4054951 | BA75: 3.3987798 | BB75: 3.3928722 | BC75: 3.3877384 | BD75: 3.3833446 | BE75: 3.3796573 | BF75: 3.3766452 | BG75: 3.3742886 | BH75: 3.3725717 | BI75: 3.3714786 | BJ75: 3.3709933 | BK75: 3.3710999 | BL75: 3.3717825 | BM75: 3.3730252 | BN75: 3.3748121 | BO75: 3.3771271 | BP75: 3.3799545 | BQ75: 3.3832782 | BR75: 3.4124666 | BS75: 3.4537561
A76: =A71+7 -> 45385 | B76: =MONTH(A76) -> 4 | C76: =YEAR(A76) -> 2024 | D76: =C76*100+B76 -> 202404 | E76: =IF(B76<4,1,IF(B76<7,2,IF(B76<10,3,4))) -> 2 | F76: =C76*100+E76 -> 202402 | G76: 20240403 | H76: 5.25 | I76: 5.1952 | J76: 5.1797674 | K76: 5.1131197 | L76: 5.0320872 | M76: 4.9409016 | N76: 4.8471024 | O76: 4.7546427 | P76: 4.6646348 | Q76: 4.5782068 | R76: 4.4967782 | S76: 4.4211358 | T76: 4.3513992 | U76: 4.2873411 | V76: 4.2279176 | W76: 4.1723537 | X76: 4.1200009 | Y76: 4.0702083 | Z76: 4.0223254 | AA76: 3.9757031 | AB76: 3.9298374 | AC76: 3.8848387 | AD76: 3.8409809 | AE76: 3.7985361 | AF76: 3.7577764 | AG76: 3.7189756 | AH76: 3.6823697 | AI76: 3.6479792 | AJ76: 3.6157465 | AK76: 3.5856125 | AL76: 3.5575183 | AM76: 3.531406 | AN76: 3.5072165 | AO76: 3.4848911 | AP76: 3.4643715 | AQ76: 3.445599 | AR76: 3.4285146 | AS76: 3.4130603 | AT76: 3.399174 | AU76: 3.3867787 | AV76: 3.375793 | AW76: 3.3661353 | AX76: 3.3577239 | AY76: 3.3504775 | AZ76: 3.3443143 | BA76: 3.3391528 | BB76: 3.3349114 | BC76: 3.3315087 | BD76: 3.3288628 | BE76: 3.3268925 | BF76: 3.3255251 | BG76: 3.324728 | BH76: 3.3244799 | BI76: 3.3247592 | BJ76: 3.3255443 | BK76: 3.3268139 | BL76: 3.3285463 | BM76: 3.3307202 | BN76: 3.3333139 | BO76: 3.3363061 | BP76: 3.3396751 | BQ76: 3.3433996 | BR76: 3.3723498 | BS76: 3.4107635
A77: =A72+7 -> 45386 | B77: =MONTH(A77) -> 4 | C77: =YEAR(A77) -> 2024 | D77: =C77*100+B77 -> 202404 | E77: =IF(B77<4,1,IF(B77<7,2,IF(B77<10,3,4))) -> 2 | F77: =C77*100+E77 -> 202402 | G77: 20240404 | H77: 5.25 | I77: 5.1949 | J77: 5.1769496 | K77: 5.1016997 | L77: 5.0170889 | M77: 4.9251208 | N77: 4.8317243 | O77: 4.740301 | P77: 4.6518337 | Q77: 4.5674583 | R77: 4.488418 | S77: 4.415362 | T77: 4.3478637 | U77: 4.285214 | V77: 4.2255322 | W77: 4.1681248 | X77: 4.1126996 | Y77: 4.0589627 | Z77: 4.0066199 | AA77: 3.9553792 | AB77: 3.9050367 | AC77: 3.8558508 | AD77: 3.8082292 | AE77: 3.762578 | AF77: 3.7193033 | AG77: 3.6788126 | AH77: 3.6414432 | AI77: 3.6071603 | AJ77: 3.5758061 | AK77: 3.5472212 | AL77: 3.5212464 | AM77: 3.4977234 | AN77: 3.4764931 | AO77: 3.4573963 | AP77: 3.4402745 | AQ77: 3.4249688 | AR77: 3.4113199 | AS77: 3.3991694 | AT77: 3.3883705 | AU77: 3.3788308 | AV77: 3.3704734 | AW77: 3.3632209 | AX77: 3.356996 | AY77: 3.3517216 | AZ77: 3.3473204 | BA77: 3.3437151 | BB77: 3.3408285 | BC77: 3.3385835 | BD77: 3.3369027 | BE77: 3.3357089 | BF77: 3.3349356 | BG77: 3.3345643 | BH77: 3.3345893 | BI77: 3.3350051 | BJ77: 3.3358062 | BK77: 3.3369869 | BL77: 3.3385418 | BM77: 3.3404654 | BN77: 3.3427521 | BO77: 3.3453962 | BP77: 3.3483924 | BQ77: 3.3517351 | BR77: 3.3785759 | BS77: 3.4153988
A78: =A73+7 -> 45387 | B78: =MONTH(A78) -> 4 | C78: =YEAR(A78) -> 2024 | D78: =C78*100+B78 -> 202404 | E78: =IF(B78<4,1,IF(B78<7,2,IF(B78<10,3,4))) -> 2 | F78: =C78*100+E78 -> 202402 | G78: 20240405 | H78: 5.25 | I78: 5.1949 | J78: 5.1743507 | K78: 5.0990626 | L78: 5.0156411 | M78: 4.9256211 | N78: 4.8342136 | O78: 4.7444207 | P78: 4.6568399 | Q78: 4.5722358 | R78: 4.4916264 | S78: 4.4156849 | T78: 4.3445416 | U78: 4.2781786 | V78: 4.2157358 | W78: 4.1567632 | X78: 4.1010152 | Y78: 4.0482438 | Z78: 3.9982015 | AA78: 3.9506425 | AB78: 3.9053601 | AC78: 3.862339 | AD78: 3.8216207 | AE78: 3.783245 | AF78: 3.747252 | AG78: 3.7136829 | AH78: 3.682556 | AI78: 3.6537839 | AJ78: 3.6272481 | AK78: 3.6028289 | AL78: 3.5804068 | AM78: 3.5598631 | AN78: 3.5410783 | AO78: 3.5239328 | AP78: 3.5083079 | AQ78: 3.494084 | AR78: 3.4811418 | AS78: 3.4693622 | AT78: 3.4586379 | AU78: 3.4489092 | AV78: 3.440129 | AW78: 3.4322496 | AX78: 3.4252234 | AY78: 3.4190032 | AZ78: 3.4135414 | BA78: 3.4087904 | BB78: 3.4047029 | BC78: 3.4012313 | BD78: 3.3983281 | BE78: 3.3959459 | BF78: 3.394043 | BG78: 3.3926035 | BH78: 3.3916186 | BI78: 3.3910794 | BJ78: 3.390977 | BK78: 3.3913028 | BL78: 3.3920477 | BM78: 3.3932031 | BN78: 3.39476 | BO78: 3.3967096 | BP78: 3.3990431 | BQ78: 3.4017517 | BR78: 3.4253239 | BS78: 3.4598017
A79: =A74+7 -> 45390 | B79: =MONTH(A79) -> 4 | C79: =YEAR(A79) -> 2024 | D79: =C79*100+B79 -> 202404 | E79: =IF(B79<4,1,IF(B79<7,2,IF(B79<10,3,4))) -> 2 | F79: =C79*100+E79 -> 202402 | G79: 20240408 | H79: 5.25 | I79: 5.1949 | J79: 5.1730522 | K79: 5.0963888 | L79: 5.0139903 | M79: 4.927098 | N79: 4.8391915 | O79: 4.7523231 | P79: 4.6673225 | Q79: 4.5856252 | R79: 4.5090046 | S79: 4.438254 | T79: 4.3734106 | U79: 4.3140391 | V79: 4.2587921 | W79: 4.2069901 | X79: 4.1582037 | Y79: 4.1120019 | Z79: 4.0679533 | AA79: 4.0256285 | AB79: 3.9846795 | AC79: 3.945108 | AD79: 3.9070088 | AE79: 3.8704753 | AF79: 3.8356012 | AG79: 3.802481 | AH79: 3.7711816 | AI79: 3.7416622 | AJ79: 3.7138564 | AK79: 3.6876969 | AL79: 3.6631161 | AM79: 3.6400476 | AN79: 3.6184239 | AO79: 3.5981777 | AP79: 3.5792423 | AQ79: 3.5615504 | AR79: 3.5450348 | AS79: 3.5296285 | AT79: 3.5152706 | AU79: 3.5019243 | AV79: 3.4895598 | AW79: 3.4781464 | AX79: 3.4676539 | AY79: 3.458052 | AZ79: 3.4493105 | BA79: 3.4413988 | BB79: 3.4342869 | BC79: 3.4279443 | BD79: 3.4223407 | BE79: 3.417446 | BF79: 3.4132316 | BG79: 3.4096799 | BH79: 3.4067769 | BI79: 3.4045083 | BJ79: 3.4028602 | BK79: 3.4018183 | BL79: 3.4013687 | BM79: 3.4014971 | BN79: 3.4021895 | BO79: 3.4034318 | BP79: 3.4052099 | BQ79: 3.4075096 | BR79: 3.431248 | BS79: 3.4688325
