Workbook
Name _DLX1.INC: HAVERD!$B$2:$BN$7
Name _DLX2.INC: HAVERM!$B$1:$F$6
Name _DLX3.INC: HAVERQ!$B$1:$G$6
Name Annual_Data: GMW!$A$1:$A$2
Name Data: [4]sheet0!$C$2

Sheet Chart Data
A1: Interest rates - OE forecast & market expectations - monthly | F1: =TODAY() -> 45401 | CL1: Interest rates - OE forecast & market expectations - quarterly | CM1: 42094 | CN1: 42185 | CO1: 42277 | CP1: 42369 | CQ1: 42460 | CR1: 42551 | CS1: 42643 | CT1: 42735 | CU1: 42825 | CV1: 42916 | CW1: 43008 | CX1: 43100 | CY1: 43190 | CZ1: 43281 | DA1: 43373 | DB1: 43465 | DC1: 43555 | DD1: 43646 | DE1: 43738 | DF1: 43830 | DG1: 43921 | DH1: 44012 | DI1: 44104 | DJ1: 44196 | DK1: 44286 | DL1: 44377 | DM1: 44469 | DN1: 44561 | DO1: 44651 | DP1: 44742 | DQ1: 44834 | DR1: 44926 | DS1: 45016 | DT1: 45107 | DU1: 45199 | DV1: 45291 | DW1: 45382 | DX1: 45473 | DY1: 45565 | DZ1: 45657 | EA1: 45747 | EB1: 45838 | EC1: 45930 | ED1: 46022 | EE1: 46112 | EF1: 46203 | EG1: 46295 | EH1: 46387 | EI1: 46477
E2: 43466 | F2: 43497 | G2: 43525 | H2: 43556 | I2: 43586 | J2: 43617 | K2: 43647 | L2: 43678 | M2: 43709 | N2: 43739 | O2: 43770 | P2: 43800 | Q2: 43831 | R2: 43862 | S2: 43891 | T2: 43922 | U2: 43952 | V2: 43983 | W2: 44013 | X2: 44044 | Y2: 44075 | Z2: 44105 | AA2: 44136 | AB2: 44166 | AC2: 44197 | AD2: 44228 | AE2: 44256 | AF2: 44287 | AG2: 44317 | AH2: 44348 | AI2: 44378 | AJ2: 44409 | AK2: 44440 | AL2: 44470 | AM2: 44501 | AN2: 44531 | AO2: 44562 | AP2: 44593 | AQ2: 44621 | AR2: 44652 | AS2: 44682 | AT2: 44713 | AU2: 44743 | AV2: 44774 | AW2: 44805 | AX2: 44835 | AY2: 44866 | AZ2: 44896 | BA2: 44927 | BB2: 44958 | BC2: 44986 | BD2: 45017 | BE2: 45047 | BF2: 45078 | BG2: 45108 | BH2: 45139 | BI2: 45170 | BJ2: 45200 | BK2: 45231 | BL2: 45261 | BM2: 45292 | BN2: 45323 | BO2: 45352 | BP2: 45383 | BQ2: 45413 | BR2: 45444 | BS2: 45474 | BT2: 45505 | BU2: 45536 | BV2: 45566 | BW2: 45597 | BX2: 45627 | BY2: 45658 | BZ2: 45689 | CA2: 45717 | CB2: 45748 | CC2: 45778 | CD2: 45809 | CE2: 45839 | CF2: 45870 | CG2: 45901 | CH2: 45931 | CI2: 45962 | CJ2: 45992 | CM2: 42005 | CN2: 42095 | CO2: 42186 | CP2: 42278 | CQ2: 42370 | CR2: 42461 | CS2: 42552 | CT2: 42644 | CU2: 42736 | CV2: 42826 | CW2: 42917 | CX2: 43009 | CY2: 43101 | CZ2: 43191 | DA2: 43282 | DB2: 43374 | DC2: 43466 | DD2: 43556 | DE2: 43647 | DF2: 43739 | DG2: 43831 | DH2: 43922 | DI2: 44013 | DJ2: 44105 | DK2: 44197 | DL2: 44287 | DM2: 44378 | DN2: 44470 | DO2: 44562 | DP2: 44652 | DQ2: 44743 | DR2: 44835 | DS2: 44927 | DT2: 45017 | DU2: 45108 | DV2: 45200 | DW2: 45292 | DX2: 45383 | DY2: 45474 | DZ2: 45566 | EA2: 45658 | EB2: 45748 | EC2: 45839 | ED2: 45931 | EE2: 46023 | EF2: 46113 | EG2: 46204 | EH2: 46296 | EI2: 46388
E3: =EOMONTH(E2,0) -> 43496 | F3: =EOMONTH(F2,0) -> 43524 | G3: =EOMONTH(G2,0) -> 43555 | H3: =EOMONTH(H2,0) -> 43585 | I3: =EOMONTH(I2,0) -> 43616 | J3: =EOMONTH(J2,0) -> 43646 | K3: =EOMONTH(K2,0) -> 43677 | L3: =EOMONTH(L2,0) -> 43708 | ... CJ3: =EOMONTH(CJ2,0) -> 46022 | CM3: =EOMONTH(CM2,0) -> 42035 | CN3: =EOMONTH(CN2,0) -> 42124 | CO3: =EOMONTH(CO2,0) -> 42216 | CP3: =EOMONTH(CP2,0) -> 42308 | CQ3: =EOMONTH(CQ2,0) -> 42400 | CR3: =EOMONTH(CR2,0) -> 42490 | CS3: =EOMONTH(CS2,0) -> 42582 | CT3: =EOMONTH(CT2,0) -> 42674 | ... EI3: =EOMONTH(EI2,0) -> 46418
A4: =D4 -> Bank Rate | B4: =D4 -> Bank Rate | C4: =B4 -> Bank Rate | D4: Bank Rate | E4: =VLOOKUP(E2,HAVERM!$A:$C,3,FALSE) -> 0.75 | F4: =VLOOKUP(F2,HAVERM!$A:$C,3,FALSE) -> 0.75 | G4: =VLOOKUP(G2,HAVERM!$A:$C,3,FALSE) -> 0.75 | H4: =VLOOKUP(H2,HAVERM!$A:$C,3,FALSE) -> 0.75 | I4: =VLOOKUP(I2,HAVERM!$A:$C,3,FALSE) -> 0.75 | J4: =VLOOKUP(J2,HAVERM!$A:$C,3,FALSE) -> 0.75 | K4: =VLOOKUP(K2,HAVERM!$A:$C,3,FALSE) -> 0.75 | L4: =VLOOKUP(L2,HAVERM!$A:$C,3,FALSE) -> 0.75 | ... BO4: =VLOOKUP(BO2,HAVERM!$A:$C,3,FALSE) -> 5.25 | BP4: 5.25 | BQ4: =VLOOKUP(BQ2,HAVERM!$A:$C,3,FALSE) -> #N/A | BR4: =VLOOKUP(BR2,HAVERM!$A:$C,3,FALSE) -> #N/A | BS4: =VLOOKUP(BS2,HAVERM!$A:$C,3,FALSE) -> #N/A | BT4: =VLOOKUP(BT2,HAVERM!$A:$C,3,FALSE) -> #N/A | BU4: =VLOOKUP(BU2,HAVERM!$A:$C,3,FALSE) -> #N/A | BV4: =VLOOKUP(BV2,HAVERM!$A:$C,3,FALSE) -> #N/A | BW4: =VLOOKUP(BW2,HAVERM!$A:$C,3,FALSE) -> #N/A | BX4: =VLOOKUP(BX2,HAVERM!$A:$C,3,FALSE) -> #N/A | ... CJ4: =VLOOKUP(CJ2,HAVERM!$A:$C,3,FALSE) -> #N/A | CL4: =A4 -> Bank Rate | CM4: =IF(CM1<$F$1,VLOOKUP(CM2,HAVERQ!$A:$D,4,FALSE),NA()) -> 0.5 | CN4: =IF(CN1<$F$1,VLOOKUP(CN2,HAVERQ!$A:$D,4,FALSE),NA()) -> 0.5 | CO4: =IF(CO1<$F$1,VLOOKUP(CO2,HAVERQ!$A:$D,4,FALSE),NA()) -> 0.5 | CP4: =IF(CP1<$F$1,VLOOKUP(CP2,HAVERQ!$A:$D,4,FALSE),NA()) -> 0.5 | CQ4: =IF(CQ1<$F$1,VLOOKUP(CQ2,HAVERQ!$A:$D,4,FALSE),NA()) -> 0.5 | CR4: =IF(CR1<$F$1,VLOOKUP(CR2,HAVERQ!$A:$D,4,FALSE),NA()) -> 0.5 | CS4: =IF(CS1<$F$1,VLOOKUP(CS2,HAVERQ!$A:$D,4,FALSE),NA()) -> 0.34090909 | CT4: =IF(CT1<$F$1,VLOOKUP(CT2,HAVERQ!$A:$D,4,FALSE),NA()) -> 0.25 | ... EG4: =IF(EG1<$F$1,VLOOKUP(EG2,HAVERQ!$A:$D,4,FALSE),NA()) -> #N/A
A5: Market expectations - After February MPC meeting | B5: =D5 -> 45324 | C5: After February MPC | D5: =D15 -> 45324 | E5: =HLOOKUP(E$3,$E$14:$AO$15,2,FALSE) -> #N/A | F5: =HLOOKUP(F$3,$E$14:$AO$15,2,FALSE) -> #N/A | G5: =HLOOKUP(G$3,$E$14:$AO$15,2,FALSE) -> #N/A | H5: =HLOOKUP(H$3,$E$14:$AO$15,2,FALSE) -> #N/A | I5: =HLOOKUP(I$3,$E$14:$AO$15,2,FALSE) -> #N/A | J5: =HLOOKUP(J$3,$E$14:$AO$15,2,FALSE) -> #N/A | K5: =HLOOKUP(K$3,$E$14:$AO$15,2,FALSE) -> #N/A | L5: =HLOOKUP(L$3,$E$14:$AO$15,2,FALSE) -> #N/A | ... CJ5: =HLOOKUP(CJ$3,$E$14:$AO$15,2,FALSE) -> 3.5800488 | CL5: =A5 -> Market expectations - After February MPC meeting | DT5: =AVERAGE(BF5:BG5) -> #N/A | DU5: =AVERAGE(BH5:BJ5) -> #N/A | DV5: =AVERAGE(BK5:BM5) -> #N/A | DW5: =AVERAGE(BN5:BP5) -> 5.1794648 | DX5: =AVERAGE(BQ5:BS5) -> 5.0520878 | DY5: =AVERAGE(BT5:BV5) -> 4.734236 | DZ5: =AVERAGE(BW5:BY5) -> 4.4132062 | EA5: =AVERAGE(BZ5:CB5) -> 4.1488487 | EB5: =AVERAGE(CC5:CE5) -> 3.9186041 | EC5: =AVERAGE(CF5:CH5) -> 3.7277959 | ED5: =AVERAGE(CI5:CK5) -> 3.6020545
A6: Market expectations - After March MPC meeting | B6: =D6 -> 45373 | C6: After March MPC | D6: =D23 -> 45373 | E6: =HLOOKUP(E$3,$E$22:$AO$23,2,FALSE) -> #N/A | F6: =HLOOKUP(F$3,$E$22:$AO$23,2,FALSE) -> #N/A | G6: =HLOOKUP(G$3,$E$22:$AO$23,2,FALSE) -> #N/A | H6: =HLOOKUP(H$3,$E$22:$AO$23,2,FALSE) -> #N/A | I6: =HLOOKUP(I$3,$E$22:$AO$23,2,FALSE) -> #N/A | J6: =HLOOKUP(J$3,$E$22:$AO$23,2,FALSE) -> #N/A | K6: =HLOOKUP(K$3,$E$22:$AO$23,2,FALSE) -> #N/A | L6: =HLOOKUP(L$3,$E$22:$AO$23,2,FALSE) -> #N/A | ... CJ6: =HLOOKUP(CJ$3,$E$22:$AO$23,2,FALSE) -> 3.7120729 | CL6: Market expectations - Before August MPC | DT6: {=TRANSPOSE(HAVERQ!C40:C55)} -> #N/A | DU6: #N/A | DV6: #N/A | DW6: 5.11 | DX6: 5.02 | DY6: 4.63 | DZ6: 4.22 | EA6: 3.92 | EB6: 3.7 | EC6: 3.52 | ED6: 3.4 | EE6: 3.31 | EF6: 3.25 | EG6: 3.21 | EH6: 3.18 | EI6: 3.17
A7: Market expectations - Latest | B7: =D7 -> 45399 | C7: Latest | D7: =D31 -> 45399 | E7: =HLOOKUP(E$3,$E$30:$AO$31,2,FALSE) -> #N/A | F7: =HLOOKUP(F$3,$E$30:$AO$31,2,FALSE) -> #N/A | G7: =HLOOKUP(G$3,$E$30:$AO$31,2,FALSE) -> #N/A | H7: =HLOOKUP(H$3,$E$30:$AO$31,2,FALSE) -> #N/A | I7: =HLOOKUP(I$3,$E$30:$AO$31,2,FALSE) -> #N/A | J7: =HLOOKUP(J$3,$E$30:$AO$31,2,FALSE) -> #N/A | K7: =HLOOKUP(K$3,$E$30:$AO$31,2,FALSE) -> #N/A | L7: =HLOOKUP(L$3,$E$30:$AO$31,2,FALSE) -> #N/A | ... CJ7: =HLOOKUP(CJ$3,$E$30:$AO$31,2,FALSE) -> 4.2794607 | CL7: =A7 -> Market expectations - Latest | DT7: =AVERAGE(BF7:BG7) -> #N/A | DU7: =AVERAGE(BH7:BJ7) -> #N/A | DV7: =AVERAGE(BK7:BM7) -> #N/A | DW7: =AVERAGE(BN7:BP7) -> #N/A | DX7: =AVERAGE(BQ7:BS7) -> 5.1365021 | DY7: =AVERAGE(BT7:BV7) -> 4.9536643 | DZ7: =AVERAGE(BW7:BY7) -> 4.7726709 | EA7: =AVERAGE(BZ7:CB7) -> 4.6353058 | EB7: =AVERAGE(CC7:CE7) -> 4.5235269 | EC7: =AVERAGE(CF7:CH7) -> 4.4061715 | ED7: =AVERAGE(CI7:CK7) -> 4.3011212
A8: =D8 -> OE forecast | D8: OE forecast | E8: =IF(E3>$F$1,HLOOKUP(E$3,$AL$35:$DQ$36,2,FALSE),NA()) -> #N/A | F8: =IF(F3>$F$1,HLOOKUP(F$3,$AL$35:$DQ$36,2,FALSE),NA()) -> #N/A | G8: =IF(G3>$F$1,HLOOKUP(G$3,$AL$35:$DQ$36,2,FALSE),NA()) -> #N/A | H8: =IF(H3>$F$1,HLOOKUP(H$3,$AL$35:$DQ$36,2,FALSE),NA()) -> #N/A | I8: =IF(I3>$F$1,HLOOKUP(I$3,$AL$35:$DQ$36,2,FALSE),NA()) -> #N/A | J8: =IF(J3>$F$1,HLOOKUP(J$3,$AL$35:$DQ$36,2,FALSE),NA()) -> #N/A | K8: =IF(K3>$F$1,HLOOKUP(K$3,$AL$35:$DQ$36,2,FALSE),NA()) -> #N/A | L8: =IF(L3>$F$1,HLOOKUP(L$3,$AL$35:$DQ$36,2,FALSE),NA()) -> #N/A | ... BO8: =IF(BO3>$F$1,HLOOKUP(BO$3,$AL$35:$DQ$36,2,FALSE),NA()) -> #N/A | BP8: 5.25 | BQ8: 5.25 | BR8: =+BQ8-0.25 -> 5 | BS8: =BR8 -> 5 | BT8: =+BS8-0.25 -> 4.75 | BU8: =BT8 -> 4.75 | BV8: =BT8 -> 4.75 | BW8: =+BV8-0.25 -> 4.5 | BX8: =BW8 -> 4.5 | BY8: =BW8 -> 4.5 | BZ8: =+BY8-0.25 -> 4.25 | CA8: =BZ8 -> 4.25 | CB8: =BZ8 -> 4.25 | CC8: =+CB8-0.25 -> 4 | CD8: =CC8 -> 4 | CE8: =CC8 -> 4 | CF8: =+CE8-0.25 -> 3.75 | CG8: =CF8 -> 3.75 | CH8: =CF8 -> 3.75 | CI8: =+CH8-0.25 -> 3.5 | CJ8: =CI8 -> 3.5 | CL8: =A8 -> OE forecast | CM8: =IF(CM1>$F$1,VLOOKUP(CM2,Data!$A:$D,4,FALSE),NA()) -> #N/A | CN8: =IF(CN1>$F$1,VLOOKUP(CN2,Data!$A:$D,4,FALSE),NA()) -> #N/A | CO8: =IF(CO1>$F$1,VLOOKUP(CO2,Data!$A:$D,4,FALSE),NA()) -> #N/A | CP8: =IF(CP1>$F$1,VLOOKUP(CP2,Data!$A:$D,4,FALSE),NA()) -> #N/A | CQ8: =IF(CQ1>$F$1,VLOOKUP(CQ2,Data!$A:$D,4,FALSE),NA()) -> #N/A | CR8: =IF(CR1>$F$1,VLOOKUP(CR2,Data!$A:$D,4,FALSE),NA()) -> #N/A | CS8: =IF(CS1>$F$1,VLOOKUP(CS2,Data!$A:$D,4,FALSE),NA()) -> #N/A | CT8: =IF(CT1>$F$1,VLOOKUP(CT2,Data!$A:$D,4,FALSE),NA()) -> #N/A | ... EG8: =IF(EG1>$F$1,VLOOKUP(EG2,Data!$A:$D,4,FALSE),NA()) -> 2.75 | EH8: 2.75 | EI8: 2.5
D10: Column # | E10: 4 | F10: =+E10+1 -> 5 | G10: =+F10+1 -> 6 | H10: =+G10+1 -> 7 | I10: =+H10+1 -> 8 | J10: =+I10+1 -> 9 | K10: =+J10+1 -> 10 | L10: =+K10+1 -> 11 | M10: =+L10+1 -> 12 | ... BM10: =+BL10+1 -> 64
D11: Months | E11: =HAVERD!D$1 -> Overnight | F11: =HAVERD!E$1 -> 1 | G11: =HAVERD!F$1 -> 2 | H11: =HAVERD!G$1 -> 3 | I11: =HAVERD!H$1 -> 4 | J11: =HAVERD!I$1 -> 5 | K11: =HAVERD!J$1 -> 6 | L11: =HAVERD!K$1 -> 7 | ... BM11: =HAVERD!BL$1 -> 60
D12: Days | F12: 30.416667 | G12: =+F12+30.4166667 -> 60.833333 | H12: =+G12+30.4166667 -> 91.25 | I12: =+H12+30.4166667 -> 121.66667 | J12: =+I12+30.4166667 -> 152.08333 | K12: =+J12+30.4166667 -> 182.5 | L12: =+K12+30.4166667 -> 212.91667 | M12: =+L12+30.4166667 -> 243.33333 | N12: =+M12+30.4166667 -> 273.75 | ... BM12: =+BL12+30.4166667 -> 1825
E13: =D15 -> 45324 | F13: =$E13+F12 -> 45354.417 | G13: =$E13+G12 -> 45384.833 | H13: =$E13+H12 -> 45415.25 | I13: =$E13+I12 -> 45445.667 | J13: =$E13+J12 -> 45476.083 | K13: =$E13+K12 -> 45506.5 | L13: =$E13+L12 -> 45536.917 | M13: =$E13+M12 -> 45567.333 | ... BM13: =$E13+BM12 -> 47149
E14: =EOMONTH(E13,0) -> 45351 | F14: =EOMONTH(F13,0) -> 45382 | G14: =EOMONTH(G13,0) -> 45412 | H14: =EOMONTH(H13,0) -> 45443 | I14: =EOMONTH(I13,0) -> 45473 | J14: =EOMONTH(J13,0) -> 45504 | K14: =EOMONTH(K13,0) -> 45535 | L14: =EOMONTH(L13,0) -> 45565 | ... BM14: =EOMONTH(BM13,0) -> 47149
D15: 45324 | E15: =VLOOKUP($D15,HAVERD!$A:$BL,E10,FALSE) -> 5.1885 | F15: =VLOOKUP($D15,HAVERD!$A:$BL,F10,FALSE) -> 5.1810986 | G15: =VLOOKUP($D15,HAVERD!$A:$BL,G10,FALSE) -> 5.1687959 | H15: =VLOOKUP($D15,HAVERD!$A:$BL,H10,FALSE) -> 5.1308084 | I15: =VLOOKUP($D15,HAVERD!$A:$BL,I10,FALSE) -> 5.0609635 | J15: =VLOOKUP($D15,HAVERD!$A:$BL,J10,FALSE) -> 4.9644914 | K15: =VLOOKUP($D15,HAVERD!$A:$BL,K10,FALSE) -> 4.8513274 | L15: =VLOOKUP($D15,HAVERD!$A:$BL,L10,FALSE) -> 4.7330915 | ... BM15: =VLOOKUP($D15,HAVERD!$A:$BL,BM10,FALSE) -> 3.3153328
D16: Diff vs overinight | F16: =F15-$E$15 -> -0.0074014 | G16: =G15-$E$15 -> -0.0197041 | H16: =H15-$E$15 -> -0.0576916 | I16: =I15-$E$15 -> -0.1275365 | J16: =J15-$E$15 -> -0.2240086 | K16: =K15-$E$15 -> -0.3371726 | L16: =L15-$E$15 -> -0.4554085 | M16: =M15-$E$15 -> -0.5702109 | ... BM16: =BM15-$E$15 -> -1.8731672
D18: Column # | E18: 4 | F18: =+E18+1 -> 5 | G18: =+F18+1 -> 6 | H18: =+G18+1 -> 7 | I18: =+H18+1 -> 8 | J18: =+I18+1 -> 9 | K18: =+J18+1 -> 10 | L18: =+K18+1 -> 11 | M18: =+L18+1 -> 12 | ... BM18: =+BL18+1 -> 64
D19: Months | E19: =HAVERD!D$1 -> Overnight | F19: =HAVERD!E$1 -> 1 | G19: =HAVERD!F$1 -> 2 | H19: =HAVERD!G$1 -> 3 | I19: =HAVERD!H$1 -> 4 | J19: =HAVERD!I$1 -> 5 | K19: =HAVERD!J$1 -> 6 | L19: =HAVERD!K$1 -> 7 | ... BM19: =HAVERD!BL$1 -> 60
D20: Days | F20: 30.416667 | G20: =+F20+30.4166667 -> 60.833333 | H20: =+G20+30.4166667 -> 91.25 | I20: =+H20+30.4166667 -> 121.66667 | J20: =+I20+30.4166667 -> 152.08333 | K20: =+J20+30.4166667 -> 182.5 | L20: =+K20+30.4166667 -> 212.91667 | M20: =+L20+30.4166667 -> 243.33333 | N20: =+M20+30.4166667 -> 273.75 | ... BM20: =+BL20+30.4166667 -> 1825
E21: =D23 -> 45373 | F21: =$E21+F20 -> 45403.417 | G21: =$E21+G20 -> 45433.833 | H21: =$E21+H20 -> 45464.25 | I21: =$E21+I20 -> 45494.667 | J21: =$E21+J20 -> 45525.083 | K21: =$E21+K20 -> 45555.5 | L21: =$E21+L20 -> 45585.917 | M21: =$E21+M20 -> 45616.333 | ... BM21: =$E21+BM20 -> 47198
E22: =EOMONTH(E21,0) -> 45382 | F22: =EOMONTH(F21,0) -> 45412 | G22: =EOMONTH(G21,0) -> 45443 | H22: =EOMONTH(H21,0) -> 45473 | I22: =EOMONTH(I21,0) -> 45504 | J22: =EOMONTH(J21,0) -> 45535 | K22: =EOMONTH(K21,0) -> 45565 | L22: =EOMONTH(L21,0) -> 45596 | ... BM22: =EOMONTH(BM21,0) -> 47208
D23: 45373 | E23: =VLOOKUP($D23,HAVERD!$A:$BL,E18,FALSE) -> 5.1906 | F23: =VLOOKUP($D23,HAVERD!$A:$BL,F18,FALSE) -> 5.1805712 | G23: =VLOOKUP($D23,HAVERD!$A:$BL,G18,FALSE) -> 5.1182898 | H23: =VLOOKUP($D23,HAVERD!$A:$BL,H18,FALSE) -> 5.037206 | I23: =VLOOKUP($D23,HAVERD!$A:$BL,I18,FALSE) -> 4.9406043 | J23: =VLOOKUP($D23,HAVERD!$A:$BL,J18,FALSE) -> 4.8376756 | K23: =VLOOKUP($D23,HAVERD!$A:$BL,K18,FALSE) -> 4.7334883 | L23: =VLOOKUP($D23,HAVERD!$A:$BL,L18,FALSE) -> 4.6303639 | ... BM23: =VLOOKUP($D23,HAVERD!$A:$BL,BM18,FALSE) -> 3.2805562
D24: Diff vs overinight | F24: =F23-$E$23 -> -0.0100288 | G24: =G23-$E$23 -> -0.0723102 | H24: =H23-$E$23 -> -0.153394 | I24: =I23-$E$23 -> -0.2499957 | J24: =J23-$E$23 -> -0.3529244 | K24: =K23-$E$23 -> -0.4571117 | L24: =L23-$E$23 -> -0.5602361 | M24: =M23-$E$23 -> -0.6604868 | ... BM24: =BM23-$E$23 -> -1.9100438
D26: Column # | E26: 4 | F26: =+E26+1 -> 5 | G26: =+F26+1 -> 6 | H26: =+G26+1 -> 7 | I26: =+H26+1 -> 8 | J26: =+I26+1 -> 9 | K26: =+J26+1 -> 10 | L26: =+K26+1 -> 11 | M26: =+L26+1 -> 12 | ... BM26: =+BL26+1 -> 64
D27: Months | E27: =HAVERD!D$1 -> Overnight | F27: =HAVERD!E$1 -> 1 | G27: =HAVERD!F$1 -> 2 | H27: =HAVERD!G$1 -> 3 | I27: =HAVERD!H$1 -> 4 | J27: =HAVERD!I$1 -> 5 | K27: =HAVERD!J$1 -> 6 | L27: =HAVERD!K$1 -> 7 | ... BM27: =HAVERD!BL$1 -> 60
D28: Days | F28: 30.416667 | G28: =+F28+30.4166667 -> 60.833333 | H28: =+G28+30.4166667 -> 91.25 | I28: =+H28+30.4166667 -> 121.66667 | J28: =+I28+30.4166667 -> 152.08333 | K28: =+J28+30.4166667 -> 182.5 | L28: =+K28+30.4166667 -> 212.91667 | M28: =+L28+30.4166667 -> 243.33333 | N28: =+M28+30.4166667 -> 273.75 | ... BM28: =+BL28+30.4166667 -> 1825
E29: =D31 -> 45399 | F29: =$E29+F28 -> 45429.417 | G29: =$E29+G28 -> 45459.833 | H29: =$E29+H28 -> 45490.25 | I29: =$E29+I28 -> 45520.667 | J29: =$E29+J28 -> 45551.083 | K29: =$E29+K28 -> 45581.5 | L29: =$E29+L28 -> 45611.917 | M29: =$E29+M28 -> 45642.333 | ... BM29: =$E29+BM28 -> 47224
E30: =EOMONTH(E29,0) -> 45412 | F30: =EOMONTH(F29,0) -> 45443 | G30: =EOMONTH(G29,0) -> 45473 | H30: =EOMONTH(H29,0) -> 45504 | I30: =EOMONTH(I29,0) -> 45535 | J30: =EOMONTH(J29,0) -> 45565 | K30: =EOMONTH(K29,0) -> 45596 | L30: =EOMONTH(L29,0) -> 45626 | ... BM30: =EOMONTH(BM29,0) -> 47238
D31: 45399 | E31: =VLOOKUP($D31,HAVERD!$A:$BL,E26,FALSE) -> 5.1984 | F31: =VLOOKUP($D31,HAVERD!$A:$BL,F26,FALSE) -> 5.1864649 | G31: =VLOOKUP($D31,HAVERD!$A:$BL,G26,FALSE) -> 5.1406635 | H31: =VLOOKUP($D31,HAVERD!$A:$BL,H26,FALSE) -> 5.082378 | I31: =VLOOKUP($D31,HAVERD!$A:$BL,I26,FALSE) -> 5.0182776 | J31: =VLOOKUP($D31,HAVERD!$A:$BL,J26,FALSE) -> 4.953339 | K31: =VLOOKUP($D31,HAVERD!$A:$BL,K26,FALSE) -> 4.8893764 | L31: =VLOOKUP($D31,HAVERD!$A:$BL,L26,FALSE) -> 4.8279117 | ... BM31: =VLOOKUP($D31,HAVERD!$A:$BL,BM26,FALSE) -> 3.544147
D32: Diff vs today | F32: =F31-$E$31 -> -0.0119351 | G32: =G31-$E$31 -> -0.0577365 | H32: =H31-$E$31 -> -0.116022 | I32: =I31-$E$31 -> -0.1801224 | J32: =J31-$E$31 -> -0.245061 | K32: =K31-$E$31 -> -0.3090236 | L32: =L31-$E$31 -> -0.3704883 | M32: =M31-$E$31 -> -0.4276804 | ... BM32: =BM31-$E$31 -> -1.654253
E34: =E2 -> 43466 | F34: =F2 -> 43497 | G34: =G2 -> 43525 | H34: =H2 -> 43556 | I34: =I2 -> 43586 | J34: =J2 -> 43617 | K34: =K2 -> 43647 | L34: =L2 -> 43678 | ... BX34: =BX2 -> 45627
E35: =E34+30 -> 43496 | F35: =F34+30 -> 43527 | G35: =G34+30 -> 43555 | H35: =H34+30 -> 43586 | I35: =I34+30 -> 43616 | J35: =J34+30 -> 43647 | K35: =K34+30 -> 43677 | L35: =L34+30 -> 43708 | ... BX35: =BX34+30 -> 45657
D36: OE forecast | E36: =VLOOKUP(E34,Data!$A:$D,4,FALSE) -> 0.75 | F36: =VLOOKUP(F34,Data!$A:$D,4,FALSE) -> #N/A | G36: =VLOOKUP(G34,Data!$A:$D,4,FALSE) -> #N/A | H36: =VLOOKUP(H34,Data!$A:$D,4,FALSE) -> 0.75 | I36: =VLOOKUP(I34,Data!$A:$D,4,FALSE) -> #N/A | J36: =VLOOKUP(J34,Data!$A:$D,4,FALSE) -> #N/A | K36: =VLOOKUP(K34,Data!$A:$D,4,FALSE) -> 0.75 | L36: =VLOOKUP(L34,Data!$A:$D,4,FALSE) -> #N/A | ... BX36: =VLOOKUP(BX34,Data!$A:$D,4,FALSE) -> #N/A
H38: =AVERAGE(K31:M31) -> 4.8293359
B39: % chance of 25bps hike at next meeting | E39: =(F31-E31)/0.25 -> -0.0477404
B40: % chance of 50bps hike at next meeting | E40: =(F31-E31-0.25)/0.25 -> -1.0477404
B42: max % chance of another hike | E42: =((MAX(F31:Q31)-E31)/0.25) -> -0.0477404
B44: % chance of 25bps cut by mid-2024 | E44: =(L31-E31)/-0.25 -> 1.4819532
B45: % chance of 25bps cut by end-2024 | E45: =(R31-E31)/-0.25 -> 2.549412

Sheet HAVERQ
B1: 20151 !Q | C1: UKVCP@UK | D1: R112RD@INTDAILY
B2: .DESC | C2: UK: BoE Conditioning Path for Market Interest Rates (%) | D2: United Kingdom: Official Bank Rate (%)
B3: .T1 | C3: Q1-2024 | D3: Q1-1953 <- 01-Jan-1953
B4: .TN | C4: Q2-2027 | D4: Q1-2024 <- 17-Apr-2024
B5: .LSOURCE | C5: Bank of England | D5: Bank of England
B6: .DTLM | C6: Feb-01-2024 12:10 | D6: Apr-17-2024 13:57
A7: 42005 | B7: 20151 | C7: #N/A | D7: 0.5
A8: 42095 | B8: 20152 | C8: #N/A | D8: 0.5
A9: 42186 | B9: 20153 | C9: #N/A | D9: 0.5
A10: 42278 | B10: 20154 | C10: #N/A | D10: 0.5
A11: 42370 | B11: 20161 | C11: #N/A | D11: 0.5
A12: 42461 | B12: 20162 | C12: #N/A | D12: 0.5
A13: 42552 | B13: 20163 | C13: #N/A | D13: 0.34090909
A14: 42644 | B14: 20164 | C14: #N/A | D14: 0.25
A15: 42736 | B15: 20171 | C15: #N/A | D15: 0.25
A16: 42826 | B16: 20172 | C16: #N/A | D16: 0.25
A17: 42917 | B17: 20173 | C17: #N/A | D17: 0.25
A18: 43009 | B18: 20174 | C18: #N/A | D18: 0.41153846
... A42: 45200 | B42: 20234 | C42: #N/A | D42: 5.25
A43: 45292 | B43: 20241 | C43: 5.11 | D43: 5.25
A44: 45383 | B44: 20242 | C44: 5.02
A45: 45474 | B45: 20243 | C45: 4.63
A46: 45566 | B46: 20244 | C46: 4.22
A47: 45658 | B47: 20251 | C47: 3.92
A48: 45748 | B48: 20252 | C48: 3.7
A49: 45839 | B49: 20253 | C49: 3.52
A50: 45931 | B50: 20254 | C50: 3.4
A51: 46023 | B51: 20261 | C51: 3.31
A52: 46113 | B52: 20262 | C52: 3.25
A53: 46204 | B53: 20263 | C53: 3.21
A54: 46296 | B54: 20264 | C54: 3.18
A55: 46388 | B55: 20271 | C55: 3.17
A56: 46478 | B56: 20272 | C56: 3.16

Sheet HAVERD
C1: Bank Rate | D1: Overnight | E1: 1 | F1: 2 | G1: 3 | H1: 4 | I1: 5 | J1: 6 | K1: 7 | L1: 8 | M1: 9 | N1: 10 | O1: 11 | P1: 12 | Q1: 13 | R1: 14 | S1: 15 | T1: 16 | U1: 17 | V1: 18 | W1: 19 | X1: 20 | Y1: 21 | Z1: 22 | AA1: 23 | AB1: 24 | AC1: 25 | AD1: 26 | AE1: 27 | AF1: 28 | AG1: 29 | AH1: 30 | AI1: 31 | AJ1: 32 | AK1: 33 | AL1: 34 | AM1: 35 | AN1: 36 | AO1: 37 | AP1: 38 | AQ1: 39 | AR1: 40 | AS1: 41 | AT1: 42 | AU1: 43 | AV1: 44 | AW1: 45 | AX1: 46 | AY1: 47 | AZ1: 48 | BA1: 49 | BB1: 50 | BC1: 51 | BD1: 52 | BE1: 53 | BF1: 54 | BG1: 55 | BH1: 56 | BI1: 57 | BJ1: 58 | BK1: 59 | BL1: 60 | BM1: 5.5yrs | BN1: 6yrs
B2: 20190101 !D | C2: R112RD@INTDAILY | D2: R112LOS@INTDAILY | E2: R11201F@INTDAILY | F2: R11202F@INTDAILY | G2: R11203F@INTDAILY | H2: R11204F@INTDAILY | I2: R11205F@INTDAILY | J2: R11206F@INTDAILY | K2: R11207F@INTDAILY | L2: R11208F@INTDAILY | M2: R11209F@INTDAILY | N2: R11210F@INTDAILY | O2: R11211F@INTDAILY | P2: R11212F@INTDAILY | Q2: R11213F@INTDAILY | R2: R11214F@INTDAILY | S2: R11215F@INTDAILY | T2: R11216F@INTDAILY | U2: R11217F@INTDAILY | V2: R11218F@INTDAILY | W2: R11219F@INTDAILY | X2: R11220F@INTDAILY | Y2: R11221F@INTDAILY | Z2: R11222F@INTDAILY | AA2: R11223F@INTDAILY | AB2: R11224F@INTDAILY | AC2: R11225F@INTDAILY | AD2: R11226F@INTDAILY | AE2: R11227F@INTDAILY | AF2: R11228F@INTDAILY | AG2: R11229F@INTDAILY | AH2: R11230F@INTDAILY | AI2: R11231F@INTDAILY | AJ2: R11232F@INTDAILY | AK2: R11233F@INTDAILY | AL2: R11234F@INTDAILY | AM2: R11235F@INTDAILY | AN2: R11236F@INTDAILY | AO2: R11237F@INTDAILY | AP2: R11238F@INTDAILY | AQ2: R11239F@INTDAILY | AR2: R11240F@INTDAILY | AS2: R11241F@INTDAILY | AT2: R11242F@INTDAILY | AU2: R11243F@INTDAILY | AV2: R11244F@INTDAILY | AW2: R11245F@INTDAILY | AX2: R11246F@INTDAILY | AY2: R11247F@INTDAILY | AZ2: R11248F@INTDAILY | BA2: R11249F@INTDAILY | BB2: R11250F@INTDAILY | BC2: R11251F@INTDAILY | BD2: R11252F@INTDAILY | BE2: R11253F@INTDAILY | BF2: R11254F@INTDAILY | BG2: R11255F@INTDAILY | BH2: R11256F@INTDAILY | BI2: R11257F@INTDAILY | BJ2: R11258F@INTDAILY | BK2: R11259F@INTDAILY | BL2: R11260F@INTDAILY | BM2: R112I5B@INTDAILY | BN2: R112I6A@INTDAILY
B3: .DESC | C3: United Kingdom: Official Bank Rate (%) | D3: UK:Lending Rate: Sterling Overnight Interbank Average [SONIA] (% pa) | E3: UK: Overnight Index Swap: Forward Yields, 1-Month (% p.a.) | F3: UK: Overnight Index Swap: Forward Yields, 2-Month (% p.a.) | G3: UK: Overnight Index Swap: Forward Yields, 3-Month (% p.a.) | H3: UK: Overnight Index Swap: Forward Yields, 4-Month (% p.a.) | I3: UK: Overnight Index Swap: Forward Yields, 5-Month (% p.a.) | J3: UK: Overnight Index Swap: Forward Yields, 6-Month (% p.a.) | K3: UK: Overnight Index Swap: Forward Yields, 7-Month (% p.a.) | L3: UK: Overnight Index Swap: Forward Yields, 8-Month (% p.a.) | M3: UK: Overnight Index Swap: Forward Yields, 9-Month (% p.a.) | N3: UK: Overnight Index Swap: Forward Yields, 10-Month (% p.a.) | O3: UK: Overnight Index Swap: Forward Yields, 11-Month (% p.a.) | P3: UK: Overnight Index Swap: Forward Yields, 12-Month (% p.a.) | Q3: UK: Overnight Index Swap: Forward Yields, 13-Month (% p.a.) | R3: UK: Overnight Index Swap: Forward Yields, 14-Month (% p.a.) | S3: UK: Overnight Index Swap: Forward Yields, 15-Month (% p.a.) | T3: UK: Overnight Index Swap: Forward Yields, 16-Month (% p.a.) | U3: UK: Overnight Index Swap: Forward Yields, 17-Month (% p.a.) | V3: UK: Overnight Index Swap: Forward Yields, 18-Month (% p.a.) | W3: UK: Overnight Index Swap: Forward Yields, 19-Month (% p.a.) | X3: UK: Overnight Index Swap: Forward Yields, 20-Month (% p.a.) | Y3: UK: Overnight Index Swap: Forward Yields, 21-Month (% p.a.) | Z3: UK: Overnight Index Swap: Forward Yields, 22-Month (% p.a.) | AA3: UK: Overnight Index Swap: Forward Yields, 23-Month (% p.a.) | AB3: UK: Overnight Index Swap: Forward Yields, 24-Month (% p.a.) | AC3: UK: Overnight Index Swap: Forward Yields, 25-Month (% p.a.) | AD3: UK: Overnight Index Swap: Forward Yields, 26-Month (% p.a.) | AE3: UK: Overnight Index Swap: Forward Yields, 27-Month (% p.a.) | AF3: UK: Overnight Index Swap: Forward Yields, 28-Month (% p.a.) | AG3: UK: Overnight Index Swap: Forward Yields, 29-Month (% p.a.) | AH3: UK: Overnight Index Swap: Forward Yields, 30-Month (% p.a.) | AI3: UK: Overnight Index Swap: Forward Yields, 31-Month (% p.a.) | AJ3: UK: Overnight Index Swap: Forward Yields, 32-Month (% p.a.) | AK3: UK: Overnight Index Swap: Forward Yields, 33-Month (% p.a.) | AL3: UK: Overnight Index Swap: Forward Yields, 34-Month (% p.a.) | AM3: UK: Overnight Index Swap: Forward Yields, 35-Month (% p.a.) | AN3: UK: Overnight Index Swap: Forward Yields, 36-Month (% p.a.) | AO3: UK: Overnight Index Swap: Forward Yields, 37-Month (% p.a.) | AP3: UK: Overnight Index Swap: Forward Yields, 38-Month (% p.a.) | AQ3: UK: Overnight Index Swap: Forward Yields, 39-Month (% p.a.) | AR3: UK: Overnight Index Swap: Forward Yields, 40-Month (% p.a.) | AS3: UK: Overnight Index Swap: Forward Yields, 41-Month (% p.a.) | AT3: UK: Overnight Index Swap: Forward Yields, 42-Month (% p.a.) | AU3: UK: Overnight Index Swap: Forward Yields, 43-Month (% p.a.) | AV3: UK: Overnight Index Swap: Forward Yields, 44-Month (% p.a.) | AW3: UK: Overnight Index Swap: Forward Yields, 45-Month (% p.a.) | AX3: UK: Overnight Index Swap: Forward Yields, 46-Month (% p.a.) | AY3: UK: Overnight Index Swap: Forward Yields, 47-Month (% p.a.) | AZ3: UK: Overnight Index Swap: Forward Yields, 48-Month (% p.a.) | BA3: UK: Overnight Index Swap: Forward Yields, 49-Month (% p.a.) | BB3: UK: Overnight Index Swap: Forward Yields, 50-Month (% p.a.) | BC3: UK: Overnight Index Swap: Forward Yields, 51-Month (% p.a.) | BD3: UK: Overnight Index Swap: Forward Yields, 52-Month (% p.a.) | BE3: UK: Overnight Index Swap: Forward Yields, 53-Month (% p.a.) | BF3: UK: Overnight Index Swap: Forward Yields, 54-Month (% p.a.) | BG3: UK: Overnight Index Swap: Forward Yields, 55-Month (% p.a.) | BH3: UK: Overnight Index Swap: Forward Yields, 56-Month (% p.a.) | BI3: UK: Overnight Index Swap: Forward Yields, 57-Month (% p.a.) | BJ3: UK: Overnight Index Swap: Forward Yields, 58-Month (% p.a.) | BK3: UK: Overnight Index Swap: Forward Yields, 59-Month (% p.a.) | BL3: UK: Overnight Index Swap: Forward Yields, 60-Month (% p.a.) | BM3: UK: Overnight Index Swap: Forward Yields, 5.5-Year (% p.a.) | BN3: UK: Overnight Index Swap: Forward Yields, 6-Year (% p.a.)
B4: .T1 | C4: 01-Jan-1953 | D4: 02-Jan-1997 | E4: 02-Jan-2009 | F4: 02-Jan-2009 | G4: 02-Jan-2009 | H4: 02-Jan-2009 | I4: 02-Jan-2009 | J4: 02-Jan-2009 | K4: 02-Jan-2009 | L4: 02-Jan-2009 | M4: 02-Jan-2009 | N4: 02-Jan-2009 | O4: 02-Jan-2009 | P4: 02-Jan-2009 | Q4: 02-Jan-2009 | R4: 02-Jan-2009 | S4: 02-Jan-2009 | T4: 02-Jan-2009 | U4: 02-Jan-2009 | V4: 02-Jan-2009 | W4: 02-Jan-2009 | X4: 02-Jan-2009 | Y4: 02-Jan-2009 | Z4: 02-Jan-2009 | AA4: 02-Jan-2009 | AB4: 02-Jan-2009 | AC4: 02-Jan-2009 | AD4: 02-Jan-2009 | AE4: 02-Jan-2009 | AF4: 02-Jan-2009 | AG4: 02-Jan-2009 | AH4: 02-Jan-2009 | AI4: 02-Jan-2009 | AJ4: 02-Jan-2009 | AK4: 02-Jan-2009 | AL4: 02-Jan-2009 | AM4: 02-Jan-2009 | AN4: 02-Jan-2009 | AO4: 02-Jan-2009 | AP4: 02-Jan-2009 | AQ4: 02-Jan-2009 | AR4: 02-Jan-2009 | AS4: 02-Jan-2009 | AT4: 02-Jan-2009 | AU4: 02-Jan-2009 | AV4: 02-Jan-2009 | AW4: 02-Jan-2009 | AX4: 02-Jan-2009 | AY4: 02-Jan-2009 | AZ4: 02-Jan-2009 | BA4: 02-Jan-2009 | BB4: 02-Jan-2009 | BC4: 02-Jan-2009 | BD4: 02-Jan-2009 | BE4: 02-Jan-2009 | BF4: 02-Jan-2009 | BG4: 02-Jan-2009 | BH4: 02-Jan-2009 | BI4: 02-Jan-2009 | BJ4: 02-Jan-2009 | BK4: 02-Jan-2009 | BL4: 02-Jan-2009 | BM4: 01-Dec-2021 | BN4: 01-Dec-2021
B5: .TN | C5: 18-Apr-2024 | D5: 17-Apr-2024 | E5: 17-Apr-2024 | F5: 17-Apr-2024 | G5: 17-Apr-2024 | H5: 17-Apr-2024 | I5: 17-Apr-2024 | J5: 17-Apr-2024 | K5: 17-Apr-2024 | L5: 17-Apr-2024 | M5: 17-Apr-2024 | N5: 17-Apr-2024 | O5: 17-Apr-2024 | P5: 17-Apr-2024 | Q5: 17-Apr-2024 | R5: 17-Apr-2024 | S5: 17-Apr-2024 | T5: 17-Apr-2024 | U5: 17-Apr-2024 | V5: 17-Apr-2024 | W5: 17-Apr-2024 | X5: 17-Apr-2024 | Y5: 17-Apr-2024 | Z5: 17-Apr-2024 | AA5: 17-Apr-2024 | AB5: 17-Apr-2024 | AC5: 17-Apr-2024 | AD5: 17-Apr-2024 | AE5: 17-Apr-2024 | AF5: 17-Apr-2024 | AG5: 17-Apr-2024 | AH5: 17-Apr-2024 | AI5: 17-Apr-2024 | AJ5: 17-Apr-2024 | AK5: 17-Apr-2024 | AL5: 17-Apr-2024 | AM5: 17-Apr-2024 | AN5: 17-Apr-2024 | AO5: 17-Apr-2024 | AP5: 17-Apr-2024 | AQ5: 17-Apr-2024 | AR5: 17-Apr-2024 | AS5: 17-Apr-2024 | AT5: 17-Apr-2024 | AU5: 17-Apr-2024 | AV5: 17-Apr-2024 | AW5: 17-Apr-2024 | AX5: 17-Apr-2024 | AY5: 17-Apr-2024 | AZ5: 17-Apr-2024 | BA5: 17-Apr-2024 | BB5: 17-Apr-2024 | BC5: 17-Apr-2024 | BD5: 17-Apr-2024 | BE5: 17-Apr-2024 | BF5: 17-Apr-2024 | BG5: 17-Apr-2024 | BH5: 17-Apr-2024 | BI5: 17-Apr-2024 | BJ5: 17-Apr-2024 | BK5: 17-Apr-2024 | BL5: 17-Apr-2024 | BM5: 17-Apr-2024 | BN5: 17-Apr-2024
B6: .LSOURCE | C6: Bank of England | D6: Bank of England | E6: Bank of England | F6: Bank of England | G6: Bank of England | H6: Bank of England | I6: Bank of England | J6: Bank of England | K6: Bank of England | L6: Bank of England | M6: Bank of England | N6: Bank of England | O6: Bank of England | P6: Bank of England | Q6: Bank of England | R6: Bank of England | S6: Bank of England | T6: Bank of England | U6: Bank of England | V6: Bank of England | W6: Bank of England | X6: Bank of England | Y6: Bank of England | Z6: Bank of England | AA6: Bank of England | AB6: Bank of England | AC6: Bank of England | AD6: Bank of England | AE6: Bank of England | AF6: Bank of England | AG6: Bank of England | AH6: Bank of England | AI6: Bank of England | AJ6: Bank of England | AK6: Bank of England | AL6: Bank of England | AM6: Bank of England | AN6: Bank of England | AO6: Bank of England | AP6: Bank of England | AQ6: Bank of England | AR6: Bank of England | AS6: Bank of England | AT6: Bank of England | AU6: Bank of England | AV6: Bank of England | AW6: Bank of England | AX6: Bank of England | AY6: Bank of England | AZ6: Bank of England | BA6: Bank of England | BB6: Bank of England | BC6: Bank of England | BD6: Bank of England | BE6: Bank of England | BF6: Bank of England | BG6: Bank of England | BH6: Bank of England | BI6: Bank of England | BJ6: Bank of England | BK6: Bank of England | BL6: Bank of England | BM6: Bank of England | BN6: Bank of England
B7: .DTLM | C7: Apr-18-2024 13:57 | D7: Apr-19-2024 09:39 | E7: Apr-18-2024 11:47 | F7: Apr-18-2024 11:47 | G7: Apr-18-2024 11:47 | H7: Apr-18-2024 11:47 | I7: Apr-18-2024 11:47 | J7: Apr-18-2024 11:47 | K7: Apr-18-2024 11:47 | L7: Apr-18-2024 11:47 | M7: Apr-18-2024 11:47 | N7: Apr-18-2024 11:47 | O7: Apr-18-2024 11:47 | P7: Apr-18-2024 11:47 | Q7: Apr-18-2024 11:47 | R7: Apr-18-2024 11:47 | S7: Apr-18-2024 11:47 | T7: Apr-18-2024 11:47 | U7: Apr-18-2024 11:47 | V7: Apr-18-2024 11:47 | W7: Apr-18-2024 11:47 | X7: Apr-18-2024 11:47 | Y7: Apr-18-2024 11:47 | Z7: Apr-18-2024 11:47 | AA7: Apr-18-2024 11:47 | AB7: Apr-18-2024 11:47 | AC7: Apr-18-2024 11:47 | AD7: Apr-18-2024 11:47 | AE7: Apr-18-2024 11:47 | AF7: Apr-18-2024 11:47 | AG7: Apr-18-2024 11:47 | AH7: Apr-18-2024 11:47 | AI7: Apr-18-2024 11:47 | AJ7: Apr-18-2024 11:47 | AK7: Apr-18-2024 11:47 | AL7: Apr-18-2024 11:47 | AM7: Apr-18-2024 11:47 | AN7: Apr-18-2024 11:47 | AO7: Apr-18-2024 11:47 | AP7: Apr-18-2024 11:47 | AQ7: Apr-18-2024 11:47 | AR7: Apr-18-2024 11:47 | AS7: Apr-18-2024 11:47 | AT7: Apr-18-2024 11:47 | AU7: Apr-18-2024 11:47 | AV7: Apr-18-2024 11:47 | AW7: Apr-18-2024 11:47 | AX7: Apr-18-2024 11:47 | AY7: Apr-18-2024 11:47 | AZ7: Apr-18-2024 11:47 | BA7: Apr-18-2024 11:47 | BB7: Apr-18-2024 11:47 | BC7: Apr-18-2024 11:47 | BD7: Apr-18-2024 11:47 | BE7: Apr-18-2024 11:47 | BF7: Apr-18-2024 11:47 | BG7: Apr-18-2024 11:47 | BH7: Apr-18-2024 11:47 | BI7: Apr-18-2024 11:47 | BJ7: Apr-18-2024 11:47 | BK7: Apr-18-2024 11:47 | BL7: Apr-18-2024 11:47 | BM7: Apr-18-2024 11:47 | BN7: Apr-18-2024 11:47
A8: 43466 | B8: 20190101 | C8: 0.75 | D8: #N/A | E8: #N/A | F8: #N/A | G8: #N/A | H8: #N/A | I8: #N/A | J8: #N/A | K8: #N/A | L8: #N/A | M8: #N/A | N8: #N/A | O8: #N/A | P8: #N/A | Q8: #N/A | R8: #N/A | S8: #N/A | T8: #N/A | U8: #N/A | V8: #N/A | W8: #N/A | X8: #N/A | Y8: #N/A | Z8: #N/A | AA8: #N/A | AB8: #N/A | AC8: #N/A | AD8: #N/A | AE8: #N/A | AF8: #N/A | AG8: #N/A | AH8: #N/A | AI8: #N/A | AJ8: #N/A | AK8: #N/A | AL8: #N/A | AM8: #N/A | AN8: #N/A | AO8: #N/A | AP8: #N/A | AQ8: #N/A | AR8: #N/A | AS8: #N/A | AT8: #N/A | AU8: #N/A | AV8: #N/A | AW8: #N/A | AX8: #N/A | AY8: #N/A | AZ8: #N/A | BA8: #N/A | BB8: #N/A | BC8: #N/A | BD8: #N/A | BE8: #N/A | BF8: #N/A | BG8: #N/A | BH8: #N/A | BI8: #N/A | BJ8: #N/A | BK8: #N/A | BL8: #N/A | BM8: #N/A | BN8: #N/A
A9: 43467 | B9: 20190102 | C9: 0.75 | D9: 0.7044 | E9: 0.7032037 | F9: 0.7089814 | G9: 0.7192978 | H9: 0.7353211 | I9: 0.7536458 | J9: 0.77078 | K9: 0.7854065 | L9: 0.7981328 | M9: 0.8098529 | N9: 0.8209815 | O9: 0.8316713 | P9: 0.8418998 | Q9: 0.851558 | R9: 0.8606768 | S9: 0.8693273 | T9: 0.8775809 | U9: 0.8855087 | V9: 0.893182 | W9: 0.9006669 | X9: 0.9080101 | Y9: 0.9152537 | Z9: 0.9224399 | AA9: 0.9296107 | AB9: 0.9368084 | AC9: 0.9440669 | AD9: 0.9513769 | AE9: 0.9587144 | AF9: 0.9660556 | AG9: 0.9733765 | AH9: 0.9806532 | AI9: 0.9878617 | AJ9: 0.9949782 | AK9: 1.0019787 | AL9: 1.0088393 | AM9: 1.0155361 | AN9: 1.022045 | AO9: 1.0283462 | AP9: 1.0344397 | AQ9: 1.0403331 | AR9: 1.0460334 | AS9: 1.0515479 | AT9: 1.0568839 | AU9: 1.0620486 | AV9: 1.0670493 | AW9: 1.0718931 | AX9: 1.0765875 | AY9: 1.0811395 | AZ9: 1.0855565 | BA9: 1.0898463 | BB9: 1.0940202 | BC9: 1.0980905 | BD9: 1.1020692 | BE9: 1.1059688 | BF9: 1.1098013 | BG9: 1.113579 | BH9: 1.1173141 | BI9: 1.1210189 | BJ9: 1.1247056 | BK9: 1.1283864 | BL9: 1.1320734 | BM9: #N/A | BN9: #N/A
A10: 43468 | B10: 20190103 | C10: 0.75 | D10: 0.7048 | E10: 0.7029977 | F10: 0.7134649 | G10: 0.7220919 | H10: 0.7312484 | I10: 0.7411584 | J10: 0.7502592 | K10: 0.7584658 | L10: 0.7669758 | M10: 0.7771158 | N10: 0.7894951 | O10: 0.8038593 | P10: 0.8194246 | Q10: 0.8349995 | R10: 0.8500425 | S10: 0.8642063 | T10: 0.8771435 | U10: 0.8885068 | V10: 0.8979489 | W10: 0.9052608 | X10: 0.91076 | Y10: 0.9148892 | Z10: 0.9180913 | AA10: 0.9208089 | AB10: 0.9234851 | AC10: 0.9264988 | AD10: 0.9299195 | AE10: 0.9337221 | AF10: 0.9378816 | AG10: 0.9423731 | AH10: 0.9471714 | AI10: 0.9522516 | AJ10: 0.9575887 | AK10: 0.9631576 | AL10: 0.9689334 | AM10: 0.974891 | AN10: 0.9810054 | AO10: 0.9872514 | AP10: 0.9936023 | AQ10: 1.0000313 | AR10: 1.0065114 | AS10: 1.0130157 | AT10: 1.0195173 | AU10: 1.0259892 | AV10: 1.0324045 | AW10: 1.0387362 | AX10: 1.0449575 | AY10: 1.0510414 | AZ10: 1.0569609 | BA10: 1.0626951 | BB10: 1.0682489 | BC10: 1.0736345 | BD10: 1.0788641 | BE10: 1.0839498 | BF10: 1.0889038 | BG10: 1.0937383 | BH10: 1.0984655 | BI10: 1.1030975 | BJ10: 1.1076466 | BK10: 1.1121248 | BL10: 1.1165444 | BM10: #N/A | BN10: #N/A
A11: 43469 | B11: 20190104 | C11: 0.75 | D11: 0.7046 | E11: 0.6992401 | F11: 0.7090764 | G11: 0.7218147 | H11: 0.7380887 | I11: 0.7560536 | J11: 0.7731404 | K11: 0.7887358 | L11: 0.802927 | M11: 0.8163037 | N11: 0.8295201 | O11: 0.8424828 | P11: 0.8548654 | Q11: 0.866152 | R11: 0.8763547 | S11: 0.8856695 | T11: 0.8942924 | U11: 0.9024193 | V11: 0.9102462 | W11: 0.9179469 | X11: 0.9255922 | Y11: 0.933223 | Z11: 0.94088 | AA11: 0.9486044 | AB11: 0.9564369 | AC11: 0.9644078 | AD11: 0.9725004 | AE11: 0.9806852 | AF11: 0.9889326 | AG11: 0.9972128 | AH11: 1.0054964 | AI11: 1.0137537 | AJ11: 1.021955 | AK11: 1.0300709 | AL11: 1.0380716 | AM11: 1.0459276 | AN11: 1.0536093 | AO11: 1.0610922 | AP11: 1.0683756 | AQ11: 1.0754647 | AR11: 1.0823652 | AS11: 1.0890824 | AT11: 1.0956218 | AU11: 1.1019889 | AV11: 1.1081892 | AW11: 1.1142281 | AX11: 1.1201111 | AY11: 1.1258436 | AZ11: 1.1314312 | BA11: 1.1368797 | BB11: 1.1421971 | BC11: 1.1473919 | BD11: 1.1524728 | BE11: 1.1574481 | BF11: 1.1623265 | BG11: 1.1671165 | BH11: 1.1718265 | BI11: 1.1764652 | BJ11: 1.1810411 | BK11: 1.1855626 | BL11: 1.1900384 | BM11: #N/A | BN11: #N/A
A12: 43472 | B12: 20190107 | C12: 0.75 | D12: 0.7052 | E12: 0.7021822 | F12: 0.7085778 | G12: 0.7176464 | H12: 0.7311107 | I12: 0.7476524 | J12: 0.7655477 | K12: 0.7833081 | L12: 0.7997056 | M12: 0.8142545 | N12: 0.8272766 | O12: 0.8391977 | P12: 0.8503747 | Q12: 0.8610767 | R12: 0.8713862 | S12: 0.8813415 | T12: 0.8909811 | U12: 0.9003433 | V12: 0.9094664 | W12: 0.918385 | X12: 0.9271185 | Y12: 0.9356833 | Z12: 0.9440951 | AA12: 0.9523703 | AB12: 0.9605248 | AC12: 0.9685715 | AD12: 0.9765085 | AE12: 0.98433 | AF12: 0.9920302 | AG12: 0.9996034 | AH12: 1.0070436 | AI12: 1.0143452 | AJ12: 1.0215022 | AK12: 1.028509 | AL12: 1.0353596 | AM12: 1.0420483 | AN12: 1.0485693 | AO12: 1.054919 | AP12: 1.061104 | AQ12: 1.0671334 | AR12: 1.0730167 | AS12: 1.078763 | AT12: 1.0843817 | AU12: 1.0898819 | AV12: 1.0952731 | AW12: 1.1005644 | AX12: 1.1057651 | AY12: 1.1108846 | AZ12: 1.115932 | BA12: 1.1209161 | BB12: 1.1258429 | BC12: 1.1307171 | BD12: 1.1355437 | BE12: 1.1403275 | BF12: 1.1450735 | BG12: 1.1497865 | BH12: 1.1544715 | BI12: 1.1591333 | BJ12: 1.1637768 | BK12: 1.168407 | BL12: 1.1730286 | BM12: #N/A | BN12: #N/A
A13: =+A8+7 -> 43473 | B13: 20190108 | C13: 0.75 | D13: 0.7052 | E13: 0.7060108 | F13: 0.719186 | G13: 0.7330512 | H13: 0.7475804 | I13: 0.7622457 | J13: 0.7759024 | K13: 0.7885108 | L13: 0.80098 | M13: 0.814182 | N13: 0.8284588 | O13: 0.8436717 | P13: 0.8593748 | Q13: 0.874734 | R13: 0.8895048 | S13: 0.9036257 | T13: 0.9170353 | U13: 0.9296721 | V13: 0.9414748 | W13: 0.9524091 | X13: 0.9625446 | Y13: 0.9719753 | Z13: 0.9807954 | AA13: 0.9890992 | AB13: 0.9969807 | AC13: 1.004523 | AD13: 1.0117592 | AE13: 1.0187092 | AF13: 1.0253925 | AG13: 1.0318288 | AH13: 1.0380378 | AI13: 1.0440391 | AJ13: 1.0498523 | AK13: 1.0554972 | AL13: 1.0609933 | AM13: 1.0663604 | AN13: 1.071618 | AO13: 1.0767842 | AP13: 1.0818681 | AQ13: 1.0868759 | AR13: 1.0918136 | AS13: 1.0966875 | AT13: 1.1015036 | AU13: 1.1062682 | AV13: 1.1109873 | AW13: 1.115667 | AX13: 1.1203136 | AY13: 1.1249332 | AZ13: 1.1295319 | BA13: 1.1341153 | BB13: 1.1386869 | BC13: 1.1432491 | BD13: 1.1478046 | BE13: 1.152356 | BF13: 1.1569058 | BG13: 1.1614568 | BH13: 1.1660114 | BI13: 1.1705723 | BJ13: 1.1751422 | BK13: 1.1797235 | BL13: 1.1843189 | BM13: #N/A | BN13: #N/A
A14: =+A9+7 -> 43474 | B14: 20190109 | C14: 0.75 | D14: 0.7063 | E14: 0.7100109 | F14: 0.717848 | G14: 0.7308931 | H14: 0.748249 | I14: 0.7675985 | J14: 0.7857248 | K14: 0.8011893 | L14: 0.8148817 | M14: 0.8281324 | N14: 0.8417694 | O14: 0.8559673 | P14: 0.8704975 | Q14: 0.8846981 | R14: 0.8983226 | S14: 0.911259 | T14: 0.9233953 | U14: 0.9346197 | V14: 0.9448202 | W14: 0.9539359 | X14: 0.9621003 | Y14: 0.9694933 | Z14: 0.9762944 | AA14: 0.9826834 | AB14: 0.9888401 | AC14: 0.9949216 | AD14: 1.0009637 | AE14: 1.0069612 | AF14: 1.012909 | AG14: 1.0188021 | AH14: 1.0246353 | AI14: 1.0304035 | AJ14: 1.0361017 | AK14: 1.0417247 | AL14: 1.0472674 | AM14: 1.0527248 | AN14: 1.0580916 | AO14: 1.063364 | AP14: 1.0685431 | AQ14: 1.0736317 | AR14: 1.0786324 | AS14: 1.0835482 | AT14: 1.0883818 | AU14: 1.0931359 | AV14: 1.0978133 | AW14: 1.1024169 | AX14: 1.1069493 | AY14: 1.1114133 | AZ14: 1.1158118 | BA14: 1.120148 | BB14: 1.124428 | BC14: 1.1286582 | BD14: 1.1328455 | BE14: 1.1369963 | BF14: 1.1411173 | BG14: 1.1452152 | BH14: 1.1492965 | BI14: 1.153368 | BJ14: 1.1574362 | BK14: 1.1615078 | BL14: 1.1655893 | BM14: #N/A | BN14: #N/A
A15: =+A10+7 -> 43475 | B15: 20190110 | C15: 0.75 | D15: 0.7067 | E15: 0.7092429 | F15: 0.7151994 | G15: 0.7307526 | H15: 0.7538403 | I15: 0.778424 | J15: 0.8003983 | K15: 0.8189446 | L15: 0.8350739 | M15: 0.8500106 | N15: 0.8645 | O15: 0.8788374 | P15: 0.8930332 | Q15: 0.9068055 | R15: 0.9200691 | S15: 0.9328077 | T15: 0.9450046 | U15: 0.9566435 | V15: 0.9677078 | W15: 0.9781886 | X15: 0.988106 | Y15: 0.997487 | Z15: 1.0063584 | AA15: 1.0147473 | AB15: 1.0226804 | AC15: 1.0301848 | AD15: 1.0372869 | AE15: 1.0440131 | AF15: 1.0503898 | AG15: 1.0564435 | AH15: 1.0622006 | AI15: 1.0676874 | AJ15: 1.0729305 | AK15: 1.0779561 | AL15: 1.0827907 | AM15: 1.0874608 | AN15: 1.0919927 | AO15: 1.0964103 | AP15: 1.1007264 | AQ15: 1.1049508 | AR15: 1.1090931 | AS15: 1.113163 | AT15: 1.1171703 | AU15: 1.1211246 | AV15: 1.1250358 | AW15: 1.1289134 | AX15: 1.1327672 | AY15: 1.1366069 | AZ15: 1.1404423 | BA15: 1.1442818 | BB15: 1.1481289 | BC15: 1.1519853 | BD15: 1.1558531 | BE15: 1.1597342 | BF15: 1.1636304 | BG15: 1.1675437 | BH15: 1.1714761 | BI15: 1.1754294 | BJ15: 1.1794055 | BK15: 1.1834064 | BL15: 1.1874339 | BM15: #N/A | BN15: #N/A
A16: =+A11+7 -> 43476 | B16: 20190111 | C16: 0.75 | D16: 0.7072 | E16: 0.7050896 | F16: 0.7204684 | G16: 0.7386326 | H16: 0.7611365 | I16: 0.7850236 | J16: 0.8075052 | K16: 0.8278594 | L16: 0.8467033 | M16: 0.8647028 | N16: 0.8821459 | O16: 0.8990363 | P16: 0.9152555 | Q16: 0.9304334 | R16: 0.9445401 | S16: 0.9576738 | T16: 0.9699328 | U16: 0.9814153 | V16: 0.9922195 | W16: 1.0024351 | X16: 1.0121119 | Y16: 1.0212884 | Z16: 1.0300029 | AA16: 1.0382938 | AB16: 1.0461993 | AC16: 1.0537546 | AD16: 1.0609804 | AE16: 1.0678932 | AF16: 1.0745099 | AG16: 1.080847 | AH16: 1.0869212 | AI16: 1.0927492 | AJ16: 1.0983477 | AK16: 1.1037333 | AL16: 1.1089228 | AM16: 1.1139327 | AN16: 1.1187798 | AO16: 1.1234797 | AP16: 1.1280432 | AQ16: 1.1324799 | AR16: 1.1367994 | AS16: 1.1410112 | AT16: 1.1451249 | AU16: 1.1491501 | AV16: 1.1530963 | AW16: 1.1569731 | AX16: 1.16079 | AY16: 1.1645567 | AZ16: 1.1682827 | BA16: 1.1719765 | BB16: 1.1756418 | BC16: 1.1792811 | BD16: 1.1828967 | BE16: 1.1864912 | BF16: 1.1900669 | BG16: 1.1936263 | BH16: 1.1971717 | BI16: 1.2007057 | BJ16: 1.2042307 | BK16: 1.207749 | BL16: 1.2112632 | BM16: #N/A | BN16: #N/A
A17: =+A12+7 -> 43479 | B17: 20190114 | C17: 0.75 | D17: 0.7067 | E17: 0.7059616 | F17: 0.7186233 | G17: 0.7383395 | H17: 0.7634172 | I17: 0.7888004 | J17: 0.8111594 | K17: 0.8301639 | L17: 0.8472272 | M17: 0.8637093 | N17: 0.8803353 | O17: 0.8972885 | P17: 0.9144142 | Q17: 0.9313197 | R17: 0.9477735 | S17: 0.9636021 | T17: 0.9786321 | U17: 0.9926898 | V17: 1.0056019 | W17: 1.017253 | X17: 1.0277503 | Y17: 1.0372536 | Z17: 1.0459227 | AA17: 1.0539176 | AB17: 1.061398 | AC17: 1.0685029 | AD17: 1.0752793 | AE17: 1.0817485 | AF17: 1.087932 | AG17: 1.0938511 | AH17: 1.0995274 | AI17: 1.1049822 | AJ17: 1.110237 | AK17: 1.1153132 | AL17: 1.1202322 | AM17: 1.1250155 | AN17: 1.1296845 | AO17: 1.1342578 | AP17: 1.138742 | AQ17: 1.1431403 | AR17: 1.1474559 | AS17: 1.1516921 | AT17: 1.1558519 | AU17: 1.1599387 | AV17: 1.1639555 | AW17: 1.1679057 | AX17: 1.1717925 | AY17: 1.1756189 | AZ17: 1.1793882 | BA17: 1.1831043 | BB17: 1.1867745 | BC17: 1.1904073 | BD17: 1.194011 | BE17: 1.1975942 | BF17: 1.2011654 | BG17: 1.204733 | BH17: 1.2083055 | BI17: 1.2118914 | BJ17: 1.2154991 | BK17: 1.2191371 | BL17: 1.2228139 | BM17: #N/A | BN17: #N/A
A18: =+A13+7 -> 43480 | B18: 20190115 | C18: 0.75 | D18: 0.7057 | E18: 0.7075983 | F18: 0.7146432 | G18: 0.7305802 | H18: 0.7531417 | I18: 0.7781431 | J18: 0.8030225 | K18: 0.8264905 | L18: 0.847754 | M18: 0.8666674 | N18: 0.8835448 | O18: 0.8985829 | P18: 0.9119787 | Q18: 0.9240134 | R18: 0.9348995 | S18: 0.9448256 | T18: 0.9539805 | U18: 0.9625528 | V18: 0.9707312 | W18: 0.9786752 | X18: 0.9864341 | Y18: 0.9940306 | Z18: 1.0014875 | AA18: 1.0088276 | AB18: 1.0160735 | AC18: 1.0232431 | AD18: 1.0303309 | AE18: 1.0373255 | AF18: 1.0442153 | AG18: 1.0509888 | AH18: 1.0576345 | AI18: 1.0641407 | AJ18: 1.0704959 | AK18: 1.0766887 | AL18: 1.0827074 | AM18: 1.0885404 | AN18: 1.0941764 | AO18: 1.0996063 | AP18: 1.1048361 | AQ18: 1.1098762 | AR18: 1.1147375 | AS18: 1.1194305 | AT18: 1.1239659 | AU18: 1.1283544 | AV18: 1.1326066 | AW18: 1.1367332 | AX18: 1.1407448 | AY18: 1.1446521 | AZ18: 1.1484658 | BA18: 1.1521964 | BB18: 1.1558541 | BC18: 1.1594488 | BD18: 1.1629904 | BE18: 1.166489 | BF18: 1.1699545 | BG18: 1.173397 | BH18: 1.1768263 | BI18: 1.1802524 | BJ18: 1.1836854 | BK18: 1.1871352 | BL18: 1.1906118 | BM18: #N/A | BN18: #N/A
A19: =+A14+7 -> 43481 | B19: 20190116 | C19: 0.75 | D19: 0.7059 | E19: 0.7067978 | F19: 0.7136277 | G19: 0.7263814 | H19: 0.7462401 | I19: 0.7702967 | J19: 0.7954767 | K19: 0.8195382 | L19: 0.8415226 | M19: 0.8617163 | N19: 0.8808299 | O19: 0.8993795 | P19: 0.9175494 | Q19: 0.9352594 | R19: 0.9523534 | S19: 0.9686673 | T19: 0.9840371 | U19: 0.9982986 | V19: 1.0112877 | W19: 1.0229015 | X19: 1.0332696 | Y19: 1.0425773 | Z19: 1.0510095 | AA19: 1.0587513 | AB19: 1.0659879 | AC19: 1.072884 | AD19: 1.0794949 | AE19: 1.0858392 | AF19: 1.0919354 | AG19: 1.097802 | AH19: 1.1034576 | AI19: 1.1089208 | AJ19: 1.1142101 | AK19: 1.1193441 | AL19: 1.1243412 | AM19: 1.1292201 | AN19: 1.1339993 | AO19: 1.1386951 | AP19: 1.1433133 | AQ19: 1.1478565 | AR19: 1.1523272 | AS19: 1.1567278 | AT19: 1.161061 | AU19: 1.1653292 | AV19: 1.169535 | AW19: 1.173681 | AX19: 1.1777695 | AY19: 1.1818032 | AZ19: 1.1857846 | BA19: 1.1897169 | BB19: 1.1936063 | BC19: 1.1974599 | BD19: 1.2012849 | BE19: 1.2050882 | BF19: 1.2088769 | BG19: 1.2126582 | BH19: 1.2164391 | BI19: 1.2202267 | BJ19: 1.2240281 | BK19: 1.2278503 | BL19: 1.2317004 | BM19: #N/A | BN19: #N/A
A20: =+A15+7 -> 43482 | B20: 20190117 | C20: 0.75 | D20: 0.7055 | E20: 0.7048826 | F20: 0.7118953 | G20: 0.723907 | H20: 0.7410693 | I20: 0.7612425 | J20: 0.7822967 | K20: 0.8028857 | L20: 0.8227187 | M20: 0.8422505 | N20: 0.8619302 | O20: 0.8818122 | P20: 0.9016248 | Q20: 0.9207097 | R20: 0.9388784 | S20: 0.9560891 | T20: 0.9723003 | U20: 0.9874703 | V20: 1.0015575 | W20: 1.0145499 | X20: 1.0265488 | Y20: 1.0376821 | Z20: 1.048078 | AA20: 1.0578646 | AB20: 1.0671698 | AC20: 1.0761067 | AD20: 1.0847135 | AE20: 1.093006 | AF20: 1.1010001 | AG20: 1.1087115 | AH20: 1.1161559 | AI20: 1.1233492 | AJ20: 1.1303072 | AK20: 1.1370455 | AL20: 1.14358 | AM20: 1.1499265 | AN20: 1.1561007 | AO20: 1.1621171 | AP20: 1.1679844 | AQ20: 1.1737097 | AR20: 1.1793 | AS20: 1.1847624 | AT20: 1.1901041 | AU20: 1.1953321 | AV20: 1.2004535 | AW20: 1.2054755 | AX20: 1.210405 | AY20: 1.2152491 | AZ20: 1.220015 | BA20: 1.2247094 | BB20: 1.2293374 | BC20: 1.2339035 | BD20: 1.2384124 | BE20: 1.2428686 | BF20: 1.2472769 | BG20: 1.2516419 | BH20: 1.255968 | BI20: 1.2602601 | BJ20: 1.2645226 | BK20: 1.2687602 | BL20: 1.2729775 | BM20: #N/A | BN20: #N/A
A21: =+A16+7 -> 43483 | B21: 20190118 | C21: 0.75 | D21: 0.7059 | E21: 0.7088309 | F21: 0.7150154 | G21: 0.7268355 | H21: 0.7417879 | I21: 0.758287 | J21: 0.775822 | K21: 0.793983 | L21: 0.8124646 | M21: 0.8314704 | N21: 0.8511374 | O21: 0.8712017 | P21: 0.891161 | Q21: 0.9101356 | R21: 0.9279416 | S21: 0.9446456 | T21: 0.9603144 | U21: 0.9750148 | V21: 0.9888135 | W21: 1.0017839 | X21: 1.0140302 | Y21: 1.0256654 | Z21: 1.0368028 | AA21: 1.0475553 | AB21: 1.0580361 | AC21: 1.0683399 | AD21: 1.07848 | AE21: 1.0884474 | AF21: 1.098233 | AG21: 1.1078279 | AH21: 1.1172228 | AI21: 1.1264089 | AJ21: 1.135377 | AK21: 1.1441181 | AL21: 1.1526232 | AM21: 1.1608832 | AN21: 1.168889 | AO21: 1.1766342 | AP21: 1.1841235 | AQ21: 1.1913648 | AR21: 1.198366 | AS21: 1.205135 | AT21: 1.2116796 | AU21: 1.2180078 | AV21: 1.2241273 | AW21: 1.2300461 | AX21: 1.2357722 | AY21: 1.2413132 | AZ21: 1.2466772 | BA21: 1.2518725 | BB21: 1.2569096 | BC21: 1.2617996 | BD21: 1.2665537 | BE21: 1.2711829 | BF21: 1.2756985 | BG21: 1.2801114 | BH21: 1.2844329 | BI21: 1.288674 | BJ21: 1.2928458 | BK21: 1.2969595 | BL21: 1.3010262 | BM21: #N/A | BN21: #N/A
A22: =+A17+7 -> 43486 | B22: 20190121 | C22: 0.75 | D22: 0.7055 | E22: 0.7091005 | F22: 0.7129171 | G22: 0.7206919 | H22: 0.7336517 | I22: 0.7489616 | J22: 0.7650503 | K22: 0.7813164 | L22: 0.797782 | M22: 0.8149167 | N22: 0.8329193 | O22: 0.8516037 | P22: 0.8705974 | Q22: 0.889372 | R22: 0.9076804 | S22: 0.9253619 | T22: 0.9422559 | U22: 0.9582017 | V22: 0.9730388 | W22: 0.9866623 | X22: 0.9991812 | Y22: 1.0107551 | Z22: 1.0215435 | AA22: 1.031706 | AB22: 1.0414023 | AC22: 1.05077 | AD22: 1.0598503 | AE22: 1.0686576 | AF22: 1.0772065 | AG22: 1.0855113 | AH22: 1.0935866 | AI22: 1.1014468 | AJ22: 1.1091064 | AK22: 1.1165798 | AL22: 1.1238816 | AM22: 1.1310263 | AN22: 1.1380282 | AO22: 1.1448998 | AP22: 1.1516446 | AQ22: 1.1582636 | AR22: 1.1647576 | AS22: 1.1711276 | AT22: 1.1773747 | AU22: 1.1834997 | AV22: 1.1895036 | AW22: 1.1953875 | AX22: 1.2011522 | AY22: 1.2067986 | AZ22: 1.2123279 | BA22: 1.2177418 | BB22: 1.223047 | BC22: 1.2282518 | BD22: 1.2333645 | BE22: 1.2383934 | BF22: 1.2433469 | BG22: 1.2482332 | BH22: 1.2530607 | BI22: 1.2578376 | BJ22: 1.2625722 | BK22: 1.2672729 | BL22: 1.2719479 | BM22: #N/A | BN22: #N/A
A23: =+A18+7 -> 43487 | B23: 20190122 | C23: 0.75 | D23: 0.7047 | E23: 0.7064989 | F23: 0.7122639 | G23: 0.7240498 | H23: 0.7403481 | I23: 0.7586008 | J23: 0.7778023 | K23: 0.7974208 | L23: 0.8171444 | M23: 0.8368485 | N23: 0.8563281 | O23: 0.8753219 | P23: 0.8935889 | Q23: 0.9108245 | R23: 0.9270225 | S23: 0.9422622 | T23: 0.9566228 | U23: 0.9701835 | V23: 0.9830236 | W23: 0.9952199 | X23: 1.0068392 | Y23: 1.0179465 | Z23: 1.0286063 | AA23: 1.0388835 | AB23: 1.0488427 | AC23: 1.0585387 | AD23: 1.0679819 | AE23: 1.0771705 | AF23: 1.086103 | AG23: 1.0947774 | AH23: 1.1031921 | AI23: 1.1113454 | AJ23: 1.1192354 | AK23: 1.1268606 | AL23: 1.134219 | AM23: 1.141309 | AN23: 1.1481289 | AO23: 1.1546789 | AP23: 1.1609698 | AQ23: 1.1670163 | AR23: 1.1728327 | AS23: 1.1784336 | AT23: 1.1838334 | AU23: 1.1890467 | AV23: 1.1940879 | AW23: 1.1989715 | AX23: 1.203712 | AY23: 1.2083239 | AZ23: 1.2128217 | BA23: 1.217219 | BB23: 1.2215249 | BC23: 1.2257474 | BD23: 1.2298945 | BE23: 1.2339739 | BF23: 1.2379936 | BG23: 1.2419614 | BH23: 1.2458853 | BI23: 1.2497732 | BJ23: 1.2536329 | BK23: 1.2574724 | BL23: 1.2612995 | BM23: #N/A | BN23: #N/A
A24: =+A19+7 -> 43488 | B24: 20190123 | C24: 0.75 | D24: 0.7053 | E24: 0.7077084 | F24: 0.7181591 | G24: 0.7332729 | H24: 0.7505141 | I24: 0.7683926 | J24: 0.7866867 | K24: 0.8051813 | L24: 0.8236848 | M24: 0.8423381 | N24: 0.861186 | O24: 0.8800833 | P24: 0.898829 | Q24: 0.9170155 | R24: 0.9344989 | S24: 0.9512197 | T24: 0.9671183 | U24: 0.9821353 | V24: 0.9962113 | W24: 1.0093147 | X24: 1.0215203 | Y24: 1.0329282 | Z24: 1.0436387 | AA24: 1.053752 | AB24: 1.0633681 | AC24: 1.0725775 | AD24: 1.0814179 | AE24: 1.0899095 | AF24: 1.0980724 | AG24: 1.1059267 | AH24: 1.1134924 | AI24: 1.1207898 | AJ24: 1.1278389 | AK24: 1.1346598 | AL24: 1.1412727 | AM24: 1.1476977 | AN24: 1.1539548 | AO24: 1.1600623 | AP24: 1.166029 | AQ24: 1.1718608 | AR24: 1.1775635 | AS24: 1.1831432 | AT24: 1.1886059 | AU24: 1.1939573 | AV24: 1.1992035 | AW24: 1.2043503 | AX24: 1.2094038 | AY24: 1.2143699 | AZ24: 1.2192544 | BA24: 1.2240635 | BB24: 1.2288041 | BC24: 1.2334832 | BD24: 1.2381081 | BE24: 1.2426856 | BF24: 1.2472231 | BG24: 1.2517274 | BH24: 1.2562059 | BI24: 1.2606654 | BJ24: 1.2651132 | BK24: 1.2695563 | BL24: 1.2740019 | BM24: #N/A | BN24: #N/A
... A85: =+A80+7 -> 43573 | B85: 20190418 | C85: 0.75 | D85: 0.7087 | E85: 0.707241 | F85: 0.7092092 | G85: 0.7151963 | H85: 0.7245737 | I85: 0.7361272 | J85: 0.7489904 | K85: 0.7624269 | L85: 0.7757027 | M85: 0.7884523 | N85: 0.8006183 | O85: 0.8122933 | P85: 0.8235875 | Q85: 0.8345911 | R85: 0.8453732 | S85: 0.8559965 | T85: 0.8665242 | U85: 0.8770191 | V85: 0.8875442 | W85: 0.8981481 | X85: 0.9088057 | Y85: 0.9194684 | Z85: 0.9300875 | AA85: 0.9406144 | AB85: 0.9510005 | AC85: 0.9612027 | AD85: 0.9712049 | AE85: 0.9809994 | AF85: 0.9905782 | AG85: 0.9999337 | AH85: 1.0090579 | AI85: 1.0179431 | AJ85: 1.0265814 | AK85: 1.034965 | AL85: 1.0430861 | AM85: 1.0509369 | AN85: 1.0585095 | AO85: 1.0657988 | AP85: 1.072812 | AQ85: 1.0795605 | AR85: 1.0860553 | AS85: 1.0923078 | AT85: 1.098329 | AU85: 1.1041302 | AV85: 1.1097227 | AW85: 1.1151175 | AX85: 1.120326 | AY85: 1.1253592 | AZ85: 1.1302285 | BA85: 1.1349447 | BB85: 1.139518 | BC85: 1.143958 | BD85: 1.1482746 | BE85: 1.1524774 | BF85: 1.1565763 | BG85: 1.1605809 | BH85: 1.1645011 | BI85: 1.1683466 | BJ85: 1.1721271 | BK85: 1.1758524 | BL85: 1.1795322 | BM85: #N/A | BN85: #N/A
A86: =+A81+7 -> 43574 | B86: 20190419 | C86: 0.75 | D86: #N/A | E86: #N/A | F86: #N/A | G86: #N/A | H86: #N/A | I86: #N/A | J86: #N/A | K86: #N/A | L86: #N/A | M86: #N/A | N86: #N/A | O86: #N/A | P86: #N/A | Q86: #N/A | R86: #N/A | S86: #N/A | T86: #N/A | U86: #N/A | V86: #N/A | W86: #N/A | X86: #N/A | Y86: #N/A | Z86: #N/A | AA86: #N/A | AB86: #N/A | AC86: #N/A | AD86: #N/A | AE86: #N/A | AF86: #N/A | AG86: #N/A | AH86: #N/A | AI86: #N/A | AJ86: #N/A | AK86: #N/A | AL86: #N/A | AM86: #N/A | AN86: #N/A | AO86: #N/A | AP86: #N/A | AQ86: #N/A | AR86: #N/A | AS86: #N/A | AT86: #N/A | AU86: #N/A | AV86: #N/A | AW86: #N/A | AX86: #N/A | AY86: #N/A | AZ86: #N/A | BA86: #N/A | BB86: #N/A | BC86: #N/A | BD86: #N/A | BE86: #N/A | BF86: #N/A | BG86: #N/A | BH86: #N/A | BI86: #N/A | BJ86: #N/A | BK86: #N/A | BL86: #N/A | BM86: #N/A | BN86: #N/A
A87: =+A82+7 -> 43577 | B87: 20190422 | C87: 0.75 | D87: #N/A | E87: #N/A | F87: #N/A | G87: #N/A | H87: #N/A | I87: #N/A | J87: #N/A | K87: #N/A | L87: #N/A | M87: #N/A | N87: #N/A | O87: #N/A | P87: #N/A | Q87: #N/A | R87: #N/A | S87: #N/A | T87: #N/A | U87: #N/A | V87: #N/A | W87: #N/A | X87: #N/A | Y87: #N/A | Z87: #N/A | AA87: #N/A | AB87: #N/A | AC87: #N/A | AD87: #N/A | AE87: #N/A | AF87: #N/A | AG87: #N/A | AH87: #N/A | AI87: #N/A | AJ87: #N/A | AK87: #N/A | AL87: #N/A | AM87: #N/A | AN87: #N/A | AO87: #N/A | AP87: #N/A | AQ87: #N/A | AR87: #N/A | AS87: #N/A | AT87: #N/A | AU87: #N/A | AV87: #N/A | AW87: #N/A | AX87: #N/A | AY87: #N/A | AZ87: #N/A | BA87: #N/A | BB87: #N/A | BC87: #N/A | BD87: #N/A | BE87: #N/A | BF87: #N/A | BG87: #N/A | BH87: #N/A | BI87: #N/A | BJ87: #N/A | BK87: #N/A | BL87: #N/A | BM87: #N/A | BN87: #N/A
A88: =+A83+7 -> 43578 | B88: 20190423 | C88: 0.75 | D88: 0.7092 | E88: 0.7064798 | F88: 0.7146189 | G88: 0.7273739 | H88: 0.7425742 | I88: 0.757993 | J88: 0.7732623 | K88: 0.788258 | L88: 0.8025692 | M88: 0.8159816 | N88: 0.8285699 | O88: 0.840537 | P88: 0.8520962 | Q88: 0.8634707 | R88: 0.8747228 | S88: 0.8858658 | T88: 0.8969131 | U88: 0.9078781 | V88: 0.9187741 | W88: 0.9296068 | X88: 0.9403452 | Y88: 0.950948 | Z88: 0.9613735 | AA88: 0.9715805 | AB88: 0.9815275 | AC88: 0.9911802 | AD88: 1.000536 | AE88: 1.0096009 | AF88: 1.018381 | AG88: 1.0268824 | AH88: 1.0351113 | AI88: 1.0430736 | AJ88: 1.0507755 | AK88: 1.058223 | AL88: 1.0654222 | AM88: 1.0723792 | AN88: 1.0791002 | AO88: 1.0855917 | AP88: 1.091864 | AQ88: 1.0979285 | AR88: 1.1037964 | AS88: 1.1094791 | AT88: 1.1149879 | AU88: 1.1203343 | AV88: 1.1255295 | AW88: 1.1305848 | AX88: 1.1355116 | AY88: 1.1403213 | AZ88: 1.1450251 | BA88: 1.1496338 | BB88: 1.1541543 | BC88: 1.1585928 | BD88: 1.1629553 | BE88: 1.1672478 | BF88: 1.1714764 | BG88: 1.175647 | BH88: 1.1797657 | BI88: 1.1838387 | BJ88: 1.1878718 | BK88: 1.1918711 | BL88: 1.1958428 | BM88: #N/A | BN88: #N/A
A89: =+A84+7 -> 43579 | B89: 20190424 | C89: 0.75 | D89: 0.7087 | E89: 0.7067223 | F89: 0.7086687 | G89: 0.7164351 | H89: 0.728125 | I89: 0.7401223 | J89: 0.751495 | K89: 0.7621913 | L89: 0.7722565 | M89: 0.7820352 | N89: 0.7918752 | O89: 0.8019679 | P89: 0.8124071 | Q89: 0.8231647 | R89: 0.834118 | S89: 0.8451252 | T89: 0.8560442 | U89: 0.8667334 | V89: 0.8770507 | W89: 0.8868781 | X89: 0.8962328 | Y89: 0.9051794 | Z89: 0.9137826 | AA89: 0.9221069 | AB89: 0.9302173 | AC89: 0.9381707 | AD89: 0.9459845 | AE89: 0.9536624 | AF89: 0.961208 | AG89: 0.9686251 | AH89: 0.9759174 | AI89: 0.9830886 | AJ89: 0.9901425 | AK89: 0.9970827 | AL89: 1.003913 | AM89: 1.0106371 | AN89: 1.0172587 | AO89: 1.0237809 | AP89: 1.0302033 | AQ89: 1.0365249 | AR89: 1.0427444 | AS89: 1.0488605 | AT89: 1.0548721 | AU89: 1.0607779 | AV89: 1.0665767 | AW89: 1.0722673 | AX89: 1.0778484 | AY89: 1.0833188 | AZ89: 1.0886774 | BA89: 1.0939239 | BB89: 1.0990628 | BC89: 1.1041001 | BD89: 1.1090414 | BE89: 1.1138926 | BF89: 1.1186596 | BG89: 1.123348 | BH89: 1.1279638 | BI89: 1.1325127 | BJ89: 1.1370006 | BK89: 1.1414332 | BL89: 1.1458165 | BM89: #N/A | BN89: #N/A
A90: =+A85+7 -> 43580 | B90: 20190425 | C90: 0.75 | D90: 0.7096 | E90: 0.7077486 | F90: 0.7102523 | G90: 0.7190003 | H90: 0.7307304 | I90: 0.7417487 | J90: 0.7517613 | K90: 0.7610614 | L90: 0.7696264 | M90: 0.7776006 | N90: 0.785212 | O90: 0.792665 | P90: 0.8001526 | Q90: 0.8077774 | R90: 0.8155522 | S90: 0.8234674 | T90: 0.8315133 | U90: 0.8396801 | V90: 0.8479582 | W90: 0.856335 | X90: 0.8647831 | Y90: 0.8732703 | Z90: 0.8817646 | AA90: 0.8902339 | AB90: 0.8986461 | AC90: 0.9069725 | AD90: 0.915201 | AE90: 0.9233248 | AF90: 0.9313369 | AG90: 0.9392303 | AH90: 0.9469981 | AI90: 0.9546334 | AJ90: 0.9621291 | AK90: 0.9694784 | AL90: 0.9766742 | AM90: 0.9837097 | AN90: 0.9905779 | AO90: 0.9972738 | AP90: 1.0038014 | AQ90: 1.0101672 | AR90: 1.0163775 | AS90: 1.0224388 | AT90: 1.0283575 | AU90: 1.03414 | AV90: 1.0397927 | AW90: 1.045322 | AX90: 1.0507344 | AY90: 1.0560363 | AZ90: 1.061234 | BA90: 1.0663338 | BB90: 1.0713409 | BC90: 1.0762599 | BD90: 1.0810958 | BE90: 1.0858535 | BF90: 1.0905377 | BG90: 1.0951533 | BH90: 1.0997051 | BI90: 1.104198 | BJ90: 1.1086368 | BK90: 1.1130264 | BL90: 1.1173715 | BM90: #N/A | BN90: #N/A
A91: =+A86+7 -> 43581 | B91: 20190426 | C91: 0.75 | D91: 0.7107 | E91: 0.7095528 | F91: 0.7154788 | G91: 0.726963 | H91: 0.7403957 | I91: 0.7519252 | J91: 0.7610044 | K91: 0.7681313 | L91: 0.7737464 | M91: 0.7782787 | N91: 0.782129 | O91: 0.7856931 | P91: 0.789378 | Q91: 0.7937214 | R91: 0.798814 | S91: 0.80459 | T91: 0.8109837 | U91: 0.8179295 | V91: 0.8253616 | W91: 0.8332106 | X91: 0.8413888 | Y91: 0.8498035 | Z91: 0.8583621 | AA91: 0.8669718 | AB91: 0.8755398 | AC91: 0.8839877 | AD91: 0.8922992 | AE91: 0.9004757 | AF91: 0.9085183 | AG91: 0.916428 | AH91: 0.9242062 | AI91: 0.931854 | AJ91: 0.9393725 | AK91: 0.9467629 | AL91: 0.9540264 | AM91: 0.9611642 | AN91: 0.9681774 | AO91: 0.9750672 | AP91: 0.9818352 | AQ91: 0.988483 | AR91: 0.9950121 | AS91: 1.001424 | AT91: 1.0077205 | AU91: 1.013903 | AV91: 1.0199732 | AW91: 1.0259325 | AX91: 1.0317827 | AY91: 1.0375252 | AZ91: 1.0431617 | BA91: 1.0486941 | BB91: 1.0541256 | BC91: 1.0594601 | BD91: 1.0647013 | BE91: 1.0698529 | BF91: 1.0749186 | BG91: 1.0799022 | BH91: 1.0848075 | BI91: 1.0896381 | BJ91: 1.0943979 | BK91: 1.0990905 | BL91: 1.1037197 | BM91: #N/A | BN91: #N/A
A92: =+A87+7 -> 43584 | B92: 20190429 | C92: 0.75 | D92: 0.7097 | E92: 0.7092457 | F92: 0.7172887 | G92: 0.7282753 | H92: 0.7393674 | I92: 0.7488954 | J92: 0.7576392 | K92: 0.7660091 | L92: 0.7739143 | M92: 0.7815378 | N92: 0.7891316 | O92: 0.7969013 | P92: 0.8050538 | Q92: 0.8138192 | R92: 0.8231209 | S92: 0.8327897 | T92: 0.8426563 | U92: 0.8525516 | V92: 0.8623063 | W92: 0.871777 | X92: 0.8809401 | Y92: 0.8898068 | Z92: 0.8983882 | AA92: 0.9066955 | AB92: 0.9147398 | AC92: 0.9225328 | AD92: 0.9300877 | AE92: 0.9374185 | AF92: 0.9445391 | AG92: 0.9514635 | AH92: 0.9582053 | AI92: 0.9647787 | AJ92: 0.9711974 | AK92: 0.9774755 | AL92: 0.9836266 | AM92: 0.9896649 | AN92: 0.9956041 | AO92: 1.0014564 | AP92: 1.0072267 | AQ92: 1.0129177 | AR92: 1.0185321 | AS92: 1.0240726 | AT92: 1.0295419 | AU92: 1.0349428 | AV92: 1.0402779 | AW92: 1.0455501 | AX92: 1.050762 | AY92: 1.0559164 | AZ92: 1.0610159 | BA92: 1.0660633 | BB92: 1.0710611 | BC92: 1.0760115 | BD92: 1.080917 | BE92: 1.08578 | BF92: 1.0906028 | BG92: 1.0953879 | BH92: 1.1001375 | BI92: 1.1048541 | BJ92: 1.1095401 | BK92: 1.1141978 | BL92: 1.1188296 | BM92: #N/A | BN92: #N/A
A93: =+A88+7 -> 43585 | B93: 20190430 | C93: 0.75 | D93: 0.7109 | E93: 0.7095882 | F93: 0.7181951 | G93: 0.731039 | H93: 0.7456724 | I93: 0.7599334 | J93: 0.7735528 | K93: 0.7862481 | L93: 0.797707 | M93: 0.8082007 | N93: 0.8182246 | O93: 0.8281416 | P93: 0.8381792 | Q93: 0.8484199 | R93: 0.8587745 | S93: 0.8691135 | T93: 0.8793074 | U93: 0.8892268 | V93: 0.8987421 | W93: 0.9077435 | X93: 0.9162436 | Y93: 0.9243025 | Z93: 0.9319804 | AA93: 0.9393375 | AB93: 0.946434 | AC93: 0.9533227 | AD93: 0.960023 | AE93: 0.9665453 | AF93: 0.9728999 | AG93: 0.9790973 | AH93: 0.9851478 | AI93: 0.9910617 | AJ93: 0.9968495 | AK93: 1.0025215 | AL93: 1.008088 | AM93: 1.0135595 | AN93: 1.0189463 | AO93: 1.0242579 | AP93: 1.0294988 | AQ93: 1.0346715 | AR93: 1.0397786 | AS93: 1.0448227 | AT93: 1.0498064 | AU93: 1.0547322 | AV93: 1.0596027 | AW93: 1.0644204 | AX93: 1.069188 | AY93: 1.073908 | AZ93: 1.0785829 | BA93: 1.0832156 | BB93: 1.0878094 | BC93: 1.0923681 | BD93: 1.0968954 | BE93: 1.101395 | BF93: 1.1058706 | BG93: 1.110326 | BH93: 1.1147649 | BI93: 1.1191909 | BJ93: 1.123608 | BK93: 1.1280196 | BL93: 1.1324296 | BM93: #N/A | BN93: #N/A
