Workbook
Name _DLX1.INC: HAVERM!$A$1:$E$6
Name _DLX2.INC: HAVERD!$A$1:$M$6

Sheet Chart Data
B1: Quoted mortgage rates | E1: New-old
B2: 2 year fix, 75% LTV | C2: 5 year fix, 75% LTV | F2: 2 year fix, 75% LTV | G2: 5 year fix, 75% LTV | H2: ZERO LINE
A3: 41640 | B3: =HAVERM!B295 -> 2.37 | C3: =HAVERM!C295 -> 3.34 | E3: 41640 | H3: 0
A4: 41671 | B4: =HAVERM!B296 -> 2.38 | C4: =HAVERM!C296 -> 3.45 | E4: 41671 | H4: 0
A5: 41699 | B5: =HAVERM!B297 -> 2.37 | C5: =HAVERM!C297 -> 3.48 | E5: 41699 | H5: 0
A6: 41730 | B6: =HAVERM!B298 -> 2.54 | C6: =HAVERM!C298 -> 3.69 | E6: 41730 | H6: 0
A7: 41760 | B7: =HAVERM!B299 -> 2.56 | C7: =HAVERM!C299 -> 3.72 | E7: 41760 | H7: 0
A8: 41791 | B8: =HAVERM!B300 -> 2.6 | C8: =HAVERM!C300 -> 3.69 | E8: 41791 | H8: 0
A9: 41821 | B9: =HAVERM!B301 -> 2.54 | C9: =HAVERM!C301 -> 3.78 | E9: 41821 | H9: 0
A10: 41852 | B10: =HAVERM!B302 -> 2.54 | C10: =HAVERM!C302 -> 3.76 | E10: 41852 | H10: 0
A11: 41883 | B11: =HAVERM!B303 -> 2.46 | C11: =HAVERM!C303 -> 3.61 | E11: 41883 | H11: 0
A12: 41913 | B12: =HAVERM!B304 -> 2.21 | C12: =HAVERM!C304 -> 3.27 | E12: 41913 | H12: 0
A13: 41944 | B13: =HAVERM!B305 -> 2.17 | C13: =HAVERM!C305 -> 3.21 | E13: 41944 | H13: 0
A14: 41974 | B14: =HAVERM!B306 -> 2.08 | C14: =HAVERM!C306 -> 3.21 | E14: 41974 | H14: 0
... A33: 42552 | B33: =HAVERM!B325 -> 1.72 | C33: =HAVERM!C325 -> 2.51 | E33: 42552 | H33: 0
A34: 42583 | B34: =HAVERM!B326 -> 1.69 | C34: =HAVERM!C326 -> 2.39 | E34: 42583 | F34: =B34-B10 -> -0.85 | H34: 0
A35: 42614 | B35: =HAVERM!B327 -> 1.59 | C35: =HAVERM!C327 -> 2.34 | E35: 42614 | F35: =B35-B11 -> -0.87 | H35: 0
A36: 42644 | B36: =HAVERM!B328 -> 1.52 | C36: =HAVERM!C328 -> 2.27 | E36: 42644 | F36: =B36-B12 -> -0.69 | H36: 0
A37: 42675 | B37: =HAVERM!B329 -> 1.43 | C37: =HAVERM!C329 -> 2.25 | E37: 42675 | F37: =B37-B13 -> -0.74 | H37: 0
A38: 42705 | B38: =HAVERM!B330 -> 1.45 | C38: =HAVERM!C330 -> 2.26 | E38: 42705 | F38: =B38-B14 -> -0.63 | H38: 0
A39: 42736 | B39: =HAVERM!B331 -> 1.45 | C39: =HAVERM!C331 -> 2.22 | E39: 42736 | F39: =B39-B15 -> -0.56 | H39: 0
A40: 42767 | B40: =HAVERM!B332 -> 1.42 | C40: =HAVERM!C332 -> 2.2 | E40: 42767 | F40: =B40-B16 -> -0.54 | H40: 0
A41: 42795 | B41: =HAVERM!B333 -> 1.37 | C41: =HAVERM!C333 -> 2.15 | E41: 42795 | F41: =B41-B17 -> -0.62 | H41: 0
A42: 42826 | B42: =HAVERM!B334 -> 1.35 | C42: =HAVERM!C334 -> 2.09 | E42: 42826 | F42: =B42-B18 -> -0.6 | H42: 0
A43: 42856 | B43: =HAVERM!B335 -> 1.49 | C43: =HAVERM!C335 -> 2.03 | E43: 42856 | F43: =B43-B19 -> -0.41 | H43: 0
A44: 42887 | B44: =HAVERM!B336 -> 1.48 | C44: =HAVERM!C336 -> 1.99 | E44: 42887 | F44: =B44-B20 -> -0.35 | H44: 0
A45: 42917 | B45: =HAVERM!B337 -> 1.41 | C45: =HAVERM!C337 -> 1.97 | E45: 42917 | F45: =B45-B21 -> -0.46 | H45: 0
... A62: 43435 | B62: =HAVERM!B354 -> 1.73 | C62: =HAVERM!C354 -> 2.01 | E62: 43435 | F62: =B62-B38 -> 0.28 | H62: 0
A63: 43466 | B63: =HAVERM!B355 -> 1.72 | C63: =HAVERM!C355 -> 2.05 | E63: 43466 | F63: =B63-B39 -> 0.27 | G63: =C63-C3 -> -1.29 | H63: 0
A64: 43497 | B64: =HAVERM!B356 -> 1.7 | C64: =HAVERM!C356 -> 2.05 | E64: 43497 | F64: =B64-B40 -> 0.28 | G64: =C64-C4 -> -1.4 | H64: 0
A65: 43525 | B65: =HAVERM!B357 -> 1.7 | C65: =HAVERM!C357 -> 2.03 | E65: 43525 | F65: =B65-B41 -> 0.33 | G65: =C65-C5 -> -1.45 | H65: 0
A66: 43556 | B66: =HAVERM!B358 -> 1.66 | C66: =HAVERM!C358 -> 2 | E66: 43556 | F66: =B66-B42 -> 0.31 | G66: =C66-C6 -> -1.69 | H66: 0
A67: 43586 | B67: =HAVERM!B359 -> 1.65 | C67: =HAVERM!C359 -> 1.99 | E67: 43586 | F67: =B67-B43 -> 0.16 | G67: =C67-C7 -> -1.73 | H67: 0
A68: 43617 | B68: =HAVERM!B360 -> 1.64 | C68: =HAVERM!C360 -> 1.97 | E68: 43617 | F68: =B68-B44 -> 0.16 | G68: =C68-C8 -> -1.72 | H68: 0
A69: 43647 | B69: =HAVERM!B361 -> 1.61 | C69: =HAVERM!C361 -> 1.93 | E69: 43647 | F69: =B69-B45 -> 0.2 | G69: =C69-C9 -> -1.85 | H69: 0
A70: 43678 | B70: =HAVERM!B362 -> 1.59 | C70: =HAVERM!C362 -> 1.89 | E70: 43678 | F70: =B70-B46 -> 0.16 | G70: =C70-C10 -> -1.87 | H70: 0
A71: 43709 | B71: =HAVERM!B363 -> 1.55 | C71: =HAVERM!C363 -> 1.79 | E71: 43709 | F71: =B71-B47 -> 0.15 | G71: =C71-C11 -> -1.82 | H71: 0
A72: 43739 | B72: =HAVERM!B364 -> 1.47 | C72: =HAVERM!C364 -> 1.71 | E72: 43739 | F72: =B72-B48 -> -0.08 | G72: =C72-C12 -> -1.56 | H72: 0
A73: 43770 | B73: =HAVERM!B365 -> 1.41 | C73: =HAVERM!C365 -> 1.67 | E73: 43770 | F73: =B73-B49 -> -0.2 | G73: =C73-C13 -> -1.54 | H73: 0
A74: 43800 | B74: =HAVERM!B366 -> 1.42 | C74: =HAVERM!C366 -> 1.67 | E74: 43800 | F74: =B74-B50 -> -0.15 | G74: =C74-C14 -> -1.54 | H74: 0
...

Sheet HAVERM
A1: 199001 !M | B1: UNBV34@UK | C1: UNBV42@UK
A2: .DESC | B2: UK: Mortgages: Fixed Rates: MFIS ex Central Bank: 2-Year 75% LTV (AVG, %) | C2: UK: Mortgages: Fixed Rates: MFIS ex Central Bank: 5-Year 75% LTV (AVG, %)
A3: .T1 | B3: Jan-1995 | C3: Jan-1995
A4: .TN | B4: Dec-2023 | C4: Dec-2023
A5: .LSOURCE | B5: Bank of England | C5: Bank of England
A6: .DTLM | B6: Jan-08-2024 09:31 | C6: Jan-08-2024 09:31
A7: 199001 | B7: #N/A | C7: #N/A
A8: 199002 | B8: #N/A | C8: #N/A
A9: 199003 | B9: #N/A | C9: #N/A
A10: 199004 | B10: #N/A | C10: #N/A
A11: 199005 | B11: #N/A | C11: #N/A
A12: 199006 | B12: #N/A | C12: #N/A
A13: 199007 | B13: #N/A | C13: #N/A
A14: 199008 | B14: #N/A | C14: #N/A
A15: 199009 | B15: #N/A | C15: #N/A
A16: 199010 | B16: #N/A | C16: #N/A
A17: 199011 | B17: #N/A | C17: #N/A
A18: 199012 | B18: #N/A | C18: #N/A
... A66: 199412 | B66: #N/A | C66: #N/A
A67: 199501 | B67: 8.13 | C67: 9.44
A68: 199502 | B68: 8.38 | C68: 9.38
A69: 199503 | B69: 8.08 | C69: 9.33
A70: 199504 | B70: 8.29 | C70: 9.4
A71: 199505 | B71: 8.22 | C71: 9.4
A72: 199506 | B72: 7.94 | C72: 9.01
A73: 199507 | B73: 7.89 | C73: 8.93
A74: 199508 | B74: 7.99 | C74: 8.85
A75: 199509 | B75: 7.99 | C75: 8.57
A76: 199510 | B76: 7.99 | C76: 8.19
A77: 199511 | B77: 7.99 | C77: 8.14
A78: 199512 | B78: 7.99 | C78: 8.13
... A414: 202312 | B414: 5.03 | C414: 4.68
A416: Dec | B416: =+B414-B413 -> -0.25 | C416: =+C414-C413 -> -0.2
A417: Jul-Dec | B417: =+B414-B409 -> -1.19 | C417: =+C414-C409 -> -1.03

Sheet HAVERD
A1: 20230101 !D | B1: T112G2@INTDAILY | C1: T112G5@INTDAILY | D1: T112GA@INTDAILY | E1: FCM2@DAILY | F1: FCM5@DAILY | G1: FCM10@DAILY | H1: M112IHH@INTDAILY | I1: M112I5Y@INTDAILY | J1: M112IAY@INTDAILY
A2: .DESC | B2: UK: 2-Yr Government Bond Yield (%) | C2: UK: 5-Yr Government Bond Yield (%) | D2: UK: 10-Yr Government Bond Yield (%) | E2: 2-Year Treasury Note Yield at Constant Maturity (% p.a.) | F2: 5-Year Treasury Note Yield at Constant Maturity (% p.a.) | G2: 10-Year Treasury Note Yield at Constant Maturity (% p.a.) | H2: UK: 24 Month Overnight Index Swap[Ann,Act/365]v SONIA:Mid Rate[2PM ET](%p.a) | I2: UK: 5 Year Overnight Index Swap[Ann,Act/365]v SONIA:Mid Rate[2PM ET](%p.a) | J2: UK: 10 Year Overnight Index Swap[Ann,Act/365]v SONIA:Mid Rate[2PM ET](%p.a)
A3: .T1 | B3: 26-Jan-1994 | C3: 03-Jan-1995 | D3: 26-Jan-1994 | E3: 01-Jun-1976 | F3: 02-Jan-1962 | G3: 02-Jan-1962 | H3: 26-Aug-2014 | I3: 26-Aug-2014 | J3: 26-Aug-2014
A4: .TN | B4: 10-Jan-2024 | C4: 10-Jan-2024 | D4: 10-Jan-2024 | E4: 10-Jan-2024 | F4: 10-Jan-2024 | G4: 10-Jan-2024 | H4: 10-Jan-2024 | I4: 10-Jan-2024 | J4: 10-Jan-2024
A5: .LSOURCE | B5: London Stock Exchange Group | C5: London Stock Exchange Group | D5: London Stock Exchange Group | E5: Federal Reserve Board | F5: Federal Reserve Board | G5: Federal Reserve Board | H5: Tullett Prebon Information/Haver Analytics | I5: Tullett Prebon Information/Haver Analytics | J5: Tullett Prebon Information/Haver Analytics
A6: .DTLM | B6: Jan-10-2024 20:46 | C6: Jan-10-2024 20:46 | D6: Jan-10-2024 20:46 | E6: Jan-10-2024 21:04 | F6: Jan-10-2024 21:04 | G6: Jan-10-2024 21:04 | H6: Jan-10-2024 19:25 | I6: Jan-10-2024 19:25 | J6: Jan-10-2024 19:25
A7: 20230102 | B7: #N/A | C7: #N/A | D7: 3.67 | E7: #N/A | F7: #N/A | G7: #N/A | H7: 4.4692 | I7: 4.0929 | J7: 3.7491
A8: 20230103 | B8: 3.57 | C8: 3.61 | D8: 3.65 | E8: 4.4 | F8: 3.94 | G8: 3.79 | H8: 4.3962 | I8: 4.0118 | J8: 3.6974
A9: 20230104 | B9: 3.44 | C9: 3.49 | D9: 3.5 | E9: 4.36 | F9: 3.85 | G9: 3.69 | H9: 4.2848 | I9: 3.8556 | J9: 3.5437
A10: 20230105 | B10: 3.5 | C10: 3.54 | D10: 3.55 | E10: 4.45 | F10: 3.9 | G10: 3.71 | H10: 4.3917 | I10: 3.9431 | J10: 3.6098
A11: 20230106 | B11: 3.41 | C11: 3.44 | D11: 3.47 | E11: 4.24 | F11: 3.69 | G11: 3.55 | H11: 4.3201 | I11: 3.8677 | J11: 3.5532
A12: 20230109 | B12: 3.44 | C12: 3.44 | D12: 3.53 | E12: 4.19 | F12: 3.66 | G12: 3.53 | H12: 4.2377 | I12: 3.8118 | J12: 3.5758
A13: 20230110 | B13: 3.46 | C13: 3.46 | D13: 3.56 | E13: 4.24 | F13: 3.72 | G13: 3.61 | H13: 4.2666 | I13: 3.8362 | J13: 3.5938
A14: 20230111 | B14: 3.52 | C14: 3.33 | D14: 3.41 | E14: 4.2 | F14: 3.66 | G14: 3.54 | H14: 4.1442 | I14: 3.6913 | J14: 3.4487
A15: 20230112 | B15: 3.41 | C15: 3.22 | D15: 3.32 | E15: 4.12 | F15: 3.53 | G15: 3.43 | H15: 4.0866 | I15: 3.6104 | J15: 3.3564
A16: 20230113 | B16: 3.48 | C16: 3.3 | D16: 3.37 | E16: 4.22 | F16: 3.6 | G16: 3.49 | H16: 4.1078 | I16: 3.6417 | J16: 3.3931
A17: 20230116 | B17: 3.5 | C17: 3.32 | D17: 3.39 | E17: #N/A | F17: #N/A | G17: #N/A | H17: 4.1161 | I17: 3.643 | J17: 3.3948
A18: 20230117 | B18: 3.46 | C18: 3.28 | D18: 3.33 | E18: 4.18 | F18: 3.6 | G18: 3.53 | H18: 4.109 | I18: 3.6129 | J18: 3.3429
A19: 20230118 | B19: 3.48 | C19: 3.26 | D19: 3.31 | E19: 4.06 | F19: 3.43 | G19: 3.37 | H19: 4.13 | I19: 3.6207 | J19: 3.3319
A20: 20230119 | B20: 3.49 | C20: 3.28 | D20: 3.32 | E20: 4.09 | F20: 3.48 | G20: 3.39 | H20: 4.1163 | I20: 3.621 | J20: 3.3388
A21: 20230120 | B21: 3.48 | C21: 3.28 | D21: 3.37 | E21: 4.14 | F21: 3.56 | G21: 3.48 | H21: 4.1136 | I21: 3.6503 | J21: 3.4019
A22: 20230123 | B22: 3.45 | C22: 3.26 | D22: 3.36 | E22: 4.21 | F22: 3.61 | G22: 3.52 | H22: 4.1045 | I22: 3.645 | J22: 3.4018
A23: 20230124 | B23: 3.36 | C23: 3.18 | D23: 3.28 | E23: 4.12 | F23: 3.58 | G23: 3.46 | H23: 4.0486 | I23: 3.581 | J23: 3.3363
A24: 20230125 | B24: 3.41 | C24: 3.14 | D24: 3.24 | E24: 4.11 | F24: 3.54 | G24: 3.46 | H24: 3.9709 | I24: 3.5147 | J24: 3.2769
A25: 20230126 | B25: 3.43 | C25: 3.17 | D25: 3.3 | E25: 4.17 | F25: 3.58 | G25: 3.49 | H25: 4.0161 | I25: 3.5728 | J25: 3.3417
A26: 20230127 | B26: 3.48 | C26: 3.21 | D26: 3.33 | E26: 4.19 | F26: 3.62 | G26: 3.52 | H26: 4.0392 | I26: 3.597 | J26: 3.3628
A27: 20230130 | B27: 3.47 | C27: 3.23 | D27: 3.35 | E27: 4.25 | F27: 3.68 | G27: 3.55 | H27: 4.0709 | I27: 3.6203 | J27: 3.3831
A28: 20230131 | B28: 3.46 | C28: 3.22 | D28: 3.34 | E28: 4.21 | F28: 3.63 | G28: 3.52 | H28: 4.0446 | I28: 3.608 | J28: 3.3874
A29: 20230201 | B29: 3.41 | C29: 3.16 | D29: 3.3 | E29: 4.09 | F29: 3.48 | G29: 3.39 | H29: 4.0081 | I29: 3.5689 | J29: 3.352
... A41: 20230217 | B41: 3.79 | C41: 3.42 | D41: 3.51 | E41: 4.6 | F41: 4.03 | G41: 3.82 | H41: 4.1942 | I41: 3.7713 | J41: 3.5274
A42: 20230220 | B42: 3.75 | C42: 3.39 | D42: 3.48 | E42: #N/A | F42: #N/A | G42: #N/A | H42: 4.1549 | I42: 3.716 | J42: 3.4782
A43: 20230221 | B43: 3.93 | C43: 3.57 | D43: 3.63 | E43: 4.67 | F43: 4.16 | G43: 3.95 | H43: 4.3227 | I43: 3.8841 | J43: 3.6316
A44: 20230222 | B44: 3.92 | C44: 3.57 | D44: 3.61 | E44: 4.66 | F44: 4.13 | G44: 3.93 | H44: 4.3163 | I44: 3.8976 | J44: 3.6394
A45: 20230223 | B45: 3.9 | C45: 3.56 | D45: 3.58 | E45: 4.66 | F45: 4.09 | G45: 3.88 | H45: 4.3453 | I45: 3.9022 | J45: 3.6294
A46: 20230224 | B46: 3.62 | C46: 3.64 | D46: 3.75 | E46: 4.78 | F46: 4.19 | G46: 3.95 | H46: 4.4921 | I46: 4.0135 | J46: 3.701
A47: 20230227 | B47: 3.68 | C47: 3.7 | D47: 3.8 | E47: 4.78 | F47: 4.17 | G47: 3.92 | H47: 4.555 | I47: 4.0612 | J47: 3.7495
A48: 20230228 | B48: 3.66 | C48: 3.68 | D48: 3.84 | E48: 4.81 | F48: 4.18 | G48: 3.92 | H48: 4.5813 | I48: 4.0631 | J48: 3.7442
A49: 20230301 | B49: 3.68 | C49: 3.68 | D49: 3.83 | E49: 4.89 | F49: 4.27 | G49: 4.01 | H49: 4.5123 | I49: 4.0313 | J49: 3.7657
A50: 20230302 | B50: 3.69 | C50: 3.69 | D50: 3.91 | E50: 4.89 | F50: 4.32 | G50: 4.08 | H50: 4.5475 | I50: 4.0811 | J50: 3.814
A51: 20230303 | B51: 3.69 | C51: 3.65 | D51: 3.8 | E51: 4.86 | F51: 4.26 | G51: 3.97 | H51: 4.5394 | I51: 4.0655 | J51: 3.7797
...
