Workbook
Name _DLX1.INC: HAVER!$B$2:$I$7
Name IQ_CH: 110000
Name IQ_CQ: 5000
Name IQ_CY: 10000
Name IQ_DAILY: 500000
Name IQ_FH: 100000
Name IQ_FQ: 500
Name IQ_FY: 1000
Name IQ_LTM: 2000
Name IQ_MONTH: 15000
Name IQ_NTM: 6000
Name IQ_WEEK: 50000
Name IQ_YTD: 3000

Sheet Election result
A1: Election result
B3: Seats
A4: Labour | B4: 412
A5: Conservative | B5: 121
A6: Lib Dem | B6: 72
A7: SNP | B7: 9
A8: Other | B8: =650-B4-B5-B6-B7 -> 36
A10: Labour majority | B10: =(B4-(650/2))*2 -> 174

Sheet Election chart calculations
V1: Ring# | W1: Dots/Row | X1: #dots-adj | Y1: Cumulative | Z1: Ring# | AA1: Check | AB1: Radius | AC1: Scalar | AD1: Zeros | AF1: Splits | AU1: CHECK
A2: Obs# | B2: Ring# | C2: Radius | D2: Scalar | E2: Dummy | F2: Number | G2: Radians | H2: x | I2: y | J2: PARTY | K2: xLAB | L2: yLab | M2: xCon | N2: yCon | O2: xLD | P2: yLD | Q2: xSNP | R2: ySNP | S2: xOth | T2: yOth | V2: 0 | W2: 0 | X2: 0 | Y2: 0 | Z2: 1 | AD2: 0 | AF2: Ring# | AG2: #dots | AH2: Labour | AI2: Conservatives | AJ2: Lib Dem | AK2: SNP | AL2: Other | AN2: Ring# | AO2: Party | AP2: Dots/Ring | AQ2: Position | AR2: Party | AT2: Labour | AU2: L | AV2: =COUNTIF($J$3:$J$652,AU2) -> 412 | AW2: ='Election result'!B4 -> 412
A3: 1 | B3: =VLOOKUP(A3,$Y$2:$Z$13,2,1) -> 1 | C3: =VLOOKUP(B3,$V$2:$AC$13,7,0) -> 1 | D3: =VLOOKUP(B3,$V$2:$AC$13,8,0) -> 5 | E3: 0 | F3: 0 | G3: =(F3/180)*PI() -> 0 | H3: =C3*COS(G3) -> 1 | I3: =C3*SIN(G3) -> 0 | J3: =VLOOKUP(A3,$AQ$3:$AR$58,2,1) -> L | K3: =IF(J3="L",H3,NA()) -> 1 | L3: =IF(J3="l",I3,NA()) -> 0 | M3: =IF(J3="C",H3,NA()) -> #N/A | N3: =IF(J3="C",I3,NA()) -> #N/A | O3: =IF(J3="LD",H3,NA()) -> #N/A | P3: =IF(J3="LD",I3,NA()) -> #N/A | Q3: =IF(J3="SNP",H3,NA()) -> #N/A | R3: =IF(J3="SNP",I3,NA()) -> #N/A | S3: =IF(J3="Oth",H3,NA()) -> #N/A | T3: =IF(J3="oth",I3,NA()) -> #N/A | V3: 1 | W3: 37 | X3: =W3+1 -> 38 | Y3: =X3 -> 38 | Z3: =Z2+1 -> 2 | AA3: =COUNTIF($B$3:$B$652,Z2)-X3 -> -1 | AB3: 1 | AC3: =180/(W3-1) -> 5 | AD3: 0 | AF3: 1 | AG3: 37 | AH3: 20 | AI3: =AG3-AH3-AJ3-AK3-AL3+1 -> 7 | AJ3: 6 | AK3: 2 | AL3: 3 | AN3: 1 | AO3: Labour | AP3: =HLOOKUP(AO3,$AH$2:$AL$13,AN3+1) -> 20 | AQ3: 0 | AR3: L | AT3: Conservatives | AU3: C | AV3: =COUNTIF($J$3:$J$652,AU3) -> 121 | AW3: ='Election result'!B5 -> 121
A4: 2 | B4: =VLOOKUP(A4,$Y$2:$Z$13,2,1) -> 1 | C4: =VLOOKUP(B4,$V$2:$AB$14,7,0) -> 1 | D4: =VLOOKUP(B4,$V$2:$AC$13,8,0) -> 5 | E4: =IF(OR(A4=$Y$3,A4=$Y$4,A4=$Y$5,A4=$Y$6,A4=$Y$7,A4=$Y$8,A4=$Y$9,A4=$Y$10,A4=$Y$11,A4=$Y$12,A4=$Y$12),0,1) -> 1 | F4: =IF(E4=0,0,D4+F3) -> 5 | G4: =(F4/180)*PI() -> 0.087266463 | H4: =C4*COS(G4) -> 0.9961947 | I4: =C4*SIN(G4) -> 0.087155743 | J4: =VLOOKUP(A4,$AQ$3:$AR$58,2,1) -> L | K4: =IF(J4="L",H4,NA()) -> 0.9961947 | L4: =IF(J4="l",I4,NA()) -> 0.087155743 | M4: =IF(J4="C",H4,NA()) -> #N/A | N4: =IF(J4="C",I4,NA()) -> #N/A | O4: =IF(J4="LD",H4,NA()) -> #N/A | P4: =IF(J4="LD",I4,NA()) -> #N/A | Q4: =IF(J4="SNP",H4,NA()) -> #N/A | R4: =IF(J4="SNP",I4,NA()) -> #N/A | S4: =IF(J4="Oth",H4,NA()) -> #N/A | T4: =IF(J4="oth",I4,NA()) -> #N/A | V4: 2 | W4: 41 | X4: =W4 -> 41 | Y4: =Y3+X4 -> 79 | Z4: =Z3+1 -> 3 | AA4: =COUNTIF($B$3:$B$652,Z3)-X4 -> 0 | AB4: =AB3+0.1 -> 1.1 | AC4: =180/(W4-1) -> 4.5 | AD4: 0 | AF4: 2 | AG4: 41 | AH4: 22 | AI4: =AG4-AH4-AJ4-AK4-AL4 -> 8 | AJ4: 7 | AK4: 1 | AL4: 3 | AN4: 1 | AO4: Conservatives | AP4: =HLOOKUP(AO4,$AH$2:$AL$13,AN4+1,) -> 7 | AQ4: =AQ3+AP3 -> 20 | AR4: C | AT4: Lib Dem | AU4: LD | AV4: =COUNTIF($J$3:$J$652,AU4) -> 72 | AW4: ='Election result'!B6 -> 72
A5: 3 | B5: =VLOOKUP(A5,$Y$2:$Z$13,2,1) -> 1 | C5: =VLOOKUP(B5,$V$2:$AB$14,7,0) -> 1 | D5: =VLOOKUP(B5,$V$2:$AC$13,8,0) -> 5 | E5: =IF(OR(A5=$Y$3,A5=$Y$4,A5=$Y$5,A5=$Y$6,A5=$Y$7,A5=$Y$8,A5=$Y$9,A5=$Y$10,A5=$Y$11,A5=$Y$12,A5=$Y$12),0,1) -> 1 | F5: =IF(E5=0,0,D5+F4) -> 10 | G5: =(F5/180)*PI() -> 0.17453293 | H5: =C5*COS(G5) -> 0.98480775 | I5: =C5*SIN(G5) -> 0.17364818 | J5: =VLOOKUP(A5,$AQ$3:$AR$58,2,1) -> L | K5: =IF(J5="L",H5,NA()) -> 0.98480775 | L5: =IF(J5="l",I5,NA()) -> 0.17364818 | M5: =IF(J5="C",H5,NA()) -> #N/A | N5: =IF(J5="C",I5,NA()) -> #N/A | O5: =IF(J5="LD",H5,NA()) -> #N/A | P5: =IF(J5="LD",I5,NA()) -> #N/A | Q5: =IF(J5="SNP",H5,NA()) -> #N/A | R5: =IF(J5="SNP",I5,NA()) -> #N/A | S5: =IF(J5="Oth",H5,NA()) -> #N/A | T5: =IF(J5="oth",I5,NA()) -> #N/A | V5: 3 | W5: 45 | X5: =W5 -> 45 | Y5: =Y4+X5 -> 124 | Z5: =Z4+1 -> 4 | AA5: =COUNTIF($B$3:$B$652,Z4)-X5 -> 0 | AB5: =AB4+0.1 -> 1.2 | AC5: =180/(W5-1) -> 4.0909091 | AD5: 0 | AF5: 3 | AG5: 45 | AH5: 26 | AI5: =AG5-AH5-AJ5-AK5-AL5 -> 8 | AJ5: 7 | AK5: 1 | AL5: 3 | AN5: 1 | AO5: Lib Dem | AP5: =HLOOKUP(AO5,$AH$2:$AL$13,AN5+1,) -> 6 | AQ5: =AQ4+AP4 -> 27 | AR5: LD | AT5: SNP | AU5: SNP | AV5: =COUNTIF($J$3:$J$652,AU5) -> 9 | AW5: ='Election result'!B7 -> 9
A6: 4 | B6: =VLOOKUP(A6,$Y$2:$Z$13,2,1) -> 1 | C6: =VLOOKUP(B6,$V$2:$AB$14,7,0) -> 1 | D6: =VLOOKUP(B6,$V$2:$AC$13,8,0) -> 5 | E6: =IF(OR(A6=$Y$3,A6=$Y$4,A6=$Y$5,A6=$Y$6,A6=$Y$7,A6=$Y$8,A6=$Y$9,A6=$Y$10,A6=$Y$11,A6=$Y$12,A6=$Y$12),0,1) -> 1 | F6: =IF(E6=0,0,D6+F5) -> 15 | G6: =(F6/180)*PI() -> 0.26179939 | H6: =C6*COS(G6) -> 0.96592583 | I6: =C6*SIN(G6) -> 0.25881905 | J6: =VLOOKUP(A6,$AQ$3:$AR$58,2,1) -> L | K6: =IF(J6="L",H6,NA()) -> 0.96592583 | L6: =IF(J6="l",I6,NA()) -> 0.25881905 | M6: =IF(J6="C",H6,NA()) -> #N/A | N6: =IF(J6="C",I6,NA()) -> #N/A | O6: =IF(J6="LD",H6,NA()) -> #N/A | P6: =IF(J6="LD",I6,NA()) -> #N/A | Q6: =IF(J6="SNP",H6,NA()) -> #N/A | R6: =IF(J6="SNP",I6,NA()) -> #N/A | S6: =IF(J6="Oth",H6,NA()) -> #N/A | T6: =IF(J6="oth",I6,NA()) -> #N/A | V6: 4 | W6: 50 | X6: =W6 -> 50 | Y6: =Y5+X6 -> 174 | Z6: =Z5+1 -> 5 | AA6: =COUNTIF($B$3:$B$652,Z5)-X6 -> 0 | AB6: =AB5+0.1 -> 1.3 | AC6: =180/(W6-1) -> 3.6734694 | AD6: 0 | AF6: 4 | AG6: 50 | AH6: 30 | AI6: =AG6-AH6-AJ6-AK6-AL6 -> 9 | AJ6: 7 | AK6: 1 | AL6: 3 | AN6: 1 | AO6: SNP | AP6: =HLOOKUP(AO6,$AH$2:$AL$13,AN6+1,) -> 2 | AQ6: =AQ5+AP5 -> 33 | AR6: SNP | AT6: Other | AU6: Oth | AV6: =COUNTIF($J$3:$J$652,AU6) -> 36 | AW6: ='Election result'!B8 -> 36
A7: 5 | B7: =VLOOKUP(A7,$Y$2:$Z$13,2,1) -> 1 | C7: =VLOOKUP(B7,$V$2:$AB$14,7,0) -> 1 | D7: =VLOOKUP(B7,$V$2:$AC$13,8,0) -> 5 | E7: =IF(OR(A7=$Y$3,A7=$Y$4,A7=$Y$5,A7=$Y$6,A7=$Y$7,A7=$Y$8,A7=$Y$9,A7=$Y$10,A7=$Y$11,A7=$Y$12,A7=$Y$12),0,1) -> 1 | F7: =IF(E7=0,0,D7+F6) -> 20 | G7: =(F7/180)*PI() -> 0.34906585 | H7: =C7*COS(G7) -> 0.93969262 | I7: =C7*SIN(G7) -> 0.34202014 | J7: =VLOOKUP(A7,$AQ$3:$AR$58,2,1) -> L | K7: =IF(J7="L",H7,NA()) -> 0.93969262 | L7: =IF(J7="l",I7,NA()) -> 0.34202014 | M7: =IF(J7="C",H7,NA()) -> #N/A | N7: =IF(J7="C",I7,NA()) -> #N/A | O7: =IF(J7="LD",H7,NA()) -> #N/A | P7: =IF(J7="LD",I7,NA()) -> #N/A | Q7: =IF(J7="SNP",H7,NA()) -> #N/A | R7: =IF(J7="SNP",I7,NA()) -> #N/A | S7: =IF(J7="Oth",H7,NA()) -> #N/A | T7: =IF(J7="oth",I7,NA()) -> #N/A | V7: 5 | W7: 55 | X7: =W7 -> 55 | Y7: =Y6+X7 -> 229 | Z7: =Z6+1 -> 6 | AA7: =COUNTIF($B$3:$B$652,Z6)-X7 -> 0 | AB7: =AB6+0.1 -> 1.4 | AC7: =180/(W7-1) -> 3.3333333 | AD7: 0 | AF7: 5 | AG7: 55 | AH7: 34 | AI7: =AG7-AH7-AJ7-AK7-AL7 -> 10 | AJ7: 7 | AK7: 1 | AL7: 3 | AN7: 1 | AO7: Other | AP7: =HLOOKUP(AO7,$AH$2:$AL$13,AN7+1,) -> 3 | AQ7: =AQ6+AP6 -> 35 | AR7: Oth | AU7: SUM | AV7: =SUM(AV2:AV6) -> 650
A8: 6 | B8: =VLOOKUP(A8,$Y$2:$Z$13,2,1) -> 1 | C8: =VLOOKUP(B8,$V$2:$AB$14,7,0) -> 1 | D8: =VLOOKUP(B8,$V$2:$AC$13,8,0) -> 5 | E8: =IF(OR(A8=$Y$3,A8=$Y$4,A8=$Y$5,A8=$Y$6,A8=$Y$7,A8=$Y$8,A8=$Y$9,A8=$Y$10,A8=$Y$11,A8=$Y$12,A8=$Y$12),0,1) -> 1 | F8: =IF(E8=0,0,D8+F7) -> 25 | G8: =(F8/180)*PI() -> 0.43633231 | H8: =C8*COS(G8) -> 0.90630779 | I8: =C8*SIN(G8) -> 0.42261826 | J8: =VLOOKUP(A8,$AQ$3:$AR$58,2,1) -> L | K8: =IF(J8="L",H8,NA()) -> 0.90630779 | L8: =IF(J8="l",I8,NA()) -> 0.42261826 | M8: =IF(J8="C",H8,NA()) -> #N/A | N8: =IF(J8="C",I8,NA()) -> #N/A | O8: =IF(J8="LD",H8,NA()) -> #N/A | P8: =IF(J8="LD",I8,NA()) -> #N/A | Q8: =IF(J8="SNP",H8,NA()) -> #N/A | R8: =IF(J8="SNP",I8,NA()) -> #N/A | S8: =IF(J8="Oth",H8,NA()) -> #N/A | T8: =IF(J8="oth",I8,NA()) -> #N/A | V8: 6 | W8: 60 | X8: =W8 -> 60 | Y8: =Y7+X8 -> 289 | Z8: =Z7+1 -> 7 | AA8: =COUNTIF($B$3:$B$652,Z7)-X8 -> 0 | AB8: =AB7+0.1 -> 1.5 | AC8: =180/(W8-1) -> 3.0508475 | AD8: 0 | AF8: 6 | AG8: 60 | AH8: 38 | AI8: =AG8-AH8-AJ8-AK8-AL8 -> 11 | AJ8: 7 | AK8: 1 | AL8: 3 | AN8: 2 | AO8: =AO3 -> Labour | AP8: =HLOOKUP(AO8,$AH$2:$AL$13,AN8+1,) -> 22 | AQ8: =AQ7+AP7 -> 38 | AR8: =AR3 -> L
A9: 7 | B9: =VLOOKUP(A9,$Y$2:$Z$13,2,1) -> 1 | C9: =VLOOKUP(B9,$V$2:$AB$14,7,0) -> 1 | D9: =VLOOKUP(B9,$V$2:$AC$13,8,0) -> 5 | E9: =IF(OR(A9=$Y$3,A9=$Y$4,A9=$Y$5,A9=$Y$6,A9=$Y$7,A9=$Y$8,A9=$Y$9,A9=$Y$10,A9=$Y$11,A9=$Y$12,A9=$Y$12),0,1) -> 1 | F9: =IF(E9=0,0,D9+F8) -> 30 | G9: =(F9/180)*PI() -> 0.52359878 | H9: =C9*COS(G9) -> 0.8660254 | I9: =C9*SIN(G9) -> 0.5 | J9: =VLOOKUP(A9,$AQ$3:$AR$58,2,1) -> L | K9: =IF(J9="L",H9,NA()) -> 0.8660254 | L9: =IF(J9="l",I9,NA()) -> 0.5 | M9: =IF(J9="C",H9,NA()) -> #N/A | N9: =IF(J9="C",I9,NA()) -> #N/A | O9: =IF(J9="LD",H9,NA()) -> #N/A | P9: =IF(J9="LD",I9,NA()) -> #N/A | Q9: =IF(J9="SNP",H9,NA()) -> #N/A | R9: =IF(J9="SNP",I9,NA()) -> #N/A | S9: =IF(J9="Oth",H9,NA()) -> #N/A | T9: =IF(J9="oth",I9,NA()) -> #N/A | V9: 7 | W9: 65 | X9: =W9 -> 65 | Y9: =Y8+X9 -> 354 | Z9: =Z8+1 -> 8 | AA9: =COUNTIF($B$3:$B$652,Z8)-X9 -> 0 | AB9: =AB8+0.1 -> 1.6 | AC9: =180/(W9-1) -> 2.8125 | AD9: 0 | AF9: 7 | AG9: 65 | AH9: 42 | AI9: =AG9-AH9-AJ9-AK9-AL9 -> 12 | AJ9: 7 | AK9: 1 | AL9: 3 | AN9: 2 | AO9: =AO4 -> Conservatives | AP9: =HLOOKUP(AO9,$AH$2:$AL$13,AN9+1,) -> 8 | AQ9: =AQ8+AP8 -> 60 | AR9: =AR4 -> C | AU9: Seat tallies
A10: 8 | B10: =VLOOKUP(A10,$Y$2:$Z$13,2,1) -> 1 | C10: =VLOOKUP(B10,$V$2:$AB$14,7,0) -> 1 | D10: =VLOOKUP(B10,$V$2:$AC$13,8,0) -> 5 | E10: =IF(OR(A10=$Y$3,A10=$Y$4,A10=$Y$5,A10=$Y$6,A10=$Y$7,A10=$Y$8,A10=$Y$9,A10=$Y$10,A10=$Y$11,A10=$Y$12,A10=$Y$12),0,1) -> 1 | F10: =IF(E10=0,0,D10+F9) -> 35 | G10: =(F10/180)*PI() -> 0.61086524 | H10: =C10*COS(G10) -> 0.81915204 | I10: =C10*SIN(G10) -> 0.57357644 | J10: =VLOOKUP(A10,$AQ$3:$AR$58,2,1) -> L | K10: =IF(J10="L",H10,NA()) -> 0.81915204 | L10: =IF(J10="l",I10,NA()) -> 0.57357644 | M10: =IF(J10="C",H10,NA()) -> #N/A | N10: =IF(J10="C",I10,NA()) -> #N/A | O10: =IF(J10="LD",H10,NA()) -> #N/A | P10: =IF(J10="LD",I10,NA()) -> #N/A | Q10: =IF(J10="SNP",H10,NA()) -> #N/A | R10: =IF(J10="SNP",I10,NA()) -> #N/A | S10: =IF(J10="Oth",H10,NA()) -> #N/A | T10: =IF(J10="oth",I10,NA()) -> #N/A | V10: 8 | W10: 69 | X10: =W10 -> 69 | Y10: =Y9+X10 -> 423 | Z10: =Z9+1 -> 9 | AA10: =COUNTIF($B$3:$B$652,Z9)-X10 -> 0 | AB10: =AB9+0.1 -> 1.7 | AC10: =180/(W10-1) -> 2.6470588 | AD10: 0 | AF10: 8 | AG10: 69 | AH10: 46 | AI10: =AG10-AH10-AJ10-AK10-AL10 -> 13 | AJ10: 6 | AK10: 1 | AL10: 3 | AN10: 2 | AO10: =AO5 -> Lib Dem | AP10: =HLOOKUP(AO10,$AH$2:$AL$13,AN10+1,) -> 7 | AQ10: =AQ9+AP9 -> 68 | AR10: =AR5 -> LD | AU10: =AT2 -> Labour | AV10: =AT2&" "&""&AV2 -> Labour 412
A11: 9 | B11: =VLOOKUP(A11,$Y$2:$Z$13,2,1) -> 1 | C11: =VLOOKUP(B11,$V$2:$AB$14,7,0) -> 1 | D11: =VLOOKUP(B11,$V$2:$AC$13,8,0) -> 5 | E11: =IF(OR(A11=$Y$3,A11=$Y$4,A11=$Y$5,A11=$Y$6,A11=$Y$7,A11=$Y$8,A11=$Y$9,A11=$Y$10,A11=$Y$11,A11=$Y$12,A11=$Y$12),0,1) -> 1 | F11: =IF(E11=0,0,D11+F10) -> 40 | G11: =(F11/180)*PI() -> 0.6981317 | H11: =C11*COS(G11) -> 0.76604444 | I11: =C11*SIN(G11) -> 0.64278761 | J11: =VLOOKUP(A11,$AQ$3:$AR$58,2,1) -> L | K11: =IF(J11="L",H11,NA()) -> 0.76604444 | L11: =IF(J11="l",I11,NA()) -> 0.64278761 | M11: =IF(J11="C",H11,NA()) -> #N/A | N11: =IF(J11="C",I11,NA()) -> #N/A | O11: =IF(J11="LD",H11,NA()) -> #N/A | P11: =IF(J11="LD",I11,NA()) -> #N/A | Q11: =IF(J11="SNP",H11,NA()) -> #N/A | R11: =IF(J11="SNP",I11,NA()) -> #N/A | S11: =IF(J11="Oth",H11,NA()) -> #N/A | T11: =IF(J11="oth",I11,NA()) -> #N/A | V11: 9 | W11: 73 | X11: =W11 -> 73 | Y11: =Y10+X11 -> 496 | Z11: =Z10+1 -> 10 | AA11: =COUNTIF($B$3:$B$652,Z10)-X11 -> 0 | AB11: =AB10+0.1 -> 1.8 | AC11: =180/(W11-1) -> 2.5 | AD11: 0 | AF11: 9 | AG11: 73 | AH11: 49 | AI11: =AG11-AH11-AJ11-AK11-AL11 -> 14 | AJ11: 6 | AK11: 0 | AL11: 4 | AN11: 2 | AO11: =AO6 -> SNP | AP11: =HLOOKUP(AO11,$AH$2:$AL$13,AN11+1,) -> 1 | AQ11: =AQ10+AP10 -> 75 | AR11: =AR6 -> SNP | AU11: x | AV11: 0
A12: 10 | B12: =VLOOKUP(A12,$Y$2:$Z$13,2,1) -> 1 | C12: =VLOOKUP(B12,$V$2:$AB$14,7,0) -> 1 | D12: =VLOOKUP(B12,$V$2:$AC$13,8,0) -> 5 | E12: =IF(OR(A12=$Y$3,A12=$Y$4,A12=$Y$5,A12=$Y$6,A12=$Y$7,A12=$Y$8,A12=$Y$9,A12=$Y$10,A12=$Y$11,A12=$Y$12,A12=$Y$12),0,1) -> 1 | F12: =IF(E12=0,0,D12+F11) -> 45 | G12: =(F12/180)*PI() -> 0.78539816 | H12: =C12*COS(G12) -> 0.70710678 | I12: =C12*SIN(G12) -> 0.70710678 | J12: =VLOOKUP(A12,$AQ$3:$AR$58,2,1) -> L | K12: =IF(J12="L",H12,NA()) -> 0.70710678 | L12: =IF(J12="l",I12,NA()) -> 0.70710678 | M12: =IF(J12="C",H12,NA()) -> #N/A | N12: =IF(J12="C",I12,NA()) -> #N/A | O12: =IF(J12="LD",H12,NA()) -> #N/A | P12: =IF(J12="LD",I12,NA()) -> #N/A | Q12: =IF(J12="SNP",H12,NA()) -> #N/A | R12: =IF(J12="SNP",I12,NA()) -> #N/A | S12: =IF(J12="Oth",H12,NA()) -> #N/A | T12: =IF(J12="oth",I12,NA()) -> #N/A | V12: 10 | W12: 75 | X12: =W12 -> 75 | Y12: =Y11+X12 -> 571 | Z12: =Z11+1 -> 11 | AA12: =COUNTIF($B$3:$B$652,Z11)-X12 -> 0 | AB12: =AB11+0.1 -> 1.9 | AC12: =180/(W12-1) -> 2.4324324 | AD12: 0 | AF12: 10 | AG12: 75 | AH12: 51 | AI12: =AG12-AH12-AJ12-AK12-AL12 -> 14 | AJ12: 6 | AK12: 0 | AL12: 4 | AN12: 2 | AO12: =AO7 -> Other | AP12: =HLOOKUP(AO12,$AH$2:$AL$13,AN12+1,) -> 3 | AQ12: =AQ11+AP11 -> 76 | AR12: =AR7 -> Oth | AU12: y | AV12: =0.75*SIN(90/180) -> 0.35956915
A13: 11 | B13: =VLOOKUP(A13,$Y$2:$Z$13,2,1) -> 1 | C13: =VLOOKUP(B13,$V$2:$AB$14,7,0) -> 1 | D13: =VLOOKUP(B13,$V$2:$AC$13,8,0) -> 5 | E13: =IF(OR(A13=$Y$3,A13=$Y$4,A13=$Y$5,A13=$Y$6,A13=$Y$7,A13=$Y$8,A13=$Y$9,A13=$Y$10,A13=$Y$11,A13=$Y$12,A13=$Y$12),0,1) -> 1 | F13: =IF(E13=0,0,D13+F12) -> 50 | G13: =(F13/180)*PI() -> 0.87266463 | H13: =C13*COS(G13) -> 0.64278761 | I13: =C13*SIN(G13) -> 0.76604444 | J13: =VLOOKUP(A13,$AQ$3:$AR$58,2,1) -> L | K13: =IF(J13="L",H13,NA()) -> 0.64278761 | L13: =IF(J13="l",I13,NA()) -> 0.76604444 | M13: =IF(J13="C",H13,NA()) -> #N/A | N13: =IF(J13="C",I13,NA()) -> #N/A | O13: =IF(J13="LD",H13,NA()) -> #N/A | P13: =IF(J13="LD",I13,NA()) -> #N/A | Q13: =IF(J13="SNP",H13,NA()) -> #N/A | R13: =IF(J13="SNP",I13,NA()) -> #N/A | S13: =IF(J13="Oth",H13,NA()) -> #N/A | T13: =IF(J13="oth",I13,NA()) -> #N/A | V13: 11 | W13: 80 | X13: =W13 -> 80 | Y13: =Y12+X13 -> 651 | Z13: =Z12+1 -> 12 | AA13: =COUNTIF($B$3:$B$652,Z12)-X13 -> 0 | AB13: =AB12+0.1 -> 2 | AC13: =180/(W13-1) -> 2.278481 | AD13: 0 | AF13: 11 | AG13: 80 | AH13: 55 | AI13: =AG13-AH13-AJ13-AK13-AL13 -> 15 | AJ13: 6 | AK13: 0 | AL13: 4 | AN13: 3 | AO13: =AO8 -> Labour | AP13: =HLOOKUP(AO13,$AH$2:$AL$13,AN13+1,) -> 26 | AQ13: =AQ12+AP12 -> 79 | AR13: =AR8 -> L
A14: =A13+1 -> 12 | B14: =VLOOKUP(A14,$Y$2:$Z$13,2,1) -> 1 | C14: =VLOOKUP(B14,$V$2:$AB$14,7,0) -> 1 | D14: =VLOOKUP(B14,$V$2:$AC$13,8,0) -> 5 | E14: =IF(OR(A14=$Y$3,A14=$Y$4,A14=$Y$5,A14=$Y$6,A14=$Y$7,A14=$Y$8,A14=$Y$9,A14=$Y$10,A14=$Y$11,A14=$Y$12,A14=$Y$12),0,1) -> 1 | F14: =IF(E14=0,0,D14+F13) -> 55 | G14: =(F14/180)*PI() -> 0.95993109 | H14: =C14*COS(G14) -> 0.57357644 | I14: =C14*SIN(G14) -> 0.81915204 | J14: =VLOOKUP(A14,$AQ$3:$AR$58,2,1) -> L | K14: =IF(J14="L",H14,NA()) -> 0.57357644 | L14: =IF(J14="l",I14,NA()) -> 0.81915204 | M14: =IF(J14="C",H14,NA()) -> #N/A | N14: =IF(J14="C",I14,NA()) -> #N/A | O14: =IF(J14="LD",H14,NA()) -> #N/A | P14: =IF(J14="LD",I14,NA()) -> #N/A | Q14: =IF(J14="SNP",H14,NA()) -> #N/A | R14: =IF(J14="SNP",I14,NA()) -> #N/A | S14: =IF(J14="Oth",H14,NA()) -> #N/A | T14: =IF(J14="oth",I14,NA()) -> #N/A | V14: Total Seats | W14: =SUM(W3:W13) -> 650 | X14: =SUM(X3:X13) -> 651 | AG14: TOTAL | AH14: =SUM(AH3:AH13) -> 413 | AI14: =SUM(AI3:AI13) -> 121 | AJ14: =SUM(AJ3:AJ13) -> 72 | AK14: =SUM(AK3:AK13) -> 9 | AL14: =SUM(AL3:AL13) -> 36 | AN14: 3 | AO14: =AO9 -> Conservatives | AP14: =HLOOKUP(AO14,$AH$2:$AL$13,AN14+1,) -> 8 | AQ14: =AQ13+AP13 -> 105 | AR14: =AR9 -> C | AU14: =AT3 -> Conservatives | AV14: =AT3&" "&""&AV3 -> Conservatives 121
A15: =A14+1 -> 13 | B15: =VLOOKUP(A15,$Y$2:$Z$13,2,1) -> 1 | C15: =VLOOKUP(B15,$V$2:$AB$14,7,0) -> 1 | D15: =VLOOKUP(B15,$V$2:$AC$13,8,0) -> 5 | E15: =IF(OR(A15=$Y$3,A15=$Y$4,A15=$Y$5,A15=$Y$6,A15=$Y$7,A15=$Y$8,A15=$Y$9,A15=$Y$10,A15=$Y$11,A15=$Y$12,A15=$Y$12),0,1) -> 1 | F15: =IF(E15=0,0,D15+F14) -> 60 | G15: =(F15/180)*PI() -> 1.0471976 | H15: =C15*COS(G15) -> 0.5 | I15: =C15*SIN(G15) -> 0.8660254 | J15: =VLOOKUP(A15,$AQ$3:$AR$58,2,1) -> L | K15: =IF(J15="L",H15,NA()) -> 0.5 | L15: =IF(J15="l",I15,NA()) -> 0.8660254 | M15: =IF(J15="C",H15,NA()) -> #N/A | N15: =IF(J15="C",I15,NA()) -> #N/A | O15: =IF(J15="LD",H15,NA()) -> #N/A | P15: =IF(J15="LD",I15,NA()) -> #N/A | Q15: =IF(J15="SNP",H15,NA()) -> #N/A | R15: =IF(J15="SNP",I15,NA()) -> #N/A | S15: =IF(J15="Oth",H15,NA()) -> #N/A | T15: =IF(J15="oth",I15,NA()) -> #N/A | AG15: TRUE | AH15: ='Election result'!B4 -> 412 | AI15: ='Election result'!B5 -> 121 | AJ15: ='Election result'!B6 -> 72 | AK15: ='Election result'!B7 -> 9 | AL15: ='Election result'!B8 -> 36 | AN15: 3 | AO15: =AO10 -> Lib Dem | AP15: =HLOOKUP(AO15,$AH$2:$AL$13,AN15+1,) -> 7 | AQ15: =AQ14+AP14 -> 113 | AR15: =AR10 -> LD | AU15: x | AV15: 0
A16: =A15+1 -> 14 | B16: =VLOOKUP(A16,$Y$2:$Z$13,2,1) -> 1 | C16: =VLOOKUP(B16,$V$2:$AB$14,7,0) -> 1 | D16: =VLOOKUP(B16,$V$2:$AC$13,8,0) -> 5 | E16: =IF(OR(A16=$Y$3,A16=$Y$4,A16=$Y$5,A16=$Y$6,A16=$Y$7,A16=$Y$8,A16=$Y$9,A16=$Y$10,A16=$Y$11,A16=$Y$12,A16=$Y$12),0,1) -> 1 | F16: =IF(E16=0,0,D16+F15) -> 65 | G16: =(F16/180)*PI() -> 1.134464 | H16: =C16*COS(G16) -> 0.42261826 | I16: =C16*SIN(G16) -> 0.90630779 | J16: =VLOOKUP(A16,$AQ$3:$AR$58,2,1) -> L | K16: =IF(J16="L",H16,NA()) -> 0.42261826 | L16: =IF(J16="l",I16,NA()) -> 0.90630779 | M16: =IF(J16="C",H16,NA()) -> #N/A | N16: =IF(J16="C",I16,NA()) -> #N/A | O16: =IF(J16="LD",H16,NA()) -> #N/A | P16: =IF(J16="LD",I16,NA()) -> #N/A | Q16: =IF(J16="SNP",H16,NA()) -> #N/A | R16: =IF(J16="SNP",I16,NA()) -> #N/A | S16: =IF(J16="Oth",H16,NA()) -> #N/A | T16: =IF(J16="oth",I16,NA()) -> #N/A | AG16: CHECK | AH16: =AH14-AH15 -> 1 | AI16: =AI14-AI15 -> 0 | AJ16: =AJ14-AJ15 -> 0 | AK16: =AK14-AK15 -> 0 | AL16: =AL14-AL15 -> 0 | AN16: 3 | AO16: =AO11 -> SNP | AP16: =HLOOKUP(AO16,$AH$2:$AL$13,AN16+1,) -> 1 | AQ16: =AQ15+AP15 -> 120 | AR16: =AR11 -> SNP | AU16: y | AV16: =0.75*SIN(90/180) -> 0.35956915
A17: =A16+1 -> 15 | B17: =VLOOKUP(A17,$Y$2:$Z$13,2,1) -> 1 | C17: =VLOOKUP(B17,$V$2:$AB$14,7,0) -> 1 | D17: =VLOOKUP(B17,$V$2:$AC$13,8,0) -> 5 | E17: =IF(OR(A17=$Y$3,A17=$Y$4,A17=$Y$5,A17=$Y$6,A17=$Y$7,A17=$Y$8,A17=$Y$9,A17=$Y$10,A17=$Y$11,A17=$Y$12,A17=$Y$12),0,1) -> 1 | F17: =IF(E17=0,0,D17+F16) -> 70 | G17: =(F17/180)*PI() -> 1.2217305 | H17: =C17*COS(G17) -> 0.34202014 | I17: =C17*SIN(G17) -> 0.93969262 | J17: =VLOOKUP(A17,$AQ$3:$AR$58,2,1) -> L | K17: =IF(J17="L",H17,NA()) -> 0.34202014 | L17: =IF(J17="l",I17,NA()) -> 0.93969262 | M17: =IF(J17="C",H17,NA()) -> #N/A | N17: =IF(J17="C",I17,NA()) -> #N/A | O17: =IF(J17="LD",H17,NA()) -> #N/A | P17: =IF(J17="LD",I17,NA()) -> #N/A | Q17: =IF(J17="SNP",H17,NA()) -> #N/A | R17: =IF(J17="SNP",I17,NA()) -> #N/A | S17: =IF(J17="Oth",H17,NA()) -> #N/A | T17: =IF(J17="oth",I17,NA()) -> #N/A | V17: *This Arc-Dot chart may take some time to understand how it all works, but the philosophy is simple: | AG17: ALL | AH17: =SUM(AH14:AL14) -> 651 | AN17: 3 | AO17: =AO12 -> Other | AP17: =HLOOKUP(AO17,$AH$2:$AL$13,AN17+1,) -> 3 | AQ17: =AQ16+AP16 -> 121 | AR17: =AR12 -> Oth
A18: =A17+1 -> 16 | B18: =VLOOKUP(A18,$Y$2:$Z$13,2,1) -> 1 | C18: =VLOOKUP(B18,$V$2:$AB$14,7,0) -> 1 | D18: =VLOOKUP(B18,$V$2:$AC$13,8,0) -> 5 | E18: =IF(OR(A18=$Y$3,A18=$Y$4,A18=$Y$5,A18=$Y$6,A18=$Y$7,A18=$Y$8,A18=$Y$9,A18=$Y$10,A18=$Y$11,A18=$Y$12,A18=$Y$12),0,1) -> 1 | F18: =IF(E18=0,0,D18+F17) -> 75 | G18: =(F18/180)*PI() -> 1.3089969 | H18: =C18*COS(G18) -> 0.25881905 | I18: =C18*SIN(G18) -> 0.96592583 | J18: =VLOOKUP(A18,$AQ$3:$AR$58,2,1) -> L | K18: =IF(J18="L",H18,NA()) -> 0.25881905 | L18: =IF(J18="l",I18,NA()) -> 0.96592583 | M18: =IF(J18="C",H18,NA()) -> #N/A | N18: =IF(J18="C",I18,NA()) -> #N/A | O18: =IF(J18="LD",H18,NA()) -> #N/A | P18: =IF(J18="LD",I18,NA()) -> #N/A | Q18: =IF(J18="SNP",H18,NA()) -> #N/A | R18: =IF(J18="SNP",I18,NA()) -> #N/A | S18: =IF(J18="Oth",H18,NA()) -> #N/A | T18: =IF(J18="oth",I18,NA()) -> #N/A | V18: *create six half-circles, divide each ring into X number of points, and use radians to find the position | AG18: CHECK | AH18: =SUM(AH15:AL15) -> 650 | AN18: =AN13+1 -> 4 | AO18: =AO13 -> Labour | AP18: =HLOOKUP(AO18,$AH$2:$AL$13,AN18+1,) -> 30 | AQ18: =AQ17+AP17 -> 124 | AR18: =AR13 -> L | AU18: =AT4 -> Lib Dem | AV18: =AT4&" "&""&AV4 -> Lib Dem 72
A19: =A18+1 -> 17 | B19: =VLOOKUP(A19,$Y$2:$Z$13,2,1) -> 1 | C19: =VLOOKUP(B19,$V$2:$AB$14,7,0) -> 1 | D19: =VLOOKUP(B19,$V$2:$AC$13,8,0) -> 5 | E19: =IF(OR(A19=$Y$3,A19=$Y$4,A19=$Y$5,A19=$Y$6,A19=$Y$7,A19=$Y$8,A19=$Y$9,A19=$Y$10,A19=$Y$11,A19=$Y$12,A19=$Y$12),0,1) -> 1 | F19: =IF(E19=0,0,D19+F18) -> 80 | G19: =(F19/180)*PI() -> 1.3962634 | H19: =C19*COS(G19) -> 0.17364818 | I19: =C19*SIN(G19) -> 0.98480775 | J19: =VLOOKUP(A19,$AQ$3:$AR$58,2,1) -> L | K19: =IF(J19="L",H19,NA()) -> 0.17364818 | L19: =IF(J19="l",I19,NA()) -> 0.98480775 | M19: =IF(J19="C",H19,NA()) -> #N/A | N19: =IF(J19="C",I19,NA()) -> #N/A | O19: =IF(J19="LD",H19,NA()) -> #N/A | P19: =IF(J19="LD",I19,NA()) -> #N/A | Q19: =IF(J19="SNP",H19,NA()) -> #N/A | R19: =IF(J19="SNP",I19,NA()) -> #N/A | S19: =IF(J19="Oth",H19,NA()) -> #N/A | T19: =IF(J19="oth",I19,NA()) -> #N/A | V19: *of each point along each ring. The method used here tries to automate the process as much as possible, | AN19: =AN14+1 -> 4 | AO19: =AO14 -> Conservatives | AP19: =HLOOKUP(AO19,$AH$2:$AL$13,AN19+1,) -> 9 | AQ19: =AQ18+AP18 -> 154 | AR19: =AR14 -> C | AU19: x | AV19: 0
A20: =A19+1 -> 18 | B20: =VLOOKUP(A20,$Y$2:$Z$13,2,1) -> 1 | C20: =VLOOKUP(B20,$V$2:$AB$14,7,0) -> 1 | D20: =VLOOKUP(B20,$V$2:$AC$13,8,0) -> 5 | E20: =IF(OR(A20=$Y$3,A20=$Y$4,A20=$Y$5,A20=$Y$6,A20=$Y$7,A20=$Y$8,A20=$Y$9,A20=$Y$10,A20=$Y$11,A20=$Y$12,A20=$Y$12),0,1) -> 1 | F20: =IF(E20=0,0,D20+F19) -> 85 | G20: =(F20/180)*PI() -> 1.4835299 | H20: =C20*COS(G20) -> 0.087155743 | I20: =C20*SIN(G20) -> 0.9961947 | J20: =VLOOKUP(A20,$AQ$3:$AR$58,2,1) -> L | K20: =IF(J20="L",H20,NA()) -> 0.087155743 | L20: =IF(J20="l",I20,NA()) -> 0.9961947 | M20: =IF(J20="C",H20,NA()) -> #N/A | N20: =IF(J20="C",I20,NA()) -> #N/A | O20: =IF(J20="LD",H20,NA()) -> #N/A | P20: =IF(J20="LD",I20,NA()) -> #N/A | Q20: =IF(J20="SNP",H20,NA()) -> #N/A | R20: =IF(J20="SNP",I20,NA()) -> #N/A | S20: =IF(J20="Oth",H20,NA()) -> #N/A | T20: =IF(J20="oth",I20,NA()) -> #N/A | V20: *though with something other than three groups, some additional work is necessary. | AN20: =AN15+1 -> 4 | AO20: =AO15 -> Lib Dem | AP20: =HLOOKUP(AO20,$AH$2:$AL$13,AN20+1,) -> 7 | AQ20: =AQ19+AP19 -> 163 | AR20: =AR15 -> LD | AU20: y | AV20: =0.75*SIN(90/180) -> 0.35956915
A21: =A20+1 -> 19 | B21: =VLOOKUP(A21,$Y$2:$Z$13,2,1) -> 1 | C21: =VLOOKUP(B21,$V$2:$AB$14,7,0) -> 1 | D21: =VLOOKUP(B21,$V$2:$AC$13,8,0) -> 5 | E21: =IF(OR(A21=$Y$3,A21=$Y$4,A21=$Y$5,A21=$Y$6,A21=$Y$7,A21=$Y$8,A21=$Y$9,A21=$Y$10,A21=$Y$11,A21=$Y$12,A21=$Y$12),0,1) -> 1 | F21: =IF(E21=0,0,D21+F20) -> 90 | G21: =(F21/180)*PI() -> 1.5707963 | H21: =C21*COS(G21) -> 6.1257423e-17 | I21: =C21*SIN(G21) -> 1 | J21: =VLOOKUP(A21,$AQ$3:$AR$58,2,1) -> L | K21: =IF(J21="L",H21,NA()) -> 6.1257423e-17 | L21: =IF(J21="l",I21,NA()) -> 1 | M21: =IF(J21="C",H21,NA()) -> #N/A | N21: =IF(J21="C",I21,NA()) -> #N/A | O21: =IF(J21="LD",H21,NA()) -> #N/A | P21: =IF(J21="LD",I21,NA()) -> #N/A | Q21: =IF(J21="SNP",H21,NA()) -> #N/A | R21: =IF(J21="SNP",I21,NA()) -> #N/A | S21: =IF(J21="Oth",H21,NA()) -> #N/A | T21: =IF(J21="oth",I21,NA()) -> #N/A | AN21: =AN16+1 -> 4 | AO21: =AO16 -> SNP | AP21: =HLOOKUP(AO21,$AH$2:$AL$13,AN21+1,) -> 1 | AQ21: =AQ20+AP20 -> 170 | AR21: =AR16 -> SNP
A22: =A21+1 -> 20 | B22: =VLOOKUP(A22,$Y$2:$Z$13,2,1) -> 1 | C22: =VLOOKUP(B22,$V$2:$AB$14,7,0) -> 1 | D22: =VLOOKUP(B22,$V$2:$AC$13,8,0) -> 5 | E22: =IF(OR(A22=$Y$3,A22=$Y$4,A22=$Y$5,A22=$Y$6,A22=$Y$7,A22=$Y$8,A22=$Y$9,A22=$Y$10,A22=$Y$11,A22=$Y$12,A22=$Y$12),0,1) -> 1 | F22: =IF(E22=0,0,D22+F21) -> 95 | G22: =(F22/180)*PI() -> 1.6580628 | H22: =C22*COS(G22) -> -0.087155743 | I22: =C22*SIN(G22) -> 0.9961947 | J22: =VLOOKUP(A22,$AQ$3:$AR$58,2,1) -> C | K22: =IF(J22="L",H22,NA()) -> #N/A | L22: =IF(J22="l",I22,NA()) -> #N/A | M22: =IF(J22="C",H22,NA()) -> -0.087155743 | N22: =IF(J22="C",I22,NA()) -> 0.9961947 | O22: =IF(J22="LD",H22,NA()) -> #N/A | P22: =IF(J22="LD",I22,NA()) -> #N/A | Q22: =IF(J22="SNP",H22,NA()) -> #N/A | R22: =IF(J22="SNP",I22,NA()) -> #N/A | S22: =IF(J22="Oth",H22,NA()) -> #N/A | T22: =IF(J22="oth",I22,NA()) -> #N/A | AN22: =AN17+1 -> 4 | AO22: =AO17 -> Other | AP22: =HLOOKUP(AO22,$AH$2:$AL$13,AN22+1,) -> 3 | AQ22: =AQ21+AP21 -> 171 | AR22: =AR17 -> Oth | AU22: =AT5 -> SNP | AV22: =AT5&" "&""&AV5 -> SNP 9
A23: =A22+1 -> 21 | B23: =VLOOKUP(A23,$Y$2:$Z$13,2,1) -> 1 | C23: =VLOOKUP(B23,$V$2:$AB$14,7,0) -> 1 | D23: =VLOOKUP(B23,$V$2:$AC$13,8,0) -> 5 | E23: =IF(OR(A23=$Y$3,A23=$Y$4,A23=$Y$5,A23=$Y$6,A23=$Y$7,A23=$Y$8,A23=$Y$9,A23=$Y$10,A23=$Y$11,A23=$Y$12,A23=$Y$12),0,1) -> 1 | F23: =IF(E23=0,0,D23+F22) -> 100 | G23: =(F23/180)*PI() -> 1.7453293 | H23: =C23*COS(G23) -> -0.17364818 | I23: =C23*SIN(G23) -> 0.98480775 | J23: =VLOOKUP(A23,$AQ$3:$AR$58,2,1) -> C | K23: =IF(J23="L",H23,NA()) -> #N/A | L23: =IF(J23="l",I23,NA()) -> #N/A | M23: =IF(J23="C",H23,NA()) -> -0.17364818 | N23: =IF(J23="C",I23,NA()) -> 0.98480775 | O23: =IF(J23="LD",H23,NA()) -> #N/A | P23: =IF(J23="LD",I23,NA()) -> #N/A | Q23: =IF(J23="SNP",H23,NA()) -> #N/A | R23: =IF(J23="SNP",I23,NA()) -> #N/A | S23: =IF(J23="Oth",H23,NA()) -> #N/A | T23: =IF(J23="oth",I23,NA()) -> #N/A | AN23: =AN18+1 -> 5 | AO23: =AO18 -> Labour | AP23: =HLOOKUP(AO23,$AH$2:$AL$13,AN23+1,) -> 34 | AQ23: =AQ22+AP22 -> 174 | AR23: =AR18 -> L | AU23: x | AV23: 0
A24: =A23+1 -> 22 | B24: =VLOOKUP(A24,$Y$2:$Z$13,2,1) -> 1 | C24: =VLOOKUP(B24,$V$2:$AB$14,7,0) -> 1 | D24: =VLOOKUP(B24,$V$2:$AC$13,8,0) -> 5 | E24: =IF(OR(A24=$Y$3,A24=$Y$4,A24=$Y$5,A24=$Y$6,A24=$Y$7,A24=$Y$8,A24=$Y$9,A24=$Y$10,A24=$Y$11,A24=$Y$12,A24=$Y$12),0,1) -> 1 | F24: =IF(E24=0,0,D24+F23) -> 105 | G24: =(F24/180)*PI() -> 1.8325957 | H24: =C24*COS(G24) -> -0.25881905 | I24: =C24*SIN(G24) -> 0.96592583 | J24: =VLOOKUP(A24,$AQ$3:$AR$58,2,1) -> C | K24: =IF(J24="L",H24,NA()) -> #N/A | L24: =IF(J24="l",I24,NA()) -> #N/A | M24: =IF(J24="C",H24,NA()) -> -0.25881905 | N24: =IF(J24="C",I24,NA()) -> 0.96592583 | O24: =IF(J24="LD",H24,NA()) -> #N/A | P24: =IF(J24="LD",I24,NA()) -> #N/A | Q24: =IF(J24="SNP",H24,NA()) -> #N/A | R24: =IF(J24="SNP",I24,NA()) -> #N/A | S24: =IF(J24="Oth",H24,NA()) -> #N/A | T24: =IF(J24="oth",I24,NA()) -> #N/A | AN24: =AN19+1 -> 5 | AO24: =AO19 -> Conservatives | AP24: =HLOOKUP(AO24,$AH$2:$AL$13,AN24+1,) -> 10 | AQ24: =AQ23+AP23 -> 208 | AR24: =AR19 -> C | AU24: y | AV24: =0.75*SIN(90/180) -> 0.35956915
A25: =A24+1 -> 23 | B25: =VLOOKUP(A25,$Y$2:$Z$13,2,1) -> 1 | C25: =VLOOKUP(B25,$V$2:$AB$14,7,0) -> 1 | D25: =VLOOKUP(B25,$V$2:$AC$13,8,0) -> 5 | E25: =IF(OR(A25=$Y$3,A25=$Y$4,A25=$Y$5,A25=$Y$6,A25=$Y$7,A25=$Y$8,A25=$Y$9,A25=$Y$10,A25=$Y$11,A25=$Y$12,A25=$Y$12),0,1) -> 1 | F25: =IF(E25=0,0,D25+F24) -> 110 | G25: =(F25/180)*PI() -> 1.9198622 | H25: =C25*COS(G25) -> -0.34202014 | I25: =C25*SIN(G25) -> 0.93969262 | J25: =VLOOKUP(A25,$AQ$3:$AR$58,2,1) -> C | K25: =IF(J25="L",H25,NA()) -> #N/A | L25: =IF(J25="l",I25,NA()) -> #N/A | M25: =IF(J25="C",H25,NA()) -> -0.34202014 | N25: =IF(J25="C",I25,NA()) -> 0.93969262 | O25: =IF(J25="LD",H25,NA()) -> #N/A | P25: =IF(J25="LD",I25,NA()) -> #N/A | Q25: =IF(J25="SNP",H25,NA()) -> #N/A | R25: =IF(J25="SNP",I25,NA()) -> #N/A | S25: =IF(J25="Oth",H25,NA()) -> #N/A | T25: =IF(J25="oth",I25,NA()) -> #N/A | AN25: =AN20+1 -> 5 | AO25: =AO20 -> Lib Dem | AP25: =HLOOKUP(AO25,$AH$2:$AL$13,AN25+1,) -> 7 | AQ25: =AQ24+AP24 -> 218 | AR25: =AR20 -> LD
A26: =A25+1 -> 24 | B26: =VLOOKUP(A26,$Y$2:$Z$13,2,1) -> 1 | C26: =VLOOKUP(B26,$V$2:$AB$14,7,0) -> 1 | D26: =VLOOKUP(B26,$V$2:$AC$13,8,0) -> 5 | E26: =IF(OR(A26=$Y$3,A26=$Y$4,A26=$Y$5,A26=$Y$6,A26=$Y$7,A26=$Y$8,A26=$Y$9,A26=$Y$10,A26=$Y$11,A26=$Y$12,A26=$Y$12),0,1) -> 1 | F26: =IF(E26=0,0,D26+F25) -> 115 | G26: =(F26/180)*PI() -> 2.0071286 | H26: =C26*COS(G26) -> -0.42261826 | I26: =C26*SIN(G26) -> 0.90630779 | J26: =VLOOKUP(A26,$AQ$3:$AR$58,2,1) -> C | K26: =IF(J26="L",H26,NA()) -> #N/A | L26: =IF(J26="l",I26,NA()) -> #N/A | M26: =IF(J26="C",H26,NA()) -> -0.42261826 | N26: =IF(J26="C",I26,NA()) -> 0.90630779 | O26: =IF(J26="LD",H26,NA()) -> #N/A | P26: =IF(J26="LD",I26,NA()) -> #N/A | Q26: =IF(J26="SNP",H26,NA()) -> #N/A | R26: =IF(J26="SNP",I26,NA()) -> #N/A | S26: =IF(J26="Oth",H26,NA()) -> #N/A | T26: =IF(J26="oth",I26,NA()) -> #N/A | AN26: =AN21+1 -> 5 | AO26: =AO21 -> SNP | AP26: =HLOOKUP(AO26,$AH$2:$AL$13,AN26+1,) -> 1 | AQ26: =AQ25+AP25 -> 225 | AR26: =AR21 -> SNP | AU26: =AT6 -> Other | AV26: =AT6&" "&""&AV6 -> Other 36
A27: =A26+1 -> 25 | B27: =VLOOKUP(A27,$Y$2:$Z$13,2,1) -> 1 | C27: =VLOOKUP(B27,$V$2:$AB$14,7,0) -> 1 | D27: =VLOOKUP(B27,$V$2:$AC$13,8,0) -> 5 | E27: =IF(OR(A27=$Y$3,A27=$Y$4,A27=$Y$5,A27=$Y$6,A27=$Y$7,A27=$Y$8,A27=$Y$9,A27=$Y$10,A27=$Y$11,A27=$Y$12,A27=$Y$12),0,1) -> 1 | F27: =IF(E27=0,0,D27+F26) -> 120 | G27: =(F27/180)*PI() -> 2.0943951 | H27: =C27*COS(G27) -> -0.5 | I27: =C27*SIN(G27) -> 0.8660254 | J27: =VLOOKUP(A27,$AQ$3:$AR$58,2,1) -> C | K27: =IF(J27="L",H27,NA()) -> #N/A | L27: =IF(J27="l",I27,NA()) -> #N/A | M27: =IF(J27="C",H27,NA()) -> -0.5 | N27: =IF(J27="C",I27,NA()) -> 0.8660254 | O27: =IF(J27="LD",H27,NA()) -> #N/A | P27: =IF(J27="LD",I27,NA()) -> #N/A | Q27: =IF(J27="SNP",H27,NA()) -> #N/A | R27: =IF(J27="SNP",I27,NA()) -> #N/A | S27: =IF(J27="Oth",H27,NA()) -> #N/A | T27: =IF(J27="oth",I27,NA()) -> #N/A | AN27: =AN22+1 -> 5 | AO27: =AO22 -> Other | AP27: =HLOOKUP(AO27,$AH$2:$AL$13,AN27+1,) -> 3 | AQ27: =AQ26+AP26 -> 226 | AR27: =AR22 -> Oth | AU27: x | AV27: 0
A28: =A27+1 -> 26 | B28: =VLOOKUP(A28,$Y$2:$Z$13,2,1) -> 1 | C28: =VLOOKUP(B28,$V$2:$AB$14,7,0) -> 1 | D28: =VLOOKUP(B28,$V$2:$AC$13,8,0) -> 5 | E28: =IF(OR(A28=$Y$3,A28=$Y$4,A28=$Y$5,A28=$Y$6,A28=$Y$7,A28=$Y$8,A28=$Y$9,A28=$Y$10,A28=$Y$11,A28=$Y$12,A28=$Y$12),0,1) -> 1 | F28: =IF(E28=0,0,D28+F27) -> 125 | G28: =(F28/180)*PI() -> 2.1816616 | H28: =C28*COS(G28) -> -0.57357644 | I28: =C28*SIN(G28) -> 0.81915204 | J28: =VLOOKUP(A28,$AQ$3:$AR$58,2,1) -> C | K28: =IF(J28="L",H28,NA()) -> #N/A | L28: =IF(J28="l",I28,NA()) -> #N/A | M28: =IF(J28="C",H28,NA()) -> -0.57357644 | N28: =IF(J28="C",I28,NA()) -> 0.81915204 | O28: =IF(J28="LD",H28,NA()) -> #N/A | P28: =IF(J28="LD",I28,NA()) -> #N/A | Q28: =IF(J28="SNP",H28,NA()) -> #N/A | R28: =IF(J28="SNP",I28,NA()) -> #N/A | S28: =IF(J28="Oth",H28,NA()) -> #N/A | T28: =IF(J28="oth",I28,NA()) -> #N/A | AN28: =AN23+1 -> 6 | AO28: =AO23 -> Labour | AP28: =HLOOKUP(AO28,$AH$2:$AL$13,AN28+1,) -> 38 | AQ28: =AQ27+AP27 -> 229 | AR28: =AR23 -> L | AU28: y | AV28: =0.75*SIN(90/180) -> 0.35956915
A29: =A28+1 -> 27 | B29: =VLOOKUP(A29,$Y$2:$Z$13,2,1) -> 1 | C29: =VLOOKUP(B29,$V$2:$AB$14,7,0) -> 1 | D29: =VLOOKUP(B29,$V$2:$AC$13,8,0) -> 5 | E29: =IF(OR(A29=$Y$3,A29=$Y$4,A29=$Y$5,A29=$Y$6,A29=$Y$7,A29=$Y$8,A29=$Y$9,A29=$Y$10,A29=$Y$11,A29=$Y$12,A29=$Y$12),0,1) -> 1 | F29: =IF(E29=0,0,D29+F28) -> 130 | G29: =(F29/180)*PI() -> 2.268928 | H29: =C29*COS(G29) -> -0.64278761 | I29: =C29*SIN(G29) -> 0.76604444 | J29: =VLOOKUP(A29,$AQ$3:$AR$58,2,1) -> LD | K29: =IF(J29="L",H29,NA()) -> #N/A | L29: =IF(J29="l",I29,NA()) -> #N/A | M29: =IF(J29="C",H29,NA()) -> #N/A | N29: =IF(J29="C",I29,NA()) -> #N/A | O29: =IF(J29="LD",H29,NA()) -> -0.64278761 | P29: =IF(J29="LD",I29,NA()) -> 0.76604444 | Q29: =IF(J29="SNP",H29,NA()) -> #N/A | R29: =IF(J29="SNP",I29,NA()) -> #N/A | S29: =IF(J29="Oth",H29,NA()) -> #N/A | T29: =IF(J29="oth",I29,NA()) -> #N/A | AN29: =AN24+1 -> 6 | AO29: =AO24 -> Conservatives | AP29: =HLOOKUP(AO29,$AH$2:$AL$13,AN29+1,) -> 11 | AQ29: =AQ28+AP28 -> 267 | AR29: =AR24 -> C
A30: =A29+1 -> 28 | B30: =VLOOKUP(A30,$Y$2:$Z$13,2,1) -> 1 | C30: =VLOOKUP(B30,$V$2:$AB$14,7,0) -> 1 | D30: =VLOOKUP(B30,$V$2:$AC$13,8,0) -> 5 | E30: =IF(OR(A30=$Y$3,A30=$Y$4,A30=$Y$5,A30=$Y$6,A30=$Y$7,A30=$Y$8,A30=$Y$9,A30=$Y$10,A30=$Y$11,A30=$Y$12,A30=$Y$12),0,1) -> 1 | F30: =IF(E30=0,0,D30+F29) -> 135 | G30: =(F30/180)*PI() -> 2.3561945 | H30: =C30*COS(G30) -> -0.70710678 | I30: =C30*SIN(G30) -> 0.70710678 | J30: =VLOOKUP(A30,$AQ$3:$AR$58,2,1) -> LD | K30: =IF(J30="L",H30,NA()) -> #N/A | L30: =IF(J30="l",I30,NA()) -> #N/A | M30: =IF(J30="C",H30,NA()) -> #N/A | N30: =IF(J30="C",I30,NA()) -> #N/A | O30: =IF(J30="LD",H30,NA()) -> -0.70710678 | P30: =IF(J30="LD",I30,NA()) -> 0.70710678 | Q30: =IF(J30="SNP",H30,NA()) -> #N/A | R30: =IF(J30="SNP",I30,NA()) -> #N/A | S30: =IF(J30="Oth",H30,NA()) -> #N/A | T30: =IF(J30="oth",I30,NA()) -> #N/A | AN30: =AN25+1 -> 6 | AO30: =AO25 -> Lib Dem | AP30: =HLOOKUP(AO30,$AH$2:$AL$13,AN30+1,) -> 7 | AQ30: =AQ29+AP29 -> 278 | AR30: =AR25 -> LD
A31: =A30+1 -> 29 | B31: =VLOOKUP(A31,$Y$2:$Z$13,2,1) -> 1 | C31: =VLOOKUP(B31,$V$2:$AB$14,7,0) -> 1 | D31: =VLOOKUP(B31,$V$2:$AC$13,8,0) -> 5 | E31: =IF(OR(A31=$Y$3,A31=$Y$4,A31=$Y$5,A31=$Y$6,A31=$Y$7,A31=$Y$8,A31=$Y$9,A31=$Y$10,A31=$Y$11,A31=$Y$12,A31=$Y$12),0,1) -> 1 | F31: =IF(E31=0,0,D31+F30) -> 140 | G31: =(F31/180)*PI() -> 2.443461 | H31: =C31*COS(G31) -> -0.76604444 | I31: =C31*SIN(G31) -> 0.64278761 | J31: =VLOOKUP(A31,$AQ$3:$AR$58,2,1) -> LD | K31: =IF(J31="L",H31,NA()) -> #N/A | L31: =IF(J31="l",I31,NA()) -> #N/A | M31: =IF(J31="C",H31,NA()) -> #N/A | N31: =IF(J31="C",I31,NA()) -> #N/A | O31: =IF(J31="LD",H31,NA()) -> -0.76604444 | P31: =IF(J31="LD",I31,NA()) -> 0.64278761 | Q31: =IF(J31="SNP",H31,NA()) -> #N/A | R31: =IF(J31="SNP",I31,NA()) -> #N/A | S31: =IF(J31="Oth",H31,NA()) -> #N/A | T31: =IF(J31="oth",I31,NA()) -> #N/A | AN31: =AN26+1 -> 6 | AO31: =AO26 -> SNP | AP31: =HLOOKUP(AO31,$AH$2:$AL$13,AN31+1,) -> 1 | AQ31: =AQ30+AP30 -> 285 | AR31: =AR26 -> SNP
A32: =A31+1 -> 30 | B32: =VLOOKUP(A32,$Y$2:$Z$13,2,1) -> 1 | C32: =VLOOKUP(B32,$V$2:$AB$14,7,0) -> 1 | D32: =VLOOKUP(B32,$V$2:$AC$13,8,0) -> 5 | E32: =IF(OR(A32=$Y$3,A32=$Y$4,A32=$Y$5,A32=$Y$6,A32=$Y$7,A32=$Y$8,A32=$Y$9,A32=$Y$10,A32=$Y$11,A32=$Y$12,A32=$Y$12),0,1) -> 1 | F32: =IF(E32=0,0,D32+F31) -> 145 | G32: =(F32/180)*PI() -> 2.5307274 | H32: =C32*COS(G32) -> -0.81915204 | I32: =C32*SIN(G32) -> 0.57357644 | J32: =VLOOKUP(A32,$AQ$3:$AR$58,2,1) -> LD | K32: =IF(J32="L",H32,NA()) -> #N/A | L32: =IF(J32="l",I32,NA()) -> #N/A | M32: =IF(J32="C",H32,NA()) -> #N/A | N32: =IF(J32="C",I32,NA()) -> #N/A | O32: =IF(J32="LD",H32,NA()) -> -0.81915204 | P32: =IF(J32="LD",I32,NA()) -> 0.57357644 | Q32: =IF(J32="SNP",H32,NA()) -> #N/A | R32: =IF(J32="SNP",I32,NA()) -> #N/A | S32: =IF(J32="Oth",H32,NA()) -> #N/A | T32: =IF(J32="oth",I32,NA()) -> #N/A | AN32: =AN27+1 -> 6 | AO32: =AO27 -> Other | AP32: =HLOOKUP(AO32,$AH$2:$AL$13,AN32+1,) -> 3 | AQ32: =AQ31+AP31 -> 286 | AR32: =AR27 -> Oth
A33: =A32+1 -> 31 | B33: =VLOOKUP(A33,$Y$2:$Z$13,2,1) -> 1 | C33: =VLOOKUP(B33,$V$2:$AB$14,7,0) -> 1 | D33: =VLOOKUP(B33,$V$2:$AC$13,8,0) -> 5 | E33: =IF(OR(A33=$Y$3,A33=$Y$4,A33=$Y$5,A33=$Y$6,A33=$Y$7,A33=$Y$8,A33=$Y$9,A33=$Y$10,A33=$Y$11,A33=$Y$12,A33=$Y$12),0,1) -> 1 | F33: =IF(E33=0,0,D33+F32) -> 150 | G33: =(F33/180)*PI() -> 2.6179939 | H33: =C33*COS(G33) -> -0.8660254 | I33: =C33*SIN(G33) -> 0.5 | J33: =VLOOKUP(A33,$AQ$3:$AR$58,2,1) -> LD | K33: =IF(J33="L",H33,NA()) -> #N/A | L33: =IF(J33="l",I33,NA()) -> #N/A | M33: =IF(J33="C",H33,NA()) -> #N/A | N33: =IF(J33="C",I33,NA()) -> #N/A | O33: =IF(J33="LD",H33,NA()) -> -0.8660254 | P33: =IF(J33="LD",I33,NA()) -> 0.5 | Q33: =IF(J33="SNP",H33,NA()) -> #N/A | R33: =IF(J33="SNP",I33,NA()) -> #N/A | S33: =IF(J33="Oth",H33,NA()) -> #N/A | T33: =IF(J33="oth",I33,NA()) -> #N/A | AN33: =AN28+1 -> 7 | AO33: =AO28 -> Labour | AP33: =HLOOKUP(AO33,$AH$2:$AL$13,AN33+1,) -> 42 | AQ33: =AQ32+AP32 -> 289 | AR33: =AR28 -> L
A34: =A33+1 -> 32 | B34: =VLOOKUP(A34,$Y$2:$Z$13,2,1) -> 1 | C34: =VLOOKUP(B34,$V$2:$AB$14,7,0) -> 1 | D34: =VLOOKUP(B34,$V$2:$AC$13,8,0) -> 5 | E34: =IF(OR(A34=$Y$3,A34=$Y$4,A34=$Y$5,A34=$Y$6,A34=$Y$7,A34=$Y$8,A34=$Y$9,A34=$Y$10,A34=$Y$11,A34=$Y$12,A34=$Y$12),0,1) -> 1 | F34: =IF(E34=0,0,D34+F33) -> 155 | G34: =(F34/180)*PI() -> 2.7052603 | H34: =C34*COS(G34) -> -0.90630779 | I34: =C34*SIN(G34) -> 0.42261826 | J34: =VLOOKUP(A34,$AQ$3:$AR$58,2,1) -> LD | K34: =IF(J34="L",H34,NA()) -> #N/A | L34: =IF(J34="l",I34,NA()) -> #N/A | M34: =IF(J34="C",H34,NA()) -> #N/A | N34: =IF(J34="C",I34,NA()) -> #N/A | O34: =IF(J34="LD",H34,NA()) -> -0.90630779 | P34: =IF(J34="LD",I34,NA()) -> 0.42261826 | Q34: =IF(J34="SNP",H34,NA()) -> #N/A | R34: =IF(J34="SNP",I34,NA()) -> #N/A | S34: =IF(J34="Oth",H34,NA()) -> #N/A | T34: =IF(J34="oth",I34,NA()) -> #N/A | AN34: =AN29+1 -> 7 | AO34: =AO29 -> Conservatives | AP34: =HLOOKUP(AO34,$AH$2:$AL$13,AN34+1,) -> 12 | AQ34: =AQ33+AP33 -> 331 | AR34: =AR29 -> C
A35: =A34+1 -> 33 | B35: =VLOOKUP(A35,$Y$2:$Z$13,2,1) -> 1 | C35: =VLOOKUP(B35,$V$2:$AB$14,7,0) -> 1 | D35: =VLOOKUP(B35,$V$2:$AC$13,8,0) -> 5 | E35: =IF(OR(A35=$Y$3,A35=$Y$4,A35=$Y$5,A35=$Y$6,A35=$Y$7,A35=$Y$8,A35=$Y$9,A35=$Y$10,A35=$Y$11,A35=$Y$12,A35=$Y$12),0,1) -> 1 | F35: =IF(E35=0,0,D35+F34) -> 160 | G35: =(F35/180)*PI() -> 2.7925268 | H35: =C35*COS(G35) -> -0.93969262 | I35: =C35*SIN(G35) -> 0.34202014 | J35: =VLOOKUP(A35,$AQ$3:$AR$58,2,1) -> SNP | K35: =IF(J35="L",H35,NA()) -> #N/A | L35: =IF(J35="l",I35,NA()) -> #N/A | M35: =IF(J35="C",H35,NA()) -> #N/A | N35: =IF(J35="C",I35,NA()) -> #N/A | O35: =IF(J35="LD",H35,NA()) -> #N/A | P35: =IF(J35="LD",I35,NA()) -> #N/A | Q35: =IF(J35="SNP",H35,NA()) -> -0.93969262 | R35: =IF(J35="SNP",I35,NA()) -> 0.34202014 | S35: =IF(J35="Oth",H35,NA()) -> #N/A | T35: =IF(J35="oth",I35,NA()) -> #N/A | AN35: =AN30+1 -> 7 | AO35: =AO30 -> Lib Dem | AP35: =HLOOKUP(AO35,$AH$2:$AL$13,AN35+1,) -> 7 | AQ35: =AQ34+AP34 -> 343 | AR35: =AR30 -> LD
A36: =A35+1 -> 34 | B36: =VLOOKUP(A36,$Y$2:$Z$13,2,1) -> 1 | C36: =VLOOKUP(B36,$V$2:$AB$14,7,0) -> 1 | D36: =VLOOKUP(B36,$V$2:$AC$13,8,0) -> 5 | E36: =IF(OR(A36=$Y$3,A36=$Y$4,A36=$Y$5,A36=$Y$6,A36=$Y$7,A36=$Y$8,A36=$Y$9,A36=$Y$10,A36=$Y$11,A36=$Y$12,A36=$Y$12),0,1) -> 1 | F36: =IF(E36=0,0,D36+F35) -> 165 | G36: =(F36/180)*PI() -> 2.8797933 | H36: =C36*COS(G36) -> -0.96592583 | I36: =C36*SIN(G36) -> 0.25881905 | J36: =VLOOKUP(A36,$AQ$3:$AR$58,2,1) -> SNP | K36: =IF(J36="L",H36,NA()) -> #N/A | L36: =IF(J36="l",I36,NA()) -> #N/A | M36: =IF(J36="C",H36,NA()) -> #N/A | N36: =IF(J36="C",I36,NA()) -> #N/A | O36: =IF(J36="LD",H36,NA()) -> #N/A | P36: =IF(J36="LD",I36,NA()) -> #N/A | Q36: =IF(J36="SNP",H36,NA()) -> -0.96592583 | R36: =IF(J36="SNP",I36,NA()) -> 0.25881905 | S36: =IF(J36="Oth",H36,NA()) -> #N/A | T36: =IF(J36="oth",I36,NA()) -> #N/A | AN36: =AN31+1 -> 7 | AO36: =AO31 -> SNP | AP36: =HLOOKUP(AO36,$AH$2:$AL$13,AN36+1,) -> 1 | AQ36: =AQ35+AP35 -> 350 | AR36: =AR31 -> SNP
A37: =A36+1 -> 35 | B37: =VLOOKUP(A37,$Y$2:$Z$13,2,1) -> 1 | C37: =VLOOKUP(B37,$V$2:$AB$14,7,0) -> 1 | D37: =VLOOKUP(B37,$V$2:$AC$13,8,0) -> 5 | E37: =IF(OR(A37=$Y$3,A37=$Y$4,A37=$Y$5,A37=$Y$6,A37=$Y$7,A37=$Y$8,A37=$Y$9,A37=$Y$10,A37=$Y$11,A37=$Y$12,A37=$Y$12),0,1) -> 1 | F37: =IF(E37=0,0,D37+F36) -> 170 | G37: =(F37/180)*PI() -> 2.9670597 | H37: =C37*COS(G37) -> -0.98480775 | I37: =C37*SIN(G37) -> 0.17364818 | J37: =VLOOKUP(A37,$AQ$3:$AR$58,2,1) -> Oth | K37: =IF(J37="L",H37,NA()) -> #N/A | L37: =IF(J37="l",I37,NA()) -> #N/A | M37: =IF(J37="C",H37,NA()) -> #N/A | N37: =IF(J37="C",I37,NA()) -> #N/A | O37: =IF(J37="LD",H37,NA()) -> #N/A | P37: =IF(J37="LD",I37,NA()) -> #N/A | Q37: =IF(J37="SNP",H37,NA()) -> #N/A | R37: =IF(J37="SNP",I37,NA()) -> #N/A | S37: =IF(J37="Oth",H37,NA()) -> -0.98480775 | T37: =IF(J37="oth",I37,NA()) -> 0.17364818 | AN37: =AN32+1 -> 7 | AO37: =AO32 -> Other | AP37: =HLOOKUP(AO37,$AH$2:$AL$13,AN37+1,) -> 3 | AQ37: =AQ36+AP36 -> 351 | AR37: =AR32 -> Oth
A38: =A37+1 -> 36 | B38: =VLOOKUP(A38,$Y$2:$Z$13,2,1) -> 1 | C38: =VLOOKUP(B38,$V$2:$AB$14,7,0) -> 1 | D38: =VLOOKUP(B38,$V$2:$AC$13,8,0) -> 5 | E38: =IF(OR(A38=$Y$3,A38=$Y$4,A38=$Y$5,A38=$Y$6,A38=$Y$7,A38=$Y$8,A38=$Y$9,A38=$Y$10,A38=$Y$11,A38=$Y$12,A38=$Y$12),0,1) -> 1 | F38: =IF(E38=0,0,D38+F37) -> 175 | G38: =(F38/180)*PI() -> 3.0543262 | H38: =C38*COS(G38) -> -0.9961947 | I38: =C38*SIN(G38) -> 0.087155743 | J38: =VLOOKUP(A38,$AQ$3:$AR$58,2,1) -> Oth | K38: =IF(J38="L",H38,NA()) -> #N/A | L38: =IF(J38="l",I38,NA()) -> #N/A | M38: =IF(J38="C",H38,NA()) -> #N/A | N38: =IF(J38="C",I38,NA()) -> #N/A | O38: =IF(J38="LD",H38,NA()) -> #N/A | P38: =IF(J38="LD",I38,NA()) -> #N/A | Q38: =IF(J38="SNP",H38,NA()) -> #N/A | R38: =IF(J38="SNP",I38,NA()) -> #N/A | S38: =IF(J38="Oth",H38,NA()) -> -0.9961947 | T38: =IF(J38="oth",I38,NA()) -> 0.087155743 | AN38: =AN33+1 -> 8 | AO38: =AO33 -> Labour | AP38: =HLOOKUP(AO38,$AH$2:$AL$13,AN38+1,) -> 46 | AQ38: =AQ37+AP37 -> 354 | AR38: =AR33 -> L
A39: =A38+1 -> 37 | B39: =VLOOKUP(A39,$Y$2:$Z$13,2,1) -> 1 | C39: =VLOOKUP(B39,$V$2:$AB$14,7,0) -> 1 | D39: =VLOOKUP(B39,$V$2:$AC$13,8,0) -> 5 | E39: =IF(OR(A39=$Y$3,A39=$Y$4,A39=$Y$5,A39=$Y$6,A39=$Y$7,A39=$Y$8,A39=$Y$9,A39=$Y$10,A39=$Y$11,A39=$Y$12,A39=$Y$12),0,1) -> 1 | F39: =IF(E39=0,0,D39+F38) -> 180 | G39: =(F39/180)*PI() -> 3.1415927 | H39: =C39*COS(G39) -> -1 | I39: =C39*SIN(G39) -> 1.2251485e-16 | J39: =VLOOKUP(A39,$AQ$3:$AR$58,2,1) -> Oth | K39: =IF(J39="L",H39,NA()) -> #N/A | L39: =IF(J39="l",I39,NA()) -> #N/A | M39: =IF(J39="C",H39,NA()) -> #N/A | N39: =IF(J39="C",I39,NA()) -> #N/A | O39: =IF(J39="LD",H39,NA()) -> #N/A | P39: =IF(J39="LD",I39,NA()) -> #N/A | Q39: =IF(J39="SNP",H39,NA()) -> #N/A | R39: =IF(J39="SNP",I39,NA()) -> #N/A | S39: =IF(J39="Oth",H39,NA()) -> -1 | T39: =IF(J39="oth",I39,NA()) -> 1.2251485e-16 | AN39: =AN34+1 -> 8 | AO39: =AO34 -> Conservatives | AP39: =HLOOKUP(AO39,$AH$2:$AL$13,AN39+1,) -> 13 | AQ39: =AQ38+AP38 -> 400 | AR39: =AR34 -> C
A40: =A39+1 -> 38 | B40: =VLOOKUP(A40,$Y$2:$Z$13,2,1) -> 2 | C40: =VLOOKUP(B40,$V$2:$AB$14,7,0) -> 1.1 | D40: =VLOOKUP(B40,$V$2:$AC$13,8,0) -> 4.5 | E40: =IF(OR(A40=$Y$3,A40=$Y$4,A40=$Y$5,A40=$Y$6,A40=$Y$7,A40=$Y$8,A40=$Y$9,A40=$Y$10,A40=$Y$11,A40=$Y$12,A40=$Y$12),0,1) -> 0 | F40: =IF(E40=0,0,D40+F39) -> 0 | G40: =(F40/180)*PI() -> 0 | H40: =C40*COS(G40) -> 1.1 | I40: =C40*SIN(G40) -> 0 | J40: =VLOOKUP(A40,$AQ$3:$AR$58,2,1) -> L | K40: =IF(J40="L",H40,NA()) -> 1.1 | L40: =IF(J40="l",I40,NA()) -> 0 | M40: =IF(J40="C",H40,NA()) -> #N/A | N40: =IF(J40="C",I40,NA()) -> #N/A | O40: =IF(J40="LD",H40,NA()) -> #N/A | P40: =IF(J40="LD",I40,NA()) -> #N/A | Q40: =IF(J40="SNP",H40,NA()) -> #N/A | R40: =IF(J40="SNP",I40,NA()) -> #N/A | S40: =IF(J40="Oth",H40,NA()) -> #N/A | T40: =IF(J40="oth",I40,NA()) -> #N/A | AN40: =AN35+1 -> 8 | AO40: =AO35 -> Lib Dem | AP40: =HLOOKUP(AO40,$AH$2:$AL$13,AN40+1,) -> 6 | AQ40: =AQ39+AP39 -> 413 | AR40: =AR35 -> LD
...

Sheet DMP Chart Data
A1: DMP - prices & wages
B2: Prices - past year | C2: Prices - next year | D2: Wages - past year | E2: Wages - next year
A3: 42736 | B3: =AVERAGE(HAVER!C90:C92) -> #N/A | C3: =AVERAGE(HAVER!D90:D92) -> #N/A
A4: 42767 | B4: =AVERAGE(HAVER!C91:C93) -> #N/A | C4: =AVERAGE(HAVER!D91:D93) -> #N/A
A5: 42795 | B5: =AVERAGE(HAVER!C92:C94) -> 2.792 | C5: =AVERAGE(HAVER!D92:D94) -> 2.8653333
A6: 42826 | B6: =AVERAGE(HAVER!C93:C95) -> 2.7696667 | C6: =AVERAGE(HAVER!D93:D95) -> 2.801
A7: 42856 | B7: =AVERAGE(HAVER!C94:C96) -> 2.6693333 | C7: =AVERAGE(HAVER!D94:D96) -> 2.7436667
A8: 42887 | B8: =AVERAGE(HAVER!C95:C97) -> 2.6 | C8: =AVERAGE(HAVER!D95:D97) -> 2.6796667
A9: 42917 | B9: =AVERAGE(HAVER!C96:C98) -> 2.4496667 | C9: =AVERAGE(HAVER!D96:D98) -> 2.573
A10: 42948 | B10: =AVERAGE(HAVER!C97:C99) -> 2.4543333 | C10: =AVERAGE(HAVER!D97:D99) -> 2.5016667
A11: 42979 | B11: =AVERAGE(HAVER!C98:C100) -> 2.561 | C11: =AVERAGE(HAVER!D98:D100) -> 2.4886667
A12: 43009 | B12: =AVERAGE(HAVER!C99:C101) -> 2.4786667 | C12: =AVERAGE(HAVER!D99:D101) -> 2.4983333
A13: 43040 | B13: =AVERAGE(HAVER!C100:C102) -> 2.4653333 | C13: =AVERAGE(HAVER!D100:D102) -> 2.5016667
A14: 43070 | B14: =AVERAGE(HAVER!C101:C103) -> 2.4813333 | C14: =AVERAGE(HAVER!D101:D103) -> 2.475
... A68: 44713 | B68: =AVERAGE(HAVER!C155:C157) -> 6.0576667 | C68: =AVERAGE(HAVER!D155:D157) -> 5.854
A69: 44743 | B69: =AVERAGE(HAVER!C156:C158) -> 6.281 | C69: =AVERAGE(HAVER!D156:D158) -> 6.0853333 | D69: =AVERAGE(HAVER!E156:E158) -> 5.5666667 | E69: =AVERAGE(HAVER!F156:F158) -> 5.0333333
A70: 44774 | B70: =AVERAGE(HAVER!C157:C159) -> 6.4646667 | C70: =AVERAGE(HAVER!D157:D159) -> 6.268 | D70: =AVERAGE(HAVER!E157:E159) -> 5.8666667 | E70: =AVERAGE(HAVER!F157:F159) -> 5.2666667
A71: 44805 | B71: =AVERAGE(HAVER!C158:C160) -> 6.58 | C71: =AVERAGE(HAVER!D158:D160) -> 6.442 | D71: =AVERAGE(HAVER!E158:E160) -> 6.1333333 | E71: =AVERAGE(HAVER!F158:F160) -> 5.5333333
A72: 44835 | B72: =AVERAGE(HAVER!C159:C161) -> 6.431 | C72: =AVERAGE(HAVER!D159:D161) -> 6.492 | D72: =AVERAGE(HAVER!E159:E161) -> 6.3333333 | E72: =AVERAGE(HAVER!F159:F161) -> 5.7333333
A73: 44866 | B73: =AVERAGE(HAVER!C160:C162) -> 6.202 | C73: =AVERAGE(HAVER!D160:D162) -> 6.4043333 | D73: =AVERAGE(HAVER!E160:E162) -> 6.2333333 | E73: =AVERAGE(HAVER!F160:F162) -> 5.8333333
A74: 44896 | B74: =AVERAGE(HAVER!C161:C163) -> 5.917 | C74: =AVERAGE(HAVER!D161:D163) -> 6.1833333 | D74: =AVERAGE(HAVER!E161:E163) -> 6.2666667 | E74: =AVERAGE(HAVER!F161:F163) -> 5.9666667
A75: 44927 | B75: =AVERAGE(HAVER!C162:C164) -> 5.7766667 | C75: =AVERAGE(HAVER!D162:D164) -> 5.9653333 | D75: =AVERAGE(HAVER!E162:E164) -> 6.3333333 | E75: =AVERAGE(HAVER!F162:F164) -> 5.9333333
A76: 44958 | B76: =AVERAGE(HAVER!C163:C165) -> 5.657 | C76: =AVERAGE(HAVER!D163:D165) -> 5.7836667 | D76: =AVERAGE(HAVER!E163:E165) -> 6.5 | E76: =AVERAGE(HAVER!F163:F165) -> 5.9333333
A77: 44986 | B77: =AVERAGE(HAVER!C164:C166) -> 5.4996667 | C77: =AVERAGE(HAVER!D164:D166) -> 5.6443333 | D77: =AVERAGE(HAVER!E164:E166) -> 6.4666667 | E77: =AVERAGE(HAVER!F164:F166) -> 5.7
A78: 45017 | B78: =AVERAGE(HAVER!C165:C167) -> 5.5516667 | C78: =AVERAGE(HAVER!D165:D167) -> 5.5693333 | D78: =AVERAGE(HAVER!E165:E167) -> 6.5666667 | E78: =AVERAGE(HAVER!F165:F167) -> 5.6
A79: 45047 | B79: =AVERAGE(HAVER!C166:C168) -> 5.4696667 | C79: =AVERAGE(HAVER!D166:D168) -> 5.507 | D79: =AVERAGE(HAVER!E166:E168) -> 6.6333333 | E79: =AVERAGE(HAVER!F166:F168) -> 5.4
A80: 45078 | B80: =AVERAGE(HAVER!C167:C169) -> 5.3216667 | C80: =AVERAGE(HAVER!D167:D169) -> 5.448 | D80: =AVERAGE(HAVER!E167:E169) -> 6.8333333 | E80: =AVERAGE(HAVER!F167:F169) -> 5.3
... A92: 45444 | B92: =AVERAGE(HAVER!C179:C181) -> 3.871 | C92: =AVERAGE(HAVER!D179:D181) -> 3.9293333 | D92: =AVERAGE(HAVER!E179:E181) -> 5.9666667 | E92: =AVERAGE(HAVER!F179:F181) -> 4.2333333

Sheet HAVER
C1: Prices - past year | D1: Prices - next year | E1: Wages - past year | F1: Wages - next year
B2: 201001 !M | C2: UNVDPE1@UK | D2: UNVDPE3@UK | E2: UNVDWR@UK | F2: UNVDWE@UK
B3: .DESC | C3: UK: BoE DMP: Expected Price Growth Over the Next Year: Single Month (%) | D3: UK: BoE DMP: Expected Price Growth Over the Next Year: 3 Month Average (%) | E3: UK: BoE DMP: Realized Wage Growth Over the Past Year: Single Month (%) | F3: UK: BoE DMP: Expected Wage Growth Over the Next Year: Single Month (%)
B4: .T1 | C4: Jan-2017 | D4: Jan-2017 | E4: Aug-2017 | F4: Aug-2017
B5: .TN | C5: Jun-2024 | D5: Jun-2024 | E5: Jun-2024 | F5: Jun-2024
B6: .LSOURCE | C6: Bank of England | D6: Bank of England | E6: Bank of England | F6: Bank of England
B7: .DTLM | C7: Jul-04-2024 09:33 | D7: Jul-04-2024 09:33 | E7: Jul-04-2024 09:36 | F7: Jul-04-2024 09:36
A8: 40179 | B8: 201001 | C8: #N/A | D8: #N/A | E8: #N/A | F8: #N/A
A9: 40210 | B9: 201002 | C9: #N/A | D9: #N/A | E9: #N/A | F9: #N/A
A10: 40238 | B10: 201003 | C10: #N/A | D10: #N/A | E10: #N/A | F10: #N/A
A11: 40269 | B11: 201004 | C11: #N/A | D11: #N/A | E11: #N/A | F11: #N/A
A12: 40299 | B12: 201005 | C12: #N/A | D12: #N/A | E12: #N/A | F12: #N/A
A13: 40330 | B13: 201006 | C13: #N/A | D13: #N/A | E13: #N/A | F13: #N/A
A14: 40360 | B14: 201007 | C14: #N/A | D14: #N/A | E14: #N/A | F14: #N/A
A15: 40391 | B15: 201008 | C15: #N/A | D15: #N/A | E15: #N/A | F15: #N/A
A16: 40422 | B16: 201009 | C16: #N/A | D16: #N/A | E16: #N/A | F16: #N/A
A17: 40452 | B17: 201010 | C17: #N/A | D17: #N/A | E17: #N/A | F17: #N/A
A18: 40483 | B18: 201011 | C18: #N/A | D18: #N/A | E18: #N/A | F18: #N/A
A19: 40513 | B19: 201012 | C19: #N/A | D19: #N/A | E19: #N/A | F19: #N/A
... A91: 42705 | B91: 201612 | C91: #N/A | D91: #N/A | E91: #N/A | F91: #N/A
A92: 42736 | B92: 201701 | C92: 3.346 | D92: 2.963 | E92: #N/A | F92: #N/A
A93: 42767 | B93: 201702 | C93: 2.748 | D93: 2.841 | E93: #N/A | F93: #N/A
A94: 42795 | B94: 201703 | C94: 2.282 | D94: 2.792 | E94: #N/A | F94: #N/A
A95: 42826 | B95: 201704 | C95: 3.279 | D95: 2.77 | E95: #N/A | F95: #N/A
A96: 42856 | B96: 201705 | C96: 2.447 | D96: 2.669 | E96: #N/A | F96: #N/A
A97: 42887 | B97: 201706 | C97: 2.074 | D97: 2.6 | E97: #N/A | F97: #N/A
A98: 42917 | B98: 201707 | C98: 2.828 | D98: 2.45 | E98: #N/A | F98: #N/A
A99: 42948 | B99: 201708 | C99: 2.461 | D99: 2.455 | E99: 2.6 | F99: 2.4
A100: 42979 | B100: 201709 | C100: 2.394 | D100: 2.561 | E100: 2.5 | F100: 2.3
A101: 43009 | B101: 201710 | C101: 2.581 | D101: 2.479 | E101: 2.7 | F101: 2.6
A102: 43040 | B102: 201711 | C102: 2.421 | D102: 2.465
A103: 43070 | B103: 201712 | C103: 2.442 | D103: 2.481
A104: 43101 | B104: 201801 | C104: 2.463 | D104: 2.442
A105: 43132 | B105: 201802 | C105: 2.408 | D105: 2.438
A106: 43160 | B106: 201803 | C106: 2.135 | D106: 2.335
A107: 43191 | B107: 201804 | C107: 2.444 | D107: 2.329
A108: 43221 | B108: 201805 | C108: 1.977 | D108: 2.186
A109: 43252 | B109: 201806 | C109: 2.317 | D109: 2.246
A110: 43282 | B110: 201807 | C110: 2.424 | D110: 2.239
A111: 43313 | B111: 201808 | C111: 2.254 | D111: 2.332
...
