Workbook
Name _DLX1.INC: HAVERD!$A$1:$AL$6

Sheet Calculations
A1: Interest rates - gilts | E1: Interest rates - market expectations | J1: Interest rates - gilts | N1: Interest rates - short rates
B2: Budget Oct24* | C2: 19th December | F2: Budget Oct24 | G2: 19th December | J2: OBR gilt | K2: Markets gilt | L2: Impact | N2: OBR RCB | O2: Markets RCB | P2: Impact | R2: Total impact
A3: 2 | B3: {=TRANSPOSE(HAVERD!B537:G537)+0.25} -> 4.2390909 | C3: {=TRANSPOSE(HAVERD!B538:G538)} -> 4.46 | E3: 2024 | F3: {=TRANSPOSE(HAVERD!H537:M537)+0.25} -> 3.9658356 | G3: {=TRANSPOSE(HAVERD!H538:M538)} -> 4.1867781 | I3: FY2023/24 | J3: 4.273714 | K3: =J3 -> 4.273714 | L3: ='OBR RR Mar24 - Debt interest'!C10*(K3-J3) -> 0 | N3: 5.029625 | O3: =N3 -> 5.029625 | P3: ='OBR RR Mar24 - Debt interest'!C17*(O3-N3) -> 0
A4: 5 | B4: 4.0472727 | C4: 4.39 | E4: 2025 | F4: 3.6815352 | G4: 4.0234214 | I4: FY2024/25 | J4: 4.0656667 | K4: =J4+0.33 -> 4.3956667 | L4: ='OBR RR Mar24 - Debt interest'!D11*(K4-J4)+'OBR RR Mar24 - Debt interest'!D10*(K3-J3) -> 427.0567 | N4: 4.8745814 | O4: =N4+(G3-F3) -> 5.0955239 | P4: ='OBR RR Mar24 - Debt interest'!D18*(O4-N4)+'OBR RR Mar24 - Debt interest'!D17*(O3-N3) -> 2128.0397 | R4: =P4+L4 -> 2555.0964
A5: 10 | B5: 4.1690909 | C5: 4.61 | E5: 2026 | F5: 3.5758239 | G5: 3.8533846 | I5: FY2025/26 | J5: 4.147109 | K5: =J5+0.33 -> 4.477109 | L5: ='OBR RR Mar24 - Debt interest'!E12*(K5-J5)+'OBR RR Mar24 - Debt interest'!E11*(K4-J4)+'OBR RR Mar24 - Debt interest'!E10*(K3-J3) -> 1218.1135 | N5: 3.9095605 | O5: =N5+(G4-F4) -> 4.2514467 | P5: ='OBR RR Mar24 - Debt interest'!E19*(O5-N5)+'OBR RR Mar24 - Debt interest'!E18*(O4-N4) -> 3016.6719 | R5: =P5+L5 -> 4234.7854
A6: 15 | B6: 4.4490909 | C6: 4.89 | E6: 2027 | F6: 3.5328945 | G6: 3.777909 | I6: FY2026/27 | J6: 4.2265644 | K6: =J6+0.33 -> 4.5565644 | L6: ='OBR RR Mar24 - Debt interest'!F13*(K6-J6)+'OBR RR Mar24 - Debt interest'!F12*(K5-J5)+'OBR RR Mar24 - Debt interest'!F11*(K4-J4)+'OBR RR Mar24 - Debt interest'!F10*(K3-J3) -> 1906.2003 | N6: 3.6534969 | O6: =N6+(G5-F5) -> 3.9310576 | P6: ='OBR RR Mar24 - Debt interest'!F20*(O6-N6)+'OBR RR Mar24 - Debt interest'!F19*(O5-N5) -> 2288.609 | R6: =P6+L6 -> 4194.8093
A7: 20 | B7: 4.6427273 | C7: 5.09 | E7: 2028 | F7: 3.5469719 | G7: 3.7745549 | I7: FY2027/28 | J7: 4.3428788 | K7: =J7+0.33 -> 4.6728788 | L7: ='OBR RR Mar24 - Debt interest'!G14*(K7-J7)+'OBR RR Mar24 - Debt interest'!G13*(K6-J6)+'OBR RR Mar24 - Debt interest'!G12*(K5-J5)+'OBR RR Mar24 - Debt interest'!G11*(K4-J4)+'OBR RR Mar24 - Debt interest'!G10*(K3-J3) -> 2507.7654 | N7: 3.5561777 | O7: =N7+(G6-F6) -> 3.8011922 | P7: ='OBR RR Mar24 - Debt interest'!G21*(O7-N7)+'OBR RR Mar24 - Debt interest'!G20*(O6-N6) -> 1773.1502 | R7: =P7+L7 -> 4280.9156
A8: 30 | B8: 4.6954545 | C8: 5.13 | E8: 2029 | F8: 3.6111095 | G8: 3.82074 | I8: FY2028/29 | J8: 4.4869746 | K8: =J8+0.33 -> 4.8169746 | L8: ='OBR RR Mar24 - Debt interest'!H15*(K8-J8)+'OBR RR Mar24 - Debt interest'!H14*(K7-J7)+'OBR RR Mar24 - Debt interest'!H13*(K6-J6)+'OBR RR Mar24 - Debt interest'!H12*(K5-J5)+'OBR RR Mar24 - Debt interest'!H11*(K4-J4)+'OBR RR Mar24 - Debt interest'!H10*(K3-J3) -> 3164.9509 | N8: 3.5217886 | O8: =N8+(G7-F7) -> 3.7493716 | P8: ='OBR RR Mar24 - Debt interest'!H22*(O8-N8)+'OBR RR Mar24 - Debt interest'!H21*(O7-N7) -> 1474.4852 | R8: =P8+L8 -> 4639.436
I9: FY2029/30 | J9: 4.6177629 | K9: =J9+0.33 -> 4.9477629 | L9: ='OBR RR Mar24 - Debt interest'!I16*(K9-J9)+'OBR RR Mar24 - Debt interest'!I15*(K8-J8)+'OBR RR Mar24 - Debt interest'!I14*(K7-J7)+'OBR RR Mar24 - Debt interest'!I13*(K6-J6)+'OBR RR Mar24 - Debt interest'!I12*(K5-J5)+'OBR RR Mar24 - Debt interest'!I11*(K4-J4)+'OBR RR Mar24 - Debt interest'!I10*(K3-J3) -> 3950.0354 | N9: 3.5448441 | O9: =N9+(G8-F8) -> 3.7544746 | P9: ='OBR RR Mar24 - Debt interest'!I23*(O9-N9)+'OBR RR Mar24 - Debt interest'!I22*(O8-N8) -> 1220.0366 | R9: =P9+L9 -> 5170.072
A10: Av | B10: =AVERAGE(B3:B8) -> 4.3737879 | C10: =AVERAGE(C3:C8) -> 4.7616667 | F10: =AVERAGE(F3:F8) -> 3.6523618 | G10: =AVERAGE(G3:G8) -> 3.9061313
A11: Diff | C11: =C10-B10 -> 0.38787879 | G11: =G10-F10 -> 0.25376958

Sheet HAVERD
A1: 20230101 !D | B1: T112G2@INTDAILY | C1: T112G5@INTDAILY | D1: T112GA@INTDAILY | E1: T112GF@INTDAILY | F1: T112GK@INTDAILY | G1: T112GT@INTDAILY | H1: R11212F@INTDAILY | I1: R11224F@INTDAILY | J1: R11236F@INTDAILY | K1: R11248F@INTDAILY | L1: R11260F@INTDAILY | M1: R112I6A@INTDAILY
A2: .DESC | B2: UK: 2-Yr Government Bond Yield (%) | C2: UK: 5-Yr Government Bond Yield (%) | D2: UK: 10-Yr Government Bond Yield (%) | E2: UK: 15-Yr Government Bond Yield (%) | F2: UK: 20-Yr Government Bond Yield (%) | G2: UK: 30-Yr Government Bond Yield (%) | H2: UK: Overnight Index Swap: Forward Yields, 12-Month (% p.a.) | I2: UK: Overnight Index Swap: Forward Yields, 24-Month (% p.a.) | J2: UK: Overnight Index Swap: Forward Yields, 36-Month (% p.a.) | K2: UK: Overnight Index Swap: Forward Yields, 48-Month (% p.a.) | L2: UK: Overnight Index Swap: Forward Yields, 60-Month (% p.a.) | M2: UK: Overnight Index Swap: Forward Yields, 6-Year (% p.a.)
A3: .T1 | B3: 26-Jan-1994 | C3: 03-Jan-1995 | D3: 26-Jan-1994 | E3: 03-Jan-1995 | F3: 03-Jan-1995 | G3: 03-Jan-1995 | H3: 02-Jan-2009 | I3: 02-Jan-2009 | J3: 02-Jan-2009 | K3: 02-Jan-2009 | L3: 02-Jan-2009 | M3: 02-Jan-2018
A4: .TN | B4: 19-Dec-2024 | C4: 19-Dec-2024 | D4: 19-Dec-2024 | E4: 19-Dec-2024 | F4: 19-Dec-2024 | G4: 19-Dec-2024 | H4: 18-Dec-2024 | I4: 18-Dec-2024 | J4: 18-Dec-2024 | K4: 18-Dec-2024 | L4: 18-Dec-2024 | M4: 18-Dec-2024
A5: .LSOURCE | B5: London Stock Exchange Group | C5: London Stock Exchange Group | D5: London Stock Exchange Group | E5: London Stock Exchange Group | F5: London Stock Exchange Group | G5: London Stock Exchange Group | H5: Bank of England | I5: Bank of England | J5: Bank of England | K5: Bank of England | L5: Bank of England | M5: Bank of England
A6: .DTLM | B6: Dec-19-2024 20:54 | C6: Dec-19-2024 20:54 | D6: Dec-19-2024 20:54 | E6: Dec-19-2024 20:54 | F6: Dec-19-2024 20:54 | G6: Dec-19-2024 20:54 | H6: Dec-19-2024 10:01 | I6: Dec-19-2024 10:01 | J6: Dec-19-2024 10:01 | K6: Dec-19-2024 10:01 | L6: Dec-19-2024 10:01 | M6: Dec-19-2024 10:01
A7: 20230102 | B7: #N/A | C7: #N/A | D7: 3.67 | E7: 4 | F7: #N/A | G7: #N/A | H7: #N/A | I7: #N/A | J7: #N/A | K7: #N/A | L7: #N/A | M7: #N/A
A8: 20230103 | B8: 3.57 | C8: 3.61 | D8: 3.65 | E8: 3.98 | F8: 4.03 | G8: 3.95 | H8: 4.6062333 | I8: 4.0860817 | J8: 3.7383644 | K8: 3.5202418 | L8: 3.3603768 | M8: 3.2670637
A9: 20230104 | B9: 3.44 | C9: 3.49 | D9: 3.5 | E9: 3.86 | F9: 3.91 | G9: 3.83 | H9: 4.4897159 | I9: 3.8946255 | J9: 3.5485094 | K9: 3.3581345 | L9: 3.2157631 | M9: 3.1344241
A10: 20230105 | B10: 3.5 | C10: 3.54 | D10: 3.55 | E10: 3.92 | F10: 3.97 | G10: 3.9 | H10: 4.6093366 | I10: 4.0251201 | J10: 3.6258403 | K10: 3.4044061 | L10: 3.248598 | M10: 3.1579104
A11: 20230106 | B11: 3.41 | C11: 3.44 | D11: 3.47 | E11: 3.87 | F11: 3.92 | G11: 3.87 | H11: 4.5135822 | I11: 3.9067508 | J11: 3.5489763 | K11: 3.3517725 | L11: 3.2136096 | M11: 3.1364836
A12: 20230109 | B12: 3.44 | C12: 3.44 | D12: 3.53 | E12: 3.92 | F12: 3.99 | G12: 3.95 | H12: 4.4073146 | I12: 3.8168853 | J12: 3.4943471 | K12: 3.344989 | L12: 3.2567799 | M12: 3.2227345
A13: 20230110 | B13: 3.46 | C13: 3.46 | D13: 3.56 | E13: 3.9 | F13: 3.97 | G13: 3.9 | H13: 4.4532428 | I13: 3.8421403 | J13: 3.5138982 | K13: 3.3666806 | L13: 3.2777326 | M13: 3.2400696
A14: 20230111 | B14: 3.52 | C14: 3.33 | D14: 3.41 | E14: 3.75 | F14: 3.82 | G14: 3.75 | H14: 4.3232654 | I14: 3.6598018 | J14: 3.2991484 | K14: 3.1085172 | L14: 2.9904796 | M14: 2.9381602
A15: 20230112 | B15: 3.41 | C15: 3.22 | D15: 3.32 | E15: 3.67 | F15: 3.74 | G15: 3.68 | H15: 4.2304327 | I15: 3.5443186 | J15: 3.2434023 | K15: 3.1144553 | L15: 3.0281773 | M15: 2.9867674
A16: 20230113 | B16: 3.48 | C16: 3.3 | D16: 3.37 | E16: 3.71 | F16: 3.79 | G16: 3.73 | H16: 4.2881922 | I16: 3.5435797 | J16: 3.2706631 | K16: 3.1708117 | L16: 3.0875293 | M16: 3.0353738
A17: 20230116 | B17: 3.5 | C17: 3.32 | D17: 3.39 | E17: 3.73 | F17: 3.79 | G17: 3.73 | H17: 4.2747053 | I17: 3.542078 | J17: 3.2860175 | K17: 3.1890704 | L17: 3.1073268 | M17: 3.0597315
A18: 20230117 | B18: 3.46 | C18: 3.28 | D18: 3.33 | E18: 3.67 | F18: 3.73 | G18: 3.67 | H18: 4.2581275 | I18: 3.527278 | J18: 3.2329676 | K18: 3.1110108 | L18: 3.0186675 | M18: 2.9668799
A19: 20230118 | B19: 3.48 | C19: 3.26 | D19: 3.31 | E19: 3.65 | F19: 3.72 | G19: 3.67 | H19: 4.2900137 | I19: 3.5371655 | J19: 3.2330216 | K19: 3.0933058 | L19: 2.9859519 | M19: 2.9234031
... A75: 20230406 | B75: 3.33 | C75: 3.24 | D75: 3.41 | E75: 3.69 | F75: 3.74 | G75: 3.75 | H75: 4.158319 | I75: 3.5211395 | J75: 3.3365395 | K75: 3.1897341 | L75: 3.0491198 | M75: 2.95713
A76: 20230407 | B76: #N/A | C76: #N/A | D76: #N/A | E76: #N/A | F76: #N/A | G76: #N/A | H76: #N/A | I76: #N/A | J76: #N/A | K76: #N/A | L76: #N/A | M76: #N/A
A77: 20230410 | B77: 3.36 | C77: 3.26 | D77: #N/A | E77: 3.72 | F77: #N/A | G77: 3.77 | H77: #N/A | I77: #N/A | J77: #N/A | K77: #N/A | L77: #N/A | M77: #N/A
A78: 20230411 | B78: 3.48 | C78: 3.38 | D78: 3.54 | E78: 3.82 | F78: 3.86 | G78: 3.85 | H78: 4.3065134 | I78: 3.6673912 | J78: 3.4384934 | K78: 3.2872516 | L78: 3.1669498 | M78: 3.0930364
A79: 20230412 | B79: 3.52 | C79: 3.41 | D79: 3.57 | E79: 3.85 | F79: 3.9 | G79: 3.89 | H79: 4.3314896 | I79: 3.6943976 | J79: 3.4697311 | K79: 3.3318164 | L79: 3.2106008 | M79: 3.132033
A80: 20230413 | B80: 3.5 | C80: 3.39 | D80: 3.56 | E80: 3.85 | F80: 3.92 | G80: 3.93 | H80: 4.3058688 | I80: 3.6497702 | J80: 3.4739348 | K80: 3.3542761 | L80: 3.2218246 | M80: 3.133631
A81: 20230414 | B81: 3.6 | C81: 3.49 | D81: 3.65 | E81: 3.93 | F81: 4 | G81: 4.01 | H81: 4.3803025 | I81: 3.7827095 | J81: 3.551481 | K81: 3.3722345 | L81: 3.2280545 | M81: 3.1483612
A82: 20230417 | B82: 3.62 | C82: 3.51 | D82: 3.7 | E82: 3.97 | F82: 4.04 | G82: 4.05 | H82: 4.4128215 | I82: 3.7984261 | J82: 3.5516661 | K82: 3.3793774 | L82: 3.2660484 | M82: 3.2154803
A83: 20230418 | B83: 3.69 | C83: 3.58 | D83: 3.75 | E83: 4.02 | F83: 4.08 | G83: 4.1 | H83: 4.5153119 | I83: 3.8540431 | J83: 3.5681877 | K83: 3.4200533 | L83: 3.3183639 | M83: 3.2650511
A84: 20230419 | B84: 3.82 | C84: 3.71 | D84: 3.85 | E84: 4.12 | F84: 4.17 | G84: 4.18 | H84: 4.7060498 | I84: 4.0208502 | J84: 3.6986267 | K84: 3.5281427 | L84: 3.4031273 | M84: 3.3287484
A85: 20230420 | B85: 3.71 | C85: 3.61 | D85: 3.75 | E85: 4.02 | F85: 4.07 | G85: 4.09 | H85: 4.6234793 | I85: 3.901558 | J85: 3.6169639 | K85: 3.433208 | L85: 3.2895766 | M85: 3.2097178
A86: 20230421 | B86: 3.74 | C86: 3.61 | D86: 3.75 | E86: 4.02 | F86: 4.07 | G86: 4.09 | H86: 4.5902956 | I86: 3.9119531 | J86: 3.6309767 | K86: 3.4424543 | L86: 3.30302 | M86: 3.2276621
A87: 20230424 | B87: 3.81 | C87: 3.66 | D87: 3.78 | E87: 4.06 | F87: 4.11 | G87: 4.12 | H87: 4.6552073 | I87: 3.9766732 | J87: 3.6810599 | K87: 3.4826582 | L87: 3.3436555 | M87: 3.2782026
A88: 20230425 | B88: 3.73 | C88: 3.55 | D88: 3.69 | E88: 3.96 | F88: 4.01 | G88: 4.04 | H88: 4.5693727 | I88: 3.8898784 | J88: 3.5795324 | K88: 3.3871226 | L88: 3.2624867 | M88: 3.2031146
A89: 20230426 | B89: 3.77 | C89: 3.61 | D89: 3.74 | E89: 4.02 | F89: 4.08 | G89: 4.1 | H89: 4.5760281 | I89: 3.8704626 | J89: 3.5882628 | K89: 3.4396677 | L89: 3.3302424 | M89: 3.2688646
... A91: 20230428 | B91: 3.78 | C91: 3.61 | D91: 3.72 | E91: 4 | F91: 4.07 | G91: 4.09 | H91: 4.5760379 | I91: 3.9026073 | J91: 3.6412626 | K91: 3.4556032 | L91: 3.3150557 | M91: 3.2404901
A92: 20230501 | B92: 3.78 | C92: 3.61 | D92: #N/A | E92: 4 | F92: 4.07 | G92: 4.09 | H92: #N/A | I92: #N/A | J92: #N/A | K92: #N/A | L92: #N/A | M92: #N/A
A93: 20230502 | B93: 3.73 | C93: 3.54 | D93: 3.66 | E93: 3.94 | F93: 4.02 | G93: 4.05 | H93: 4.5135792 | I93: 3.859902 | J93: 3.5429317 | K93: 3.3629254 | L93: 3.2533834 | M93: 3.2035777
A94: 20230503 | B94: 3.76 | C94: 3.57 | D94: 3.69 | E94: 3.97 | F94: 4.05 | G94: 4.09 | H94: 4.5638913 | I94: 3.8852997 | J94: 3.5623419 | K94: 3.3931169 | L94: 3.282679 | M94: 3.2256626
A95: 20230504 | B95: 3.68 | C95: 3.48 | D95: 3.66 | E95: 3.93 | F95: 4.03 | G95: 4.08 | H95: 4.3394885 | I95: 3.7166109 | J95: 3.5325496 | K95: 3.399807 | L95: 3.297394 | M95: 3.2467831
A96: 20230505 | B96: 3.77 | C96: 3.58 | D96: 3.77 | E96: 4.04 | F96: 4.13 | G96: 4.17 | H96: 4.5183825 | I96: 3.8892196 | J96: 3.6410288 | K96: 3.4875021 | L96: 3.3792269 | M96: 3.3266601
...

Sheet OBR RR Mar24 - Debt interest
A1: Back to notes
A2: Effect of a 1 per cent increase (unless otherwise stated), £ million | B2: Year | C2: 2023-24 | D2: 2024-25 | E2: 2025-26 | F2: 2026-27 | G2: 2027-28 | H2: 2028-29 | I2: 2029-30
A3: RPI inflation | B3: 2023-24 | C3: 165.75062 | D3: 507.16566 | E3: 462.12229 | F3: 432.62358 | G3: 437.46389 | H3: 469.53112 | I3: =H3*H3/G3 -> 503.94896
B4: 2024-25 | C4: 0 | D4: 6359.6374 | E4: 479.01761 | F4: 448.53541 | G4: 462.63978 | H4: 496.48597 | I4: =H4*H3/G3 -> 532.87967
B5: 2025-26 | C5: 0 | D5: 0 | E5: 6776.7488 | F5: 446.77664 | G5: 461.98824 | H5: 499.44227 | I5: =H5*H4/G4 -> 535.98089
B6: 2026-27 | C6: 0 | D6: 0 | E6: 0 | F6: 6945.2949 | G6: 459.97012 | H6: 496.25533 | I6: =H6*H5/G5 -> 536.48744
B7: 2027-28 | C7: 0 | D7: 0 | E7: 0 | F7: 0 | G7: 7353.3938 | H7: 494.49507 | I7: =H7*H6/G6 -> 533.50381 | J7: =G7*G7/F6 -> 7785.4723
B8: 2028-29 | C8: 0 | D8: 0 | E8: 0 | F8: 0 | G8: 0 | H8: 7462.3303 | I8: =H8*H7/G7 -> 501.82074
B9: 2029-30 | C9: 0 | D9: 0 | E9: 0 | F9: 0 | G9: 0 | H9: 0 | I9: =H8*H8/G7 -> 7572.8806
A10: Gilt rates (long-term interest rates) | B10: 2023-24 | C10: 497.21742 | D10: 2185.167 | E10: 2185.167 | F10: 2185.167 | G10: 2185.167 | H10: 2185.167 | I10: =H10*H10/G10 -> 2185.167
B11: 2024-25 | C11: 0 | D11: 1294.1112 | E11: 2405.2559 | F11: 2405.2559 | G11: 2405.2559 | H11: 2405.2559 | I11: =H11*H10/G10 -> 2405.2559
B12: 2025-26 | C12: 0 | D12: 0 | E12: 1285.9971 | F12: 2377.0677 | G12: 2377.0677 | H12: 2377.0677 | I12: =H12*H11/G11 -> 2377.0677
B13: 2026-27 | C13: 0 | D13: 0 | E13: 0 | F13: 994.04099 | G13: 1876.2518 | H13: 1876.2518 | I13: =H13*H12/G12 -> 1876.2518
B14: 2027-28 | C14: 0 | D14: 0 | E14: 0 | F14: 0 | G14: 940.71373 | H14: 1808.3926 | I14: =H14*H13/G13 -> 1808.3926 | J14: =G14*G14/F13 -> 890.24731
B15: 2028-29 | C15: 0 | D15: 0 | E15: 0 | F15: 0 | G15: 0 | H15: 1123.7921 | I15: =H15*H14/G14 -> 2160.3356
B16: 2029-30 | C16: 0 | D16: 0 | E16: 0 | F16: 0 | G16: 0 | H16: 0 | I16: =H15*H15/G14 -> 1342.5005
A17: Short rates (Bank Rate) | B17: 2023-24 | C17: 9915.0201 | D17: 293.78104 | E17: 0 | F17: 0 | G17: 0 | H17: 0 | I17: 0
B18: 2024-25 | C18: 0 | D18: 9631.6442 | E18: 296.30733 | F18: 0 | G18: 0 | H18: 0 | I18: 0
B19: 2025-26 | C19: 0 | D19: 0 | E19: 8632.1274 | F19: 297.64961 | G19: 0 | H19: 0 | I19: 0
B20: 2026-27 | C20: 0 | D20: 0 | E20: 0 | F20: 7878.804 | G20: 297.98628 | H20: 0 | I20: 0
B21: 2027-28 | C21: 0 | D21: 0 | E21: 0 | F21: 0 | G21: 6899.3496 | H21: 298.00561 | I21: 0 | J21: =G21*G21/F20 -> 6041.6562
B22: 2028-29 | C22: 0 | D22: 0 | E22: 0 | F22: 0 | G22: 0 | H22: 6158.0577 | I22: =H21 -> 298.00561
B23: 2029-30 | C23: 0 | D23: 0 | E23: 0 | F23: 0 | G23: 0 | H23: 0 | I23: =H22*H22/G21 -> 5496.4129
A24: CGNCR (£1 billion change) | B24: 2023-24 | C24: 10.429541 | D24: 45.025105 | E24: 45.773715 | F24: 46.879919 | G24: 47.646399 | H24: 48.294611 | I24: =H24 -> 48.294611
B25: 2024-25 | C25: 0 | D25: 20.890821 | E25: 38.739428 | F25: 39.555129 | G25: 39.903279 | H25: 40.221324 | I25: =H25 -> 40.221324
B26: 2025-26 | C26: 0 | D26: 0 | E26: 18.234566 | F26: 38.987219 | G26: 39.271615 | H26: 39.327021 | I26: =H26 -> 39.327021
B27: 2026-27 | C27: 0 | D27: 0 | E27: 0 | F27: 16.865043 | G27: 40.911925 | H27: 40.965874 | I27: =H27 -> 40.965874
B28: 2027-28 | C28: 0 | D28: 0 | E28: 0 | F28: 0 | G28: 16.341186 | H28: 41.090974 | I28: =H28 -> 41.090974 | J28: =G28*G28/F27 -> 15.8336
B29: 2028-29 | C29: 0 | D29: 0 | E29: 0 | F29: 0 | G29: 0 | H29: 17.366496 | I29: =H28 -> 41.090974
B30: 2029-30 | C30: 0 | D30: 0 | E30: 0 | F30: 0 | G30: 0 | H30: 0 | I30: =H29 -> 17.366496
