Workbook

Sheet Calculations
G1: Only includes shops with both quotes
A2: Shop Code | B2: Region | C2: May | D2: June | E2: % change | H2: May | I2: June | K2: Rank | L2: Shop code | M2: Region | N2: % change | P2: small value to allow ranking | Q2: Values for ranking | T2: Shop code | U2: Region | V2: % change
A3: 161 | B3: =VLOOKUP($A3,June!$E:$O,11,FALSE) -> 4 | C3: =VLOOKUP($A3,May!$E:$F,2,FALSE) -> 129 | D3: =VLOOKUP($A3,June!$E:$F,2,FALSE) -> 159 | E3: =100*((D3/C3)-1) -> 23.255814 | G3: =_xlfn.IFNA(IF(AND(C3>0,D3>0),"Y","N"),"N") -> Y | H3: =_xlfn.IFNA(IF($G3="Y",C3,""),"") -> 129 | I3: =_xlfn.IFNA(IF($G3="Y",D3,""),"") -> 159 | K3: =_xlfn.IFNA(IF(G3="Y",RANK(Q3,$Q$3:$Q$127),""),"") -> 6 | L3: =_xlfn.IFNA(IF(G3="Y",A3,""),"") -> 161 | M3: =_xlfn.IFNA(IF(G3="Y",B3,""),"") -> 4 | N3: =_xlfn.IFNA(IF(G3="Y",100*((I3/H3)-1),""),"") -> 23.255814 | P3: 0.0001 | Q3: =_xlfn.IFNA(IF(G3="Y",N3+P3,""),"") -> 23.255914 | S3: 1 | T3: =VLOOKUP($S3,$K$3:$N$127,2,FALSE) -> 18982 | U3: =VLOOKUP($S3,$K$3:$N$127,3,FALSE) -> 11 | V3: =VLOOKUP($S3,$K$3:$N$127,4,FALSE) -> 176.40449 | W3: =IF(U3=9,"NW",IF(U3=11,"WA","")) -> WA
A4: 167 | B4: =VLOOKUP($A4,June!$E:$O,11,FALSE) -> 10 | C4: =VLOOKUP($A4,May!$E:$F,2,FALSE) -> 69 | D4: =VLOOKUP($A4,June!$E:$F,2,FALSE) -> 80 | E4: =100*((D4/C4)-1) -> 15.942029 | G4: =_xlfn.IFNA(IF(AND(C4>0,D4>0),"Y","N"),"N") -> Y | H4: =_xlfn.IFNA(IF($G4="Y",C4,""),"") -> 69 | I4: =_xlfn.IFNA(IF($G4="Y",D4,""),"") -> 80 | K4: =_xlfn.IFNA(IF(G4="Y",RANK(Q4,$Q$3:$Q$127),""),"") -> 10 | L4: =_xlfn.IFNA(IF(G4="Y",A4,""),"") -> 167 | M4: =_xlfn.IFNA(IF(G4="Y",B4,""),"") -> 10 | N4: =_xlfn.IFNA(IF(G4="Y",100*((I4/H4)-1),""),"") -> 15.942029 | P4: =P3+0.0001 -> 0.0002 | Q4: =_xlfn.IFNA(IF(G4="Y",N4+P4,""),"") -> 15.942229 | S4: 2 | T4: =VLOOKUP($S4,$K$3:$N$127,2,FALSE) -> 5106 | U4: =VLOOKUP($S4,$K$3:$N$127,3,FALSE) -> 9 | V4: =VLOOKUP($S4,$K$3:$N$127,4,FALSE) -> 145.36574 | W4: =IF(U4=9,"NW",IF(U4=11,"WA","")) -> NW
A5: 191 | B5: =VLOOKUP($A5,June!$E:$O,11,FALSE) -> 7 | C5: =VLOOKUP($A5,May!$E:$F,2,FALSE) -> 0 | D5: =VLOOKUP($A5,June!$E:$F,2,FALSE) -> 125 | E5: =100*((D5/C5)-1) -> #DIV/0! | G5: =_xlfn.IFNA(IF(AND(C5>0,D5>0),"Y","N"),"N") -> N | H5: =_xlfn.IFNA(IF($G5="Y",C5,""),"") | I5: =_xlfn.IFNA(IF($G5="Y",D5,""),"") | K5: =_xlfn.IFNA(IF(G5="Y",RANK(Q5,$Q$3:$Q$127),""),"") | L5: =_xlfn.IFNA(IF(G5="Y",A5,""),"") | M5: =_xlfn.IFNA(IF(G5="Y",B5,""),"") | N5: =_xlfn.IFNA(IF(G5="Y",100*((I5/H5)-1),""),"") | P5: =P4+0.0001 -> 0.0003 | Q5: =_xlfn.IFNA(IF(G5="Y",N5+P5,""),"") | S5: 3 | T5: =VLOOKUP($S5,$K$3:$N$127,2,FALSE) -> 14593 | U5: =VLOOKUP($S5,$K$3:$N$127,3,FALSE) -> 7 | V5: =VLOOKUP($S5,$K$3:$N$127,4,FALSE) -> 56.521739 | W5: =IF(U5=9,"NW",IF(U5=11,"WA",""))
A6: 210 | B6: =VLOOKUP($A6,June!$E:$O,11,FALSE) -> 8 | C6: =VLOOKUP($A6,May!$E:$F,2,FALSE) -> 0 | D6: =VLOOKUP($A6,June!$E:$F,2,FALSE) -> 154 | E6: =100*((D6/C6)-1) -> #DIV/0! | G6: =_xlfn.IFNA(IF(AND(C6>0,D6>0),"Y","N"),"N") -> N | H6: =_xlfn.IFNA(IF($G6="Y",C6,""),"") | I6: =_xlfn.IFNA(IF($G6="Y",D6,""),"") | K6: =_xlfn.IFNA(IF(G6="Y",RANK(Q6,$Q$3:$Q$127),""),"") | L6: =_xlfn.IFNA(IF(G6="Y",A6,""),"") | M6: =_xlfn.IFNA(IF(G6="Y",B6,""),"") | N6: =_xlfn.IFNA(IF(G6="Y",100*((I6/H6)-1),""),"") | P6: =P5+0.0001 -> 0.0004 | Q6: =_xlfn.IFNA(IF(G6="Y",N6+P6,""),"") | S6: 4 | T6: =VLOOKUP($S6,$K$3:$N$127,2,FALSE) -> 18027 | U6: =VLOOKUP($S6,$K$3:$N$127,3,FALSE) -> 2 | V6: =VLOOKUP($S6,$K$3:$N$127,4,FALSE) -> 36.537381 | W6: =IF(U6=9,"NW",IF(U6=11,"WA",""))
A7: 211 | B7: =VLOOKUP($A7,June!$E:$O,11,FALSE) -> 8 | C7: =VLOOKUP($A7,May!$E:$F,2,FALSE) -> 0 | D7: =VLOOKUP($A7,June!$E:$F,2,FALSE) -> 0 | E7: =100*((D7/C7)-1) -> #DIV/0! | G7: =_xlfn.IFNA(IF(AND(C7>0,D7>0),"Y","N"),"N") -> N | H7: =_xlfn.IFNA(IF($G7="Y",C7,""),"") | I7: =_xlfn.IFNA(IF($G7="Y",D7,""),"") | K7: =_xlfn.IFNA(IF(G7="Y",RANK(Q7,$Q$3:$Q$127),""),"") | L7: =_xlfn.IFNA(IF(G7="Y",A7,""),"") | M7: =_xlfn.IFNA(IF(G7="Y",B7,""),"") | N7: =_xlfn.IFNA(IF(G7="Y",100*((I7/H7)-1),""),"") | P7: =P6+0.0001 -> 0.0005 | Q7: =_xlfn.IFNA(IF(G7="Y",N7+P7,""),"") | S7: 5 | T7: =VLOOKUP($S7,$K$3:$N$127,2,FALSE) -> 5262 | U7: =VLOOKUP($S7,$K$3:$N$127,3,FALSE) -> 4 | V7: =VLOOKUP($S7,$K$3:$N$127,4,FALSE) -> 23.495146 | W7: =IF(U7=9,"NW",IF(U7=11,"WA",""))
A8: 221 | B8: =VLOOKUP($A8,June!$E:$O,11,FALSE) -> 7 | C8: =VLOOKUP($A8,May!$E:$F,2,FALSE) -> 0 | D8: =VLOOKUP($A8,June!$E:$F,2,FALSE) -> 147.5 | E8: =100*((D8/C8)-1) -> #DIV/0! | G8: =_xlfn.IFNA(IF(AND(C8>0,D8>0),"Y","N"),"N") -> N | H8: =_xlfn.IFNA(IF($G8="Y",C8,""),"") | I8: =_xlfn.IFNA(IF($G8="Y",D8,""),"") | K8: =_xlfn.IFNA(IF(G8="Y",RANK(Q8,$Q$3:$Q$127),""),"") | L8: =_xlfn.IFNA(IF(G8="Y",A8,""),"") | M8: =_xlfn.IFNA(IF(G8="Y",B8,""),"") | N8: =_xlfn.IFNA(IF(G8="Y",100*((I8/H8)-1),""),"") | P8: =P7+0.0001 -> 0.0006 | Q8: =_xlfn.IFNA(IF(G8="Y",N8+P8,""),"") | S8: 6 | T8: =VLOOKUP($S8,$K$3:$N$127,2,FALSE) -> 161 | U8: =VLOOKUP($S8,$K$3:$N$127,3,FALSE) -> 4 | V8: =VLOOKUP($S8,$K$3:$N$127,4,FALSE) -> 23.255814 | W8: =IF(U8=9,"NW",IF(U8=11,"WA",""))
A9: 255 | B9: =VLOOKUP($A9,June!$E:$O,11,FALSE) -> 6 | C9: =VLOOKUP($A9,May!$E:$F,2,FALSE) -> 109.99 | D9: =VLOOKUP($A9,June!$E:$F,2,FALSE) -> 129.99 | E9: =100*((D9/C9)-1) -> 18.183471 | G9: =_xlfn.IFNA(IF(AND(C9>0,D9>0),"Y","N"),"N") -> Y | H9: =_xlfn.IFNA(IF($G9="Y",C9,""),"") -> 109.99 | I9: =_xlfn.IFNA(IF($G9="Y",D9,""),"") -> 129.99 | K9: =_xlfn.IFNA(IF(G9="Y",RANK(Q9,$Q$3:$Q$127),""),"") -> 8 | L9: =_xlfn.IFNA(IF(G9="Y",A9,""),"") -> 255 | M9: =_xlfn.IFNA(IF(G9="Y",B9,""),"") -> 6 | N9: =_xlfn.IFNA(IF(G9="Y",100*((I9/H9)-1),""),"") -> 18.183471 | P9: =P8+0.0001 -> 0.0007 | Q9: =_xlfn.IFNA(IF(G9="Y",N9+P9,""),"") -> 18.184171 | S9: 7 | T9: =VLOOKUP($S9,$K$3:$N$127,2,FALSE) -> 18995 | U9: =VLOOKUP($S9,$K$3:$N$127,3,FALSE) -> 2 | V9: =VLOOKUP($S9,$K$3:$N$127,4,FALSE) -> 18.75 | W9: =IF(U9=9,"NW",IF(U9=11,"WA",""))
A10: 287 | B10: =VLOOKUP($A10,June!$E:$O,11,FALSE) -> 7 | C10: =VLOOKUP($A10,May!$E:$F,2,FALSE) -> 0 | D10: =VLOOKUP($A10,June!$E:$F,2,FALSE) -> 0 | E10: =100*((D10/C10)-1) -> #DIV/0! | G10: =_xlfn.IFNA(IF(AND(C10>0,D10>0),"Y","N"),"N") -> N | H10: =_xlfn.IFNA(IF($G10="Y",C10,""),"") | I10: =_xlfn.IFNA(IF($G10="Y",D10,""),"") | K10: =_xlfn.IFNA(IF(G10="Y",RANK(Q10,$Q$3:$Q$127),""),"") | L10: =_xlfn.IFNA(IF(G10="Y",A10,""),"") | M10: =_xlfn.IFNA(IF(G10="Y",B10,""),"") | N10: =_xlfn.IFNA(IF(G10="Y",100*((I10/H10)-1),""),"") | P10: =P9+0.0001 -> 0.0008 | Q10: =_xlfn.IFNA(IF(G10="Y",N10+P10,""),"") | S10: 8 | T10: =VLOOKUP($S10,$K$3:$N$127,2,FALSE) -> 255 | U10: =VLOOKUP($S10,$K$3:$N$127,3,FALSE) -> 6 | V10: =VLOOKUP($S10,$K$3:$N$127,4,FALSE) -> 18.183471 | W10: =IF(U10=9,"NW",IF(U10=11,"WA",""))
A11: 307 | B11: =VLOOKUP($A11,June!$E:$O,11,FALSE) -> 8 | C11: =VLOOKUP($A11,May!$E:$F,2,FALSE) -> 105 | D11: =VLOOKUP($A11,June!$E:$F,2,FALSE) -> 105 | E11: =100*((D11/C11)-1) -> 0 | G11: =_xlfn.IFNA(IF(AND(C11>0,D11>0),"Y","N"),"N") -> Y | H11: =_xlfn.IFNA(IF($G11="Y",C11,""),"") -> 105 | I11: =_xlfn.IFNA(IF($G11="Y",D11,""),"") -> 105 | K11: =_xlfn.IFNA(IF(G11="Y",RANK(Q11,$Q$3:$Q$127),""),"") -> 22 | L11: =_xlfn.IFNA(IF(G11="Y",A11,""),"") -> 307 | M11: =_xlfn.IFNA(IF(G11="Y",B11,""),"") -> 8 | N11: =_xlfn.IFNA(IF(G11="Y",100*((I11/H11)-1),""),"") -> 0 | P11: =P10+0.0001 -> 0.0009 | Q11: =_xlfn.IFNA(IF(G11="Y",N11+P11,""),"") -> 0.0009 | S11: 9 | T11: =VLOOKUP($S11,$K$3:$N$127,2,FALSE) -> 5226 | U11: =VLOOKUP($S11,$K$3:$N$127,3,FALSE) -> 2 | V11: =VLOOKUP($S11,$K$3:$N$127,4,FALSE) -> 17.324199 | W11: =IF(U11=9,"NW",IF(U11=11,"WA",""))
A12: 308 | B12: =VLOOKUP($A12,June!$E:$O,11,FALSE) -> 12 | C12: =VLOOKUP($A12,May!$E:$F,2,FALSE) -> 165 | D12: =VLOOKUP($A12,June!$E:$F,2,FALSE) -> 115 | E12: =100*((D12/C12)-1) -> -30.30303 | G12: =_xlfn.IFNA(IF(AND(C12>0,D12>0),"Y","N"),"N") -> Y | H12: =_xlfn.IFNA(IF($G12="Y",C12,""),"") -> 165 | I12: =_xlfn.IFNA(IF($G12="Y",D12,""),"") -> 115 | K12: =_xlfn.IFNA(IF(G12="Y",RANK(Q12,$Q$3:$Q$127),""),"") -> 31 | L12: =_xlfn.IFNA(IF(G12="Y",A12,""),"") -> 308 | M12: =_xlfn.IFNA(IF(G12="Y",B12,""),"") -> 12 | N12: =_xlfn.IFNA(IF(G12="Y",100*((I12/H12)-1),""),"") -> -30.30303 | P12: =P11+0.0001 -> 0.001 | Q12: =_xlfn.IFNA(IF(G12="Y",N12+P12,""),"") -> -30.30203 | S12: 10 | T12: =VLOOKUP($S12,$K$3:$N$127,2,FALSE) -> 167 | U12: =VLOOKUP($S12,$K$3:$N$127,3,FALSE) -> 10 | V12: =VLOOKUP($S12,$K$3:$N$127,4,FALSE) -> 15.942029 | W12: =IF(U12=9,"NW",IF(U12=11,"WA",""))
A13: 333 | B13: =VLOOKUP($A13,June!$E:$O,11,FALSE) -> 12 | C13: =VLOOKUP($A13,May!$E:$F,2,FALSE) -> #N/A | D13: =VLOOKUP($A13,June!$E:$F,2,FALSE) -> 150 | E13: =100*((D13/C13)-1) -> #N/A | G13: =_xlfn.IFNA(IF(AND(C13>0,D13>0),"Y","N"),"N") -> N | H13: =_xlfn.IFNA(IF($G13="Y",C13,""),"") | I13: =_xlfn.IFNA(IF($G13="Y",D13,""),"") | K13: =_xlfn.IFNA(IF(G13="Y",RANK(Q13,$Q$3:$Q$127),""),"") | L13: =_xlfn.IFNA(IF(G13="Y",A13,""),"") | M13: =_xlfn.IFNA(IF(G13="Y",B13,""),"") | N13: =_xlfn.IFNA(IF(G13="Y",100*((I13/H13)-1),""),"") | P13: =P12+0.0001 -> 0.0011 | Q13: =_xlfn.IFNA(IF(G13="Y",N13+P13,""),"") | S13: 11 | T13: =VLOOKUP($S13,$K$3:$N$127,2,FALSE) -> 15450 | U13: =VLOOKUP($S13,$K$3:$N$127,3,FALSE) -> 2 | V13: =VLOOKUP($S13,$K$3:$N$127,4,FALSE) -> 15.037594 | W13: =IF(U13=9,"NW",IF(U13=11,"WA",""))
A14: 335 | B14: =VLOOKUP($A14,June!$E:$O,11,FALSE) -> 12 | C14: =VLOOKUP($A14,May!$E:$F,2,FALSE) -> 0 | D14: =VLOOKUP($A14,June!$E:$F,2,FALSE) -> 0 | E14: =100*((D14/C14)-1) -> #DIV/0! | G14: =_xlfn.IFNA(IF(AND(C14>0,D14>0),"Y","N"),"N") -> N | H14: =_xlfn.IFNA(IF($G14="Y",C14,""),"") | I14: =_xlfn.IFNA(IF($G14="Y",D14,""),"") | K14: =_xlfn.IFNA(IF(G14="Y",RANK(Q14,$Q$3:$Q$127),""),"") | L14: =_xlfn.IFNA(IF(G14="Y",A14,""),"") | M14: =_xlfn.IFNA(IF(G14="Y",B14,""),"") | N14: =_xlfn.IFNA(IF(G14="Y",100*((I14/H14)-1),""),"") | P14: =P13+0.0001 -> 0.0012 | Q14: =_xlfn.IFNA(IF(G14="Y",N14+P14,""),"") | S14: 12 | T14: =VLOOKUP($S14,$K$3:$N$127,2,FALSE) -> 5247 | U14: =VLOOKUP($S14,$K$3:$N$127,3,FALSE) -> 2 | V14: =VLOOKUP($S14,$K$3:$N$127,4,FALSE) -> 3.0487805 | W14: =IF(U14=9,"NW",IF(U14=11,"WA",""))
A15: 340 | B15: =VLOOKUP($A15,June!$E:$O,11,FALSE) -> 12 | C15: =VLOOKUP($A15,May!$E:$F,2,FALSE) -> 70 | D15: =VLOOKUP($A15,June!$E:$F,2,FALSE) -> 70 | E15: =100*((D15/C15)-1) -> 0 | G15: =_xlfn.IFNA(IF(AND(C15>0,D15>0),"Y","N"),"N") -> Y | H15: =_xlfn.IFNA(IF($G15="Y",C15,""),"") -> 70 | I15: =_xlfn.IFNA(IF($G15="Y",D15,""),"") -> 70 | K15: =_xlfn.IFNA(IF(G15="Y",RANK(Q15,$Q$3:$Q$127),""),"") -> 21 | L15: =_xlfn.IFNA(IF(G15="Y",A15,""),"") -> 340 | M15: =_xlfn.IFNA(IF(G15="Y",B15,""),"") -> 12 | N15: =_xlfn.IFNA(IF(G15="Y",100*((I15/H15)-1),""),"") -> 0 | P15: =P14+0.0001 -> 0.0013 | Q15: =_xlfn.IFNA(IF(G15="Y",N15+P15,""),"") -> 0.0013 | S15: 13 | T15: =VLOOKUP($S15,$K$3:$N$127,2,FALSE) -> 16387 | U15: =VLOOKUP($S15,$K$3:$N$127,3,FALSE) -> 4 | V15: =VLOOKUP($S15,$K$3:$N$127,4,FALSE) -> 1 | W15: =IF(U15=9,"NW",IF(U15=11,"WA",""))
... A36: 5043 | B36: =VLOOKUP($A36,June!$E:$O,11,FALSE) -> 5 | C36: =VLOOKUP($A36,May!$E:$F,2,FALSE) -> 140 | D36: =VLOOKUP($A36,June!$E:$F,2,FALSE) -> 0 | E36: =100*((D36/C36)-1) -> -100 | G36: =_xlfn.IFNA(IF(AND(C36>0,D36>0),"Y","N"),"N") -> N | H36: =_xlfn.IFNA(IF($G36="Y",C36,""),"") | I36: =_xlfn.IFNA(IF($G36="Y",D36,""),"") | K36: =_xlfn.IFNA(IF(G36="Y",RANK(Q36,$Q$3:$Q$127),""),"") | L36: =_xlfn.IFNA(IF(G36="Y",A36,""),"") | M36: =_xlfn.IFNA(IF(G36="Y",B36,""),"") | N36: =_xlfn.IFNA(IF(G36="Y",100*((I36/H36)-1),""),"") | P36: =P35+0.0001 -> 0.0034 | Q36: =_xlfn.IFNA(IF(G36="Y",N36+P36,""),"") | S36: 34 | T36: =VLOOKUP($S36,$K$3:$N$127,2,FALSE) -> 5003 | U36: =VLOOKUP($S36,$K$3:$N$127,3,FALSE) -> 8 | V36: =VLOOKUP($S36,$K$3:$N$127,4,FALSE) -> -47.943666 | W36: =IF(U36=9,"NW",IF(U36=11,"WA",""))
A37: 5046 | B37: =VLOOKUP($A37,June!$E:$O,11,FALSE) -> 3 | C37: =VLOOKUP($A37,May!$E:$F,2,FALSE) -> 0 | D37: =VLOOKUP($A37,June!$E:$F,2,FALSE) -> 0 | E37: =100*((D37/C37)-1) -> #DIV/0! | G37: =_xlfn.IFNA(IF(AND(C37>0,D37>0),"Y","N"),"N") -> N | H37: =_xlfn.IFNA(IF($G37="Y",C37,""),"") | I37: =_xlfn.IFNA(IF($G37="Y",D37,""),"") | K37: =_xlfn.IFNA(IF(G37="Y",RANK(Q37,$Q$3:$Q$127),""),"") | L37: =_xlfn.IFNA(IF(G37="Y",A37,""),"") | M37: =_xlfn.IFNA(IF(G37="Y",B37,""),"") | N37: =_xlfn.IFNA(IF(G37="Y",100*((I37/H37)-1),""),"") | P37: =P36+0.0001 -> 0.0035 | Q37: =_xlfn.IFNA(IF(G37="Y",N37+P37,""),"")
A38: 5050 | B38: =VLOOKUP($A38,June!$E:$O,11,FALSE) -> 2 | C38: =VLOOKUP($A38,May!$E:$F,2,FALSE) -> 0 | D38: =VLOOKUP($A38,June!$E:$F,2,FALSE) -> 0 | E38: =100*((D38/C38)-1) -> #DIV/0! | G38: =_xlfn.IFNA(IF(AND(C38>0,D38>0),"Y","N"),"N") -> N | H38: =_xlfn.IFNA(IF($G38="Y",C38,""),"") | I38: =_xlfn.IFNA(IF($G38="Y",D38,""),"") | K38: =_xlfn.IFNA(IF(G38="Y",RANK(Q38,$Q$3:$Q$127),""),"") | L38: =_xlfn.IFNA(IF(G38="Y",A38,""),"") | M38: =_xlfn.IFNA(IF(G38="Y",B38,""),"") | N38: =_xlfn.IFNA(IF(G38="Y",100*((I38/H38)-1),""),"") | P38: =P37+0.0001 -> 0.0036 | Q38: =_xlfn.IFNA(IF(G38="Y",N38+P38,""),"") | U38: Mean | V38: =AVERAGE(V3:V36) -> 8.8194124
A39: 5084 | B39: =VLOOKUP($A39,June!$E:$O,11,FALSE) -> 3 | C39: =VLOOKUP($A39,May!$E:$F,2,FALSE) -> 153.99 | D39: =VLOOKUP($A39,June!$E:$F,2,FALSE) -> 140.99 | E39: =100*((D39/C39)-1) -> -8.4421066 | G39: =_xlfn.IFNA(IF(AND(C39>0,D39>0),"Y","N"),"N") -> Y | H39: =_xlfn.IFNA(IF($G39="Y",C39,""),"") -> 153.99 | I39: =_xlfn.IFNA(IF($G39="Y",D39,""),"") -> 140.99 | K39: =_xlfn.IFNA(IF(G39="Y",RANK(Q39,$Q$3:$Q$127),""),"") -> 25 | L39: =_xlfn.IFNA(IF(G39="Y",A39,""),"") -> 5084 | M39: =_xlfn.IFNA(IF(G39="Y",B39,""),"") -> 3 | N39: =_xlfn.IFNA(IF(G39="Y",100*((I39/H39)-1),""),"") -> -8.4421066 | P39: =P38+0.0001 -> 0.0037 | Q39: =_xlfn.IFNA(IF(G39="Y",N39+P39,""),"") -> -8.4384066 | U39: Median | V39: =MEDIAN(V3:V36) -> 0
A40: 5101 | B40: =VLOOKUP($A40,June!$E:$O,11,FALSE) -> 9 | C40: =VLOOKUP($A40,May!$E:$F,2,FALSE) -> 170 | D40: =VLOOKUP($A40,June!$E:$F,2,FALSE) -> 170 | E40: =100*((D40/C40)-1) -> 0 | G40: =_xlfn.IFNA(IF(AND(C40>0,D40>0),"Y","N"),"N") -> Y | H40: =_xlfn.IFNA(IF($G40="Y",C40,""),"") -> 170 | I40: =_xlfn.IFNA(IF($G40="Y",D40,""),"") -> 170 | K40: =_xlfn.IFNA(IF(G40="Y",RANK(Q40,$Q$3:$Q$127),""),"") -> 19 | L40: =_xlfn.IFNA(IF(G40="Y",A40,""),"") -> 5101 | M40: =_xlfn.IFNA(IF(G40="Y",B40,""),"") -> 9 | N40: =_xlfn.IFNA(IF(G40="Y",100*((I40/H40)-1),""),"") -> 0 | P40: =P39+0.0001 -> 0.0038 | Q40: =_xlfn.IFNA(IF(G40="Y",N40+P40,""),"") -> 0.0038
A41: 5101 | B41: =VLOOKUP($A41,June!$E:$O,11,FALSE) -> 9 | C41: =VLOOKUP($A41,May!$E:$F,2,FALSE) -> 170 | D41: =VLOOKUP($A41,June!$E:$F,2,FALSE) -> 170 | E41: =100*((D41/C41)-1) -> 0 | G41: =_xlfn.IFNA(IF(AND(C41>0,D41>0),"Y","N"),"N") -> Y | H41: =_xlfn.IFNA(IF($G41="Y",C41,""),"") -> 170 | I41: =_xlfn.IFNA(IF($G41="Y",D41,""),"") -> 170 | K41: =_xlfn.IFNA(IF(G41="Y",RANK(Q41,$Q$3:$Q$127),""),"") -> 18 | L41: =_xlfn.IFNA(IF(G41="Y",A41,""),"") -> 5101 | M41: =_xlfn.IFNA(IF(G41="Y",B41,""),"") -> 9 | N41: =_xlfn.IFNA(IF(G41="Y",100*((I41/H41)-1),""),"") -> 0 | P41: =P40+0.0001 -> 0.0039 | Q41: =_xlfn.IFNA(IF(G41="Y",N41+P41,""),"") -> 0.0039
A42: 5106 | B42: =VLOOKUP($A42,June!$E:$O,11,FALSE) -> 9 | C42: =VLOOKUP($A42,May!$E:$F,2,FALSE) -> 85.99 | D42: =VLOOKUP($A42,June!$E:$F,2,FALSE) -> 210.99 | E42: =100*((D42/C42)-1) -> 145.36574 | G42: =_xlfn.IFNA(IF(AND(C42>0,D42>0),"Y","N"),"N") -> Y | H42: =_xlfn.IFNA(IF($G42="Y",C42,""),"") -> 85.99 | I42: =_xlfn.IFNA(IF($G42="Y",D42,""),"") -> 210.99 | K42: =_xlfn.IFNA(IF(G42="Y",RANK(Q42,$Q$3:$Q$127),""),"") -> 2 | L42: =_xlfn.IFNA(IF(G42="Y",A42,""),"") -> 5106 | M42: =_xlfn.IFNA(IF(G42="Y",B42,""),"") -> 9 | N42: =_xlfn.IFNA(IF(G42="Y",100*((I42/H42)-1),""),"") -> 145.36574 | P42: =P41+0.0001 -> 0.004 | Q42: =_xlfn.IFNA(IF(G42="Y",N42+P42,""),"") -> 145.36974
A43: 5112 | B43: =VLOOKUP($A43,June!$E:$O,11,FALSE) -> 13 | C43: =VLOOKUP($A43,May!$E:$F,2,FALSE) -> 0 | D43: =VLOOKUP($A43,June!$E:$F,2,FALSE) -> 0 | E43: =100*((D43/C43)-1) -> #DIV/0! | G43: =_xlfn.IFNA(IF(AND(C43>0,D43>0),"Y","N"),"N") -> N | H43: =_xlfn.IFNA(IF($G43="Y",C43,""),"") | I43: =_xlfn.IFNA(IF($G43="Y",D43,""),"") | K43: =_xlfn.IFNA(IF(G43="Y",RANK(Q43,$Q$3:$Q$127),""),"") | L43: =_xlfn.IFNA(IF(G43="Y",A43,""),"") | M43: =_xlfn.IFNA(IF(G43="Y",B43,""),"") | N43: =_xlfn.IFNA(IF(G43="Y",100*((I43/H43)-1),""),"") | P43: =P42+0.0001 -> 0.0041 | Q43: =_xlfn.IFNA(IF(G43="Y",N43+P43,""),"")
A44: 5117 | B44: =VLOOKUP($A44,June!$E:$O,11,FALSE) -> 10 | C44: =VLOOKUP($A44,May!$E:$F,2,FALSE) -> 79 | D44: =VLOOKUP($A44,June!$E:$F,2,FALSE) -> 79 | E44: =100*((D44/C44)-1) -> 0 | G44: =_xlfn.IFNA(IF(AND(C44>0,D44>0),"Y","N"),"N") -> Y | H44: =_xlfn.IFNA(IF($G44="Y",C44,""),"") -> 79 | I44: =_xlfn.IFNA(IF($G44="Y",D44,""),"") -> 79 | K44: =_xlfn.IFNA(IF(G44="Y",RANK(Q44,$Q$3:$Q$127),""),"") -> 17 | L44: =_xlfn.IFNA(IF(G44="Y",A44,""),"") -> 5117 | M44: =_xlfn.IFNA(IF(G44="Y",B44,""),"") -> 10 | N44: =_xlfn.IFNA(IF(G44="Y",100*((I44/H44)-1),""),"") -> 0 | P44: =P43+0.0001 -> 0.0042 | Q44: =_xlfn.IFNA(IF(G44="Y",N44+P44,""),"") -> 0.0042
A45: 5120 | B45: =VLOOKUP($A45,June!$E:$O,11,FALSE) -> 3 | C45: =VLOOKUP($A45,May!$E:$F,2,FALSE) -> 159.85 | D45: =VLOOKUP($A45,June!$E:$F,2,FALSE) -> 134.85 | E45: =100*((D45/C45)-1) -> -15.639662 | G45: =_xlfn.IFNA(IF(AND(C45>0,D45>0),"Y","N"),"N") -> Y | H45: =_xlfn.IFNA(IF($G45="Y",C45,""),"") -> 159.85 | I45: =_xlfn.IFNA(IF($G45="Y",D45,""),"") -> 134.85 | K45: =_xlfn.IFNA(IF(G45="Y",RANK(Q45,$Q$3:$Q$127),""),"") -> 29 | L45: =_xlfn.IFNA(IF(G45="Y",A45,""),"") -> 5120 | M45: =_xlfn.IFNA(IF(G45="Y",B45,""),"") -> 3 | N45: =_xlfn.IFNA(IF(G45="Y",100*((I45/H45)-1),""),"") -> -15.639662 | P45: =P44+0.0001 -> 0.0043 | Q45: =_xlfn.IFNA(IF(G45="Y",N45+P45,""),"") -> -15.635362
A46: 5120 | B46: =VLOOKUP($A46,June!$E:$O,11,FALSE) -> 3 | C46: =VLOOKUP($A46,May!$E:$F,2,FALSE) -> 159.85 | D46: =VLOOKUP($A46,June!$E:$F,2,FALSE) -> 134.85 | E46: =100*((D46/C46)-1) -> -15.639662 | G46: =_xlfn.IFNA(IF(AND(C46>0,D46>0),"Y","N"),"N") -> Y | H46: =_xlfn.IFNA(IF($G46="Y",C46,""),"") -> 159.85 | I46: =_xlfn.IFNA(IF($G46="Y",D46,""),"") -> 134.85 | K46: =_xlfn.IFNA(IF(G46="Y",RANK(Q46,$Q$3:$Q$127),""),"") -> 28 | L46: =_xlfn.IFNA(IF(G46="Y",A46,""),"") -> 5120 | M46: =_xlfn.IFNA(IF(G46="Y",B46,""),"") -> 3 | N46: =_xlfn.IFNA(IF(G46="Y",100*((I46/H46)-1),""),"") -> -15.639662 | P46: =P45+0.0001 -> 0.0044 | Q46: =_xlfn.IFNA(IF(G46="Y",N46+P46,""),"") -> -15.635262
A47: 5122 | B47: =VLOOKUP($A47,June!$E:$O,11,FALSE) -> 11 | C47: =VLOOKUP($A47,May!$E:$F,2,FALSE) -> 95 | D47: =VLOOKUP($A47,June!$E:$F,2,FALSE) -> 0 | E47: =100*((D47/C47)-1) -> -100 | G47: =_xlfn.IFNA(IF(AND(C47>0,D47>0),"Y","N"),"N") -> N | H47: =_xlfn.IFNA(IF($G47="Y",C47,""),"") | I47: =_xlfn.IFNA(IF($G47="Y",D47,""),"") | K47: =_xlfn.IFNA(IF(G47="Y",RANK(Q47,$Q$3:$Q$127),""),"") | L47: =_xlfn.IFNA(IF(G47="Y",A47,""),"") | M47: =_xlfn.IFNA(IF(G47="Y",B47,""),"") | N47: =_xlfn.IFNA(IF(G47="Y",100*((I47/H47)-1),""),"") | P47: =P46+0.0001 -> 0.0045 | Q47: =_xlfn.IFNA(IF(G47="Y",N47+P47,""),"")
A48: 5133 | B48: =VLOOKUP($A48,June!$E:$O,11,FALSE) -> 9 | C48: =VLOOKUP($A48,May!$E:$F,2,FALSE) -> 90 | D48: =VLOOKUP($A48,June!$E:$F,2,FALSE) -> 90 | E48: =100*((D48/C48)-1) -> 0 | G48: =_xlfn.IFNA(IF(AND(C48>0,D48>0),"Y","N"),"N") -> Y | H48: =_xlfn.IFNA(IF($G48="Y",C48,""),"") -> 90 | I48: =_xlfn.IFNA(IF($G48="Y",D48,""),"") -> 90 | K48: =_xlfn.IFNA(IF(G48="Y",RANK(Q48,$Q$3:$Q$127),""),"") -> 16 | L48: =_xlfn.IFNA(IF(G48="Y",A48,""),"") -> 5133 | M48: =_xlfn.IFNA(IF(G48="Y",B48,""),"") -> 9 | N48: =_xlfn.IFNA(IF(G48="Y",100*((I48/H48)-1),""),"") -> 0 | P48: =P47+0.0001 -> 0.0046 | Q48: =_xlfn.IFNA(IF(G48="Y",N48+P48,""),"") -> 0.0046
A49: 5180 | B49: =VLOOKUP($A49,June!$E:$O,11,FALSE) -> 12 | C49: =VLOOKUP($A49,May!$E:$F,2,FALSE) -> 0 | D49: =VLOOKUP($A49,June!$E:$F,2,FALSE) -> 150 | E49: =100*((D49/C49)-1) -> #DIV/0! | G49: =_xlfn.IFNA(IF(AND(C49>0,D49>0),"Y","N"),"N") -> N | H49: =_xlfn.IFNA(IF($G49="Y",C49,""),"") | I49: =_xlfn.IFNA(IF($G49="Y",D49,""),"") | K49: =_xlfn.IFNA(IF(G49="Y",RANK(Q49,$Q$3:$Q$127),""),"") | L49: =_xlfn.IFNA(IF(G49="Y",A49,""),"") | M49: =_xlfn.IFNA(IF(G49="Y",B49,""),"") | N49: =_xlfn.IFNA(IF(G49="Y",100*((I49/H49)-1),""),"") | P49: =P48+0.0001 -> 0.0047 | Q49: =_xlfn.IFNA(IF(G49="Y",N49+P49,""),"")
A50: 5226 | B50: =VLOOKUP($A50,June!$E:$O,11,FALSE) -> 2 | C50: =VLOOKUP($A50,May!$E:$F,2,FALSE) -> 126.99 | D50: =VLOOKUP($A50,June!$E:$F,2,FALSE) -> 148.99 | E50: =100*((D50/C50)-1) -> 17.324199 | G50: =_xlfn.IFNA(IF(AND(C50>0,D50>0),"Y","N"),"N") -> Y | H50: =_xlfn.IFNA(IF($G50="Y",C50,""),"") -> 126.99 | I50: =_xlfn.IFNA(IF($G50="Y",D50,""),"") -> 148.99 | K50: =_xlfn.IFNA(IF(G50="Y",RANK(Q50,$Q$3:$Q$127),""),"") -> 9 | L50: =_xlfn.IFNA(IF(G50="Y",A50,""),"") -> 5226 | M50: =_xlfn.IFNA(IF(G50="Y",B50,""),"") -> 2 | N50: =_xlfn.IFNA(IF(G50="Y",100*((I50/H50)-1),""),"") -> 17.324199 | P50: =P49+0.0001 -> 0.0048 | Q50: =_xlfn.IFNA(IF(G50="Y",N50+P50,""),"") -> 17.328999
A51: 5246 | B51: =VLOOKUP($A51,June!$E:$O,11,FALSE) -> 2 | C51: =VLOOKUP($A51,May!$E:$F,2,FALSE) -> 0 | D51: =VLOOKUP($A51,June!$E:$F,2,FALSE) -> 144 | E51: =100*((D51/C51)-1) -> #DIV/0! | G51: =_xlfn.IFNA(IF(AND(C51>0,D51>0),"Y","N"),"N") -> N | H51: =_xlfn.IFNA(IF($G51="Y",C51,""),"") | I51: =_xlfn.IFNA(IF($G51="Y",D51,""),"") | K51: =_xlfn.IFNA(IF(G51="Y",RANK(Q51,$Q$3:$Q$127),""),"") | L51: =_xlfn.IFNA(IF(G51="Y",A51,""),"") | M51: =_xlfn.IFNA(IF(G51="Y",B51,""),"") | N51: =_xlfn.IFNA(IF(G51="Y",100*((I51/H51)-1),""),"") | P51: =P50+0.0001 -> 0.0049 | Q51: =_xlfn.IFNA(IF(G51="Y",N51+P51,""),"")
... A127: 19466 | B127: =VLOOKUP($A127,June!$E:$O,11,FALSE) -> 11 | C127: =VLOOKUP($A127,May!$E:$F,2,FALSE) -> #N/A | D127: =VLOOKUP($A127,June!$E:$F,2,FALSE) -> 57 | E127: =100*((D127/C127)-1) -> #N/A | G127: =_xlfn.IFNA(IF(AND(C127>0,D127>0),"Y","N"),"N") -> N | H127: =_xlfn.IFNA(IF($G127="Y",C127,""),"") | I127: =_xlfn.IFNA(IF($G127="Y",D127,""),"") | K127: =_xlfn.IFNA(IF(G127="Y",RANK(Q127,$Q$3:$Q$127),""),"") | L127: =_xlfn.IFNA(IF(G127="Y",A127,""),"") | M127: =_xlfn.IFNA(IF(G127="Y",B127,""),"") | N127: =_xlfn.IFNA(IF(G127="Y",100*((I127/H127)-1),""),"") | P127: =P126+0.0001 -> 0.0125 | Q127: =_xlfn.IFNA(IF(G127="Y",N127+P127,""),"")
G129: =COUNTIF($G$3:$G$127,"Y") -> 34

Sheet May
A1: QUOTE_DATE | B1: ITEM_ID | C1: ITEM_DESC | D1: VALIDITY | E1: SHOP_CODE | F1: PRICE | G1: INDICATOR_BOX | H1: ORIG_INDICATOR_BOX | I1: PRICE_RELATIVE | J1: LOG_PRICE_RELATIVE | K1: STRATUM_WEIGHT | L1: STRATUM_TYPE | M1: START_DATE | N1: END_DATE | O1: REGION | P1: SHOP_TYPE | Q1: SHOP_WEIGHT | R1: BASE_PRICE | S1: BASE_VALIDITY | T1: STRATUM_CELL | W1: https://www.ons.gov.uk/file?uri=/economy/inflationandpriceindices/datasets/consumerpriceindicescpiandretailpricesindexrpiitemindicesandpricequotes/pricequotesmay2024/upload-pricequotes202405.csv
A2: 202405 | B2: 640406 | C2: HOTEL 1 NIGHT PRICE | D2: 3 | E2: 161 | F2: 129 | I2: 1.449 | J2: 0.371 | K2: 10.37 | L2: 1 | M2: 202402 | N2: 999999 | O2: 4 | P2: 2 | Q2: 1 | R2: 89 | S2: 3 | T2: 4
A3: 202405 | B3: 640406 | C3: HOTEL 1 NIGHT PRICE | D3: 3 | E3: 167 | F3: 69 | I3: 0.972 | J3: -0.029 | K3: 3.39 | L3: 1 | M3: 202402 | N3: 999999 | O3: 10 | P3: 2 | Q3: 1 | R3: 71 | S3: 3 | T3: 10
A4: 202405 | B4: 640406 | C4: HOTEL 1 NIGHT PRICE | D4: 1 | E4: 191 | F4: 0 | G4: T | H4: T | I4: 0 | J4: 0 | K4: 8.35 | L4: 1 | M4: 202402 | N4: 999999 | O4: 7 | P4: 2 | Q4: 1 | R4: 90 | S4: 3 | T4: 7
A5: 202405 | B5: 640406 | C5: HOTEL 1 NIGHT PRICE | D5: 1 | E5: 210 | F5: 0 | G5: T | H5: T | I5: 0 | J5: 0 | K5: 9.36 | L5: 1 | M5: 202402 | N5: 999999 | O5: 8 | P5: 1 | Q5: 1 | R5: 126.99 | S5: 3 | T5: 8
A6: 202405 | B6: 640406 | C6: HOTEL 1 NIGHT PRICE | D6: 1 | E6: 211 | F6: 0 | G6: T | H6: T | I6: 0 | J6: 0 | K6: 9.36 | L6: 1 | M6: 202402 | N6: 999999 | O6: 8 | P6: 2 | Q6: 1 | R6: 40 | S6: 3 | T6: 8
A7: 202405 | B7: 640406 | C7: HOTEL 1 NIGHT PRICE | D7: 1 | E7: 221 | F7: 0 | G7: T | H7: T | I7: 0 | J7: 0 | K7: 8.35 | L7: 1 | M7: 202402 | N7: 999999 | O7: 7 | P7: 2 | Q7: 1 | R7: 99.95 | S7: 3 | T7: 7
A8: 202405 | B8: 640406 | C8: HOTEL 1 NIGHT PRICE | D8: 3 | E8: 255 | F8: 109.99 | I8: 1.089 | J8: 0.085 | K8: 7.57 | L8: 1 | M8: 202402 | N8: 999999 | O8: 6 | P8: 1 | Q8: 1 | R8: 100.99 | S8: 3 | T8: 6
A9: 202405 | B9: 640406 | C9: HOTEL 1 NIGHT PRICE | D9: 1 | E9: 287 | F9: 0 | G9: T | H9: T | I9: 0 | J9: 0 | K9: 8.35 | L9: 1 | M9: 202402 | N9: 999999 | O9: 7 | P9: 2 | Q9: 1 | R9: 129 | S9: 3 | T9: 7
A10: 202405 | B10: 640406 | C10: HOTEL 1 NIGHT PRICE | D10: 3 | E10: 307 | F10: 105 | I10: 1.167 | J10: 0.154 | K10: 9.36 | L10: 1 | M10: 202402 | N10: 999999 | O10: 8 | P10: 2 | Q10: 1 | R10: 90 | S10: 3 | T10: 8
A11: 202405 | B11: 640406 | C11: HOTEL 1 NIGHT PRICE | D11: 4 | E11: 308 | F11: 165 | I11: 1.737 | J11: 0.552 | K11: 7.87 | L11: 1 | M11: 202402 | N11: 999999 | O11: 12 | P11: 2 | Q11: 1 | R11: 95 | S11: 3 | T11: 12
A12: 202405 | B12: 640406 | C12: HOTEL 1 NIGHT PRICE | D12: 1 | E12: 335 | F12: 0 | G12: T | H12: T | I12: 0 | J12: 0 | K12: 7.87 | L12: 1 | M12: 202402 | N12: 999999 | O12: 12 | P12: 2 | Q12: 1 | R12: 44.1 | S12: 3 | T12: 12
A13: 202405 | B13: 640406 | C13: HOTEL 1 NIGHT PRICE | D13: 3 | E13: 340 | F13: 70 | I13: 1 | J13: 0 | K13: 7.87 | L13: 1 | M13: 202402 | N13: 999999 | O13: 12 | P13: 2 | Q13: 1 | R13: 70 | S13: 3 | T13: 12
A14: 202405 | B14: 640406 | C14: HOTEL 1 NIGHT PRICE | D14: 3 | E14: 372 | F14: 71.49 | I14: 1.81 | J14: 0.594 | K14: 9.89 | L14: 1 | M14: 202402 | N14: 999999 | O14: 9 | P14: 1 | Q14: 1 | R14: 39.49 | S14: 3 | T14: 9
A15: 202405 | B15: 640406 | C15: HOTEL 1 NIGHT PRICE | D15: 1 | E15: 373 | F15: 0 | G15: T | H15: T | I15: 0 | J15: 0 | K15: 9.89 | L15: 1 | M15: 202402 | N15: 999999 | O15: 9 | P15: 2 | Q15: 1 | R15: 110.88 | S15: 3 | T15: 9
A16: 202405 | B16: 640406 | C16: HOTEL 1 NIGHT PRICE | D16: 1 | E16: 378 | F16: 0 | G16: T | H16: T | I16: 0 | J16: 0 | K16: 8.35 | L16: 1 | M16: 202402 | N16: 999999 | O16: 7 | P16: 2 | Q16: 1 | R16: 141 | S16: 3 | T16: 7
A17: 202405 | B17: 640406 | C17: HOTEL 1 NIGHT PRICE | D17: 3 | E17: 393 | F17: 55 | I17: 1 | J17: 0 | K17: 7.87 | L17: 1 | M17: 202402 | N17: 999999 | O17: 12 | P17: 2 | Q17: 1 | R17: 55 | S17: 3 | T17: 12
A18: 202405 | B18: 640406 | C18: HOTEL 1 NIGHT PRICE | D18: 1 | E18: 466 | F18: 0 | G18: T | H18: T | I18: 0 | J18: 0 | K18: 8.24 | L18: 1 | M18: 202404 | N18: 999999 | O18: 5 | P18: 2 | Q18: 1 | R18: 78.622 | S18: 4 | T18: 5
A19: 202405 | B19: 640406 | C19: HOTEL 1 NIGHT PRICE | D19: 1 | E19: 518 | F19: 0 | G19: T | H19: T | I19: 0 | J19: 0 | K19: 9.75 | L19: 1 | M19: 202402 | N19: 999999 | O19: 2 | P19: 1 | Q19: 1 | R19: 279 | S19: 3 | T19: 2
A20: 202405 | B20: 640406 | C20: HOTEL 1 NIGHT PRICE | D20: 1 | E20: 519 | F20: 0 | G20: T | H20: T | I20: 0 | J20: 0 | K20: 9.75 | L20: 1 | M20: 202402 | N20: 999999 | O20: 2 | P20: 2 | Q20: 1 | R20: 55 | S20: 3 | T20: 2
A21: 202405 | B21: 640406 | C21: HOTEL 1 NIGHT PRICE | D21: 1 | E21: 541 | F21: 0 | G21: T | H21: T | I21: 0 | J21: 0 | K21: 9.75 | L21: 1 | M21: 202402 | N21: 999999 | O21: 2 | P21: 1 | Q21: 1 | R21: 149.99 | S21: 3 | T21: 2
A22: 202405 | B22: 640406 | C22: HOTEL 1 NIGHT PRICE | D22: 3 | E22: 544 | F22: 196.75 | I22: 1.139 | J22: 0.13 | K22: 9.75 | L22: 1 | M22: 202402 | N22: 999999 | O22: 2 | P22: 2 | Q22: 1 | R22: 172.75 | S22: 3 | T22: 2
A23: 202405 | B23: 640406 | C23: HOTEL 1 NIGHT PRICE | D23: 3 | E23: 642 | F23: 116 | I23: 1.055 | J23: 0.053 | K23: 9.89 | L23: 1 | M23: 202402 | N23: 999999 | O23: 9 | P23: 2 | Q23: 1 | R23: 110 | S23: 3 | T23: 9
A24: 202405 | B24: 640406 | C24: HOTEL 1 NIGHT PRICE | D24: 3 | E24: 673 | F24: 99 | I24: 1.692 | J24: 0.526 | K24: 18.44 | L24: 1 | M24: 202402 | N24: 999999 | O24: 3 | P24: 2 | Q24: 1 | R24: 58.5 | S24: 3 | T24: 3
A25: 202405 | B25: 640406 | C25: HOTEL 1 NIGHT PRICE | D25: 1 | E25: 729 | F25: 0 | G25: T | H25: T | I25: 0 | J25: 0 | K25: 18.44 | L25: 1 | M25: 202402 | N25: 999999 | O25: 3 | P25: 1 | Q25: 1 | R25: 165 | S25: 3 | T25: 3
A26: 202405 | B26: 640406 | C26: HOTEL 1 NIGHT PRICE | D26: 3 | E26: 733 | F26: 185 | I26: 1.186 | J26: 0.17 | K26: 18.44 | L26: 1 | M26: 202402 | N26: 999999 | O26: 3 | P26: 1 | Q26: 1 | R26: 156 | S26: 3 | T26: 3
A27: 202405 | B27: 640406 | C27: HOTEL 1 NIGHT PRICE | D27: 1 | E27: 5001 | F27: 0 | G27: T | H27: T | I27: 0 | J27: 0 | K27: 9.36 | L27: 1 | M27: 202402 | N27: 999999 | O27: 8 | P27: 2 | Q27: 1 | R27: 143 | S27: 3 | T27: 8
A28: 202405 | B28: 640406 | C28: HOTEL 1 NIGHT PRICE | D28: 4 | E28: 5003 | F28: 133.49 | I28: 1.816 | J28: 0.597 | K28: 9.36 | L28: 1 | M28: 202402 | N28: 999999 | O28: 8 | P28: 1 | Q28: 1 | R28: 73.49 | S28: 3 | T28: 8
A29: 202405 | B29: 640406 | C29: HOTEL 1 NIGHT PRICE | D29: 3 | E29: 5007 | F29: 130 | I29: 1.171 | J29: 0.158 | K29: 9.89 | L29: 1 | M29: 202402 | N29: 999999 | O29: 9 | P29: 1 | Q29: 1 | R29: 111 | S29: 3 | T29: 9
A30: 202405 | B30: 640406 | C30: HOTEL 1 NIGHT PRICE | D30: 3 | E30: 5028 | F30: 65 | I30: 1.196 | J30: 0.179 | K30: 9.36 | L30: 1 | M30: 202403 | N30: 999999 | O30: 8 | P30: 1 | Q30: 1 | R30: 54.338 | S30: 4 | T30: 8
A31: 202405 | B31: 640406 | C31: HOTEL 1 NIGHT PRICE | D31: 1 | E31: 5035 | F31: 0 | G31: T | H31: T | I31: 0 | J31: 0 | K31: 18.44 | L31: 1 | M31: 202402 | N31: 999999 | O31: 3 | P31: 2 | Q31: 1 | R31: 126 | S31: 3 | T31: 3
A32: 202405 | B32: 640406 | C32: HOTEL 1 NIGHT PRICE | D32: 3 | E32: 5043 | F32: 140 | I32: 1.274 | J32: 0.242 | K32: 8.24 | L32: 1 | M32: 202404 | N32: 999999 | O32: 5 | P32: 2 | Q32: 1 | R32: 109.902 | S32: 4 | T32: 5
A33: 202405 | B33: 640406 | C33: HOTEL 1 NIGHT PRICE | D33: 1 | E33: 5046 | F33: 0 | G33: T | H33: T | I33: 0 | J33: 0 | K33: 18.44 | L33: 1 | M33: 202402 | N33: 999999 | O33: 3 | P33: 2 | Q33: 1 | R33: 120 | S33: 3 | T33: 3
A34: 202405 | B34: 640406 | C34: HOTEL 1 NIGHT PRICE | D34: 1 | E34: 5050 | F34: 0 | G34: T | H34: T | I34: 0 | J34: 0 | K34: 9.75 | L34: 1 | M34: 202402 | N34: 999999 | O34: 2 | P34: 1 | Q34: 1 | R34: 660 | S34: 3 | T34: 2
A35: 202405 | B35: 640406 | C35: HOTEL 1 NIGHT PRICE | D35: 4 | E35: 5084 | F35: 153.99 | I35: 1.4 | J35: 0.336 | K35: 18.44 | L35: 1 | M35: 202402 | N35: 999999 | O35: 3 | P35: 2 | Q35: 1 | R35: 109.99 | S35: 3 | T35: 3
A36: 202405 | B36: 640406 | C36: HOTEL 1 NIGHT PRICE | D36: 3 | E36: 5101 | F36: 170 | I36: 1.314 | J36: 0.273 | K36: 9.89 | L36: 1 | M36: 202403 | N36: 999999 | O36: 9 | P36: 2 | Q36: 1 | R36: 129.399 | S36: 4 | T36: 9
A37: 202405 | B37: 640406 | C37: HOTEL 1 NIGHT PRICE | D37: 3 | E37: 5101 | F37: 57.5 | I37: 1.15 | J37: 0.14 | K37: 3.39 | L37: 1 | M37: 202402 | N37: 999999 | O37: 10 | P37: 2 | Q37: 1 | R37: 50 | S37: 3 | T37: 10
A38: 202405 | B38: 640406 | C38: HOTEL 1 NIGHT PRICE | D38: 4 | E38: 5106 | F38: 85.99 | I38: 0.489 | J38: -0.716 | K38: 9.89 | L38: 1 | M38: 202402 | N38: 999999 | O38: 9 | P38: 1 | Q38: 1 | R38: 175.99 | S38: 3 | T38: 9
A39: 202405 | B39: 640406 | C39: HOTEL 1 NIGHT PRICE | D39: 1 | E39: 5112 | F39: 0 | G39: T | H39: T | I39: 0 | J39: 0 | K39: 1.01 | L39: 1 | M39: 202403 | N39: 999999 | O39: 13 | P39: 2 | Q39: 1 | R39: 113.424 | S39: 4 | T39: 13
A40: 202405 | B40: 640406 | C40: HOTEL 1 NIGHT PRICE | D40: 3 | E40: 5117 | F40: 79 | I40: 1.099 | J40: 0.094 | K40: 3.39 | L40: 1 | M40: 202402 | N40: 999999 | O40: 10 | P40: 2 | Q40: 1 | R40: 71.89 | S40: 3 | T40: 10
...

Sheet June
A1: QUOTE_DATE | B1: ITEM_ID | C1: ITEM_DESC | D1: VALIDITY | E1: SHOP_CODE | F1: PRICE | G1: INDICATOR_BOX | H1: ORIG_INDICATOR_BOX | I1: PRICE_RELATIVE | J1: LOG_PRICE_RELATIVE | K1: STRATUM_WEIGHT | L1: STRATUM_TYPE | M1: START_DATE | N1: END_DATE | O1: REGION | P1: SHOP_TYPE | Q1: SHOP_WEIGHT | R1: BASE_PRICE | S1: BASE_VALIDITY | T1: STRATUM_CELL | W1: https://www.ons.gov.uk/file?uri=/economy/inflationandpriceindices/datasets/consumerpriceindicescpiandretailpricesindexrpiitemindicesandpricequotes/pricequotesjune2024/upload-pricequotes202406.csv
A2: 202406 | B2: 640406 | C2: HOTEL 1 NIGHT PRICE | D2: 3 | E2: 161 | F2: 159 | I2: 1.787 | J2: 0.58 | K2: 10.37 | L2: 1 | M2: 202402 | N2: 999999 | O2: 4 | P2: 2 | Q2: 1 | R2: 89 | S2: 3 | T2: 4
A3: 202406 | B3: 640406 | C3: HOTEL 1 NIGHT PRICE | D3: 3 | E3: 167 | F3: 80 | I3: 1.127 | J3: 0.119 | K3: 3.39 | L3: 1 | M3: 202402 | N3: 999999 | O3: 10 | P3: 2 | Q3: 1 | R3: 71 | S3: 3 | T3: 10
A4: 202406 | B4: 640406 | C4: HOTEL 1 NIGHT PRICE | D4: 3 | E4: 191 | F4: 125 | I4: 1.389 | J4: 0.329 | K4: 8.35 | L4: 1 | M4: 202402 | N4: 999999 | O4: 7 | P4: 2 | Q4: 1 | R4: 90 | S4: 3 | T4: 7
A5: 202406 | B5: 640406 | C5: HOTEL 1 NIGHT PRICE | D5: 3 | E5: 210 | F5: 154 | I5: 1.213 | J5: 0.193 | K5: 9.36 | L5: 1 | M5: 202402 | N5: 999999 | O5: 8 | P5: 1 | Q5: 1 | R5: 126.99 | S5: 3 | T5: 8
A6: 202406 | B6: 640406 | C6: HOTEL 1 NIGHT PRICE | D6: 1 | E6: 211 | F6: 0 | G6: T | H6: T | I6: 0 | J6: 0 | K6: 9.36 | L6: 1 | M6: 202402 | N6: 999999 | O6: 8 | P6: 2 | Q6: 1 | R6: 40 | S6: 3 | T6: 8
A7: 202406 | B7: 640406 | C7: HOTEL 1 NIGHT PRICE | D7: 3 | E7: 221 | F7: 147.5 | I7: 1.476 | J7: 0.389 | K7: 8.35 | L7: 1 | M7: 202402 | N7: 999999 | O7: 7 | P7: 2 | Q7: 1 | R7: 99.95 | S7: 3 | T7: 7
A8: 202406 | B8: 640406 | C8: HOTEL 1 NIGHT PRICE | D8: 3 | E8: 255 | F8: 129.99 | I8: 1.287 | J8: 0.252 | K8: 7.57 | L8: 1 | M8: 202402 | N8: 999999 | O8: 6 | P8: 1 | Q8: 1 | R8: 100.99 | S8: 3 | T8: 6
A9: 202406 | B9: 640406 | C9: HOTEL 1 NIGHT PRICE | D9: 1 | E9: 287 | F9: 0 | G9: T | H9: T | I9: 0 | J9: 0 | K9: 8.35 | L9: 1 | M9: 202402 | N9: 999999 | O9: 7 | P9: 2 | Q9: 1 | R9: 129 | S9: 3 | T9: 7
A10: 202406 | B10: 640406 | C10: HOTEL 1 NIGHT PRICE | D10: 3 | E10: 307 | F10: 105 | I10: 1.167 | J10: 0.154 | K10: 9.36 | L10: 1 | M10: 202402 | N10: 999999 | O10: 8 | P10: 2 | Q10: 1 | R10: 90 | S10: 3 | T10: 8
A11: 202406 | B11: 640406 | C11: HOTEL 1 NIGHT PRICE | D11: 3 | E11: 308 | F11: 115 | I11: 1.211 | J11: 0.191 | K11: 7.87 | L11: 1 | M11: 202402 | N11: 999999 | O11: 12 | P11: 2 | Q11: 1 | R11: 95 | S11: 3 | T11: 12
A12: 202406 | B12: 640406 | C12: HOTEL 1 NIGHT PRICE | D12: 3 | E12: 333 | F12: 150 | I12: 1.555 | J12: 0.442 | K12: 7.87 | L12: 1 | M12: 202406 | N12: 999999 | O12: 12 | P12: 2 | Q12: 1 | R12: 96.445 | S12: 4 | T12: 12
A13: 202406 | B13: 640406 | C13: HOTEL 1 NIGHT PRICE | D13: 1 | E13: 335 | F13: 0 | G13: T | H13: T | I13: 0 | J13: 0 | K13: 7.87 | L13: 1 | M13: 202402 | N13: 999999 | O13: 12 | P13: 2 | Q13: 1 | R13: 44.1 | S13: 3 | T13: 12
A14: 202406 | B14: 640406 | C14: HOTEL 1 NIGHT PRICE | D14: 3 | E14: 340 | F14: 70 | I14: 1 | J14: 0 | K14: 7.87 | L14: 1 | M14: 202402 | N14: 999999 | O14: 12 | P14: 2 | Q14: 1 | R14: 70 | S14: 3 | T14: 12
A15: 202406 | B15: 640406 | C15: HOTEL 1 NIGHT PRICE | D15: 1 | E15: 372 | F15: 0 | G15: T | H15: T | I15: 0 | J15: 0 | K15: 9.89 | L15: 1 | M15: 202402 | N15: 999999 | O15: 9 | P15: 1 | Q15: 1 | R15: 39.49 | S15: 3 | T15: 9
A16: 202406 | B16: 640406 | C16: HOTEL 1 NIGHT PRICE | D16: 3 | E16: 373 | F16: 205.65 | I16: 1.855 | J16: 0.618 | K16: 9.89 | L16: 1 | M16: 202402 | N16: 999999 | O16: 9 | P16: 2 | Q16: 1 | R16: 110.88 | S16: 3 | T16: 9
A17: 202406 | B17: 640406 | C17: HOTEL 1 NIGHT PRICE | D17: 3 | E17: 378 | F17: 171 | I17: 1.213 | J17: 0.193 | K17: 8.35 | L17: 1 | M17: 202402 | N17: 999999 | O17: 7 | P17: 2 | Q17: 1 | R17: 141 | S17: 3 | T17: 7
A18: 202406 | B18: 640406 | C18: HOTEL 1 NIGHT PRICE | D18: 1 | E18: 393 | F18: 0 | G18: T | H18: T | I18: 0 | J18: 0 | K18: 7.87 | L18: 1 | M18: 202402 | N18: 999999 | O18: 12 | P18: 2 | Q18: 1 | R18: 55 | S18: 3 | T18: 12
A19: 202406 | B19: 640406 | C19: HOTEL 1 NIGHT PRICE | D19: 3 | E19: 395 | F19: 127 | I19: 1.045 | J19: 0.044 | K19: 7.87 | L19: 1 | M19: 202406 | N19: 999999 | O19: 12 | P19: 2 | Q19: 1 | R19: 121.52 | S19: 4 | T19: 12
A20: 202406 | B20: 640406 | C20: HOTEL 1 NIGHT PRICE | D20: 1 | E20: 466 | F20: 0 | G20: T | H20: T | I20: 0 | J20: 0 | K20: 8.24 | L20: 1 | M20: 202404 | N20: 999999 | O20: 5 | P20: 2 | Q20: 1 | R20: 78.622 | S20: 4 | T20: 5
A21: 202406 | B21: 640406 | C21: HOTEL 1 NIGHT PRICE | D21: 3 | E21: 518 | F21: 569 | I21: 2.039 | J21: 0.713 | K21: 9.75 | L21: 1 | M21: 202402 | N21: 999999 | O21: 2 | P21: 1 | Q21: 1 | R21: 279 | S21: 3 | T21: 2
A22: 202406 | B22: 640406 | C22: HOTEL 1 NIGHT PRICE | D22: 3 | E22: 519 | F22: 108 | I22: 1.964 | J22: 0.675 | K22: 9.75 | L22: 1 | M22: 202402 | N22: 999999 | O22: 2 | P22: 2 | Q22: 1 | R22: 55 | S22: 3 | T22: 2
A23: 202406 | B23: 640406 | C23: HOTEL 1 NIGHT PRICE | D23: 1 | E23: 541 | F23: 0 | G23: T | H23: T | I23: 0 | J23: 0 | K23: 9.75 | L23: 1 | M23: 202402 | N23: 999999 | O23: 2 | P23: 1 | Q23: 1 | R23: 149.99 | S23: 3 | T23: 2
A24: 202406 | B24: 640406 | C24: HOTEL 1 NIGHT PRICE | D24: 1 | E24: 542 | F24: 0 | G24: T | H24: T | I24: 0 | J24: 0 | K24: 9.75 | L24: 1 | M24: 202406 | N24: 999999 | O24: 2 | P24: 2 | Q24: 1 | R24: 239.317 | S24: 4 | T24: 2
A25: 202406 | B25: 640406 | C25: HOTEL 1 NIGHT PRICE | D25: 1 | E25: 544 | F25: 0 | G25: T | H25: T | I25: 0 | J25: 0 | K25: 9.75 | L25: 1 | M25: 202402 | N25: 999999 | O25: 2 | P25: 2 | Q25: 1 | R25: 172.75 | S25: 3 | T25: 2
A26: 202406 | B26: 640406 | C26: HOTEL 1 NIGHT PRICE | D26: 1 | E26: 642 | F26: 0 | G26: T | H26: T | I26: 0 | J26: 0 | K26: 9.89 | L26: 1 | M26: 202402 | N26: 999999 | O26: 9 | P26: 2 | Q26: 1 | R26: 110 | S26: 3 | T26: 9
A27: 202406 | B27: 640406 | C27: HOTEL 1 NIGHT PRICE | D27: 1 | E27: 673 | F27: 0 | G27: T | H27: T | I27: 0 | J27: 0 | K27: 18.44 | L27: 1 | M27: 202402 | N27: 999999 | O27: 3 | P27: 2 | Q27: 1 | R27: 58.5 | S27: 3 | T27: 3
A28: 202406 | B28: 640406 | C28: HOTEL 1 NIGHT PRICE | D28: 4 | E28: 729 | F28: 221 | I28: 1.339 | J28: 0.292 | K28: 18.44 | L28: 1 | M28: 202402 | N28: 999999 | O28: 3 | P28: 1 | Q28: 1 | R28: 165 | S28: 3 | T28: 3
A29: 202406 | B29: 640406 | C29: HOTEL 1 NIGHT PRICE | D29: 1 | E29: 733 | F29: 0 | G29: T | H29: T | I29: 0 | J29: 0 | K29: 18.44 | L29: 1 | M29: 202402 | N29: 999999 | O29: 3 | P29: 1 | Q29: 1 | R29: 156 | S29: 3 | T29: 3
A30: 202406 | B30: 640406 | C30: HOTEL 1 NIGHT PRICE | D30: 4 | E30: 5001 | F30: 202 | I30: 1.413 | J30: 0.345 | K30: 9.36 | L30: 1 | M30: 202402 | N30: 999999 | O30: 8 | P30: 2 | Q30: 1 | R30: 143 | S30: 3 | T30: 8
A31: 202406 | B31: 640406 | C31: HOTEL 1 NIGHT PRICE | D31: 4 | E31: 5003 | F31: 69.49 | I31: 0.946 | J31: -0.056 | K31: 9.36 | L31: 1 | M31: 202402 | N31: 999999 | O31: 8 | P31: 1 | Q31: 1 | R31: 73.49 | S31: 3 | T31: 8
A32: 202406 | B32: 640406 | C32: HOTEL 1 NIGHT PRICE | D32: 1 | E32: 5007 | F32: 0 | G32: T | H32: T | I32: 0 | J32: 0 | K32: 9.89 | L32: 1 | M32: 202402 | N32: 999999 | O32: 9 | P32: 1 | Q32: 1 | R32: 111 | S32: 3 | T32: 9
A33: 202406 | B33: 640406 | C33: HOTEL 1 NIGHT PRICE | D33: 3 | E33: 5028 | F33: 65 | I33: 1.196 | J33: 0.179 | K33: 9.36 | L33: 1 | M33: 202403 | N33: 999999 | O33: 8 | P33: 1 | Q33: 1 | R33: 54.338 | S33: 4 | T33: 8
A34: 202406 | B34: 640406 | C34: HOTEL 1 NIGHT PRICE | D34: 3 | E34: 5035 | F34: 201 | I34: 1.595 | J34: 0.467 | K34: 18.44 | L34: 1 | M34: 202402 | N34: 999999 | O34: 3 | P34: 2 | Q34: 1 | R34: 126 | S34: 3 | T34: 3
A35: 202406 | B35: 640406 | C35: HOTEL 1 NIGHT PRICE | D35: 1 | E35: 5043 | F35: 0 | G35: T | H35: T | I35: 0 | J35: 0 | K35: 8.24 | L35: 1 | M35: 202404 | N35: 999999 | O35: 5 | P35: 2 | Q35: 1 | R35: 109.902 | S35: 4 | T35: 5
A36: 202406 | B36: 640406 | C36: HOTEL 1 NIGHT PRICE | D36: 1 | E36: 5046 | F36: 0 | G36: T | H36: T | I36: 0 | J36: 0 | K36: 18.44 | L36: 1 | M36: 202402 | N36: 999999 | O36: 3 | P36: 2 | Q36: 1 | R36: 120 | S36: 3 | T36: 3
A37: 202406 | B37: 640406 | C37: HOTEL 1 NIGHT PRICE | D37: 1 | E37: 5050 | F37: 0 | G37: T | H37: T | I37: 0 | J37: 0 | K37: 9.75 | L37: 1 | M37: 202402 | N37: 999999 | O37: 2 | P37: 1 | Q37: 1 | R37: 660 | S37: 3 | T37: 2
A38: 202406 | B38: 640406 | C38: HOTEL 1 NIGHT PRICE | D38: 3 | E38: 5084 | F38: 140.99 | I38: 1.282 | J38: 0.248 | K38: 18.44 | L38: 1 | M38: 202402 | N38: 999999 | O38: 3 | P38: 2 | Q38: 1 | R38: 109.99 | S38: 3 | T38: 3
A39: 202406 | B39: 640406 | C39: HOTEL 1 NIGHT PRICE | D39: 3 | E39: 5101 | F39: 170 | I39: 1.314 | J39: 0.273 | K39: 9.89 | L39: 1 | M39: 202403 | N39: 999999 | O39: 9 | P39: 2 | Q39: 1 | R39: 129.399 | S39: 4 | T39: 9
A40: 202406 | B40: 640406 | C40: HOTEL 1 NIGHT PRICE | D40: 3 | E40: 5101 | F40: 57.5 | I40: 1.15 | J40: 0.14 | K40: 3.39 | L40: 1 | M40: 202402 | N40: 999999 | O40: 10 | P40: 2 | Q40: 1 | R40: 50 | S40: 3 | T40: 10
...

Sheet Glossary
A1: Data set that contains raw price quotes collected that underpin the CPI and RPI.
A3: Column Heading | B3: Description
A5: quote_date | B5: year and month of data collection (yyyymm)
A6: item_id | B6: identification of the item collected
A7: validity | B7: validity of the quote (only codes 3 and 4 used, except where indicator_box = 'N')
B8: 3 = Validated by system
B9: 4 = Accepted internally by ONS staff
A10: shop_code | B10: code of shop that the price was collected from
A11: price | B11: price of the item collected in the quote month
A12: indicator_box | B12: indicator used to highlight any item or price change
B13: S = Sale
B14: R = Recovery
B15: M = Missing
B16: C = Comparable
B17: N = Non comparable
B18: T = Temporarily out of stock
B19: X = Comparable item on sale
B20: Z = Non comparable item on sale
A21: price_relative | B21: collected price (current month) divided by base price
A22: stratum_weight | B22: the weight of the stratum that the price quote contributes to
A23: stratum_type | B23: type of stratification used
B24: 0 = not stratified
B25: 1 = region.
B26: 2 = region and shop
B27: 3 =shop
A28: end_date | B28: where end = 999999 price contributed to index for period otherwise price was omitted
A29: region | B29: where the location is
B30: 1 = Catalogue collections
B31: 2 = London
B32: 3 = SE
B33: 4 = SW
B34: 5 = East Anglia
B35: 6 = East Midlands
B36: 7 = West Midlands
B37: 8 = Yorks & Humber
B38: 9 = NW
B39: 10 = North
B40: 11 = Wales
B41: 12 = Scotland
B42: 13 = NI
...
