Workbook
Name _DLX1.INC: HAVER!$A$1:$AK$6

Sheet Chart Data
A1: Mortgage approvals & mortgage rates | E1: Mortgage approvals & mortgage rates | I1: Mortgage approvals & mortgage rates | M1: DMP - prices & wages
B2: Mortgage approvals (LHS) | C2: Average mortgage rate* (RHS) | F2: Mortgage approvals (LHS) | G2: 2 year fixed rate, 75% LTV, lagged one month (RHS) | J2: Mortgage approvals (LHS) | K2: 5 year fixed rate, 75% LTV, lagged one month (RHS) | N2: Prices - past year | O2: Prices - next year | P2: Wages - past year | Q2: Wages - next year
A3: 43101 | B3: =HAVER!B223 -> 65812 | C3: =HAVER!C223 -> 2.02 | E3: 43101 | F3: =HAVER!B223 -> 65812 | G3: =HAVER!G222 -> 1.57 | I3: 43101 | J3: =HAVER!B223 -> 65812 | K3: =HAVER!H222 -> 2.07 | M3: 42736 | N3: =AVERAGE(HAVER!I209:I211) -> #N/A | O3: =AVERAGE(HAVER!J209:J211) -> #N/A
A4: 43132 | B4: =HAVER!B224 -> 63030 | C4: =HAVER!C224 -> 2.04 | E4: 43132 | F4: =HAVER!B224 -> 63030 | G4: =HAVER!G223 -> 1.54 | I4: 43132 | J4: =HAVER!B224 -> 63030 | K4: =HAVER!H223 -> 1.98 | M4: 42767 | N4: =AVERAGE(HAVER!I210:I212) -> #N/A | O4: =AVERAGE(HAVER!J210:J212) -> #N/A
A5: 43160 | B5: =HAVER!B225 -> 63068 | C5: =HAVER!C225 -> 2.05 | E5: 43160 | F5: =HAVER!B225 -> 63068 | G5: =HAVER!G224 -> 1.49 | I5: 43160 | J5: =HAVER!B225 -> 63068 | K5: =HAVER!H224 -> 1.99 | M5: 42795 | N5: =AVERAGE(HAVER!I211:I213) -> 2.5 | O5: =AVERAGE(HAVER!J211:J213) -> 2.5666667
A6: 43191 | B6: =HAVER!B226 -> 63277 | C6: =HAVER!C226 -> 2.08 | E6: 43191 | F6: =HAVER!B226 -> 63277 | G6: =HAVER!G225 -> 1.53 | I6: 43191 | J6: =HAVER!B226 -> 63277 | K6: =HAVER!H225 -> 2.02 | M6: 42826 | N6: =AVERAGE(HAVER!I212:I214) -> 2.7333333 | O6: =AVERAGE(HAVER!J212:J214) -> 2.6333333
A7: 43221 | B7: =HAVER!B227 -> 64951 | C7: =HAVER!C227 -> 2.1 | E7: 43221 | F7: =HAVER!B227 -> 64951 | G7: =HAVER!G226 -> 1.72 | I7: 43221 | J7: =HAVER!B227 -> 64951 | K7: =HAVER!H226 -> 2.01 | M7: 42856 | N7: =AVERAGE(HAVER!I213:I215) -> 2.8666667 | O7: =AVERAGE(HAVER!J213:J215) -> 2.7333333
A8: 43252 | B8: =HAVER!B228 -> 65778 | C8: =HAVER!C228 -> 2.11 | E8: 43252 | F8: =HAVER!B228 -> 65778 | G8: =HAVER!G227 -> 1.74 | I8: 43252 | J8: =HAVER!B228 -> 65778 | K8: =HAVER!H227 -> 2.06 | M8: 42887 | N8: =AVERAGE(HAVER!I214:I216) -> 3.1 | O8: =AVERAGE(HAVER!J214:J216) -> 2.9333333
A9: 43282 | B9: =HAVER!B229 -> 64875 | C9: =HAVER!C229 -> 2.09 | E9: 43282 | F9: =HAVER!B229 -> 64875 | G9: =HAVER!G228 -> 1.74 | I9: 43282 | J9: =HAVER!B229 -> 64875 | K9: =HAVER!H228 -> 2.03 | M9: 42917 | N9: =AVERAGE(HAVER!I215:I217) -> 2.9333333 | O9: =AVERAGE(HAVER!J215:J217) -> 2.9666667
A10: 43313 | B10: =HAVER!B230 -> 66803 | C10: =HAVER!C230 -> 2.11 | E10: 43313 | F10: =HAVER!B230 -> 66803 | G10: =HAVER!G229 -> 1.75 | I10: 43313 | J10: =HAVER!B230 -> 66803 | K10: =HAVER!H229 -> 2.04 | M10: 42948 | N10: =AVERAGE(HAVER!I216:I218) -> 3.1666667 | O10: =AVERAGE(HAVER!J216:J218) -> 3.0333333
A11: 43344 | B11: =HAVER!B231 -> 66132 | C11: =HAVER!C231 -> 2.1 | E11: 43344 | F11: =HAVER!B231 -> 66132 | G11: =HAVER!G230 -> 1.75 | I11: 43344 | J11: =HAVER!B231 -> 66132 | K11: =HAVER!H230 -> 2.03 | M11: 42979 | N11: =AVERAGE(HAVER!I217:I219) -> 3.1 | O11: =AVERAGE(HAVER!J217:J219) -> 3.0333333
A12: 43374 | B12: =HAVER!B232 -> 68298 | C12: =HAVER!C232 -> 2.12 | E12: 43374 | F12: =HAVER!B232 -> 68298 | G12: =HAVER!G231 -> 1.71 | I12: 43374 | J12: =HAVER!B232 -> 68298 | K12: =HAVER!H231 -> 2.01 | M12: 43009 | N12: =AVERAGE(HAVER!I218:I220) -> 2.8333333 | O12: =AVERAGE(HAVER!J218:J220) -> 3
A13: 43405 | B13: =HAVER!B233 -> 65023 | C13: =HAVER!C233 -> 2.13 | E13: 43405 | F13: =HAVER!B233 -> 65023 | G13: =HAVER!G232 -> 1.8 | I13: 43405 | J13: =HAVER!B233 -> 65023 | K13: =HAVER!H232 -> 2.06 | M13: 43040 | N13: =AVERAGE(HAVER!I219:I221) -> 2.7333333 | O13: =AVERAGE(HAVER!J219:J221) -> 2.8666667
A14: 43435 | B14: =HAVER!B234 -> 64398 | C14: =HAVER!C234 -> 2.14 | E14: 43435 | F14: =HAVER!B234 -> 64398 | G14: =HAVER!G233 -> 1.75 | I14: 43435 | J14: =HAVER!B234 -> 64398 | K14: =HAVER!H233 -> 2.02 | M14: 43070 | N14: =AVERAGE(HAVER!I220:I222) -> 2.8666667 | O14: =AVERAGE(HAVER!J220:J222) -> 2.8
... A68: 45078 | B68: =HAVER!B288 -> 53570 | C68: =HAVER!C288 -> 4.63 | E68: 45078 | F68: =HAVER!B288 -> 53570 | G68: =HAVER!G287 -> 4.72 | I68: 45078 | J68: =HAVER!B288 -> 53570 | K68: =HAVER!H287 -> 4.28 | M68: 44713 | N68: =AVERAGE(HAVER!I274:I276) -> 7.0666667 | O68: =AVERAGE(HAVER!J274:J276) -> 6.7333333
A69: 45108 | B69: =HAVER!B289 -> 49273 | C69: =HAVER!C289 -> 4.66 | E69: 45108 | F69: =HAVER!B289 -> 49273 | G69: =HAVER!G288 -> 5.49 | I69: 45108 | J69: =HAVER!B289 -> 49273 | K69: =HAVER!H288 -> 4.95 | M69: 44743 | N69: =AVERAGE(HAVER!I275:I277) -> 7.5666667 | O69: =AVERAGE(HAVER!J275:J277) -> 7.2 | P69: =AVERAGE(HAVER!M275:M277) -> 5.5666667 | Q69: =AVERAGE(HAVER!N275:N277) -> 5.0333333
A70: 45139 | B70: =HAVER!B290 -> 45702 | C70: =HAVER!C290 -> 4.82 | E70: 45139 | F70: =HAVER!B290 -> 45702 | G70: =HAVER!G289 -> 6.22 | I70: 45139 | J70: =HAVER!B290 -> 45702 | K70: =HAVER!H289 -> 5.71 | M70: 44774 | N70: =AVERAGE(HAVER!I276:I278) -> 7.6666667 | O70: =AVERAGE(HAVER!J276:J278) -> 7.4666667 | P70: =AVERAGE(HAVER!M276:M278) -> 5.8666667 | Q70: =AVERAGE(HAVER!N276:N278) -> 5.2666667
A71: 45170 | B71: =HAVER!B291 -> 44370 | C71: =HAVER!C291 -> 5.01 | E71: 45170 | F71: =HAVER!B291 -> 44370 | G71: =HAVER!G290 -> 6.18 | I71: 45170 | J71: =HAVER!B291 -> 44370 | K71: =HAVER!H290 -> 5.53 | M71: 44805 | N71: =AVERAGE(HAVER!I277:I279) -> 7.6666667 | O71: =AVERAGE(HAVER!J277:J279) -> 7.6666667 | P71: =AVERAGE(HAVER!M277:M279) -> 6.1333333 | Q71: =AVERAGE(HAVER!N277:N279) -> 5.5333333
A72: 45200 | B72: =HAVER!B292 -> 48819 | C72: =HAVER!C292 -> 5.25 | E72: 45200 | F72: =HAVER!B292 -> 48819 | G72: =HAVER!G291 -> 5.91 | I72: 45200 | J72: =HAVER!B292 -> 48819 | K72: =HAVER!H291 -> 5.24 | M72: 44835 | N72: =AVERAGE(HAVER!I278:I280) -> 7.6 | O72: =AVERAGE(HAVER!J278:J280) -> 7.6666667 | P72: =AVERAGE(HAVER!M278:M280) -> 6.3333333 | Q72: =AVERAGE(HAVER!N278:N280) -> 5.7333333
A73: 45231 | B73: =HAVER!B293 -> 50407 | C73: =HAVER!C293 -> 5.34 | E73: 45231 | F73: =HAVER!B293 -> 50407 | G73: =HAVER!G292 -> 5.6 | I73: 45231 | J73: =HAVER!B293 -> 50407 | K73: =HAVER!H292 -> 5.02 | M73: 44866 | N73: =AVERAGE(HAVER!I279:I281) -> 7.4666667 | O73: =AVERAGE(HAVER!J279:J281) -> 7.6 | P73: =AVERAGE(HAVER!M279:M281) -> 6.2333333 | Q73: =AVERAGE(HAVER!N279:N281) -> 5.8333333
A74: 45261 | B74: =HAVER!B294 -> 52265 | C74: =HAVER!C294 -> 5.28 | E74: 45261 | F74: =HAVER!B294 -> 52265 | G74: =HAVER!G293 -> 5.28 | I74: 45261 | J74: =HAVER!B294 -> 52265 | K74: =HAVER!H293 -> 4.89 | M74: 44896 | N74: =AVERAGE(HAVER!I280:I282) -> 7.8333333 | O74: =AVERAGE(HAVER!J280:J282) -> 7.6333333 | P74: =AVERAGE(HAVER!M280:M282) -> 6.2666667 | Q74: =AVERAGE(HAVER!N280:N282) -> 5.9666667
A75: 45292 | B75: =HAVER!B295 -> 56087 | C75: =HAVER!C295 -> 5.19 | E75: 45292 | F75: =HAVER!B295 -> 56087 | G75: =HAVER!G294 -> 5.03 | I75: 45292 | J75: =HAVER!B295 -> 56087 | K75: =HAVER!H294 -> 4.68 | M75: 44927 | N75: =AVERAGE(HAVER!I281:I283) -> 7.8666667 | O75: =AVERAGE(HAVER!J281:J283) -> 7.7333333 | P75: =AVERAGE(HAVER!M281:M283) -> 6.3333333 | Q75: =AVERAGE(HAVER!N281:N283) -> 5.9333333
A76: 45323 | B76: =HAVER!B296 -> 60383 | C76: =HAVER!C296 -> 4.9 | E76: 45323 | F76: =HAVER!B296 -> 60383 | G76: =HAVER!G295 -> 4.73 | I76: 45323 | J76: =HAVER!B296 -> 60383 | K76: =HAVER!H295 -> 4.44 | M76: 44958 | N76: =AVERAGE(HAVER!I282:I284) -> 8.0666667 | O76: =AVERAGE(HAVER!J282:J284) -> 7.9333333 | P76: =AVERAGE(HAVER!M282:M284) -> 6.5 | Q76: =AVERAGE(HAVER!N282:N284) -> 5.9333333
A77: 45352 | E77: 45352 | G77: =HAVER!G296 -> 4.77 | I77: 45352 | K77: =HAVER!H296 -> 4.4 | M77: 44986 | N77: =AVERAGE(HAVER!I283:I285) -> 7.8333333 | O77: =AVERAGE(HAVER!J283:J285) -> 7.9333333 | P77: =AVERAGE(HAVER!M283:M285) -> 6.4666667 | Q77: =AVERAGE(HAVER!N283:N285) -> 5.7
M78: 45017 | N78: =AVERAGE(HAVER!I284:I286) -> 7.6666667 | O78: =AVERAGE(HAVER!J284:J286) -> 7.8666667 | P78: =AVERAGE(HAVER!M284:M286) -> 6.5666667 | Q78: =AVERAGE(HAVER!N284:N286) -> 5.6
B79: =CORREL(B59:B76,C59:C76) -> -0.1429568 | E79: Correlation | F79: =CORREL(F59:F76,G59:G76) -> -0.76358432 | J79: =CORREL(J59:J76,K59:K76) -> -0.72443579 | M79: 45047 | N79: =AVERAGE(HAVER!I285:I287) -> 7.6 | O79: =AVERAGE(HAVER!J285:J287) -> 7.7 | P79: =AVERAGE(HAVER!M285:M287) -> 6.6333333 | Q79: =AVERAGE(HAVER!N285:N287) -> 5.4
M80: 45078 | N80: =AVERAGE(HAVER!I286:I288) -> 7.3 | O80: =AVERAGE(HAVER!J286:J288) -> 7.5333333 | P80: =AVERAGE(HAVER!M286:M288) -> 6.8333333 | Q80: =AVERAGE(HAVER!N286:N288) -> 5.3
G81: =G77-G70 -> -1.45 | K81: =K77-K70 -> -1.31 | M81: 45108 | N81: =AVERAGE(HAVER!I287:I289) -> 7.4333333 | O81: =AVERAGE(HAVER!J287:J289) -> 7.4333333 | P81: =AVERAGE(HAVER!M287:M289) -> 6.8666667 | Q81: =AVERAGE(HAVER!N287:N289) -> 5.1666667
M82: 45139 | N82: =AVERAGE(HAVER!I288:I290) -> 7.4 | O82: =AVERAGE(HAVER!J288:J290) -> 7.3666667 | P82: =AVERAGE(HAVER!M288:M290) -> 6.9 | Q82: =AVERAGE(HAVER!N288:N290) -> 5.1
M83: 45170 | N83: =AVERAGE(HAVER!I289:I291) -> 7.4 | O83: =AVERAGE(HAVER!J289:J291) -> 7.4 | P83: =AVERAGE(HAVER!M289:M291) -> 6.9 | Q83: =AVERAGE(HAVER!N289:N291) -> 5.0666667
M84: 45200 | N84: =AVERAGE(HAVER!I290:I292) -> 7.0666667 | O84: =AVERAGE(HAVER!J290:J292) -> 7.3 | P84: =AVERAGE(HAVER!M290:M292) -> 6.9333333 | Q84: =AVERAGE(HAVER!N290:N292) -> 5.1
M85: 45231 | N85: =AVERAGE(HAVER!I291:I293) -> 6.5666667 | O85: =AVERAGE(HAVER!J291:J293) -> 7.0333333 | P85: =AVERAGE(HAVER!M291:M293) -> 6.9666667 | Q85: =AVERAGE(HAVER!N291:N293) -> 5.1333333
M86: 45261 | N86: =AVERAGE(HAVER!I292:I294) -> 5.9 | O86: =AVERAGE(HAVER!J292:J294) -> 6.5333333 | P86: =AVERAGE(HAVER!M292:M294) -> 6.9333333 | Q86: =AVERAGE(HAVER!N292:N294) -> 5.2
M87: 45292 | N87: =AVERAGE(HAVER!I293:I295) -> 5.5666667 | O87: =AVERAGE(HAVER!J293:J295) -> 6.0333333 | P87: =AVERAGE(HAVER!M293:M295) -> 6.8333333 | Q87: =AVERAGE(HAVER!N293:N295) -> 5.2
M88: 45323 | N88: =AVERAGE(HAVER!I294:I296) -> 5.3666667 | O88: =AVERAGE(HAVER!J294:J296) -> 5.6333333 | P88: =AVERAGE(HAVER!M294:M296) -> 6.6666667 | Q88: =AVERAGE(HAVER!N294:N296) -> 5.1333333
M89: 45352 | N89: =AVERAGE(HAVER!I295:I297) -> 5.3333333 | O89: =AVERAGE(HAVER!J295:J297) -> 5.4333333 | P89: =AVERAGE(HAVER!M295:M297) -> 6.3666667 | Q89: =AVERAGE(HAVER!N295:N297) -> 4.9
M90: 45383
M91: 45413
M92: 45444

Sheet HAVER
A1: 200001 !M | B1: USVTVX@UK | C1: UNZ6JM@UK | D1: UNZ6K8@UK | E1: UNZ6KA@UK | F1: UNTLMV@UK | G1: UNBV34@UK | H1: UNBV42@UK | I1: UNVDPR1@UK | J1: UNVDPR3@UK | K1: UNVDPE1@UK | L1: UNVDPE3@UK | M1: UNVDWR@UK | N1: UNVDWE@UK
A2: .DESC | B2: UK: Mortgage Loans Approved: All Lenders: House Purchase (SA, Number) | C2: UK: Banks Wtd Avg Int Rate: Indivs/Indiv Trusts: New Secured Loans (%) | D2: UK: Banks Wtd Avg Int Rate: Indivs/Indiv Trusts: Floating Rate Loans(%) | E2: UK: Banks Wtd Avg Int Rate: Indivs/Indiv Trusts: Fixed Rate Secured Loans (%) | F2: UK: Mortgages: Standard Variable Rate: MFIS ex Central Bank (AVG, %) | G2: UK: Mortgages: Fixed Rates: MFIS ex Central Bank: 2-Year 75% LTV (AVG, %) | H2: UK: Mortgages: Fixed Rates: MFIS ex Central Bank: 5-Year 75% LTV (AVG, %) | I2: UK: BoE DMP: Realized Price Growth Over the Past Year: Single Month (%) | J2: UK: BoE DMP: Realized Price Growth Over the Past Year: 3 Month Average (%) | K2: UK: BoE DMP: Expected Price Growth Over the Next Year: Single Month (%) | L2: UK: BoE DMP: Expected Price Growth Over the Next Year: 3 Month Average (%) | M2: UK: BoE DMP: Realized Wage Growth Over the Past Year: Single Month (%) | N2: UK: BoE DMP: Expected Wage Growth Over the Next Year: Single Month (%)
A3: .T1 | B3: Apr-1993 | C3: Jan-2016 | D3: Jan-2016 | E3: Jan-2016 | F3: Jan-1995 | G3: Jan-1995 | H3: Jan-1995 | I3: Jan-2017 | J3: Jan-2017 | K3: Jan-2017 | L3: Jan-2017 | M3: Aug-2017 | N3: Aug-2017
A4: .TN | B4: Feb-2024 | C4: Feb-2024 | D4: Feb-2024 | E4: Feb-2024 | F4: Feb-2024 | G4: Feb-2024 | H4: Feb-2024 | I4: Mar-2024 | J4: Mar-2024 | K4: Mar-2024 | L4: Mar-2024 | M4: Mar-2024 | N4: Mar-2024
A5: .LSOURCE | B5: Bank of England | C5: Bank of England | D5: Bank of England | E5: Bank of England | F5: Bank of England | G5: Bank of England | H5: Bank of England | I5: Bank of England | J5: Bank of England | K5: Bank of England | L5: Bank of England | M5: Bank of England | N5: Bank of England
A6: .DTLM | B6: Apr-02-2024 09:36 | C6: Apr-02-2024 09:34 | D6: Apr-02-2024 09:34 | E6: Apr-02-2024 09:34 | F6: Mar-07-2024 13:12 | G6: Mar-07-2024 13:12 | H6: Mar-07-2024 13:12 | I6: Apr-04-2024 09:31 | J6: Apr-04-2024 09:31 | K6: Apr-04-2024 09:31 | L6: Apr-04-2024 09:31 | M6: Apr-04-2024 09:31 | N6: Apr-04-2024 09:31
A7: 200001 | B7: 82564 | C7: #N/A | D7: #N/A | E7: #N/A | F7: 7.13 | G7: 6.78 | H7: 7.09 | I7: #N/A | J7: #N/A | K7: #N/A | L7: #N/A | M7: #N/A | N7: #N/A
A8: 200002 | B8: 95885 | C8: #N/A | D8: #N/A | E8: #N/A | F8: 7.38 | G8: 6.79 | H8: 7.11 | I8: #N/A | J8: #N/A | K8: #N/A | L8: #N/A | M8: #N/A | N8: #N/A
A9: 200003 | B9: 96759 | C9: #N/A | D9: #N/A | E9: #N/A | F9: 7.62 | G9: 6.45 | H9: 6.94 | I9: #N/A | J9: #N/A | K9: #N/A | L9: #N/A | M9: #N/A | N9: #N/A
A10: 200004 | B10: 97567 | C10: #N/A | D10: #N/A | E10: #N/A | F10: 7.63 | G10: 6.31 | H10: 6.92 | I10: #N/A | J10: #N/A | K10: #N/A | L10: #N/A | M10: #N/A | N10: #N/A
A11: 200005 | B11: 94084 | C11: #N/A | D11: #N/A | E11: #N/A | F11: 7.64 | G11: 6.39 | H11: 6.9 | I11: #N/A | J11: #N/A | K11: #N/A | L11: #N/A | M11: #N/A | N11: #N/A
A12: 200006 | B12: 92642 | C12: #N/A | D12: #N/A | E12: #N/A | F12: 7.64 | G12: 6.46 | H12: 6.87 | I12: #N/A | J12: #N/A | K12: #N/A | L12: #N/A | M12: #N/A | N12: #N/A
A13: 200007 | B13: 89723 | C13: #N/A | D13: #N/A | E13: #N/A | F13: 7.64 | G13: 6.37 | H13: 6.81 | I13: #N/A | J13: #N/A | K13: #N/A | L13: #N/A | M13: #N/A | N13: #N/A
A14: 200008 | B14: 88465 | C14: #N/A | D14: #N/A | E14: #N/A | F14: 7.63 | G14: 6.35 | H14: 6.76 | I14: #N/A | J14: #N/A | K14: #N/A | L14: #N/A | M14: #N/A | N14: #N/A
A15: 200009 | B15: 93866 | C15: #N/A | D15: #N/A | E15: #N/A | F15: 7.59 | G15: 6.31 | H15: 6.7 | I15: #N/A | J15: #N/A | K15: #N/A | L15: #N/A | M15: #N/A | N15: #N/A
A16: 200010 | B16: 92226 | C16: #N/A | D16: #N/A | E16: #N/A | F16: 7.59 | G16: 6.05 | H16: 6.61 | I16: #N/A | J16: #N/A | K16: #N/A | L16: #N/A | M16: #N/A | N16: #N/A
A17: 200011 | B17: 95118 | C17: #N/A | D17: #N/A | E17: #N/A | F17: 7.59 | G17: 6.06 | H17: 6.58 | I17: #N/A | J17: #N/A | K17: #N/A | L17: #N/A | M17: #N/A | N17: #N/A
A18: 200012 | B18: 103225 | C18: #N/A | D18: #N/A | E18: #N/A | F18: 7.55 | G18: 6.03 | H18: 6.2 | I18: #N/A | J18: #N/A | K18: #N/A | L18: #N/A | M18: #N/A | N18: #N/A
... A198: 201512 | B198: 71354 | C198: #N/A | D198: #N/A | E198: #N/A | F198: 4.49 | G198: 1.9 | H198: 2.75 | I198: #N/A | J198: #N/A | K198: #N/A | L198: #N/A | M198: #N/A | N198: #N/A
A199: 201601 | B199: 72432 | C199: 2.47 | D199: 2.88 | E199: 3.04 | F199: 4.56 | G199: 1.93 | H199: 2.68 | I199: #N/A | J199: #N/A | K199: #N/A | L199: #N/A | M199: #N/A | N199: #N/A
A200: 201602 | B200: 71891 | C200: 2.49 | D200: 2.88 | E200: 3.01 | F200: 4.58 | G200: 1.95 | H200: 2.73 | I200: #N/A | J200: #N/A | K200: #N/A | L200: #N/A | M200: #N/A | N200: #N/A
A201: 201603 | B201: 70735 | C201: 2.47 | D201: 2.88 | E201: 2.99 | F201: 4.57 | G201: 1.9 | H201: 2.7 | I201: #N/A | J201: #N/A | K201: #N/A | L201: #N/A | M201: #N/A | N201: #N/A
A202: 201604 | B202: 68692 | C202: 2.39 | D202: 2.86 | E202: 2.96 | F202: 4.64 | G202: 1.84 | H202: 2.71 | I202: #N/A | J202: #N/A | K202: #N/A | L202: #N/A | M202: #N/A | N202: #N/A
A203: 201605 | B203: 67580 | C203: 2.39 | D203: 2.86 | E203: 2.93 | F203: 4.56 | G203: 1.91 | H203: 2.64 | I203: #N/A | J203: #N/A | K203: #N/A | L203: #N/A | M203: #N/A | N203: #N/A
A204: 201606 | B204: 65660 | C204: 2.39 | D204: 2.85 | E204: 2.91 | F204: 4.52 | G204: 1.75 | H204: 2.54 | I204: #N/A | J204: #N/A | K204: #N/A | L204: #N/A | M204: #N/A | N204: #N/A
A205: 201607 | B205: 62674 | C205: 2.3 | D205: 2.86 | E205: 2.88 | F205: 4.55 | G205: 1.72 | H205: 2.51 | I205: #N/A | J205: #N/A | K205: #N/A | L205: #N/A | M205: #N/A | N205: #N/A
A206: 201608 | B206: 61399 | C206: 2.3 | D206: 2.82 | E206: 2.85 | F206: 4.3 | G206: 1.69 | H206: 2.39 | I206: #N/A | J206: #N/A | K206: #N/A | L206: #N/A | M206: #N/A | N206: #N/A
A207: 201609 | B207: 64320 | C207: 2.25 | D207: 2.62 | E207: 2.83 | F207: 4.24 | G207: 1.59 | H207: 2.34 | I207: #N/A | J207: #N/A | K207: #N/A | L207: #N/A | M207: #N/A | N207: #N/A
A208: 201610 | B208: 67975 | C208: 2.15 | D208: 2.6 | E208: 2.79 | F208: 4.24 | G208: 1.52 | H208: 2.27 | I208: #N/A | J208: #N/A | K208: #N/A | L208: #N/A | M208: #N/A | N208: #N/A
A209: 201611 | B209: 68387 | C209: 2.15 | D209: 2.58 | E209: 2.76 | F209: 4.28 | G209: 1.43 | H209: 2.25 | I209: #N/A | J209: #N/A | K209: #N/A | L209: #N/A | M209: #N/A | N209: #N/A
A210: 201612 | B210: 68395 | C210: 2.14 | D210: 2.58 | E210: 2.73 | F210: 4.23 | G210: 1.45 | H210: 2.26 | I210: #N/A | J210: #N/A | K210: #N/A | L210: #N/A | M210: #N/A | N210: #N/A
A211: 201701 | B211: 68031 | C211: 2.03 | D211: 2.57 | E211: 2.7 | F211: 4.49 | G211: 1.45 | H211: 2.22 | I211: 3.5 | J211: 2.6 | K211: 3.3 | L211: 3 | M211: #N/A | N211: #N/A
A212: 201702 | B212: 68159 | C212: 2.09 | D212: 2.56 | E212: 2.67 | F212: 4.37 | G212: 1.42 | H212: 2.2 | I212: 2 | J212: 2.6 | K212: 2.8 | L212: 2.8 | M212: #N/A | N212: #N/A
A213: 201703 | B213: 68055 | C213: 2.1 | D213: 2.56 | E213: 2.65 | F213: 4.28 | G213: 1.37 | H213: 2.15 | I213: 2 | J213: 2.5 | K213: 2.3 | L213: 2.8 | M213: #N/A | N213: #N/A
A214: 201704 | B214: 67034 | C214: 2.03 | D214: 2.57 | E214: 2.63 | F214: 4.54 | G214: 1.35 | H214: 2.09 | I214: 4.2 | J214: 2.8 | K214: 3.3 | L214: 2.8 | M214: #N/A | N214: #N/A
A215: 201705 | B215: 65730 | C215: 2.05 | D215: 2.55 | E215: 2.6 | F215: 4.23 | G215: 1.49 | H215: 2.03 | I215: 2.4 | J215: 2.9 | K215: 2.4 | L215: 2.7 | M215: #N/A | N215: #N/A
A216: 201706 | B216: 65383 | C216: 2.05 | D216: 2.56 | E216: 2.57 | F216: 4.28 | G216: 1.48 | H216: 1.99 | I216: 2.7 | J216: 3.1 | K216: 2.1 | L216: 2.6 | M216: #N/A | N216: #N/A
A217: 201707 | B217: 68679 | C217: 1.95 | D217: 2.56 | E217: 2.54 | F217: 4.51 | G217: 1.41 | H217: 1.97 | I217: 3.7 | J217: 2.9 | K217: 2.8 | L217: 2.4 | M217: #N/A | N217: #N/A
A218: 201708 | B218: 66982 | C218: 2 | D218: 2.56 | E218: 2.51 | F218: 4.32 | G218: 1.43 | H218: 1.96 | I218: 3.1 | J218: 3.1 | K218: 2.5 | L218: 2.5 | M218: 2.6 | N218: 2.4
A219: 201709 | B219: 66334 | C219: 1.97 | D219: 2.56 | E219: 2.49 | F219: 4.31 | G219: 1.4 | H219: 1.9 | I219: 2.5 | J219: 3.1 | K219: 2.4 | L219: 2.6 | M219: 2.5 | N219: 2.3
...
