Workbook
Name _DLX1.INC: 'Haver Q'!$A$3:$N$8
Name _DLX2.INC: 'Haver M'!$A$3:$G$8

Sheet Old PESR
B2: Old
A3: Date | B3: HH & NPISH saving ratio | C3: Average
A4: 2000 | B4: 7.2 | C4: =AVERAGE($B$44:$B$83) -> 7.865
B5: 7 | C5: =AVERAGE($B$44:$B$83) -> 7.865
B6: 7.7 | C6: =AVERAGE($B$44:$B$83) -> 7.865
B7: 9 | C7: =AVERAGE($B$44:$B$83) -> 7.865
A8: 2001 | B8: 8.7 | C8: =AVERAGE($B$44:$B$83) -> 7.865
B9: 7.7 | C9: =AVERAGE($B$44:$B$83) -> 7.865
B10: 6.9 | C10: =AVERAGE($B$44:$B$83) -> 7.865
B11: 7.4 | C11: =AVERAGE($B$44:$B$83) -> 7.865
A12: 2002 | B12: 7.9 | C12: =AVERAGE($B$44:$B$83) -> 7.865
B13: 8.7 | C13: =AVERAGE($B$44:$B$83) -> 7.865
B14: 7.5 | C14: =AVERAGE($B$44:$B$83) -> 7.865
B15: 6.4 | C15: =AVERAGE($B$44:$B$83) -> 7.865
A16: 2003 | B16: 7 | C16: =AVERAGE($B$44:$B$83) -> 7.865
B17: 6 | C17: =AVERAGE($B$44:$B$83) -> 7.865
B18: 6.2 | C18: =AVERAGE($B$44:$B$83) -> 7.865
B19: 6.9 | C19: =AVERAGE($B$44:$B$83) -> 7.865
A20: 2004 | B20: 7 | C20: =AVERAGE($B$44:$B$83) -> 7.865
B21: 6.6 | C21: =AVERAGE($B$44:$B$83) -> 7.865
B22: 7.5 | C22: =AVERAGE($B$44:$B$83) -> 7.865
B23: 6.8 | C23: =AVERAGE($B$44:$B$83) -> 7.865
A24: 2005 | B24: 6.5 | C24: =AVERAGE($B$44:$B$83) -> 7.865
B25: 7.6 | C25: =AVERAGE($B$44:$B$83) -> 7.865
B26: 6.7 | C26: =AVERAGE($B$44:$B$83) -> 7.865
B27: 6.5 | C27: =AVERAGE($B$44:$B$83) -> 7.865
A28: 2006 | B28: 7.5 | C28: =AVERAGE($B$44:$B$83) -> 7.865
B29: 6.6 | C29: =AVERAGE($B$44:$B$83) -> 7.865
B30: 7.4 | C30: =AVERAGE($B$44:$B$83) -> 7.865
B31: 8.3 | C31: =AVERAGE($B$44:$B$83) -> 7.865
A32: 2007 | B32: 10.1 | C32: =AVERAGE($B$44:$B$83) -> 7.865
B33: 8.9 | C33: =AVERAGE($B$44:$B$83) -> 7.865
B34: 8.5 | C34: =AVERAGE($B$44:$B$83) -> 7.865
B35: 7.5 | C35: =AVERAGE($B$44:$B$83) -> 7.865
A36: 2008 | B36: 6.5 | C36: =AVERAGE($B$44:$B$83) -> 7.865
B37: 8.2 | C37: =AVERAGE($B$44:$B$83) -> 7.865
B38: 7.4 | C38: =AVERAGE($B$44:$B$83) -> 7.865
B39: 10.7 | C39: =AVERAGE($B$44:$B$83) -> 7.865
A40: 2009 | B40: 9.5 | C40: =AVERAGE($B$44:$B$83) -> 7.865
B41: 11.6 | C41: =AVERAGE($B$44:$B$83) -> 7.865
...

Sheet Haver Q
A3: 20001 !Q | B3: NRJSQ@UK
A4: .DESC | B4: UK: HH & NPISH: Saving Ratio (SA, %)
A5: .T1 | B5: Q1-1963
A6: .TN | B6: Q2-2024
A7: .LSOURCE | B7: Office for National Statistics
A8: .DTLM | B8: Sep-30-2024 10:02
A9: 20001 | B9: 7.1
A10: 20002 | B10: 7
A11: 20003 | B11: 7.7
A12: 20004 | B12: 9
A13: 20011 | B13: 8.7
A14: 20012 | B14: 7.7
A15: 20013 | B15: 6.9
A16: 20014 | B16: 7.4
A17: 20021 | B17: 7.9
A18: 20022 | B18: 8.7
A19: 20023 | B19: 7.5
A20: 20024 | B20: 6.4
... A106: 20242 | B106: 9.8

Sheet Haver M
B2: Prices - past year | C2: Prices - next year | D2: Wages - past year | E2: Wages - next year
A3: 201001 !M | B3: UNVDPE1@UK | C3: UNVDPE3@UK | D3: UNVDWR@UK | E3: UNVDWE@UK
A4: .DESC | B4: UK: BoE DMP: Expected Price Growth Over the Next Year: Single Month (%) | C4: UK: BoE DMP: Expected Price Growth Over the Next Year: 3 Month Average (%) | D4: UK: BoE DMP: Realized Wage Growth Over the Past Year: Single Month (%) | E4: UK: BoE DMP: Expected Wage Growth Over the Next Year: Single Month (%)
A5: .T1 | B5: Jan-2017 | C5: Jan-2017 | D5: Aug-2017 | E5: Aug-2017
A6: .TN | B6: Sep-2024 | C6: Sep-2024 | D6: Sep-2024 | E6: Sep-2024
A7: .LSOURCE | B7: Bank of England | C7: Bank of England | D7: Bank of England | E7: Bank of England
A8: .DTLM | B8: Oct-03-2024 09:34 | C8: Oct-03-2024 09:34 | D8: Oct-03-2024 09:34 | E8: Oct-03-2024 09:34
A9: 201001 | B9: #N/A | C9: #N/A | D9: #N/A | E9: #N/A
A10: 201002 | B10: #N/A | C10: #N/A | D10: #N/A | E10: #N/A
A11: 201003 | B11: #N/A | C11: #N/A | D11: #N/A | E11: #N/A
A12: 201004 | B12: #N/A | C12: #N/A | D12: #N/A | E12: #N/A
A13: 201005 | B13: #N/A | C13: #N/A | D13: #N/A | E13: #N/A
A14: 201006 | B14: #N/A | C14: #N/A | D14: #N/A | E14: #N/A
A15: 201007 | B15: #N/A | C15: #N/A | D15: #N/A | E15: #N/A
A16: 201008 | B16: #N/A | C16: #N/A | D16: #N/A | E16: #N/A
A17: 201009 | B17: #N/A | C17: #N/A | D17: #N/A | E17: #N/A
A18: 201010 | B18: #N/A | C18: #N/A | D18: #N/A | E18: #N/A
A19: 201011 | B19: #N/A | C19: #N/A | D19: #N/A | E19: #N/A
A20: 201012 | B20: #N/A | C20: #N/A | D20: #N/A | E20: #N/A
... A92: 201612 | B92: #N/A | C92: #N/A | D92: #N/A | E92: #N/A
A93: 201701 | B93: 3.346 | C93: 2.963 | D93: #N/A | E93: #N/A
A94: 201702 | B94: 2.748 | C94: 2.841 | D94: #N/A | E94: #N/A
A95: 201703 | B95: 2.282 | C95: 2.792 | D95: #N/A | E95: #N/A
A96: 201704 | B96: 3.279 | C96: 2.77 | D96: #N/A | E96: #N/A
A97: 201705 | B97: 2.447 | C97: 2.669 | D97: #N/A | E97: #N/A
A98: 201706 | B98: 2.074 | C98: 2.6 | D98: #N/A | E98: #N/A
A99: 201707 | B99: 2.828 | C99: 2.45 | D99: #N/A | E99: #N/A
A100: 201708 | B100: 2.461 | C100: 2.455 | D100: 2.6 | E100: 2.4
A101: 201709 | B101: 2.394 | C101: 2.561 | D101: 2.5 | E101: 2.3
A102: 201710 | B102: 2.581 | C102: 2.479 | D102: 2.7 | E102: 2.6
A103: 201711 | B103: 2.421 | C103: 2.465 | D103: #N/A | E103: #N/A
A104: 201712 | B104: 2.442 | C104: 2.481 | D104: #N/A | E104: #N/A
A105: 201801 | B105: 2.463 | C105: 2.442 | D105: #N/A | E105: #N/A
A106: 201802 | B106: 2.408 | C106: 2.438 | D106: #N/A | E106: #N/A
A107: 201803 | B107: 2.135 | C107: 2.335 | D107: #N/A | E107: #N/A
A108: 201804 | B108: 2.444 | C108: 2.329 | D108: #N/A | E108: #N/A
A109: 201805 | B109: 1.977 | C109: 2.186 | D109: #N/A | E109: #N/A
A110: 201806 | B110: 2.317 | C110: 2.246 | D110: #N/A | E110: #N/A
A111: 201807 | B111: 2.424 | C111: 2.239 | D111: #N/A | E111: #N/A
A112: 201808 | B112: 2.254 | C112: 2.332 | D112: #N/A | E112: #N/A
...

Sheet Chart data
A1: QNA - PESR (bluebook) | I1: DMP - prices & wages
A3: Date | B3: Bluebook revisions | C3: 2010-2019 average | D3: New estimate of excess savings | E3: Previous estimate | I3: Date | J3: Prices - past year | K3: Prices - next year | L3: Wages - past year | M3: Wages - next year
A4: 2010 | B4: ='Haver Q'!B49 -> 13.2 | C4: =AVERAGE($B$4:$B$43) -> 7.865 | D4: =B4-AVERAGE($B$4:$B$43) -> 5.335 | E4: ='Old PESR'!B44 -> 13.2 | I4: 42736 | J4: =AVERAGE('Haver M'!B91:B93) -> #N/A | K4: =AVERAGE('Haver M'!C91:C93) -> #N/A
B5: ='Haver Q'!B50 -> 11.9 | C5: =AVERAGE($B$4:$B$43) -> 7.865 | D5: =B5-AVERAGE($B$4:$B$43) -> 4.035 | E5: ='Old PESR'!B45 -> 12 | I5: 42767 | J5: =AVERAGE('Haver M'!B92:B94) -> #N/A | K5: =AVERAGE('Haver M'!C92:C94) -> #N/A
B6: ='Haver Q'!B51 -> 11.2 | C6: =AVERAGE($B$4:$B$43) -> 7.865 | D6: =B6-AVERAGE($B$4:$B$43) -> 3.335 | E6: ='Old PESR'!B46 -> 11.2 | I6: 42795 | J6: =AVERAGE('Haver M'!B93:B95) -> 2.792 | K6: =AVERAGE('Haver M'!C93:C95) -> 2.8653333
B7: ='Haver Q'!B52 -> 11.3 | C7: =AVERAGE($B$4:$B$43) -> 7.865 | D7: =B7-AVERAGE($B$4:$B$43) -> 3.435 | E7: ='Old PESR'!B47 -> 11.3 | I7: 42826 | J7: =AVERAGE('Haver M'!B94:B96) -> 2.7696667 | K7: =AVERAGE('Haver M'!C94:C96) -> 2.801
A8: 2011 | B8: ='Haver Q'!B53 -> 9.3 | C8: =AVERAGE($B$4:$B$43) -> 7.865 | D8: =B8-AVERAGE($B$4:$B$43) -> 1.435 | E8: ='Old PESR'!B48 -> 9.3 | I8: 42856 | J8: =AVERAGE('Haver M'!B95:B97) -> 2.6693333 | K8: =AVERAGE('Haver M'!C95:C97) -> 2.7436667
B9: ='Haver Q'!B54 -> 10.7 | C9: =AVERAGE($B$4:$B$43) -> 7.865 | D9: =B9-AVERAGE($B$4:$B$43) -> 2.835 | E9: ='Old PESR'!B49 -> 10.7 | I9: 42887 | J9: =AVERAGE('Haver M'!B96:B98) -> 2.6 | K9: =AVERAGE('Haver M'!C96:C98) -> 2.6796667
B10: ='Haver Q'!B55 -> 9.6 | C10: =AVERAGE($B$4:$B$43) -> 7.865 | D10: =B10-AVERAGE($B$4:$B$43) -> 1.735 | E10: ='Old PESR'!B50 -> 9.6 | I10: 42917 | J10: =AVERAGE('Haver M'!B97:B99) -> 2.4496667 | K10: =AVERAGE('Haver M'!C97:C99) -> 2.573
B11: ='Haver Q'!B56 -> 8.5 | C11: =AVERAGE($B$4:$B$43) -> 7.865 | D11: =B11-AVERAGE($B$4:$B$43) -> 0.635 | E11: ='Old PESR'!B51 -> 8.5 | I11: 42948 | J11: =AVERAGE('Haver M'!B98:B100) -> 2.4543333 | K11: =AVERAGE('Haver M'!C98:C100) -> 2.5016667
A12: 2012 | B12: ='Haver Q'!B57 -> 10.4 | C12: =AVERAGE($B$4:$B$43) -> 7.865 | D12: =B12-AVERAGE($B$4:$B$43) -> 2.535 | E12: ='Old PESR'!B52 -> 10.4 | I12: 42979 | J12: =AVERAGE('Haver M'!B99:B101) -> 2.561 | K12: =AVERAGE('Haver M'!C99:C101) -> 2.4886667
B13: ='Haver Q'!B58 -> 9.6 | C13: =AVERAGE($B$4:$B$43) -> 7.865 | D13: =B13-AVERAGE($B$4:$B$43) -> 1.735 | E13: ='Old PESR'!B53 -> 9.6 | I13: 43009 | J13: =AVERAGE('Haver M'!B100:B102) -> 2.4786667 | K13: =AVERAGE('Haver M'!C100:C102) -> 2.4983333
B14: ='Haver Q'!B59 -> 8.6 | C14: =AVERAGE($B$4:$B$43) -> 7.865 | D14: =B14-AVERAGE($B$4:$B$43) -> 0.735 | E14: ='Old PESR'!B54 -> 8.6 | I14: 43040 | J14: =AVERAGE('Haver M'!B101:B103) -> 2.4653333 | K14: =AVERAGE('Haver M'!C101:C103) -> 2.5016667
B15: ='Haver Q'!B60 -> 7 | C15: =AVERAGE($B$4:$B$43) -> 7.865 | D15: =B15-AVERAGE($B$4:$B$43) -> -0.865 | E15: ='Old PESR'!B55 -> 7 | I15: 43070 | J15: =AVERAGE('Haver M'!B102:B104) -> 2.4813333 | K15: =AVERAGE('Haver M'!C102:C104) -> 2.475
A16: 2013 | B16: ='Haver Q'!B61 -> 6.9 | C16: =AVERAGE($B$4:$B$43) -> 7.865 | D16: =B16-AVERAGE($B$4:$B$43) -> -0.965 | E16: ='Old PESR'!B56 -> 6.9 | I16: 43101 | J16: =AVERAGE('Haver M'!B103:B105) -> 2.442 | K16: =AVERAGE('Haver M'!C103:C105) -> 2.4626667
B17: ='Haver Q'!B62 -> 8.7 | C17: =AVERAGE($B$4:$B$43) -> 7.865 | D17: =B17-AVERAGE($B$4:$B$43) -> 0.835 | E17: ='Old PESR'!B57 -> 8.7 | I17: 43132 | J17: =AVERAGE('Haver M'!B104:B106) -> 2.4376667 | K17: =AVERAGE('Haver M'!C104:C106) -> 2.4536667
B18: ='Haver Q'!B63 -> 8.6 | C18: =AVERAGE($B$4:$B$43) -> 7.865 | D18: =B18-AVERAGE($B$4:$B$43) -> 0.735 | E18: ='Old PESR'!B58 -> 8.6 | I18: 43160 | J18: =AVERAGE('Haver M'!B105:B107) -> 2.3353333 | K18: =AVERAGE('Haver M'!C105:C107) -> 2.405
B19: ='Haver Q'!B64 -> 9.3 | C19: =AVERAGE($B$4:$B$43) -> 7.865 | D19: =B19-AVERAGE($B$4:$B$43) -> 1.435 | E19: ='Old PESR'!B59 -> 9.3 | I19: 43191 | J19: =AVERAGE('Haver M'!B106:B108) -> 2.329 | K19: =AVERAGE('Haver M'!C106:C108) -> 2.3673333
A20: 2014 | B20: ='Haver Q'!B65 -> 8.8 | C20: =AVERAGE($B$4:$B$43) -> 7.865 | D20: =B20-AVERAGE($B$4:$B$43) -> 0.935 | E20: ='Old PESR'!B60 -> 8.8 | I20: 43221 | J20: =AVERAGE('Haver M'!B107:B109) -> 2.1853333 | K20: =AVERAGE('Haver M'!C107:C109) -> 2.2833333
B21: ='Haver Q'!B66 -> 8.2 | C21: =AVERAGE($B$4:$B$43) -> 7.865 | D21: =B21-AVERAGE($B$4:$B$43) -> 0.335 | E21: ='Old PESR'!B61 -> 8.1 | I21: 43252 | J21: =AVERAGE('Haver M'!B108:B110) -> 2.246 | K21: =AVERAGE('Haver M'!C108:C110) -> 2.2536667
B22: ='Haver Q'!B67 -> 6.5 | C22: =AVERAGE($B$4:$B$43) -> 7.865 | D22: =B22-AVERAGE($B$4:$B$43) -> -1.365 | E22: ='Old PESR'!B62 -> 6.5 | I22: 43282 | J22: =AVERAGE('Haver M'!B109:B111) -> 2.2393333 | K22: =AVERAGE('Haver M'!C109:C111) -> 2.2236667
B23: ='Haver Q'!B68 -> 6.6 | C23: =AVERAGE($B$4:$B$43) -> 7.865 | D23: =B23-AVERAGE($B$4:$B$43) -> -1.265 | E23: ='Old PESR'!B63 -> 6.6 | I23: 43313 | J23: =AVERAGE('Haver M'!B110:B112) -> 2.3316667 | K23: =AVERAGE('Haver M'!C110:C112) -> 2.2723333
A24: 2015 | B24: ='Haver Q'!B69 -> 8.1 | C24: =AVERAGE($B$4:$B$43) -> 7.865 | D24: =B24-AVERAGE($B$4:$B$43) -> 0.235 | E24: ='Old PESR'!B64 -> 8.1 | I24: 43344 | J24: =AVERAGE('Haver M'!B111:B113) -> 2.2266667 | K24: =AVERAGE('Haver M'!C111:C113) -> 2.2656667
B25: ='Haver Q'!B70 -> 10.3 | C25: =AVERAGE($B$4:$B$43) -> 7.865 | D25: =B25-AVERAGE($B$4:$B$43) -> 2.435 | E25: ='Old PESR'!B65 -> 10.2 | I25: 43374 | J25: =AVERAGE('Haver M'!B112:B114) -> 2.2823333 | K25: =AVERAGE('Haver M'!C112:C114) -> 2.28
B26: ='Haver Q'!B71 -> 10 | C26: =AVERAGE($B$4:$B$43) -> 7.865 | D26: =B26-AVERAGE($B$4:$B$43) -> 2.135 | E26: ='Old PESR'!B66 -> 10.1 | I26: 43405 | J26: =AVERAGE('Haver M'!B113:B115) -> 2.4266667 | K26: =AVERAGE('Haver M'!C113:C115) -> 2.3116667
B27: ='Haver Q'!B72 -> 10.9 | C27: =AVERAGE($B$4:$B$43) -> 7.865 | D27: =B27-AVERAGE($B$4:$B$43) -> 3.035 | E27: ='Old PESR'!B67 -> 10.9 | I27: 43435 | J27: =AVERAGE('Haver M'!B114:B116) -> 2.4843333 | K27: =AVERAGE('Haver M'!C114:C116) -> 2.3976667
A28: 2016 | B28: ='Haver Q'!B73 -> 8.1 | C28: =AVERAGE($B$4:$B$43) -> 7.865 | D28: =B28-AVERAGE($B$4:$B$43) -> 0.235 | E28: ='Old PESR'!B68 -> 8.1 | I28: 43466 | J28: =AVERAGE('Haver M'!B115:B117) -> 2.4646667 | K28: =AVERAGE('Haver M'!C115:C117) -> 2.4586667
B29: ='Haver Q'!B74 -> 7.1 | C29: =AVERAGE($B$4:$B$43) -> 7.865 | D29: =B29-AVERAGE($B$4:$B$43) -> -0.765 | E29: ='Old PESR'!B69 -> 7.1 | I29: 43497 | J29: =AVERAGE('Haver M'!B116:B118) -> 2.4226667 | K29: =AVERAGE('Haver M'!C116:C118) -> 2.4573333
B30: ='Haver Q'!B75 -> 5.1 | C30: =AVERAGE($B$4:$B$43) -> 7.865 | D30: =B30-AVERAGE($B$4:$B$43) -> -2.765 | E30: ='Old PESR'!B70 -> 5.1 | I30: 43525 | J30: =AVERAGE('Haver M'!B117:B119) -> 2.387 | K30: =AVERAGE('Haver M'!C117:C119) -> 2.425
B31: ='Haver Q'!B76 -> 5.5 | C31: =AVERAGE($B$4:$B$43) -> 7.865 | D31: =B31-AVERAGE($B$4:$B$43) -> -2.365 | E31: ='Old PESR'!B71 -> 5.5 | I31: 43556 | J31: =AVERAGE('Haver M'!B118:B120) -> 2.448 | K31: =AVERAGE('Haver M'!C118:C120) -> 2.4193333
A32: 2017 | B32: ='Haver Q'!B77 -> 4.3 | C32: =AVERAGE($B$4:$B$43) -> 7.865 | D32: =B32-AVERAGE($B$4:$B$43) -> -3.565 | E32: ='Old PESR'!B72 -> 4.3 | I32: 43586 | J32: =AVERAGE('Haver M'!B119:B121) -> 2.3716667 | K32: =AVERAGE('Haver M'!C119:C121) -> 2.4023333
B33: ='Haver Q'!B78 -> 6.4 | C33: =AVERAGE($B$4:$B$43) -> 7.865 | D33: =B33-AVERAGE($B$4:$B$43) -> -1.465 | E33: ='Old PESR'!B73 -> 6.4 | I33: 43617 | J33: =AVERAGE('Haver M'!B120:B122) -> 2.4003333 | K33: =AVERAGE('Haver M'!C120:C122) -> 2.4066667
B34: ='Haver Q'!B79 -> 5.7 | C34: =AVERAGE($B$4:$B$43) -> 7.865 | D34: =B34-AVERAGE($B$4:$B$43) -> -2.165 | E34: ='Old PESR'!B74 -> 5.8 | I34: 43647 | J34: =AVERAGE('Haver M'!B121:B123) -> 2.1946667 | K34: =AVERAGE('Haver M'!C121:C123) -> 2.3223333
B35: ='Haver Q'!B80 -> 4.9 | C35: =AVERAGE($B$4:$B$43) -> 7.865 | D35: =B35-AVERAGE($B$4:$B$43) -> -2.965 | E35: ='Old PESR'!B75 -> 4.8 | I35: 43678 | J35: =AVERAGE('Haver M'!B122:B124) -> 2.1803333 | K35: =AVERAGE('Haver M'!C122:C124) -> 2.2583333
A36: 2018 | B36: ='Haver Q'!B81 -> 5.8 | C36: =AVERAGE($B$4:$B$43) -> 7.865 | D36: =B36-AVERAGE($B$4:$B$43) -> -2.065 | E36: ='Old PESR'!B76 -> 5.8 | I36: 43709 | J36: =AVERAGE('Haver M'!B123:B125) -> 2.2473333 | K36: =AVERAGE('Haver M'!C123:C125) -> 2.2073333
B37: ='Haver Q'!B82 -> 5.3 | C37: =AVERAGE($B$4:$B$43) -> 7.865 | D37: =B37-AVERAGE($B$4:$B$43) -> -2.565 | E37: ='Old PESR'!B77 -> 5.3 | I37: 43739 | J37: =AVERAGE('Haver M'!B124:B126) -> 2.2866667 | K37: =AVERAGE('Haver M'!C124:C126) -> 2.238
B38: ='Haver Q'!B83 -> 5.4 | C38: =AVERAGE($B$4:$B$43) -> 7.865 | D38: =B38-AVERAGE($B$4:$B$43) -> -2.465 | E38: ='Old PESR'!B78 -> 5.4 | I38: 43770 | J38: =AVERAGE('Haver M'!B125:B127) -> 2.2506667 | K38: =AVERAGE('Haver M'!C125:C127) -> 2.2616667
B39: ='Haver Q'!B84 -> 4.8 | C39: =AVERAGE($B$4:$B$43) -> 7.865 | D39: =B39-AVERAGE($B$4:$B$43) -> -3.065 | E39: ='Old PESR'!B79 -> 4.8 | I39: 43800 | J39: =AVERAGE('Haver M'!B126:B128) -> 2.256 | K39: =AVERAGE('Haver M'!C126:C128) -> 2.2646667
A40: 2019 | B40: ='Haver Q'!B85 -> 4.9 | C40: =AVERAGE($B$4:$B$43) -> 7.865 | D40: =B40-AVERAGE($B$4:$B$43) -> -2.965 | E40: ='Old PESR'!B80 -> 4.9 | I40: 43831 | J40: =AVERAGE('Haver M'!B127:B129) -> 2.2243333 | K40: =AVERAGE('Haver M'!C127:C129) -> 2.2436667
B41: ='Haver Q'!B86 -> 5.7 | C41: =AVERAGE($B$4:$B$43) -> 7.865 | D41: =B41-AVERAGE($B$4:$B$43) -> -2.165 | E41: ='Old PESR'!B81 -> 5.8 | I41: 43862 | J41: =AVERAGE('Haver M'!B128:B130) -> 2.206 | K41: =AVERAGE('Haver M'!C128:C130) -> 2.2286667
...
