Workbook
Name _DLX1.INC: HAVERD!$A$1:$AL$6

Sheet Calculations
A1: Interest rates - gilts | G1: Interest rates - market expectations | N1: Interest rates - gilts | R1: Interest rates - short rates
B2: Autumn Statement 2023 | C2: Budget 24* | D2: Budget 24 (2 weeks later than AS timetable) | E2: This week | H2: AS 2023 | I2: Budget 24 (using AS timetable*) | J2: Budget 24 (2 weeks later than AS timetable) | K2: This week | N2: OBR gilt | O2: OE gilt | P2: Impact | R2: OBR RCB | S2: OE RCB | T2: Impact
A3: 2 | B3: {=TRANSPOSE(HAVERD!B308:G308)} -> 4.8863636 | C3: {=TRANSPOSE(HAVERD!B309:G309)} -> 4.2772727 | D3: {=TRANSPOSE(HAVERD!B310:G310)} -> 4.3618182 | E3: {=TRANSPOSE(HAVERD!B311:G311)} -> 4.6 | G3: 2024 | H3: {=TRANSPOSE(HAVERD!H308:L308)} -> 5.1774546 | I3: {=TRANSPOSE(HAVERD!H309:L309)} -> 4.0697532 | J3: {=TRANSPOSE(HAVERD!H310:L310)} -> 4.1738804 | K3: {=TRANSPOSE(HAVERD!H311:L311)} -> 4.4086506 | M3: FY2022/23 | N3: 3.1333693 | O3: =N3 -> 3.1333693 | R3: 2.30915 | S3: =AVERAGE([13]CSV!AG207:AG210) -> 2.3120337
A4: 5 | B4: 4.5309091 | C4: 3.8081818 | D4: 3.8809091 | E4: 4.13 | G4: 2025 | H4: 4.5591652 | I4: 3.405686 | J4: 3.5014337 | K4: 3.8089945 | M4: FY2023/24 | N4: 4.4976273 | O4: =N4-0.5 -> 3.9976273 | P4: ='OBR RR Oct23 - Debt interest'!C8*(O4-N4) -> -553.97924 | R4: 5.0697961 | S4: =R4 -> 5.0697961 | T4: ='OBR RR Oct23 - Debt interest'!C13*(S4-R4) -> 0
A5: 10 | B5: 4.4927273 | C5: 3.8954545 | D5: 3.9227273 | E5: 4.095 | G5: 2026 | H5: 4.2005259 | I5: 3.2337975 | J5: 3.31495 | K5: 3.5581898 | M5: FY2024/25 | N5: 4.522966 | O5: =N5-0.5 -> 4.022966 | P5: ='OBR RR Oct23 - Debt interest'!D9*(O5-N5)+'OBR RR Oct23 - Debt interest'!D8*(O4-N4) -> -1671.1496 | R5: 4.9920467 | S5: =R5+(I3-H3) -> 3.8843453 | T5: ='OBR RR Oct23 - Debt interest'!D14*(S5-R5)+'OBR RR Oct23 - Debt interest'!D13*(S4-R4) -> -11027.415 | V5: =T5+P5 -> -12698.565
A6: 15 | B6: 4.8027273 | C6: 4.2618182 | D6: 4.28 | E6: 4.415 | G6: 2027 | H6: 4.0434114 | I6: 3.2167427 | J6: 3.2791499 | K6: 3.4652737 | M6: FY2025/26 | N6: 4.5462089 | O6: =N6-0.5 -> 4.0462089 | P6: ='OBR RR Oct23 - Debt interest'!E10*(O6-N6)+'OBR RR Oct23 - Debt interest'!E9*(O5-N5)+'OBR RR Oct23 - Debt interest'!E8*(O4-N4) -> -2757.6327 | R6: 4.4425855 | S6: =R6+(I4-H4) -> 3.2891063 | T6: ='OBR RR Oct23 - Debt interest'!E15*(S6-R6)+'OBR RR Oct23 - Debt interest'!E14*(S5-R5) -> -10800.729 | V6: =T6+P6 -> -13558.362
A7: 20 | B7: 4.8945455 | C7: 4.4345455 | D7: 4.4545455 | E7: 4.5675 | G7: 2028 | H7: 3.9784684 | I7: 3.2716812 | J7: 3.3161629 | K7: 3.4655415 | M7: FY2026/27 | N7: 4.6239698 | O7: =N7-0.5 -> 4.1239698 | P7: ='OBR RR Oct23 - Debt interest'!F11*(O7-N7)+'OBR RR Oct23 - Debt interest'!F10*(O6-N6)+'OBR RR Oct23 - Debt interest'!F9*(O5-N5)+'OBR RR Oct23 - Debt interest'!F8*(O4-N4) -> -3619.9077 | R7: 4.1574762 | S7: =R7+(I5-H5) -> 3.1907479 | T7: ='OBR RR Oct23 - Debt interest'!F16*(S7-R7)+'OBR RR Oct23 - Debt interest'!F15*(S6-R6) -> -8447.8421 | V7: =T7+P7 -> -12067.75
A8: 30 | B8: 4.9418182 | C8: 4.5263636 | D8: 4.5436364 | E8: 4.6325 | M8: FY2027/28 | N8: 4.7407155 | O8: =N8-0.5 -> 4.2407155 | P8: ='OBR RR Oct23 - Debt interest'!G12*(O8-N8)+'OBR RR Oct23 - Debt interest'!G11*(O7-N7)+'OBR RR Oct23 - Debt interest'!G10*(O6-N6)+'OBR RR Oct23 - Debt interest'!G9*(O5-N5)+'OBR RR Oct23 - Debt interest'!G8*(O4-N4) -> -4430.3413 | R8: 4.0322902 | S8: =R8+(I6-H6) -> 3.2056215 | T8: ='OBR RR Oct23 - Debt interest'!G17*(S8-R8)+'OBR RR Oct23 - Debt interest'!G16*(S7-R7) -> -6538.3478 | V8: =T8+P8 -> -10968.689
M9: FY2028/29 | N9: 4.8799803 | O9: =N9-0.5 -> 4.3799803 | P9: ='OBR RR Oct23 - Debt interest'!J12*(O9-N9)+'OBR RR Oct23 - Debt interest'!H12*(O8-N8)+'OBR RR Oct23 - Debt interest'!H11*(O7-N7)+'OBR RR Oct23 - Debt interest'!H10*(O6-N6)+'OBR RR Oct23 - Debt interest'!H9*(O5-N5)+'OBR RR Oct23 - Debt interest'!H8*(O4-N4) -> -5341.8895 | R9: 3.9881938 | S9: =R9+(I7-H7) -> 3.2814066 | T9: ='OBR RR Oct23 - Debt interest'!J17*(S9-R9)+'OBR RR Oct23 - Debt interest'!H17*(S8-R8) -> -5041.7454 | V9: =T9+P9 -> -10383.635
A10: Av | B10: =AVERAGE(B3:B8) -> 4.7581818 | C10: =AVERAGE(C3:C8) -> 4.2006061 | D10: =AVERAGE(D3:D8) -> 4.2406061 | E10: =AVERAGE(E3:E8) -> 4.4066667 | H10: =AVERAGE(H3:H8) -> 4.3918051 | I10: =AVERAGE(I3:I8) -> 3.4395321 | J10: =AVERAGE(J3:J8) -> 3.5171154 | K10: =AVERAGE(K3:K8) -> 3.74133
A11: Diff | C11: =C10-$B$10 -> -0.55757576 | D11: =D10-$B$10 -> -0.51757576 | E11: =E10-$B$10 -> -0.35151515 | I11: =I10-$B$10 -> -1.3186497 | J11: =J10-$B$10 -> -1.2410664 | K11: =K10-$B$10 -> -1.0168518

Sheet HAVERD
A1: 20230101 !D | B1: T112G2@INTDAILY | C1: T112G5@INTDAILY | D1: T112GA@INTDAILY | E1: T112GF@INTDAILY | F1: T112GK@INTDAILY | G1: T112GT@INTDAILY | H1: R11212F@INTDAILY | I1: R11224F@INTDAILY | J1: R11236F@INTDAILY | K1: R11248F@INTDAILY | L1: R11260F@INTDAILY | M1: R112I6A@INTDAILY
A2: .DESC | B2: UK: 2-Yr Government Bond Yield (%) | C2: UK: 5-Yr Government Bond Yield (%) | D2: UK: 10-Yr Government Bond Yield (%) | E2: UK: 15-Yr Government Bond Yield (%) | F2: UK: 20-Yr Government Bond Yield (%) | G2: UK: 30-Yr Government Bond Yield (%) | H2: UK: Overnight Index Swap: Forward Yields, 12-Month (% p.a.) | I2: UK: Overnight Index Swap: Forward Yields, 24-Month (% p.a.) | J2: UK: Overnight Index Swap: Forward Yields, 36-Month (% p.a.) | K2: UK: Overnight Index Swap: Forward Yields, 48-Month (% p.a.) | L2: UK: Overnight Index Swap: Forward Yields, 60-Month (% p.a.) | M2: UK: Overnight Index Swap: Forward Yields, 6-Year (% p.a.)
A3: .T1 | B3: 26-Jan-1994 | C3: 03-Jan-1995 | D3: 26-Jan-1994 | E3: 03-Jan-1995 | F3: 03-Jan-1995 | G3: 03-Jan-1995 | H3: 02-Jan-2009 | I3: 02-Jan-2009 | J3: 02-Jan-2009 | K3: 02-Jan-2009 | L3: 02-Jan-2009 | M3: 01-Dec-2021
A4: .TN | B4: 22-Feb-2024 | C4: 22-Feb-2024 | D4: 22-Feb-2024 | E4: 22-Feb-2024 | F4: 22-Feb-2024 | G4: 22-Feb-2024 | H4: 21-Feb-2024 | I4: 21-Feb-2024 | J4: 21-Feb-2024 | K4: 21-Feb-2024 | L4: 21-Feb-2024 | M4: 21-Feb-2024
A5: .LSOURCE | B5: London Stock Exchange Group | C5: London Stock Exchange Group | D5: London Stock Exchange Group | E5: London Stock Exchange Group | F5: London Stock Exchange Group | G5: London Stock Exchange Group | H5: Bank of England | I5: Bank of England | J5: Bank of England | K5: Bank of England | L5: Bank of England | M5: Bank of England
A6: .DTLM | B6: Feb-22-2024 20:52 | C6: Feb-22-2024 20:52 | D6: Feb-22-2024 20:52 | E6: Feb-22-2024 20:52 | F6: Feb-22-2024 20:52 | G6: Feb-22-2024 20:52 | H6: Feb-22-2024 11:23 | I6: Feb-22-2024 11:23 | J6: Feb-22-2024 11:23 | K6: Feb-22-2024 11:23 | L6: Feb-22-2024 11:23 | M6: Feb-22-2024 11:23
A7: 20230102 | B7: #N/A | C7: #N/A | D7: 3.67 | E7: 4 | F7: #N/A | G7: #N/A | H7: #N/A | I7: #N/A | J7: #N/A | K7: #N/A | L7: #N/A | M7: #N/A
A8: 20230103 | B8: 3.57 | C8: 3.61 | D8: 3.65 | E8: 3.98 | F8: 4.03 | G8: 3.95 | H8: 4.6062333 | I8: 4.0860817 | J8: 3.7383644 | K8: 3.5202418 | L8: 3.3603768 | M8: 3.2670637
A9: 20230104 | B9: 3.44 | C9: 3.49 | D9: 3.5 | E9: 3.86 | F9: 3.91 | G9: 3.83 | H9: 4.4897159 | I9: 3.8946255 | J9: 3.5485094 | K9: 3.3581345 | L9: 3.2157631 | M9: 3.1344241
A10: 20230105 | B10: 3.5 | C10: 3.54 | D10: 3.55 | E10: 3.92 | F10: 3.97 | G10: 3.9 | H10: 4.6093366 | I10: 4.0251201 | J10: 3.6258403 | K10: 3.4044061 | L10: 3.248598 | M10: 3.1579104
A11: 20230106 | B11: 3.41 | C11: 3.44 | D11: 3.47 | E11: 3.87 | F11: 3.92 | G11: 3.87 | H11: 4.5135822 | I11: 3.9067508 | J11: 3.5489763 | K11: 3.3517725 | L11: 3.2136096 | M11: 3.1364836
A12: 20230109 | B12: 3.44 | C12: 3.44 | D12: 3.53 | E12: 3.92 | F12: 3.99 | G12: 3.95 | H12: 4.4073146 | I12: 3.8168853 | J12: 3.4943471 | K12: 3.344989 | L12: 3.2567799 | M12: 3.2227345
A13: 20230110 | B13: 3.46 | C13: 3.46 | D13: 3.56 | E13: 3.9 | F13: 3.97 | G13: 3.9 | H13: 4.4532428 | I13: 3.8421403 | J13: 3.5138982 | K13: 3.3666806 | L13: 3.2777326 | M13: 3.2400696
A14: 20230111 | B14: 3.52 | C14: 3.33 | D14: 3.41 | E14: 3.75 | F14: 3.82 | G14: 3.75 | H14: 4.3232654 | I14: 3.6598018 | J14: 3.2991484 | K14: 3.1085172 | L14: 2.9904796 | M14: 2.9381602
A15: 20230112 | B15: 3.41 | C15: 3.22 | D15: 3.32 | E15: 3.67 | F15: 3.74 | G15: 3.68 | H15: 4.2304327 | I15: 3.5443186 | J15: 3.2434023 | K15: 3.1144553 | L15: 3.0281773 | M15: 2.9867674
A16: 20230113 | B16: 3.48 | C16: 3.3 | D16: 3.37 | E16: 3.71 | F16: 3.79 | G16: 3.73 | H16: 4.2881922 | I16: 3.5435797 | J16: 3.2706631 | K16: 3.1708117 | L16: 3.0875293 | M16: 3.0353738
A17: 20230116 | B17: 3.5 | C17: 3.32 | D17: 3.39 | E17: 3.73 | F17: 3.79 | G17: 3.73 | H17: 4.2747053 | I17: 3.542078 | J17: 3.2860175 | K17: 3.1890704 | L17: 3.1073268 | M17: 3.0597315
A18: 20230117 | B18: 3.46 | C18: 3.28 | D18: 3.33 | E18: 3.67 | F18: 3.73 | G18: 3.67 | H18: 4.2581275 | I18: 3.527278 | J18: 3.2329676 | K18: 3.1110108 | L18: 3.0186675 | M18: 2.9668799
A19: 20230118 | B19: 3.48 | C19: 3.26 | D19: 3.31 | E19: 3.65 | F19: 3.72 | G19: 3.67 | H19: 4.2900137 | I19: 3.5371655 | J19: 3.2330216 | K19: 3.0933058 | L19: 2.9859519 | M19: 2.9234031
... A75: 20230406 | B75: 3.33 | C75: 3.24 | D75: 3.41 | E75: 3.69 | F75: 3.74 | G75: 3.75 | H75: 4.158319 | I75: 3.5211395 | J75: 3.3365395 | K75: 3.1897341 | L75: 3.0491198 | M75: 2.95713
A76: 20230407 | B76: #N/A | C76: #N/A | D76: #N/A | E76: #N/A | F76: #N/A | G76: #N/A | H76: #N/A | I76: #N/A | J76: #N/A | K76: #N/A | L76: #N/A | M76: #N/A
A77: 20230410 | B77: 3.36 | C77: 3.26 | D77: #N/A | E77: 3.72 | F77: #N/A | G77: 3.77 | H77: #N/A | I77: #N/A | J77: #N/A | K77: #N/A | L77: #N/A | M77: #N/A
A78: 20230411 | B78: 3.48 | C78: 3.38 | D78: 3.54 | E78: 3.82 | F78: 3.86 | G78: 3.85 | H78: 4.3065134 | I78: 3.6673912 | J78: 3.4384934 | K78: 3.2872516 | L78: 3.1669498 | M78: 3.0930364
A79: 20230412 | B79: 3.52 | C79: 3.41 | D79: 3.57 | E79: 3.85 | F79: 3.9 | G79: 3.89 | H79: 4.3314896 | I79: 3.6943976 | J79: 3.4697311 | K79: 3.3318164 | L79: 3.2106008 | M79: 3.132033
A80: 20230413 | B80: 3.5 | C80: 3.39 | D80: 3.56 | E80: 3.85 | F80: 3.92 | G80: 3.93 | H80: 4.3058688 | I80: 3.6497702 | J80: 3.4739348 | K80: 3.3542761 | L80: 3.2218246 | M80: 3.133631
A81: 20230414 | B81: 3.6 | C81: 3.49 | D81: 3.65 | E81: 3.93 | F81: 4 | G81: 4.01 | H81: 4.3803025 | I81: 3.7827095 | J81: 3.551481 | K81: 3.3722345 | L81: 3.2280545 | M81: 3.1483612
A82: 20230417 | B82: 3.62 | C82: 3.51 | D82: 3.7 | E82: 3.97 | F82: 4.04 | G82: 4.05 | H82: 4.4128215 | I82: 3.7984261 | J82: 3.5516661 | K82: 3.3793774 | L82: 3.2660484 | M82: 3.2154803
A83: 20230418 | B83: 3.69 | C83: 3.58 | D83: 3.75 | E83: 4.02 | F83: 4.08 | G83: 4.1 | H83: 4.5153119 | I83: 3.8540431 | J83: 3.5681877 | K83: 3.4200533 | L83: 3.3183639 | M83: 3.2650511
A84: 20230419 | B84: 3.82 | C84: 3.71 | D84: 3.85 | E84: 4.12 | F84: 4.17 | G84: 4.18 | H84: 4.7060498 | I84: 4.0208502 | J84: 3.6986267 | K84: 3.5281427 | L84: 3.4031273 | M84: 3.3287484
A85: 20230420 | B85: 3.71 | C85: 3.61 | D85: 3.75 | E85: 4.02 | F85: 4.07 | G85: 4.09 | H85: 4.6234793 | I85: 3.901558 | J85: 3.6169639 | K85: 3.433208 | L85: 3.2895766 | M85: 3.2097178
A86: 20230421 | B86: 3.74 | C86: 3.61 | D86: 3.75 | E86: 4.02 | F86: 4.07 | G86: 4.09 | H86: 4.5902956 | I86: 3.9119531 | J86: 3.6309767 | K86: 3.4424543 | L86: 3.30302 | M86: 3.2276621
A87: 20230424 | B87: 3.81 | C87: 3.66 | D87: 3.78 | E87: 4.06 | F87: 4.11 | G87: 4.12 | H87: 4.6552073 | I87: 3.9766732 | J87: 3.6810599 | K87: 3.4826582 | L87: 3.3436555 | M87: 3.2782026
A88: 20230425 | B88: 3.73 | C88: 3.55 | D88: 3.69 | E88: 3.96 | F88: 4.01 | G88: 4.04 | H88: 4.5693727 | I88: 3.8898784 | J88: 3.5795324 | K88: 3.3871226 | L88: 3.2624867 | M88: 3.2031146
A89: 20230426 | B89: 3.77 | C89: 3.61 | D89: 3.74 | E89: 4.02 | F89: 4.08 | G89: 4.1 | H89: 4.5760281 | I89: 3.8704626 | J89: 3.5882628 | K89: 3.4396677 | L89: 3.3302424 | M89: 3.2688646
... A91: 20230428 | B91: 3.78 | C91: 3.61 | D91: 3.72 | E91: 4 | F91: 4.07 | G91: 4.09 | H91: 4.5760379 | I91: 3.9026073 | J91: 3.6412626 | K91: 3.4556032 | L91: 3.3150557 | M91: 3.2404901
A92: 20230501 | B92: 3.78 | C92: 3.61 | D92: #N/A | E92: 4 | F92: 4.07 | G92: 4.09 | H92: #N/A | I92: #N/A | J92: #N/A | K92: #N/A | L92: #N/A | M92: #N/A
A93: 20230502 | B93: 3.73 | C93: 3.54 | D93: 3.66 | E93: 3.94 | F93: 4.02 | G93: 4.05 | H93: 4.5135792 | I93: 3.859902 | J93: 3.5429317 | K93: 3.3629254 | L93: 3.2533834 | M93: 3.2035777
A94: 20230503 | B94: 3.76 | C94: 3.57 | D94: 3.69 | E94: 3.97 | F94: 4.05 | G94: 4.09 | H94: 4.5638913 | I94: 3.8852997 | J94: 3.5623419 | K94: 3.3931169 | L94: 3.282679 | M94: 3.2256626
A95: 20230504 | B95: 3.68 | C95: 3.48 | D95: 3.66 | E95: 3.93 | F95: 4.03 | G95: 4.08 | H95: 4.3394885 | I95: 3.7166109 | J95: 3.5325496 | K95: 3.399807 | L95: 3.297394 | M95: 3.2467831
A96: 20230505 | B96: 3.77 | C96: 3.58 | D96: 3.77 | E96: 4.04 | F96: 4.13 | G96: 4.17 | H96: 4.5183825 | I96: 3.8892196 | J96: 3.6410288 | K96: 3.4875021 | L96: 3.3792269 | M96: 3.3266601
...

Sheet OBR RR Oct23 - Debt interest
A1: Back to notes
A2: Effect of a 1 per cent increase (unless otherwise stated), £ million | B2: Year | C2: 2023-24 | D2: 2024-25 | E2: 2025-26 | F2: 2026-27 | G2: 2027-28 | H2: 2028-29
A3: RPI inflation | B3: 2023-24 | C3: 5877.3244 | D3: 384.73012 | E3: 332.12974 | F3: 351.28212 | G3: 406.41954 | H3: =G3*G3/F3 -> 470.21136
B4: 2024-25 | C4: 0 | D4: 5915.25 | E4: 340.15109 | F4: 359.85677 | G4: 427.83806 | H4: =G4*G3/F3 -> 494.99173
B5: 2025-26 | C5: 0 | D5: 0 | E5: 6220.0791 | F5: 359.67837 | G5: 428.2295 | H5: =G5*G4/F4 -> 509.12722
B6: 2026-27 | C6: 0 | D6: 0 | E6: 0 | F6: 6269.652 | G6: 423.64764 | H6: =G6*H5/G5 -> 503.67979
B7: 2027-28 | C7: 0 | D7: 0 | E7: 0 | F7: 0 | G7: 6621.2918 | H7: =G6*G7/F6 -> 447.40835 | J7: =G7*G7/F6 -> 6992.6536
A8: Gilt rates (long-term interest rates) | B8: 2023-24 | C8: 1107.9585 | D8: 2095.2356 | E8: 2095.2356 | F8: 2095.2356 | G8: 2095.2356 | H8: =G8*G8/F8 -> 2095.2356
B9: 2024-25 | C9: 0 | D9: 1247.0636 | E9: 2340.4324 | F9: 2340.4324 | G9: 2340.4324 | H9: =G9*G8/F8 -> 2340.4324
B10: 2025-26 | C10: 0 | D10: 0 | E10: 1079.5975 | F10: 2010 | G10: 2010 | H10: =G10*G9/F9 -> 2010
B11: 2026-27 | C11: 0 | D11: 0 | E11: 0 | F11: 794.14728 | G11: 1521.7846 | H11: =G11*H10/G10 -> 1521.7846
B12: 2027-28 | C12: 0 | D12: 0 | E12: 0 | F12: 0 | G12: 893.22993 | H12: =G11*G12/F11 -> 1711.6517 | J12: =G12*G12/F11 -> 1004.6747
A13: Short rates (Bank Rate) | B13: 2023-24 | C13: 10801.03 | D13: 296.03495 | E13: 0 | F13: 0 | G13: 0 | H13: 0
B14: 2024-25 | C14: 0 | D14: 9955.2239 | E14: 297.54751 | F14: 0 | G14: 0 | H14: 0
B15: 2025-26 | C15: 0 | D15: 0 | E15: 9077.871 | F15: 298.03182 | G15: 0 | H15: 0
B16: 2026-27 | C16: 0 | D16: 0 | E16: 0 | F16: 8382.9842 | G16: 298.23016 | H16: 0
B17: 2027-28 | C17: 0 | D17: 0 | E17: 0 | F17: 0 | G17: 7560.5136 | H17: =G16*G17/F16 -> 268.97023 | J17: =G17*G17/F16 -> 6818.7371
A18: CGNCR (£1 billion change) | B18: 2023-24 | C18: 16.739096 | D18: 30.148593 | E18: 30.242733 | F18: 31.831503 | G18: 32.585732 | H18: =G18*G18/F18 -> 33.357832
B19: 2024-25 | C19: 0 | D19: 16.484801 | E19: 30.936869 | F19: 32.455939 | G19: 33.177931 | H19: =G19*G18/F18 -> 33.964063
B20: 2025-26 | C20: 0 | D20: 0 | E20: 14.791272 | F20: 33.110969 | G20: 33.802119 | H20: =G20*G19/F19 -> 34.554057
B21: 2026-27 | C21: 0 | D21: 0 | E21: 0 | F21: 14.23342 | G21: 35.180677 | H21: =G21*H20/G20 -> 35.963282
B22: 2027-28 | C22: 0 | D22: 0 | E22: 0 | F22: 0 | G22: 13.247591 | H22: =G21*G22/F21 -> 32.744007 | J22: =G22*G22/F21 -> 12.330041
