Workbook
Name _DLX1.INC: HAVERM!$A$1:$M$6

Sheet Chart Data
A1: Private sector pay growth | F1: HMRC RTI vs AWE
B2: Outturn | C2: BoE forecast (Feb24) | D2: BoE forecast (May24) | G2: Average Weekly Earnings total pay | H2: HMRC median pay | I2: HMRC median of pay growth | J2: ZERO LINE
A3: 44562 | B3: =HAVERM!F151 -> 4.2 | F3: 42005 | G3: =100*((HAVERM!E67/HAVERM!E55)-1) -> 1.5873016 | H3: =100*((HAVERM!C67/HAVERM!C55)-1) -> #N/A | I3: =NA() -> #N/A | J3: 0
A4: 44593 | B4: =HAVERM!F152 -> 4.6 | F4: 42036 | G4: =100*((HAVERM!E68/HAVERM!E56)-1) -> 2.2727273 | H4: =100*((HAVERM!C68/HAVERM!C56)-1) -> #N/A | I4: =NA() -> #N/A | J4: 0
A5: 44621 | B5: =HAVERM!F153 -> 4.9 | F5: 42064 | G5: =100*((HAVERM!E69/HAVERM!E57)-1) -> 2.9612756 | H5: =100*((HAVERM!C69/HAVERM!C57)-1) -> #N/A | I5: =NA() -> #N/A | J5: 0
A6: 44652 | B6: =HAVERM!F154 -> 4.8 | F6: 42095 | G6: =100*((HAVERM!E70/HAVERM!E58)-1) -> 2.7272727 | H6: =100*((HAVERM!C70/HAVERM!C58)-1) -> #N/A | I6: =NA() -> #N/A | J6: 0
A7: 44682 | B7: =HAVERM!F155 -> 5.1 | F7: 42125 | G7: =100*((HAVERM!E71/HAVERM!E59)-1) -> 2.7210884 | H7: =100*((HAVERM!C71/HAVERM!C59)-1) -> #N/A | I7: =NA() -> #N/A | J7: 0
A8: 44713 | B8: =HAVERM!F156 -> 5.4 | F8: 42156 | G8: =100*((HAVERM!E72/HAVERM!E60)-1) -> 2.7210884 | H8: =100*((HAVERM!C72/HAVERM!C60)-1) -> #N/A | I8: =NA() -> #N/A | J8: 0
A9: 44743 | B9: =HAVERM!F157 -> 6 | F9: 42186 | G9: =100*((HAVERM!E73/HAVERM!E61)-1) -> 2.7149321 | H9: =100*((HAVERM!C73/HAVERM!C61)-1) -> 1.3141427 | I9: =100*'27. Median of pay growth (UK)'!B8 -> 2.4889673 | J9: 0
A10: 44774 | B10: =HAVERM!F158 -> 6.2 | F10: 42217 | G10: =100*((HAVERM!E74/HAVERM!E62)-1) -> 2.48307 | H10: =100*((HAVERM!C74/HAVERM!C62)-1) -> 0.93691443 | I10: =100*'27. Median of pay growth (UK)'!B9 -> 2.3484694 | J10: 0
A11: 44805 | B11: =HAVERM!F159 -> 6.6 | F11: 42248 | G11: =100*((HAVERM!E75/HAVERM!E63)-1) -> 2.0224719 | H11: =100*((HAVERM!C75/HAVERM!C63)-1) -> 1.0618364 | I11: =100*'27. Median of pay growth (UK)'!B10 -> 2.3516022 | J11: 0
A12: 44835 | B12: =HAVERM!F160 -> 6.9 | F12: 42278 | G12: =100*((HAVERM!E76/HAVERM!E64)-1) -> 1.5659955 | H12: =100*((HAVERM!C76/HAVERM!C64)-1) -> 1.3084112 | I12: =100*'27. Median of pay growth (UK)'!B11 -> 2.4985884 | J12: 0
A13: 44866 | B13: =HAVERM!F161 -> 7.3 | F13: 42309 | G13: =100*((HAVERM!E77/HAVERM!E65)-1) -> 2.247191 | H13: =100*((HAVERM!C77/HAVERM!C65)-1) -> 1.3681592 | I13: =100*'27. Median of pay growth (UK)'!B12 -> 2.5616065 | J13: 0
A14: 44896 | B14: =HAVERM!F162 -> 7.3 | F14: 42339 | G14: =100*((HAVERM!E78/HAVERM!E66)-1) -> 2.0134228 | H14: =100*((HAVERM!C78/HAVERM!C66)-1) -> 0.86580087 | I14: =100*'27. Median of pay growth (UK)'!B13 -> 2.2366048 | J14: 0
A15: 44927 | B15: =HAVERM!F163 -> 7.1 | F15: 42370 | G15: =100*((HAVERM!E79/HAVERM!E67)-1) -> 2.4553571 | H15: =100*((HAVERM!C79/HAVERM!C67)-1) -> 1.1111111 | I15: =100*'27. Median of pay growth (UK)'!B14 -> 2.393083 | J15: 0
A16: 44958 | B16: =HAVERM!F164 -> 7.1 | F16: 42401 | G16: =100*((HAVERM!E80/HAVERM!E68)-1) -> 2.4444444 | H16: =100*((HAVERM!C80/HAVERM!C68)-1) -> 1.2345679 | I16: =100*'27. Median of pay growth (UK)'!B15 -> 2.4444049 | J16: 0
A17: 44986 | B17: =HAVERM!F165 -> 7.2 | F17: 42430 | G17: =100*((HAVERM!E81/HAVERM!E69)-1) -> 2.2123894 | H17: =100*((HAVERM!C81/HAVERM!C69)-1) -> 1.7305315 | I17: =100*'27. Median of pay growth (UK)'!B16 -> 2.4983053 | J17: 0
A18: 45017 | B18: =HAVERM!F166 -> 7.7 | F18: 42461 | G18: =100*((HAVERM!E82/HAVERM!E70)-1) -> 2.4336283 | H18: =100*((HAVERM!C82/HAVERM!C70)-1) -> 2.354399 | I18: =100*'27. Median of pay growth (UK)'!B17 -> 2.5818764 | J18: 0
A19: 45047 | B19: =HAVERM!F167 -> 7.9 | F19: 42491 | G19: =100*((HAVERM!E83/HAVERM!E71)-1) -> 1.986755 | H19: =100*((HAVERM!C83/HAVERM!C71)-1) -> 2.2910217 | I19: =100*'27. Median of pay growth (UK)'!B18 -> 2.5051779 | J19: 0
A20: 45078 | B20: =HAVERM!F168 -> 8.2 | F20: 42522 | G20: =100*((HAVERM!E84/HAVERM!E72)-1) -> 2.4282561 | H20: =100*((HAVERM!C84/HAVERM!C72)-1) -> 2.3514851 | I20: =100*'27. Median of pay growth (UK)'!B19 -> 2.7992267 | J20: 0
... A28: 45323 | B28: =HAVERM!F176 -> 6 | F28: 42767 | G28: =100*((HAVERM!E92/HAVERM!E80)-1) -> 1.7353579 | H28: =100*((HAVERM!C92/HAVERM!C80)-1) -> 2.2560976 | I28: =100*'27. Median of pay growth (UK)'!B27 -> 2.601075 | J28: 0
A29: 45352 | B29: =HAVERM!F177 -> 5.9 | C29: ='Feb24 MPR - Chart 2.16'!B31 -> 5.7 | D29: ='May24 MPR Chart 3.10'!B15 -> 6 | F29: 42795 | G29: =100*((HAVERM!E93/HAVERM!E81)-1) -> 1.7316017 | H29: =100*((HAVERM!C93/HAVERM!C81)-1) -> 2.4301337 | I29: =100*'27. Median of pay growth (UK)'!B28 -> 2.4728238 | J29: 0
A30: 45383 | F30: 42826 | G30: =100*((HAVERM!E94/HAVERM!E82)-1) -> 1.7278618 | H30: =100*((HAVERM!C94/HAVERM!C82)-1) -> 2.2397094 | I30: =100*'27. Median of pay growth (UK)'!B29 -> 2.5664657 | J30: 0
A31: 45413 | F31: 42856 | G31: =100*((HAVERM!E95/HAVERM!E83)-1) -> 2.3809524 | H31: =100*((HAVERM!C95/HAVERM!C83)-1) -> 2.3002421 | I31: =100*'27. Median of pay growth (UK)'!B30 -> 2.6631735 | J31: 0
A32: 45444 | C32: ='Feb24 MPR - Chart 2.16'!B32 -> 4.7 | D32: ='May24 MPR Chart 3.10'!B16 -> 5.1 | F32: 42887 | G32: =100*((HAVERM!E96/HAVERM!E84)-1) -> 1.9396552 | H32: =100*((HAVERM!C96/HAVERM!C84)-1) -> 2.4183797 | I32: =100*'27. Median of pay growth (UK)'!B31 -> 2.3956532 | J32: 0
A33: 45474 | F33: 42917 | G33: =100*((HAVERM!E97/HAVERM!E85)-1) -> 2.1551724 | H33: =100*((HAVERM!C97/HAVERM!C85)-1) -> 2.0494274 | I33: =100*'27. Median of pay growth (UK)'!B32 -> 2.4104324 | J33: 0
A34: 45505 | F34: 42948 | G34: =100*((HAVERM!E98/HAVERM!E86)-1) -> 2.3706897 | H34: =100*((HAVERM!C98/HAVERM!C86)-1) -> 2.411091 | I34: =100*'27. Median of pay growth (UK)'!B33 -> 2.5656705 | J34: 0
A35: 45536 | C35: ='Feb24 MPR - Chart 2.16'!B33 -> 4.4 | D35: ='May24 MPR Chart 3.10'!B17 -> 4.8 | F35: 42979 | G35: =100*((HAVERM!E99/HAVERM!E87)-1) -> 2.1459227 | H35: =100*((HAVERM!C99/HAVERM!C87)-1) -> 2.4038462 | I35: =100*'27. Median of pay growth (UK)'!B34 -> 2.5122011 | J35: 0
F36: 43009 | G36: =100*((HAVERM!E100/HAVERM!E88)-1) -> 2.3655914 | H36: =100*((HAVERM!C100/HAVERM!C88)-1) -> 2.5856885 | I36: =100*'27. Median of pay growth (UK)'!B35 -> 2.5081779 | J36: 0
F37: 43040 | G37: =100*((HAVERM!E101/HAVERM!E89)-1) -> 2.3554604 | H37: =100*((HAVERM!C101/HAVERM!C89)-1) -> 2.8211285 | I37: =100*'27. Median of pay growth (UK)'!B36 -> 2.6620042 | J37: 0
F38: 43070 | G38: =100*((HAVERM!E102/HAVERM!E90)-1) -> 2.7896996 | H38: =100*((HAVERM!C102/HAVERM!C90)-1) -> 3.177458 | I38: =100*'27. Median of pay growth (UK)'!B37 -> 2.8207472 | J38: 0
F39: 43101 | G39: =100*((HAVERM!E103/HAVERM!E91)-1) -> 2.5641026 | H39: =100*((HAVERM!C103/HAVERM!C91)-1) -> 3.3573141 | I39: =100*'27. Median of pay growth (UK)'!B38 -> 2.9416855 | J39: 0
F40: 43132 | G40: =100*((HAVERM!E104/HAVERM!E92)-1) -> 2.771855 | H40: =100*((HAVERM!C104/HAVERM!C92)-1) -> 3.0411449 | I40: =100*'27. Median of pay growth (UK)'!B39 -> 2.9469417 | J40: 0
F41: 43160 | G41: =100*((HAVERM!E105/HAVERM!E93)-1) -> 2.9787234 | H41: =100*((HAVERM!C105/HAVERM!C93)-1) -> 2.6690391 | I41: =100*'27. Median of pay growth (UK)'!B40 -> 2.9110936 | J41: 0
F42: 43191 | G42: =100*((HAVERM!E106/HAVERM!E94)-1) -> 2.5477707 | H42: =100*((HAVERM!C106/HAVERM!C94)-1) -> 2.4274719 | I42: =100*'27. Median of pay growth (UK)'!B41 -> 2.8498474 | J42: 0
F43: 43221 | G43: =100*((HAVERM!E107/HAVERM!E95)-1) -> 2.7484144 | H43: =100*((HAVERM!C107/HAVERM!C95)-1) -> 3.4911243 | I43: =100*'27. Median of pay growth (UK)'!B42 -> 3.0621081 | J43: 0
F44: 43252 | G44: =100*((HAVERM!E108/HAVERM!E96)-1) -> 2.9598309 | H44: =100*((HAVERM!C108/HAVERM!C96)-1) -> 3.6009445 | I44: =100*'27. Median of pay growth (UK)'!B43 -> 3.1101529 | J44: 0
F45: 43282 | G45: =100*((HAVERM!E109/HAVERM!E97)-1) -> 3.164557 | H45: =100*((HAVERM!C109/HAVERM!C97)-1) -> 3.4258712 | I45: =100*'27. Median of pay growth (UK)'!B44 -> 3.1742204 | J45: 0
F46: 43313 | G46: =100*((HAVERM!E110/HAVERM!E98)-1) -> 3.3684211 | H46: =100*((HAVERM!C110/HAVERM!C98)-1) -> 4.2377869 | I46: =100*'27. Median of pay growth (UK)'!B45 -> 3.425371 | J46: 0
F47: 43344 | G47: =100*((HAVERM!E111/HAVERM!E99)-1) -> 3.1512605 | H47: =100*((HAVERM!C111/HAVERM!C99)-1) -> 3.3450704 | I47: =100*'27. Median of pay growth (UK)'!B46 -> 3.1767408 | J47: 0
...

Sheet HAVERM
A1: 201001 !M | B1: UKSEPPM@UK | C1: UKSEPPD@UK | D1: KAB9@UK | E1: KAI7@UK | F1: KAJ4@UK
A2: .DESC | B2: UK: Mean Monthly Pay: Pay As You Earn Real Time Information [RTI] (SA, Mil.GBP) | C2: UK: Median Monthly Pay: PAYE Real Time Information [RTI] (SA, GBP) | D2: Great Britain: AWE, Total Pay: Whole Economy (SA, GBP) | E2: Great Britain: AWE, Regular Pay: Whole Economy (SA, GBP) | F2: Great Britain: AWE, Regular Pay: Private Sector [3Mo Mvg Avg vs Yr Ago] (SA, %)
A3: .T1 | B3: Jul-2014 | C3: Jul-2014 | D3: Jan-2000 | E3: Jan-2000 | F3: Mar-2001
A4: .TN | B4: Mar-2024 | C4: Apr-2024 | D4: Mar-2024 | E4: Mar-2024 | F4: Mar-2024
A5: .LSOURCE | B5: Office for National Statistics | C5: Office for National Statistics | D5: Office for National Statistics | E5: Office for National Statistics | F5: Office for National Statistics
A6: .DTLM | B6: May-14-2024 07:09 | C6: May-14-2024 07:10 | D6: May-14-2024 07:02 | E6: May-14-2024 07:02 | F6: May-14-2024 07:04
A7: 201001 | B7: #N/A | C7: #N/A | D7: 439 | E7: 417 | F7: 0.5
A8: 201002 | B8: #N/A | C8: #N/A | D8: 446 | E8: 416 | F8: 0.7
A9: 201003 | B9: #N/A | C9: #N/A | D9: 441 | E9: 418 | F9: 1
A10: 201004 | B10: #N/A | C10: #N/A | D10: 441 | E10: 417 | F10: 0.9
A11: 201005 | B11: #N/A | C11: #N/A | D11: 443 | E11: 417 | F11: 0.8
A12: 201006 | B12: #N/A | C12: #N/A | D12: 442 | E12: 418 | F12: 0.6
A13: 201007 | B13: #N/A | C13: #N/A | D13: 443 | E13: 420 | F13: 1
A14: 201008 | B14: #N/A | C14: #N/A | D14: 445 | E14: 421 | F14: 1.6
A15: 201009 | B15: #N/A | C15: #N/A | D15: 446 | E15: 422 | F15: 2
A16: 201010 | B16: #N/A | C16: #N/A | D16: 447 | E16: 422 | F16: 2
A17: 201011 | B17: #N/A | C17: #N/A | D17: 448 | E17: 423 | F17: 2
A18: 201012 | B18: #N/A | C18: #N/A | D18: 449 | E18: 423 | F18: 1.9
... A60: 201406 | B60: #N/A | C60: #N/A | D60: 470 | E60: 441 | F60: 0.8
A61: 201407 | B61: 2189 | C61: 1598 | D61: 468 | E61: 442 | F61: 0.9
A62: 201408 | B62: 2195 | C62: 1601 | D62: 469 | E62: 443 | F62: 1
A63: 201409 | B63: 2197 | C63: 1601 | D63: 473 | E63: 445 | F63: 1.4
A64: 201410 | B64: 2198 | C64: 1605 | D64: 475 | E64: 447 | F64: 1.9
A65: 201411 | B65: 2217 | C65: 1608 | D65: 475 | E65: 445 | F65: 2.1
A66: 201412 | B66: 2240 | C66: 1617 | D66: 478 | E66: 447 | F66: 2
A67: 201501 | B67: 2241 | C67: 1620 | D67: 476 | E67: 448 | F67: 1.9
A68: 201502 | B68: 2234 | C68: 1620 | D68: 478 | E68: 450 | F68: 2.1
A69: 201503 | B69: 2219 | C69: 1618 | D69: 480 | E69: 452 | F69: 2.7
A70: 201504 | B70: 2226 | C70: 1614 | D70: 481 | E70: 452 | F70: 3.1
A71: 201505 | B71: 2219 | C71: 1615 | D71: 482 | E71: 453 | F71: 3.3
A72: 201506 | B72: 2221 | C72: 1616 | D72: 481 | E72: 453 | F72: 3.2
... A177: 202403 | B177: 3185 | C177: 2359 | D177: 682 | E177: 637 | F177: 5.9
A178: 202404 | C178: 2381

Sheet 27. Median of pay growth (UK)
A1: 27. Median of pay growth from PAYE RTI
A2: UK, all industries, seasonally adjusted
A4: Units | B4: %
A5: Additional notes | B5: Median of pay growth is calculated by producing the annual growth in pay for all individuals in our dataset and then selecting the median of those values. Our growth in median pay figures look at the growth in pay over the past year and so compare this month to the same month last year. This means that the median pay growth only considers those employed in both months.
A7: Date | B7: Median of pay growth
A8: July 2015 | B8: 0.024889673
A9: August 2015 | B9: 0.023484694
A10: September 2015 | B10: 0.023516022
A11: October 2015 | B11: 0.024985884
A12: November 2015 | B12: 0.025616065
A13: December 2015 | B13: 0.022366048
A14: January 2016 | B14: 0.02393083
A15: February 2016 | B15: 0.024444049
A16: March 2016 | B16: 0.024983053
A17: April 2016 | B17: 0.025818764
A18: May 2016 | B18: 0.025051779
A19: June 2016 | B19: 0.027992267
... A113: April 2024 | B113: 0.060684051

Sheet Feb24 MPR - Chart 2.16
A1: Section 2: Current economic conditions
A3: Chart 2.16 - Measures of annual private sector wage growth
A5: Date | B5: ONS private sector regular pay | C5: KPMG/REC (advanced 12 months) | D5: HMRC RTI | E5: Indeed | F5: DMP | G5: Agents' pay survey
A6: 44592 | B6: 3.8 | C6: No permission | D6: 6.5 | E6: 4.2 | F6: n.a. | G6: n.a.
A7: 44620 | B7: 4.1 | D7: 6.5 | E7: 4.7 | F7: n.a. | G7: n.a.
A8: 44651 | B8: 4.3 | D8: 6.7 | E8: 5.6 | F8: n.a. | G8: n.a.
A9: 44681 | B9: 4.8 | D9: 6.6 | E9: 6.3 | F9: n.a. | G9: n.a.
A10: 44712 | B10: 5.1 | D10: 6.8 | E10: 6.2 | F10: 5.5 | G10: n.a.
A11: 44742 | B11: 5.4 | D11: 6.9 | E11: 6.2 | F11: 5.6 | G11: n.a.
A12: 44773 | B12: 6 | D12: 7.1 | E12: 5.9 | F12: 5.5 | G12: n.a.
A13: 44804 | B13: 6.2 | D13: 7.1 | E13: 6.1 | F13: 5.8 | G13: n.a.
A14: 44834 | B14: 6.6 | D14: 7.1 | E14: 6.2 | F14: 6.1 | G14: n.a.
A15: 44865 | B15: 6.9 | D15: 7 | E15: 6 | F15: 6.3 | G15: n.a.
A16: 44895 | B16: 7.3 | D16: 6.9 | E16: 5.8 | F16: 6.2 | G16: n.a.
A17: 44926 | B17: 7.3 | D17: 6.9 | E17: 5.9 | F17: 6.3 | G17: n.a.
A18: 44957 | B18: 7.1 | D18: 7.2 | E18: 6.3 | F18: 6.3 | G18: n.a.
A19: 44985 | B19: 7 | D19: 7.4 | E19: 6.5 | F19: 6.5 | G19: n.a.
A20: 45016 | B20: 7.1 | D20: 7.4 | E20: 7 | F20: 6.5 | G20: n.a.
A21: 45046 | B21: 7.7 | D21: 7.3 | E21: 7.5 | F21: 6.6 | G21: n.a.
... A28: 45260 | B28: 6.5 | D28: 6.5 | E28: 6.5 | F28: 7 | G28: n.a.
A29: 45291 | B29: n.a. | D29: 6.3 | E29: 6.5 | F29: 6.9 | G29: n.a.
A30: 45322 | B30: n.a. | D30: n.a. | E30: n.a. | F30: 6.8 | G30: n.a.
A31: 2024 Q1 (Bank staff projection) | B31: 5.7 | D31: n.a. | E31: n.a. | F31: n.a. | G31: n.a.
A32: 2024 Q2 (Bank staff projection) | B32: 4.7 | D32: n.a. | E32: n.a. | F32: n.a. | G32: n.a.
A33: 2024 Q3 (Bank staff projection) | B33: 4.4 | D33: n.a. | E33: n.a. | F33: n.a. | G33: n.a.
A34: 2024 Q4 (Bank staff projection) | B34: 4.8 | D34: n.a. | E34: n.a. | F34: 5.2 | G34: 5.4

Sheet May24 MPR Chart 3.10
A1: Section 3: Developments in the persistence of UK inflation
A3: Chart 3.10 - Projections for private sector regular average weekly earnings four-quarter growth
C5: Swathe of wage models
A6: Date | B6: May MPR | C6: Min | D6: Max
A7: 2022 Q1 | B7: 4.9 | C7: 4.6 | D7: 5.4
A8: 2022 Q2 | B8: 5.4 | C8: 5.3 | D8: 7.1
A9: 2022 Q3 | B9: 6.6 | C9: 5.9 | D9: 8.9
A10: 2022 Q4 | B10: 7.3 | C10: 5.8 | D10: 9.2
A11: 2023 Q1 | B11: 7.2 | C11: 5.1 | D11: 8.5
A12: 2023 Q2 | B12: 8.2 | C12: 4.3 | D12: 7.5
A13: 2023 Q3 | B13: 7.9 | C13: 4.2 | D13: 6.1
A14: 2023 Q4 | B14: 6.2 | C14: 4.1 | D14: 5.2
A15: 2024 Q1 (Bank staff projections) | B15: 6 | C15: 3.7 | D15: 4.6
A16: 2024 Q2 (Bank staff projections) | B16: 5.1 | C16: 3.6 | D16: 4.2
A17: 2024 Q3 (Bank staff projections) | B17: 4.8 | C17: 3.3 | D17: 3.9
A18: 2024 Q4 (Bank staff projections) | B18: 5 | C18: 3.3 | D18: 3.7
... A28: 2027 Q2 (Bank staff projections) | B28: 2.7 | C28: 2.5 | D28: 2.8
