Workbook
Name _DLX1.INC: #REF!
Name _DLX2.INC: HAVER!$A$3:$C$8
Name _DLX3.INC: HAVER!$G$3:$I$8
Name Annual_Data: GMW!$A$1:$A$2
Name Data: [1]sheet0!$C$2

Sheet Chart Data
A4: Date | B4: Mortgage approvals (LHS) | C4: Net mortgage lending (RHS) | F4: Date | G4: BoE (Feb-2024) | H4: BoE (Nov-2023) | I4: Oxford Economics | J4: 2% line
A5: 43466 | B5: =HAVER!B117/1000 -> 65.099 | C5: =HAVER!C117/1000 -> 3.661 | F5: =LEFT(HAVER!G9,4) -> 2019 | G5: =HAVER!H9 -> #N/A | H5: 1.8453383 | I5: =NA() -> #N/A | J5: 2
A6: 43497 | B6: =HAVER!B118/1000 -> 64.339 | C6: =HAVER!C118/1000 -> 3.442 | F6: =LEFT(HAVER!G10,4) -> 2019 | G6: =HAVER!H10 -> #N/A | H6: 2.0188953 | I6: =NA() -> #N/A | J6: 2
A7: 43525 | B7: =HAVER!B119/1000 -> 62.233 | C7: =HAVER!C119/1000 -> 4.076 | F7: =LEFT(HAVER!G11,4) -> 2019 | G7: =HAVER!H11 -> #N/A | H7: 1.8501411 | I7: =NA() -> #N/A | J7: 2
A8: 43556 | B8: =HAVER!B120/1000 -> 65.776 | C8: =HAVER!C120/1000 -> 4.072 | F8: =LEFT(HAVER!G12,4) -> 2019 | G8: =HAVER!H12 -> #N/A | H8: 1.4027436 | I8: =NA() -> #N/A | J8: 2
A9: 43586 | B9: =HAVER!B121/1000 -> 65.419 | C9: =HAVER!C121/1000 -> 3.131 | F9: =LEFT(HAVER!G13,4) -> 2020 | G9: =HAVER!H13 -> #N/A | H9: 1.6557638 | I9: =NA() -> #N/A | J9: 2
A10: 43617 | B10: =HAVER!B122/1000 -> 66.554 | C10: =HAVER!C122/1000 -> 4.018 | F10: =LEFT(HAVER!G14,4) -> 2020 | G10: =HAVER!H14 -> #N/A | H10: 0.68024119 | I10: =NA() -> #N/A | J10: 2
A11: 43647 | B11: =HAVER!B123/1000 -> 67.433 | C11: =HAVER!C123/1000 -> 5.092 | F11: =LEFT(HAVER!G15,4) -> 2020 | G11: =NA() -> #N/A | H11: 0.61570178 | I11: =NA() -> #N/A | J11: 2
A12: 43678 | B12: =HAVER!B124/1000 -> 66.299 | C12: =HAVER!C124/1000 -> 4.113 | F12: =LEFT(HAVER!G16,4) -> 2020 | G12: =NA() -> #N/A | H12: 0.5841379 | I12: =NA() -> #N/A | J12: 2
A13: 43709 | B13: =HAVER!B125/1000 -> 66.349 | C13: =HAVER!C125/1000 -> 4.081 | F13: =LEFT(HAVER!G17,4) -> 2021 | G13: =NA() -> #N/A | H13: 0.64535936 | I13: =NA() -> #N/A | J13: 2
A14: 43739 | B14: =HAVER!B126/1000 -> 66.392 | C14: =HAVER!C126/1000 -> 4.786 | F14: =LEFT(HAVER!G18,4) -> 2021 | G14: =NA() -> #N/A | H14: 2.0270276 | I14: =NA() -> #N/A | J14: 2
A15: 43770 | B15: =HAVER!B127/1000 -> 66.232 | C15: =HAVER!C127/1000 -> 4.283 | F15: =LEFT(HAVER!G19,4) -> 2021 | G15: =NA() -> #N/A | H15: 2.7539788 | I15: =NA() -> #N/A | J15: 2
A16: 43800 | B16: =HAVER!B128/1000 -> 66.912 | C16: =HAVER!C128/1000 -> 4.685 | F16: =LEFT(HAVER!G20,4) -> 2021 | G16: =NA() -> #N/A | H16: 4.8899435 | I16: =NA() -> #N/A | J16: 2
A17: 43831 | B17: =HAVER!B129/1000 -> 69.31 | C17: =HAVER!C129/1000 -> 4.38 | F17: =LEFT(HAVER!G21,4) -> 2022 | G17: =NA() -> #N/A | H17: 6.1984103 | I17: =NA() -> #N/A | J17: 2
A18: 43862 | B18: =HAVER!B130/1000 -> 72.062 | C18: =HAVER!C130/1000 -> 4.574 | F18: =LEFT(HAVER!G22,4) -> 2022 | G18: =NA() -> #N/A | H18: 9.1511767 | I18: =NA() -> #N/A | J18: 2
A19: 43891 | B19: =HAVER!B131/1000 -> 56.441 | C19: =HAVER!C131/1000 -> 4.885 | F19: =LEFT(HAVER!G23,4) -> 2022 | G19: =NA() -> #N/A | H19: 10.005959 | I19: =NA() -> #N/A | J19: 2
A20: 43922 | B20: =HAVER!B132/1000 -> 15.938 | C20: =HAVER!C132/1000 -> 0.036 | F20: =LEFT(HAVER!G24,4) -> 2022 | G20: =NA() -> #N/A | H20: 10.751748 | I20: =NA() -> #N/A | J20: 2
A21: 43952 | B21: =HAVER!B133/1000 -> 9.337 | C21: =HAVER!C133/1000 -> 0.248 | F21: =LEFT(HAVER!G25,4) -> 2023 | G21: =NA() -> #N/A | H21: 10.178266 | I21: =NA() -> #N/A | J21: 2
A22: 43983 | B22: =HAVER!B134/1000 -> 40.246 | C22: =HAVER!C134/1000 -> 1.964 | F22: =LEFT(HAVER!G26,4) -> 2023 | G22: =NA() -> #N/A | H22: 8.439049 | I22: =NA() -> #N/A | J22: 2
A23: 44013 | B23: =HAVER!B135/1000 -> 66.888 | C23: =HAVER!C135/1000 -> 2.844 | F23: =LEFT(HAVER!G27,4) -> 2023 | G23: 6.7136185 | H23: 6.7136185 | I23: =NA() -> #N/A | J23: 2
A24: 44044 | B24: =HAVER!B136/1000 -> 85.648 | C24: =HAVER!C136/1000 -> 3.161 | F24: =LEFT(HAVER!G28,4) -> 2023 | G24: 4.1568272 | H24: =HAVER!I28 -> 4.6 | I24: =(('Model data'!C210/'Model data'!C206)-1)*100 -> 4.1568272 | J24: 2
A25: 44075 | B25: =HAVER!B137/1000 -> 92.647 | C25: =HAVER!C137/1000 -> 5.37 | F25: =LEFT(HAVER!G29,4) -> 2024 | G25: =HAVER!H29 -> 3.6 | H25: =HAVER!I29 -> 4.4 | I25: =(('Model data'!C211/'Model data'!C207)-1)*100 -> 3.7341085 | J25: 2
A26: 44105 | B26: =HAVER!B138/1000 -> 100.856 | C26: =HAVER!C138/1000 -> 5.179 | F26: =LEFT(HAVER!G30,4) -> 2024 | G26: =HAVER!H30 -> 2 | H26: =HAVER!I30 -> 3.6 | I26: =(('Model data'!C212/'Model data'!C208)-1)*100 -> 1.6059762 | J26: 2
A27: 44136 | B27: =HAVER!B139/1000 -> 107.058 | C27: =HAVER!C139/1000 -> 6.91 | F27: =LEFT(HAVER!G31,4) -> 2024 | G27: =HAVER!H31 -> 2.2 | H27: =HAVER!I31 -> 3.3 | I27: =(('Model data'!C213/'Model data'!C209)-1)*100 -> 1.6700152 | J27: 2
A28: 44166 | B28: =HAVER!B140/1000 -> 101.695 | C28: =HAVER!C140/1000 -> 6.602 | F28: =LEFT(HAVER!G32,4) -> 2024 | G28: =HAVER!H32 -> 2.7 | H28: =HAVER!I32 -> 3.1 | I28: =(('Model data'!C214/'Model data'!C210)-1)*100 -> 1.5187165 | J28: 2
A29: 44197 | B29: =HAVER!B141/1000 -> 96.684 | C29: =HAVER!C141/1000 -> 6.149 | F29: =LEFT(HAVER!G33,4) -> 2025 | G29: =HAVER!H33 -> 2.8 | H29: =HAVER!I33 -> 2.5 | I29: =(('Model data'!C215/'Model data'!C211)-1)*100 -> 1.2979329 | J29: 2
A30: 44228 | B30: =HAVER!B142/1000 -> 85.475 | C30: =HAVER!C142/1000 -> 7.859 | F30: =LEFT(HAVER!G34,4) -> 2025 | G30: =HAVER!H34 -> 2.7 | H30: =HAVER!I34 -> 2.1 | I30: =(('Model data'!C216/'Model data'!C212)-1)*100 -> 1.4951386 | J30: 2
A31: 44256 | B31: =HAVER!B143/1000 -> 81.486 | C31: =HAVER!C143/1000 -> 11.44 | F31: =LEFT(HAVER!G35,4) -> 2025 | G31: =HAVER!H35 -> 2.7 | H31: =HAVER!I35 -> 2.1 | I31: =(('Model data'!C217/'Model data'!C213)-1)*100 -> 1.6013396 | J31: 2
A32: 44287 | B32: =HAVER!B144/1000 -> 85.404 | C32: =HAVER!C144/1000 -> 3.023 | F32: =LEFT(HAVER!G36,4) -> 2025 | G32: =HAVER!H36 -> 2.5 | H32: =HAVER!I36 -> 1.9 | I32: =(('Model data'!C218/'Model data'!C214)-1)*100 -> 1.7387358 | J32: 2
A33: 44317 | B33: =HAVER!B145/1000 -> 85.921 | C33: =HAVER!C145/1000 -> 4.498 | F33: =LEFT(HAVER!G37,4) -> 2026 | G33: =HAVER!H37 -> 2.3 | H33: =HAVER!I37 -> 1.9 | I33: =(('Model data'!C219/'Model data'!C215)-1)*100 -> 1.8601907 | J33: 2
A34: 44348 | B34: =HAVER!B146/1000 -> 78.747 | C34: =HAVER!C146/1000 -> 17.129 | F34: =LEFT(HAVER!G38,4) -> 2026 | G34: =HAVER!H38 -> 2.2 | H34: =HAVER!I38 -> 1.7 | I34: =(('Model data'!C220/'Model data'!C216)-1)*100 -> 1.8865412 | J34: 2
A35: 44378 | B35: =HAVER!B147/1000 -> 72.879 | C35: =HAVER!C147/1000 -> -1.727 | F35: =LEFT(HAVER!G39,4) -> 2026 | G35: =HAVER!H39 -> 2.1 | H35: =HAVER!I39 -> 1.6 | I35: =(('Model data'!C221/'Model data'!C217)-1)*100 -> 1.8920136 | J35: 2
A36: 44409 | B36: =HAVER!B148/1000 -> 71.501 | C36: =HAVER!C148/1000 -> 4.292 | F36: =LEFT(HAVER!G40,4) -> 2026 | G36: =HAVER!H40 -> 2 | H36: =HAVER!I40 -> 1.5 | I36: =(('Model data'!C222/'Model data'!C218)-1)*100 -> 1.8879636 | J36: 2
A37: 44440 | B37: =HAVER!B149/1000 -> 70.822 | C37: =HAVER!C149/1000 -> 9.88 | F37: =LEFT(HAVER!G41,4) -> 2027 | G37: =HAVER!H41 -> 1.9 | H37: =NA() -> #N/A | I37: =(('Model data'!C223/'Model data'!C219)-1)*100 -> 1.8842214 | J37: 2
A38: 44470 | B38: =HAVER!B150/1000 -> 68.184 | C38: =HAVER!C150/1000 -> 1.552 | F38: =LEFT(HAVER!G42,4)
A39: 44501 | B39: =HAVER!B151/1000 -> 68.552 | C39: =HAVER!C151/1000 -> 3.601 | F39: =LEFT(HAVER!G43,4)
A40: 44531 | B40: =HAVER!B152/1000 -> 70.99 | C40: =HAVER!C152/1000 -> 4.191 | F40: =LEFT(HAVER!G44,4)
A41: 44562 | B41: =HAVER!B153/1000 -> 73.71 | C41: =HAVER!C153/1000 -> 6.138 | F41: =LEFT(HAVER!G45,4)
A42: 44593 | B42: =HAVER!B154/1000 -> 69.48 | C42: =HAVER!C154/1000 -> 5.109 | F42: =LEFT(HAVER!G46,4)
A43: 44621 | B43: =HAVER!B155/1000 -> 69.639 | C43: =HAVER!C155/1000 -> 7.231 | F43: =LEFT(HAVER!G47,4)
...

Sheet HAVER
A3: 201001 !M | B3: USVTVX@UK | C3: USVTVJ@UK | G3: 20191 !Q | H3: UNPD@UK | I3: UNPD234@UK
A4: .DESC | B4: UK: Mortgage Loans Approved: All Lenders: House Purchase (SA, Number) | C4: UK: Mortgage Lending: Total: Net New Loans (SA, Mil.GBP) | G4: .DESC | H4: UK: BoE CPI Projections Based on Expected Interest Rate: Mode (Y/Y % Chg) | I4: UK: BoE CPI Projections Based on Expected Interest Rate: Mode [Q4-23](Y/Y % Chg)
A5: .T1 | B5: Apr-1993 | C5: Apr-1993 | G5: .T1 | H5: Q1-2024 | I5: Q4-2023
A6: .TN | B6: Dec-2023 | C6: Dec-2023 | G6: .TN | H6: Q1-2027 | I6: Q4-2026
A7: .LSOURCE | B7: Bank of England | C7: Bank of England | G7: .LSOURCE | H7: Bank of England | I7: Discontinued
A8: .DTLM | B8: Jan-30-2024 09:33 | C8: Jan-30-2024 09:33 | G8: .DTLM | H8: Feb-01-2024 12:05 | I8: Nov-02-2023 12:51
A9: 201001 | B9: 46458 | C9: 1066 | G9: 20191 | H9: #N/A | I9: #N/A
A10: 201002 | B10: 47825 | C10: 944 | G10: 20192 | H10: #N/A | I10: #N/A
A11: 201003 | B11: 49165 | C11: 407 | G11: 20193 | H11: #N/A | I11: #N/A
A12: 201004 | B12: 50216 | C12: 79 | G12: 20194 | H12: #N/A | I12: #N/A
A13: 201005 | B13: 50022 | C13: 735 | G13: 20201 | H13: #N/A | I13: #N/A
A14: 201006 | B14: 49446 | C14: 594 | G14: 20202 | H14: #N/A | I14: #N/A
A15: 201007 | B15: 48717 | C15: -251 | G15: 20203 | H15: #N/A | I15: #N/A
A16: 201008 | B16: 47372 | C16: 1345 | G16: 20204 | H16: #N/A | I16: #N/A
A17: 201009 | B17: 46813 | C17: 229 | G17: 20211 | H17: #N/A | I17: #N/A
A18: 201010 | B18: 46869 | C18: 588 | G18: 20212 | H18: #N/A | I18: #N/A
A19: 201011 | B19: 46150 | C19: 467 | G19: 20213 | H19: #N/A | I19: #N/A
A20: 201012 | B20: 41711 | C20: -340 | G20: 20214 | H20: #N/A | I20: #N/A
... A27: 201107 | B27: 50870 | C27: 506 | G27: 20233 | H27: #N/A | I27: #N/A
A28: 201108 | B28: 52915 | C28: 766 | G28: 20234 | H28: #N/A | I28: 4.6
A29: 201109 | B29: 50867 | C29: 461 | G29: 20241 | H29: 3.6 | I29: 4.4
A30: 201110 | B30: 51767 | C30: 1041 | G30: 20242 | H30: 2 | I30: 3.6
A31: 201111 | B31: 52094 | C31: 632 | G31: 20243 | H31: 2.2 | I31: 3.3
A32: 201112 | B32: 51714 | C32: 109 | G32: 20244 | H32: 2.7 | I32: 3.1
A33: 201201 | B33: 55586 | C33: 1754 | G33: 20251 | H33: 2.8 | I33: 2.5
A34: 201202 | B34: 50358 | C34: 934 | G34: 20252 | H34: 2.7 | I34: 2.1
A35: 201203 | B35: 51317 | C35: 1298 | G35: 20253 | H35: 2.7 | I35: 2.1
A36: 201204 | B36: 51924 | C36: 1213 | G36: 20254 | H36: 2.5 | I36: 1.9
A37: 201205 | B37: 49210 | C37: 557 | G37: 20261 | H37: 2.3 | I37: 1.9
A38: 201206 | B38: 47825 | C38: 656 | G38: 20262 | H38: 2.2 | I38: 1.7
A39: 201207 | B39: 47266 | C39: 1003 | G39: 20263 | H39: 2.1 | I39: 1.6
A40: 201208 | B40: 48107 | C40: 339 | G40: 20264 | H40: 2 | I40: 1.5
A41: 201209 | B41: 50348 | C41: 817 | G41: 20271 | H41: 1.9
A42: 201210 | B42: 52280 | C42: 691
A43: 201211 | B43: 53122 | C43: 585
A44: 201212 | B44: 54653 | C44: 987
A45: 201301 | B45: 52284 | C45: 548
A46: 201302 | B46: 52550 | C46: 906
A47: 201303 | B47: 54445 | C47: 597
A48: 201304 | B48: 56101 | C48: 966
...

Sheet Model data
C1: FEB001G.db
C2: UK
C3: CPI
C4: GBR
C5: L
B6: =B318+5 -> 2289 | C6: {=_xlfn.CONCAT(INDEX(GMW!$A$2:$LR$60,MATCH(1,(GMW!$LQ$2:$LQ$60=C$3)*(GMW!$LP$2:$LP$60=C$4),0),$B6-1966),"0",(INDEX(GMW!$A$2:$LR$60,MATCH(1,(GMW!$LQ$2:$LQ$60=C$3)*(GMW!$LP$2:$LP$60=C$4),0),$B6-1965)))} -> 202304
A7: 1973 | B7: 1973 | C7: {=INDEX(GMW!$A$2:$LR$60,MATCH(1,(GMW!$LQ$2:$LQ$60=C$3)*(GMW!$LP$2:$LP$60=C$4),0),$B7-1966)} -> 11.88749
B8: =+B7+1 -> 1974 | C8: {=INDEX(GMW!$A$2:$LR$60,MATCH(1,(GMW!$LQ$2:$LQ$60=C$3)*(GMW!$LP$2:$LP$60=C$4),0),$B8-1966)} -> 12.3046
B9: =+B8+1 -> 1975 | C9: {=INDEX(GMW!$A$2:$LR$60,MATCH(1,(GMW!$LQ$2:$LQ$60=C$3)*(GMW!$LP$2:$LP$60=C$4),0),$B9-1966)} -> 12.51315
B10: =+B9+1 -> 1976 | C10: {=INDEX(GMW!$A$2:$LR$60,MATCH(1,(GMW!$LQ$2:$LQ$60=C$3)*(GMW!$LP$2:$LP$60=C$4),0),$B10-1966)} -> 13.00846
A11: 1974 | B11: =+B10+1 -> 1977 | C11: {=INDEX(GMW!$A$2:$LR$60,MATCH(1,(GMW!$LQ$2:$LQ$60=C$3)*(GMW!$LP$2:$LP$60=C$4),0),$B11-1966)} -> 13.47771
B12: =+B11+1 -> 1978 | C12: {=INDEX(GMW!$A$2:$LR$60,MATCH(1,(GMW!$LQ$2:$LQ$60=C$3)*(GMW!$LP$2:$LP$60=C$4),0),$B12-1966)} -> 14.23371
B13: =+B12+1 -> 1979 | C13: {=INDEX(GMW!$A$2:$LR$60,MATCH(1,(GMW!$LQ$2:$LQ$60=C$3)*(GMW!$LP$2:$LP$60=C$4),0),$B13-1966)} -> 14.57261
B14: =+B13+1 -> 1980 | C14: {=INDEX(GMW!$A$2:$LR$60,MATCH(1,(GMW!$LQ$2:$LQ$60=C$3)*(GMW!$LP$2:$LP$60=C$4),0),$B14-1966)} -> 15.2504
A15: 1975 | B15: =+B14+1 -> 1981 | C15: {=INDEX(GMW!$A$2:$LR$60,MATCH(1,(GMW!$LQ$2:$LQ$60=C$3)*(GMW!$LP$2:$LP$60=C$4),0),$B15-1966)} -> 16.05854
B16: =+B15+1 -> 1982 | C16: {=INDEX(GMW!$A$2:$LR$60,MATCH(1,(GMW!$LQ$2:$LQ$60=C$3)*(GMW!$LP$2:$LP$60=C$4),0),$B16-1966)} -> 17.46627
B17: =+B16+1 -> 1983 | C17: {=INDEX(GMW!$A$2:$LR$60,MATCH(1,(GMW!$LQ$2:$LQ$60=C$3)*(GMW!$LP$2:$LP$60=C$4),0),$B17-1966)} -> 18.22228
B18: =+B17+1 -> 1984 | C18: {=INDEX(GMW!$A$2:$LR$60,MATCH(1,(GMW!$LQ$2:$LQ$60=C$3)*(GMW!$LP$2:$LP$60=C$4),0),$B18-1966)} -> 18.84793
A19: 1976 | B19: =+B18+1 -> 1985 | C19: {=INDEX(GMW!$A$2:$LR$60,MATCH(1,(GMW!$LQ$2:$LQ$60=C$3)*(GMW!$LP$2:$LP$60=C$4),0),$B19-1966)} -> 19.42145
B20: =+B19+1 -> 1986 | C20: {=INDEX(GMW!$A$2:$LR$60,MATCH(1,(GMW!$LQ$2:$LQ$60=C$3)*(GMW!$LP$2:$LP$60=C$4),0),$B20-1966)} -> 20.12532
B21: =+B20+1 -> 1987 | C21: {=INDEX(GMW!$A$2:$LR$60,MATCH(1,(GMW!$LQ$2:$LQ$60=C$3)*(GMW!$LP$2:$LP$60=C$4),0),$B21-1966)} -> 20.59456
B22: =+B21+1 -> 1988 | C22: {=INDEX(GMW!$A$2:$LR$60,MATCH(1,(GMW!$LQ$2:$LQ$60=C$3)*(GMW!$LP$2:$LP$60=C$4),0),$B22-1966)} -> 21.50698
A23: 1977 | B23: =+B22+1 -> 1989 | C23: {=INDEX(GMW!$A$2:$LR$60,MATCH(1,(GMW!$LQ$2:$LQ$60=C$3)*(GMW!$LP$2:$LP$60=C$4),0),$B23-1966)} -> 22.47153
B24: =+B23+1 -> 1990 | C24: {=INDEX(GMW!$A$2:$LR$60,MATCH(1,(GMW!$LQ$2:$LQ$60=C$3)*(GMW!$LP$2:$LP$60=C$4),0),$B24-1966)} -> 23.41002
B25: =+B24+1 -> 1991 | C25: {=INDEX(GMW!$A$2:$LR$60,MATCH(1,(GMW!$LQ$2:$LQ$60=C$3)*(GMW!$LP$2:$LP$60=C$4),0),$B25-1966)} -> 23.82713
B26: =+B25+1 -> 1992 | C26: {=INDEX(GMW!$A$2:$LR$60,MATCH(1,(GMW!$LQ$2:$LQ$60=C$3)*(GMW!$LP$2:$LP$60=C$4),0),$B26-1966)} -> 24.13995
A27: 1978 | B27: =+B26+1 -> 1993 | C27: {=INDEX(GMW!$A$2:$LR$60,MATCH(1,(GMW!$LQ$2:$LQ$60=C$3)*(GMW!$LP$2:$LP$60=C$4),0),$B27-1966)} -> 24.45278
B28: =+B27+1 -> 1994 | C28: {=INDEX(GMW!$A$2:$LR$60,MATCH(1,(GMW!$LQ$2:$LQ$60=C$3)*(GMW!$LP$2:$LP$60=C$4),0),$B28-1966)} -> 25.07844
B29: =+B28+1 -> 1995 | C29: {=INDEX(GMW!$A$2:$LR$60,MATCH(1,(GMW!$LQ$2:$LQ$60=C$3)*(GMW!$LP$2:$LP$60=C$4),0),$B29-1966)} -> 25.46948
B30: =+B29+1 -> 1996 | C30: {=INDEX(GMW!$A$2:$LR$60,MATCH(1,(GMW!$LQ$2:$LQ$60=C$3)*(GMW!$LP$2:$LP$60=C$4),0),$B30-1966)} -> 25.86051
A31: 1979 | B31: =+B30+1 -> 1997 | C31: {=INDEX(GMW!$A$2:$LR$60,MATCH(1,(GMW!$LQ$2:$LQ$60=C$3)*(GMW!$LP$2:$LP$60=C$4),0),$B31-1966)} -> 26.43403
B32: =+B31+1 -> 1998 | C32: {=INDEX(GMW!$A$2:$LR$60,MATCH(1,(GMW!$LQ$2:$LQ$60=C$3)*(GMW!$LP$2:$LP$60=C$4),0),$B32-1966)} -> 27.26824
B33: =+B32+1 -> 1999 | C33: {=INDEX(GMW!$A$2:$LR$60,MATCH(1,(GMW!$LQ$2:$LQ$60=C$3)*(GMW!$LP$2:$LP$60=C$4),0),$B33-1966)} -> 28.91059
B34: =+B33+1 -> 2000 | C34: {=INDEX(GMW!$A$2:$LR$60,MATCH(1,(GMW!$LQ$2:$LQ$60=C$3)*(GMW!$LP$2:$LP$60=C$4),0),$B34-1966)} -> 29.71873
A35: 1980 | B35: =+B34+1 -> 2001 | C35: {=INDEX(GMW!$A$2:$LR$60,MATCH(1,(GMW!$LQ$2:$LQ$60=C$3)*(GMW!$LP$2:$LP$60=C$4),0),$B35-1966)} -> 30.60508
B36: =+B35+1 -> 2002 | C36: {=INDEX(GMW!$A$2:$LR$60,MATCH(1,(GMW!$LQ$2:$LQ$60=C$3)*(GMW!$LP$2:$LP$60=C$4),0),$B36-1966)} -> 32.24743
B37: =+B36+1 -> 2003 | C37: {=INDEX(GMW!$A$2:$LR$60,MATCH(1,(GMW!$LQ$2:$LQ$60=C$3)*(GMW!$LP$2:$LP$60=C$4),0),$B37-1966)} -> 32.9513
B38: =+B37+1 -> 2004 | C38: {=INDEX(GMW!$A$2:$LR$60,MATCH(1,(GMW!$LQ$2:$LQ$60=C$3)*(GMW!$LP$2:$LP$60=C$4),0),$B38-1966)} -> 33.55088
A39: 1981 | B39: =+B38+1 -> 2005 | C39: {=INDEX(GMW!$A$2:$LR$60,MATCH(1,(GMW!$LQ$2:$LQ$60=C$3)*(GMW!$LP$2:$LP$60=C$4),0),$B39-1966)} -> 34.3851
B40: =+B39+1 -> 2006 | C40: {=INDEX(GMW!$A$2:$LR$60,MATCH(1,(GMW!$LQ$2:$LQ$60=C$3)*(GMW!$LP$2:$LP$60=C$4),0),$B40-1966)} -> 36.07959
...

Sheet GMW
A1: Location | B1: Indicator | C1: Scenario | D1: Units | E1: Scale | F1: Measurement | G1: 1973 Q1 | H1: 1973 Q2 | I1: 1973 Q3 | J1: 1973 Q4 | K1: 1974 Q1 | L1: 1974 Q2 | M1: 1974 Q3 | N1: 1974 Q4 | O1: 1975 Q1 | P1: 1975 Q2 | Q1: 1975 Q3 | R1: 1975 Q4 | S1: 1976 Q1 | T1: 1976 Q2 | U1: 1976 Q3 | V1: 1976 Q4 | W1: 1977 Q1 | X1: 1977 Q2 | Y1: 1977 Q3 | Z1: 1977 Q4 | AA1: 1978 Q1 | AB1: 1978 Q2 | AC1: 1978 Q3 | AD1: 1978 Q4 | AE1: 1979 Q1 | AF1: 1979 Q2 | AG1: 1979 Q3 | AH1: 1979 Q4 | AI1: 1980 Q1 | AJ1: 1980 Q2 | AK1: 1980 Q3 | AL1: 1980 Q4 | AM1: 1981 Q1 | AN1: 1981 Q2 | AO1: 1981 Q3 | AP1: 1981 Q4 | AQ1: 1982 Q1 | AR1: 1982 Q2 | AS1: 1982 Q3 | AT1: 1982 Q4 | AU1: 1983 Q1 | AV1: 1983 Q2 | AW1: 1983 Q3 | AX1: 1983 Q4 | AY1: 1984 Q1 | AZ1: 1984 Q2 | BA1: 1984 Q3 | BB1: 1984 Q4 | BC1: 1985 Q1 | BD1: 1985 Q2 | BE1: 1985 Q3 | BF1: 1985 Q4 | BG1: 1986 Q1 | BH1: 1986 Q2 | BI1: 1986 Q3 | BJ1: 1986 Q4 | BK1: 1987 Q1 | BL1: 1987 Q2 | BM1: 1987 Q3 | BN1: 1987 Q4 | BO1: 1988 Q1 | BP1: 1988 Q2 | BQ1: 1988 Q3 | BR1: 1988 Q4 | BS1: 1989 Q1 | BT1: 1989 Q2 | BU1: 1989 Q3 | BV1: 1989 Q4 | BW1: 1990 Q1 | BX1: 1990 Q2 | BY1: 1990 Q3 | BZ1: 1990 Q4 | CA1: 1991 Q1 | CB1: 1991 Q2 | CC1: 1991 Q3 | CD1: 1991 Q4 | CE1: 1992 Q1 | CF1: 1992 Q2 | CG1: 1992 Q3 | CH1: 1992 Q4 | CI1: 1993 Q1 | CJ1: 1993 Q2 | CK1: 1993 Q3 | CL1: 1993 Q4 | CM1: 1994 Q1 | CN1: 1994 Q2 | CO1: 1994 Q3 | CP1: 1994 Q4 | CQ1: 1995 Q1 | CR1: 1995 Q2 | CS1: 1995 Q3 | CT1: 1995 Q4 | CU1: 1996 Q1 | CV1: 1996 Q2 | CW1: 1996 Q3 | CX1: 1996 Q4 | CY1: 1997 Q1 | CZ1: 1997 Q2 | DA1: 1997 Q3 | DB1: 1997 Q4 | DC1: 1998 Q1 | DD1: 1998 Q2 | DE1: 1998 Q3 | DF1: 1998 Q4 | DG1: 1999 Q1 | DH1: 1999 Q2 | DI1: 1999 Q3 | DJ1: 1999 Q4 | DK1: 2000 Q1 | DL1: 2000 Q2 | DM1: 2000 Q3 | DN1: 2000 Q4 | DO1: 2001 Q1 | DP1: 2001 Q2 | DQ1: 2001 Q3 | DR1: 2001 Q4 | DS1: 2002 Q1 | DT1: 2002 Q2 | DU1: 2002 Q3 | DV1: 2002 Q4 | DW1: 2003 Q1 | DX1: 2003 Q2 | DY1: 2003 Q3 | DZ1: 2003 Q4 | EA1: 2004 Q1 | EB1: 2004 Q2 | EC1: 2004 Q3 | ED1: 2004 Q4 | EE1: 2005 Q1 | EF1: 2005 Q2 | EG1: 2005 Q3 | EH1: 2005 Q4 | EI1: 2006 Q1 | EJ1: 2006 Q2 | EK1: 2006 Q3 | EL1: 2006 Q4 | EM1: 2007 Q1 | EN1: 2007 Q2 | EO1: 2007 Q3 | EP1: 2007 Q4 | EQ1: 2008 Q1 | ER1: 2008 Q2 | ES1: 2008 Q3 | ET1: 2008 Q4 | EU1: 2009 Q1 | EV1: 2009 Q2 | EW1: 2009 Q3 | EX1: 2009 Q4 | EY1: 2010 Q1 | EZ1: 2010 Q2 | FA1: 2010 Q3 | FB1: 2010 Q4 | FC1: 2011 Q1 | FD1: 2011 Q2 | FE1: 2011 Q3 | FF1: 2011 Q4 | FG1: 2012 Q1 | FH1: 2012 Q2 | FI1: 2012 Q3 | FJ1: 2012 Q4 | FK1: 2013 Q1 | FL1: 2013 Q2 | FM1: 2013 Q3 | FN1: 2013 Q4 | FO1: 2014 Q1 | FP1: 2014 Q2 | FQ1: 2014 Q3 | FR1: 2014 Q4 | FS1: 2015 Q1 | FT1: 2015 Q2 | FU1: 2015 Q3 | FV1: 2015 Q4 | FW1: 2016 Q1 | FX1: 2016 Q2 | FY1: 2016 Q3 | FZ1: 2016 Q4 | GA1: 2017 Q1 | GB1: 2017 Q2 | GC1: 2017 Q3 | GD1: 2017 Q4 | GE1: 2018 Q1 | GF1: 2018 Q2 | GG1: 2018 Q3 | GH1: 2018 Q4 | GI1: 2019 Q1 | GJ1: 2019 Q2 | GK1: 2019 Q3 | GL1: 2019 Q4 | GM1: 2020 Q1 | GN1: 2020 Q2 | GO1: 2020 Q3 | GP1: 2020 Q4 | GQ1: 2021 Q1 | GR1: 2021 Q2 | GS1: 2021 Q3 | GT1: 2021 Q4 | GU1: 2022 Q1 | GV1: 2022 Q2 | GW1: 2022 Q3 | GX1: 2022 Q4 | GY1: 2023 Q1 | GZ1: 2023 Q2 | HA1: 2023 Q3 | HB1: 2023 Q4 | HC1: 2024 Q1 | HD1: 2024 Q2 | HE1: 2024 Q3 | HF1: 2024 Q4 | HG1: 2025 Q1 | HH1: 2025 Q2 | HI1: 2025 Q3 | HJ1: 2025 Q4 | HK1: 2026 Q1 | HL1: 2026 Q2 | HM1: 2026 Q3 | HN1: 2026 Q4 | HO1: 2027 Q1 | HP1: 2027 Q2 | HQ1: 2027 Q3 | HR1: 2027 Q4 | HS1: 2028 Q1 | HT1: 2028 Q2 | HU1: 2028 Q3 | HV1: 2028 Q4 | HW1: 2029 Q1 | HX1: 2029 Q2 | HY1: 2029 Q3 | HZ1: 2029 Q4 | IA1: 2030 Q1 | IB1: 2030 Q2 | IC1: 2030 Q3 | ID1: 2030 Q4 | IE1: 2031 Q1 | IF1: 2031 Q2 | IG1: 2031 Q3 | IH1: 2031 Q4 | II1: 2032 Q1 | IJ1: 2032 Q2 | IK1: 2032 Q3 | IL1: 2032 Q4 | IM1: 2033 Q1 | IN1: 2033 Q2 | IO1: 2033 Q3 | IP1: 2033 Q4 | IQ1: 2034 Q1 | IR1: 2034 Q2 | IS1: 2034 Q3 | IT1: 2034 Q4 | IU1: 2035 Q1 | IV1: 2035 Q2 | IW1: 2035 Q3 | IX1: 2035 Q4 | IY1: 2036 Q1 | IZ1: 2036 Q2 | JA1: 2036 Q3 | JB1: 2036 Q4 | JC1: 2037 Q1 | JD1: 2037 Q2 | JE1: 2037 Q3 | JF1: 2037 Q4 | JG1: 2038 Q1 | JH1: 2038 Q2 | JI1: 2038 Q3 | JJ1: 2038 Q4 | JK1: 2039 Q1 | JL1: 2039 Q2 | JM1: 2039 Q3 | JN1: 2039 Q4 | JO1: 2040 Q1 | JP1: 2040 Q2 | JQ1: 2040 Q3 | JR1: 2040 Q4 | JS1: 2041 Q1 | JT1: 2041 Q2 | JU1: 2041 Q3 | JV1: 2041 Q4 | JW1: 2042 Q1 | JX1: 2042 Q2 | JY1: 2042 Q3 | JZ1: 2042 Q4 | KA1: 2043 Q1 | KB1: 2043 Q2 | KC1: 2043 Q3 | KD1: 2043 Q4 | KE1: 2044 Q1 | KF1: 2044 Q2 | KG1: 2044 Q3 | KH1: 2044 Q4 | KI1: 2045 Q1 | KJ1: 2045 Q2 | KK1: 2045 Q3 | KL1: 2045 Q4 | KM1: 2046 Q1 | KN1: 2046 Q2 | KO1: 2046 Q3 | KP1: 2046 Q4 | KQ1: 2047 Q1 | KR1: 2047 Q2 | KS1: 2047 Q3 | KT1: 2047 Q4 | KU1: 2048 Q1 | KV1: 2048 Q2 | KW1: 2048 Q3 | KX1: 2048 Q4 | KY1: 2049 Q1 | KZ1: 2049 Q2 | LA1: 2049 Q3 | LB1: 2049 Q4 | LC1: 2050 Q1 | LD1: 2050 Q2 | LE1: 2050 Q3 | LF1: 2050 Q4 | LG1: Source | LH1: Seasonally adjusted | LI1: Base year price | LJ1: Base year index | LK1: Historical end year | LL1: Historical end quarter | LM1: Date of last update | LN1: Source details | LO1: Additional source details | LP1: Location code | LQ1: Indicator code | LR1: Databank code
A2: United Kingdom | B2: Consumer price index | C2: FEB001G | D2: Index | E2: NA | F2: Level | G2: 11.88749 | H2: 12.3046 | I2: 12.51315 | J2: 13.00846 | K2: 13.47771 | L2: 14.23371 | M2: 14.57261 | N2: 15.2504 | O2: 16.05854 | P2: 17.46627 | Q2: 18.22228 | R2: 18.84793 | S2: 19.42145 | T2: 20.12532 | U2: 20.59456 | V2: 21.50698 | W2: 22.47153 | X2: 23.41002 | Y2: 23.82713 | Z2: 24.13995 | AA2: 24.45278 | AB2: 25.07844 | AC2: 25.46948 | AD2: 25.86051 | AE2: 26.43403 | AF2: 27.26824 | AG2: 28.91059 | AH2: 29.71873 | AI2: 30.60508 | AJ2: 32.24743 | AK2: 32.9513 | AL2: 33.55088 | AM2: 34.3851 | AN2: 36.07959 | AO2: 36.73131 | AP2: 37.43518 | AQ2: 37.87835 | AR2: 39.1818 | AS2: 39.41642 | AT2: 39.88567 | AU2: 40.17243 | AV2: 40.85022 | AW2: 41.2934 | AX2: 41.76264 | AY2: 41.86692 | AZ2: 42.77934 | BA2: 42.98789 | BB2: 43.43106 | BC2: 43.87423 | BD2: 44.9952 | BE2: 45.12555 | BF2: 45.49052 | BG2: 45.64693 | BH2: 46.3508 | BI2: 46.53328 | BJ2: 46.92432 | BK2: 47.23714 | BL2: 47.83673 | BM2: 47.88887 | BN2: 48.43632 | BO2: 48.56667 | BP2: 49.5 | BQ2: 49.9 | BR2: 50.46667 | BS2: 51 | BT2: 52.13334 | BU2: 52.46667 | BV2: 53.26667 | BW2: 53.93333 | BX2: 55.6 | BY2: 56.4 | BZ2: 57.46667 | CA2: 57.66667 | CB2: 60.26667 | CC2: 60.83333 | CD2: 61.46667 | CE2: 61.7 | CF2: 62.83333 | CG2: 62.73333 | CH2: 63.13334 | CI2: 63.2 | CJ2: 64.43333 | CK2: 64.5 | CL2: 64.66666 | CM2: 64.76667 | CN2: 65.7 | CO2: 65.63333 | CP2: 65.8 | CQ2: 66.33334 | CR2: 67.26667 | CS2: 67.4 | CT2: 67.73333 | CU2: 68.1 | CV2: 68.86667 | CW2: 68.93333 | CX2: 69.36667 | CY2: 69.36667 | CZ2: 70 | DA2: 70.26667 | DB2: 70.63333 | DC2: 70.5 | DD2: 71.26667 | DE2: 71.23333 | DF2: 71.63333 | DG2: 71.6 | DH2: 72.3 | DI2: 72.13333 | DJ2: 72.43333 | DK2: 72.13333 | DL2: 72.76667 | DM2: 72.7 | DN2: 73.16666 | DO2: 72.76667 | DP2: 73.83334 | DQ2: 73.86667 | DR2: 73.9 | DS2: 73.86667 | DT2: 74.53333 | DU2: 74.6 | DV2: 75 | DW2: 75 | DX2: 75.46667 | DY2: 75.6 | DZ2: 76.03333 | EA2: 75.96667 | EB2: 76.53333 | EC2: 76.56667 | ED2: 77.1 | EE2: 77.23333 | EF2: 78 | EG2: 78.4 | EH2: 78.76667 | EI2: 78.73333 | EJ2: 79.8 | EK2: 80.3 | EL2: 80.9 | EM2: 81 | EN2: 81.8 | EO2: 81.73333 | EP2: 82.6 | EQ2: 82.93333 | ER2: 84.6 | ES2: 85.63333 | ET2: 85.73333 | EU2: 85.43333 | EV2: 86.36667 | EW2: 86.93333 | EX2: 87.56667 | EY2: 88.23333 | EZ2: 89.36667 | FA2: 89.63333 | FB2: 90.5 | FC2: 91.83334 | FD2: 93.3 | FE2: 93.83334 | FF2: 94.73333 | FG2: 95.03333 | FH2: 95.8 | FI2: 96.06667 | FJ2: 97.26667 | FK2: 97.66666 | FL2: 98.36667 | FM2: 98.7 | FN2: 99.3 | FO2: 99.4 | FP2: 100.1 | FQ2: 100.1333 | FR2: 100.2 | FS2: 99.5 | FT2: 100.0667 | FU2: 100.1667 | FV2: 100.3 | FW2: 99.83334 | FX2: 100.4 | FY2: 100.8667 | FZ2: 101.5 | GA2: 102 | GB2: 103.1667 | GC2: 103.7 | GD2: 104.5667 | GE2: 104.7667 | GF2: 105.6667 | GG2: 106.3 | GH2: 106.9333 | GI2: 106.7 | GJ2: 107.8 | GK2: 108.2667 | GL2: 108.4333 | GM2: 108.4667 | GN2: 108.5333 | GO2: 108.9333 | GP2: 109.0667 | GQ2: 109.1667 | GR2: 110.7333 | GS2: 111.9333 | GT2: 114.4 | GU2: 115.9333 | GV2: 120.8667 | GW2: 123.1333 | GX2: 126.7 | GY2: 127.7333 | GZ2: 131.0667 | HA2: 131.4 | HB2: 131.9667 | HC2: 132.503 | HD2: 133.1716 | HE2: 133.5944 | HF2: 133.9709 | HG2: 134.2228 | HH2: 135.1627 | HI2: 135.7337 | HJ2: 136.3003 | HK2: 136.7196 | HL2: 137.7126 | HM2: 138.3018 | HN2: 138.8736 | HO2: 139.2957 | HP2: 140.3477 | HQ2: 140.9886 | HR2: 141.6125 | HS2: 142.071 | HT2: 143.1641 | HU2: 143.8183 | HV2: 144.444 | HW2: 144.9134 | HX2: 145.9971 | HY2: 146.662 | HZ2: 147.3093 | IA2: 147.798 | IB2: 148.9121 | IC2: 149.5927 | ID2: 150.2559 | IE2: 150.7591 | IF2: 151.8987 | IG2: 152.5884 | IH2: 153.2595 | II2: 153.7663 | IJ2: 154.9232 | IK2: 155.6282 | IL2: 156.3149 | IM2: 156.8337 | IN2: 158.0156 | IO2: 158.7364 | IP2: 159.4384 | IQ2: 159.9691 | IR2: 161.176 | IS2: 161.9124 | IT2: 162.6295 | IU2: 163.1717 | IV2: 164.4037 | IW2: 165.1557 | IX2: 165.8855 | IY2: 166.4351 | IZ2: 167.6918 | JA2: 168.4588 | JB2: 169.2032 | JC2: 169.7638 | JD2: 171.0456 | JE2: 171.828 | JF2: 172.5873 | JG2: 173.1591 | JH2: 174.4665 | JI2: 175.2645 | JJ2: 176.039 | JK2: 176.6223 | JL2: 177.9559 | JM2: 178.7698 | JN2: 179.5598 | JO2: 180.1547 | JP2: 181.515 | JQ2: 182.3452 | JR2: 183.151 | JS2: 183.7578 | JT2: 185.1453 | JU2: 185.9921 | JV2: 186.814 | JW2: 187.433 | JX2: 188.8482 | JY2: 189.712 | JZ2: 190.5503 | KA2: 191.1817 | KB2: 192.6251 | KC2: 193.5062 | KD2: 194.3613 | KE2: 195.0053 | KF2: 196.4776 | KG2: 197.3763 | KH2: 198.2485 | KI2: 198.9054 | KJ2: 200.4072 | KK2: 201.3239 | KL2: 202.2135 | KM2: 202.8835 | KN2: 204.4153 | KO2: 205.3503 | KP2: 206.2578 | KQ2: 206.9412 | KR2: 208.5036 | KS2: 209.4573 | KT2: 210.3829 | KU2: 211.08 | KV2: 212.6737 | KW2: 213.6465 | KX2: 214.5906 | KY2: 215.3016 | KZ2: 216.9272 | LA2: 217.9194 | LB2: 218.8824 | LC2: 219.6076 | LD2: 221.2657 | LE2: 222.2778 | LF2: 223.26 | LG2: Office for National Statistics\Haver Analytics | LH2: False | LI2: NA | LJ2: 2015 | LK2: 2023 | LL2: 4 | LM2: NA | LN2: D7BT@UK | LO2: UK: Consumer Price Index: All Items (NSA, 2015=100) | LP2: GBR | LQ2: CPI | LR2: FEB001G.db
