Workbook
Name _DLX1.INC: HAVERA!$A$3:$BO$8
Name _DLX2.INC: HAVERD!$B$2:$L$7
Name Data: [1]sheet0!$C$2

Sheet >> CHARTS

Sheet >> DATA

Sheet Chart Data
A1: Budget policy decisions | I1: Fiscal rules | U1: Fiscal rules | AA1: Public sector net investment | AH1: OBR estimates of fiscal tightening | AM1: NICs impact | BH1: Opinion polls | BO1: Conservative RDEL plans | BU1: Government investment | CC1: Conservative DEL plans | CI1: AE debt dynamics (2024-2028) | DE1: Taxes as share of total | DH1: How could headroom be eroded | DK1: OBR GC forecasts
K2: Levels | P2: Diff | V2: Public sector net debt | W2: Public sector net debt (ex BoE) | X2: Public sector net financial liabilities | Y2: Public sector net worth | AN2: GDP | AR2: ER | AV2: ETILO | AZ2: UPILO | BD2: TP | BH2: YouGov | BI2: https://yougov.co.uk/politics/articles/50820-britons-say-public-services-are-bad-but-they-arent-willing-to-pay-more-to-fix-them | DL2: 2022=100 | DT2: Level £bn
B3: 2024-2025 | C3: 2025-2026 | D3: 2026-2027 | E3: 2027-2028 | F3: 2028-2029 | G3: 2029-2030 | K3: Public sector net debt | L3: Public sector net debt (ex BoE) | M3: Public sector net financial liabilities | N3: Public sector net worth (inverted) | P3: Public sector net debt | Q3: Public sector net debt (ex BoE) | R3: Public sector net financial liabilities | S3: Public sector net worth (inverted) | V3: Public sector net debt | W3: Public sector net debt (ex BoE) | X3: Public sector net financial liabilities | Y3: Public sector net worth (inverted) | AC3: Budget (Oct24) | AD3: Budget (Mar24) | AE3: UK average (2004-2023) | AF3: OECD average | AJ3: Budget (Oct24) | AK3: Budget (Mar24) | AN3: Baseline | AO3: Scenario | AP3: Diff | AR3: Baseline | AS3: Scenario | AT3: Diff | AV3: Baseline | AW3: Scenario | AX3: Diff | AZ3: Baseline | BA3: Scenario | BB3: Diff | BD3: Baseline | BE3: Scenario | BF3: Diff | BI3: Higher taxes and more funding for public services | BJ3: Current tax levels and public services funding remaining as it is | BK3: Lower taxes and less funding for public services | BL3: Don't know | BP3: Real PSCE in RDEL per capita | BQ3: 100 LINE | BS3: Real PSCE in RDEL per capita | BW3: 2003-2022 | CA3: 2003-2022 | CD3: Real PSGI in RDEL per capita | CE3: 100 LINE | CG3: Real PSGI in RDEL per capita | CJ3: =DataA!BK2 -> UK | CK3: =DataA!BL2 -> US | CL3: =DataA!BM2 -> Japan | CM3: =DataA!BN2 -> Canada | CN3: =DataA!BO2 -> Australia | CO3: =DataA!BP2 -> Denmark | CP3: =DataA!BQ2 -> Sweden | CQ3: =DataA!BR2 -> Switzerland | ... DC3: =DataA!CD2 -> Portugal | DF3: 2024-2025 | DI3: £bn | DL3: =DT3 -> 44621 | DM3: =DU3 -> 44866 | DN3: =DV3 -> 44986 | DO3: =DW3 -> 45231 | DP3: =DX3 -> 45352 | DQ3: =DY3 -> 45566 | DT3: 44621 | DU3: 44866 | DV3: 44986 | DW3: 45231 | DX3: 45352 | DY3: 45566
A4: Tax | B4: ='HMT - Table 5.1'!F88 -> 1160 | C4: ='HMT - Table 5.1'!G88 -> 24005 | D4: ='HMT - Table 5.1'!H88 -> 34785 | E4: ='HMT - Table 5.1'!I88 -> 39065 | F4: ='HMT - Table 5.1'!J88 -> 39725 | G4: ='HMT - Table 5.1'!K88 -> 41170 | I4: 2000-01 | J4: =LEFT(I4,4) -> 2000 | K4: {=TRANSPOSE('C6.11'!D26:AG29)} -> 28.3 | L4: 28.4 | M4: 26.955398 | N4: 32.43637 | U4: 2029-2030 | V4: =-(P33/100)*$V$7 -> 6.6405827 | W4: =-(Q33/100)*$V$7 -> -5.7796597 | X4: =-(R33/100)*$V$7 -> 15.747235 | Y4: =-(S33/100)*$V$7 -> 16.945561 | AA4: ='Aggregates (% GDP) Oct24'!B57 -> 2000-01 | AB4: =LEFT(AA4,4) -> 2000 | AC4: ='Aggregates (% GDP) Oct24'!F57 -> 0.40470502 | AD4: ='Aggregates (% GDP) Mar24'!F57 -> 0.40470502 | AE4: =AVERAGE($AD$8:$AD$27) -> 2.145275 | AH4: ='Aggregates (% GDP) Oct24'!B57 -> 2000-01 | AI4: =LEFT(AH4,4) -> 2000 | AJ4: =-('Aggregates (% GDP) Oct24'!M57-'Aggregates (% GDP) Oct24'!M56) -> -0.014492648 | AM4: 2024 | AN4: =100*((DataCY!B51/DataCY!B50)-1) -> 0.98266797 | AO4: =100*((DataCY!H51/DataCY!H50)-1) -> 0.98266797 | AP4: =AO4-AN4 -> 0 | AR4: =100*((DataCY!D51/DataCY!D50)-1) -> 4.2451725 | AS4: =100*((DataCY!J51/DataCY!J50)-1) -> 4.2451725 | AT4: =AS4-AR4 -> 0 | AV4: =DataCY!C51 -> 33138.705 | AW4: =DataCY!I51 -> 33138.705 | AX4: =AW4-AV4 -> 0 | AZ4: =DataCY!E51 -> 4.2879467 | BA4: =DataCY!K51 -> 4.2879467 | BB4: =BA4-AZ4 -> 0 | BD4: =DataFY!G51 -> 152663.25 | BE4: =DataFY!M51 -> 152663.25 | BF4: =BE4-BD4 -> 0 | BH4: All Britons | BI4: 31 | BJ4: 30 | BK4: 20 | BL4: 19 | BM4: =SUM(BI4:BL4) -> 100 | BO4: {=TRANSPOSE(OBR_MAR24_ST4.3!E4:Z4)} -> 2007-08 | BP4: =100*(BS4/$BS$20) -> 100.43541 | BQ4: 100 | BS4: {=TRANSPOSE(OBR_MAR24_ST4.3!E11:Z11)} -> 6193.1143 | BU4: 1 | BV4: =VLOOKUP($BU4,$BY$4:$CA$34,2,FALSE) -> Estonia | BW4: =VLOOKUP($BU4,$BY$4:$CA$34,3,FALSE) -> 5.3362375 | BY4: =RANK(CA4,$CA$4:$CA$34) -> 27 | BZ4: {=TRANSPOSE(HAVERA!BN1:CR2)} -> UK | CA4: 2.814318 | CC4: {=TRANSPOSE(OBR_MAR24_ST4.3!E4:Z4)} -> 2007-08 | CD4: =100*(CG4/$CG$20) -> 83.985641 | CE4: 100 | CG4: {=TRANSPOSE(OBR_MAR24_ST4.3!E17:Z17)} -> 1170.3834 | CI4: Expected effective interest rates on government debt (r) | CJ4: =AVERAGE(DataA!BK58:BK62) -> 3.9112168 | CK4: =AVERAGE(DataA!BL58:BL62) -> 3.4758633 | CL4: =AVERAGE(DataA!BM58:BM62) -> 0.78474053 | CM4: =AVERAGE(DataA!BN58:BN62) -> 3.286119 | CN4: =AVERAGE(DataA!BO58:BO62) -> 2.8132632 | CO4: =AVERAGE(DataA!BP58:BP62) -> 1.951017 | CP4: =AVERAGE(DataA!BQ58:BQ62) -> 1.4633902 | CQ4: =AVERAGE(DataA!BR58:BR62) -> 1.2019786 | ... DC4: =AVERAGE(DataA!CD58:CD62) -> 2.4149445 | DE4: Income tax | DF4: =OBR_MAR24_ST3.9!F7 -> 302.63177 | DH4: Headroom | DI4: 9.9 | DK4: 2020 | DS4: 2020 | DT4: ='[2]1.1'!D53 -> 105.648 | DU4: ='[3]1.1'!D53 -> 104.088 | DV4: ='[4]1.1'!D53 -> 104.088 | DW4: ='[5]1.1'!D53 -> 103.574 | DX4: ='[6]1.1'!D53 -> 103.574 | DY4: ='[7]1.1'!D53 -> 103.574
A5: Current spending | B5: ='HMT - Table 5.1'!F87-'Chart Data'!B6 -> -27630 | C5: ='HMT - Table 5.1'!G87-'Chart Data'!C6 -> -48190 | D5: ='HMT - Table 5.1'!H87-'Chart Data'!D6 -> -50675 | E5: ='HMT - Table 5.1'!I87-'Chart Data'!E6 -> -51825 | F5: ='HMT - Table 5.1'!J87-'Chart Data'!F6 -> -52805 | G5: ='HMT - Table 5.1'!K87-'Chart Data'!G6 -> -51035 | I5: 2001-02 | J5: =LEFT(I5,4) -> 2001 | K5: 28.1 | L5: 28.2 | M5: 28.366806 | N5: 34.14847 | P5: =K5-K4 -> -0.2 | Q5: =L5-L4 -> -0.2 | R5: =M5-M4 -> 1.4114071 | S5: =N5-N4 -> 1.7120996 | AA5: ='Aggregates (% GDP) Oct24'!B58 -> 2001-02 | AB5: =LEFT(AA5,4) -> 2001 | AC5: ='Aggregates (% GDP) Oct24'!F58 -> 1.0969634 | AD5: ='Aggregates (% GDP) Mar24'!F58 -> 1.0969634 | AE5: =AVERAGE($AD$8:$AD$27) -> 2.145275 | AH5: ='Aggregates (% GDP) Oct24'!B58 -> 2001-02 | AI5: =LEFT(AH5,4) -> 2001 | AJ5: =-('Aggregates (% GDP) Oct24'!M58-'Aggregates (% GDP) Oct24'!M57) -> 1.9591308 | AM5: 2025 | AN5: =100*((DataCY!B52/DataCY!B51)-1) -> 1.5341097 | AO5: =100*((DataCY!H52/DataCY!H51)-1) -> 1.39618 | AP5: =AO5-AN5 -> -0.13792967 | AR5: =100*((DataCY!D52/DataCY!D51)-1) -> 3.5514545 | AS5: =100*((DataCY!J52/DataCY!J51)-1) -> 3.478492 | AT5: =AS5-AR5 -> -0.072962485 | AV5: =DataCY!C52 -> 33430.338 | AW5: =DataCY!I52 -> 33403.51 | AX5: =AW5-AV5 -> -26.8275 | AZ5: =DataCY!E52 -> 4.3347963 | BA5: =DataCY!K52 -> 4.4113922 | BB5: =BA5-AZ5 -> 0.076596 | BD5: =DataFY!G52 -> 159368.98 | BE5: =DataFY!M52 -> 182720.43 | BF5: =BE5-BD5 -> 23351.45 | BH5: Labour voters | BI5: 51 | BJ5: 25 | BK5: 10 | BL5: 14 | BM5: =SUM(BI5:BL5) -> 100 | BO5: 2008-09 | BP5: =100*(BS5/$BS$20) -> 100.66341 | BQ5: 100 | BS5: 6207.1735 | BU5: =+BU4+1 -> 2 | BV5: =VLOOKUP($BU5,$BY$4:$CA$34,2,FALSE) -> Korea | BW5: =VLOOKUP($BU5,$BY$4:$CA$34,3,FALSE) -> 4.956172 | BY5: =RANK(CA5,$CA$4:$CA$34) -> 19 | BZ5: US | CA5: 3.5916962 | CC5: 2008-09 | CD5: =100*(CG5/$CG$20) -> 86.761543 | CE5: 100 | CG5: 1209.067 | CI5: Expected annual average nominal GDP growth (g) | CJ5: =100*((DataA!AP62/DataA!AP57)^(1/5)-1) -> 3.8491937 | CK5: =100*((DataA!AQ62/DataA!AQ57)^(1/5)-1) -> 4.5938897 | CL5: =100*((DataA!AR62/DataA!AR57)^(1/5)-1) -> 1.8311871 | CM5: =100*((DataA!AS62/DataA!AS57)^(1/5)-1) -> 4.0511319 | CN5: =100*((DataA!AT62/DataA!AT57)^(1/5)-1) -> 4.2423302 | CO5: =100*((DataA!AU62/DataA!AU57)^(1/5)-1) -> 4.1839752 | CP5: =100*((DataA!AV62/DataA!AV57)^(1/5)-1) -> 4.0221267 | CQ5: =100*((DataA!AW62/DataA!AW57)^(1/5)-1) -> 2.5650576 | ... DC5: =100*((DataA!BI62/DataA!BI57)^(1/5)-1) -> 3.882884 | DE5: Employees' NICs | DF5: =OBR_MAR24_ST3.9!F12*(OBR_MAR24_ST3.4!E15/OBR_MAR24_ST3.4!$E$14) -> 55.860867 | DT5: ='[2]1.1'!D54 -> 86.758 | DU5: ='[3]1.1'!D54 -> 85.179 | DV5: ='[4]1.1'!D54 -> 85.179 | DW5: ='[5]1.1'!D54 -> 84.624 | DX5: ='[6]1.1'!D54 -> 84.624 | DY5: ='[7]1.1'!D54 -> 84.624
A6: Capital spending | B6: ='HMT - Table 5.1'!F5 -> 1765 | C6: ='HMT - Table 5.1'!G5 -> -15360 | D6: ='HMT - Table 5.1'!H5 -> -19440 | E6: ='HMT - Table 5.1'!I5 -> -23820 | F6: ='HMT - Table 5.1'!J5 -> -25695 | G6: ='HMT - Table 5.1'!K5 -> -23125 | I6: 2002-03 | J6: =LEFT(I6,4) -> 2002 | K6: 29.8 | L6: 29.9 | M6: 31.350052 | N6: 36.652789 | P6: =K6-K5 -> 1.7 | Q6: =L6-L5 -> 1.7 | R6: =M6-M5 -> 2.9832465 | S6: =N6-N5 -> 2.5043195 | U6: Change % of GDP | AA6: ='Aggregates (% GDP) Oct24'!B59 -> 2002-03 | AB6: =LEFT(AA6,4) -> 2002 | AC6: ='Aggregates (% GDP) Oct24'!F59 -> 1.4448275 | AD6: ='Aggregates (% GDP) Mar24'!F59 -> 1.4448275 | AE6: =AVERAGE($AD$8:$AD$27) -> 2.145275 | AH6: ='Aggregates (% GDP) Oct24'!B59 -> 2002-03 | AI6: =LEFT(AH6,4) -> 2002 | AJ6: =-('Aggregates (% GDP) Oct24'!M59-'Aggregates (% GDP) Oct24'!M58) -> 2.0383229 | AM6: 2026 | AN6: =100*((DataCY!B53/DataCY!B52)-1) -> 1.631252 | AO6: =100*((DataCY!H53/DataCY!H52)-1) -> 1.5073108 | AP6: =AO6-AN6 -> -0.12394115 | AR6: =100*((DataCY!D53/DataCY!D52)-1) -> 2.6851513 | AS6: =100*((DataCY!J53/DataCY!J52)-1) -> 2.5624237 | AT6: =AS6-AR6 -> -0.12272757 | AV6: =DataCY!C53 -> 33874.042 | AW6: =DataCY!I53 -> 33820.61 | AX6: =AW6-AV6 -> -53.4325 | AZ6: =DataCY!E53 -> 4.127162 | BA6: =DataCY!K53 -> 4.2783833 | BB6: =BA6-AZ6 -> 0.15122125 | BD6: =DataFY!G53 -> 166351.45 | BE6: =DataFY!M53 -> 189385.05 | BF6: =BE6-BD6 -> 23033.6 | BH6: Lib Dem voters | BI6: 52 | BJ6: 26 | BK6: 10 | BL6: 13 | BM6: =SUM(BI6:BL6) -> 101 | BO6: 2009-10 | BP6: =100*(BS6/$BS$20) -> 104.95422 | BQ6: 100 | BS6: 6471.7565 | BU6: =+BU5+1 -> 3 | BV6: =VLOOKUP($BU6,$BY$4:$CA$34,2,FALSE) -> Latvia | BW6: =VLOOKUP($BU6,$BY$4:$CA$34,3,FALSE) -> 4.7532364 | BY6: =RANK(CA6,$CA$4:$CA$34) -> 13 | BZ6: Japan | CA6: 3.9530871 | CC6: 2009-10 | CD6: =100*(CG6/$CG$20) -> 96.7349 | CE6: 100 | CG6: 1348.0509 | DE6: VAT | DF6: =OBR_MAR24_ST3.9!F13 -> 173.8803 | DH6: Continue to freeze fuel duty | DI6: 4.7 | DT6: ='[2]1.1'!D55 -> 102.475 | DU6: ='[3]1.1'!D55 -> 100.663 | DV6: ='[4]1.1'!D55 -> 100.663 | DW6: ='[5]1.1'!D55 -> 99.934 | DX6: ='[6]1.1'!D55 -> 99.934 | DY6: ='[7]1.1'!D55 -> 99.934
A7: Total | B7: =SUM(B4:B6) -> -24705 | C7: =SUM(C4:C6) -> -39545 | D7: =SUM(D4:D6) -> -35330 | E7: =SUM(E4:E6) -> -36580 | F7: =SUM(F4:F6) -> -38775 | G7: =SUM(G4:G6) -> -32990 | I7: 2003-04 | J7: =LEFT(I7,4) -> 2003 | K7: 30.9 | L7: 31 | M7: 31.244827 | N7: 37.45462 | P7: =K7-K6 -> 1.1 | Q7: =L7-L6 -> 1.1 | R7: =M7-M6 -> -0.10522481 | S7: =N7-N6 -> 0.80183026 | U7: GDP! | V7: 3459.596 | AA7: ='Aggregates (% GDP) Oct24'!B60 -> 2003-04 | AB7: =LEFT(AA7,4) -> 2003 | AC7: ='Aggregates (% GDP) Oct24'!F60 -> 1.6922036 | AD7: ='Aggregates (% GDP) Mar24'!F60 -> 1.6922036 | AE7: =AVERAGE($AD$8:$AD$27) -> 2.145275 | AH7: ='Aggregates (% GDP) Oct24'!B60 -> 2003-04 | AI7: =LEFT(AH7,4) -> 2003 | AJ7: =-('Aggregates (% GDP) Oct24'!M60-'Aggregates (% GDP) Oct24'!M59) -> 0.4553037 | AM7: 2027 | AN7: =100*((DataCY!B54/DataCY!B53)-1) -> 1.6566706 | AO7: =100*((DataCY!H54/DataCY!H53)-1) -> 1.6837409 | AP7: =AO7-AN7 -> 0.027070292 | AR7: =100*((DataCY!D54/DataCY!D53)-1) -> 2.5895984 | AS7: =100*((DataCY!J54/DataCY!J53)-1) -> 2.6013744 | AT7: =AS7-AR7 -> 0.011775959 | AV7: =DataCY!C54 -> 34275.132 | AW7: =DataCY!I54 -> 34229.768 | AX7: =AW7-AV7 -> -45.365 | AZ7: =DataCY!E54 -> 3.940423 | BA7: =DataCY!K54 -> 4.0675903 | BB7: =BA7-AZ7 -> 0.12716725 | BD7: =DataFY!G54 -> 173561.32 | BE7: =DataFY!M54 -> 197158.96 | BF7: =BE7-BD7 -> 23597.64 | BH7: Conservative voters | BI7: 15 | BJ7: 43 | BK7: 27 | BL7: 15 | BM7: =SUM(BI7:BL7) -> 100 | BO7: 2010-11 | BP7: =100*(BS7/$BS$20) -> 104.32871 | BQ7: 100 | BS7: 6433.1857 | BU7: =+BU6+1 -> 4 | BV7: =VLOOKUP($BU7,$BY$4:$CA$34,2,FALSE) -> Czechia | BW7: =VLOOKUP($BU7,$BY$4:$CA$34,3,FALSE) -> 4.7454643 | BY7: =RANK(CA7,$CA$4:$CA$34) -> 31 | BZ7: Germany | CA7: 2.2421639 | CC7: 2010-11 | CD7: =100*(CG7/$CG$20) -> 80.784526 | CE7: 100 | CG7: 1125.7742 | CI7: AE debt dynamics (2025-2029) | DE7: Corporation tax | DF7: =OBR_MAR24_ST3.9!F14 -> 96.966938 | DH7: Increase defence spending to 2.5% of GDP | DI7: 10 | DT7: ='[2]1.1'!D56 -> 106.312 | DU7: ='[3]1.1'!D56 -> 104.53 | DV7: ='[4]1.1'!D56 -> 104.53 | DW7: ='[5]1.1'!D56 -> 104.835 | DX7: ='[6]1.1'!D56 -> 104.835 | DY7: ='[7]1.1'!D56 -> 104.835
I8: 2004-05 | J8: =LEFT(I8,4) -> 2004 | K8: 33.5 | L8: 33.6 | M8: 33.412416 | N8: 37.390259 | P8: =K8-K7 -> 2.6 | Q8: =L8-L7 -> 2.6 | R8: =M8-M7 -> 2.1675887 | S8: =N8-N7 -> -0.064360255 | AA8: ='Aggregates (% GDP) Oct24'!B61 -> 2004-05 | AB8: =LEFT(AA8,4) -> 2004 | AC8: ='Aggregates (% GDP) Oct24'!F61 -> 2.0459664 | AD8: ='Aggregates (% GDP) Mar24'!F61 -> 2.0459664 | AE8: =AVERAGE($AD$8:$AD$27) -> 2.145275 | AH8: ='Aggregates (% GDP) Oct24'!B61 -> 2004-05 | AI8: =LEFT(AH8,4) -> 2004 | AJ8: =-('Aggregates (% GDP) Oct24'!M61-'Aggregates (% GDP) Oct24'!M60) -> 0.50237965 | AM8: 2028 | AN8: =100*((DataCY!B55/DataCY!B54)-1) -> 1.6473682 | AO8: =100*((DataCY!H55/DataCY!H54)-1) -> 1.6778525 | AP8: =AO8-AN8 -> 0.030484248 | AR8: =100*((DataCY!D55/DataCY!D54)-1) -> 2.591253 | AS8: =100*((DataCY!J55/DataCY!J54)-1) -> 2.6296951 | AT8: =AS8-AR8 -> 0.038442166 | AV8: =DataCY!C55 -> 34669.898 | AW8: =DataCY!I55 -> 34633.96 | AX8: =AW8-AV8 -> -35.9375 | AZ8: =DataCY!E55 -> 3.7972135 | BA8: =DataCY!K55 -> 3.8969493 | BB8: =BA8-AZ8 -> 0.09973575 | BD8: =DataFY!G55 -> 180390.25 | BE8: =DataFY!M55 -> 204855.91 | BF8: =BE8-BD8 -> 24465.66 | BH8: Reform UK voters | BI8: 13 | BJ8: 33 | BK8: 37 | BL8: 17 | BM8: =SUM(BI8:BL8) -> 100 | BO8: 2011-12 | BP8: =100*(BS8/$BS$20) -> 100.33174 | BQ8: 100 | BS8: 6186.7218 | BU8: =+BU7+1 -> 5 | BV8: =VLOOKUP($BU8,$BY$4:$CA$34,2,FALSE) -> Hungary | BW8: =VLOOKUP($BU8,$BY$4:$CA$34,3,FALSE) -> 4.6181676 | BY8: =RANK(CA8,$CA$4:$CA$34) -> 15 | BZ8: France | CA8: 3.7980744 | CC8: 2011-12 | CD8: =100*(CG8/$CG$20) -> 68.060388 | CE8: 100 | CG8: 948.45675 | CJ8: =DataA!BK2 -> UK | CK8: =DataA!BL2 -> US | CL8: =DataA!BM2 -> Japan | CM8: =DataA!BN2 -> Canada | CN8: =DataA!BO2 -> Australia | CO8: =DataA!BP2 -> Denmark | CP8: =DataA!BQ2 -> Sweden | CQ8: =DataA!BR2 -> Switzerland | ... DC8: =DataA!CD2 -> Portugal | DE8: Employers' NICs | DF8: =OBR_MAR24_ST3.9!F12*(OBR_MAR24_ST3.4!E16/OBR_MAR24_ST3.4!$E$14) -> 113.47014 | DH8: 100bps increase in gilt yields | DI8: =OBR_OCT24_RR5.1!H6 -> 11.95889 | DK8: 2021 | DS8: 2021 | DT8: ='[2]1.1'!D57 -> 108.097 | DU8: ='[3]1.1'!D57 -> 104.634 | DV8: ='[4]1.1'!D57 -> 104.377 | DW8: ='[5]1.1'!D57 -> 105.864 | DX8: ='[6]1.1'!D57 -> 105.864 | DY8: ='[7]1.1'!D57 -> 105.864
A9: check | B9: ='HMT - Table 5.1'!F86 -> -24705 | C9: ='HMT - Table 5.1'!G86 -> -39550 | D9: ='HMT - Table 5.1'!H86 -> -35330 | E9: ='HMT - Table 5.1'!I86 -> -36585 | F9: ='HMT - Table 5.1'!J86 -> -38775 | G9: ='HMT - Table 5.1'!K86 -> -32990 | I9: 2005-06 | J9: =LEFT(I9,4) -> 2005 | K9: 34.3 | L9: 34.5 | M9: 32.378335 | N9: 34.942387 | P9: =K9-K8 -> 0.8 | Q9: =L9-L8 -> 0.9 | R9: =M9-M8 -> -1.0340813 | S9: =N9-N8 -> -2.4478726 | W9: Diff | X9: £bn | Y9: =X4-W4 -> 21.526895 | AA9: ='Aggregates (% GDP) Oct24'!B62 -> 2005-06 | AB9: =LEFT(AA9,4) -> 2005 | AC9: ='Aggregates (% GDP) Oct24'!F62 -> 1.8521352 | AD9: ='Aggregates (% GDP) Mar24'!F62 -> 1.8521352 | AE9: =AVERAGE($AD$8:$AD$27) -> 2.145275 | AH9: ='Aggregates (% GDP) Oct24'!B62 -> 2005-06 | AI9: =LEFT(AH9,4) -> 2005 | AJ9: =-('Aggregates (% GDP) Oct24'!M62-'Aggregates (% GDP) Oct24'!M61) -> -0.69717717 | AM9: 2029 | AN9: =100*((DataCY!B56/DataCY!B55)-1) -> 1.6121887 | AO9: =100*((DataCY!H56/DataCY!H55)-1) -> 1.6514389 | AP9: =AO9-AN9 -> 0.039250219 | AR9: =100*((DataCY!D56/DataCY!D55)-1) -> 2.649545 | AS9: =100*((DataCY!J56/DataCY!J55)-1) -> 2.6857202 | AT9: =AS9-AR9 -> 0.036175242 | AV9: =DataCY!C56 -> 35019.358 | AW9: =DataCY!I56 -> 34992.588 | AX9: =AW9-AV9 -> -26.77 | AZ9: =DataCY!E56 -> 3.749889 | BA9: =DataCY!K56 -> 3.8234867 | BB9: =BA9-AZ9 -> 0.07359775 | BD9: =DataFY!G56 -> 187169.91 | BE9: =DataFY!M56 -> 212530.68 | BF9: =BE9-BD9 -> 25360.77 | BO9: 2012-13 | BP9: =100*(BS9/$BS$20) -> 96.544117 | BQ9: 100 | BS9: 5953.1669 | BU9: =+BU8+1 -> 6 | BV9: =VLOOKUP($BU9,$BY$4:$CA$34,2,FALSE) -> Sweden | BW9: =VLOOKUP($BU9,$BY$4:$CA$34,3,FALSE) -> 4.5506017 | BY9: =RANK(CA9,$CA$4:$CA$34) -> 28 | BZ9: Italy | CA9: 2.7823445 | CC9: 2012-13 | CD9: =100*(CG9/$CG$20) -> 64.3172 | CE9: 100 | CG9: 896.29347 | CI9: Expected effective interest rates on government debt (r) | CJ9: =AVERAGE(DataA!BK59:BK63) -> 3.7872637 | CK9: =AVERAGE(DataA!BL59:BL63) -> 3.4794354 | CL9: =AVERAGE(DataA!BM59:BM63) -> 0.93904773 | CM9: =AVERAGE(DataA!BN59:BN63) -> 3.284709 | CN9: =AVERAGE(DataA!BO59:BO63) -> 3.099439 | CO9: =AVERAGE(DataA!BP59:BP63) -> 1.8489287 | CP9: =AVERAGE(DataA!BQ59:BQ63) -> 1.4549596 | CQ9: =AVERAGE(DataA!BR59:BR63) -> 1.2277362 | ... DC9: =AVERAGE(DataA!CD59:CD63) -> 2.4551536 | DE9: Fuel duties | DF9: =OBR_MAR24_ST3.9!F21 -> 24.740818 | DH9: 100bps increase in expectations for Bank Rate | DI9: =OBR_OCT24_RR5.1!H7 -> 4.6651018 | DT9: ='[2]1.1'!D58 -> 116.428 | DU9: ='[3]1.1'!D58 -> 112.51 | DV9: ='[4]1.1'!D58 -> 112.392 | DW9: ='[5]1.1'!D58 -> 114.096 | DX9: ='[6]1.1'!D58 -> 114.096 | DY9: ='[7]1.1'!D58 -> 114.096
I10: 2006-07 | J10: =LEFT(I10,4) -> 2006 | K10: 35.1 | L10: 35.3 | M10: 32.440742 | N10: 35.127873 | P10: =K10-K9 -> 0.8 | Q10: =L10-L9 -> 0.8 | R10: =M10-M9 -> 0.062407551 | S10: =N10-N9 -> 0.18548609 | X10: % of GDP | Y10: =R33-Q33 -> -0.62223726 | AA10: ='Aggregates (% GDP) Oct24'!B63 -> 2006-07 | AB10: =LEFT(AA10,4) -> 2006 | AC10: ='Aggregates (% GDP) Oct24'!F63 -> 1.8163774 | AD10: ='Aggregates (% GDP) Mar24'!F63 -> 1.8163774 | AE10: =AVERAGE($AD$8:$AD$27) -> 2.145275 | AH10: ='Aggregates (% GDP) Oct24'!B63 -> 2006-07 | AI10: =LEFT(AH10,4) -> 2006 | AJ10: =-('Aggregates (% GDP) Oct24'!M63-'Aggregates (% GDP) Oct24'!M62) -> -0.71890443 | AM10: 2030 | AN10: =100*((DataCY!B57/DataCY!B56)-1) -> 1.6097059 | AO10: =100*((DataCY!H57/DataCY!H56)-1) -> 1.6548179 | AP10: =AO10-AN10 -> 0.045112052 | AR10: =100*((DataCY!D57/DataCY!D56)-1) -> 2.7035181 | AS10: =100*((DataCY!J57/DataCY!J56)-1) -> 2.7420534 | AT10: =AS10-AR10 -> 0.038535354 | AV10: =DataCY!C57 -> 35334.71 | AW10: =DataCY!I57 -> 35317.572 | AX10: =AW10-AV10 -> -17.1375 | AZ10: =DataCY!E57 -> 3.7498765 | BA10: =DataCY!K57 -> 3.7965653 | BB10: =BA10-AZ10 -> 0.04668875 | BH10: Exclude DKs | BO10: 2013-14 | BP10: =100*(BS10/$BS$20) -> 95.557909 | BQ10: 100 | BS10: 5892.3547 | BU10: =+BU9+1 -> 7 | BV10: =VLOOKUP($BU10,$BY$4:$CA$34,2,FALSE) -> Norway | BW10: =VLOOKUP($BU10,$BY$4:$CA$34,3,FALSE) -> 4.5081333 | BY10: =RANK(CA10,$CA$4:$CA$34) -> 22 | BZ10: Australia | CA10: 3.1343494 | CC10: 2013-14 | CD10: =100*(CG10/$CG$20) -> 67.741493 | CE10: 100 | CG10: 944.01278 | CI10: Expected annual average nominal GDP growth (g) | CJ10: =100*((DataA!AP63/DataA!AP58)^(1/5)-1) -> 3.8045697 | CK10: =100*((DataA!AQ63/DataA!AQ58)^(1/5)-1) -> 4.3724944 | CL10: =100*((DataA!AR63/DataA!AR58)^(1/5)-1) -> 1.7705182 | CM10: =100*((DataA!AS63/DataA!AS58)^(1/5)-1) -> 4.155786 | CN10: =100*((DataA!AT63/DataA!AT58)^(1/5)-1) -> 4.5718689 | CO10: =100*((DataA!AU63/DataA!AU58)^(1/5)-1) -> 4.2828992 | CP10: =100*((DataA!AV63/DataA!AV58)^(1/5)-1) -> 3.9706052 | CQ10: =100*((DataA!AW63/DataA!AW58)^(1/5)-1) -> 2.5674863 | ... DC10: =100*((DataA!BI63/DataA!BI58)^(1/5)-1) -> 3.2856373 | DE10: Business rates | DF10: =OBR_MAR24_ST3.9!F52 -> 32.462397 | DT10: ='[2]1.1'!D59 -> 116.409 | DU10: ='[3]1.1'!D59 -> 112.792 | DV10: ='[4]1.1'!D59 -> 112.854 | DW10: ='[5]1.1'!D59 -> 115.146 | DX10: ='[6]1.1'!D59 -> 115.146 | DY10: ='[7]1.1'!D59 -> 115.146
A11: GDP! | B11: 2814.6771 | C11: 2950.0172 | D11: 3059.3962 | E11: 3167.3346 | F11: 3279.0494 | G11: 3397.2814 | I11: 2007-08 | J11: =LEFT(I11,4) -> 2007 | K11: 35.6 | L11: 35.8 | M11: 34.196775 | N11: 37.427136 | P11: =K11-K10 -> 0.5 | Q11: =L11-L10 -> 0.5 | R11: =M11-M10 -> 1.7560329 | S11: =N11-N10 -> 2.2992633 | AA11: ='Aggregates (% GDP) Oct24'!B64 -> 2007-08 | AB11: =LEFT(AA11,4) -> 2007 | AC11: ='Aggregates (% GDP) Oct24'!F64 -> 1.7924771 | AD11: ='Aggregates (% GDP) Mar24'!F64 -> 1.7924771 | AE11: =AVERAGE($AD$8:$AD$27) -> 2.145275 | AH11: ='Aggregates (% GDP) Oct24'!B64 -> 2007-08 | AI11: =LEFT(AH11,4) -> 2007 | AJ11: =-('Aggregates (% GDP) Oct24'!M64-'Aggregates (% GDP) Oct24'!M63) -> 0.49578275 | BI11: Higher taxes and more funding for public services | BJ11: Current tax levels and public services funding remaining as it is | BK11: Lower taxes and less funding for public services | BO11: 2014-15 | BP11: =100*(BS11/$BS$20) -> 94.289963 | BQ11: 100 | BS11: 5814.1698 | BU11: =+BU10+1 -> 8 | BV11: =VLOOKUP($BU11,$BY$4:$CA$34,2,FALSE) -> Poland | BW11: =VLOOKUP($BU11,$BY$4:$CA$34,3,FALSE) -> 4.29505 | BY11: =RANK(CA11,$CA$4:$CA$34) -> 23 | BZ11: Austria | CA11: 3.0502152 | CC11: 2014-15 | CD11: =100*(CG11/$CG$20) -> 72.034572 | CE11: 100 | CG11: 1003.839 | DE11: Council tax | DF11: =OBR_MAR24_ST3.9!F53 -> 46.298781 | DL11: =100*(DT11/AVERAGE(DT$12:DT$15)) -> 100.60698 | DT11: ='[2]1.1'!D60 -> 118.62 | DU11: ='[3]1.1'!D60 -> 114.347 | DV11: ='[4]1.1'!D60 -> 114.284 | DW11: ='[5]1.1'!D60 -> 116.404 | DX11: ='[6]1.1'!D60 -> 116.404 | DY11: ='[7]1.1'!D60 -> 116.404
I12: 2008-09 | J12: =LEFT(I12,4) -> 2008 | K12: 50.6 | L12: 50.6 | M12: 47.544202 | N12: 46.938699 | P12: =K12-K11 -> 15 | Q12: =L12-L11 -> 14.8 | R12: =M12-M11 -> 13.347427 | S12: =N12-N11 -> 9.5115631 | AA12: ='Aggregates (% GDP) Oct24'!B65 -> 2008-09 | AB12: =LEFT(AA12,4) -> 2008 | AC12: ='Aggregates (% GDP) Oct24'!F65 -> 3.0053462 | AD12: ='Aggregates (% GDP) Mar24'!F65 -> 3.0053462 | AE12: =AVERAGE($AD$8:$AD$27) -> 2.145275 | AH12: ='Aggregates (% GDP) Oct24'!B65 -> 2008-09 | AI12: =LEFT(AH12,4) -> 2008 | AJ12: =-('Aggregates (% GDP) Oct24'!M65-'Aggregates (% GDP) Oct24'!M64) -> 3.6279951 | BH12: All Britons | BI12: =100*(BI4/($BI4+$BJ4+$BK4)) -> 38.271605 | BJ12: =100*(BJ4/($BI4+$BJ4+$BK4)) -> 37.037037 | BK12: =100*(BK4/($BI4+$BJ4+$BK4)) -> 24.691358 | BM12: =SUM(BI12:BL12) -> 100 | BO12: 2015-16 | BP12: =100*(BS12/$BS$20) -> 92.40396 | BQ12: 100 | BS12: 5697.8739 | BU12: =+BU11+1 -> 9 | BV12: =VLOOKUP($BU12,$BY$4:$CA$34,2,FALSE) -> Slovenia | BW12: =VLOOKUP($BU12,$BY$4:$CA$34,3,FALSE) -> 4.2756384 | BY12: =RANK(CA12,$CA$4:$CA$34) -> 30 | BZ12: Belgium | CA12: 2.3573553 | CC12: 2015-16 | CD12: =100*(CG12/$CG$20) -> 68.29393 | CE12: 100 | CG12: 951.71127 | DE12: Capital gains tax | DF12: =OBR_MAR24_ST3.9!F22 -> 15.242148 | DK12: 2022 | DL12: =100*(DT12/AVERAGE(DT$12:DT$15)) -> 99.963094 | DS12: 2022 | DT12: ='[2]1.1'!D61 -> 117.86083 | DU12: ='[3]1.1'!D61 -> 113.062 | DV12: ='[4]1.1'!D61 -> 113.813 | DW12: ='[5]1.1'!D61 -> 117.297 | DX12: ='[6]1.1'!D61 -> 117.6 | DY12: ='[7]1.1'!D61 -> 117.6
A13: % of GDP | I13: 2009-10 | J13: =LEFT(I13,4) -> 2009 | K13: 64.7 | L13: 63.9 | M13: 54.597887 | N13: 54.07218 | P13: =K13-K12 -> 14.1 | Q13: =L13-L12 -> 13.3 | R13: =M13-M12 -> 7.0536849 | S13: =N13-N12 -> 7.1334808 | AA13: ='Aggregates (% GDP) Oct24'!B66 -> 2009-10 | AB13: =LEFT(AA13,4) -> 2009 | AC13: ='Aggregates (% GDP) Oct24'!F66 -> 3.0029004 | AD13: ='Aggregates (% GDP) Mar24'!F66 -> 3.0029004 | AE13: =AVERAGE($AD$8:$AD$27) -> 2.145275 | AH13: ='Aggregates (% GDP) Oct24'!B66 -> 2009-10 | AI13: =LEFT(AH13,4) -> 2009 | AJ13: =-('Aggregates (% GDP) Oct24'!M66-'Aggregates (% GDP) Oct24'!M65) -> 1.4319908 | BH13: Labour voters | BI13: =100*(BI5/($BI5+$BJ5+$BK5)) -> 59.302326 | BJ13: =100*(BJ5/($BI5+$BJ5+$BK5)) -> 29.069767 | BK13: =100*(BK5/($BI5+$BJ5+$BK5)) -> 11.627907 | BM13: =SUM(BI13:BL13) -> 100 | BO13: 2016-17 | BP13: =100*(BS13/$BS$20) -> 90.751464 | BQ13: 100 | BS13: 5595.9765 | BU13: =+BU12+1 -> 10 | BV13: =VLOOKUP($BU13,$BY$4:$CA$34,2,FALSE) -> Luxembourg | BW13: =VLOOKUP($BU13,$BY$4:$CA$34,3,FALSE) -> 4.1890307 | BY13: =RANK(CA13,$CA$4:$CA$34) -> 4 | BZ13: Czechia | CA13: 4.7454643 | CC13: 2016-17 | CD13: =100*(CG13/$CG$20) -> 67.698326 | CE13: 100 | CG13: 943.41122 | DE13: Inheritance tax | DF13: =OBR_MAR24_ST3.9!F23 -> 7.5239694 | DL13: =100*(DT13/AVERAGE(DT$12:DT$15)) -> 99.633216 | DT13: ='[2]1.1'!D62 -> 117.47189 | DU13: ='[3]1.1'!D62 -> 111.34 | DV13: ='[4]1.1'!D62 -> 112.16 | DW13: ='[5]1.1'!D62 -> 114.908 | DX13: ='[6]1.1'!D62 -> 114.55 | DY13: ='[7]1.1'!D62 -> 114.55
A14: Tax | B14: =100*((B4/1000)/B$11) -> 0.041212542 | C14: =100*((C4/1000)/C$11) -> 0.81372406 | D14: =100*((D4/1000)/D$11) -> 1.1369891 | E14: =100*((E4/1000)/E$11) -> 1.2333714 | F14: =100*((F4/1000)/F$11) -> 1.2114791 | G14: =100*((G4/1000)/G$11) -> 1.2118513 | I14: 2010-11 | J14: =LEFT(I14,4) -> 2010 | K14: 70.9 | L14: 70.6 | M14: 58.946492 | N14: 49.558414 | P14: =K14-K13 -> 6.2 | Q14: =L14-L13 -> 6.7 | R14: =M14-M13 -> 4.3486046 | S14: =N14-N13 -> -4.5137655 | AA14: ='Aggregates (% GDP) Oct24'!B67 -> 2010-11 | AB14: =LEFT(AA14,4) -> 2010 | AC14: ='Aggregates (% GDP) Oct24'!F67 -> 2.4446147 | AD14: ='Aggregates (% GDP) Mar24'!F67 -> 2.4446147 | AE14: =AVERAGE($AD$8:$AD$27) -> 2.145275 | AH14: ='Aggregates (% GDP) Oct24'!B67 -> 2010-11 | AI14: =LEFT(AH14,4) -> 2010 | AJ14: =-('Aggregates (% GDP) Oct24'!M67-'Aggregates (% GDP) Oct24'!M66) -> -2.2415985 | BH14: Lib Dem voters | BI14: =100*(BI6/($BI6+$BJ6+$BK6)) -> 59.090909 | BJ14: =100*(BJ6/($BI6+$BJ6+$BK6)) -> 29.545455 | BK14: =100*(BK6/($BI6+$BJ6+$BK6)) -> 11.363636 | BM14: =SUM(BI14:BL14) -> 100 | BO14: 2017-18 | BP14: =100*(BS14/$BS$20) -> 89.829709 | BQ14: 100 | BS14: 5539.1387 | BU14: =+BU13+1 -> 11 | BV14: =VLOOKUP($BU14,$BY$4:$CA$34,2,FALSE) -> Greece | BW14: =VLOOKUP($BU14,$BY$4:$CA$34,3,FALSE) -> 4.0946323 | BY14: =RANK(CA14,$CA$4:$CA$34) -> 21 | BZ14: Denmark | CA14: 3.2815288 | CC14: 2017-18 | CD14: =100*(CG14/$CG$20) -> 70.926661 | CE14: 100 | CG14: 988.39974 | DE14: Stamp duty (land) | DF14: =OBR_MAR24_ST3.9!F24 -> 12.76865 | DL14: =100*(DT14/AVERAGE(DT$12:DT$15)) -> 100.01182 | DM14: =100*(DU14/AVERAGE(DU$12:DU$15)) -> 100.12648 | DT14: ='[2]1.1'!D63 -> 117.91828 | DU14: ='[3]1.1'!D63 -> 113.5668 | DV14: ='[4]1.1'!D63 -> 112.747 | DW14: ='[5]1.1'!D63 -> 115.748 | DX14: ='[6]1.1'!D63 -> 115.094 | DY14: ='[7]1.1'!D63 -> 115.094
A15: Current spending | B15: =100*((B5/1000)/B$11) -> -0.98164012 | C15: =100*((C5/1000)/C$11) -> -1.6335498 | D15: =100*((D5/1000)/D$11) -> -1.6563726 | E15: =100*((E5/1000)/E$11) -> -1.6362338 | F15: =100*((F5/1000)/F$11) -> -1.6103752 | G15: =100*((G5/1000)/G$11) -> -1.5022306 | I15: 2011-12 | J15: =LEFT(I15,4) -> 2011 | K15: 74.3 | L15: 74.6 | M15: 65.016918 | N15: 54.680429 | P15: =K15-K14 -> 3.4 | Q15: =L15-L14 -> 4 | R15: =M15-M14 -> 6.0704267 | S15: =N15-N14 -> 5.1220142 | AA15: ='Aggregates (% GDP) Oct24'!B68 -> 2011-12 | AB15: =LEFT(AA15,4) -> 2011 | AC15: ='Aggregates (% GDP) Oct24'!F68 -> 1.8421103 | AD15: ='Aggregates (% GDP) Mar24'!F68 -> 1.8421103 | AE15: =AVERAGE($AD$8:$AD$27) -> 2.145275 | AH15: ='Aggregates (% GDP) Oct24'!B68 -> 2011-12 | AI15: =LEFT(AH15,4) -> 2011 | AJ15: =-('Aggregates (% GDP) Oct24'!M68-'Aggregates (% GDP) Oct24'!M67) -> -1.4113887 | BH15: Conservative voters | BI15: =100*(BI7/($BI7+$BJ7+$BK7)) -> 17.647059 | BJ15: =100*(BJ7/($BI7+$BJ7+$BK7)) -> 50.588235 | BK15: =100*(BK7/($BI7+$BJ7+$BK7)) -> 31.764706 | BM15: =SUM(BI15:BL15) -> 100 | BO15: 2018-19 | BP15: =100*(BS15/$BS$20) -> 89.519645 | BQ15: 100 | BS15: 5520.0193 | BU15: =+BU14+1 -> 12 | BV15: =VLOOKUP($BU15,$BY$4:$CA$34,2,FALSE) -> Finland | BW15: =VLOOKUP($BU15,$BY$4:$CA$34,3,FALSE) -> 3.9606967 | BY15: =RANK(CA15,$CA$4:$CA$34) -> 1 | BZ15: Estonia | CA15: 5.3362375 | CC15: 2018-19 | CD15: =100*(CG15/$CG$20) -> 73.803986 | CE15: 100 | CG15: 1028.4968 | DE15: Tobacco & alcohol duties | DF15: =OBR_MAR24_ST3.9!F27+OBR_MAR24_ST3.9!F28+OBR_MAR24_ST3.9!F29+OBR_MAR24_ST3.9!F30 -> 21.513849 | DL15: =100*(DT15/AVERAGE(DT$12:DT$15)) -> 100.39187 | DM15: =100*(DU15/AVERAGE(DU$12:DU$15)) -> 102.02888 | DN15: =100*(DV15/AVERAGE(DV$12:DV$15)) -> 100.48634 | DT15: ='[2]1.1'!D64 -> 118.36637 | DU15: ='[3]1.1'!D64 -> 115.72457 | DV15: ='[4]1.1'!D64 -> 113.64 | DW15: ='[5]1.1'!D64 -> 114.896 | DX15: ='[6]1.1'!D64 -> 114.44 | DY15: ='[7]1.1'!D64 -> 114.44
A16: Capital spending | B16: =100*((B6/1000)/B$11) -> 0.062707015 | C16: =100*((C6/1000)/C$11) -> -0.52067492 | D16: =100*((D6/1000)/D$11) -> -0.6354195 | E16: =100*((E6/1000)/E$11) -> -0.7520519 | F16: =100*((F6/1000)/F$11) -> -0.78361125 | G16: =100*((G6/1000)/G$11) -> -0.68069133 | I16: 2012-13 | J16: =LEFT(I16,4) -> 2012 | K16: 77.5 | L16: 76.2 | M16: 69.72436 | N16: 58.751603 | P16: =K16-K15 -> 3.2 | Q16: =L16-L15 -> 1.6 | R16: =M16-M15 -> 4.7074411 | S16: =N16-N15 -> 4.0711743 | AA16: ='Aggregates (% GDP) Oct24'!B69 -> 2012-13 | AB16: =LEFT(AA16,4) -> 2012 | AC16: ='Aggregates (% GDP) Oct24'!F69 -> 1.8798625 | AD16: ='Aggregates (% GDP) Mar24'!F69 -> 1.8798625 | AE16: =AVERAGE($AD$8:$AD$27) -> 2.145275 | AH16: ='Aggregates (% GDP) Oct24'!B69 -> 2012-13 | AI16: =LEFT(AH16,4) -> 2012 | AJ16: =-('Aggregates (% GDP) Oct24'!M69-'Aggregates (% GDP) Oct24'!M68) -> 0.44780765 | BH16: Reform UK voters | BI16: =100*(BI8/($BI8+$BJ8+$BK8)) -> 15.662651 | BJ16: =100*(BJ8/($BI8+$BJ8+$BK8)) -> 39.759036 | BK16: =100*(BK8/($BI8+$BJ8+$BK8)) -> 44.578313 | BM16: =SUM(BI16:BL16) -> 100 | BO16: 2019-20 | BP16: =100*(BS16/$BS$20) -> 93.503228 | BQ16: 100 | BS16: 5765.6577 | BU16: =+BU15+1 -> 13 | BV16: =VLOOKUP($BU16,$BY$4:$CA$34,2,FALSE) -> Japan | BW16: =VLOOKUP($BU16,$BY$4:$CA$34,3,FALSE) -> 3.9530871 | BY16: =RANK(CA16,$CA$4:$CA$34) -> 12 | BZ16: Finland | CA16: 3.9606967 | CC16: 2019-20 | CD16: =100*(CG16/$CG$20) -> 75.285142 | CE16: 100 | CG16: 1049.1374 | DE16: Other | DF16: =DF17-SUM(DF4:DF15) -> 235.761 | DK16: 2023 | DL16: =100*(DT16/AVERAGE(DT$12:DT$15)) -> 100.74324 | DM16: =100*(DU16/AVERAGE(DU$12:DU$15)) -> 103.40627 | DN16: =100*(DV16/AVERAGE(DV$12:DV$15)) -> 102.12992 | DS16: 2023 | DT16: ='[2]1.1'!D65 -> 118.78066 | DU16: ='[3]1.1'!D65 -> 117.28685 | DV16: ='[4]1.1'!D65 -> 115.49872 | DW16: ='[5]1.1'!D65 -> 113.546 | DX16: ='[6]1.1'!D65 -> 113.218 | DY16: ='[7]1.1'!D65 -> 113.488
A17: Total | B17: =100*((B7/1000)/B$11) -> -0.87772057 | C17: =100*((C7/1000)/C$11) -> -1.3405006 | D17: =100*((D7/1000)/D$11) -> -1.154803 | E17: =100*((E7/1000)/E$11) -> -1.1549143 | F17: =100*((F7/1000)/F$11) -> -1.1825073 | G17: =100*((G7/1000)/G$11) -> -0.97107057 | I17: 2013-14 | J17: =LEFT(I17,4) -> 2013 | K17: 79.2 | L17: 77 | M17: 70.718374 | N17: 56.326968 | P17: =K17-K16 -> 1.7 | Q17: =L17-L16 -> 0.8 | R17: =M17-M16 -> 0.99401484 | S17: =N17-N16 -> -2.4246345 | AA17: ='Aggregates (% GDP) Oct24'!B70 -> 2013-14 | AB17: =LEFT(AA17,4) -> 2013 | AC17: ='Aggregates (% GDP) Oct24'!F70 -> 1.4526683 | AD17: ='Aggregates (% GDP) Mar24'!F70 -> 1.4526683 | AE17: =AVERAGE($AD$8:$AD$27) -> 2.145275 | AH17: ='Aggregates (% GDP) Oct24'!B70 -> 2013-14 | AI17: =LEFT(AH17,4) -> 2013 | AJ17: =-('Aggregates (% GDP) Oct24'!M70-'Aggregates (% GDP) Oct24'!M69) -> -0.91274837 | BO17: 2020-21 | BP17: =100*(BS17/$BS$20) -> 112.15508 | BQ17: 100 | BS17: 6915.7804 | BU17: =+BU16+1 -> 14 | BV17: =VLOOKUP($BU17,$BY$4:$CA$34,2,FALSE) -> Lithuania | BW17: =VLOOKUP($BU17,$BY$4:$CA$34,3,FALSE) -> 3.8993341 | BY17: =RANK(CA17,$CA$4:$CA$34) -> 11 | BZ17: Greece | CA17: 4.0946323 | CC17: 2020-21 | CD17: =100*(CG17/$CG$20) -> 91.228347 | CE17: 100 | CG17: 1271.3142 | DE17: Total | DF17: =OBR_MAR24_ST3.9!F63 -> 1139.1216 | DL17: =100*(DT17/AVERAGE(DT$12:DT$15)) -> 101.07569 | DM17: =100*(DU17/AVERAGE(DU$12:DU$15)) -> 104.59545 | DN17: =100*(DV17/AVERAGE(DV$12:DV$15)) -> 103.3951 | DO17: =100*(DW17/AVERAGE(DW$12:DW$15)) -> 100.60646 | DT17: ='[2]1.1'!D66 -> 119.17263 | DU17: ='[3]1.1'!D66 -> 118.63565 | DV17: ='[4]1.1'!D66 -> 116.92951 | DW17: ='[5]1.1'!D66 -> 116.414 | DX17: ='[6]1.1'!D66 -> 116.107 | DY17: ='[7]1.1'!D66 -> 116.016
I18: 2014-15 | J18: =LEFT(I18,4) -> 2014 | K18: 81.6 | L18: 79.2 | M18: 72.913428 | N18: 53.4578 | P18: =K18-K17 -> 2.4 | Q18: =L18-L17 -> 2.2 | R18: =M18-M17 -> 2.1950537 | S18: =N18-N17 -> -2.8691685 | AA18: ='Aggregates (% GDP) Oct24'!B71 -> 2014-15 | AB18: =LEFT(AA18,4) -> 2014 | AC18: ='Aggregates (% GDP) Oct24'!F71 -> 1.929131 | AD18: ='Aggregates (% GDP) Mar24'!F71 -> 1.929131 | AE18: =AVERAGE($AD$8:$AD$27) -> 2.145275 | AH18: ='Aggregates (% GDP) Oct24'!B71 -> 2014-15 | AI18: =LEFT(AH18,4) -> 2014 | AJ18: =-('Aggregates (% GDP) Oct24'!M71-'Aggregates (% GDP) Oct24'!M70) -> 0.36659488 | BO18: 2021-22 | BP18: =100*(BS18/$BS$20) -> 110.01328 | BQ18: 100 | BS18: 6783.7111 | BU18: =+BU17+1 -> 15 | BV18: =VLOOKUP($BU18,$BY$4:$CA$34,2,FALSE) -> France | BW18: =VLOOKUP($BU18,$BY$4:$CA$34,3,FALSE) -> 3.7980744 | BY18: =RANK(CA18,$CA$4:$CA$34) -> 5 | BZ18: Hungary | CA18: 4.6181676 | CC18: 2021-22 | CD18: =100*(CG18/$CG$20) -> 93.606097 | CE18: 100 | CG18: 1304.4494 | DL18: =100*(DT18/AVERAGE(DT$12:DT$15)) -> 101.39913 | DM18: =100*(DU18/AVERAGE(DU$12:DU$15)) -> 105.43221 | DN18: =100*(DV18/AVERAGE(DV$12:DV$15)) -> 104.34503 | DO18: =100*(DW18/AVERAGE(DW$12:DW$15)) -> 101.41131 | DT18: ='[2]1.1'!D67 -> 119.55398 | DU18: ='[3]1.1'!D67 -> 119.58473 | DV18: ='[4]1.1'!D67 -> 118.00379 | DW18: ='[5]1.1'!D67 -> 117.34531 | DX18: ='[6]1.1'!D67 -> 116.994 | DY18: ='[7]1.1'!D67 -> 117.255
I19: 2015-16 | J19: =LEFT(I19,4) -> 2015 | K19: 81.3 | L19: 78.9 | M19: 73.981933 | N19: 51.950634 | P19: =K19-K18 -> -0.3 | Q19: =L19-L18 -> -0.3 | R19: =M19-M18 -> 1.0685047 | S19: =N19-N18 -> -1.5071661 | AA19: ='Aggregates (% GDP) Oct24'!B72 -> 2015-16 | AB19: =LEFT(AA19,4) -> 2015 | AC19: ='Aggregates (% GDP) Oct24'!F72 -> 1.6691683 | AD19: ='Aggregates (% GDP) Mar24'!F72 -> 1.6691683 | AE19: =AVERAGE($AD$8:$AD$27) -> 2.145275 | AH19: ='Aggregates (% GDP) Oct24'!B72 -> 2015-16 | AI19: =LEFT(AH19,4) -> 2015 | AJ19: =-('Aggregates (% GDP) Oct24'!M72-'Aggregates (% GDP) Oct24'!M71) -> -0.50198668 | BO19: 2022-23 | BP19: =100*(BS19/$BS$20) -> 103.59736 | BQ19: 100 | BS19: 6388.0887 | BU19: =+BU18+1 -> 16 | BV19: =VLOOKUP($BU19,$BY$4:$CA$34,2,FALSE) -> Netherlands | BW19: =VLOOKUP($BU19,$BY$4:$CA$34,3,FALSE) -> 3.7365702 | BY19: =RANK(CA19,$CA$4:$CA$34) -> 17 | BZ19: Iceland | CA19: 3.7317937 | CC19: 2022-23 | CD19: =100*(CG19/$CG$20) -> 101.01867 | CE19: 100 | CG19: 1407.7475 | DL19: =100*(DT19/AVERAGE(DT$12:DT$15)) -> 101.73375 | DM19: =100*(DU19/AVERAGE(DU$12:DU$15)) -> 105.90665 | DN19: =100*(DV19/AVERAGE(DV$12:DV$15)) -> 104.74908 | DO19: =100*(DW19/AVERAGE(DW$12:DW$15)) -> 102.52684 | DP19: =100*(DX19/AVERAGE(DX$12:DX$15)) -> 102.80916 | DT19: ='[2]1.1'!D68 -> 119.94851 | DU19: ='[3]1.1'!D68 -> 120.12287 | DV19: ='[4]1.1'!D68 -> 118.46074 | DW19: ='[5]1.1'!D68 -> 118.63611 | DX19: ='[6]1.1'!D68 -> 118.66336 | DY19: ='[7]1.1'!D68 -> 117.343
I20: 2016-17 | J20: =LEFT(I20,4) -> 2016 | K20: 83.5 | L20: 77.4 | M20: 74.221682 | N20: 61.429268 | P20: =K20-K19 -> 2.2 | Q20: =L20-L19 -> -1.5 | R20: =M20-M19 -> 0.23974945 | S20: =N20-N19 -> 9.4786344 | AA20: ='Aggregates (% GDP) Oct24'!B73 -> 2016-17 | AB20: =LEFT(AA20,4) -> 2016 | AC20: ='Aggregates (% GDP) Oct24'!F73 -> 1.8101862 | AD20: ='Aggregates (% GDP) Mar24'!F73 -> 1.8101862 | AE20: =AVERAGE($AD$8:$AD$27) -> 2.145275 | AH20: ='Aggregates (% GDP) Oct24'!B73 -> 2016-17 | AI20: =LEFT(AH20,4) -> 2016 | AJ20: =-('Aggregates (% GDP) Oct24'!M73-'Aggregates (% GDP) Oct24'!M72) -> -1.4760005 | BH20: Alternative survey from Ipsos: | BO20: 2023-24 | BP20: =100*(BS20/$BS$20) -> 100 | BQ20: 100 | BS20: 6166.2659 | BU20: =+BU19+1 -> 17 | BV20: =VLOOKUP($BU20,$BY$4:$CA$34,2,FALSE) -> Iceland | BW20: =VLOOKUP($BU20,$BY$4:$CA$34,3,FALSE) -> 3.7317937 | BY20: =RANK(CA20,$CA$4:$CA$34) -> 26 | BZ20: Ireland | CA20: 2.8311903 | CC20: 2023-24 | CD20: =100*(CG20/$CG$20) -> 100 | CE20: 100 | CG20: 1393.5518 | DK20: 2024 | DL20: =100*(DT20/AVERAGE(DT$12:DT$15)) -> 102.08982 | DM20: =100*(DU20/AVERAGE(DU$12:DU$15)) -> 106.22437 | DN20: =100*(DV20/AVERAGE(DV$12:DV$15)) -> 104.89539 | DO20: =100*(DW20/AVERAGE(DW$12:DW$15)) -> 103.55211 | DP20: =100*(DX20/AVERAGE(DX$12:DX$15)) -> 103.91807 | DS20: 2024 | DT20: ='[2]1.1'!D69 -> 120.36833 | DU20: ='[3]1.1'!D69 -> 120.48324 | DV20: ='[4]1.1'!D69 -> 118.6262 | DW20: ='[5]1.1'!D69 -> 119.82247 | DX20: ='[6]1.1'!D69 -> 119.94327 | DY20: ='[7]1.1'!D69 -> 117.324
I21: 2017-18 | J21: =LEFT(I21,4) -> 2017 | K21: 82.3 | L21: 73.7 | M21: 70.188464 | N21: 63.049303 | P21: =K21-K20 -> -1.2 | Q21: =L21-L20 -> -3.7 | R21: =M21-M20 -> -4.0332186 | S21: =N21-N20 -> 1.6200343 | AA21: ='Aggregates (% GDP) Oct24'!B74 -> 2017-18 | AB21: =LEFT(AA21,4) -> 2017 | AC21: ='Aggregates (% GDP) Oct24'!F74 -> 2.2089205 | AD21: ='Aggregates (% GDP) Mar24'!F74 -> 2.2089205 | AE21: =AVERAGE($AD$8:$AD$27) -> 2.145275 | AH21: ='Aggregates (% GDP) Oct24'!B74 -> 2017-18 | AI21: =LEFT(AH21,4) -> 2017 | AJ21: =-('Aggregates (% GDP) Oct24'!M74-'Aggregates (% GDP) Oct24'!M73) -> 0.080590287 | BH21: https://www.ipsos.com/sites/default/files/ct/news/documents/2024-10/Ipsos_Oct%2024_Pre-Budget_Polling.pdf | BO21: 2024-25 | BP21: =100*(BS21/$BS$20) -> 100.10405 | BQ21: 100 | BS21: 6172.6818 | BU21: =+BU20+1 -> 18 | BV21: =VLOOKUP($BU21,$BY$4:$CA$34,2,FALSE) -> Slovakia | BW21: =VLOOKUP($BU21,$BY$4:$CA$34,3,FALSE) -> 3.5965286 | BY21: =RANK(CA21,$CA$4:$CA$34) -> 29 | BZ21: Israel | CA21: 2.4090049 | CC21: 2024-25 | CD21: =100*(CG21/$CG$20) -> 102.14023 | CE21: 100 | CG21: 1423.377 | DL21: =100*(DT21/AVERAGE(DT$12:DT$15)) -> 102.45734 | DM21: =100*(DU21/AVERAGE(DU$12:DU$15)) -> 106.38371 | DN21: =100*(DV21/AVERAGE(DV$12:DV$15)) -> 105.17799 | DO21: =100*(DW21/AVERAGE(DW$12:DW$15)) -> 104.44265 | DP21: =100*(DX21/AVERAGE(DX$12:DX$15)) -> 104.66146 | DQ21: =100*(DY21/AVERAGE(DY$12:DY$15)) -> 103.11815 | DT21: ='[2]1.1'!D70 -> 120.80166 | DU21: ='[3]1.1'!D70 -> 120.66396 | DV21: ='[4]1.1'!D70 -> 118.94579 | DW21: ='[5]1.1'!D70 -> 120.85295 | DX21: ='[6]1.1'!D70 -> 120.8013 | DY21: ='[7]1.1'!D70 -> 119.02
I22: 2018-19 | J22: =LEFT(I22,4) -> 2018 | K22: 80.3 | L22: 72.3 | M22: 66.982374 | N22: 58.905421 | P22: =K22-K21 -> -2 | Q22: =L22-L21 -> -1.4 | R22: =M22-M21 -> -3.2060891 | S22: =N22-N21 -> -4.1438817 | AA22: ='Aggregates (% GDP) Oct24'!B75 -> 2018-19 | AB22: =LEFT(AA22,4) -> 2018 | AC22: ='Aggregates (% GDP) Oct24'!F75 -> 2.100128 | AD22: ='Aggregates (% GDP) Mar24'!F75 -> 2.100128 | AE22: =AVERAGE($AD$8:$AD$27) -> 2.145275 | AH22: ='Aggregates (% GDP) Oct24'!B75 -> 2018-19 | AI22: =LEFT(AH22,4) -> 2018 | AJ22: =-('Aggregates (% GDP) Oct24'!M75-'Aggregates (% GDP) Oct24'!M74) -> -0.22729184 | BO22: 2025-26 | BP22: =100*(BS22/$BS$20) -> 100.4689 | BQ22: 100 | BS22: 6195.1797 | BU22: =+BU21+1 -> 19 | BV22: =VLOOKUP($BU22,$BY$4:$CA$34,2,FALSE) -> US | BW22: =VLOOKUP($BU22,$BY$4:$CA$34,3,FALSE) -> 3.5916962 | BY22: =RANK(CA22,$CA$4:$CA$34) -> 2 | BZ22: Korea | CA22: 4.956172 | CC22: 2025-26 | CD22: =100*(CG22/$CG$20) -> 99.07125 | CE22: 100 | CG22: 1380.6092 | DL22: =100*(DT22/AVERAGE(DT$12:DT$15)) -> 102.84668 | DM22: =100*(DU22/AVERAGE(DU$12:DU$15)) -> 106.54329 | DN22: =100*(DV22/AVERAGE(DV$12:DV$15)) -> 105.41809 | DO22: =100*(DW22/AVERAGE(DW$12:DW$15)) -> 105.06931 | DP22: =100*(DX22/AVERAGE(DX$12:DX$15)) -> 105.36942 | DQ22: =100*(DY22/AVERAGE(DY$12:DY$15)) -> 103.78939 | DT22: ='[2]1.1'!D71 -> 121.26071 | DU22: ='[3]1.1'!D71 -> 120.84496 | DV22: ='[4]1.1'!D71 -> 119.21731 | DW22: ='[5]1.1'!D71 -> 121.57806 | DX22: ='[6]1.1'!D71 -> 121.61844 | DY22: ='[7]1.1'!D71 -> 119.79476
I23: 2019-20 | J23: =LEFT(I23,4) -> 2019 | K23: 85.2 | L23: 77.1 | M23: 74.576335 | N23: 67.191349 | P23: =K23-K22 -> 4.9 | Q23: =L23-L22 -> 4.8 | R23: =M23-M22 -> 7.5939601 | S23: =N23-N22 -> 8.2859278 | AA23: ='Aggregates (% GDP) Oct24'!B76 -> 2019-20 | AB23: =LEFT(AA23,4) -> 2019 | AC23: ='Aggregates (% GDP) Oct24'!F76 -> 1.8937327 | AD23: ='Aggregates (% GDP) Mar24'!F76 -> 1.8960049 | AE23: =AVERAGE($AD$8:$AD$27) -> 2.145275 | AH23: ='Aggregates (% GDP) Oct24'!B76 -> 2019-20 | AI23: =LEFT(AH23,4) -> 2019 | AJ23: =-('Aggregates (% GDP) Oct24'!M76-'Aggregates (% GDP) Oct24'!M75) -> 1.0124527 | BO23: 2026-27 | BP23: =100*(BS23/$BS$20) -> 100.98314 | BQ23: 100 | BS23: 6226.8892 | BU23: =+BU22+1 -> 20 | BV23: =VLOOKUP($BU23,$BY$4:$CA$34,2,FALSE) -> Spain | BW23: =VLOOKUP($BU23,$BY$4:$CA$34,3,FALSE) -> 3.3271083 | BY23: =RANK(CA23,$CA$4:$CA$34) -> 3 | BZ23: Latvia | CA23: 4.7532364 | CC23: 2026-27 | CD23: =100*(CG23/$CG$20) -> 97.164108 | CE23: 100 | CG23: 1354.0321 | DL23: =100*(DT23/AVERAGE(DT$12:DT$15)) -> 103.24778 | DM23: =100*(DU23/AVERAGE(DU$12:DU$15)) -> 106.7031 | DN23: =100*(DV23/AVERAGE(DV$12:DV$15)) -> 105.77381 | DO23: =100*(DW23/AVERAGE(DW$12:DW$15)) -> 105.6577 | DP23: =100*(DX23/AVERAGE(DX$12:DX$15)) -> 105.92792 | DQ23: =100*(DY23/AVERAGE(DY$12:DY$15)) -> 105.62769 | DT23: ='[2]1.1'!D72 -> 121.73362 | DU23: ='[3]1.1'!D72 -> 121.02622 | DV23: ='[4]1.1'!D72 -> 119.6196 | DW23: ='[5]1.1'!D72 -> 122.2589 | DX23: ='[6]1.1'!D72 -> 122.26306 | DY23: ='[7]1.1'!D72 -> 121.91654
I24: 2020-21 | J24: =LEFT(I24,4) -> 2020 | K24: 96.5 | L24: 86.5 | M24: 83.079863 | N24: 73.560623 | P24: =K24-K23 -> 11.3 | Q24: =L24-L23 -> 9.4 | R24: =M24-M23 -> 8.5035288 | S24: =N24-N23 -> 6.3692739 | AA24: ='Aggregates (% GDP) Oct24'!B77 -> 2020-21 | AB24: =LEFT(AA24,4) -> 2020 | AC24: ='Aggregates (% GDP) Oct24'!F77 -> 3.4413002 | AD24: ='Aggregates (% GDP) Mar24'!F77 -> 3.4519952 | AE24: =AVERAGE($AD$8:$AD$27) -> 2.145275 | AH24: ='Aggregates (% GDP) Oct24'!B77 -> 2020-21 | AI24: =LEFT(AH24,4) -> 2020 | AJ24: =-('Aggregates (% GDP) Oct24'!M77-'Aggregates (% GDP) Oct24'!M76) -> 12.342741 | BO24: 2027-28 | BP24: =100*(BS24/$BS$20) -> 101.50633 | BQ24: 100 | BS24: 6259.1505 | BU24: =+BU23+1 -> 21 | BV24: =VLOOKUP($BU24,$BY$4:$CA$34,2,FALSE) -> Denmark | BW24: =VLOOKUP($BU24,$BY$4:$CA$34,3,FALSE) -> 3.2815288 | BY24: =RANK(CA24,$CA$4:$CA$34) -> 14 | BZ24: Lithuania | CA24: 3.8993341 | CC24: 2027-28 | CD24: =100*(CG24/$CG$20) -> 94.874097 | CE24: 100 | CG24: 1322.1197 | DK24: 2025 | DL24: =100*(DT24/AVERAGE(DT$12:DT$15)) -> 103.66077 | DM24: =100*(DU24/AVERAGE(DU$12:DU$15)) -> 106.89517 | DN24: =100*(DV24/AVERAGE(DV$12:DV$15)) -> 106.14076 | DO24: =100*(DW24/AVERAGE(DW$12:DW$15)) -> 106.17542 | DP24: =100*(DX24/AVERAGE(DX$12:DX$15)) -> 106.38239 | DQ24: =100*(DY24/AVERAGE(DY$12:DY$15)) -> 106.92982 | DS24: 2025 | DT24: ='[2]1.1'!D73 -> 122.22056 | DU24: ='[3]1.1'!D73 -> 121.24407 | DV24: ='[4]1.1'!D73 -> 120.03458 | DW24: ='[5]1.1'!D73 -> 122.85797 | DX24: ='[6]1.1'!D73 -> 122.78761 | DY24: ='[7]1.1'!D73 -> 123.41947
I25: 2021-22 | J25: =LEFT(I25,4) -> 2021 | K25: 96.6 | L25: 83.2 | M25: 80.629863 | N25: 67.135032 | P25: =K25-K24 -> 0.1 | Q25: =L25-L24 -> -3.3 | R25: =M25-M24 -> -2.4500005 | S25: =N25-N24 -> -6.4255903 | AA25: ='Aggregates (% GDP) Oct24'!B78 -> 2021-22 | AB25: =LEFT(AA25,4) -> 2021 | AC25: ='Aggregates (% GDP) Oct24'!F78 -> 2.2556225 | AD25: ='Aggregates (% GDP) Mar24'!F78 -> 2.3021101 | AE25: =AVERAGE($AD$8:$AD$27) -> 2.145275 | AH25: ='Aggregates (% GDP) Oct24'!B78 -> 2021-22 | AI25: =LEFT(AH25,4) -> 2021 | AJ25: =-('Aggregates (% GDP) Oct24'!M78-'Aggregates (% GDP) Oct24'!M77) -> -10.050778 | BO25: 2028-29 | BP25: =100*(BS25/$BS$20) -> 101.96151 | BQ25: 100 | BS25: 6287.2179 | BU25: =+BU24+1 -> 22 | BV25: =VLOOKUP($BU25,$BY$4:$CA$34,2,FALSE) -> Australia | BW25: =VLOOKUP($BU25,$BY$4:$CA$34,3,FALSE) -> 3.1343494 | BY25: =RANK(CA25,$CA$4:$CA$34) -> 10 | BZ25: Luxembourg | CA25: 4.1890307 | CC25: 2028-29 | CD25: =100*(CG25/$CG$20) -> 91.6701 | CE25: 100 | CG25: 1277.4703 | DL25: =100*(DT25/AVERAGE(DT$12:DT$15)) -> 104.08578 | DM25: =100*(DU25/AVERAGE(DU$12:DU$15)) -> 107.1624 | DN25: =100*(DV25/AVERAGE(DV$12:DV$15)) -> 106.36054 | DO25: =100*(DW25/AVERAGE(DW$12:DW$15)) -> 106.68032 | DP25: =100*(DX25/AVERAGE(DX$12:DX$15)) -> 106.75948 | DQ25: =100*(DY25/AVERAGE(DY$12:DY$15)) -> 107.48393 | DT25: ='[2]1.1'!D74 -> 122.72166 | DU25: ='[3]1.1'!D74 -> 121.54718 | DV25: ='[4]1.1'!D74 -> 120.28313 | DW25: ='[5]1.1'!D74 -> 123.4422 | DX25: ='[6]1.1'!D74 -> 123.22286 | DY25: ='[7]1.1'!D74 -> 124.05903
I26: 2022-23 | J26: =LEFT(I26,4) -> 2022 | K26: 95.7 | L26: 84.8 | M26: 81.31136 | N26: 69.332774 | P26: =K26-K25 -> -0.9 | Q26: =L26-L25 -> 1.6 | R26: =M26-M25 -> 0.68149667 | S26: =N26-N25 -> 2.1977416 | AA26: ='Aggregates (% GDP) Oct24'!B79 -> 2022-23 | AB26: =LEFT(AA26,4) -> 2022 | AC26: ='Aggregates (% GDP) Oct24'!F79 -> 1.79943 | AD26: ='Aggregates (% GDP) Mar24'!F79 -> 1.7982158 | AE26: =AVERAGE($AD$8:$AD$27) -> 2.145275 | AH26: ='Aggregates (% GDP) Oct24'!B79 -> 2022-23 | AI26: =LEFT(AH26,4) -> 2022 | AJ26: =-('Aggregates (% GDP) Oct24'!M79-'Aggregates (% GDP) Oct24'!M78) -> -2.0594822 | BU26: =+BU25+1 -> 23 | BV26: =VLOOKUP($BU26,$BY$4:$CA$34,2,FALSE) -> Austria | BW26: =VLOOKUP($BU26,$BY$4:$CA$34,3,FALSE) -> 3.0502152 | BY26: =RANK(CA26,$CA$4:$CA$34) -> 16 | BZ26: Netherlands | CA26: 3.7365702 | DL26: =100*(DT26/AVERAGE(DT$12:DT$15)) -> 104.53335 | DM26: =100*(DU26/AVERAGE(DU$12:DU$15)) -> 107.48389 | DN26: =100*(DV26/AVERAGE(DV$12:DV$15)) -> 106.64407 | DO26: =100*(DW26/AVERAGE(DW$12:DW$15)) -> 107.08886 | DP26: =100*(DX26/AVERAGE(DX$12:DX$15)) -> 107.02354 | DQ26: =100*(DY26/AVERAGE(DY$12:DY$15)) -> 108.01804 | DT26: ='[2]1.1'!D75 -> 123.24936 | DU26: ='[3]1.1'!D75 -> 121.91182 | DV26: ='[4]1.1'!D75 -> 120.60378 | DW26: ='[5]1.1'!D75 -> 123.91492 | DX26: ='[6]1.1'!D75 -> 123.52764 | DY26: ='[7]1.1'!D75 -> 124.6755
I27: 2023-24 | J27: =LEFT(I27,4) -> 2023 | K27: 97.810368 | L27: 88.853958 | M27: 82.794795 | N27: 69.878037 | P27: =K27-K26 -> 2.1103679 | Q27: =L27-L26 -> 4.0539585 | R27: =M27-M26 -> 1.4834357 | S27: =N27-N26 -> 0.54526299 | AA27: ='Aggregates (% GDP) Oct24'!B80 -> 2023-24 | AB27: =LEFT(AA27,4) -> 2023 | AC27: ='Aggregates (% GDP) Oct24'!F80 -> 2.5565458 | AD27: ='Aggregates (% GDP) Mar24'!F80 -> 2.6051807 | AE27: =AVERAGE($AD$8:$AD$27) -> 2.145275 | AH27: ='Aggregates (% GDP) Oct24'!B80 -> 2023-24 | AI27: =LEFT(AH27,4) -> 2023 | AJ27: =-('Aggregates (% GDP) Oct24'!M80-'Aggregates (% GDP) Oct24'!M79) -> -0.20463319 | BU27: =+BU26+1 -> 24 | BV27: =VLOOKUP($BU27,$BY$4:$CA$34,2,FALSE) -> Portugal | BW27: =VLOOKUP($BU27,$BY$4:$CA$34,3,FALSE) -> 2.9605304 | BY27: =RANK(CA27,$CA$4:$CA$34) -> 7 | BZ27: Norway | CA27: 4.5081333 | DL27: =100*(DT27/AVERAGE(DT$12:DT$15)) -> 105.01421 | DM27: =100*(DU27/AVERAGE(DU$12:DU$15)) -> 107.86008 | DN27: =100*(DV27/AVERAGE(DV$12:DV$15)) -> 106.99168 | DO27: =100*(DW27/AVERAGE(DW$12:DW$15)) -> 107.50196 | DP27: =100*(DX27/AVERAGE(DX$12:DX$15)) -> 107.38918 | DQ27: =100*(DY27/AVERAGE(DY$12:DY$15)) -> 108.42934 | DT27: ='[2]1.1'!D76 -> 123.81631 | DU27: ='[3]1.1'!D76 -> 122.33851 | DV27: ='[4]1.1'!D76 -> 120.99689 | DW27: ='[5]1.1'!D76 -> 124.39293 | DX27: ='[6]1.1'!D76 -> 123.94967 | DY27: ='[7]1.1'!D76 -> 125.15023
I28: 2024-25 | J28: =LEFT(I28,4) -> 2024 | K28: 98.395587 | L28: 91.752913 | M28: 83.54479 | N28: 69.572316 | P28: =K28-K27 -> 0.58521875 | Q28: =L28-L27 -> 2.8989543 | R28: =M28-M27 -> 0.74999443 | S28: =N28-N27 -> -0.30572066 | AA28: ='Aggregates (% GDP) Oct24'!B81 -> 2024-25 | AB28: =LEFT(AA28,4) -> 2024 | AC28: ='Aggregates (% GDP) Oct24'!F81 -> 2.5585174 | AD28: ='Aggregates (% GDP) Mar24'!F81 -> 2.3896524 | AE28: =AVERAGE($AD$8:$AD$27) -> 2.145275 | AH28: ='Aggregates (% GDP) Oct24'!B81 -> 2024-25 | AI28: =LEFT(AH28,4) -> 2024 | AJ28: =-('Aggregates (% GDP) Oct24'!M81-'Aggregates (% GDP) Oct24'!M80) -> -0.18733025 | AK28: =-('Aggregates (% GDP) Mar24'!N81-'Aggregates (% GDP) Mar24'!N80) -> -1.1415503 | BU28: =+BU27+1 -> 25 | BV28: =VLOOKUP($BU28,$BY$4:$CA$34,2,FALSE) -> Switzerland | BW28: =VLOOKUP($BU28,$BY$4:$CA$34,3,FALSE) -> 2.9605102 | BY28: =RANK(CA28,$CA$4:$CA$34) -> 8 | BZ28: Poland | CA28: 4.29505 | DK28: 2026 | DL28: =100*(DT28/AVERAGE(DT$12:DT$15)) -> 105.56028 | DM28: =100*(DU28/AVERAGE(DU$12:DU$15)) -> 108.29152 | DN28: =100*(DV28/AVERAGE(DV$12:DV$15)) -> 107.45728 | DO28: =100*(DW28/AVERAGE(DW$12:DW$15)) -> 107.91957 | DP28: =100*(DX28/AVERAGE(DX$12:DX$15)) -> 107.80133 | DQ28: =100*(DY28/AVERAGE(DY$12:DY$15)) -> 108.88743 | DS28: 2026 | DT28: ='[2]1.1'!D77 -> 124.46016 | DU28: ='[3]1.1'!D77 -> 122.82787 | DV28: ='[4]1.1'!D77 -> 121.52344 | DW28: ='[5]1.1'!D77 -> 124.87617 | DX28: ='[6]1.1'!D77 -> 124.42537 | DY28: ='[7]1.1'!D77 -> 125.67896
I29: 2025-26 | J29: =LEFT(I29,4) -> 2025 | K29: 96.921744 | L29: 93.140493 | M29: 83.791436 | N29: 69.261948 | P29: =K29-K28 -> -1.4738427 | Q29: =L29-L28 -> 1.3875805 | R29: =M29-M28 -> 0.24664648 | S29: =N29-N28 -> -0.31036835 | AA29: ='Aggregates (% GDP) Oct24'!B82 -> 2025-26 | AB29: =LEFT(AA29,4) -> 2025 | AC29: ='Aggregates (% GDP) Oct24'!F82 -> 2.6919811 | AD29: ='Aggregates (% GDP) Mar24'!F82 -> 2.1199635 | AE29: =AVERAGE($AD$8:$AD$27) -> 2.145275 | AH29: ='Aggregates (% GDP) Oct24'!B82 -> 2025-26 | AI29: =LEFT(AH29,4) -> 2025 | AJ29: =-('Aggregates (% GDP) Oct24'!M82-'Aggregates (% GDP) Oct24'!M81) -> -0.76306604 | AK29: =-('Aggregates (% GDP) Mar24'!N82-'Aggregates (% GDP) Mar24'!N81) -> -0.57313333 | BU29: =+BU28+1 -> 26 | BV29: =VLOOKUP($BU29,$BY$4:$CA$34,2,FALSE) -> Ireland | BW29: =VLOOKUP($BU29,$BY$4:$CA$34,3,FALSE) -> 2.8311903 | BY29: =RANK(CA29,$CA$4:$CA$34) -> 24 | BZ29: Portugal | CA29: 2.9605304 | DL29: =100*(DT29/AVERAGE(DT$12:DT$15)) -> 106.1303 | DM29: =100*(DU29/AVERAGE(DU$12:DU$15)) -> 108.83298 | DN29: =100*(DV29/AVERAGE(DV$12:DV$15)) -> 107.93466 | DO29: =100*(DW29/AVERAGE(DW$12:DW$15)) -> 108.33983 | DP29: =100*(DX29/AVERAGE(DX$12:DX$15)) -> 108.25083 | DQ29: =100*(DY29/AVERAGE(DY$12:DY$15)) -> 109.14042 | DT29: ='[2]1.1'!D78 -> 125.13224 | DU29: ='[3]1.1'!D78 -> 123.44201 | DV29: ='[4]1.1'!D78 -> 122.06331 | DW29: ='[5]1.1'!D78 -> 125.36246 | DX29: ='[6]1.1'!D78 -> 124.94419 | DY29: ='[7]1.1'!D78 -> 125.97096
I30: 2026-27 | J30: =LEFT(I30,4) -> 2026 | K30: 96.966301 | L30: 94.384386 | M30: 84.227751 | N30: 69.189137 | P30: =K30-K29 -> 0.044556571 | Q30: =L30-L29 -> 1.2438926 | R30: =M30-M29 -> 0.43631488 | S30: =N30-N29 -> -0.072811329 | AA30: ='Aggregates (% GDP) Oct24'!B83 -> 2026-27 | AB30: =LEFT(AA30,4) -> 2026 | AC30: ='Aggregates (% GDP) Oct24'!F83 -> 2.7207402 | AD30: ='Aggregates (% GDP) Mar24'!F83 -> 1.9804928 | AE30: =AVERAGE($AD$8:$AD$27) -> 2.145275 | AH30: ='Aggregates (% GDP) Oct24'!B83 -> 2026-27 | AI30: =LEFT(AH30,4) -> 2026 | AJ30: =-('Aggregates (% GDP) Oct24'!M83-'Aggregates (% GDP) Oct24'!M82) -> -0.52998375 | AK30: =-('Aggregates (% GDP) Mar24'!N83-'Aggregates (% GDP) Mar24'!N82) -> -0.3785978 | BU30: =+BU29+1 -> 27 | BV30: =VLOOKUP($BU30,$BY$4:$CA$34,2,FALSE) -> UK | BW30: =VLOOKUP($BU30,$BY$4:$CA$34,3,FALSE) -> 2.814318 | BY30: =RANK(CA30,$CA$4:$CA$34) -> 18 | BZ30: Slovakia | CA30: 3.5965286 | DL30: =100*(DT30/AVERAGE(DT$12:DT$15)) -> 106.71402 | DM30: =100*(DU30/AVERAGE(DU$12:DU$15)) -> 109.37715 | DN30: =100*(DV30/AVERAGE(DV$12:DV$15)) -> 108.36016 | DO30: =100*(DW30/AVERAGE(DW$12:DW$15)) -> 108.75423 | DP30: =100*(DX30/AVERAGE(DX$12:DX$15)) -> 108.65971 | DQ30: =100*(DY30/AVERAGE(DY$12:DY$15)) -> 109.54207 | DT30: ='[2]1.1'!D79 -> 125.82047 | DU30: ='[3]1.1'!D79 -> 124.05922 | DV30: ='[4]1.1'!D79 -> 122.5445 | DW30: ='[5]1.1'!D79 -> 125.84197 | DX30: ='[6]1.1'!D79 -> 125.41612 | DY30: ='[7]1.1'!D79 -> 126.43455
I31: 2027-28 | J31: =LEFT(I31,4) -> 2027 | K31: 97.245969 | L31: 95.054134 | M31: 84.100989 | N31: 68.709184 | P31: =K31-K30 -> 0.27966853 | Q31: =L31-L30 -> 0.66974783 | R31: =M31-M30 -> -0.12676194 | S31: =N31-N30 -> -0.47995311 | AA31: ='Aggregates (% GDP) Oct24'!B84 -> 2027-28 | AB31: =LEFT(AA31,4) -> 2027 | AC31: ='Aggregates (% GDP) Oct24'!F84 -> 2.6234059 | AD31: ='Aggregates (% GDP) Mar24'!F84 -> 1.8204393 | AE31: =AVERAGE($AD$8:$AD$27) -> 2.145275 | AH31: ='Aggregates (% GDP) Oct24'!B84 -> 2027-28 | AI31: =LEFT(AH31,4) -> 2027 | AJ31: =-('Aggregates (% GDP) Oct24'!M84-'Aggregates (% GDP) Oct24'!M83) -> -0.69853767 | AK31: =-('Aggregates (% GDP) Mar24'!N84-'Aggregates (% GDP) Mar24'!N83) -> -0.60360284 | BU31: =+BU30+1 -> 28 | BV31: =VLOOKUP($BU31,$BY$4:$CA$34,2,FALSE) -> Italy | BW31: =VLOOKUP($BU31,$BY$4:$CA$34,3,FALSE) -> 2.7823445 | BY31: =RANK(CA31,$CA$4:$CA$34) -> 9 | BZ31: Slovenia | CA31: 4.2756384 | DL31: =100*(DT31/AVERAGE(DT$12:DT$15)) -> 107.31162 | DM31: =100*(DU31/AVERAGE(DU$12:DU$15)) -> 109.81466 | DN31: =100*(DV31/AVERAGE(DV$12:DV$15)) -> 108.94983 | DO31: =100*(DW31/AVERAGE(DW$12:DW$15)) -> 109.16886 | DP31: =100*(DX31/AVERAGE(DX$12:DX$15)) -> 109.07563 | DQ31: =100*(DY31/AVERAGE(DY$12:DY$15)) -> 109.97123 | DT31: ='[2]1.1'!D80 -> 126.52506 | DU31: ='[3]1.1'!D80 -> 124.55545 | DV31: ='[4]1.1'!D80 -> 123.21137 | DW31: ='[5]1.1'!D80 -> 126.32174 | DX31: ='[6]1.1'!D80 -> 125.89618 | DY31: ='[7]1.1'!D80 -> 126.9299
I32: 2028-29 | J32: =LEFT(I32,4) -> 2028 | K32: 97.339932 | L32: 95.607594 | M32: 83.872927 | N32: 68.377937 | P32: =K32-K31 -> 0.093962633 | Q32: =L32-L31 -> 0.55346059 | R32: =M32-M31 -> -0.22806211 | S32: =N32-N31 -> -0.33124701 | AA32: ='Aggregates (% GDP) Oct24'!B85 -> 2028-29 | AB32: =LEFT(AA32,4) -> 2028 | AC32: ='Aggregates (% GDP) Oct24'!F85 -> 2.4777518 | AD32: ='Aggregates (% GDP) Mar24'!F85 -> 1.6542068 | AE32: =AVERAGE($AD$8:$AD$27) -> 2.145275 | AH32: ='Aggregates (% GDP) Oct24'!B85 -> 2028-29 | AI32: =LEFT(AH32,4) -> 2028 | AJ32: =-('Aggregates (% GDP) Oct24'!M85-'Aggregates (% GDP) Oct24'!M84) -> -0.21076074 | AK32: =-('Aggregates (% GDP) Mar24'!N85-'Aggregates (% GDP) Mar24'!N84) -> -0.43227169 | BU32: =+BU31+1 -> 29 | BV32: =VLOOKUP($BU32,$BY$4:$CA$34,2,FALSE) -> Israel | BW32: =VLOOKUP($BU32,$BY$4:$CA$34,3,FALSE) -> 2.4090049 | BY32: =RANK(CA32,$CA$4:$CA$34) -> 20 | BZ32: Spain | CA32: 3.3271083 | DK32: 2027 | DL32: =100*(DT32/AVERAGE(DT$12:DT$15)) -> 107.91256 | DM32: =100*(DU32/AVERAGE(DU$12:DU$15)) -> 110.19901 | DN32: =100*(DV32/AVERAGE(DV$12:DV$15)) -> 109.48824 | DO32: =100*(DW32/AVERAGE(DW$12:DW$15)) -> 109.58372 | DP32: =100*(DX32/AVERAGE(DX$12:DX$15)) -> 109.4985 | DQ32: =100*(DY32/AVERAGE(DY$12:DY$15)) -> 110.42759 | DS32: 2027 | DT32: ='[2]1.1'!D81 -> 127.2336 | DU32: ='[3]1.1'!D81 -> 124.9914 | DV32: ='[4]1.1'!D81 -> 123.82025 | DW32: ='[5]1.1'!D81 -> 126.80178 | DX32: ='[6]1.1'!D81 -> 126.38427 | DY32: ='[7]1.1'!D81 -> 127.45663
I33: 2029-30 | J33: =LEFT(I33,4) -> 2029 | K33: 97.147985 | L33: 95.774656 | M33: 83.417751 | N33: 67.888123 | P33: =K33-K32 -> -0.19194677 | Q33: =L33-L32 -> 0.1670617 | R33: =M33-M32 -> -0.45517556 | S33: =N33-N32 -> -0.48981329 | AA33: ='Aggregates (% GDP) Oct24'!B86 -> 2029-30 | AB33: =LEFT(AA33,4) -> 2029 | AC33: ='Aggregates (% GDP) Oct24'!F86 -> 2.3699287 | AE33: =AVERAGE($AD$8:$AD$27) -> 2.145275 | AH33: ='Aggregates (% GDP) Oct24'!B86 -> 2029-30 | AI33: =LEFT(AH33,4) -> 2029 | AJ33: =-('Aggregates (% GDP) Oct24'!M86-'Aggregates (% GDP) Oct24'!M85) -> -0.18679438 | BU33: =+BU32+1 -> 30 | BV33: =VLOOKUP($BU33,$BY$4:$CA$34,2,FALSE) -> Belgium | BW33: =VLOOKUP($BU33,$BY$4:$CA$34,3,FALSE) -> 2.3573553 | BY33: =RANK(CA33,$CA$4:$CA$34) -> 6 | BZ33: Sweden | CA33: 4.5506017 | DM33: =100*(DU33/AVERAGE(DU$12:DU$15)) -> 110.5847 | DN33: =100*(DV33/AVERAGE(DV$12:DV$15)) -> 110.02931 | DO33: =100*(DW33/AVERAGE(DW$12:DW$15)) -> 109.97769 | DP33: =100*(DX33/AVERAGE(DX$12:DX$15)) -> 109.90615 | DQ33: =100*(DY33/AVERAGE(DY$12:DY$15)) -> 110.88451 | DU33: ='[3]1.1'!D82 -> 125.42887 | DV33: ='[4]1.1'!D82 -> 124.43215 | DW33: ='[5]1.1'!D82 -> 127.25766 | DX33: ='[6]1.1'!D82 -> 126.85478 | DY33: ='[7]1.1'!D82 -> 127.98401
BU34: =+BU33+1 -> 31 | BV34: =VLOOKUP($BU34,$BY$4:$CA$34,2,FALSE) -> Germany | BW34: =VLOOKUP($BU34,$BY$4:$CA$34,3,FALSE) -> 2.2421639 | BY34: =RANK(CA34,$CA$4:$CA$34) -> 25 | BZ34: Switzerland | CA34: 2.9605102 | DM34: =100*(DU34/AVERAGE(DU$12:DU$15)) -> 110.97175 | DN34: =100*(DV34/AVERAGE(DV$12:DV$15)) -> 110.46472 | DO34: =100*(DW34/AVERAGE(DW$12:DW$15)) -> 110.38951 | DP34: =100*(DX34/AVERAGE(DX$12:DX$15)) -> 110.32585 | DQ34: =100*(DY34/AVERAGE(DY$12:DY$15)) -> 111.33713 | DU34: ='[3]1.1'!D83 -> 125.86787 | DV34: ='[4]1.1'!D83 -> 124.92455 | DW34: ='[5]1.1'!D83 -> 127.73418 | DX34: ='[6]1.1'!D83 -> 127.3392 | DY34: ='[7]1.1'!D83 -> 128.50642
DM35: =100*(DU35/AVERAGE(DU$12:DU$15)) -> 111.41564 | DN35: =100*(DV35/AVERAGE(DV$12:DV$15)) -> 110.95869 | DO35: =100*(DW35/AVERAGE(DW$12:DW$15)) -> 110.82074 | DP35: =100*(DX35/AVERAGE(DX$12:DX$15)) -> 110.7659 | DQ35: =100*(DY35/AVERAGE(DY$12:DY$15)) -> 111.81399 | DU35: ='[3]1.1'!D84 -> 126.37134 | DV35: ='[4]1.1'!D84 -> 125.48319 | DW35: ='[5]1.1'!D84 -> 128.23318 | DX35: ='[6]1.1'!D84 -> 127.84711 | DY35: ='[7]1.1'!D84 -> 129.05683
I36: 23-24 | K36: 97.6 | L36: 88.8 | M36: 82.9 | N36: 69.5 | DK36: 2028 | DM36: =100*(DU36/AVERAGE(DU$12:DU$15)) -> 111.8613 | DN36: =100*(DV36/AVERAGE(DV$12:DV$15)) -> 111.45645 | DO36: =100*(DW36/AVERAGE(DW$12:DW$15)) -> 111.27118 | DP36: =100*(DX36/AVERAGE(DX$12:DX$15)) -> 111.22606 | DQ36: =100*(DY36/AVERAGE(DY$12:DY$15)) -> 112.31481 | DS36: 2028 | DU36: ='[3]1.1'!D85 -> 126.87682 | DV36: ='[4]1.1'!D85 -> 126.0461 | DW36: ='[5]1.1'!D85 -> 128.75439 | DX36: ='[6]1.1'!D85 -> 128.37823 | DY36: ='[7]1.1'!D85 -> 129.63488
I37: 24-25 | K37: 98.8 | L37: 91.7 | M37: 83.6 | N37: 70.2 | DO37: =100*(DW37/AVERAGE(DW$12:DW$15)) -> 111.72668 | DP37: =100*(DX37/AVERAGE(DX$12:DX$15)) -> 111.72816 | DQ37: =100*(DY37/AVERAGE(DY$12:DY$15)) -> 112.82674 | DW37: ='[5]1.1'!D86 -> 129.28145 | DX37: ='[6]1.1'!D86 -> 128.95775 | DY37: ='[7]1.1'!D86 -> 130.22575
I38: 25-26 | K38: 96.4 | L38: 92.8 | M38: 83.2 | N38: 69.5 | DO38: =100*(DW38/AVERAGE(DW$12:DW$15)) -> 112.18004 | DP38: =100*(DX38/AVERAGE(DX$12:DX$15)) -> 112.15481 | DQ38: =100*(DY38/AVERAGE(DY$12:DY$15)) -> 113.32308 | DW38: ='[5]1.1'!D87 -> 129.80605 | DX38: ='[6]1.1'!D87 -> 129.4502 | DY38: ='[7]1.1'!D87 -> 130.79864
I39: 26-27 | K39: 95.5 | L39: 93.2 | M39: 82.1 | N39: 67.9 | DO39: =100*(DW39/AVERAGE(DW$12:DW$15)) -> 112.63557 | DP39: =100*(DX39/AVERAGE(DX$12:DX$15)) -> 112.60215 | DQ39: =100*(DY39/AVERAGE(DY$12:DY$15)) -> 113.82968 | DW39: ='[5]1.1'!D88 -> 130.33315 | DX39: ='[6]1.1'!D88 -> 129.96653 | DY39: ='[7]1.1'!D88 -> 131.38336
I40: 27-28 | K40: 95.1 | L40: 93.2 | M40: 80.6 | N40: 66 | DK40: 2029 | DO40: =100*(DW40/AVERAGE(DW$12:DW$15)) -> 113.09324 | DP40: =100*(DX40/AVERAGE(DX$12:DX$15)) -> 113.06995 | DQ40: =100*(DY40/AVERAGE(DY$12:DY$15)) -> 114.3464 | DS40: 2029 | DW40: ='[5]1.1'!D89 -> 130.86273 | DX40: ='[6]1.1'!D89 -> 130.50646 | DY40: ='[7]1.1'!D89 -> 131.97976
...

Sheet GMWA
A1: Location | B1: Indicator | C1: Scenario | D1: Units | E1: Scale | F1: Measurement | G1: 1973 | H1: 1974 | I1: 1975 | J1: 1976 | K1: 1977 | L1: 1978 | M1: 1979 | N1: 1980 | O1: 1981 | P1: 1982 | Q1: 1983 | R1: 1984 | S1: 1985 | T1: 1986 | U1: 1987 | V1: 1988 | W1: 1989 | X1: 1990 | Y1: 1991 | Z1: 1992 | AA1: 1993 | AB1: 1994 | AC1: 1995 | AD1: 1996 | AE1: 1997 | AF1: 1998 | AG1: 1999 | AH1: 2000 | AI1: 2001 | AJ1: 2002 | AK1: 2003 | AL1: 2004 | AM1: 2005 | AN1: 2006 | AO1: 2007 | AP1: 2008 | AQ1: 2009 | AR1: 2010 | AS1: 2011 | AT1: 2012 | AU1: 2013 | AV1: 2014 | AW1: 2015 | AX1: 2016 | AY1: 2017 | AZ1: 2018 | BA1: 2019 | BB1: 2020 | BC1: 2021 | BD1: 2022 | BE1: 2023 | BF1: 2024 | BG1: 2025 | BH1: 2026 | BI1: 2027 | BJ1: 2028 | BK1: 2029 | BL1: 2030 | BM1: 2031 | BN1: 2032 | BO1: 2033 | BP1: 2034 | BQ1: 2035 | BR1: 2036 | BS1: 2037 | BT1: 2038 | BU1: 2039 | BV1: 2040 | BW1: 2041 | BX1: 2042 | BY1: 2043 | BZ1: 2044 | CA1: 2045 | CB1: 2046 | CC1: 2047 | CD1: 2048 | CE1: 2049 | CF1: 2050 | CG1: Source | CH1: Seasonally adjusted | CI1: Base year price | CJ1: Base year index | CK1: Historical end year | CL1: Historical end quarter | CM1: Date of last update | CN1: Source details | CO1: Additional source details | CP1: Location code | CQ1: Indicator code | CR1: Databank code
