Workbook
Name _DLX1.INC: HAVERM!$A$1:$AG$6
Name Data: [1]sheet0!$C$2

Sheet >> CHARTS

Sheet >> DATA

Sheet Chart Data
A1: Quoted mortgage rates | H1: Margins | Q1: Diff vs expiring deal | U1: Interest rates | Z1: Interest rates - change since Bank Rate started to rise | AF1: Interest rates
A2: End-date: | B2: =HAVERM!B4 -> Jun-2025 | C2: =HAVERM!C4 -> Jun-2025 | D2: =HAVERM!D4 -> Jun-2025 | Q2: Standard variable rate * | R2: 2 year fix, 75% LTV ** | S2: 5 year fix, 75% LTV ** | V2: =HAVERM!E4 -> Jun-2025 <- 10-Jul-2025 | W2: =HAVERM!H4 -> May-2025 | X2: =HAVERM!I4 -> May-2025
B3: Standard variable rate | C3: 2 year fix, 75% LTV | D3: 5 year fix, 75% LTV | E3: 2yr | F3: 5yr | H3: Standard variable rate | I3: 2 year fix, 75% LTV | J3: 5 year fix, 75% LTV | L3: Bank Rate | M3: 2 year swap | N3: 5 year swap | Q3: Standard variable rate | R3: 2 year fix, 75% LTV | S3: 5 year fix, 75% LTV | V3: Bank Rate | W3: Non-financial corporations | X3: Secured household | AA3: Companies | AB3: Household mortgages | AC3: Hiking cycle | AD3: Cutting cycle | AG3: Secured household | AH3: Non-financial corporations
A4: 41640 | B4: =HAVERM!B295 -> 4.41 | C4: =HAVERM!C295 -> 2.37 | D4: =HAVERM!D295 -> 3.34 | H4: =B4-L4 -> 3.91 | I4: =C4-M4 -> #N/A | J4: =D4-N4 -> #N/A | L4: =HAVERM!E295 -> 0.5 | M4: =HAVERM!F295 -> #N/A | N4: =HAVERM!G295 -> #N/A | P4: 41640 | U4: 43466 | V4: =HAVERM!E355 -> 0.75 | W4: =HAVERM!H355 -> 3.35 | X4: =HAVERM!I355 -> 2.48 | Z4: 44531 | AA4: =W39-W$38 -> 0.05 | AB4: =X39-X$38 -> -0.01 | AC4: 1000 | AF4: 43466 | AG4: =Data!G191 -> 2.463333 | AH4: =Data!H191 -> 3.343333
A5: 41671 | B5: =HAVERM!B296 -> 4.43 | C5: =HAVERM!C296 -> 2.38 | D5: =HAVERM!D296 -> 3.45 | H5: =B5-L5 -> 3.93 | I5: =C5-M5 -> #N/A | J5: =D5-N5 -> #N/A | L5: =HAVERM!E296 -> 0.5 | M5: =HAVERM!F296 -> #N/A | N5: =HAVERM!G296 -> #N/A | P5: 41671 | U5: 43497 | V5: =HAVERM!E356 -> 0.75 | W5: =HAVERM!H356 -> 3.34 | X5: =HAVERM!I356 -> 2.46 | Z5: 44562 | AA5: =W40-W$38 -> 0.11 | AB5: =X40-X$38 -> -0.01 | AC5: 1000 | AF5: 43556 | AG5: =Data!G192 -> 2.436667 | AH5: =Data!H192 -> 3.323333
A6: 41699 | B6: =HAVERM!B297 -> 4.43 | C6: =HAVERM!C297 -> 2.37 | D6: =HAVERM!D297 -> 3.48 | H6: =B6-L6 -> 3.93 | I6: =C6-M6 -> #N/A | J6: =D6-N6 -> #N/A | L6: =HAVERM!E297 -> 0.5 | M6: =HAVERM!F297 -> #N/A | N6: =HAVERM!G297 -> #N/A | P6: 41699 | U6: 43525 | V6: =HAVERM!E357 -> 0.75 | W6: =HAVERM!H357 -> 3.34 | X6: =HAVERM!I357 -> 2.45 | Z6: 44593 | AA6: =W41-W$38 -> 0.25 | AB6: =X41-X$38 -> 0 | AC6: 1000 | AF6: 43647 | AG6: =Data!G193 -> 2.413333 | AH6: =Data!H193 -> 3.28
A7: 41730 | B7: =HAVERM!B298 -> 4.43 | C7: =HAVERM!C298 -> 2.54 | D7: =HAVERM!D298 -> 3.69 | H7: =B7-L7 -> 3.93 | I7: =C7-M7 -> #N/A | J7: =D7-N7 -> #N/A | L7: =HAVERM!E298 -> 0.5 | M7: =HAVERM!F298 -> #N/A | N7: =HAVERM!G298 -> #N/A | P7: 41730 | U7: 43556 | V7: =HAVERM!E358 -> 0.75 | W7: =HAVERM!H358 -> 3.34 | X7: =HAVERM!I358 -> 2.45 | Z7: 44621 | AA7: =W42-W$38 -> 0.35 | AB7: =X42-X$38 -> 0.03 | AC7: 1000 | AF7: 43739 | AG7: =Data!G194 -> 2.386667 | AH7: =Data!H194 -> 3.26
A8: 41760 | B8: =HAVERM!B299 -> 4.42 | C8: =HAVERM!C299 -> 2.56 | D8: =HAVERM!D299 -> 3.72 | H8: =B8-L8 -> 3.92 | I8: =C8-M8 -> #N/A | J8: =D8-N8 -> #N/A | L8: =HAVERM!E299 -> 0.5 | M8: =HAVERM!F299 -> #N/A | N8: =HAVERM!G299 -> #N/A | P8: 41760 | U8: 43586 | V8: =HAVERM!E359 -> 0.75 | W8: =HAVERM!H359 -> 3.32 | X8: =HAVERM!I359 -> 2.43 | Z8: 44652 | AA8: =W43-W$38 -> 0.45 | AB8: =X43-X$38 -> 0.03 | AC8: 1000 | AF8: 43831 | AG8: =Data!G195 -> 2.356667 | AH8: =Data!H195 -> 3.266667
A9: 41791 | B9: =HAVERM!B300 -> 4.36 | C9: =HAVERM!C300 -> 2.6 | D9: =HAVERM!D300 -> 3.69 | H9: =B9-L9 -> 3.86 | I9: =C9-M9 -> #N/A | J9: =D9-N9 -> #N/A | L9: =HAVERM!E300 -> 0.5 | M9: =HAVERM!F300 -> #N/A | N9: =HAVERM!G300 -> #N/A | P9: 41791 | U9: 43617 | V9: =HAVERM!E360 -> 0.75 | W9: =HAVERM!H360 -> 3.31 | X9: =HAVERM!I360 -> 2.43 | Z9: 44682 | AA9: =W44-W$38 -> 0.65 | AB9: =X44-X$38 -> 0.06 | AC9: 1000 | AF9: 43922 | AG9: =Data!G196 -> 2.183333 | AH9: =Data!H196 -> 2.876667
A10: 41821 | B10: =HAVERM!B301 -> 4.45 | C10: =HAVERM!C301 -> 2.54 | D10: =HAVERM!D301 -> 3.78 | H10: =B10-L10 -> 3.95 | I10: =C10-M10 -> #N/A | J10: =D10-N10 -> #N/A | L10: =HAVERM!E301 -> 0.5 | M10: =HAVERM!F301 -> #N/A | N10: =HAVERM!G301 -> #N/A | P10: 41821 | U10: 43647 | V10: =HAVERM!E361 -> 0.75 | W10: =HAVERM!H361 -> 3.3 | X10: =HAVERM!I361 -> 2.42 | Z10: 44713 | AA10: =W45-W$38 -> 0.78 | AB10: =X45-X$38 -> 0.1 | AC10: 1000 | AF10: 44013 | AG10: =Data!G197 -> 2.143333 | AH10: =Data!H197 -> 2.57
A11: 41852 | B11: =HAVERM!B302 -> 4.45 | C11: =HAVERM!C302 -> 2.54 | D11: =HAVERM!D302 -> 3.76 | H11: =B11-L11 -> 3.95 | I11: =C11-M11 -> 1.5588 | J11: =D11-N11 -> 2.15 | L11: =HAVERM!E302 -> 0.5 | M11: =HAVERM!F302 -> 0.9812 | N11: =HAVERM!G302 -> 1.61 | P11: 41852 | U11: 43678 | V11: =HAVERM!E362 -> 0.75 | W11: =HAVERM!H362 -> 3.27 | X11: =HAVERM!I362 -> 2.42 | Z11: 44743 | AA11: =W46-W$38 -> 0.86 | AB11: =X46-X$38 -> 0.11 | AC11: 1000 | AF11: 44105 | AG11: =Data!G198 -> 2.12 | AH11: =Data!H198 -> 2.453333
A12: 41883 | B12: =HAVERM!B303 -> 4.52 | C12: =HAVERM!C303 -> 2.46 | D12: =HAVERM!D303 -> 3.61 | H12: =B12-L12 -> 4.02 | I12: =C12-M12 -> 1.4812727 | J12: =D12-N12 -> 1.9375955 | L12: =HAVERM!E303 -> 0.5 | M12: =HAVERM!F303 -> 0.97872727 | N12: =HAVERM!G303 -> 1.6724045 | P12: 41883 | U12: 43709 | V12: =HAVERM!E363 -> 0.75 | W12: =HAVERM!H363 -> 3.27 | X12: =HAVERM!I363 -> 2.4 | Z12: 44774 | AA12: =W47-W$38 -> 1.17 | AB12: =X47-X$38 -> 0.16 | AC12: 1000 | AF12: 44197 | AG12: =Data!G199 -> 2.09 | AH12: =Data!H199 -> 2.426667
A13: 41913 | B13: =HAVERM!B304 -> 4.53 | C13: =HAVERM!C304 -> 2.21 | D13: =HAVERM!D304 -> 3.27 | H13: =B13-L13 -> 4.03 | I13: =C13-M13 -> 1.3656522 | J13: =D13-N13 -> 1.8341696 | L13: =HAVERM!E304 -> 0.5 | M13: =HAVERM!F304 -> 0.84434783 | N13: =HAVERM!G304 -> 1.4358304 | P13: 41913 | U13: 43739 | V13: =HAVERM!E364 -> 0.75 | W13: =HAVERM!H364 -> 3.26 | X13: =HAVERM!I364 -> 2.39 | Z13: 44805 | AA13: =W48-W$38 -> 1.38 | AB13: =X48-X$38 -> 0.23 | AC13: 1000 | AF13: 44287 | AG13: =Data!G200 -> 2.073333 | AH13: =Data!H200 -> 2.49
A14: 41944 | B14: =HAVERM!B305 -> 4.49 | C14: =HAVERM!C305 -> 2.17 | D14: =HAVERM!D305 -> 3.21 | H14: =B14-L14 -> 3.99 | I14: =C14-M14 -> 1.4026833 | J14: =D14-N14 -> 1.8787167 | L14: =HAVERM!E305 -> 0.5 | M14: =HAVERM!F305 -> 0.76731667 | N14: =HAVERM!G305 -> 1.3312833 | P14: 41944 | U14: 43770 | V14: =HAVERM!E365 -> 0.75 | W14: =HAVERM!H365 -> 3.24 | X14: =HAVERM!I365 -> 2.4 | Z14: 44835 | AA14: =W49-W$38 -> 1.63 | AB14: =X49-X$38 -> 0.27 | AC14: 1000 | AF14: 44378 | AG14: =Data!G201 -> 2.053333 | AH14: =Data!H201 -> 2.616667
A15: 41974 | B15: =HAVERM!B306 -> 4.48 | C15: =HAVERM!C306 -> 2.08 | D15: =HAVERM!D306 -> 3.21 | H15: =B15-L15 -> 3.98 | I15: =C15-M15 -> 1.3790636 | J15: =D15-N15 -> 2.0094227 | L15: =HAVERM!E306 -> 0.5 | M15: =HAVERM!F306 -> 0.70093636 | N15: =HAVERM!G306 -> 1.2005773 | P15: 41974 | U15: 43800 | V15: =HAVERM!E366 -> 0.75 | W15: =HAVERM!H366 -> 3.28 | X15: =HAVERM!I366 -> 2.37 | Z15: 44866 | AA15: =W50-W$38 -> 2.12 | AB15: =X50-X$38 -> 0.37 | AC15: 1000 | AF15: 44470 | AG15: =Data!G202 -> 2.02 | AH15: =Data!H202 -> 2.703333
A16: 42005 | B16: =HAVERM!B307 -> 4.56 | C16: =HAVERM!C307 -> 2.01 | D16: =HAVERM!D307 -> 3.09 | H16: =B16-L16 -> 4.06 | I16: =C16-M16 -> 1.4174286 | J16: =D16-N16 -> 2.1329952 | L16: =HAVERM!E307 -> 0.5 | M16: =HAVERM!F307 -> 0.59257143 | N16: =HAVERM!G307 -> 0.95700476 | P16: 42005 | Q16: =B16-B4 -> 0.15 | U16: 43831 | V16: =HAVERM!E367 -> 0.75 | W16: =HAVERM!H367 -> 3.29 | X16: =HAVERM!I367 -> 2.37 | Z16: 44896 | AA16: =W51-W$38 -> 2.44 | AB16: =X51-X$38 -> 0.49 | AC16: 1000 | AF16: 44562 | AG16: =Data!G203 -> 2.026667 | AH16: =Data!H203 -> 2.936667
A17: 42036 | B17: =HAVERM!B308 -> 4.51 | C17: =HAVERM!C308 -> 1.96 | D17: =HAVERM!D308 -> 3.05 | H17: =B17-L17 -> 4.01 | I17: =C17-M17 -> 1.280755 | J17: =D17-N17 -> 1.92882 | L17: =HAVERM!E308 -> 0.5 | M17: =HAVERM!F308 -> 0.679245 | N17: =HAVERM!G308 -> 1.12118 | P17: 42036 | Q17: =B17-B5 -> 0.08 | U17: 43862 | V17: =HAVERM!E368 -> 0.75 | W17: =HAVERM!H368 -> 3.3 | X17: =HAVERM!I368 -> 2.37 | Z17: 44927 | AA17: =W52-W$38 -> 2.6 | AB17: =X52-X$38 -> 0.53 | AC17: 1000 | AF17: 44652 | AG17: =Data!G204 -> 2.083333 | AH17: =Data!H204 -> 3.326667
A18: 42064 | B18: =HAVERM!B309 -> 4.51 | C18: =HAVERM!C309 -> 1.99 | D18: =HAVERM!D309 -> 2.98 | H18: =B18-L18 -> 4.01 | I18: =C18-M18 -> 1.3028524 | J18: =D18-N18 -> 1.8285952 | L18: =HAVERM!E309 -> 0.5 | M18: =HAVERM!F309 -> 0.68714762 | N18: =HAVERM!G309 -> 1.1514048 | P18: 42064 | Q18: =B18-B6 -> 0.08 | U18: 43891 | V18: =HAVERM!E369 -> 0.34772727 | W18: =HAVERM!H369 -> 3.21 | X18: =HAVERM!I369 -> 2.33 | Z18: 44958 | AA18: =W53-W$38 -> 2.95 | AB18: =X53-X$38 -> 0.63 | AC18: 1000 | AF18: 44743 | AG18: =Data!G205 -> 2.186667 | AH18: =Data!H205 -> 3.836667
A19: 42095 | B19: =HAVERM!B310 -> 4.53 | C19: =HAVERM!C310 -> 1.95 | D19: =HAVERM!D310 -> 2.92 | H19: =B19-L19 -> 4.03 | I19: =C19-M19 -> 1.3036476 | J19: =D19-N19 -> 1.8594333 | L19: =HAVERM!E310 -> 0.5 | M19: =HAVERM!F310 -> 0.64635238 | N19: =HAVERM!G310 -> 1.0605667 | P19: 42095 | Q19: =B19-B7 -> 0.1 | U19: 43922 | V19: =HAVERM!E370 -> 0.1 | W19: =HAVERM!H370 -> 2.98 | X19: =HAVERM!I370 -> 2.21 | Z19: 44986 | AA19: =W54-W$38 -> 3.09 | AB19: =X54-X$38 -> 0.73 | AC19: 1000 | AF19: 44835 | AG19: =Data!G206 -> 2.396667 | AH19: =Data!H206 -> 4.763333
A20: 42125 | B20: =HAVERM!B311 -> 4.55 | C20: =HAVERM!C311 -> 1.9 | D20: =HAVERM!D311 -> 2.86 | H20: =B20-L20 -> 4.05 | I20: =C20-M20 -> 1.1638524 | J20: =D20-N20 -> 1.5970476 | L20: =HAVERM!E311 -> 0.5 | M20: =HAVERM!F311 -> 0.73614762 | N20: =HAVERM!G311 -> 1.2629524 | P20: 42125 | Q20: =B20-B8 -> 0.13 | U20: 43952 | V20: =HAVERM!E371 -> 0.1 | W20: =HAVERM!H371 -> 2.86 | X20: =HAVERM!I371 -> 2.17 | Z20: 45017 | AA20: =W55-W$38 -> 3.21 | AB20: =X55-X$38 -> 0.74 | AC20: 1000 | AF20: 44927 | AG20: =Data!G207 -> 2.65 | AH20: =Data!H207 -> 5.58
A21: 42156 | B21: =HAVERM!B312 -> 4.49 | C21: =HAVERM!C312 -> 1.83 | D21: =HAVERM!D312 -> 2.82 | H21: =B21-L21 -> 3.99 | I21: =C21-M21 -> 1.0497955 | J21: =D21-N21 -> 1.4679636 | L21: =HAVERM!E312 -> 0.5 | M21: =HAVERM!F312 -> 0.78020455 | N21: =HAVERM!G312 -> 1.3520364 | P21: 42156 | Q21: =B21-B9 -> 0.13 | U21: 43983 | V21: =HAVERM!E372 -> 0.1 | W21: =HAVERM!H372 -> 2.79 | X21: =HAVERM!I372 -> 2.17 | Z21: 45047 | AA21: =W56-W$38 -> 3.34 | AB21: =X56-X$38 -> 0.81 | AC21: 1000 | AF21: 45017 | AG21: =Data!G208 -> 2.84 | AH21: =Data!H208 -> 6.09
A22: 42186 | B22: =HAVERM!B313 -> 4.5 | C22: =HAVERM!C313 -> 1.87 | D22: =HAVERM!D313 -> 2.83 | H22: =B22-L22 -> 4 | I22: =C22-M22 -> 1.0242609 | J22: =D22-N22 -> 1.422013 | L22: =HAVERM!E313 -> 0.5 | M22: =HAVERM!F313 -> 0.84573913 | N22: =HAVERM!G313 -> 1.407987 | P22: 42186 | Q22: =B22-B10 -> 0.05 | U22: 44013 | V22: =HAVERM!E373 -> 0.1 | W22: =HAVERM!H373 -> 2.66 | X22: =HAVERM!I373 -> 2.16 | Z22: 45078 | AA22: =W57-W$38 -> 3.62 | AB22: =X57-X$38 -> 0.91 | AC22: 1000 | AF22: 45108 | AG22: =Data!G209 -> 3.07 | AH22: =Data!H209 -> 6.676667
A23: 42217 | B23: =HAVERM!B314 -> 4.48 | C23: =HAVERM!C314 -> 1.95 | D23: =HAVERM!D314 -> 2.92 | H23: =B23-L23 -> 3.98 | I23: =C23-M23 -> 1.1439048 | J23: =D23-N23 -> 1.5978381 | L23: =HAVERM!E314 -> 0.5 | M23: =HAVERM!F314 -> 0.80609524 | N23: =HAVERM!G314 -> 1.3221619 | P23: 42217 | Q23: =B23-B11 -> 0.03 | U23: 44044 | V23: =HAVERM!E374 -> 0.1 | W23: =HAVERM!H374 -> 2.53 | X23: =HAVERM!I374 -> 2.14 | Z23: 45108 | AA23: =W58-W$38 -> 3.81 | AB23: =X58-X$38 -> 0.96 | AC23: 1000 | AF23: 45200 | AG23: =Data!G210 -> 3.29 | AH23: =Data!H210 -> 6.8
A24: 42248 | B24: =HAVERM!B315 -> 4.5 | C24: =HAVERM!C315 -> 1.91 | D24: =HAVERM!D315 -> 2.84 | H24: =B24-L24 -> 4 | I24: =C24-M24 -> 1.1834227 | J24: =D24-N24 -> 1.6508136 | L24: =HAVERM!E315 -> 0.5 | M24: =HAVERM!F315 -> 0.72657727 | N24: =HAVERM!G315 -> 1.1891864 | P24: 42248 | Q24: =B24-B12 -> -0.02 | U24: 44075 | V24: =HAVERM!E375 -> 0.1 | W24: =HAVERM!H375 -> 2.52 | X24: =HAVERM!I375 -> 2.13 | Z24: 45139 | AA24: =W59-W$38 -> 4.01 | AB24: =X59-X$38 -> 1.05 | AC24: 1000 | AF24: 45292 | AG24: =Data!G211 -> 3.473333 | AH24: =Data!H211 -> 6.856667
A25: 42278 | B25: =HAVERM!B316 -> 4.54 | C25: =HAVERM!C316 -> 1.87 | D25: =HAVERM!D316 -> 2.78 | H25: =B25-L25 -> 4.04 | I25: =C25-M25 -> 1.2124818 | J25: =D25-N25 -> 1.6863545 | L25: =HAVERM!E316 -> 0.5 | M25: =HAVERM!F316 -> 0.65751818 | N25: =HAVERM!G316 -> 1.0936455 | P25: 42278 | Q25: =B25-B13 -> 0.01 | U25: 44105 | V25: =HAVERM!E376 -> 0.1 | W25: =HAVERM!H376 -> 2.46 | X25: =HAVERM!I376 -> 2.12 | Z25: 45170 | AA25: =W60-W$38 -> 4.11 | AB25: =X60-X$38 -> 1.14 | AF25: 45383 | AG25: =Data!G212 -> 3.62 | AH25: =Data!H212 -> 6.89
A26: 42309 | B26: =HAVERM!B317 -> 4.49 | C26: =HAVERM!C317 -> 1.92 | D26: =HAVERM!D317 -> 2.77 | H26: =B26-L26 -> 3.99 | I26: =C26-M26 -> 1.1974619 | J26: =D26-N26 -> 1.5989381 | L26: =HAVERM!E317 -> 0.5 | M26: =HAVERM!F317 -> 0.7225381 | N26: =HAVERM!G317 -> 1.1710619 | P26: 42309 | Q26: =B26-B14 -> 0 | U26: 44136 | V26: =HAVERM!E377 -> 0.1 | W26: =HAVERM!H377 -> 2.45 | X26: =HAVERM!I377 -> 2.12 | Z26: 45200 | AA26: =W61-W$38 -> 4.08 | AB26: =X61-X$38 -> 1.2 | AF26: 45474 | AG26: =Data!G213 -> 3.726667 | AH26: =Data!H213 -> 6.806667
A27: 42339 | B27: =HAVERM!B318 -> 4.49 | C27: =HAVERM!C318 -> 1.9 | D27: =HAVERM!D318 -> 2.75 | H27: =B27-L27 -> 3.99 | I27: =C27-M27 -> 1.1574739 | J27: =D27-N27 -> 1.5918435 | L27: =HAVERM!E318 -> 0.5 | M27: =HAVERM!F318 -> 0.74252609 | N27: =HAVERM!G318 -> 1.1581565 | P27: 42339 | Q27: =B27-B15 -> 0.01 | U27: 44166 | V27: =HAVERM!E378 -> 0.1 | W27: =HAVERM!H378 -> 2.45 | X27: =HAVERM!I378 -> 2.12 | Z27: 45231 | AA27: =W62-W$38 -> 4.1 | AB27: =X62-X$38 -> 1.26 | AF27: 45566 | AG27: =Data!G214 -> 3.8 | AH27: =Data!H214 -> 6.646667
A28: 42370 | B28: =HAVERM!B319 -> 4.56 | C28: =HAVERM!C319 -> 1.93 | D28: =HAVERM!D319 -> 2.68 | H28: =B28-L28 -> 4.06 | I28: =C28-M28 -> 1.3224 | J28: =D28-N28 -> 1.6969905 | L28: =HAVERM!E319 -> 0.5 | M28: =HAVERM!F319 -> 0.6076 | N28: =HAVERM!G319 -> 0.98300952 | P28: 42370 | Q28: =B28-B16 -> 0 | R28: =C28-C4 -> -0.44 | U28: 44197 | V28: =HAVERM!E379 -> 0.1 | W28: =HAVERM!H379 -> 2.41 | X28: =HAVERM!I379 -> 2.09 | Z28: 45261 | AA28: =W63-W$38 -> 4.12 | AB28: =X63-X$38 -> 1.35 | AF28: 45658 | AG28: =Data!G215 -> 3.846667 | AH28: =Data!H215 -> 6.41
A29: 42401 | B29: =HAVERM!B320 -> 4.58 | C29: =HAVERM!C320 -> 1.95 | D29: =HAVERM!D320 -> 2.73 | H29: =B29-L29 -> 4.08 | I29: =C29-M29 -> 1.5433238 | J29: =D29-N29 -> 2.1155333 | L29: =HAVERM!E320 -> 0.5 | M29: =HAVERM!F320 -> 0.40667619 | N29: =HAVERM!G320 -> 0.61446667 | P29: 42401 | Q29: =B29-B17 -> 0.07 | R29: =C29-C5 -> -0.43 | U29: 44228 | V29: =HAVERM!E380 -> 0.1 | W29: =HAVERM!H380 -> 2.43 | X29: =HAVERM!I380 -> 2.09 | Z29: 45292 | AA29: =W64-W$38 -> 4.14 | AB29: =X64-X$38 -> 1.4 | AF29: 45748 | AG29: =Data!G216 -> 3.873333 | AH29: =Data!H216 -> 6.216667
A30: 42430 | B30: =HAVERM!B321 -> 4.57 | C30: =HAVERM!C321 -> 1.9 | D30: =HAVERM!D321 -> 2.7 | H30: =B30-L30 -> 4.07 | I30: =C30-M30 -> 1.4501435 | J30: =D30-N30 -> 2.0500696 | L30: =HAVERM!E321 -> 0.5 | M30: =HAVERM!F321 -> 0.44985652 | N30: =HAVERM!G321 -> 0.64993043 | P30: 42430 | Q30: =B30-B18 -> 0.06 | R30: =C30-C6 -> -0.47 | U30: 44256 | V30: =HAVERM!E381 -> 0.1 | W30: =HAVERM!H381 -> 2.44 | X30: =HAVERM!I381 -> 2.09 | Z30: 45323 | AA30: =W65-W$38 -> 4.15 | AB30: =X65-X$38 -> 1.47 | AF30: 45839 | AG30: =Data!G217 -> 3.854621 | AH30: =Data!H217 -> 6.023008
A31: 42461 | B31: =HAVERM!B322 -> 4.64 | C31: =HAVERM!C322 -> 1.84 | D31: =HAVERM!D322 -> 2.71 | H31: =B31-L31 -> 4.14 | I31: =C31-M31 -> 1.3879619 | J31: =D31-N31 -> 2.0608476 | L31: =HAVERM!E322 -> 0.5 | M31: =HAVERM!F322 -> 0.4520381 | N31: =HAVERM!G322 -> 0.64915238 | P31: 42461 | Q31: =B31-B19 -> 0.11 | R31: =C31-C7 -> -0.7 | U31: 44287 | V31: =HAVERM!E382 -> 0.1 | W31: =HAVERM!H382 -> 2.42 | X31: =HAVERM!I382 -> 2.07 | Z31: 45352 | AA31: =W66-W$38 -> 4.18 | AB31: =X66-X$38 -> 1.49 | AF31: 45931 | AG31: =Data!G218 -> 3.855985 | AH31: =Data!H218 -> 5.811905
A32: 42491 | B32: =HAVERM!B323 -> 4.56 | C32: =HAVERM!C323 -> 1.91 | D32: =HAVERM!D323 -> 2.64 | H32: =B32-L32 -> 4.06 | I32: =C32-M32 -> 1.4411136 | J32: =D32-N32 -> 1.9507182 | L32: =HAVERM!E323 -> 0.5 | M32: =HAVERM!F323 -> 0.46888636 | N32: =HAVERM!G323 -> 0.68928182 | P32: 42491 | Q32: =B32-B20 -> 0.01 | R32: =C32-C8 -> -0.65 | U32: 44317 | V32: =HAVERM!E383 -> 0.1 | W32: =HAVERM!H383 -> 2.5 | X32: =HAVERM!I383 -> 2.07 | Z32: 45383 | AA32: =W67-W$38 -> 4.17 | AB32: =X67-X$38 -> 1.56 | AF32: 46023 | AG32: =Data!G219 -> 3.88 | AH32: =Data!H219 -> 5.606066
A33: 42522 | B33: =HAVERM!B324 -> 4.52 | C33: =HAVERM!C324 -> 1.75 | D33: =HAVERM!D324 -> 2.54 | H33: =B33-L33 -> 4.02 | I33: =C33-M33 -> 1.3929045 | J33: =D33-N33 -> 2.0278727 | L33: =HAVERM!E324 -> 0.5 | M33: =HAVERM!F324 -> 0.35709545 | N33: =HAVERM!G324 -> 0.51212727 | P33: 42522 | Q33: =B33-B21 -> 0.03 | R33: =C33-C9 -> -0.85 | U33: 44348 | V33: =HAVERM!E384 -> 0.1 | W33: =HAVERM!H384 -> 2.55 | X33: =HAVERM!I384 -> 2.08 | Z33: 45413 | AA33: =W68-W$38 -> 4.18 | AB33: =X68-X$38 -> 1.6 | AF33: 46113 | AG33: =Data!G220 -> 3.895385 | AH33: =Data!H220 -> 5.398326
A34: 42552 | B34: =HAVERM!B325 -> 4.55 | C34: =HAVERM!C325 -> 1.72 | D34: =HAVERM!D325 -> 2.51 | H34: =B34-L34 -> 4.05 | I34: =C34-M34 -> 1.5872619 | J34: =D34-N34 -> 2.2893238 | L34: =HAVERM!E325 -> 0.5 | M34: =HAVERM!F325 -> 0.1327381 | N34: =HAVERM!G325 -> 0.22067619 | P34: 42552 | Q34: =B34-B22 -> 0.05 | R34: =C34-C10 -> -0.82 | U34: 44378 | V34: =HAVERM!E385 -> 0.1 | W34: =HAVERM!H385 -> 2.55 | X34: =HAVERM!I385 -> 2.05 | Z34: 45444 | AA34: =W69-W$38 -> 4.22 | AB34: =X69-X$38 -> 1.64 | AF34: 46204 | AG34: =Data!G221 -> 3.944082 | AH34: =Data!H221 -> 5.25076
A35: 42583 | B35: =HAVERM!B326 -> 4.3 | C35: =HAVERM!C326 -> 1.69 | D35: =HAVERM!D326 -> 2.39 | H35: =B35-L35 -> 4.0173913 | I35: =C35-M35 -> 1.5824 | J35: =D35-N35 -> 2.2147217 | L35: =HAVERM!E326 -> 0.2826087 | M35: =HAVERM!F326 -> 0.1076 | N35: =HAVERM!G326 -> 0.17527826 | P35: 42583 | Q35: =B35-B23 -> -0.18 | R35: =C35-C11 -> -0.85 | U35: 44409 | V35: =HAVERM!E386 -> 0.1 | W35: =HAVERM!H386 -> 2.65 | X35: =HAVERM!I386 -> 2.06 | Z35: 45474 | AA35: =W70-W$38 -> 4.18 | AB35: =X70-X$38 -> 1.68 | AF35: 46296 | AG35: =Data!G222 -> 3.99024 | AH35: =Data!H222 -> 5.083459
A36: 42614 | B36: =HAVERM!B327 -> 4.24 | C36: =HAVERM!C327 -> 1.59 | D36: =HAVERM!D327 -> 2.34 | H36: =B36-L36 -> 3.99 | I36: =C36-M36 -> 1.4666318 | J36: =D36-N36 -> 2.1336091 | L36: =HAVERM!E327 -> 0.25 | M36: =HAVERM!F327 -> 0.12336818 | N36: =HAVERM!G327 -> 0.20639091 | P36: 42614 | Q36: =B36-B24 -> -0.26 | R36: =C36-C12 -> -0.87 | U36: 44440 | V36: =HAVERM!E387 -> 0.1 | W36: =HAVERM!H387 -> 2.65 | X36: =HAVERM!I387 -> 2.05 | Z36: 45505 | AA36: =W71-W$38 -> 4.07 | AB36: =X71-X$38 -> 1.71 | AD36: 1000 | AF36: 46388 | AG36: =Data!G223 -> 4.021269 | AH36: =Data!H223 -> 4.943674
A37: 42644 | B37: =HAVERM!B328 -> 4.24 | C37: =HAVERM!C328 -> 1.52 | D37: =HAVERM!D328 -> 2.27 | H37: =B37-L37 -> 3.99 | I37: =C37-M37 -> 1.3240381 | J37: =D37-N37 -> 1.9146571 | L37: =HAVERM!E328 -> 0.25 | M37: =HAVERM!F328 -> 0.1959619 | N37: =HAVERM!G328 -> 0.35534286 | P37: 42644 | Q37: =B37-B25 -> -0.3 | R37: =C37-C13 -> -0.69 | U37: 44470 | V37: =HAVERM!E388 -> 0.1 | W37: =HAVERM!H388 -> 2.66 | X37: =HAVERM!I388 -> 2.03 | Z37: 45536 | AA37: =W72-W$38 -> 4.07 | AB37: =X72-X$38 -> 1.73 | AD37: 1000 | AF37: 46478 | AG37: =Data!G224 -> 4.029451 | AH37: =Data!H224 -> 4.782779
A38: 42675 | B38: =HAVERM!B329 -> 4.28 | C38: =HAVERM!C329 -> 1.43 | D38: =HAVERM!D329 -> 2.25 | H38: =B38-L38 -> 4.03 | I38: =C38-M38 -> 1.1526455 | J38: =D38-N38 -> 1.6863136 | L38: =HAVERM!E329 -> 0.25 | M38: =HAVERM!F329 -> 0.27735455 | N38: =HAVERM!G329 -> 0.56368636 | P38: 42675 | Q38: =B38-B26 -> -0.21 | R38: =C38-C14 -> -0.74 | U38: 44501 | V38: =HAVERM!E389 -> 0.1 | W38: =HAVERM!H389 -> 2.7 | X38: =HAVERM!I389 -> 2.02 | Z38: 45566 | AA38: =W73-W$38 -> 4.05 | AB38: =X73-X$38 -> 1.77 | AD38: 1000 | AF38: 46569 | AG38: =Data!G225 -> 4.010621 | AH38: =Data!H225 -> 4.649104
A39: 42705 | B39: =HAVERM!B330 -> 4.23 | C39: =HAVERM!C330 -> 1.45 | D39: =HAVERM!D330 -> 2.26 | H39: =B39-L39 -> 3.98 | I39: =C39-M39 -> 1.1509364 | J39: =D39-N39 -> 1.6513864 | L39: =HAVERM!E330 -> 0.25 | M39: =HAVERM!F330 -> 0.29906364 | N39: =HAVERM!G330 -> 0.60861364 | P39: 42705 | Q39: =B39-B27 -> -0.26 | R39: =C39-C15 -> -0.63 | U39: 44531 | V39: =HAVERM!E390 -> 0.17826087 | W39: =HAVERM!H390 -> 2.75 | X39: =HAVERM!I390 -> 2.01 | Z39: 45597 | AA39: =W74-W$38 -> 3.91 | AB39: =X74-X$38 -> 1.79 | AD39: 1000 | AF39: 46661 | AG39: =Data!G226 -> 3.930274 | AH39: =Data!H226 -> 4.493542
A40: 42736 | B40: =HAVERM!B331 -> 4.49 | C40: =HAVERM!C331 -> 1.45 | D40: =HAVERM!D331 -> 2.22 | H40: =B40-L40 -> 4.24 | I40: =C40-M40 -> 1.1252182 | J40: =D40-N40 -> 1.61045 | L40: =HAVERM!E331 -> 0.25 | M40: =HAVERM!F331 -> 0.32478182 | N40: =HAVERM!G331 -> 0.60955 | P40: 42736 | Q40: =B40-B28 -> -0.07 | R40: =C40-C16 -> -0.56 | U40: 44562 | V40: =HAVERM!E391 -> 0.25 | W40: =HAVERM!H391 -> 2.81 | X40: =HAVERM!I391 -> 2.01 | Z40: 45627 | AA40: =W75-W$38 -> 3.88 | AB40: =X75-X$38 -> 1.78 | AD40: 1000 | AF40: 46753 | AG40: =Data!G227 -> 3.885861 | AH40: =Data!H227 -> 4.371559
...

Sheet HAVERM
A1: 199001 !M | B1: UNTLMV@UK | C1: UNBV34@UK | D1: UNBV42@UK | E1: R112RD@INTDAILY | F1: M112IHH@INTDAILY | G1: M112I5Y@INTDAILY | H1: UNHSDC@UK | I1: UNHSDE@UK
A2: .DESC | B2: UK: Mortgages: Standard Variable Rate: MFIS ex Central Bank (AVG, %) | C2: UK: Mortgages: Fixed Rates: MFIS ex Central Bank: 2-Year 75% LTV (AVG, %) | D2: UK: Mortgages: Fixed Rates: MFIS ex Central Bank: 5-Year 75% LTV (AVG, %) | E2: United Kingdom: Official Bank Rate (%) | F2: UK: 24 Month Overnight Index Swap[Ann,Act/365]v SONIA:Mid Rate[2PM ET](%p.a) | G2: UK: 5 Year Overnight Index Swap[Ann,Act/365]v SONIA:Mid Rate[2PM ET](%p.a) | H2: UK: Banks Weighted Average Interest Rate, Other Loans to Nonfin Corps (%) | I2: UK: Banks Weighted Avg Interest Rate, HH Loans Secured on Dwellings (%)
A3: .T1 | B3: Jan-1995 | C3: Jan-1995 | D3: Jan-1995 | E3: Jan-1954 <- 01-Jan-1954 | F3: Aug-2014 <- 26-Aug-2014 | G3: Aug-2014 <- 26-Aug-2014 | H3: Jan-1999 | I3: Jan-1999
A4: .TN | B4: Jun-2025 | C4: Jun-2025 | D4: Jun-2025 | E4: Jun-2025 <- 10-Jul-2025 | F4: Jun-2025 <- 10-Jul-2025 | G4: Jun-2025 <- 10-Jul-2025 | H4: May-2025 | I4: May-2025
A5: .LSOURCE | B5: Bank of England | C5: Bank of England | D5: Bank of England | E5: Bank of England | F5: Tullett Prebon Information/Haver Analytics | G5: Tullett Prebon Information/Haver Analytics | H5: Bank of England | I5: Bank of England
A6: .DTLM | B6: Jul-07-2025 09:34 | C6: Jul-07-2025 09:34 | D6: Jul-07-2025 09:34 | E6: Jul-10-2025 14:17 | F6: Jul-10-2025 19:25 | G6: Jul-10-2025 19:25 | H6: Jun-30-2025 09:30 | I6: Jun-30-2025 09:30
A7: 199001 | B7: #N/A | C7: #N/A | D7: #N/A | E7: 14.875 | F7: #N/A | G7: #N/A | H7: #N/A | I7: #N/A
A8: 199002 | B8: #N/A | C8: #N/A | D8: #N/A | E8: 14.875 | F8: #N/A | G8: #N/A | H8: #N/A | I8: #N/A
A9: 199003 | B9: #N/A | C9: #N/A | D9: #N/A | E9: 14.875 | F9: #N/A | G9: #N/A | H9: #N/A | I9: #N/A
A10: 199004 | B10: #N/A | C10: #N/A | D10: #N/A | E10: 14.875 | F10: #N/A | G10: #N/A | H10: #N/A | I10: #N/A
A11: 199005 | B11: #N/A | C11: #N/A | D11: #N/A | E11: 14.875 | F11: #N/A | G11: #N/A | H11: #N/A | I11: #N/A
A12: 199006 | B12: #N/A | C12: #N/A | D12: #N/A | E12: 14.875 | F12: #N/A | G12: #N/A | H12: #N/A | I12: #N/A
A13: 199007 | B13: #N/A | C13: #N/A | D13: #N/A | E13: 14.875 | F13: #N/A | G13: #N/A | H13: #N/A | I13: #N/A
A14: 199008 | B14: #N/A | C14: #N/A | D14: #N/A | E14: 14.875 | F14: #N/A | G14: #N/A | H14: #N/A | I14: #N/A
A15: 199009 | B15: #N/A | C15: #N/A | D15: #N/A | E15: 14.875 | F15: #N/A | G15: #N/A | H15: #N/A | I15: #N/A
A16: 199010 | B16: #N/A | C16: #N/A | D16: #N/A | E16: 14.092391 | F16: #N/A | G16: #N/A | H16: #N/A | I16: #N/A
A17: 199011 | B17: #N/A | C17: #N/A | D17: #N/A | E17: 13.875 | F17: #N/A | G17: #N/A | H17: #N/A | I17: #N/A
A18: 199012 | B18: #N/A | C18: #N/A | D18: #N/A | E18: 13.875 | F18: #N/A | G18: #N/A | H18: #N/A | I18: #N/A
... A66: 199412 | B66: #N/A | C66: #N/A | D66: #N/A | E66: 6.0340909 | F66: #N/A | G66: #N/A | H66: #N/A | I66: #N/A
A67: 199501 | B67: 8.21 | C67: 8.13 | D67: 9.44 | E67: 6.125 | F67: #N/A | G67: #N/A | H67: #N/A | I67: #N/A
A68: 199502 | B68: 8.33 | C68: 8.38 | D68: 9.38 | E68: 6.6 | F68: #N/A | G68: #N/A | H68: #N/A | I68: #N/A
A69: 199503 | B69: 8.36 | C69: 8.08 | D69: 9.33 | E69: 6.625 | F69: #N/A | G69: #N/A | H69: #N/A | I69: #N/A
A70: 199504 | B70: 8.36 | C70: 8.29 | D70: 9.4 | E70: 6.625 | F70: #N/A | G70: #N/A | H70: #N/A | I70: #N/A
A71: 199505 | B71: 8.36 | C71: 8.22 | D71: 9.4 | E71: 6.625 | F71: #N/A | G71: #N/A | H71: #N/A | I71: #N/A
A72: 199506 | B72: 8.35 | C72: 7.94 | D72: 9.01 | E72: 6.625 | F72: #N/A | G72: #N/A | H72: #N/A | I72: #N/A
A73: 199507 | B73: 8.36 | C73: 7.89 | D73: 8.93 | E73: 6.625 | F73: #N/A | G73: #N/A | H73: #N/A | I73: #N/A
A74: 199508 | B74: 8.36 | C74: 7.99 | D74: 8.85 | E74: 6.625 | F74: #N/A | G74: #N/A | H74: #N/A | I74: #N/A
A75: 199509 | B75: 8.36 | C75: 7.99 | D75: 8.57 | E75: 6.625 | F75: #N/A | G75: #N/A | H75: #N/A | I75: #N/A
A76: 199510 | B76: 8 | C76: 7.99 | D76: 8.19 | E76: 6.625 | F76: #N/A | G76: #N/A | H76: #N/A | I76: #N/A
A77: 199511 | B77: 7.96 | C77: 7.99 | D77: 8.14 | E77: 6.625 | F77: #N/A | G77: #N/A | H77: #N/A | I77: #N/A
A78: 199512 | B78: 7.95 | C78: 7.99 | D78: 8.13 | E78: 6.4702381 | F78: #N/A | G78: #N/A | H78: #N/A | I78: #N/A
... A114: 199812 | B114: 8 | C114: 6.42 | D114: 6.36 | E114: 6.4021739 | F114: #N/A | G114: #N/A | H114: #N/A | I114: #N/A
A115: 199901 | B115: 7.6 | C115: 5.9 | D115: 5.9 | E115: 6.047619 | F115: #N/A | G115: #N/A | H115: 8.11 | I115: 7.41
A116: 199902 | B116: 7.35 | C116: 5.78 | D116: 5.7 | E116: 5.575 | F116: #N/A | G116: #N/A | H116: 7.69 | I116: 7.21
A117: 199903 | B117: 6.85 | C117: 5.64 | D117: 5.8 | E117: 5.5 | F117: #N/A | G117: #N/A | H117: 7.38 | I117: 6.89
A118: 199904 | B118: 6.83 | C118: 5.71 | D118: 5.89 | E118: 5.3068182 | F118: #N/A | G118: #N/A | H118: 7.14 | I118: 6.87
A119: 199905 | B119: 6.75 | C119: 5.72 | D119: 5.97 | E119: 5.25 | F119: #N/A | G119: #N/A | H119: 7.12 | I119: 6.72
A120: 199906 | B120: 6.73 | C120: 5.89 | D120: 6.29 | E120: 5.0795455 | F120: #N/A | G120: #N/A | H120: 7.05 | I120: 6.63
A121: 199907 | B121: 6.72 | C121: 6 | D121: 6.3 | E121: 5 | F121: #N/A | G121: #N/A | H121: 7.12 | I121: 6.64
A122: 199908 | B122: 6.72 | C122: 6.19 | D122: 6.64 | E122: 5 | F122: #N/A | G122: #N/A | H122: 6.98 | I122: 6.61
...

Sheet Data
C1: =GMW!C2 -> JUL009E | D1: =$C$1 -> JUL009E | E1: =$C$1 -> JUL009E | F1: =$C$1 -> JUL009E | G1: =$C$1 -> JUL009E | H1: =$C$1 -> JUL009E
C2: UK | D2: UK | E2: UK | F2: UK | G2: UK | H2: UK
C3: PEDIR_UNADJ | D3: PEDIP_UNADJ | E3: RCBEOP | F3: RLGEOP | G3: RBM | H3: RLOAN
C4: GBR | D4: GBR | E4: GBR | F4: GBR | G4: GBR | H4: GBR
C5: L | D5: L | E5: L | F5: L | G5: L | H5: L
B6: =B358+5 -> 2329 | C6: {=_xlfn.CONCAT(INDEX(GMW!$A$2:$NE$60,MATCH(1,(GMW!$NE$2:$NE$60=C$3)*(GMW!$ND$2:$ND$60=C$4),0),$B6-1966),"0",(INDEX(GMW!$A$2:$NE$60,MATCH(1,(GMW!$NE$2:$NE$60=C$3)*(GMW!$ND$2:$ND$60=C$4),0),$B6-1965)))} -> 202501 | D6: {=_xlfn.CONCAT(INDEX(GMW!$A$2:$NE$60,MATCH(1,(GMW!$NE$2:$NE$60=D$3)*(GMW!$ND$2:$ND$60=D$4),0),$B6-1966),"0",(INDEX(GMW!$A$2:$NE$60,MATCH(1,(GMW!$NE$2:$NE$60=D$3)*(GMW!$ND$2:$ND$60=D$4),0),$B6-1965)))} -> 202501 | E6: {=_xlfn.CONCAT(INDEX(GMW!$A$2:$NE$60,MATCH(1,(GMW!$NE$2:$NE$60=E$3)*(GMW!$ND$2:$ND$60=E$4),0),$B6-1966),"0",(INDEX(GMW!$A$2:$NE$60,MATCH(1,(GMW!$NE$2:$NE$60=E$3)*(GMW!$ND$2:$ND$60=E$4),0),$B6-1965)))} -> 202502 | F6: {=_xlfn.CONCAT(INDEX(GMW!$A$2:$NE$60,MATCH(1,(GMW!$NE$2:$NE$60=F$3)*(GMW!$ND$2:$ND$60=F$4),0),$B6-1966),"0",(INDEX(GMW!$A$2:$NE$60,MATCH(1,(GMW!$NE$2:$NE$60=F$3)*(GMW!$ND$2:$ND$60=F$4),0),$B6-1965)))} -> 202502 | G6: {=_xlfn.CONCAT(INDEX(GMW!$A$2:$NE$60,MATCH(1,(GMW!$NE$2:$NE$60=G$3)*(GMW!$ND$2:$ND$60=G$4),0),$B6-1966),"0",(INDEX(GMW!$A$2:$NE$60,MATCH(1,(GMW!$NE$2:$NE$60=G$3)*(GMW!$ND$2:$ND$60=G$4),0),$B6-1965)))} -> 202501 | H6: {=_xlfn.CONCAT(INDEX(GMW!$A$2:$NE$60,MATCH(1,(GMW!$NE$2:$NE$60=H$3)*(GMW!$ND$2:$ND$60=H$4),0),$B6-1966),"0",(INDEX(GMW!$A$2:$NE$60,MATCH(1,(GMW!$NE$2:$NE$60=H$3)*(GMW!$ND$2:$ND$60=H$4),0),$B6-1965)))} -> 202501
A7: 1973 | B7: 1973 | C7: {=INDEX(GMW!$A$2:$NF$60,MATCH(1,(GMW!$NE$2:$NE$60=C$3)*(GMW!$ND$2:$ND$60=C$4),0),$B7-1966)} -> 0.001 | D7: {=INDEX(GMW!$A$2:$NF$60,MATCH(1,(GMW!$NE$2:$NE$60=D$3)*(GMW!$ND$2:$ND$60=D$4),0),$B7-1966)} -> 0.001 | E7: {=INDEX(GMW!$A$2:$NF$60,MATCH(1,(GMW!$NE$2:$NE$60=E$3)*(GMW!$ND$2:$ND$60=E$4),0),$B7-1966)} -> 8.5 | F7: {=INDEX(GMW!$A$2:$NF$60,MATCH(1,(GMW!$NE$2:$NE$60=F$3)*(GMW!$ND$2:$ND$60=F$4),0),$B7-1966)} -> 0.001 | G7: {=INDEX(GMW!$A$2:$NF$60,MATCH(1,(GMW!$NE$2:$NE$60=G$3)*(GMW!$ND$2:$ND$60=G$4),0),$B7-1966)} -> 8.5 | H7: {=INDEX(GMW!$A$2:$NF$60,MATCH(1,(GMW!$NE$2:$NE$60=H$3)*(GMW!$ND$2:$ND$60=H$4),0),$B7-1966)} -> 0.001
B8: =+B7+1 -> 1974 | C8: {=INDEX(GMW!$A$2:$NF$60,MATCH(1,(GMW!$NE$2:$NE$60=C$3)*(GMW!$ND$2:$ND$60=C$4),0),$B8-1966)} -> 0.001 | D8: {=INDEX(GMW!$A$2:$NF$60,MATCH(1,(GMW!$NE$2:$NE$60=D$3)*(GMW!$ND$2:$ND$60=D$4),0),$B8-1966)} -> 0.001 | E8: {=INDEX(GMW!$A$2:$NF$60,MATCH(1,(GMW!$NE$2:$NE$60=E$3)*(GMW!$ND$2:$ND$60=E$4),0),$B8-1966)} -> 7.5 | F8: {=INDEX(GMW!$A$2:$NF$60,MATCH(1,(GMW!$NE$2:$NE$60=F$3)*(GMW!$ND$2:$ND$60=F$4),0),$B8-1966)} -> 0.001 | G8: {=INDEX(GMW!$A$2:$NF$60,MATCH(1,(GMW!$NE$2:$NE$60=G$3)*(GMW!$ND$2:$ND$60=G$4),0),$B8-1966)} -> 9.5 | H8: {=INDEX(GMW!$A$2:$NF$60,MATCH(1,(GMW!$NE$2:$NE$60=H$3)*(GMW!$ND$2:$ND$60=H$4),0),$B8-1966)} -> 0.001
B9: =+B8+1 -> 1975 | C9: {=INDEX(GMW!$A$2:$NF$60,MATCH(1,(GMW!$NE$2:$NE$60=C$3)*(GMW!$ND$2:$ND$60=C$4),0),$B9-1966)} -> 0.001 | D9: {=INDEX(GMW!$A$2:$NF$60,MATCH(1,(GMW!$NE$2:$NE$60=D$3)*(GMW!$ND$2:$ND$60=D$4),0),$B9-1966)} -> 0.001 | E9: {=INDEX(GMW!$A$2:$NF$60,MATCH(1,(GMW!$NE$2:$NE$60=E$3)*(GMW!$ND$2:$ND$60=E$4),0),$B9-1966)} -> 11.5 | F9: {=INDEX(GMW!$A$2:$NF$60,MATCH(1,(GMW!$NE$2:$NE$60=F$3)*(GMW!$ND$2:$ND$60=F$4),0),$B9-1966)} -> 0.001 | G9: {=INDEX(GMW!$A$2:$NF$60,MATCH(1,(GMW!$NE$2:$NE$60=G$3)*(GMW!$ND$2:$ND$60=G$4),0),$B9-1966)} -> 10 | H9: {=INDEX(GMW!$A$2:$NF$60,MATCH(1,(GMW!$NE$2:$NE$60=H$3)*(GMW!$ND$2:$ND$60=H$4),0),$B9-1966)} -> 0.001
B10: =+B9+1 -> 1976 | C10: {=INDEX(GMW!$A$2:$NF$60,MATCH(1,(GMW!$NE$2:$NE$60=C$3)*(GMW!$ND$2:$ND$60=C$4),0),$B10-1966)} -> 0.001 | D10: {=INDEX(GMW!$A$2:$NF$60,MATCH(1,(GMW!$NE$2:$NE$60=D$3)*(GMW!$ND$2:$ND$60=D$4),0),$B10-1966)} -> 0.001 | E10: {=INDEX(GMW!$A$2:$NF$60,MATCH(1,(GMW!$NE$2:$NE$60=E$3)*(GMW!$ND$2:$ND$60=E$4),0),$B10-1966)} -> 13 | F10: {=INDEX(GMW!$A$2:$NF$60,MATCH(1,(GMW!$NE$2:$NE$60=F$3)*(GMW!$ND$2:$ND$60=F$4),0),$B10-1966)} -> 0.001 | G10: {=INDEX(GMW!$A$2:$NF$60,MATCH(1,(GMW!$NE$2:$NE$60=G$3)*(GMW!$ND$2:$ND$60=G$4),0),$B10-1966)} -> 11 | H10: {=INDEX(GMW!$A$2:$NF$60,MATCH(1,(GMW!$NE$2:$NE$60=H$3)*(GMW!$ND$2:$ND$60=H$4),0),$B10-1966)} -> 0.001
A11: 1974 | B11: =+B10+1 -> 1977 | C11: {=INDEX(GMW!$A$2:$NF$60,MATCH(1,(GMW!$NE$2:$NE$60=C$3)*(GMW!$ND$2:$ND$60=C$4),0),$B11-1966)} -> 0.001 | D11: {=INDEX(GMW!$A$2:$NF$60,MATCH(1,(GMW!$NE$2:$NE$60=D$3)*(GMW!$ND$2:$ND$60=D$4),0),$B11-1966)} -> 0.001 | E11: {=INDEX(GMW!$A$2:$NF$60,MATCH(1,(GMW!$NE$2:$NE$60=E$3)*(GMW!$ND$2:$ND$60=E$4),0),$B11-1966)} -> 12.5 | F11: {=INDEX(GMW!$A$2:$NF$60,MATCH(1,(GMW!$NE$2:$NE$60=F$3)*(GMW!$ND$2:$ND$60=F$4),0),$B11-1966)} -> 0.001 | G11: {=INDEX(GMW!$A$2:$NF$60,MATCH(1,(GMW!$NE$2:$NE$60=G$3)*(GMW!$ND$2:$ND$60=G$4),0),$B11-1966)} -> 11 | H11: {=INDEX(GMW!$A$2:$NF$60,MATCH(1,(GMW!$NE$2:$NE$60=H$3)*(GMW!$ND$2:$ND$60=H$4),0),$B11-1966)} -> 0.001
B12: =+B11+1 -> 1978 | C12: {=INDEX(GMW!$A$2:$NF$60,MATCH(1,(GMW!$NE$2:$NE$60=C$3)*(GMW!$ND$2:$ND$60=C$4),0),$B12-1966)} -> 0.001 | D12: {=INDEX(GMW!$A$2:$NF$60,MATCH(1,(GMW!$NE$2:$NE$60=D$3)*(GMW!$ND$2:$ND$60=D$4),0),$B12-1966)} -> 0.001 | E12: {=INDEX(GMW!$A$2:$NF$60,MATCH(1,(GMW!$NE$2:$NE$60=E$3)*(GMW!$ND$2:$ND$60=E$4),0),$B12-1966)} -> 11.75 | F12: {=INDEX(GMW!$A$2:$NF$60,MATCH(1,(GMW!$NE$2:$NE$60=F$3)*(GMW!$ND$2:$ND$60=F$4),0),$B12-1966)} -> 0.001 | G12: {=INDEX(GMW!$A$2:$NF$60,MATCH(1,(GMW!$NE$2:$NE$60=G$3)*(GMW!$ND$2:$ND$60=G$4),0),$B12-1966)} -> 11 | H12: {=INDEX(GMW!$A$2:$NF$60,MATCH(1,(GMW!$NE$2:$NE$60=H$3)*(GMW!$ND$2:$ND$60=H$4),0),$B12-1966)} -> 0.001
B13: =+B12+1 -> 1979 | C13: {=INDEX(GMW!$A$2:$NF$60,MATCH(1,(GMW!$NE$2:$NE$60=C$3)*(GMW!$ND$2:$ND$60=C$4),0),$B13-1966)} -> 0.001 | D13: {=INDEX(GMW!$A$2:$NF$60,MATCH(1,(GMW!$NE$2:$NE$60=D$3)*(GMW!$ND$2:$ND$60=D$4),0),$B13-1966)} -> 0.001 | E13: {=INDEX(GMW!$A$2:$NF$60,MATCH(1,(GMW!$NE$2:$NE$60=E$3)*(GMW!$ND$2:$ND$60=E$4),0),$B13-1966)} -> 11.5 | F13: {=INDEX(GMW!$A$2:$NF$60,MATCH(1,(GMW!$NE$2:$NE$60=F$3)*(GMW!$ND$2:$ND$60=F$4),0),$B13-1966)} -> 0.001 | G13: {=INDEX(GMW!$A$2:$NF$60,MATCH(1,(GMW!$NE$2:$NE$60=G$3)*(GMW!$ND$2:$ND$60=G$4),0),$B13-1966)} -> 11 | H13: {=INDEX(GMW!$A$2:$NF$60,MATCH(1,(GMW!$NE$2:$NE$60=H$3)*(GMW!$ND$2:$ND$60=H$4),0),$B13-1966)} -> 0.001
B14: =+B13+1 -> 1980 | C14: {=INDEX(GMW!$A$2:$NF$60,MATCH(1,(GMW!$NE$2:$NE$60=C$3)*(GMW!$ND$2:$ND$60=C$4),0),$B14-1966)} -> 0.001 | D14: {=INDEX(GMW!$A$2:$NF$60,MATCH(1,(GMW!$NE$2:$NE$60=D$3)*(GMW!$ND$2:$ND$60=D$4),0),$B14-1966)} -> 0.001 | E14: {=INDEX(GMW!$A$2:$NF$60,MATCH(1,(GMW!$NE$2:$NE$60=E$3)*(GMW!$ND$2:$ND$60=E$4),0),$B14-1966)} -> 11.5 | F14: {=INDEX(GMW!$A$2:$NF$60,MATCH(1,(GMW!$NE$2:$NE$60=F$3)*(GMW!$ND$2:$ND$60=F$4),0),$B14-1966)} -> 0.001 | G14: {=INDEX(GMW!$A$2:$NF$60,MATCH(1,(GMW!$NE$2:$NE$60=G$3)*(GMW!$ND$2:$ND$60=G$4),0),$B14-1966)} -> 11 | H14: {=INDEX(GMW!$A$2:$NF$60,MATCH(1,(GMW!$NE$2:$NE$60=H$3)*(GMW!$ND$2:$ND$60=H$4),0),$B14-1966)} -> 0.001
A15: 1975 | B15: =+B14+1 -> 1981 | C15: {=INDEX(GMW!$A$2:$NF$60,MATCH(1,(GMW!$NE$2:$NE$60=C$3)*(GMW!$ND$2:$ND$60=C$4),0),$B15-1966)} -> 0.001 | D15: {=INDEX(GMW!$A$2:$NF$60,MATCH(1,(GMW!$NE$2:$NE$60=D$3)*(GMW!$ND$2:$ND$60=D$4),0),$B15-1966)} -> 0.001 | E15: {=INDEX(GMW!$A$2:$NF$60,MATCH(1,(GMW!$NE$2:$NE$60=E$3)*(GMW!$ND$2:$ND$60=E$4),0),$B15-1966)} -> 10 | F15: {=INDEX(GMW!$A$2:$NF$60,MATCH(1,(GMW!$NE$2:$NE$60=F$3)*(GMW!$ND$2:$ND$60=F$4),0),$B15-1966)} -> 0.001 | G15: {=INDEX(GMW!$A$2:$NF$60,MATCH(1,(GMW!$NE$2:$NE$60=G$3)*(GMW!$ND$2:$ND$60=G$4),0),$B15-1966)} -> 11 | H15: {=INDEX(GMW!$A$2:$NF$60,MATCH(1,(GMW!$NE$2:$NE$60=H$3)*(GMW!$ND$2:$ND$60=H$4),0),$B15-1966)} -> 0.001
B16: =+B15+1 -> 1982 | C16: {=INDEX(GMW!$A$2:$NF$60,MATCH(1,(GMW!$NE$2:$NE$60=C$3)*(GMW!$ND$2:$ND$60=C$4),0),$B16-1966)} -> 0.001 | D16: {=INDEX(GMW!$A$2:$NF$60,MATCH(1,(GMW!$NE$2:$NE$60=D$3)*(GMW!$ND$2:$ND$60=D$4),0),$B16-1966)} -> 0.001 | E16: {=INDEX(GMW!$A$2:$NF$60,MATCH(1,(GMW!$NE$2:$NE$60=E$3)*(GMW!$ND$2:$ND$60=E$4),0),$B16-1966)} -> 10 | F16: {=INDEX(GMW!$A$2:$NF$60,MATCH(1,(GMW!$NE$2:$NE$60=F$3)*(GMW!$ND$2:$ND$60=F$4),0),$B16-1966)} -> 0.001 | G16: {=INDEX(GMW!$A$2:$NF$60,MATCH(1,(GMW!$NE$2:$NE$60=G$3)*(GMW!$ND$2:$ND$60=G$4),0),$B16-1966)} -> 11 | H16: {=INDEX(GMW!$A$2:$NF$60,MATCH(1,(GMW!$NE$2:$NE$60=H$3)*(GMW!$ND$2:$ND$60=H$4),0),$B16-1966)} -> 0.001
B17: =+B16+1 -> 1983 | C17: {=INDEX(GMW!$A$2:$NF$60,MATCH(1,(GMW!$NE$2:$NE$60=C$3)*(GMW!$ND$2:$ND$60=C$4),0),$B17-1966)} -> 0.001 | D17: {=INDEX(GMW!$A$2:$NF$60,MATCH(1,(GMW!$NE$2:$NE$60=D$3)*(GMW!$ND$2:$ND$60=D$4),0),$B17-1966)} -> 0.001 | E17: {=INDEX(GMW!$A$2:$NF$60,MATCH(1,(GMW!$NE$2:$NE$60=E$3)*(GMW!$ND$2:$ND$60=E$4),0),$B17-1966)} -> 11 | F17: {=INDEX(GMW!$A$2:$NF$60,MATCH(1,(GMW!$NE$2:$NE$60=F$3)*(GMW!$ND$2:$ND$60=F$4),0),$B17-1966)} -> 0.001 | G17: {=INDEX(GMW!$A$2:$NF$60,MATCH(1,(GMW!$NE$2:$NE$60=G$3)*(GMW!$ND$2:$ND$60=G$4),0),$B17-1966)} -> 11 | H17: {=INDEX(GMW!$A$2:$NF$60,MATCH(1,(GMW!$NE$2:$NE$60=H$3)*(GMW!$ND$2:$ND$60=H$4),0),$B17-1966)} -> 0.001
B18: =+B17+1 -> 1984 | C18: {=INDEX(GMW!$A$2:$NF$60,MATCH(1,(GMW!$NE$2:$NE$60=C$3)*(GMW!$ND$2:$ND$60=C$4),0),$B18-1966)} -> 0.001 | D18: {=INDEX(GMW!$A$2:$NF$60,MATCH(1,(GMW!$NE$2:$NE$60=D$3)*(GMW!$ND$2:$ND$60=D$4),0),$B18-1966)} -> 0.001 | E18: {=INDEX(GMW!$A$2:$NF$60,MATCH(1,(GMW!$NE$2:$NE$60=E$3)*(GMW!$ND$2:$ND$60=E$4),0),$B18-1966)} -> 11.25 | F18: {=INDEX(GMW!$A$2:$NF$60,MATCH(1,(GMW!$NE$2:$NE$60=F$3)*(GMW!$ND$2:$ND$60=F$4),0),$B18-1966)} -> 0.001 | G18: {=INDEX(GMW!$A$2:$NF$60,MATCH(1,(GMW!$NE$2:$NE$60=G$3)*(GMW!$ND$2:$ND$60=G$4),0),$B18-1966)} -> 11 | H18: {=INDEX(GMW!$A$2:$NF$60,MATCH(1,(GMW!$NE$2:$NE$60=H$3)*(GMW!$ND$2:$ND$60=H$4),0),$B18-1966)} -> 0.001
A19: 1976 | B19: =+B18+1 -> 1985 | C19: {=INDEX(GMW!$A$2:$NF$60,MATCH(1,(GMW!$NE$2:$NE$60=C$3)*(GMW!$ND$2:$ND$60=C$4),0),$B19-1966)} -> 0.001 | D19: {=INDEX(GMW!$A$2:$NF$60,MATCH(1,(GMW!$NE$2:$NE$60=D$3)*(GMW!$ND$2:$ND$60=D$4),0),$B19-1966)} -> 0.001 | E19: {=INDEX(GMW!$A$2:$NF$60,MATCH(1,(GMW!$NE$2:$NE$60=E$3)*(GMW!$ND$2:$ND$60=E$4),0),$B19-1966)} -> 9 | F19: {=INDEX(GMW!$A$2:$NF$60,MATCH(1,(GMW!$NE$2:$NE$60=F$3)*(GMW!$ND$2:$ND$60=F$4),0),$B19-1966)} -> 0.001 | G19: {=INDEX(GMW!$A$2:$NF$60,MATCH(1,(GMW!$NE$2:$NE$60=G$3)*(GMW!$ND$2:$ND$60=G$4),0),$B19-1966)} -> 11 | H19: {=INDEX(GMW!$A$2:$NF$60,MATCH(1,(GMW!$NE$2:$NE$60=H$3)*(GMW!$ND$2:$ND$60=H$4),0),$B19-1966)} -> 0.001
B20: =+B19+1 -> 1986 | C20: {=INDEX(GMW!$A$2:$NF$60,MATCH(1,(GMW!$NE$2:$NE$60=C$3)*(GMW!$ND$2:$ND$60=C$4),0),$B20-1966)} -> 0.001 | D20: {=INDEX(GMW!$A$2:$NF$60,MATCH(1,(GMW!$NE$2:$NE$60=D$3)*(GMW!$ND$2:$ND$60=D$4),0),$B20-1966)} -> 0.001 | E20: {=INDEX(GMW!$A$2:$NF$60,MATCH(1,(GMW!$NE$2:$NE$60=E$3)*(GMW!$ND$2:$ND$60=E$4),0),$B20-1966)} -> 11.5 | F20: {=INDEX(GMW!$A$2:$NF$60,MATCH(1,(GMW!$NE$2:$NE$60=F$3)*(GMW!$ND$2:$ND$60=F$4),0),$B20-1966)} -> 0.001 | G20: {=INDEX(GMW!$A$2:$NF$60,MATCH(1,(GMW!$NE$2:$NE$60=G$3)*(GMW!$ND$2:$ND$60=G$4),0),$B20-1966)} -> 10.5 | H20: {=INDEX(GMW!$A$2:$NF$60,MATCH(1,(GMW!$NE$2:$NE$60=H$3)*(GMW!$ND$2:$ND$60=H$4),0),$B20-1966)} -> 0.001
B21: =+B20+1 -> 1987 | C21: {=INDEX(GMW!$A$2:$NF$60,MATCH(1,(GMW!$NE$2:$NE$60=C$3)*(GMW!$ND$2:$ND$60=C$4),0),$B21-1966)} -> 0.001 | D21: {=INDEX(GMW!$A$2:$NF$60,MATCH(1,(GMW!$NE$2:$NE$60=D$3)*(GMW!$ND$2:$ND$60=D$4),0),$B21-1966)} -> 0.001 | E21: {=INDEX(GMW!$A$2:$NF$60,MATCH(1,(GMW!$NE$2:$NE$60=E$3)*(GMW!$ND$2:$ND$60=E$4),0),$B21-1966)} -> 13 | F21: {=INDEX(GMW!$A$2:$NF$60,MATCH(1,(GMW!$NE$2:$NE$60=F$3)*(GMW!$ND$2:$ND$60=F$4),0),$B21-1966)} -> 0.001 | G21: {=INDEX(GMW!$A$2:$NF$60,MATCH(1,(GMW!$NE$2:$NE$60=G$3)*(GMW!$ND$2:$ND$60=G$4),0),$B21-1966)} -> 10.5 | H21: {=INDEX(GMW!$A$2:$NF$60,MATCH(1,(GMW!$NE$2:$NE$60=H$3)*(GMW!$ND$2:$ND$60=H$4),0),$B21-1966)} -> 0.001
B22: =+B21+1 -> 1988 | C22: {=INDEX(GMW!$A$2:$NF$60,MATCH(1,(GMW!$NE$2:$NE$60=C$3)*(GMW!$ND$2:$ND$60=C$4),0),$B22-1966)} -> 0.001 | D22: {=INDEX(GMW!$A$2:$NF$60,MATCH(1,(GMW!$NE$2:$NE$60=D$3)*(GMW!$ND$2:$ND$60=D$4),0),$B22-1966)} -> 0.001 | E22: {=INDEX(GMW!$A$2:$NF$60,MATCH(1,(GMW!$NE$2:$NE$60=E$3)*(GMW!$ND$2:$ND$60=E$4),0),$B22-1966)} -> 14.25 | F22: {=INDEX(GMW!$A$2:$NF$60,MATCH(1,(GMW!$NE$2:$NE$60=F$3)*(GMW!$ND$2:$ND$60=F$4),0),$B22-1966)} -> 0.001 | G22: {=INDEX(GMW!$A$2:$NF$60,MATCH(1,(GMW!$NE$2:$NE$60=G$3)*(GMW!$ND$2:$ND$60=G$4),0),$B22-1966)} -> 12.25 | H22: {=INDEX(GMW!$A$2:$NF$60,MATCH(1,(GMW!$NE$2:$NE$60=H$3)*(GMW!$ND$2:$ND$60=H$4),0),$B22-1966)} -> 0.001
A23: 1977 | B23: =+B22+1 -> 1989 | C23: {=INDEX(GMW!$A$2:$NF$60,MATCH(1,(GMW!$NE$2:$NE$60=C$3)*(GMW!$ND$2:$ND$60=C$4),0),$B23-1966)} -> 0.001 | D23: {=INDEX(GMW!$A$2:$NF$60,MATCH(1,(GMW!$NE$2:$NE$60=D$3)*(GMW!$ND$2:$ND$60=D$4),0),$B23-1966)} -> 0.001 | E23: {=INDEX(GMW!$A$2:$NF$60,MATCH(1,(GMW!$NE$2:$NE$60=E$3)*(GMW!$ND$2:$ND$60=E$4),0),$B23-1966)} -> 9.5 | F23: {=INDEX(GMW!$A$2:$NF$60,MATCH(1,(GMW!$NE$2:$NE$60=F$3)*(GMW!$ND$2:$ND$60=F$4),0),$B23-1966)} -> 0.001 | G23: {=INDEX(GMW!$A$2:$NF$60,MATCH(1,(GMW!$NE$2:$NE$60=G$3)*(GMW!$ND$2:$ND$60=G$4),0),$B23-1966)} -> 12.25 | H23: {=INDEX(GMW!$A$2:$NF$60,MATCH(1,(GMW!$NE$2:$NE$60=H$3)*(GMW!$ND$2:$ND$60=H$4),0),$B23-1966)} -> 0.001
B24: =+B23+1 -> 1990 | C24: {=INDEX(GMW!$A$2:$NF$60,MATCH(1,(GMW!$NE$2:$NE$60=C$3)*(GMW!$ND$2:$ND$60=C$4),0),$B24-1966)} -> 0.001 | D24: {=INDEX(GMW!$A$2:$NF$60,MATCH(1,(GMW!$NE$2:$NE$60=D$3)*(GMW!$ND$2:$ND$60=D$4),0),$B24-1966)} -> 0.001 | E24: {=INDEX(GMW!$A$2:$NF$60,MATCH(1,(GMW!$NE$2:$NE$60=E$3)*(GMW!$ND$2:$ND$60=E$4),0),$B24-1966)} -> 8 | F24: {=INDEX(GMW!$A$2:$NF$60,MATCH(1,(GMW!$NE$2:$NE$60=F$3)*(GMW!$ND$2:$ND$60=F$4),0),$B24-1966)} -> 0.001 | G24: {=INDEX(GMW!$A$2:$NF$60,MATCH(1,(GMW!$NE$2:$NE$60=G$3)*(GMW!$ND$2:$ND$60=G$4),0),$B24-1966)} -> 11.25 | H24: {=INDEX(GMW!$A$2:$NF$60,MATCH(1,(GMW!$NE$2:$NE$60=H$3)*(GMW!$ND$2:$ND$60=H$4),0),$B24-1966)} -> 0.001
B25: =+B24+1 -> 1991 | C25: {=INDEX(GMW!$A$2:$NF$60,MATCH(1,(GMW!$NE$2:$NE$60=C$3)*(GMW!$ND$2:$ND$60=C$4),0),$B25-1966)} -> 0.001 | D25: {=INDEX(GMW!$A$2:$NF$60,MATCH(1,(GMW!$NE$2:$NE$60=D$3)*(GMW!$ND$2:$ND$60=D$4),0),$B25-1966)} -> 0.001 | E25: {=INDEX(GMW!$A$2:$NF$60,MATCH(1,(GMW!$NE$2:$NE$60=E$3)*(GMW!$ND$2:$ND$60=E$4),0),$B25-1966)} -> 6 | F25: {=INDEX(GMW!$A$2:$NF$60,MATCH(1,(GMW!$NE$2:$NE$60=F$3)*(GMW!$ND$2:$ND$60=F$4),0),$B25-1966)} -> 0.001 | G25: {=INDEX(GMW!$A$2:$NF$60,MATCH(1,(GMW!$NE$2:$NE$60=G$3)*(GMW!$ND$2:$ND$60=G$4),0),$B25-1966)} -> 10.5 | H25: {=INDEX(GMW!$A$2:$NF$60,MATCH(1,(GMW!$NE$2:$NE$60=H$3)*(GMW!$ND$2:$ND$60=H$4),0),$B25-1966)} -> 0.001
B26: =+B25+1 -> 1992 | C26: {=INDEX(GMW!$A$2:$NF$60,MATCH(1,(GMW!$NE$2:$NE$60=C$3)*(GMW!$ND$2:$ND$60=C$4),0),$B26-1966)} -> 0.001 | D26: {=INDEX(GMW!$A$2:$NF$60,MATCH(1,(GMW!$NE$2:$NE$60=D$3)*(GMW!$ND$2:$ND$60=D$4),0),$B26-1966)} -> 0.001 | E26: {=INDEX(GMW!$A$2:$NF$60,MATCH(1,(GMW!$NE$2:$NE$60=E$3)*(GMW!$ND$2:$ND$60=E$4),0),$B26-1966)} -> 7 | F26: {=INDEX(GMW!$A$2:$NF$60,MATCH(1,(GMW!$NE$2:$NE$60=F$3)*(GMW!$ND$2:$ND$60=F$4),0),$B26-1966)} -> 0.001 | G26: {=INDEX(GMW!$A$2:$NF$60,MATCH(1,(GMW!$NE$2:$NE$60=G$3)*(GMW!$ND$2:$ND$60=G$4),0),$B26-1966)} -> 9.5 | H26: {=INDEX(GMW!$A$2:$NF$60,MATCH(1,(GMW!$NE$2:$NE$60=H$3)*(GMW!$ND$2:$ND$60=H$4),0),$B26-1966)} -> 0.001
A27: 1978 | B27: =+B26+1 -> 1993 | C27: {=INDEX(GMW!$A$2:$NF$60,MATCH(1,(GMW!$NE$2:$NE$60=C$3)*(GMW!$ND$2:$ND$60=C$4),0),$B27-1966)} -> 0.001 | D27: {=INDEX(GMW!$A$2:$NF$60,MATCH(1,(GMW!$NE$2:$NE$60=D$3)*(GMW!$ND$2:$ND$60=D$4),0),$B27-1966)} -> 0.001 | E27: {=INDEX(GMW!$A$2:$NF$60,MATCH(1,(GMW!$NE$2:$NE$60=E$3)*(GMW!$ND$2:$ND$60=E$4),0),$B27-1966)} -> 6.5 | F27: {=INDEX(GMW!$A$2:$NF$60,MATCH(1,(GMW!$NE$2:$NE$60=F$3)*(GMW!$ND$2:$ND$60=F$4),0),$B27-1966)} -> 0.001 | G27: {=INDEX(GMW!$A$2:$NF$60,MATCH(1,(GMW!$NE$2:$NE$60=G$3)*(GMW!$ND$2:$ND$60=G$4),0),$B27-1966)} -> 8.5 | H27: {=INDEX(GMW!$A$2:$NF$60,MATCH(1,(GMW!$NE$2:$NE$60=H$3)*(GMW!$ND$2:$ND$60=H$4),0),$B27-1966)} -> 0.001
B28: =+B27+1 -> 1994 | C28: {=INDEX(GMW!$A$2:$NF$60,MATCH(1,(GMW!$NE$2:$NE$60=C$3)*(GMW!$ND$2:$ND$60=C$4),0),$B28-1966)} -> 0.001 | D28: {=INDEX(GMW!$A$2:$NF$60,MATCH(1,(GMW!$NE$2:$NE$60=D$3)*(GMW!$ND$2:$ND$60=D$4),0),$B28-1966)} -> 0.001 | E28: {=INDEX(GMW!$A$2:$NF$60,MATCH(1,(GMW!$NE$2:$NE$60=E$3)*(GMW!$ND$2:$ND$60=E$4),0),$B28-1966)} -> 10 | F28: {=INDEX(GMW!$A$2:$NF$60,MATCH(1,(GMW!$NE$2:$NE$60=F$3)*(GMW!$ND$2:$ND$60=F$4),0),$B28-1966)} -> 0.001 | G28: {=INDEX(GMW!$A$2:$NF$60,MATCH(1,(GMW!$NE$2:$NE$60=G$3)*(GMW!$ND$2:$ND$60=G$4),0),$B28-1966)} -> 8.5 | H28: {=INDEX(GMW!$A$2:$NF$60,MATCH(1,(GMW!$NE$2:$NE$60=H$3)*(GMW!$ND$2:$ND$60=H$4),0),$B28-1966)} -> 0.001
B29: =+B28+1 -> 1995 | C29: {=INDEX(GMW!$A$2:$NF$60,MATCH(1,(GMW!$NE$2:$NE$60=C$3)*(GMW!$ND$2:$ND$60=C$4),0),$B29-1966)} -> 0.001 | D29: {=INDEX(GMW!$A$2:$NF$60,MATCH(1,(GMW!$NE$2:$NE$60=D$3)*(GMW!$ND$2:$ND$60=D$4),0),$B29-1966)} -> 0.001 | E29: {=INDEX(GMW!$A$2:$NF$60,MATCH(1,(GMW!$NE$2:$NE$60=E$3)*(GMW!$ND$2:$ND$60=E$4),0),$B29-1966)} -> 10 | F29: {=INDEX(GMW!$A$2:$NF$60,MATCH(1,(GMW!$NE$2:$NE$60=F$3)*(GMW!$ND$2:$ND$60=F$4),0),$B29-1966)} -> 0.001 | G29: {=INDEX(GMW!$A$2:$NF$60,MATCH(1,(GMW!$NE$2:$NE$60=G$3)*(GMW!$ND$2:$ND$60=G$4),0),$B29-1966)} -> 9.75 | H29: {=INDEX(GMW!$A$2:$NF$60,MATCH(1,(GMW!$NE$2:$NE$60=H$3)*(GMW!$ND$2:$ND$60=H$4),0),$B29-1966)} -> 0.001
B30: =+B29+1 -> 1996 | C30: {=INDEX(GMW!$A$2:$NF$60,MATCH(1,(GMW!$NE$2:$NE$60=C$3)*(GMW!$ND$2:$ND$60=C$4),0),$B30-1966)} -> 0.001 | D30: {=INDEX(GMW!$A$2:$NF$60,MATCH(1,(GMW!$NE$2:$NE$60=D$3)*(GMW!$ND$2:$ND$60=D$4),0),$B30-1966)} -> 0.001 | E30: {=INDEX(GMW!$A$2:$NF$60,MATCH(1,(GMW!$NE$2:$NE$60=E$3)*(GMW!$ND$2:$ND$60=E$4),0),$B30-1966)} -> 12.5 | F30: {=INDEX(GMW!$A$2:$NF$60,MATCH(1,(GMW!$NE$2:$NE$60=F$3)*(GMW!$ND$2:$ND$60=F$4),0),$B30-1966)} -> 0.001 | G30: {=INDEX(GMW!$A$2:$NF$60,MATCH(1,(GMW!$NE$2:$NE$60=G$3)*(GMW!$ND$2:$ND$60=G$4),0),$B30-1966)} -> 10.42 | H30: {=INDEX(GMW!$A$2:$NF$60,MATCH(1,(GMW!$NE$2:$NE$60=H$3)*(GMW!$ND$2:$ND$60=H$4),0),$B30-1966)} -> 0.001
A31: 1979 | B31: =+B30+1 -> 1997 | C31: {=INDEX(GMW!$A$2:$NF$60,MATCH(1,(GMW!$NE$2:$NE$60=C$3)*(GMW!$ND$2:$ND$60=C$4),0),$B31-1966)} -> 0.001 | D31: {=INDEX(GMW!$A$2:$NF$60,MATCH(1,(GMW!$NE$2:$NE$60=D$3)*(GMW!$ND$2:$ND$60=D$4),0),$B31-1966)} -> 0.001 | E31: {=INDEX(GMW!$A$2:$NF$60,MATCH(1,(GMW!$NE$2:$NE$60=E$3)*(GMW!$ND$2:$ND$60=E$4),0),$B31-1966)} -> 13 | F31: {=INDEX(GMW!$A$2:$NF$60,MATCH(1,(GMW!$NE$2:$NE$60=F$3)*(GMW!$ND$2:$ND$60=F$4),0),$B31-1966)} -> 0.001 | G31: {=INDEX(GMW!$A$2:$NF$60,MATCH(1,(GMW!$NE$2:$NE$60=G$3)*(GMW!$ND$2:$ND$60=G$4),0),$B31-1966)} -> 11.75 | H31: {=INDEX(GMW!$A$2:$NF$60,MATCH(1,(GMW!$NE$2:$NE$60=H$3)*(GMW!$ND$2:$ND$60=H$4),0),$B31-1966)} -> 0.001
B32: =+B31+1 -> 1998 | C32: {=INDEX(GMW!$A$2:$NF$60,MATCH(1,(GMW!$NE$2:$NE$60=C$3)*(GMW!$ND$2:$ND$60=C$4),0),$B32-1966)} -> 0.001 | D32: {=INDEX(GMW!$A$2:$NF$60,MATCH(1,(GMW!$NE$2:$NE$60=D$3)*(GMW!$ND$2:$ND$60=D$4),0),$B32-1966)} -> 0.001 | E32: {=INDEX(GMW!$A$2:$NF$60,MATCH(1,(GMW!$NE$2:$NE$60=E$3)*(GMW!$ND$2:$ND$60=E$4),0),$B32-1966)} -> 14 | F32: {=INDEX(GMW!$A$2:$NF$60,MATCH(1,(GMW!$NE$2:$NE$60=F$3)*(GMW!$ND$2:$ND$60=F$4),0),$B32-1966)} -> 0.001 | G32: {=INDEX(GMW!$A$2:$NF$60,MATCH(1,(GMW!$NE$2:$NE$60=G$3)*(GMW!$ND$2:$ND$60=G$4),0),$B32-1966)} -> 11.246 | H32: {=INDEX(GMW!$A$2:$NF$60,MATCH(1,(GMW!$NE$2:$NE$60=H$3)*(GMW!$ND$2:$ND$60=H$4),0),$B32-1966)} -> 0.001
B33: =+B32+1 -> 1999 | C33: {=INDEX(GMW!$A$2:$NF$60,MATCH(1,(GMW!$NE$2:$NE$60=C$3)*(GMW!$ND$2:$ND$60=C$4),0),$B33-1966)} -> 0.001 | D33: {=INDEX(GMW!$A$2:$NF$60,MATCH(1,(GMW!$NE$2:$NE$60=D$3)*(GMW!$ND$2:$ND$60=D$4),0),$B33-1966)} -> 0.001 | E33: {=INDEX(GMW!$A$2:$NF$60,MATCH(1,(GMW!$NE$2:$NE$60=E$3)*(GMW!$ND$2:$ND$60=E$4),0),$B33-1966)} -> 14 | F33: {=INDEX(GMW!$A$2:$NF$60,MATCH(1,(GMW!$NE$2:$NE$60=F$3)*(GMW!$ND$2:$ND$60=F$4),0),$B33-1966)} -> 0.001 | G33: {=INDEX(GMW!$A$2:$NF$60,MATCH(1,(GMW!$NE$2:$NE$60=G$3)*(GMW!$ND$2:$ND$60=G$4),0),$B33-1966)} -> 11.75 | H33: {=INDEX(GMW!$A$2:$NF$60,MATCH(1,(GMW!$NE$2:$NE$60=H$3)*(GMW!$ND$2:$ND$60=H$4),0),$B33-1966)} -> 0.001
B34: =+B33+1 -> 2000 | C34: {=INDEX(GMW!$A$2:$NF$60,MATCH(1,(GMW!$NE$2:$NE$60=C$3)*(GMW!$ND$2:$ND$60=C$4),0),$B34-1966)} -> 0.001 | D34: {=INDEX(GMW!$A$2:$NF$60,MATCH(1,(GMW!$NE$2:$NE$60=D$3)*(GMW!$ND$2:$ND$60=D$4),0),$B34-1966)} -> 0.001 | E34: {=INDEX(GMW!$A$2:$NF$60,MATCH(1,(GMW!$NE$2:$NE$60=E$3)*(GMW!$ND$2:$ND$60=E$4),0),$B34-1966)} -> 17 | F34: {=INDEX(GMW!$A$2:$NF$60,MATCH(1,(GMW!$NE$2:$NE$60=F$3)*(GMW!$ND$2:$ND$60=F$4),0),$B34-1966)} -> 0.001 | G34: {=INDEX(GMW!$A$2:$NF$60,MATCH(1,(GMW!$NE$2:$NE$60=G$3)*(GMW!$ND$2:$ND$60=G$4),0),$B34-1966)} -> 13.38 | H34: {=INDEX(GMW!$A$2:$NF$60,MATCH(1,(GMW!$NE$2:$NE$60=H$3)*(GMW!$ND$2:$ND$60=H$4),0),$B34-1966)} -> 0.001
A35: 1980 | B35: =+B34+1 -> 2001 | C35: {=INDEX(GMW!$A$2:$NF$60,MATCH(1,(GMW!$NE$2:$NE$60=C$3)*(GMW!$ND$2:$ND$60=C$4),0),$B35-1966)} -> 0.001 | D35: {=INDEX(GMW!$A$2:$NF$60,MATCH(1,(GMW!$NE$2:$NE$60=D$3)*(GMW!$ND$2:$ND$60=D$4),0),$B35-1966)} -> 0.001 | E35: {=INDEX(GMW!$A$2:$NF$60,MATCH(1,(GMW!$NE$2:$NE$60=E$3)*(GMW!$ND$2:$ND$60=E$4),0),$B35-1966)} -> 17 | F35: {=INDEX(GMW!$A$2:$NF$60,MATCH(1,(GMW!$NE$2:$NE$60=F$3)*(GMW!$ND$2:$ND$60=F$4),0),$B35-1966)} -> 0.001 | G35: {=INDEX(GMW!$A$2:$NF$60,MATCH(1,(GMW!$NE$2:$NE$60=G$3)*(GMW!$ND$2:$ND$60=G$4),0),$B35-1966)} -> 14.7821 | H35: {=INDEX(GMW!$A$2:$NF$60,MATCH(1,(GMW!$NE$2:$NE$60=H$3)*(GMW!$ND$2:$ND$60=H$4),0),$B35-1966)} -> 21.73742
B36: =+B35+1 -> 2002 | C36: {=INDEX(GMW!$A$2:$NF$60,MATCH(1,(GMW!$NE$2:$NE$60=C$3)*(GMW!$ND$2:$ND$60=C$4),0),$B36-1966)} -> 0.001 | D36: {=INDEX(GMW!$A$2:$NF$60,MATCH(1,(GMW!$NE$2:$NE$60=D$3)*(GMW!$ND$2:$ND$60=D$4),0),$B36-1966)} -> 0.001 | E36: {=INDEX(GMW!$A$2:$NF$60,MATCH(1,(GMW!$NE$2:$NE$60=E$3)*(GMW!$ND$2:$ND$60=E$4),0),$B36-1966)} -> 17 | F36: {=INDEX(GMW!$A$2:$NF$60,MATCH(1,(GMW!$NE$2:$NE$60=F$3)*(GMW!$ND$2:$ND$60=F$4),0),$B36-1966)} -> 0.001 | G36: {=INDEX(GMW!$A$2:$NF$60,MATCH(1,(GMW!$NE$2:$NE$60=G$3)*(GMW!$ND$2:$ND$60=G$4),0),$B36-1966)} -> 14.8755 | H36: {=INDEX(GMW!$A$2:$NF$60,MATCH(1,(GMW!$NE$2:$NE$60=H$3)*(GMW!$ND$2:$ND$60=H$4),0),$B36-1966)} -> 21.10538
B37: =+B36+1 -> 2003 | C37: {=INDEX(GMW!$A$2:$NF$60,MATCH(1,(GMW!$NE$2:$NE$60=C$3)*(GMW!$ND$2:$ND$60=C$4),0),$B37-1966)} -> 0.001 | D37: {=INDEX(GMW!$A$2:$NF$60,MATCH(1,(GMW!$NE$2:$NE$60=D$3)*(GMW!$ND$2:$ND$60=D$4),0),$B37-1966)} -> 0.001 | E37: {=INDEX(GMW!$A$2:$NF$60,MATCH(1,(GMW!$NE$2:$NE$60=E$3)*(GMW!$ND$2:$ND$60=E$4),0),$B37-1966)} -> 16 | F37: {=INDEX(GMW!$A$2:$NF$60,MATCH(1,(GMW!$NE$2:$NE$60=F$3)*(GMW!$ND$2:$ND$60=F$4),0),$B37-1966)} -> 0.001 | G37: {=INDEX(GMW!$A$2:$NF$60,MATCH(1,(GMW!$NE$2:$NE$60=G$3)*(GMW!$ND$2:$ND$60=G$4),0),$B37-1966)} -> 14.8876 | H37: {=INDEX(GMW!$A$2:$NF$60,MATCH(1,(GMW!$NE$2:$NE$60=H$3)*(GMW!$ND$2:$ND$60=H$4),0),$B37-1966)} -> 20.08708
B38: =+B37+1 -> 2004 | C38: {=INDEX(GMW!$A$2:$NF$60,MATCH(1,(GMW!$NE$2:$NE$60=C$3)*(GMW!$ND$2:$ND$60=C$4),0),$B38-1966)} -> 0.001 | D38: {=INDEX(GMW!$A$2:$NF$60,MATCH(1,(GMW!$NE$2:$NE$60=D$3)*(GMW!$ND$2:$ND$60=D$4),0),$B38-1966)} -> 0.001 | E38: {=INDEX(GMW!$A$2:$NF$60,MATCH(1,(GMW!$NE$2:$NE$60=E$3)*(GMW!$ND$2:$ND$60=E$4),0),$B38-1966)} -> 14 | F38: {=INDEX(GMW!$A$2:$NF$60,MATCH(1,(GMW!$NE$2:$NE$60=F$3)*(GMW!$ND$2:$ND$60=F$4),0),$B38-1966)} -> 0.001 | G38: {=INDEX(GMW!$A$2:$NF$60,MATCH(1,(GMW!$NE$2:$NE$60=G$3)*(GMW!$ND$2:$ND$60=G$4),0),$B38-1966)} -> 14.9682 | H38: {=INDEX(GMW!$A$2:$NF$60,MATCH(1,(GMW!$NE$2:$NE$60=H$3)*(GMW!$ND$2:$ND$60=H$4),0),$B38-1966)} -> 20.07705
A39: 1981 | B39: =+B38+1 -> 2005 | C39: {=INDEX(GMW!$A$2:$NF$60,MATCH(1,(GMW!$NE$2:$NE$60=C$3)*(GMW!$ND$2:$ND$60=C$4),0),$B39-1966)} -> 0.001 | D39: {=INDEX(GMW!$A$2:$NF$60,MATCH(1,(GMW!$NE$2:$NE$60=D$3)*(GMW!$ND$2:$ND$60=D$4),0),$B39-1966)} -> 0.001 | E39: {=INDEX(GMW!$A$2:$NF$60,MATCH(1,(GMW!$NE$2:$NE$60=E$3)*(GMW!$ND$2:$ND$60=E$4),0),$B39-1966)} -> 12 | F39: {=INDEX(GMW!$A$2:$NF$60,MATCH(1,(GMW!$NE$2:$NE$60=F$3)*(GMW!$ND$2:$ND$60=F$4),0),$B39-1966)} -> 0.001 | G39: {=INDEX(GMW!$A$2:$NF$60,MATCH(1,(GMW!$NE$2:$NE$60=G$3)*(GMW!$ND$2:$ND$60=G$4),0),$B39-1966)} -> 13.8888 | H39: {=INDEX(GMW!$A$2:$NF$60,MATCH(1,(GMW!$NE$2:$NE$60=H$3)*(GMW!$ND$2:$ND$60=H$4),0),$B39-1966)} -> 20.83951
B40: =+B39+1 -> 2006 | C40: {=INDEX(GMW!$A$2:$NF$60,MATCH(1,(GMW!$NE$2:$NE$60=C$3)*(GMW!$ND$2:$ND$60=C$4),0),$B40-1966)} -> 0.001 | D40: {=INDEX(GMW!$A$2:$NF$60,MATCH(1,(GMW!$NE$2:$NE$60=D$3)*(GMW!$ND$2:$ND$60=D$4),0),$B40-1966)} -> 0.001 | E40: {=INDEX(GMW!$A$2:$NF$60,MATCH(1,(GMW!$NE$2:$NE$60=E$3)*(GMW!$ND$2:$ND$60=E$4),0),$B40-1966)} -> 12 | F40: {=INDEX(GMW!$A$2:$NF$60,MATCH(1,(GMW!$NE$2:$NE$60=F$3)*(GMW!$ND$2:$ND$60=F$4),0),$B40-1966)} -> 0.001 | G40: {=INDEX(GMW!$A$2:$NF$60,MATCH(1,(GMW!$NE$2:$NE$60=G$3)*(GMW!$ND$2:$ND$60=G$4),0),$B40-1966)} -> 13.0457 | H40: {=INDEX(GMW!$A$2:$NF$60,MATCH(1,(GMW!$NE$2:$NE$60=H$3)*(GMW!$ND$2:$ND$60=H$4),0),$B40-1966)} -> 21.33612
...

Sheet GMW
A1: Location | B1: Indicator | C1: Scenario | D1: Units | E1: Scale | F1: Measurement | G1: 1973 Q1 | H1: 1973 Q2 | I1: 1973 Q3 | J1: 1973 Q4 | K1: 1974 Q1 | L1: 1974 Q2 | M1: 1974 Q3 | N1: 1974 Q4 | O1: 1975 Q1 | P1: 1975 Q2 | Q1: 1975 Q3 | R1: 1975 Q4 | S1: 1976 Q1 | T1: 1976 Q2 | U1: 1976 Q3 | V1: 1976 Q4 | W1: 1977 Q1 | X1: 1977 Q2 | Y1: 1977 Q3 | Z1: 1977 Q4 | AA1: 1978 Q1 | AB1: 1978 Q2 | AC1: 1978 Q3 | AD1: 1978 Q4 | AE1: 1979 Q1 | AF1: 1979 Q2 | AG1: 1979 Q3 | AH1: 1979 Q4 | AI1: 1980 Q1 | AJ1: 1980 Q2 | AK1: 1980 Q3 | AL1: 1980 Q4 | AM1: 1981 Q1 | AN1: 1981 Q2 | AO1: 1981 Q3 | AP1: 1981 Q4 | AQ1: 1982 Q1 | AR1: 1982 Q2 | AS1: 1982 Q3 | AT1: 1982 Q4 | AU1: 1983 Q1 | AV1: 1983 Q2 | AW1: 1983 Q3 | AX1: 1983 Q4 | AY1: 1984 Q1 | AZ1: 1984 Q2 | BA1: 1984 Q3 | BB1: 1984 Q4 | BC1: 1985 Q1 | BD1: 1985 Q2 | BE1: 1985 Q3 | BF1: 1985 Q4 | BG1: 1986 Q1 | BH1: 1986 Q2 | BI1: 1986 Q3 | BJ1: 1986 Q4 | BK1: 1987 Q1 | BL1: 1987 Q2 | BM1: 1987 Q3 | BN1: 1987 Q4 | BO1: 1988 Q1 | BP1: 1988 Q2 | BQ1: 1988 Q3 | BR1: 1988 Q4 | BS1: 1989 Q1 | BT1: 1989 Q2 | BU1: 1989 Q3 | BV1: 1989 Q4 | BW1: 1990 Q1 | BX1: 1990 Q2 | BY1: 1990 Q3 | BZ1: 1990 Q4 | CA1: 1991 Q1 | CB1: 1991 Q2 | CC1: 1991 Q3 | CD1: 1991 Q4 | CE1: 1992 Q1 | CF1: 1992 Q2 | CG1: 1992 Q3 | CH1: 1992 Q4 | CI1: 1993 Q1 | CJ1: 1993 Q2 | CK1: 1993 Q3 | CL1: 1993 Q4 | CM1: 1994 Q1 | CN1: 1994 Q2 | CO1: 1994 Q3 | CP1: 1994 Q4 | CQ1: 1995 Q1 | CR1: 1995 Q2 | CS1: 1995 Q3 | CT1: 1995 Q4 | CU1: 1996 Q1 | CV1: 1996 Q2 | CW1: 1996 Q3 | CX1: 1996 Q4 | CY1: 1997 Q1 | CZ1: 1997 Q2 | DA1: 1997 Q3 | DB1: 1997 Q4 | DC1: 1998 Q1 | DD1: 1998 Q2 | DE1: 1998 Q3 | DF1: 1998 Q4 | DG1: 1999 Q1 | DH1: 1999 Q2 | DI1: 1999 Q3 | DJ1: 1999 Q4 | DK1: 2000 Q1 | DL1: 2000 Q2 | DM1: 2000 Q3 | DN1: 2000 Q4 | DO1: 2001 Q1 | DP1: 2001 Q2 | DQ1: 2001 Q3 | DR1: 2001 Q4 | DS1: 2002 Q1 | DT1: 2002 Q2 | DU1: 2002 Q3 | DV1: 2002 Q4 | DW1: 2003 Q1 | DX1: 2003 Q2 | DY1: 2003 Q3 | DZ1: 2003 Q4 | EA1: 2004 Q1 | EB1: 2004 Q2 | EC1: 2004 Q3 | ED1: 2004 Q4 | EE1: 2005 Q1 | EF1: 2005 Q2 | EG1: 2005 Q3 | EH1: 2005 Q4 | EI1: 2006 Q1 | EJ1: 2006 Q2 | EK1: 2006 Q3 | EL1: 2006 Q4 | EM1: 2007 Q1 | EN1: 2007 Q2 | EO1: 2007 Q3 | EP1: 2007 Q4 | EQ1: 2008 Q1 | ER1: 2008 Q2 | ES1: 2008 Q3 | ET1: 2008 Q4 | EU1: 2009 Q1 | EV1: 2009 Q2 | EW1: 2009 Q3 | EX1: 2009 Q4 | EY1: 2010 Q1 | EZ1: 2010 Q2 | FA1: 2010 Q3 | FB1: 2010 Q4 | FC1: 2011 Q1 | FD1: 2011 Q2 | FE1: 2011 Q3 | FF1: 2011 Q4 | FG1: 2012 Q1 | FH1: 2012 Q2 | FI1: 2012 Q3 | FJ1: 2012 Q4 | FK1: 2013 Q1 | FL1: 2013 Q2 | FM1: 2013 Q3 | FN1: 2013 Q4 | FO1: 2014 Q1 | FP1: 2014 Q2 | FQ1: 2014 Q3 | FR1: 2014 Q4 | FS1: 2015 Q1 | FT1: 2015 Q2 | FU1: 2015 Q3 | FV1: 2015 Q4 | FW1: 2016 Q1 | FX1: 2016 Q2 | FY1: 2016 Q3 | FZ1: 2016 Q4 | GA1: 2017 Q1 | GB1: 2017 Q2 | GC1: 2017 Q3 | GD1: 2017 Q4 | GE1: 2018 Q1 | GF1: 2018 Q2 | GG1: 2018 Q3 | GH1: 2018 Q4 | GI1: 2019 Q1 | GJ1: 2019 Q2 | GK1: 2019 Q3 | GL1: 2019 Q4 | GM1: 2020 Q1 | GN1: 2020 Q2 | GO1: 2020 Q3 | GP1: 2020 Q4 | GQ1: 2021 Q1 | GR1: 2021 Q2 | GS1: 2021 Q3 | GT1: 2021 Q4 | GU1: 2022 Q1 | GV1: 2022 Q2 | GW1: 2022 Q3 | GX1: 2022 Q4 | GY1: 2023 Q1 | GZ1: 2023 Q2 | HA1: 2023 Q3 | HB1: 2023 Q4 | HC1: 2024 Q1 | HD1: 2024 Q2 | HE1: 2024 Q3 | HF1: 2024 Q4 | HG1: 2025 Q1 | HH1: 2025 Q2 | HI1: 2025 Q3 | HJ1: 2025 Q4 | HK1: 2026 Q1 | HL1: 2026 Q2 | HM1: 2026 Q3 | HN1: 2026 Q4 | HO1: 2027 Q1 | HP1: 2027 Q2 | HQ1: 2027 Q3 | HR1: 2027 Q4 | HS1: 2028 Q1 | HT1: 2028 Q2 | HU1: 2028 Q3 | HV1: 2028 Q4 | HW1: 2029 Q1 | HX1: 2029 Q2 | HY1: 2029 Q3 | HZ1: 2029 Q4 | IA1: 2030 Q1 | IB1: 2030 Q2 | IC1: 2030 Q3 | ID1: 2030 Q4 | IE1: 2031 Q1 | IF1: 2031 Q2 | IG1: 2031 Q3 | IH1: 2031 Q4 | II1: 2032 Q1 | IJ1: 2032 Q2 | IK1: 2032 Q3 | IL1: 2032 Q4 | IM1: 2033 Q1 | IN1: 2033 Q2 | IO1: 2033 Q3 | IP1: 2033 Q4 | IQ1: 2034 Q1 | IR1: 2034 Q2 | IS1: 2034 Q3 | IT1: 2034 Q4 | IU1: 2035 Q1 | IV1: 2035 Q2 | IW1: 2035 Q3 | IX1: 2035 Q4 | IY1: 2036 Q1 | IZ1: 2036 Q2 | JA1: 2036 Q3 | JB1: 2036 Q4 | JC1: 2037 Q1 | JD1: 2037 Q2 | JE1: 2037 Q3 | JF1: 2037 Q4 | JG1: 2038 Q1 | JH1: 2038 Q2 | JI1: 2038 Q3 | JJ1: 2038 Q4 | JK1: 2039 Q1 | JL1: 2039 Q2 | JM1: 2039 Q3 | JN1: 2039 Q4 | JO1: 2040 Q1 | JP1: 2040 Q2 | JQ1: 2040 Q3 | JR1: 2040 Q4 | JS1: 2041 Q1 | JT1: 2041 Q2 | JU1: 2041 Q3 | JV1: 2041 Q4 | JW1: 2042 Q1 | JX1: 2042 Q2 | JY1: 2042 Q3 | JZ1: 2042 Q4 | KA1: 2043 Q1 | KB1: 2043 Q2 | KC1: 2043 Q3 | KD1: 2043 Q4 | KE1: 2044 Q1 | KF1: 2044 Q2 | KG1: 2044 Q3 | KH1: 2044 Q4 | KI1: 2045 Q1 | KJ1: 2045 Q2 | KK1: 2045 Q3 | KL1: 2045 Q4 | KM1: 2046 Q1 | KN1: 2046 Q2 | KO1: 2046 Q3 | KP1: 2046 Q4 | KQ1: 2047 Q1 | KR1: 2047 Q2 | KS1: 2047 Q3 | KT1: 2047 Q4 | KU1: 2048 Q1 | KV1: 2048 Q2 | KW1: 2048 Q3 | KX1: 2048 Q4 | KY1: 2049 Q1 | KZ1: 2049 Q2 | LA1: 2049 Q3 | LB1: 2049 Q4 | LC1: 2050 Q1 | LD1: 2050 Q2 | LE1: 2050 Q3 | LF1: 2050 Q4 | LG1: 2051 Q1 | LH1: 2051 Q2 | LI1: 2051 Q3 | LJ1: 2051 Q4 | LK1: 2052 Q1 | LL1: 2052 Q2 | LM1: 2052 Q3 | LN1: 2052 Q4 | LO1: 2053 Q1 | LP1: 2053 Q2 | LQ1: 2053 Q3 | LR1: 2053 Q4 | LS1: 2054 Q1 | LT1: 2054 Q2 | LU1: 2054 Q3 | LV1: 2054 Q4 | LW1: 2055 Q1 | LX1: 2055 Q2 | LY1: 2055 Q3 | LZ1: 2055 Q4 | MA1: 2056 Q1 | MB1: 2056 Q2 | MC1: 2056 Q3 | MD1: 2056 Q4 | ME1: 2057 Q1 | MF1: 2057 Q2 | MG1: 2057 Q3 | MH1: 2057 Q4 | MI1: 2058 Q1 | MJ1: 2058 Q2 | MK1: 2058 Q3 | ML1: 2058 Q4 | MM1: 2059 Q1 | MN1: 2059 Q2 | MO1: 2059 Q3 | MP1: 2059 Q4 | MQ1: 2060 Q1 | MR1: 2060 Q2 | MS1: 2060 Q3 | MT1: 2060 Q4 | MU1: Source | MV1: Seasonally adjusted | MW1: Base year price | MX1: Base year index | MY1: Historical end year | MZ1: Historical end quarter | NA1: Date of last update | NB1: Source details | NC1: Additional source details | ND1: Location code | NE1: Indicator code | NF1: Databank code
