Workbook
Name _DLX1.INC: HAVER!$B$2:$I$7
Name IQ_CH: 110000
Name IQ_CQ: 5000
Name IQ_CY: 10000
Name IQ_DAILY: 500000
Name IQ_FH: 100000
Name IQ_FQ: 500
Name IQ_FY: 1000
Name IQ_LTM: 2000
Name IQ_MONTH: 15000
Name IQ_NTM: 6000
Name IQ_WEEK: 50000
Name IQ_YTD: 3000

Sheet DMP Chart Data
A1: DMP - prices & wages
B2: Prices - past year | C2: Prices - next year | D2: Wages - past year | E2: Wages - next year
A3: 42736 | B3: =AVERAGE(HAVER!C90:C92) -> #N/A | C3: =AVERAGE(HAVER!D90:D92) -> #N/A
A4: 42767 | B4: =AVERAGE(HAVER!C91:C93) -> #N/A | C4: =AVERAGE(HAVER!D91:D93) -> #N/A
A5: 42795 | B5: =AVERAGE(HAVER!C92:C94) -> 2.8203333 | C5: =AVERAGE(HAVER!D92:D94) -> 2.8916667
A6: 42826 | B6: =AVERAGE(HAVER!C93:C95) -> 2.766 | C6: =AVERAGE(HAVER!D93:D95) -> 2.8163333
A7: 42856 | B7: =AVERAGE(HAVER!C94:C96) -> 2.681 | C7: =AVERAGE(HAVER!D94:D96) -> 2.7556667
A8: 42887 | B8: =AVERAGE(HAVER!C95:C97) -> 2.6146667 | C8: =AVERAGE(HAVER!D95:D97) -> 2.6873333
A9: 42917 | B9: =AVERAGE(HAVER!C96:C98) -> 2.4683333 | C9: =AVERAGE(HAVER!D96:D98) -> 2.588
A10: 42948 | B10: =AVERAGE(HAVER!C97:C99) -> 2.4666667 | C10: =AVERAGE(HAVER!D97:D99) -> 2.5166667
A11: 42979 | B11: =AVERAGE(HAVER!C98:C100) -> 2.527 | C11: =AVERAGE(HAVER!D98:D100) -> 2.4873333
A12: 43009 | B12: =AVERAGE(HAVER!C99:C101) -> 2.444 | C12: =AVERAGE(HAVER!D99:D101) -> 2.4793333
A13: 43040 | B13: =AVERAGE(HAVER!C100:C102) -> 2.4226667 | C13: =AVERAGE(HAVER!D100:D102) -> 2.4646667
A14: 43070 | B14: =AVERAGE(HAVER!C101:C103) -> 2.4713333 | C14: =AVERAGE(HAVER!D101:D103) -> 2.446
... A68: 44713 | B68: =AVERAGE(HAVER!C155:C157) -> 6.0463333 | C68: =AVERAGE(HAVER!D155:D157) -> 5.8393333
A69: 44743 | B69: =AVERAGE(HAVER!C156:C158) -> 6.2726667 | C69: =AVERAGE(HAVER!D156:D158) -> 6.0723333 | D69: =AVERAGE(HAVER!E156:E158) -> 5.5666667 | E69: =AVERAGE(HAVER!F156:F158) -> 5.0333333
A70: 44774 | B70: =AVERAGE(HAVER!C157:C159) -> 6.464 | C70: =AVERAGE(HAVER!D157:D159) -> 6.2606667 | D70: =AVERAGE(HAVER!E157:E159) -> 5.8666667 | E70: =AVERAGE(HAVER!F157:F159) -> 5.2666667
A71: 44805 | B71: =AVERAGE(HAVER!C158:C160) -> 6.5743333 | C71: =AVERAGE(HAVER!D158:D160) -> 6.4366667 | D71: =AVERAGE(HAVER!E158:E160) -> 6.1333333 | E71: =AVERAGE(HAVER!F158:F160) -> 5.5
A72: 44835 | B72: =AVERAGE(HAVER!C159:C161) -> 6.422 | C72: =AVERAGE(HAVER!D159:D161) -> 6.4866667 | D72: =AVERAGE(HAVER!E159:E161) -> 6.3333333 | E72: =AVERAGE(HAVER!F159:F161) -> 5.7333333
A73: 44866 | B73: =AVERAGE(HAVER!C160:C162) -> 6.186 | C73: =AVERAGE(HAVER!D160:D162) -> 6.394 | D73: =AVERAGE(HAVER!E160:E162) -> 6.2333333 | E73: =AVERAGE(HAVER!F160:F162) -> 5.8333333
A74: 44896 | B74: =AVERAGE(HAVER!C161:C163) -> 5.9046667 | C74: =AVERAGE(HAVER!D161:D163) -> 6.1706667 | D74: =AVERAGE(HAVER!E161:E163) -> 6.2666667 | E74: =AVERAGE(HAVER!F161:F163) -> 6
A75: 44927 | B75: =AVERAGE(HAVER!C162:C164) -> 5.7643333 | C75: =AVERAGE(HAVER!D162:D164) -> 5.9513333 | D75: =AVERAGE(HAVER!E162:E164) -> 6.3333333 | E75: =AVERAGE(HAVER!F162:F164) -> 5.9333333
A76: 44958 | B76: =AVERAGE(HAVER!C163:C165) -> 5.6496667 | C76: =AVERAGE(HAVER!D163:D165) -> 5.7726667 | D76: =AVERAGE(HAVER!E163:E165) -> 6.5 | E76: =AVERAGE(HAVER!F163:F165) -> 5.9333333
A77: 44986 | B77: =AVERAGE(HAVER!C164:C166) -> 5.4926667 | C77: =AVERAGE(HAVER!D164:D166) -> 5.6353333 | D77: =AVERAGE(HAVER!E164:E166) -> 6.4666667 | E77: =AVERAGE(HAVER!F164:F166) -> 5.7
A78: 45017 | B78: =AVERAGE(HAVER!C165:C167) -> 5.545 | C78: =AVERAGE(HAVER!D165:D167) -> 5.5623333 | D78: =AVERAGE(HAVER!E165:E167) -> 6.5666667 | E78: =AVERAGE(HAVER!F165:F167) -> 5.6
A79: 45047 | B79: =AVERAGE(HAVER!C166:C168) -> 5.4436667 | C79: =AVERAGE(HAVER!D166:D168) -> 5.4936667 | D79: =AVERAGE(HAVER!E166:E168) -> 6.6333333 | E79: =AVERAGE(HAVER!F166:F168) -> 5.4
A80: 45078 | B80: =AVERAGE(HAVER!C167:C169) -> 5.2973333 | C80: =AVERAGE(HAVER!D167:D169) -> 5.4286667 | D80: =AVERAGE(HAVER!E167:E169) -> 6.8333333 | E80: =AVERAGE(HAVER!F167:F169) -> 5.3
... A100: 45689 | B100: =AVERAGE(HAVER!C187:C189) -> 3.9603333 | C100: =AVERAGE(HAVER!D187:D189) -> 3.885 | D100: =AVERAGE(HAVER!E187:E189) -> 5.2 | E100: =AVERAGE(HAVER!F187:F189) -> 3.9333333

Sheet HAVER
C1: Prices - past year | D1: Prices - next year | E1: Wages - past year | F1: Wages - next year
B2: 201001 !M | C2: UNVDPE1@UK | D2: UNVDPE3@UK | E2: UNVDWR@UK | F2: UNVDWE@UK
B3: .DESC | C3: UK: BoE DMP: Expected Price Growth Over the Next Year: Single Month (%) | D3: UK: BoE DMP: Expected Price Growth Over the Next Year: 3 Month Average (%) | E3: UK: BoE DMP: Realized Wage Growth Over the Past Year: Single Month (%) | F3: UK: BoE DMP: Expected Wage Growth Over the Next Year: Single Month (%)
B4: .T1 | C4: Jan-2017 | D4: Jan-2017 | E4: Aug-2017 | F4: Aug-2017
B5: .TN | C5: Feb-2025 | D5: Feb-2025 | E5: Feb-2025 | F5: Feb-2025
B6: .LSOURCE | C6: Bank of England | D6: Bank of England | E6: Bank of England | F6: Bank of England
B7: .DTLM | C7: Mar-06-2025 09:31 | D7: Mar-06-2025 09:31 | E7: Mar-06-2025 09:31 | F7: Mar-06-2025 09:31
A8: 40179 | B8: 201001 | C8: #N/A | D8: #N/A | E8: #N/A | F8: #N/A
A9: 40210 | B9: 201002 | C9: #N/A | D9: #N/A | E9: #N/A | F9: #N/A
A10: 40238 | B10: 201003 | C10: #N/A | D10: #N/A | E10: #N/A | F10: #N/A
A11: 40269 | B11: 201004 | C11: #N/A | D11: #N/A | E11: #N/A | F11: #N/A
A12: 40299 | B12: 201005 | C12: #N/A | D12: #N/A | E12: #N/A | F12: #N/A
A13: 40330 | B13: 201006 | C13: #N/A | D13: #N/A | E13: #N/A | F13: #N/A
A14: 40360 | B14: 201007 | C14: #N/A | D14: #N/A | E14: #N/A | F14: #N/A
A15: 40391 | B15: 201008 | C15: #N/A | D15: #N/A | E15: #N/A | F15: #N/A
A16: 40422 | B16: 201009 | C16: #N/A | D16: #N/A | E16: #N/A | F16: #N/A
A17: 40452 | B17: 201010 | C17: #N/A | D17: #N/A | E17: #N/A | F17: #N/A
A18: 40483 | B18: 201011 | C18: #N/A | D18: #N/A | E18: #N/A | F18: #N/A
A19: 40513 | B19: 201012 | C19: #N/A | D19: #N/A | E19: #N/A | F19: #N/A
... A91: 42705 | B91: 201612 | C91: #N/A | D91: #N/A | E91: #N/A | F91: #N/A
A92: 42736 | B92: 201701 | C92: 3.43 | D92: 2.992 | E92: #N/A | F92: #N/A
A93: 42767 | B93: 201702 | C93: 2.723 | D93: 2.863 | E93: #N/A | F93: #N/A
A94: 42795 | B94: 201703 | C94: 2.308 | D94: 2.82 | E94: #N/A | F94: #N/A
A95: 42826 | B95: 201704 | C95: 3.267 | D95: 2.766 | E95: #N/A | F95: #N/A
A96: 42856 | B96: 201705 | C96: 2.468 | D96: 2.681 | E96: #N/A | F96: #N/A
A97: 42887 | B97: 201706 | C97: 2.109 | D97: 2.615 | E97: #N/A | F97: #N/A
A98: 42917 | B98: 201707 | C98: 2.828 | D98: 2.468 | E98: #N/A | F98: #N/A
A99: 42948 | B99: 201708 | C99: 2.463 | D99: 2.467 | E99: 2.6 | F99: 2.4
A100: 42979 | B100: 201709 | C100: 2.29 | D100: 2.527 | E100: 2.5 | F100: 2.3
A101: 43009 | B101: 201710 | C101: 2.579 | D101: 2.444 | E101: 2.7 | F101: 2.6
A102: 43040 | B102: 201711 | C102: 2.399 | D102: 2.423 | E102: #N/A | F102: #N/A
A103: 43070 | B103: 201712 | C103: 2.436 | D103: 2.471 | E103: #N/A | F103: #N/A
A104: 43101 | B104: 201801 | C104: 2.472 | D104: 2.436 | E104: #N/A | F104: #N/A
A105: 43132 | B105: 201802 | C105: 2.399 | D105: 2.436 | E105: #N/A | F105: #N/A
A106: 43160 | B106: 201803 | C106: 2.197 | D106: 2.356 | E106: #N/A | F106: #N/A
A107: 43191 | B107: 201804 | C107: 2.446 | D107: 2.347 | E107: #N/A | F107: #N/A
A108: 43221 | B108: 201805 | C108: 1.938 | D108: 2.194 | E108: #N/A | F108: #N/A
A109: 43252 | B109: 201806 | C109: 2.315 | D109: 2.233 | E109: #N/A | F109: #N/A
A110: 43282 | B110: 201807 | C110: 2.421 | D110: 2.225 | E110: #N/A | F110: #N/A
A111: 43313 | B111: 201808 | C111: 2.251 | D111: 2.329 | E111: #N/A | F111: #N/A
...
