Workbook
Name _DLX1.INC: HAVER!$A$1:$J$6

Sheet Chart Data
A1: Implied probability of rate cut by meeting | F1: Change compared with today
B2: November | C2: December | D2: 0.5 | F2: November | G2: December
A3: 45880 | B3: =IF(F3<0,-F3/0.25,F3/0.25) -> 0.4836 | C3: =IF(G3<0,-G3/0.25,G3/0.25) -> 0.7396 | D3: 0.5 | F3: =HAVER!D79-HAVER!$B79 -> -0.1209 | G3: =HAVER!E79-HAVER!$B79 -> -0.1849
A4: 45881 | B4: =IF(F4<0,-F4/0.25,F4/0.25) -> 0.412 | C4: =IF(G4<0,-G4/0.25,G4/0.25) -> 0.64 | D4: 0.5 | F4: =HAVER!D80-HAVER!$B80 -> -0.103 | G4: =HAVER!E80-HAVER!$B80 -> -0.16
A5: 45882 | B5: =IF(F5<0,-F5/0.25,F5/0.25) -> 0.3968 | C5: =IF(G5<0,-G5/0.25,G5/0.25) -> 0.6448 | D5: 0.5 | F5: =HAVER!D81-HAVER!$B81 -> -0.0992 | G5: =HAVER!E81-HAVER!$B81 -> -0.1612
A6: 45883 | B6: =IF(F6<0,-F6/0.25,F6/0.25) -> 0.3376 | C6: =IF(G6<0,-G6/0.25,G6/0.25) -> 0.5696 | D6: 0.5 | F6: =HAVER!D82-HAVER!$B82 -> -0.0844 | G6: =HAVER!E82-HAVER!$B82 -> -0.1424
A7: 45884 | B7: =IF(F7<0,-F7/0.25,F7/0.25) -> 0.3084 | C7: =IF(G7<0,-G7/0.25,G7/0.25) -> 0.5244 | D7: 0.5 | F7: =HAVER!D83-HAVER!$B83 -> -0.0771 | G7: =HAVER!E83-HAVER!$B83 -> -0.1311
A8: =+A3+7 -> 45887 | B8: =IF(F8<0,-F8/0.25,F8/0.25) -> 0.2876 | C8: =IF(G8<0,-G8/0.25,G8/0.25) -> 0.4916 | D8: 0.5 | F8: =HAVER!D84-HAVER!$B84 -> -0.0719 | G8: =HAVER!E84-HAVER!$B84 -> -0.1229
A9: =+A4+7 -> 45888 | B9: =IF(F9<0,-F9/0.25,F9/0.25) -> 0.2964 | C9: =IF(G9<0,-G9/0.25,G9/0.25) -> 0.4684 | D9: 0.5 | F9: =HAVER!D85-HAVER!$B85 -> -0.0741 | G9: =HAVER!E85-HAVER!$B85 -> -0.1171
A10: =+A5+7 -> 45889 | B10: =IF(F10<0,-F10/0.25,F10/0.25) -> 0.2772 | C10: =IF(G10<0,-G10/0.25,G10/0.25) -> 0.4852 | D10: 0.5 | F10: =HAVER!D86-HAVER!$B86 -> -0.0693 | G10: =HAVER!E86-HAVER!$B86 -> -0.1213
A11: =+A6+7 -> 45890 | B11: =IF(F11<0,-F11/0.25,F11/0.25) -> 0.19 | C11: =IF(G11<0,-G11/0.25,G11/0.25) -> 0.366 | D11: 0.5 | F11: =HAVER!D87-HAVER!$B87 -> -0.0475 | G11: =HAVER!E87-HAVER!$B87 -> -0.0915
A12: =+A7+7 -> 45891 | B12: =IF(F12<0,-F12/0.25,F12/0.25) -> 0.2124 | C12: =IF(G12<0,-G12/0.25,G12/0.25) -> 0.4044 | D12: 0.5 | F12: =HAVER!D88-HAVER!$B88 -> -0.0531 | G12: =HAVER!E88-HAVER!$B88 -> -0.1011
A13: =+A8+7 -> 45894 | B13: =IF(F13<0,-F13/0.25,F13/0.25) -> #N/A | C13: =IF(G13<0,-G13/0.25,G13/0.25) -> #N/A | D13: 0.5 | F13: =HAVER!D89-HAVER!$B89 -> #N/A | G13: =HAVER!E89-HAVER!$B89 -> #N/A
A14: =+A9+7 -> 45895 | B14: =IF(F14<0,-F14/0.25,F14/0.25) -> 0.1976 | C14: =IF(G14<0,-G14/0.25,G14/0.25) -> 0.3896 | D14: 0.5 | F14: =HAVER!D90-HAVER!$B90 -> -0.0494 | G14: =HAVER!E90-HAVER!$B90 -> -0.0974
A15: =+A10+7 -> 45896 | B15: =IF(F15<0,-F15/0.25,F15/0.25) -> 0.174 | C15: =IF(G15<0,-G15/0.25,G15/0.25) -> 0.354 | D15: 0.5 | F15: =HAVER!D91-HAVER!$B91 -> -0.0435 | G15: =HAVER!E91-HAVER!$B91 -> -0.0885
A16: =+A11+7 -> 45897 | B16: =IF(F16<0,-F16/0.25,F16/0.25) -> 0.174 | C16: =IF(G16<0,-G16/0.25,G16/0.25) -> 0.382 | D16: 0.5 | F16: =HAVER!D92-HAVER!$B92 -> -0.0435 | G16: =HAVER!E92-HAVER!$B92 -> -0.0955
A17: =+A12+7 -> 45898 | B17: =IF(F17<0,-F17/0.25,F17/0.25) -> 0.154 | C17: =IF(G17<0,-G17/0.25,G17/0.25) -> 0.37 | D17: 0.5 | F17: =HAVER!D93-HAVER!$B93 -> -0.0385 | G17: =HAVER!E93-HAVER!$B93 -> -0.0925
A18: =+A13+7 -> 45901 | B18: =IF(F18<0,-F18/0.25,F18/0.25) -> 0.1676 | C18: =IF(G18<0,-G18/0.25,G18/0.25) -> 0.3716 | D18: 0.5 | F18: =HAVER!D94-HAVER!$B94 -> -0.0419 | G18: =HAVER!E94-HAVER!$B94 -> -0.0929
A19: =+A14+7 -> 45902 | B19: =IF(F19<0,-F19/0.25,F19/0.25) -> 0.1596 | C19: =IF(G19<0,-G19/0.25,G19/0.25) -> 0.3356 | D19: 0.5 | F19: =HAVER!D95-HAVER!$B95 -> -0.0399 | G19: =HAVER!E95-HAVER!$B95 -> -0.0839
... A31: =+A26+7 -> 45918 | B31: =IF(F31<0,-F31/0.25,F31/0.25) -> 0.0936 | C31: =IF(G31<0,-G31/0.25,G31/0.25) -> 0.2656 | D31: 0.5 | F31: =HAVER!D107-HAVER!$B107 -> -0.0234 | G31: =HAVER!E107-HAVER!$B107 -> -0.0664
A32: =+A27+7 -> 45919 | B32: =IF(F32<0,-F32/0.25,F32/0.25) -> 0.0532 | C32: =IF(G32<0,-G32/0.25,G32/0.25) -> 0.2412 | D32: 0.5 | F32: =HAVER!C108-HAVER!$B108 -> -0.0133 | G32: =HAVER!D108-HAVER!$B108 -> -0.0603
A33: =+A28+7 -> 45922 | B33: =IF(F33<0,-F33/0.25,F33/0.25) -> 0.0524 | C33: =IF(G33<0,-G33/0.25,G33/0.25) -> 0.2404 | D33: 0.5 | F33: =HAVER!C109-HAVER!$B109 -> -0.0131 | G33: =HAVER!D109-HAVER!$B109 -> -0.0601
A34: =+A29+7 -> 45923 | B34: =IF(F34<0,-F34/0.25,F34/0.25) -> 0.0672 | C34: =IF(G34<0,-G34/0.25,G34/0.25) -> 0.2472 | D34: 0.5 | F34: =HAVER!C110-HAVER!$B110 -> -0.0168 | G34: =HAVER!D110-HAVER!$B110 -> -0.0618
A35: =+A30+7 -> 45924 | B35: =IF(F35<0,-F35/0.25,F35/0.25) -> 0.0668 | C35: =IF(G35<0,-G35/0.25,G35/0.25) -> 0.2428 | D35: 0.5 | F35: =HAVER!C111-HAVER!$B111 -> -0.0167 | G35: =HAVER!D111-HAVER!$B111 -> -0.0607
A36: =+A31+7 -> 45925 | B36: =IF(F36<0,-F36/0.25,F36/0.25) -> 0.046 | C36: =IF(G36<0,-G36/0.25,G36/0.25) -> 0.198 | D36: 0.5 | F36: =HAVER!C112-HAVER!$B112 -> -0.0115 | G36: =HAVER!D112-HAVER!$B112 -> -0.0495
A37: =+A32+7 -> 45926 | B37: =IF(F37<0,-F37/0.25,F37/0.25) -> 0.0316 | C37: =IF(G37<0,-G37/0.25,G37/0.25) -> 0.1876 | D37: 0.5 | F37: =HAVER!C113-HAVER!$B113 -> -0.0079 | G37: =HAVER!D113-HAVER!$B113 -> -0.0469
A38: =+A33+7 -> 45929 | B38: =IF(F38<0,-F38/0.25,F38/0.25) -> 0.0308 | C38: =IF(G38<0,-G38/0.25,G38/0.25) -> 0.1868 | D38: 0.5 | F38: =HAVER!C114-HAVER!$B114 -> -0.0077 | G38: =HAVER!D114-HAVER!$B114 -> -0.0467
A39: =+A34+7 -> 45930 | B39: =IF(F39<0,-F39/0.25,F39/0.25) -> 0.0484 | C39: =IF(G39<0,-G39/0.25,G39/0.25) -> 0.1924 | D39: 0.5 | F39: =HAVER!C115-HAVER!$B115 -> -0.0121 | G39: =HAVER!D115-HAVER!$B115 -> -0.0481
A40: =+A35+7 -> 45931 | B40: =IF(F40<0,-F40/0.25,F40/0.25) -> 0.0576 | C40: =IF(G40<0,-G40/0.25,G40/0.25) -> 0.2216 | D40: 0.5 | F40: =HAVER!C116-HAVER!$B116 -> -0.0144 | G40: =HAVER!D116-HAVER!$B116 -> -0.0554
A41: =+A36+7 -> 45932 | B41: =IF(F41<0,-F41/0.25,F41/0.25) -> 0.0216 | C41: =IF(G41<0,-G41/0.25,G41/0.25) -> 0.1816 | D41: 0.5 | F41: =HAVER!C117-HAVER!$B117 -> -0.0054 | G41: =HAVER!D117-HAVER!$B117 -> -0.0454
A42: =+A37+7 -> 45933 | B42: =IF(F42<0,-F42/0.25,F42/0.25) -> 0.0248 | C42: =IF(G42<0,-G42/0.25,G42/0.25) -> 0.2048 | D42: 0.5 | F42: =HAVER!C118-HAVER!$B118 -> -0.0062 | G42: =HAVER!D118-HAVER!$B118 -> -0.0512
A43: =+A38+7 -> 45936 | B43: =IF(F43<0,-F43/0.25,F43/0.25) -> 0.0296 | C43: =IF(G43<0,-G43/0.25,G43/0.25) -> 0.2056 | D43: 0.5 | F43: =HAVER!C119-HAVER!$B119 -> -0.0074 | G43: =HAVER!D119-HAVER!$B119 -> -0.0514
... A61: =+A56+7 -> 45960 | B61: =IF(F61<0,-F61/0.25,F61/0.25) -> 0.2296 | C61: =IF(G61<0,-G61/0.25,G61/0.25) -> 0.5976 | D61: 0.5 | F61: =HAVER!C137-HAVER!$B137 -> -0.0574 | G61: =HAVER!D137-HAVER!$B137 -> -0.1494
A62: =+A57+7 -> 45961 | D62: 0.5

Sheet HAVER
A1: 20250501 !D | B1: R112LOS@INTDAILY | C1: M112MOT@INTDAILY | D1: M112MTH@INTDAILY | E1: M112MHF@INTDAILY | F1: M112MHV@INTDAILY
A2: .DESC | B2: UK:Lending Rate: Sterling Overnight Interbank Average [SONIA] (% pa) | C2: UK: Forward OIS: MPC Mtg Date # 1 vs MPC Mtg Date # 2: Mid Rate (% p.a.) | D2: UK: Forward OIS: MPC Mtg Date # 2 vs MPC Mtg Date # 3: Mid Rate (% p.a.) | E2: UK: Forward OIS: MPC Mtg Date # 3 vs MPC Mtg Date # 4: Mid Rate (% p.a.) | F2: UK: Forward OIS: MPC Mtg Date # 4 vs MPC Mtg Date # 5: Mid Rate (% p.a.)
A3: .T1 | B3: 02-Jan-1997 | C3: 16-May-2007 | D3: 16-May-2007 | E3: 16-May-2007 | F3: 16-May-2007
A4: .TN | B4: 28-Oct-2025 | C4: 30-Oct-2025 | D4: 30-Oct-2025 | E4: 30-Oct-2025 | F4: 30-Oct-2025
A5: .LSOURCE | B5: Bank of England | C5: Tullett Prebon Information/Haver Analytics | D5: Tullett Prebon Information/Haver Analytics | E5: Tullett Prebon Information/Haver Analytics | F5: Tullett Prebon Information/Haver Analytics
A6: .DTLM | B6: Oct-30-2025 09:30 | C6: Oct-30-2025 18:23 | D6: Oct-30-2025 18:23 | E6: Oct-30-2025 18:23 | F6: Oct-30-2025 18:23
A7: 20250501 | B7: 4.4586 | C7: 4.2 | D7: 4.062 | E7: 3.852 | F7: 3.715
A8: 20250502 | B8: 4.4594 | C8: 4.204 | D8: 4.075 | E8: 3.873 | F8: 3.735
A9: 20250505 | B9: #N/A | C9: 4.208 | D9: 4.078 | E9: 3.875 | F9: 3.74
A10: 20250506 | B10: 4.459 | C10: 4.2 | D10: 4.068 | E10: 3.866 | F10: 3.725
A11: 20250507 | B11: 4.4601 | C11: 4.204 | D11: 4.073 | E11: 3.872 | F11: 3.726
A12: 20250508 | B12: 4.21 | C12: 4.219 | D12: 4.172 | E12: 3.987 | F12: 3.876
A13: 20250509 | B13: 4.2103 | C13: 4.166 | D13: 3.976 | E13: 3.873 | F13: 3.712
A14: 20250512 | B14: 4.21 | C14: 4.19 | D14: 4.01 | E14: 3.934 | F14: 3.792
A15: 20250513 | B15: 4.2106 | C15: 4.195 | D15: 4.018 | E15: 3.946 | F15: 3.798
A16: 20250514 | B16: 4.2108 | C16: 4.199 | D16: 4.041 | E16: 3.984 | F16: 3.853
A17: 20250515 | B17: 4.2111 | C17: 4.199 | D17: 4.038 | E17: 3.971 | F17: 3.833
A18: 20250516 | B18: 4.2106 | C18: 4.202 | D18: 4.049 | E18: 3.98 | F18: 3.846
A19: 20250519 | B19: 4.2109 | C19: 4.199 | D19: 4.041 | E19: 3.981 | F19: 3.853
A20: 20250520 | B20: 4.2108 | C20: 4.203 | D20: 4.056 | E20: 3.996 | F20: 3.872
A21: 20250521 | B21: 4.2115 | C21: 4.213 | D21: 4.095 | E21: 4.035 | F21: 3.908
... A23: 20250523 | B23: 4.2108 | C23: 4.215 | D23: 4.088 | E23: 4.028 | F23: 3.884
A24: 20250526 | B24: #N/A | C24: 4.218 | D24: 4.093 | E24: 4.033 | F24: 3.884
A25: 20250527 | B25: 4.2107 | C25: 4.218 | D25: 4.102 | E25: 4.052 | F25: 3.912
A26: 20250528 | B26: 4.2104 | C26: 4.219 | D26: 4.104 | E26: 4.061 | F26: 3.924
A27: 20250529 | B27: 4.2107 | C27: 4.217 | D27: 4.101 | E27: 4.056 | F27: 3.907
A28: 20250530 | B28: 4.2111 | C28: 4.21 | D28: 4.098 | E28: 4.053 | F28: 3.909
A29: 20250602 | B29: 4.2112 | C29: 4.216 | D29: 4.1 | E29: 4.056 | F29: 3.916
A30: 20250603 | B30: 4.2112 | C30: 4.217 | D30: 4.074 | E30: 4.028 | F30: 3.889
A31: 20250604 | B31: 4.2111 | C31: 4.213 | D31: 4.065 | E31: 4.016 | F31: 3.869
A32: 20250605 | B32: 4.2119 | C32: 4.217 | D32: 4.063 | E32: 4.019 | F32: 3.877
A33: 20250606 | B33: 4.2118 | C33: 4.216 | D33: 4.062 | E33: 4.025 | F33: 3.891
A34: 20250609 | B34: 4.2128 | C34: 4.214 | D34: 4.054 | E34: 4.01 | F34: 3.867
A35: 20250610 | B35: 4.2126 | C35: 4.207 | D35: 4.017 | E35: 3.957 | F35: 3.802
A36: 20250611 | B36: 4.2129 | C36: 4.208 | D36: 4.018 | E36: 3.956 | F36: 3.801
... A88: 20250822 | B88: 3.9671 | C88: 3.973 | D88: 3.914 | E88: 3.866 | F88: 3.769
A89: 20250825 | B89: #N/A | C89: 3.975 | D89: 3.914 | E89: 3.863 | F89: 3.764
A90: 20250826 | B90: 3.9674 | C90: 3.975 | D90: 3.918 | E90: 3.87 | F90: 3.775
A91: 20250827 | B91: 3.9675 | C91: 3.977 | D91: 3.924 | E91: 3.879 | F91: 3.784
A92: 20250828 | B92: 3.9675 | C92: 3.974 | D92: 3.924 | E92: 3.872 | F92: 3.773
...
