Workbook
Name Astartpg: #REF!
Name Row_A: #REF!
Name Row_B: #REF!
Name Row_C: #REF!
Name Row_D: #REF!
Name Row_E: #REF!
Name Row_F: #REF!
Name Row_G: #REF!
Name toolong: #REF!

Sheet Migration reason data
A1: Table 4: Long-term international immigration, emigration and net migration of non-EU+ nationals by reason,
M2: Link
A3: Some shorthand is used in this table, P = provisional, R = revised, YE = Year Ending, BNO = British National (Overseas)
A5: Flow [note 2] | B5: Period [note 10] | C5: All reasons | D5: Work: Main applicant | E5: Work: Dependant | F5: Study: Main applicant | G5: Study: Dependant | H5: Family [definition 7] | I5: Humanitarian: BNO [definition 8] | J5: Humanitarian: Resettlement [definition 9] | K5: Humanitarian: Ukraine [definition 10] | L5: Asylum [definition 11] | M5: Other [definition 12]
A6: Immigration | B6: YE Jun 19 | C6: 347000 | D6: 56000 | E6: 33000 | F6: 119000 | G6: 7000 | H6: 65000 | I6: 0 | J6: 6000 | K6: 0 | L6: 39000 | M6: 22000
A7: Immigration | B7: YE Sep 19 | C7: 351000 | D7: 59000 | E7: 35000 | F7: 109000 | G7: 8000 | H7: 71000 | I7: 0 | J7: 6000 | K7: 0 | L7: 41000 | M7: 22000
A8: Immigration | B8: YE Dec 19 | C8: 368000 | D8: 62000 | E8: 37000 | F8: 112000 | G8: 9000 | H8: 78000 | I8: 0 | J8: 6000 | K8: 0 | L8: 42000 | M8: 23000 | P8: Definitions
A9: Immigration | B9: YE Mar 20 | C9: 388000 | D9: 63000 | E9: 39000 | F9: 124000 | G9: 11000 | H9: 82000 | I9: 0 | J9: 5000 | K9: 0 | L9: 42000 | M9: 23000 | P9: This worksheet contains one table.
A10: Immigration | B10: YE Jun 20 | C10: 331000 | D10: 49000 | E10: 30000 | F10: 114000 | G10: 10000 | H10: 68000 | I10: 0 | J10: 4000 | K10: 0 | L10: 38000 | M10: 17000 | P10: Definition number | Q10: Term | R10: Definition
A11: Immigration | B11: YE Sep 20 | C11: 260000 | D11: 42000 | E11: 26000 | F11: 69000 | G11: 8000 | H11: 59000 | I11: 0 | J11: 2000 | K11: 0 | L11: 37000 | M11: 16000 | P11: 1 | Q11: International migrant | R11: Estimates are based on the UN definition of an international migrant. That is, a person who moves to a country other than that of his or her usual residence for a period of at least a year (12 months), so that the country of destination effectively becomes his or her new country of usual residence.
A12: Immigration | B12: YE Dec 20 | C12: 294000 | D12: 42000 | E12: 29000 | F12: 100000 | G12: 12000 | H12: 56000 | I12: 0 | J12: 1000 | K12: 0 | L12: 35000 | M12: 20000 | P12: 2 | Q12: British | R12: There are six different types of British nationality: British citizenship British Overseas Territories citizen British overseas citizen British subject British National (Overseas) British protected person For the purposes of our estimates, we have treated British National (Overseas) as a separate category within the non-EU+ country grouping. All other types of British nationality are included in our British nationals estimates. For more information, see the Types of British nationality guide on GOV.UK. Please also see definition 8.
A13: Immigration | B13: YE Mar 21 | C13: 297000 | D13: 40000 | E13: 30000 | F13: 109000 | G13: 15000 | H13: 51000 | I13: 0 | J13: 0 | K13: 0 | L13: 31000 | M13: 21000 | P13: =P12+1 -> 3 | Q13: European Union+ (EU+) | R13: For 2012 to 2021 this category includes countries of the European Union (EU) for each given time period (excluding the UK). For year ending June 2021 onwards it covers the EU+ category. The EU+ category includes nationals from all EU countries and those from Norway, Iceland, Liechtenstein and Switzerland. We have included these within our EU category because people from these countries were, and still are, subject to the same immigration controls as those from the EU. For example, people from Norway, Iceland, Liechtenstein and Switzerland are able to apply for EU Settled Status. British nationals are not included in these numbers in any time period.
A14: Immigration | B14: YE Jun 21 | C14: 371000 | D14: 55000 | E14: 41000 | F14: 114000 | G14: 19000 | H14: 67000 | I14: 9000 | J14: 1000 | K14: 0 | L14: 38000 | M14: 28000 | P14: =P13+1 -> 4 | Q14: Non-EU+ | R14: This category includes countries not in the EU+ category for each time period. British nationals are also excluded.
A15: Immigration | B15: YE Sep 21 | C15: 539000 | D15: 68000 | E15: 52000 | F15: 200000 | G15: 27000 | H15: 72000 | I15: 28000 | J15: 16000 | K15: 0 | L15: 46000 | M15: 30000 | P15: =P14+1 -> 5 | Q15: Non-EU+ reason for migration: Work-related | R15: This includes work main applicants and dependants
A16: Immigration | B16: YE Dec 21 | C16: 617000 | D16: 81000 | E16: 62000 | F16: 224000 | G16: 38000 | H16: 70000 | I16: 39000 | J16: 18000 | K16: 0 | L16: 59000 | M16: 28000 | P16: =P15+1 -> 6 | Q16: Non-EU+ reason for migration: Study-related | R16: This includes study main applicants and dependants
A17: Immigration | B17: YE Mar 22 | C17: 727000 | D17: 100000 | E17: 75000 | F17: 254000 | G17: 54000 | H17: 72000 | I17: 50000 | J17: 19000 | K17: 7000 | L17: 68000 | M17: 28000 | P17: =P16+1 -> 7 | Q17: Non-EU+ reason for migration: Family | R17: This includes all family-related visas
A18: Immigration | B18: YE Jun 22 | C18: 845000 | D18: 117000 | E18: 88000 | F18: 260000 | G18: 59000 | H18: 64000 | I18: 57000 | J18: 20000 | K18: 73000 | L18: 76000 | M18: 30000 | P18: =P17+1 -> 8 | Q18: Non-EU+ reason for migration: Humanitarian: British Nationals (Overseas) | R18: Someone who was a British Overseas Territories citizen by connection with Hong Kong lost that citizenship on 30 June 1997, when sovereignty returned to China. However, such a person was able to register as a British National (Overseas) (BN(O)) before 1 July 1997. For more information, see the Types of British nationality guide on GOV.UK. On 31 January 2021, the UK launched a bespoke immigration route for BN(O) status holders and their families from Hong Kong.
A19: Immigration | B19: YE Sep 22 | C19: 1003000 | D19: 141000 | E19: 106000 | F19: 327000 | G19: 78000 | H19: 62000 | I19: 56000 | J19: 7000 | K19: 109000 | L19: 87000 | M19: 30000 | P19: =P18+1 -> 9 | Q19: Non-EU+ reason for migration: Humanitarian: Resettlement | R19: Refugees are selected by the United Nations for resettlement, and transferred to the UK with the agreement of the Home Office, where they receive refugee status on arrival. This data includes refugees on the UK Resettlement Scheme, Community Sponsorship Scheme, Mandate Resettlement Scheme, Afghan Citizens Resettlement Scheme and Afghan Relocations and Assistance Policy.
A20: Immigration | B20: YE Dec 22 | C20: 1078000 | D20: 156000 | E20: 124000 | F20: 321000 | G20: 104000 | H20: 68000 | I20: 56000 | J20: 6000 | K20: 126000 | L20: 90000 | M20: 28000 | P20: =P19+1 -> 10 | Q20: Non-EU+ reason for migration: Humanitarian: Ukraine | R20: People coming to the UK on a long-term basis via a Ukraine scheme. Find out more about these on GOV.UK.
A21: Immigration | B21: YE Mar 23 | C21: 1083000 | D21: 163000 | E21: 134000 | F21: 297000 | G21: 108000 | H21: 75000 | I21: 53000 | J21: 4000 | K21: 130000 | L21: 92000 | M21: 25000 | P21: =P20+1 -> 11 | Q21: Non-EU+ reason for migration: Asylum | R21: This refers to the long-term international migration of people who have applied (that is, made a claim) for asylum within a year of their arrival in the UK. It includes people who claimed asylum after arriving in the UK via a regular route and those who claimed after arriving irregularly, for example, via small boats.
A22: Immigration | B22: YE Jun 23 | C22: 1095000 | D22: 189000 | E22: 166000 | F22: 302000 | G22: 115000 | H22: 85000 | I22: 48000 | J22: 3000 | K22: 74000 | L22: 91000 | M22: 21000 | P22: =P21+1 -> 12 | Q22: Non-EU+ reason for migration: Other | R22: "Other" reasons for immigration in table 3a and 3b refer to all reasons other than work-related, study-related, asylum or humanitarian resettlement. "Other" reasons for immigration in table 4 include those who arrived on administrative, settlement, visit or other visas
A23: Immigration | B23: YE Sep 23 R | C23: 1119000 | D23: 204000 | E23: 194000 | F23: 316000 | G23: 123000 | H23: 89000 | I23: 41000 | J23: 2000 | K23: 45000 | L23: 88000 | M23: 18000
A24: Immigration | B24: YE Dec 23 R | C24: 1132000 | D24: 221000 | E24: 230000 | F24: 302000 | G24: 121000 | H24: 86000 | I24: 35000 | J24: 4000 | K24: 37000 | L24: 80000 | M24: 16000
A25: Immigration | B25: YE Mar 24 P R | C25: 1122000 | D25: 216000 | E25: 256000 | F25: 303000 | G25: 100000 | H25: 81000 | I25: 31000 | J25: 7000 | K25: 32000 | L25: 81000 | M25: 15000
A26: Immigration | B26: YE Jun 24 P R | C26: 1057000 | D26: 188000 | E26: 243000 | F26: 296000 | G26: 86000 | H26: 81000 | I26: 27000 | J26: 8000 | K26: 29000 | L26: 83000 | M26: 15000
A27: Immigration | B27: YE Sep 24 P | C27: 919000 | D27: 155000 | E27: 207000 | F27: 263000 | G27: 54000 | H27: 81000 | I27: 23000 | J27: 10000 | K27: 26000 | L27: 86000 | M27: 15000
A28: Immigration | B28: YE Dec 24 P | C28: 766000 | D28: 113000 | E28: 149000 | F28: 249000 | G28: 17000 | H28: 76000 | I28: 21000 | J28: 8000 | K28: 22000 | L28: 95000 | M28: 15000
A30: Emigration | B30: YE Jun 19 | C30: 167000 | D30: 30000 | E30: 14000 | F30: 96000 | G30: 7000 | H30: 10000 | I30: 0 | J30: 0 | K30: 0 | L30: 2000 | M30: 8000
A31: Emigration | B31: YE Sep 19 | C31: 180000 | D31: 36000 | E31: 16000 | F31: 100000 | G31: 7000 | H31: 11000 | I31: 0 | J31: 0 | K31: 0 | L31: 2000 | M31: 8000
A32: Emigration | B32: YE Dec 19 | C32: 182000 | D32: 35000 | E32: 17000 | F32: 101000 | G32: 7000 | H32: 11000 | I32: 0 | J32: 0 | K32: 0 | L32: 2000 | M32: 9000
A33: Emigration | B33: YE Mar 20 | C33: 222000 | D33: 36000 | E33: 18000 | F33: 134000 | G33: 8000 | H33: 13000 | I33: 0 | J33: 0 | K33: 0 | L33: 2000 | M33: 11000
A34: Emigration | B34: YE Jun 20 | C34: 216000 | D34: 33000 | E34: 15000 | F34: 134000 | G34: 8000 | H34: 14000 | I34: 0 | J34: 0 | K34: 0 | L34: 1000 | M34: 11000
A35: Emigration | B35: YE Sep 20 | C35: 199000 | D35: 28000 | E35: 14000 | F35: 124000 | G35: 7000 | H35: 16000 | I35: 0 | J35: 0 | K35: 0 | L35: 1000 | M35: 10000
... A76: Net migration | B76: YE Dec 24 P | C76: 544000 | D76: 81000 | E76: 132000 | F76: 135000 | G76: -3000 | H76: 50000 | I76: 21000 | J76: 8000 | K76: 21000 | L76: 90000 | M76: 10000

Sheet Chart Data
A1: Chart 1: Net migration | L1: Chart 2: Net migration (grouped) | U1: Chart 3: Immigration (grouped) | AD1: Chart 4: Student flows | AJ1: Chart 5: POPW
B3: Work | C3: Study | D3: Dependents | E3: Family | F3: Humanitarian | G3: Asylum | H3: Other | I3: Zeroline | M3: Work | N3: Study | O3: Dependents | P3: Humanitarian | Q3: Other | R3: tot | V3: Work | W3: Study | X3: Dependents | Y3: Humanitarian | Z3: Other | AA3: tot | AE3: Immigration | AF3: Emigration | AG3: Net migration | AK3: New | AL3: Previous | AM3: State pension increases
A4: YE Dec-19 | B4: ='Migration reason data'!D56 -> 27000 | C4: ='Migration reason data'!F56 -> 10000 | D4: ='Migration reason data'!E56+'Migration reason data'!G56 -> 23000 | E4: ='Migration reason data'!H56 -> 66000 | F4: ='Migration reason data'!I56+'Migration reason data'!J56+'Migration reason data'!K56 -> 6000 | G4: ='Migration reason data'!L56 -> 40000 | H4: ='Migration reason data'!M56 -> 14000 | I4: 0 | L4: YE Dec-19 | M4: ='Migration reason data'!D56 -> 27000 | N4: ='Migration reason data'!F56 -> 10000 | O4: ='Migration reason data'!E56+'Migration reason data'!G56 -> 23000 | P4: ='Migration reason data'!I56+'Migration reason data'!J56+'Migration reason data'!K56 -> 6000 | Q4: =E4+G4+H4 -> 120000 | R4: =SUM(M4:Q4) -> 186000 | U4: YE Dec-19 | V4: ='Migration reason data'!D8 -> 62000 | W4: ='Migration reason data'!F8 -> 112000 | X4: ='Migration reason data'!E8+'Migration reason data'!G8 -> 46000 | Y4: ='Migration reason data'!I8+'Migration reason data'!J8+'Migration reason data'!K8 -> 6000 | Z4: ='Migration reason data'!H8+'Migration reason data'!L8+'Migration reason data'!M8 -> 143000 | AA4: =SUM(V4:Z4) -> 369000 | AD4: YE Dec-19 | AE4: ='Migration reason data'!F8 -> 112000 | AF4: ='Migration reason data'!F32 -> 101000 | AG4: ='Migration reason data'!F56 -> 10000 | AJ4: 2020 | AK4: 42.633978 | AL4: 42.614901
A5: YE Mar-20 | B5: ='Migration reason data'!D57 -> 27000 | C5: ='Migration reason data'!F57 -> -10000 | D5: ='Migration reason data'!E57+'Migration reason data'!G57 -> 24000 | E5: ='Migration reason data'!H57 -> 69000 | F5: ='Migration reason data'!I57+'Migration reason data'!J57+'Migration reason data'!K57 -> 5000 | G5: ='Migration reason data'!L57 -> 40000 | H5: ='Migration reason data'!M57 -> 11000 | I5: 0 | L5: YE Mar-20 | M5: ='Migration reason data'!D57 -> 27000 | N5: ='Migration reason data'!F57 -> -10000 | O5: ='Migration reason data'!E57+'Migration reason data'!G57 -> 24000 | P5: ='Migration reason data'!I57+'Migration reason data'!J57+'Migration reason data'!K57 -> 5000 | Q5: =E5+G5+H5 -> 120000 | R5: =SUM(M5:Q5) -> 166000 | U5: YE Mar-20 | V5: ='Migration reason data'!D9 -> 63000 | W5: ='Migration reason data'!F9 -> 124000 | X5: ='Migration reason data'!E9+'Migration reason data'!G9 -> 50000 | Y5: ='Migration reason data'!I9+'Migration reason data'!J9+'Migration reason data'!K9 -> 5000 | Z5: ='Migration reason data'!H9+'Migration reason data'!L9+'Migration reason data'!M9 -> 147000 | AA5: =SUM(V5:Z5) -> 389000 | AD5: YE Mar-20 | AE5: ='Migration reason data'!F9 -> 124000 | AF5: ='Migration reason data'!F33 -> 134000 | AG5: ='Migration reason data'!F57 -> -10000 | AJ5: 2021 | AK5: 42.897715 | AL5: 42.845915
A6: YE Jun-20 | B6: ='Migration reason data'!D58 -> 17000 | C6: ='Migration reason data'!F58 -> -20000 | D6: ='Migration reason data'!E58+'Migration reason data'!G58 -> 17000 | E6: ='Migration reason data'!H58 -> 54000 | F6: ='Migration reason data'!I58+'Migration reason data'!J58+'Migration reason data'!K58 -> 4000 | G6: ='Migration reason data'!L58 -> 37000 | H6: ='Migration reason data'!M58 -> 6000 | I6: 0 | L6: YE Jun-20 | M6: ='Migration reason data'!D58 -> 17000 | N6: ='Migration reason data'!F58 -> -20000 | O6: ='Migration reason data'!E58+'Migration reason data'!G58 -> 17000 | P6: ='Migration reason data'!I58+'Migration reason data'!J58+'Migration reason data'!K58 -> 4000 | Q6: =E6+G6+H6 -> 97000 | R6: =SUM(M6:Q6) -> 115000 | U6: YE Jun-20 | V6: ='Migration reason data'!D10 -> 49000 | W6: ='Migration reason data'!F10 -> 114000 | X6: ='Migration reason data'!E10+'Migration reason data'!G10 -> 40000 | Y6: ='Migration reason data'!I10+'Migration reason data'!J10+'Migration reason data'!K10 -> 4000 | Z6: ='Migration reason data'!H10+'Migration reason data'!L10+'Migration reason data'!M10 -> 123000 | AA6: =SUM(V6:Z6) -> 330000 | AD6: YE Jun-20 | AE6: ='Migration reason data'!F10 -> 114000 | AF6: ='Migration reason data'!F34 -> 134000 | AG6: ='Migration reason data'!F58 -> -20000 | AJ6: 2022 | AK6: 43.255563 | AL6: 43.1992
A7: YE Sep-20 | B7: ='Migration reason data'!D59 -> 14000 | C7: ='Migration reason data'!F59 -> -55000 | D7: ='Migration reason data'!E59+'Migration reason data'!G59 -> 14000 | E7: ='Migration reason data'!H59 -> 43000 | F7: ='Migration reason data'!I59+'Migration reason data'!J59+'Migration reason data'!K59 -> 2000 | G7: ='Migration reason data'!L59 -> 36000 | H7: ='Migration reason data'!M59 -> 6000 | I7: 0 | L7: YE Sep-20 | M7: ='Migration reason data'!D59 -> 14000 | N7: ='Migration reason data'!F59 -> -55000 | O7: ='Migration reason data'!E59+'Migration reason data'!G59 -> 14000 | P7: ='Migration reason data'!I59+'Migration reason data'!J59+'Migration reason data'!K59 -> 2000 | Q7: =E7+G7+H7 -> 85000 | R7: =SUM(M7:Q7) -> 60000 | U7: YE Sep-20 | V7: ='Migration reason data'!D11 -> 42000 | W7: ='Migration reason data'!F11 -> 69000 | X7: ='Migration reason data'!E11+'Migration reason data'!G11 -> 34000 | Y7: ='Migration reason data'!I11+'Migration reason data'!J11+'Migration reason data'!K11 -> 2000 | Z7: ='Migration reason data'!H11+'Migration reason data'!L11+'Migration reason data'!M11 -> 112000 | AA7: =SUM(V7:Z7) -> 259000 | AD7: YE Sep-20 | AE7: ='Migration reason data'!F11 -> 69000 | AF7: ='Migration reason data'!F35 -> 124000 | AG7: ='Migration reason data'!F59 -> -55000 | AJ7: 2023 | AK7: 43.70223 | AL7: 43.617552
A8: YE Dec-20 | B8: ='Migration reason data'!D60 -> 15000 | C8: ='Migration reason data'!F60 -> -16000 | D8: ='Migration reason data'!E60+'Migration reason data'!G60 -> 20000 | E8: ='Migration reason data'!H60 -> 38000 | F8: ='Migration reason data'!I60+'Migration reason data'!J60+'Migration reason data'!K60 -> 1000 | G8: ='Migration reason data'!L60 -> 34000 | H8: ='Migration reason data'!M60 -> 11000 | I8: 0 | L8: YE Dec-20 | M8: ='Migration reason data'!D60 -> 15000 | N8: ='Migration reason data'!F60 -> -16000 | O8: ='Migration reason data'!E60+'Migration reason data'!G60 -> 20000 | P8: ='Migration reason data'!I60+'Migration reason data'!J60+'Migration reason data'!K60 -> 1000 | Q8: =E8+G8+H8 -> 83000 | R8: =SUM(M8:Q8) -> 103000 | U8: YE Dec-20 | V8: ='Migration reason data'!D12 -> 42000 | W8: ='Migration reason data'!F12 -> 100000 | X8: ='Migration reason data'!E12+'Migration reason data'!G12 -> 41000 | Y8: ='Migration reason data'!I12+'Migration reason data'!J12+'Migration reason data'!K12 -> 1000 | Z8: ='Migration reason data'!H12+'Migration reason data'!L12+'Migration reason data'!M12 -> 111000 | AA8: =SUM(V8:Z8) -> 295000 | AD8: YE Dec-20 | AE8: ='Migration reason data'!F12 -> 100000 | AF8: ='Migration reason data'!F36 -> 116000 | AG8: ='Migration reason data'!F60 -> -16000 | AJ8: 2024 | AK8: 44.230457 | AL8: 44.199397
A9: YE Mar-21 | B9: ='Migration reason data'!D61 -> 16000 | C9: ='Migration reason data'!F61 -> 32000 | D9: ='Migration reason data'!E61+'Migration reason data'!G61 -> 25000 | E9: ='Migration reason data'!H61 -> 32000 | F9: ='Migration reason data'!I61+'Migration reason data'!J61+'Migration reason data'!K61 -> 0 | G9: ='Migration reason data'!L61 -> 30000 | H9: ='Migration reason data'!M61 -> 15000 | I9: 0 | L9: YE Mar-21 | M9: ='Migration reason data'!D61 -> 16000 | N9: ='Migration reason data'!F61 -> 32000 | O9: ='Migration reason data'!E61+'Migration reason data'!G61 -> 25000 | P9: ='Migration reason data'!I61+'Migration reason data'!J61+'Migration reason data'!K61 -> 0 | Q9: =E9+G9+H9 -> 77000 | R9: =SUM(M9:Q9) -> 150000 | U9: YE Mar-21 | V9: ='Migration reason data'!D13 -> 40000 | W9: ='Migration reason data'!F13 -> 109000 | X9: ='Migration reason data'!E13+'Migration reason data'!G13 -> 45000 | Y9: ='Migration reason data'!I13+'Migration reason data'!J13+'Migration reason data'!K13 -> 0 | Z9: ='Migration reason data'!H13+'Migration reason data'!L13+'Migration reason data'!M13 -> 103000 | AA9: =SUM(V9:Z9) -> 297000 | AD9: YE Mar-21 | AE9: ='Migration reason data'!F13 -> 109000 | AF9: ='Migration reason data'!F37 -> 77000 | AG9: ='Migration reason data'!F61 -> 32000 | AJ9: 2025 | AK9: 44.576067 | AL9: 44.68133
A10: YE Jun-21 | B10: ='Migration reason data'!D62 -> 31000 | C10: ='Migration reason data'!F62 -> 45000 | D10: ='Migration reason data'!E62+'Migration reason data'!G62 -> 42000 | E10: ='Migration reason data'!H62 -> 60000 | F10: ='Migration reason data'!I62+'Migration reason data'!J62+'Migration reason data'!K62 -> 10000 | G10: ='Migration reason data'!L62 -> 38000 | H10: ='Migration reason data'!M62 -> 26000 | I10: 0 | L10: YE Jun-21 | M10: ='Migration reason data'!D62 -> 31000 | N10: ='Migration reason data'!F62 -> 45000 | O10: ='Migration reason data'!E62+'Migration reason data'!G62 -> 42000 | P10: ='Migration reason data'!I62+'Migration reason data'!J62+'Migration reason data'!K62 -> 10000 | Q10: =E10+G10+H10 -> 124000 | R10: =SUM(M10:Q10) -> 252000 | U10: YE Jun-21 | V10: ='Migration reason data'!D14 -> 55000 | W10: ='Migration reason data'!F14 -> 114000 | X10: ='Migration reason data'!E14+'Migration reason data'!G14 -> 60000 | Y10: ='Migration reason data'!I14+'Migration reason data'!J14+'Migration reason data'!K14 -> 10000 | Z10: ='Migration reason data'!H14+'Migration reason data'!L14+'Migration reason data'!M14 -> 133000 | AA10: =SUM(V10:Z10) -> 372000 | AD10: YE Jun-21 | AE10: ='Migration reason data'!F14 -> 114000 | AF10: ='Migration reason data'!F38 -> 69000 | AG10: ='Migration reason data'!F62 -> 45000 | AJ10: 2026 | AK10: 45.008455 | AL10: 45.10529 | AM10: =[1]Calculations!AJ9 -> 100000
A11: YE Sep-21 | B11: ='Migration reason data'!D63 -> 46000 | C11: ='Migration reason data'!F63 -> 149000 | D11: ='Migration reason data'!E63+'Migration reason data'!G63 -> 64000 | E11: ='Migration reason data'!H63 -> 64000 | F11: ='Migration reason data'!I63+'Migration reason data'!J63+'Migration reason data'!K63 -> 44000 | G11: ='Migration reason data'!L63 -> 46000 | H11: ='Migration reason data'!M63 -> 28000 | I11: 0 | L11: YE Sep-21 | M11: ='Migration reason data'!D63 -> 46000 | N11: ='Migration reason data'!F63 -> 149000 | O11: ='Migration reason data'!E63+'Migration reason data'!G63 -> 64000 | P11: ='Migration reason data'!I63+'Migration reason data'!J63+'Migration reason data'!K63 -> 44000 | Q11: =E11+G11+H11 -> 138000 | R11: =SUM(M11:Q11) -> 441000 | U11: YE Sep-21 | V11: ='Migration reason data'!D15 -> 68000 | W11: ='Migration reason data'!F15 -> 200000 | X11: ='Migration reason data'!E15+'Migration reason data'!G15 -> 79000 | Y11: ='Migration reason data'!I15+'Migration reason data'!J15+'Migration reason data'!K15 -> 44000 | Z11: ='Migration reason data'!H15+'Migration reason data'!L15+'Migration reason data'!M15 -> 148000 | AA11: =SUM(V11:Z11) -> 539000 | AD11: YE Sep-21 | AE11: ='Migration reason data'!F15 -> 200000 | AF11: ='Migration reason data'!F39 -> 50000 | AG11: ='Migration reason data'!F63 -> 149000 | AJ11: 2027 | AK11: 45.589575 | AL11: 45.736222 | AM11: =[1]Calculations!AJ10 -> 100000
A12: YE Dec-21 | B12: ='Migration reason data'!D64 -> 62000 | C12: ='Migration reason data'!F64 -> 180000 | D12: ='Migration reason data'!E64+'Migration reason data'!G64 -> 85000 | E12: ='Migration reason data'!H64 -> 61000 | F12: ='Migration reason data'!I64+'Migration reason data'!J64+'Migration reason data'!K64 -> 57000 | G12: ='Migration reason data'!L64 -> 59000 | H12: ='Migration reason data'!M64 -> 26000 | I12: 0 | L12: YE Dec-21 | M12: ='Migration reason data'!D64 -> 62000 | N12: ='Migration reason data'!F64 -> 180000 | O12: ='Migration reason data'!E64+'Migration reason data'!G64 -> 85000 | P12: ='Migration reason data'!I64+'Migration reason data'!J64+'Migration reason data'!K64 -> 57000 | Q12: =E12+G12+H12 -> 146000 | R12: =SUM(M12:Q12) -> 530000 | U12: YE Dec-21 | V12: ='Migration reason data'!D16 -> 81000 | W12: ='Migration reason data'!F16 -> 224000 | X12: ='Migration reason data'!E16+'Migration reason data'!G16 -> 100000 | Y12: ='Migration reason data'!I16+'Migration reason data'!J16+'Migration reason data'!K16 -> 57000 | Z12: ='Migration reason data'!H16+'Migration reason data'!L16+'Migration reason data'!M16 -> 157000 | AA12: =SUM(V12:Z12) -> 619000 | AD12: YE Dec-21 | AE12: ='Migration reason data'!F16 -> 224000 | AF12: ='Migration reason data'!F40 -> 45000 | AG12: ='Migration reason data'!F64 -> 180000 | AJ12: 2028 | AK12: 45.984238 | AL12: 46.180929 | AM12: =[1]Calculations!AJ11 -> 100000
A13: YE Mar-22 | B13: ='Migration reason data'!D65 -> 83000 | C13: ='Migration reason data'!F65 -> 211000 | D13: ='Migration reason data'!E65+'Migration reason data'!G65 -> 115000 | E13: ='Migration reason data'!H65 -> 62000 | F13: ='Migration reason data'!I65+'Migration reason data'!J65+'Migration reason data'!K65 -> 76000 | G13: ='Migration reason data'!L65 -> 67000 | H13: ='Migration reason data'!M65 -> 25000 | I13: 0 | L13: YE Mar-22 | M13: ='Migration reason data'!D65 -> 83000 | N13: ='Migration reason data'!F65 -> 211000 | O13: ='Migration reason data'!E65+'Migration reason data'!G65 -> 115000 | P13: ='Migration reason data'!I65+'Migration reason data'!J65+'Migration reason data'!K65 -> 76000 | Q13: =E13+G13+H13 -> 154000 | R13: =SUM(M13:Q13) -> 639000 | U13: YE Mar-22 | V13: ='Migration reason data'!D17 -> 100000 | W13: ='Migration reason data'!F17 -> 254000 | X13: ='Migration reason data'!E17+'Migration reason data'!G17 -> 129000 | Y13: ='Migration reason data'!I17+'Migration reason data'!J17+'Migration reason data'!K17 -> 76000 | Z13: ='Migration reason data'!H17+'Migration reason data'!L17+'Migration reason data'!M17 -> 168000 | AA13: =SUM(V13:Z13) -> 727000 | AD13: YE Mar-22 | AE13: ='Migration reason data'!F17 -> 254000 | AF13: ='Migration reason data'!F41 -> 43000 | AG13: ='Migration reason data'!F65 -> 211000 | AJ13: 2029 | AK13: 46.114245 | AL13: 46.296628
A14: YE Jun-22 | B14: ='Migration reason data'!D66 -> 100000 | C14: ='Migration reason data'!F66 -> 214000 | D14: ='Migration reason data'!E66+'Migration reason data'!G66 -> 133000 | E14: ='Migration reason data'!H66 -> 54000 | F14: ='Migration reason data'!I66+'Migration reason data'!J66+'Migration reason data'!K66 -> 150000 | G14: ='Migration reason data'!L66 -> 76000 | H14: ='Migration reason data'!M66 -> 28000 | I14: 0 | L14: YE Jun-22 | M14: ='Migration reason data'!D66 -> 100000 | N14: ='Migration reason data'!F66 -> 214000 | O14: ='Migration reason data'!E66+'Migration reason data'!G66 -> 133000 | P14: ='Migration reason data'!I66+'Migration reason data'!J66+'Migration reason data'!K66 -> 150000 | Q14: =E14+G14+H14 -> 158000 | R14: =SUM(M14:Q14) -> 755000 | U14: YE Jun-22 | V14: ='Migration reason data'!D18 -> 117000 | W14: ='Migration reason data'!F18 -> 260000 | X14: ='Migration reason data'!E18+'Migration reason data'!G18 -> 147000 | Y14: ='Migration reason data'!I18+'Migration reason data'!J18+'Migration reason data'!K18 -> 150000 | Z14: ='Migration reason data'!H18+'Migration reason data'!L18+'Migration reason data'!M18 -> 170000 | AA14: =SUM(V14:Z14) -> 844000 | AD14: YE Jun-22 | AE14: ='Migration reason data'!F18 -> 260000 | AF14: ='Migration reason data'!F42 -> 46000 | AG14: ='Migration reason data'!F66 -> 214000 | AJ14: 2030 | AK14: 46.195475 | AL14: 46.378976
A15: YE Sep-22 | B15: ='Migration reason data'!D67 -> 125000 | C15: ='Migration reason data'!F67 -> 271000 | D15: ='Migration reason data'!E67+'Migration reason data'!G67 -> 170000 | E15: ='Migration reason data'!H67 -> 51000 | F15: ='Migration reason data'!I67+'Migration reason data'!J67+'Migration reason data'!K67 -> 172000 | G15: ='Migration reason data'!L67 -> 86000 | H15: ='Migration reason data'!M67 -> 27000 | I15: 0 | L15: YE Sep-22 | M15: ='Migration reason data'!D67 -> 125000 | N15: ='Migration reason data'!F67 -> 271000 | O15: ='Migration reason data'!E67+'Migration reason data'!G67 -> 170000 | P15: ='Migration reason data'!I67+'Migration reason data'!J67+'Migration reason data'!K67 -> 172000 | Q15: =E15+G15+H15 -> 164000 | R15: =SUM(M15:Q15) -> 902000 | U15: YE Sep-22 | V15: ='Migration reason data'!D19 -> 141000 | W15: ='Migration reason data'!F19 -> 327000 | X15: ='Migration reason data'!E19+'Migration reason data'!G19 -> 184000 | Y15: ='Migration reason data'!I19+'Migration reason data'!J19+'Migration reason data'!K19 -> 172000 | Z15: ='Migration reason data'!H19+'Migration reason data'!L19+'Migration reason data'!M19 -> 179000 | AA15: =SUM(V15:Z15) -> 1003000 | AD15: YE Sep-22 | AE15: ='Migration reason data'!F19 -> 327000 | AF15: ='Migration reason data'!F43 -> 56000 | AG15: ='Migration reason data'!F67 -> 271000 | AJ15: 2031 | AK15: 46.262122 | AL15: 46.44425
A16: YE Dec-22 | B16: ='Migration reason data'!D68 -> 139000 | C16: ='Migration reason data'!F68 -> 255000 | D16: ='Migration reason data'!E68+'Migration reason data'!G68 -> 212000 | E16: ='Migration reason data'!H68 -> 57000 | F16: ='Migration reason data'!I68+'Migration reason data'!J68+'Migration reason data'!K68 -> 188000 | G16: ='Migration reason data'!L68 -> 90000 | H16: ='Migration reason data'!M68 -> 26000 | I16: 0 | L16: YE Dec-22 | M16: ='Migration reason data'!D68 -> 139000 | N16: ='Migration reason data'!F68 -> 255000 | O16: ='Migration reason data'!E68+'Migration reason data'!G68 -> 212000 | P16: ='Migration reason data'!I68+'Migration reason data'!J68+'Migration reason data'!K68 -> 188000 | Q16: =E16+G16+H16 -> 173000 | R16: =SUM(M16:Q16) -> 967000 | U16: YE Dec-22 | V16: ='Migration reason data'!D20 -> 156000 | W16: ='Migration reason data'!F20 -> 321000 | X16: ='Migration reason data'!E20+'Migration reason data'!G20 -> 228000 | Y16: ='Migration reason data'!I20+'Migration reason data'!J20+'Migration reason data'!K20 -> 188000 | Z16: ='Migration reason data'!H20+'Migration reason data'!L20+'Migration reason data'!M20 -> 186000 | AA16: =SUM(V16:Z16) -> 1079000 | AD16: YE Dec-22 | AE16: ='Migration reason data'!F20 -> 321000 | AF16: ='Migration reason data'!F44 -> 66000 | AG16: ='Migration reason data'!F68 -> 255000 | AJ16: 2032 | AK16: 46.326863 | AL16: 46.511147
A17: YE Mar-23 | B17: ='Migration reason data'!D69 -> 145000 | C17: ='Migration reason data'!F69 -> 222000 | D17: ='Migration reason data'!E69+'Migration reason data'!G69 -> 225000 | E17: ='Migration reason data'!H69 -> 64000 | F17: ='Migration reason data'!I69+'Migration reason data'!J69+'Migration reason data'!K69 -> 186000 | G17: ='Migration reason data'!L69 -> 91000 | H17: ='Migration reason data'!M69 -> 22000 | I17: 0 | L17: YE Mar-23 | M17: ='Migration reason data'!D69 -> 145000 | N17: ='Migration reason data'!F69 -> 222000 | O17: ='Migration reason data'!E69+'Migration reason data'!G69 -> 225000 | P17: ='Migration reason data'!I69+'Migration reason data'!J69+'Migration reason data'!K69 -> 186000 | Q17: =E17+G17+H17 -> 177000 | R17: =SUM(M17:Q17) -> 955000 | U17: YE Mar-23 | V17: ='Migration reason data'!D21 -> 163000 | W17: ='Migration reason data'!F21 -> 297000 | X17: ='Migration reason data'!E21+'Migration reason data'!G21 -> 242000 | Y17: ='Migration reason data'!I21+'Migration reason data'!J21+'Migration reason data'!K21 -> 187000 | Z17: ='Migration reason data'!H21+'Migration reason data'!L21+'Migration reason data'!M21 -> 192000 | AA17: =SUM(V17:Z17) -> 1081000 | AD17: YE Mar-23 | AE17: ='Migration reason data'!F21 -> 297000 | AF17: ='Migration reason data'!F45 -> 75000 | AG17: ='Migration reason data'!F69 -> 222000 | AJ17: 2033 | AK17: 46.380782 | AL17: 46.567098
A18: YE Jun-23 | B18: ='Migration reason data'!D70 -> 169000 | C18: ='Migration reason data'!F70 -> 219000 | D18: ='Migration reason data'!E70+'Migration reason data'!G70 -> 262000 | E18: ='Migration reason data'!H70 -> 73000 | F18: ='Migration reason data'!I70+'Migration reason data'!J70+'Migration reason data'!K70 -> 123000 | G18: ='Migration reason data'!L70 -> 90000 | H18: ='Migration reason data'!M70 -> 18000 | I18: 0 | L18: YE Jun-23 | M18: ='Migration reason data'!D70 -> 169000 | N18: ='Migration reason data'!F70 -> 219000 | O18: ='Migration reason data'!E70+'Migration reason data'!G70 -> 262000 | P18: ='Migration reason data'!I70+'Migration reason data'!J70+'Migration reason data'!K70 -> 123000 | Q18: =E18+G18+H18 -> 181000 | R18: =SUM(M18:Q18) -> 954000 | U18: YE Jun-23 | V18: ='Migration reason data'!D22 -> 189000 | W18: ='Migration reason data'!F22 -> 302000 | X18: ='Migration reason data'!E22+'Migration reason data'!G22 -> 281000 | Y18: ='Migration reason data'!I22+'Migration reason data'!J22+'Migration reason data'!K22 -> 125000 | Z18: ='Migration reason data'!H22+'Migration reason data'!L22+'Migration reason data'!M22 -> 197000 | AA18: =SUM(V18:Z18) -> 1094000 | AD18: YE Jun-23 | AE18: ='Migration reason data'!F22 -> 302000 | AF18: ='Migration reason data'!F46 -> 83000 | AG18: ='Migration reason data'!F70 -> 219000 | AJ18: 2034 | AK18: 46.423607 | AL18: 46.608568
A19: YE Sep-23 | B19: ='Migration reason data'!D71 -> 182000 | C19: ='Migration reason data'!F71 -> 219000 | D19: ='Migration reason data'!E71+'Migration reason data'!G71 -> 295000 | E19: ='Migration reason data'!H71 -> 78000 | F19: ='Migration reason data'!I71+'Migration reason data'!J71+'Migration reason data'!K71 -> 83000 | G19: ='Migration reason data'!L71 -> 86000 | H19: ='Migration reason data'!M71 -> 15000 | I19: 0 | L19: YE Sep-23 | M19: ='Migration reason data'!D71 -> 182000 | N19: ='Migration reason data'!F71 -> 219000 | O19: ='Migration reason data'!E71+'Migration reason data'!G71 -> 295000 | P19: ='Migration reason data'!I71+'Migration reason data'!J71+'Migration reason data'!K71 -> 83000 | Q19: =E19+G19+H19 -> 179000 | R19: =SUM(M19:Q19) -> 958000 | U19: YE Sep-23 | V19: ='Migration reason data'!D23 -> 204000 | W19: ='Migration reason data'!F23 -> 316000 | X19: ='Migration reason data'!E23+'Migration reason data'!G23 -> 317000 | Y19: ='Migration reason data'!I23+'Migration reason data'!J23+'Migration reason data'!K23 -> 88000 | Z19: ='Migration reason data'!H23+'Migration reason data'!L23+'Migration reason data'!M23 -> 195000 | AA19: =SUM(V19:Z19) -> 1120000 | AD19: YE Sep-23 | AE19: ='Migration reason data'!F23 -> 316000 | AF19: ='Migration reason data'!F47 -> 97000 | AG19: ='Migration reason data'!F71 -> 219000 | AJ19: 2035 | AK19: 46.465398 | AL19: 46.652419
A20: YE Dec-23 | B20: ='Migration reason data'!D72 -> 195000 | C20: ='Migration reason data'!F72 -> 198000 | D20: ='Migration reason data'!E72+'Migration reason data'!G72 -> 326000 | E20: ='Migration reason data'!H72 -> 73000 | F20: ='Migration reason data'!I72+'Migration reason data'!J72+'Migration reason data'!K72 -> 70000 | G20: ='Migration reason data'!L72 -> 77000 | H20: ='Migration reason data'!M72 -> 12000 | I20: 0 | L20: YE Dec-23 | M20: ='Migration reason data'!D72 -> 195000 | N20: ='Migration reason data'!F72 -> 198000 | O20: ='Migration reason data'!E72+'Migration reason data'!G72 -> 326000 | P20: ='Migration reason data'!I72+'Migration reason data'!J72+'Migration reason data'!K72 -> 70000 | Q20: =E20+G20+H20 -> 162000 | R20: =SUM(M20:Q20) -> 951000 | U20: YE Dec-23 | V20: ='Migration reason data'!D24 -> 221000 | W20: ='Migration reason data'!F24 -> 302000 | X20: ='Migration reason data'!E24+'Migration reason data'!G24 -> 351000 | Y20: ='Migration reason data'!I24+'Migration reason data'!J24+'Migration reason data'!K24 -> 76000 | Z20: ='Migration reason data'!H24+'Migration reason data'!L24+'Migration reason data'!M24 -> 182000 | AA20: =SUM(V20:Z20) -> 1132000 | AD20: YE Dec-23 | AE20: ='Migration reason data'!F24 -> 302000 | AF20: ='Migration reason data'!F48 -> 103000 | AG20: ='Migration reason data'!F72 -> 198000 | AJ20: 2036 | AK20: 46.500207 | AL20: 46.686085
A21: YE Mar-24 | B21: ='Migration reason data'!D73 -> 188000 | C21: ='Migration reason data'!F73 -> 193000 | D21: ='Migration reason data'!E73+'Migration reason data'!G73 -> 327000 | E21: ='Migration reason data'!H73 -> 67000 | F21: ='Migration reason data'!I73+'Migration reason data'!J73+'Migration reason data'!K73 -> 63000 | G21: ='Migration reason data'!L73 -> 77000 | H21: ='Migration reason data'!M73 -> 12000 | I21: 0 | L21: YE Mar-24 | M21: ='Migration reason data'!D73 -> 188000 | N21: ='Migration reason data'!F73 -> 193000 | O21: ='Migration reason data'!E73+'Migration reason data'!G73 -> 327000 | P21: ='Migration reason data'!I73+'Migration reason data'!J73+'Migration reason data'!K73 -> 63000 | Q21: =E21+G21+H21 -> 156000 | R21: =SUM(M21:Q21) -> 927000 | U21: YE Mar-24 | V21: ='Migration reason data'!D25 -> 216000 | W21: ='Migration reason data'!F25 -> 303000 | X21: ='Migration reason data'!E25+'Migration reason data'!G25 -> 356000 | Y21: ='Migration reason data'!I25+'Migration reason data'!J25+'Migration reason data'!K25 -> 70000 | Z21: ='Migration reason data'!H25+'Migration reason data'!L25+'Migration reason data'!M25 -> 177000 | AA21: =SUM(V21:Z21) -> 1122000 | AD21: YE Mar-24 | AE21: ='Migration reason data'!F25 -> 303000 | AF21: ='Migration reason data'!F49 -> 110000 | AG21: ='Migration reason data'!F73 -> 193000 | AJ21: 2037 | AK21: 46.53442 | AL21: 46.72246
A22: YE Jun-24 | B22: ='Migration reason data'!D74 -> 159000 | C22: ='Migration reason data'!F74 -> 185000 | D22: ='Migration reason data'!E74+'Migration reason data'!G74 -> 296000 | E22: ='Migration reason data'!H74 -> 66000 | F22: ='Migration reason data'!I74+'Migration reason data'!J74+'Migration reason data'!K74 -> 59000 | G22: ='Migration reason data'!L74 -> 79000 | H22: ='Migration reason data'!M74 -> 11000 | I22: 0 | L22: YE Jun-24 | M22: ='Migration reason data'!D74 -> 159000 | N22: ='Migration reason data'!F74 -> 185000 | O22: ='Migration reason data'!E74+'Migration reason data'!G74 -> 296000 | P22: ='Migration reason data'!I74+'Migration reason data'!J74+'Migration reason data'!K74 -> 59000 | Q22: =E22+G22+H22 -> 156000 | R22: =SUM(M22:Q22) -> 855000 | U22: YE Jun-24 | V22: ='Migration reason data'!D26 -> 188000 | W22: ='Migration reason data'!F26 -> 296000 | X22: ='Migration reason data'!E26+'Migration reason data'!G26 -> 329000 | Y22: ='Migration reason data'!I26+'Migration reason data'!J26+'Migration reason data'!K26 -> 64000 | Z22: ='Migration reason data'!H26+'Migration reason data'!L26+'Migration reason data'!M26 -> 179000 | AA22: =SUM(V22:Z22) -> 1056000 | AD22: YE Jun-24 | AE22: ='Migration reason data'!F26 -> 296000 | AF22: ='Migration reason data'!F50 -> 111000 | AG22: ='Migration reason data'!F74 -> 185000 | AJ22: 2038 | AK22: 46.560592 | AL22: 46.748213
A23: YE Sep-24 | B23: ='Migration reason data'!D75 -> 124000 | C23: ='Migration reason data'!F75 -> 149000 | D23: ='Migration reason data'!E75+'Migration reason data'!G75 -> 226000 | E23: ='Migration reason data'!H75 -> 62000 | F23: ='Migration reason data'!I75+'Migration reason data'!J75+'Migration reason data'!K75 -> 55000 | G23: ='Migration reason data'!L75 -> 81000 | H23: ='Migration reason data'!M75 -> 11000 | I23: 0 | L23: YE Sep-24 | M23: ='Migration reason data'!D75 -> 124000 | N23: ='Migration reason data'!F75 -> 149000 | O23: ='Migration reason data'!E75+'Migration reason data'!G75 -> 226000 | P23: ='Migration reason data'!I75+'Migration reason data'!J75+'Migration reason data'!K75 -> 55000 | Q23: =E23+G23+H23 -> 154000 | R23: =SUM(M23:Q23) -> 708000 | U23: YE Sep-24 | V23: ='Migration reason data'!D27 -> 155000 | W23: ='Migration reason data'!F27 -> 263000 | X23: ='Migration reason data'!E27+'Migration reason data'!G27 -> 261000 | Y23: ='Migration reason data'!I27+'Migration reason data'!J27+'Migration reason data'!K27 -> 59000 | Z23: ='Migration reason data'!H27+'Migration reason data'!L27+'Migration reason data'!M27 -> 182000 | AA23: =SUM(V23:Z23) -> 920000 | AD23: YE Sep-24 | AE23: ='Migration reason data'!F27 -> 263000 | AF23: ='Migration reason data'!F51 -> 114000 | AG23: ='Migration reason data'!F75 -> 149000 | AJ23: 2039 | AK23: 46.590735 | AL23: 46.772661
A24: YE Dec-24 | B24: ='Migration reason data'!D76 -> 81000 | C24: ='Migration reason data'!F76 -> 135000 | D24: ='Migration reason data'!E76+'Migration reason data'!G76 -> 129000 | E24: ='Migration reason data'!H76 -> 50000 | F24: ='Migration reason data'!I76+'Migration reason data'!J76+'Migration reason data'!K76 -> 50000 | G24: ='Migration reason data'!L76 -> 90000 | H24: ='Migration reason data'!M76 -> 10000 | I24: 0 | L24: YE Dec-24 | M24: ='Migration reason data'!D76 -> 81000 | N24: ='Migration reason data'!F76 -> 135000 | O24: ='Migration reason data'!E76+'Migration reason data'!G76 -> 129000 | P24: ='Migration reason data'!I76+'Migration reason data'!J76+'Migration reason data'!K76 -> 50000 | Q24: =E24+G24+H24 -> 150000 | R24: =SUM(M24:Q24) -> 545000 | U24: YE Dec-24 | V24: ='Migration reason data'!D28 -> 113000 | W24: ='Migration reason data'!F28 -> 249000 | X24: ='Migration reason data'!E28+'Migration reason data'!G28 -> 166000 | Y24: ='Migration reason data'!I28+'Migration reason data'!J28+'Migration reason data'!K28 -> 51000 | Z24: ='Migration reason data'!H28+'Migration reason data'!L28+'Migration reason data'!M28 -> 186000 | AA24: =SUM(V24:Z24) -> 765000 | AD24: YE Dec-24 | AE24: ='Migration reason data'!F28 -> 249000 | AF24: ='Migration reason data'!F52 -> 115000 | AG24: ='Migration reason data'!F76 -> 135000 | AJ24: 2040 | AK24: 46.649525 | AL24: 46.827023
AJ25: 2041 | AK25: 46.737607 | AL25: 46.914979
AJ26: 2042 | AK26: 46.83934 | AL26: 47.014811
AJ27: 2043 | AK27: 46.976315 | AL27: 47.128745
L28: change | M28: =M24-M16 -> -58000 | N28: =N24-N16 -> -120000 | O28: =O24-O16 -> -83000 | P28: =P24-P16 -> -138000 | Q28: =Q24-Q16 -> -23000 | R28: =R24-R16 -> -422000 | V28: =V24-V16 -> -43000 | W28: =W24-W16 -> -72000 | X28: =X24-X16 -> -62000 | Y28: =Y24-Y16 -> -137000 | Z28: =Z24-Z16 -> 0 | AA28: =AA24-AA16 -> -314000 | AJ28: 2044 | AK28: 47.255745 | AL28: 47.370251 | AM28: =[1]Calculations!AJ27 -> 100000
AJ29: 2045 | AK29: 47.706117 | AL29: 47.856559 | AM29: =[1]Calculations!AJ28 -> 100000
L30: % | M30: =M28/$R$28 -> 0.13744076 | N30: =N28/$R$28 -> 0.28436019 | O30: =O28/$R$28 -> 0.19668246 | P30: =P28/$R$28 -> 0.32701422 | Q30: =Q28/$R$28 -> 0.05450237 | V30: =V28/$AA$28 -> 0.13694268 | W30: =W28/$AA$28 -> 0.22929936 | X30: =X28/$AA$28 -> 0.19745223 | Y30: =Y28/$AA$28 -> 0.43630573 | Z30: =Z28/$AA$28 -> 0 | AJ30: 2046 | AK30: 48.029723 | AL30: 48.232802 | AM30: =[1]Calculations!AJ29 -> 100000
AJ31: 2047 | AK31: 48.101912 | AL31: 48.291625
AJ32: 2048 | AK32: 48.128367 | AL32: 48.315945
AJ33: 2049 | AK33: 48.15376 | AL33: 48.340137
AJ34: 2050 | AK34: 48.182628 | AL34: 48.370682
AJ35: 2051 | AK35: 48.206315 | AL35: 48.394392
AJ36: 2052 | AK36: 48.222358 | AL36: 48.415723
AJ37: 2053 | AK37: 48.215155 | AL37: 48.408043
AJ38: 2054 | AK38: 48.19884 | AL38: 48.393247
AJ39: 2055 | AK39: 48.169488 | AL39: 48.36798
AJ40: 2056 | AK40: 48.121255 | AL40: 48.317418
AJ41: 2057 | AK41: 48.07216 | AL41: 48.270877
...
