Workbook
Name _DLX1.INC: HAVERQ!$C$1:$H$213
Name _DLX2.INC: HAVERW!$A$1:$G$6
Name Annual_Data: OE_FCST!$A$1:$A$2
Name Data: [1]sheet0!$C$2

Sheet Chart Data
A1: Inflation forecast
E2: 2016 | I2: 2017 | M2: 2018 | Q2: 2019 | U2: 2020 | Y2: 2021 | AC2: 2022 | AG2: 2023 | AK2: 2024 | AO2: 2025 | AS2: 2026 | AW2: 2027 | BA2: 2028
A3: BoE - Nov24 | B3: 45597 | C3: CPI inflation (LHS) | E3: =100*((HAVERQ!BA$63/HAVERQ!AW$63)-1) -> 0.33500838 | F3: =100*((HAVERQ!BB$63/HAVERQ!AX$63)-1) -> 0.33311126 | G3: =100*((HAVERQ!BC$63/HAVERQ!AY$63)-1) -> 0.69883527 | H3: =100*((HAVERQ!BD$63/HAVERQ!AZ$63)-1) -> 1.1964108 | I3: =100*((HAVERQ!BE$63/HAVERQ!BA$63)-1) -> 2.1702838 | J3: =100*((HAVERQ!BF$63/HAVERQ!BB$63)-1) -> 2.7556441 | K3: =100*((HAVERQ!BG$63/HAVERQ!BC$63)-1) -> 2.8089888 | L3: =100*((HAVERQ!BH$63/HAVERQ!BD$63)-1) -> 3.0213465 | ... AM3: =100*((HAVERQ!CI$63/HAVERQ!CE$63)-1) -> 2.0547945 | AN3: =HAVERQ!CJ93 -> 2.4 | AO3: =HAVERQ!CK93 -> 2.4 | AP3: =HAVERQ!CL93 -> 2.6 | AQ3: =HAVERQ!CM93 -> 2.8 | AR3: =HAVERQ!CN93 -> 2.7 | AS3: =HAVERQ!CO93 -> 2.6 | AT3: =HAVERQ!CP93 -> 2.4 | AU3: =HAVERQ!CQ93 -> 2.3 | ... AZ3: =HAVERQ!CV93 -> 1.8
A4: BoE - Feb25 | B4: 45689 | C4: CPI inflation (LHS) | E4: =100*((HAVERQ!BA$63/HAVERQ!AW$63)-1) -> 0.33500838 | F4: =100*((HAVERQ!BB$63/HAVERQ!AX$63)-1) -> 0.33311126 | G4: =100*((HAVERQ!BC$63/HAVERQ!AY$63)-1) -> 0.69883527 | H4: =100*((HAVERQ!BD$63/HAVERQ!AZ$63)-1) -> 1.1964108 | I4: =100*((HAVERQ!BE$63/HAVERQ!BA$63)-1) -> 2.1702838 | J4: =100*((HAVERQ!BF$63/HAVERQ!BB$63)-1) -> 2.7556441 | K4: =100*((HAVERQ!BG$63/HAVERQ!BC$63)-1) -> 2.8089888 | L4: =100*((HAVERQ!BH$63/HAVERQ!BD$63)-1) -> 3.0213465 | ... AN4: =100*((HAVERQ!CJ$63/HAVERQ!CF$63)-1) -> 2.4753726 | AO4: =HAVERQ!CK94 -> 2.8 | AP4: =HAVERQ!CL94 -> 3.5 | AQ4: =HAVERQ!CM94 -> 3.7 | AR4: =HAVERQ!CN94 -> 3.5 | AS4: =HAVERQ!CO94 -> 3 | AT4: =HAVERQ!CP94 -> 2.6 | AU4: =HAVERQ!CQ94 -> 2.6 | AV4: =HAVERQ!CR94 -> 2.4 | ... BA4: =HAVERQ!CW94 -> 1.9
A5: ZERO LINE | B5: ZERO LINE | C5: =A5 -> ZERO LINE | E5: 0 | F5: 0 | G5: 0 | H5: 0 | I5: 0 | J5: 0 | K5: 0 | L5: 0 | M5: 0 | N5: 0 | O5: 0 | P5: 0 | Q5: 0 | R5: 0 | S5: 0 | T5: 0 | U5: 0 | V5: 0 | W5: 0 | X5: 0 | Y5: 0 | Z5: 0 | AA5: 0 | AB5: 0 | AC5: 0 | AD5: 0 | AE5: 0 | AF5: 0 | AG5: 0 | AH5: 0 | AI5: 0 | AJ5: 0 | AK5: 0 | AL5: 0 | AM5: 0 | AN5: 0 | AO5: 0 | AP5: 0 | AQ5: 0 | AR5: 0 | AS5: 0 | AT5: 0 | AU5: 0 | AV5: 0 | AW5: 0 | AX5: 0 | AY5: 0 | AZ5: 0 | BA5: 0
A6: 2% LINE | B6: 2% LINE | C6: =A6 -> 2% LINE | E6: 2 | F6: 2 | G6: 2 | H6: 2 | I6: 2 | J6: 2 | K6: 2 | L6: 2 | M6: 2 | N6: 2 | O6: 2 | P6: 2 | Q6: 2 | R6: 2 | S6: 2 | T6: 2 | U6: 2 | V6: 2 | W6: 2 | X6: 2 | Y6: 2 | Z6: 2 | AA6: 2 | AB6: 2 | AC6: 2 | AD6: 2 | AE6: 2 | AF6: 2 | AG6: 2 | AH6: 2 | AI6: 2 | AJ6: 2 | AK6: 2 | AL6: 2 | AM6: 2 | AN6: 2 | AO6: 2 | AP6: 2 | AQ6: 2 | AR6: 2 | AS6: 2 | AT6: 2 | AU6: 2 | AV6: 2 | AW6: 2 | AX6: 2 | AY6: 2 | AZ6: 2 | BA6: 2
A7: Oxford Economics | C7: =A7 -> Oxford Economics | AM7: =100*((OE_FCST!HE3/OE_FCST!HA3)-1) -> 2.0547945 | AN7: =100*((OE_FCST!HF3/OE_FCST!HB3)-1) -> 2.4753214 | AO7: =100*((OE_FCST!HG3/OE_FCST!HC3)-1) -> 2.7272927 | AP7: =100*((OE_FCST!HH3/OE_FCST!HD3)-1) -> 2.9570369 | AQ7: =100*((OE_FCST!HI3/OE_FCST!HE3)-1) -> 3.4639821 | AR7: =100*((OE_FCST!HJ3/OE_FCST!HF3)-1) -> 3.3718766 | AS7: =100*((OE_FCST!HK3/OE_FCST!HG3)-1) -> 3.105745 | AT7: =100*((OE_FCST!HL3/OE_FCST!HH3)-1) -> 2.5992301 | ... BA7: =100*((OE_FCST!HS3/OE_FCST!HO3)-1) -> 2.1187229
A8: Historical | E8: =100*((HAVERQ!BA$63/HAVERQ!AW$63)-1) -> 0.33500838 | F8: =100*((HAVERQ!BB$63/HAVERQ!AX$63)-1) -> 0.33311126 | G8: =100*((HAVERQ!BC$63/HAVERQ!AY$63)-1) -> 0.69883527 | H8: =100*((HAVERQ!BD$63/HAVERQ!AZ$63)-1) -> 1.1964108 | I8: =100*((HAVERQ!BE$63/HAVERQ!BA$63)-1) -> 2.1702838 | J8: =100*((HAVERQ!BF$63/HAVERQ!BB$63)-1) -> 2.7556441 | K8: =100*((HAVERQ!BG$63/HAVERQ!BC$63)-1) -> 2.8089888 | L8: =100*((HAVERQ!BH$63/HAVERQ!BD$63)-1) -> 3.0213465 | ... AB8: =100*((HAVERQ!BX$63/HAVERQ!BT$63)-1) -> 4.8899756
C9: Excess supply/excess demand (RHS) | AK9: 0.75 | AO9: 0 | AS9: -0.25 | AW9: -0.25 | BA9: -0.5
D10: Market interest rate expectations | E10: =E4 -> 0.33500838 | F10: =F4 -> 0.33311126 | G10: =G4 -> 0.69883527 | H10: =H4 -> 1.1964108 | I10: =I4 -> 2.1702838 | J10: =J4 -> 2.7556441 | K10: =K4 -> 2.8089888 | L10: =L4 -> 3.0213465 | ... BA10: =BA4 -> 1.9
D11: Constant interest rates | E11: =E10 -> 0.33500838 | F11: =F10 -> 0.33311126 | G11: =G10 -> 0.69883527 | H11: =H10 -> 1.1964108 | I11: =I10 -> 2.1702838 | J11: =J10 -> 2.7556441 | K11: =K10 -> 2.8089888 | L11: =L10 -> 3.0213465 | ... AM11: =AM10 -> 2.0547945 | AN11: =HAVERQ!CJ159 -> #N/A | AO11: =HAVERQ!CK159 -> 2.8 | AP11: =HAVERQ!CL159 -> 3.4 | AQ11: =HAVERQ!CM159 -> 3.5 | AR11: =HAVERQ!CN159 -> 3.2 | AS11: =HAVERQ!CO159 -> 2.7 | AT11: =HAVERQ!CP159 -> 2.3 | AU11: =HAVERQ!CQ159 -> 2.3 | ... BA11: =HAVERQ!CW159 -> 1.7
D12: Modal forecast | E12: =E10 -> 0.33500838 | F12: =F10 -> 0.33311126 | G12: =G10 -> 0.69883527 | H12: =H10 -> 1.1964108 | I12: =I10 -> 2.1702838 | J12: =J10 -> 2.7556441 | K12: =K10 -> 2.8089888 | L12: =L10 -> 3.0213465 | ... BA12: =BA10 -> 1.9
D13: Mean forecast | E13: =E11 -> 0.33500838 | F13: =F11 -> 0.33311126 | G13: =G11 -> 0.69883527 | H13: =H11 -> 1.1964108 | I13: =I11 -> 2.1702838 | J13: =J11 -> 2.7556441 | K13: =K11 -> 2.8089888 | L13: =L11 -> 3.0213465 | ... AM13: =AM11 -> 2.0547945 | AN13: =HAVERQ!CJ160 -> #N/A | AO13: =HAVERQ!CK160 -> 2.8 | AP13: =HAVERQ!CL160 -> 3.5 | AQ13: =HAVERQ!CM160 -> 3.7 | AR13: =HAVERQ!CN160 -> 3.5 | AS13: =HAVERQ!CO160 -> 3 | AT13: =HAVERQ!CP160 -> 2.6 | AU13: =HAVERQ!CQ160 -> 2.6 | ... BA13: =HAVERQ!CW160 -> 1.9
A15: ILO unemployment forecast
E16: 2016 | I16: 2017 | M16: 2018 | Q16: 2019 | U16: 2020 | Y16: 2021 | AC16: 2022 | AG16: 2023 | AK16: 2024 | AO16: 2025 | AS16: 2026 | AW16: 2027 | BA16: 2028
A17: BoE - Nov24 | B17: 45597 | E17: =HAVERQ!BA$95 -> 5.1 | F17: =HAVERQ!BB$95 -> 4.9 | G17: =HAVERQ!BC$95 -> 4.8 | H17: =HAVERQ!BD$95 -> 4.7 | I17: =HAVERQ!BE$95 -> 4.6 | J17: =HAVERQ!BF$95 -> 4.4 | K17: =HAVERQ!BG$95 -> 4.3 | L17: =HAVERQ!BH$95 -> 4.4 | ... AL17: =HAVERQ!CH$95 -> 4.2 | AM17: =HAVERQ!CI125 -> 4.2 | AN17: =HAVERQ!CJ125 -> 4.2 | AO17: =HAVERQ!CK125 -> 4.1 | AP17: =HAVERQ!CL125 -> 4.1 | AQ17: =HAVERQ!CM125 -> 4.1 | AR17: =HAVERQ!CN125 -> 4.1 | AS17: =HAVERQ!CO125 -> 4.2 | AT17: =HAVERQ!CP125 -> 4.2 | ... AZ17: =HAVERQ!CV125 -> 4.4
A18: BoE - Feb25 | B18: 45689 | E18: =HAVERQ!BA$95 -> 5.1 | F18: =HAVERQ!BB$95 -> 4.9 | G18: =HAVERQ!BC$95 -> 4.8 | H18: =HAVERQ!BD$95 -> 4.7 | I18: =HAVERQ!BE$95 -> 4.6 | J18: =HAVERQ!BF$95 -> 4.4 | K18: =HAVERQ!BG$95 -> 4.3 | L18: =HAVERQ!BH$95 -> 4.4 | ... AM18: =HAVERQ!CI$95 -> 4.3 | AN18: =HAVERQ!CJ126 -> 4.4 | AO18: =HAVERQ!CK126 -> 4.5 | AP18: =HAVERQ!CL126 -> 4.5 | AQ18: =HAVERQ!CM126 -> 4.5 | AR18: =HAVERQ!CN126 -> 4.5 | AS18: =HAVERQ!CO126 -> 4.5 | AT18: =HAVERQ!CP126 -> 4.6 | AU18: =HAVERQ!CQ126 -> 4.6 | ... BA18: =HAVERQ!CW126 -> 4.8
B19: Equilibrium | E19: 4.5 | F19: 4.5 | G19: 4.5 | H19: 4.5 | I19: 4.5 | J19: 4.5 | K19: 4.5 | L19: 4.5 | M19: 4.25 | N19: 4.25 | O19: 4.25 | P19: 4.25 | Q19: 4.25 | R19: 4.25 | S19: 4.25 | T19: 4.25 | U19: 4.25 | V19: 4.25 | W19: 4.25 | X19: 4.25 | Y19: 4.25 | Z19: 4.25 | AA19: 4.25 | AB19: 4.25 | AC19: 4.25 | AD19: 4.25 | AE19: 4.25 | AF19: 4.25 | AG19: 4.25 | AH19: 4.25 | AI19: 4.25 | AJ19: 4.5 | AK19: 4.5 | AL19: 4.5 | AM19: 4.5 | AN19: 4.5 | AO19: 4.5 | AP19: 4.5 | AQ19: 4.5 | AR19: 4.5 | AS19: 4.5 | AT19: 4.5 | AU19: 4.5 | AV19: 4.5 | AW19: 4.5 | AX19: 4.5 | AY19: 4.5 | AZ19: 4.5 | BA19: 4.5
A20: Oxford Economics | AL20: =OE_FCST!HD4 -> 4.2 | AM20: =OE_FCST!HE4 -> 4.3 | AN20: =OE_FCST!HF4 -> 4.408384 | AO20: =OE_FCST!HG4 -> 4.492019 | AP20: =OE_FCST!HH4 -> 4.502507 | AQ20: =OE_FCST!HI4 -> 4.512015 | AR20: =OE_FCST!HJ4 -> 4.502531 | AS20: =OE_FCST!HK4 -> 4.483452 | ... BA20: =OE_FCST!HS4 -> 4.201129
A22: Market conditioning path for interest rates
E23: 42370 | F23: 42461 | G23: 42552 | H23: 42644 | I23: 42736 | J23: 42826 | K23: 42917 | L23: 43009 | M23: 43101 | N23: 43191 | O23: 43282 | P23: 43374 | Q23: 43466 | R23: 43556 | S23: 43647 | T23: 43739 | U23: 43831 | V23: 43922 | W23: 44013 | X23: 44105 | Y23: 44197 | Z23: 44287 | AA23: 44378 | AB23: 44470 | AC23: 44562 | AD23: 44652 | AE23: 44743 | AF23: 44835 | AG23: 44927 | AH23: 45017 | AI23: 45108 | AJ23: 45200 | AK23: 45292 | AL23: 45383 | AM23: 45474 | AN23: 45566 | AO23: 45658 | AP23: 45748 | AQ23: 45839 | AR23: 45931 | AS23: 46023 | AT23: 46113 | AU23: 46204 | AV23: 46296 | AW23: 46388 | AX23: 46478 | AY23: 46569 | AZ23: 46661 | BA23: 46753 | BB23: 46844
A24: Bank Rate | B24: Bank Rate | E24: =HAVERQ!BA$127 -> 0.5 | F24: =HAVERQ!BB$127 -> 0.5 | G24: =HAVERQ!BC$127 -> 0.25 | H24: =HAVERQ!BD$127 -> 0.25 | I24: =HAVERQ!BE$127 -> 0.25 | J24: =HAVERQ!BF$127 -> 0.25 | K24: =HAVERQ!BG$127 -> 0.25 | L24: =HAVERQ!BH$127 -> 0.5 | ... AN24: =HAVERQ!CJ$127 -> 4.75
A25: Market expectations (MPR Nov24) | B25: 45597 | AN25: =HAVERQ!CJ157 -> 4.78 | AO25: =HAVERQ!CK157 -> 4.39 | AP25: =HAVERQ!CL157 -> 4.03 | AQ25: =HAVERQ!CM157 -> 3.81 | AR25: =HAVERQ!CN157 -> 3.72 | AS25: =HAVERQ!CO157 -> 3.69 | AT25: =HAVERQ!CP157 -> 3.68 | AU25: =HAVERQ!CQ157 -> 3.67 | ... BA25: =HAVERQ!CW157 -> 3.6
A26: Market expectations (MPR Feb25) | B26: 45689 | AO26: =HAVERQ!CK158 -> 4.55 | AP26: =HAVERQ!CL158 -> 4.37 | AQ26: =HAVERQ!CM158 -> 4.23 | AR26: =HAVERQ!CN158 -> 4.16 | AS26: =HAVERQ!CO158 -> 4.15 | AT26: =HAVERQ!CP158 -> 4.15 | AU26: =HAVERQ!CQ158 -> 4.13 | AV26: =HAVERQ!CR158 -> 4.11 | ... BB26: =HAVERQ!CX158 -> 3.98
A27: Oxford Economics | AN27: =OE_FCST!HF5 -> 4.75 | AO27: =OE_FCST!HG5 -> 4.5 | AP27: =OE_FCST!HH5 -> 4.25 | AQ27: =OE_FCST!HI5 -> 4 | AR27: =OE_FCST!HJ5 -> 3.75 | AS27: =OE_FCST!HK5 -> 3.5 | AT27: =OE_FCST!HL5 -> 3.25 | AU27: =OE_FCST!HM5 -> 3.25 | ... BB27: =OE_FCST!HT5 -> 2.5
A28: ZERO LINE | B28: ZERO LINE | E28: 0 | F28: 0 | G28: 0 | H28: 0 | I28: 0 | J28: 0 | K28: 0 | L28: 0 | M28: 0 | N28: 0 | O28: 0 | P28: 0 | Q28: 0 | R28: 0 | S28: 0 | T28: 0 | U28: 0 | V28: 0 | W28: 0 | X28: 0 | Y28: 0 | Z28: 0 | AA28: 0 | AB28: 0 | AC28: 0 | AD28: 0 | AE28: 0 | AF28: 0 | AG28: 0 | AH28: 0 | AI28: 0 | AJ28: 0 | AK28: 0 | AL28: 0 | AM28: 0 | AN28: 0 | AO28: 0 | AP28: 0 | AQ28: 0 | AR28: 0 | AS28: 0 | AT28: 0 | AU28: 0 | AV28: 0 | AW28: 0 | AX28: 0 | AY28: 0 | AZ28: 0 | BA28: 0 | BB28: 0
A30: Diff - Nov-24 to Feb-25 | AN30: =+AN26-AN25 -> -4.78 | AO30: =+AO26-AO25 -> 0.16 | AP30: =+AP26-AP25 -> 0.34 | AQ30: =+AQ26-AQ25 -> 0.42 | AR30: =+AR26-AR25 -> 0.44 | AS30: =+AS26-AS25 -> 0.46 | AT30: =+AT26-AT25 -> 0.47 | AU30: =+AU26-AU25 -> 0.46 | ... BA30: =+BA26-BA25 -> 0.39
A31: Change in Bank Rate compared with today | AO31: =AO26-4.7 -> -0.15 | AP31: =AP26-4.7 -> -0.33 | AQ31: =AQ26-4.7 -> -0.47 | AR31: =AR26-4.7 -> -0.54 | AS31: =AS26-4.7 -> -0.55 | AT31: =AT26-4.7 -> -0.55 | AU31: =AU26-4.7 -> -0.57 | AV31: =AV26-4.7 -> -0.59 | ... BB31: =BB26-4.7 -> -0.72
A33: Forecasts for UK GDP growth
B34: 2023 | C34: 2024 | D34: 2025 | E34: 2026
A35: BoE* (Feb) | B35: 0.5 | C35: 0.75 | D35: 0.65 | E35: 1.5
A36: BoE* (Nov) | B36: 0.25 | C36: 1 | D36: 1.5 | E36: 1.25
A38: OE (Feb) | B38: 0.4 | C38: 0.75 | D38: 1.01 | E38: 1.558
A39: HMT consensus (Jan) | B39: 0.3 | C39: 0.8 | D39: 1.2 | E39: 1.5
A40: OBR (Oct) | B40: 0.1 | C40: 1.1 | D40: 2 | E40: 1.8
A43: NOT BEING USED>>>>
A44: GDP forecast
E45: 2016 | I45: 2017 | M45: 2018 | Q45: 2019 | U45: 2020 | Y45: 2021 | AC45: 2022 | AG45: 2023 | AK45: 2024
A46: BoE - Nov19 | B46: 43770 | E46: =HAVERQ!BA12 -> 2.07 | F46: =HAVERQ!BB12 -> 1.89 | G46: =HAVERQ!BC12 -> 1.91 | H46: =HAVERQ!BD12 -> 1.81 | I46: =HAVERQ!BE12 -> 2.24 | J46: =HAVERQ!BF12 -> 2.06 | K46: =HAVERQ!BG12 -> 2.01 | L46: =HAVERQ!BH12 -> 1.78 | ... R46: =HAVERQ!BN12 -> 1.35 | S46: 1.13 | T46: =HAVERQ!BP42 -> 0.99 | U46: =HAVERQ!BQ42 -> 0.66 | V46: =HAVERQ!BR42 -> 1.3 | W46: =HAVERQ!BS42 -> 1.34 | X46: =HAVERQ!BT42 -> 1.55 | Y46: =HAVERQ!BU42 -> 1.72 | Z46: =HAVERQ!BV42 -> 1.76 | AA46: =HAVERQ!BW42 -> 1.79 | ... AF46: =HAVERQ!CB42 -> 2.06
A47: BoE - Jan20 | B47: 43831 | E47: =HAVERQ!BA13 -> 2.07 | F47: =HAVERQ!BB13 -> 1.89 | G47: =HAVERQ!BC13 -> 1.91 | H47: =HAVERQ!BD13 -> 1.81 | I47: =HAVERQ!BE13 -> 2.23 | J47: =HAVERQ!BF13 -> 2.05 | K47: =HAVERQ!BG13 -> 2 | L47: =HAVERQ!BH13 -> 1.77 | ... S47: =HAVERQ!BO13 -> 1.11 | T47: 0.99 | U47: =HAVERQ!BQ43 -> 0.37 | V47: =HAVERQ!BR43 -> 0.83 | W47: =HAVERQ!BS43 -> 0.76 | X47: =HAVERQ!BT43 -> 1.21 | Y47: =HAVERQ!BU43 -> 1.37 | Z47: =HAVERQ!BV43 -> 1.45 | AA47: =HAVERQ!BW43 -> 1.48 | AB47: =HAVERQ!BX43 -> 1.46 | ... AG47: =HAVERQ!CC43 -> 1.95
...

Sheet HAVERQ
C1: 20051 !Q | D1: .DESC | E1: .T1 | F1: .TN | G1: .SOURCE | H1: .DTLM | I1: 20051 | J1: 20052 | K1: 20053 | L1: 20054 | M1: 20061 | N1: 20062 | O1: 20063 | P1: 20064 | Q1: 20071 | R1: 20072 | S1: 20073 | T1: 20074 | U1: 20081 | V1: 20082 | W1: 20083 | X1: 20084 | Y1: 20091 | Z1: 20092 | AA1: 20093 | AB1: 20094 | AC1: 20101 | AD1: 20102 | AE1: 20103 | AF1: 20104 | AG1: 20111 | AH1: 20112 | AI1: 20113 | AJ1: 20114 | AK1: 20121 | AL1: 20122 | AM1: 20123 | AN1: 20124 | AO1: 20131 | AP1: 20132 | AQ1: 20133 | AR1: 20134 | AS1: 20141 | AT1: 20142 | AU1: 20143 | AV1: 20144 | AW1: 20151 | AX1: 20152 | AY1: 20153 | AZ1: 20154 | BA1: 20161 | BB1: 20162 | BC1: 20163 | BD1: 20164 | BE1: 20171 | BF1: 20172 | BG1: 20173 | BH1: 20174 | BI1: 20181 | BJ1: 20182 | BK1: 20183 | BL1: 20184 | BM1: 20191 | BN1: 20192 | BO1: 20193 | BP1: 20194 | BQ1: 20201 | BR1: 20202 | BS1: 20203 | BT1: 20204 | BU1: 20211 | BV1: 20212 | BW1: 20213 | BX1: 20214 | BY1: 20221 | BZ1: 20222 | CA1: 20223 | CB1: 20224 | CC1: 20231 | CD1: 20232 | CE1: 20233 | CF1: 20234 | CG1: 20241 | CH1: 20242 | CI1: 20243 | CJ1: 20244 | CK1: 20251 | CL1: 20252 | CM1: 20253 | CN1: 20254 | CO1: 20261 | CP1: 20262 | CQ1: 20263 | CR1: 20264 | CS1: 20271 | CT1: 20272 | CU1: 20273 | CV1: 20274 | CW1: 20281 | CX1: 20282
A2: GDP backcast | B2: 42856 | C2: UNGB172@UK | D2: UK: BoE MPC Backcasts of GDP Growth: [May 2017] Real GDP (SA, Y/Y % Change) | E2: Q3-2009 | F2: Q1-2017 | G2: DISC | H2: May-11-2017 13:50 | I2: #N/A | J2: #N/A | K2: #N/A | L2: #N/A | M2: #N/A | N2: #N/A | O2: #N/A | P2: #N/A | Q2: #N/A | R2: #N/A | S2: #N/A | T2: #N/A | U2: #N/A | V2: #N/A | W2: #N/A | X2: #N/A | Y2: #N/A | Z2: #N/A | AA2: -4.01 | AB2: -1.39 | AC2: 0.8 | AD2: 2.05 | AE2: 2.55 | AF2: 2.26 | AG2: 2.26 | AH2: 1.3 | AI2: 1.17 | AJ2: 1.31 | AK2: 1.19 | AL2: 1.04 | AM2: 1.75 | AN2: 1.27 | AO2: 1.46 | AP2: 2.07 | AQ2: 1.69 | AR2: 2.42 | AS2: 2.69 | AT2: 3.12 | AU2: 3.23 | AV2: 3.53 | AW2: 3.04 | AX2: 2.58 | AY2: 2.12 | AZ2: 1.94 | BA2: 1.85 | BB2: 1.92 | BC2: 2.06 | BD2: 2.12 | BE2: 2.21
B3: 42948 | C3: UNGB173@UK | D3: UK: BoE MPC Backcasts of GDP Growth: [Aug 2017] Real GDP (SA, Y/Y % Change) | E3: Q4-2009 | F3: Q2-2017 | G3: DISC | H3: Aug-03-2017 15:19 | I3: #N/A | J3: #N/A | K3: #N/A | L3: #N/A | M3: #N/A | N3: #N/A | O3: #N/A | P3: #N/A | Q3: #N/A | R3: #N/A | S3: #N/A | T3: #N/A | U3: #N/A | V3: #N/A | W3: #N/A | X3: #N/A | Y3: #N/A | Z3: #N/A | AA3: #N/A | AB3: -1.39 | AC3: 0.8 | AD3: 2.05 | AE3: 2.55 | AF3: 2.26 | AG3: 2.26 | AH3: 1.3 | AI3: 1.17 | AJ3: 1.31 | AK3: 1.19 | AL3: 1.04 | AM3: 1.75 | AN3: 1.27 | AO3: 1.46 | AP3: 2.07 | AQ3: 1.69 | AR3: 2.42 | AS3: 2.69 | AT3: 3.12 | AU3: 3.22 | AV3: 3.53 | AW3: 3.03 | AX3: 2.57 | AY3: 2.11 | AZ3: 1.93 | BA3: 1.85 | BB3: 1.92 | BC3: 2.05 | BD3: 2.05 | BE3: 2.07 | BF3: 1.82
B4: 43040 | C4: UNGB174@UK | D4: UK: BoE MPC Backcasts of GDP Growth: [Nov 2017] Real GDP (SA, Y/Y % Change) | E4: Q1-2010 | F4: Q3-2017 | G4: DISC | H4: Nov-02-2017 14:14 | I4: #N/A | J4: #N/A | K4: #N/A | L4: #N/A | M4: #N/A | N4: #N/A | O4: #N/A | P4: #N/A | Q4: #N/A | R4: #N/A | S4: #N/A | T4: #N/A | U4: #N/A | V4: #N/A | W4: #N/A | X4: #N/A | Y4: #N/A | Z4: #N/A | AA4: #N/A | AB4: #N/A | AC4: 0.74 | AD4: 1.87 | AE4: 2.19 | AF4: 1.99 | AG4: 2.04 | AH4: 1.28 | AI4: 1.19 | AJ4: 1.31 | AK4: 1.37 | AL4: 1.11 | AM4: 1.89 | AN4: 1.55 | AO4: 1.54 | AP4: 2.2 | AQ4: 1.89 | AR4: 2.57 | AS4: 2.8 | AT4: 3.12 | AU4: 3.03 | AV4: 3.27 | AW4: 2.89 | AX4: 2.62 | AY4: 2.38 | AZ4: 2.26 | BA4: 2.09 | BB4: 1.99 | BC4: 1.91 | BD4: 1.8 | BE4: 1.84 | BF4: 1.65 | BG4: 1.6
B5: 43132 | C5: UNGB181@UK | D5: UK: BoE MPC Backcasts of GDP Growth: [February 2018] Real GDP (SA, Y/Y % Change) | E5: Q2-2010 | F5: Q4-2017 | G5: DISC | H5: Feb-08-2018 15:38 | I5: #N/A | J5: #N/A | K5: #N/A | L5: #N/A | M5: #N/A | N5: #N/A | O5: #N/A | P5: #N/A | Q5: #N/A | R5: #N/A | S5: #N/A | T5: #N/A | U5: #N/A | V5: #N/A | W5: #N/A | X5: #N/A | Y5: #N/A | Z5: #N/A | AA5: #N/A | AB5: #N/A | AC5: #N/A | AD5: 1.87 | AE5: 2.19 | AF5: 1.99 | AG5: 2.04 | AH5: 1.28 | AI5: 1.19 | AJ5: 1.31 | AK5: 1.37 | AL5: 1.11 | AM5: 1.89 | AN5: 1.55 | AO5: 1.54 | AP5: 2.2 | AQ5: 1.89 | AR5: 2.57 | AS5: 2.8 | AT5: 3.12 | AU5: 3.03 | AV5: 3.27 | AW5: 2.89 | AX5: 2.62 | AY5: 2.37 | AZ5: 2.26 | BA5: 2.14 | BB5: 2.03 | BC5: 2.08 | BD5: 2.11 | BE5: 2.17 | BF5: 1.99 | BG5: 1.8 | BH5: 1.62
B6: 43221 | C6: UNGB182@UK | D6: UK: BoE MPC Backcasts of GDP Growth: [May 2018] Real GDP (SA, Y/Y % Change) | E6: Q3-2010 | F6: Q1-2018 | G6: DISC | H6: May-10-2018 13:09 | I6: #N/A | J6: #N/A | K6: #N/A | L6: #N/A | M6: #N/A | N6: #N/A | O6: #N/A | P6: #N/A | Q6: #N/A | R6: #N/A | S6: #N/A | T6: #N/A | U6: #N/A | V6: #N/A | W6: #N/A | X6: #N/A | Y6: #N/A | Z6: #N/A | AA6: #N/A | AB6: #N/A | AC6: #N/A | AD6: #N/A | AE6: 2.19 | AF6: 1.99 | AG6: 2.04 | AH6: 1.28 | AI6: 1.19 | AJ6: 1.31 | AK6: 1.37 | AL6: 1.11 | AM6: 1.89 | AN6: 1.55 | AO6: 1.54 | AP6: 2.2 | AQ6: 1.89 | AR6: 2.57 | AS6: 2.8 | AT6: 3.12 | AU6: 3.03 | AV6: 3.27 | AW6: 2.89 | AX6: 2.61 | AY6: 2.36 | AZ6: 2.25 | BA6: 2.13 | BB6: 2.02 | BC6: 2.08 | BD6: 2.11 | BE6: 2.17 | BF6: 2.05 | BG6: 1.97 | BH6: 1.73 | BI6: 1.62
B7: 43313 | C7: UNGB183@UK | D7: UK: BoE MPC Backcasts of GDP Growth: [Aug 2018] Real GDP (SA, Y/Y % Change) | E7: Q4-2010 | F7: Q1-2018 | G7: DISC | H7: Aug-02-2018 15:07 | I7: #N/A | J7: #N/A | K7: #N/A | L7: #N/A | M7: #N/A | N7: #N/A | O7: #N/A | P7: #N/A | Q7: #N/A | R7: #N/A | S7: #N/A | T7: #N/A | U7: #N/A | V7: #N/A | W7: #N/A | X7: #N/A | Y7: #N/A | Z7: #N/A | AA7: #N/A | AB7: #N/A | AC7: #N/A | AD7: #N/A | AE7: #N/A | AF7: 2.03 | AG7: 2.34 | AH7: 1.61 | AI7: 1.3 | AJ7: 1.34 | AK7: 1.24 | AL7: 1.03 | AM7: 1.96 | AN7: 1.56 | AO7: 1.56 | AP7: 2.17 | AQ7: 1.87 | AR7: 2.58 | AS7: 2.78 | AT7: 3.07 | AU7: 2.87 | AV7: 3.07 | AW7: 2.77 | AX7: 2.53 | AY7: 2.34 | AZ7: 2.36 | BA7: 2.21 | BB7: 1.85 | BC7: 1.82 | BD7: 1.83 | BE7: 1.89 | BF7: 1.97 | BG7: 1.88 | BH7: 1.57 | BI7: 1.43
B8: 43405 | C8: UNGB184@UK | D8: UK: BoE MPC Backcasts of GDP Growth: [Nov 2018] Real GDP (SA, Y/Y % Change) | E8: Q1-2011 | F8: Q2-2018 | G8: DISC | H8: Nov-01-2018 14:59 | I8: #N/A | J8: #N/A | K8: #N/A | L8: #N/A | M8: #N/A | N8: #N/A | O8: #N/A | P8: #N/A | Q8: #N/A | R8: #N/A | S8: #N/A | T8: #N/A | U8: #N/A | V8: #N/A | W8: #N/A | X8: #N/A | Y8: #N/A | Z8: #N/A | AA8: #N/A | AB8: #N/A | AC8: #N/A | AD8: #N/A | AE8: #N/A | AF8: #N/A | AG8: 2.34 | AH8: 1.61 | AI8: 1.3 | AJ8: 1.34 | AK8: 1.24 | AL8: 1.03 | AM8: 1.96 | AN8: 1.56 | AO8: 1.56 | AP8: 2.17 | AQ8: 1.87 | AR8: 2.58 | AS8: 2.78 | AT8: 3.07 | AU8: 2.87 | AV8: 3.07 | AW8: 2.76 | AX8: 2.52 | AY8: 2.32 | AZ8: 2.35 | BA8: 2.2 | BB8: 1.83 | BC8: 1.81 | BD8: 1.82 | BE8: 1.93 | BF8: 2.04 | BG8: 1.94 | BH8: 1.62 | BI8: 1.43 | BJ8: 1.53
B9: 43497 | C9: UNGB191@UK | D9: UK: BoE MPC Backcasts of GDP Growth [Feb-19]: Real GDP(SA, Y/Y % Change) | E9: Q2-2011 | F9: Q3-2018 | G9: DISC | H9: Feb-07-2019 12:39 | I9: #N/A | J9: #N/A | K9: #N/A | L9: #N/A | M9: #N/A | N9: #N/A | O9: #N/A | P9: #N/A | Q9: #N/A | R9: #N/A | S9: #N/A | T9: #N/A | U9: #N/A | V9: #N/A | W9: #N/A | X9: #N/A | Y9: #N/A | Z9: #N/A | AA9: #N/A | AB9: #N/A | AC9: #N/A | AD9: #N/A | AE9: #N/A | AF9: #N/A | AG9: #N/A | AH9: 1.61 | AI9: 1.3 | AJ9: 1.34 | AK9: 1.24 | AL9: 1.03 | AM9: 1.96 | AN9: 1.56 | AO9: 1.56 | AP9: 2.17 | AQ9: 1.87 | AR9: 2.58 | AS9: 2.78 | AT9: 3.07 | AU9: 2.87 | AV9: 3.07 | AW9: 2.76 | AX9: 2.52 | AY9: 2.32 | AZ9: 2.36 | BA9: 2.2 | BB9: 1.83 | BC9: 1.81 | BD9: 1.82 | BE9: 1.91 | BF9: 2.04 | BG9: 2.08 | BH9: 1.79 | BI9: 1.61 | BJ9: 1.72 | BK9: 1.81
B10: 43586 | C10: UNGB192@UK | D10: UK: BoE MPC Backcasts of GDP Growth: Real GDP [May 2019] (SA, Y/Y % Change) | E10: Q3-2011 | F10: Q4-2018 | G10: DISC | H10: May-02-2019 12:20 | I10: #N/A | J10: #N/A | K10: #N/A | L10: #N/A | M10: #N/A | N10: #N/A | O10: #N/A | P10: #N/A | Q10: #N/A | R10: #N/A | S10: #N/A | T10: #N/A | U10: #N/A | V10: #N/A | W10: #N/A | X10: #N/A | Y10: #N/A | Z10: #N/A | AA10: #N/A | AB10: #N/A | AC10: #N/A | AD10: #N/A | AE10: #N/A | AF10: #N/A | AG10: #N/A | AH10: #N/A | AI10: 1.3 | AJ10: 1.34 | AK10: 1.24 | AL10: 1.03 | AM10: 1.96 | AN10: 1.56 | AO10: 1.56 | AP10: 2.17 | AQ10: 1.87 | AR10: 2.58 | AS10: 2.78 | AT10: 3.07 | AU10: 2.87 | AV10: 3.07 | AW10: 2.75 | AX10: 2.51 | AY10: 2.31 | AZ10: 2.35 | BA10: 2.2 | BB10: 1.83 | BC10: 1.82 | BD10: 1.83 | BE10: 1.92 | BF10: 2.05 | BG10: 2.08 | BH10: 1.79 | BI10: 1.62 | BJ10: 1.72 | BK10: 1.82 | BL10: 1.7
B11: 43678 | C11: UNGB193@UK | D11: UK: BoE MPC Backcasts of GDP Growth: Real GDP [Aug 19] (SA, Y/Y % Change) | E11: Q4-2011 | F11: Q1-2019 | G11: DISC | H11: Aug-01-2019 12:24 | I11: #N/A | J11: #N/A | K11: #N/A | L11: #N/A | M11: #N/A | N11: #N/A | O11: #N/A | P11: #N/A | Q11: #N/A | R11: #N/A | S11: #N/A | T11: #N/A | U11: #N/A | V11: #N/A | W11: #N/A | X11: #N/A | Y11: #N/A | Z11: #N/A | AA11: #N/A | AB11: #N/A | AC11: #N/A | AD11: #N/A | AE11: #N/A | AF11: #N/A | AG11: #N/A | AH11: #N/A | AI11: #N/A | AJ11: 1.34 | AK11: 1.24 | AL11: 1.03 | AM11: 1.96 | AN11: 1.56 | AO11: 1.56 | AP11: 2.17 | AQ11: 1.87 | AR11: 2.58 | AS11: 2.78 | AT11: 3.07 | AU11: 2.87 | AV11: 3.07 | AW11: 2.75 | AX11: 2.51 | AY11: 2.3 | AZ11: 2.34 | BA11: 2.19 | BB11: 1.83 | BC11: 1.81 | BD11: 1.82 | BE11: 1.92 | BF11: 2.04 | BG11: 2.07 | BH11: 1.78 | BI11: 1.61 | BJ11: 1.73 | BK11: 1.84 | BL11: 1.74 | BM11: 1.91
B12: 43770 | C12: UNGB194@UK | D12: UK: BoE MPC Backcasts of GDP Growth: Real GDP [Q4-19](SA, Y/Y % Change) | E12: Q1-2012 | F12: Q2-2019 | G12: DISC | H12: Nov-07-2019 15:05 | I12: #N/A | J12: #N/A | K12: #N/A | L12: #N/A | M12: #N/A | N12: #N/A | O12: #N/A | P12: #N/A | Q12: #N/A | R12: #N/A | S12: #N/A | T12: #N/A | U12: #N/A | V12: #N/A | W12: #N/A | X12: #N/A | Y12: #N/A | Z12: #N/A | AA12: #N/A | AB12: #N/A | AC12: #N/A | AD12: #N/A | AE12: #N/A | AF12: #N/A | AG12: #N/A | AH12: #N/A | AI12: #N/A | AJ12: #N/A | AK12: 1.24 | AL12: 1.06 | AM12: 1.98 | AN12: 1.63 | AO12: 1.63 | AP12: 2.26 | AQ12: 1.98 | AR12: 2.68 | AS12: 2.7 | AT12: 2.82 | AU12: 2.44 | AV12: 2.47 | AW12: 2.34 | AX12: 2.4 | AY12: 2.25 | AZ12: 2.44 | BA12: 2.07 | BB12: 1.89 | BC12: 1.91 | BD12: 1.81 | BE12: 2.24 | BF12: 2.06 | BG12: 2.01 | BH12: 1.78 | BI12: 1.44 | BJ12: 1.67 | BK12: 1.87 | BL12: 1.84 | BM12: 2.17 | BN12: 1.35
B13: 43831 | C13: UNGB201@UK | D13: UK: BoE MPC Backcasts of GDP Growth: Real GDP [Q1-20](SA, Y/Y % Change) | E13: Q2-2012 | F13: Q3-2019 | G13: DISC | H13: Jan-30-2020 12:22 | I13: #N/A | J13: #N/A | K13: #N/A | L13: #N/A | M13: #N/A | N13: #N/A | O13: #N/A | P13: #N/A | Q13: #N/A | R13: #N/A | S13: #N/A | T13: #N/A | U13: #N/A | V13: #N/A | W13: #N/A | X13: #N/A | Y13: #N/A | Z13: #N/A | AA13: #N/A | AB13: #N/A | AC13: #N/A | AD13: #N/A | AE13: #N/A | AF13: #N/A | AG13: #N/A | AH13: #N/A | AI13: #N/A | AJ13: #N/A | AK13: #N/A | AL13: 1.06 | AM13: 1.98 | AN13: 1.63 | AO13: 1.63 | AP13: 2.26 | AQ13: 1.98 | AR13: 2.68 | AS13: 2.7 | AT13: 2.82 | AU13: 2.44 | AV13: 2.47 | AW13: 2.34 | AX13: 2.4 | AY13: 2.25 | AZ13: 2.44 | BA13: 2.07 | BB13: 1.89 | BC13: 1.91 | BD13: 1.81 | BE13: 2.23 | BF13: 2.05 | BG13: 2 | BH13: 1.77 | BI13: 1.43 | BJ13: 1.65 | BK13: 1.82 | BL13: 1.68 | BM13: 2.04 | BN13: 1.27 | BO13: 1.11
B14: 44044 | C14: UNGB203@UK | D14: UK: BoE MPC Backcasts of GDP Growth: Real GDP [Aug-20] (SA, Y/Y % Chg) | E14: Q4-2012 | F14: Q1-2020 | G14: DISC | H14: Aug-11-2020 12:33 | I14: #N/A | J14: #N/A | K14: #N/A | L14: #N/A | M14: #N/A | N14: #N/A | O14: #N/A | P14: #N/A | Q14: #N/A | R14: #N/A | S14: #N/A | T14: #N/A | U14: #N/A | V14: #N/A | W14: #N/A | X14: #N/A | Y14: #N/A | Z14: #N/A | AA14: #N/A | AB14: #N/A | AC14: #N/A | AD14: #N/A | AE14: #N/A | AF14: #N/A | AG14: #N/A | AH14: #N/A | AI14: #N/A | AJ14: #N/A | AK14: #N/A | AL14: #N/A | AM14: #N/A | AN14: 1.63 | AO14: 1.63 | AP14: 2.26 | AQ14: 1.98 | AR14: 2.68 | AS14: 2.7 | AT14: 2.82 | AU14: 2.44 | AV14: 2.47 | AW14: 2.34 | AX14: 2.4 | AY14: 2.25 | AZ14: 2.44 | BA14: 2.07 | BB14: 1.89 | BC14: 1.91 | BD14: 1.81 | BE14: 2.24 | BF14: 2.05 | BG14: 1.99 | BH14: 1.76 | BI14: 1.4 | BJ14: 1.62 | BK14: 1.79 | BL14: 1.72 | BM14: 2.15 | BN14: 1.51 | BO14: 1.32 | BP14: 1.08 | BQ14: -1.77
B15: 44136 | C15: UNGB204@UK | D15: UK: BoE MPC Backcasts of GDP Growth: Real GDP [Q4-20] (SA, Y/Y % Change) | E15: Q1-2013 | F15: Q2-2020 | G15: DISC | H15: Nov-05-2020 12:20 | I15: #N/A | J15: #N/A | K15: #N/A | L15: #N/A | M15: #N/A | N15: #N/A | O15: #N/A | P15: #N/A | Q15: #N/A | R15: #N/A | S15: #N/A | T15: #N/A | U15: #N/A | V15: #N/A | W15: #N/A | X15: #N/A | Y15: #N/A | Z15: #N/A | AA15: #N/A | AB15: #N/A | AC15: #N/A | AD15: #N/A | AE15: #N/A | AF15: #N/A | AG15: #N/A | AH15: #N/A | AI15: #N/A | AJ15: #N/A | AK15: #N/A | AL15: #N/A | AM15: #N/A | AN15: #N/A | AO15: 1.38 | AP15: 2.35 | AQ15: 2.06 | AR15: 2.94 | AS15: 3.19 | AT15: 3.03 | AU15: 2.65 | AV15: 2.59 | AW15: 2.36 | AX15: 2.46 | AY15: 2.28 | AZ15: 2.35 | BA15: 2 | BB15: 1.71 | BC15: 1.62 | BD15: 1.56 | BE15: 1.86 | BF15: 1.7 | BG15: 1.82 | BH15: 1.58 | BI15: 1.3 | BJ15: 1.48 | BK15: 1.6 | BL15: 1.53 | BM15: 1.86 | BN15: 1.37 | BO15: 1.15 | BP15: 1.07 | BQ15: -2.02 | BR15: -21.42
B16: 44228 | C16: UNGB211@UK | D16: UK: BoE MPC Backcasts of GDP Growth: Real GDP [Q1-21] (SA, Y/Y % Change) | E16: Q2-2013 | F16: Q3-2020 | G16: DISC | H16: Feb-04-2021 14:25 | I16: #N/A | J16: #N/A | K16: #N/A | L16: #N/A | M16: #N/A | N16: #N/A | O16: #N/A | P16: #N/A | Q16: #N/A | R16: #N/A | S16: #N/A | T16: #N/A | U16: #N/A | V16: #N/A | W16: #N/A | X16: #N/A | Y16: #N/A | Z16: #N/A | AA16: #N/A | AB16: #N/A | AC16: #N/A | AD16: #N/A | AE16: #N/A | AF16: #N/A | AG16: #N/A | AH16: #N/A | AI16: #N/A | AJ16: #N/A | AK16: #N/A | AL16: #N/A | AM16: #N/A | AN16: #N/A | AO16: #N/A | AP16: 2.35 | AQ16: 2.06 | AR16: 2.94 | AS16: 3.19 | AT16: 3.03 | AU16: 2.65 | AV16: 2.59 | AW16: 2.36 | AX16: 2.46 | AY16: 2.28 | AZ16: 2.35 | BA16: 2 | BB16: 1.71 | BC16: 1.62 | BD16: 1.56 | BE16: 1.86 | BF16: 1.7 | BG16: 1.82 | BH16: 1.58 | BI16: 1.22 | BJ16: 1.41 | BK16: 1.7 | BL16: 1.58 | BM16: 1.99 | BN16: 1.64 | BO16: 1.44 | BP16: 1.42 | BQ16: -2.18 | BR16: -20.64 | BS16: -8.4
B17: 44317 | C17: UNGB212@UK | D17: UK: BoE MPC Backcasts of GDP Growth: Real GDP [Q2-21] (SA, Y/Y % Change) | E17: Q3-2013 | F17: Q4-2020 | G17: DISC | H17: May-06-2021 13:01 | I17: #N/A | J17: #N/A | K17: #N/A | L17: #N/A | M17: #N/A | N17: #N/A | O17: #N/A | P17: #N/A | Q17: #N/A | R17: #N/A | S17: #N/A | T17: #N/A | U17: #N/A | V17: #N/A | W17: #N/A | X17: #N/A | Y17: #N/A | Z17: #N/A | AA17: #N/A | AB17: #N/A | AC17: #N/A | AD17: #N/A | AE17: #N/A | AF17: #N/A | AG17: #N/A | AH17: #N/A | AI17: #N/A | AJ17: #N/A | AK17: #N/A | AL17: #N/A | AM17: #N/A | AN17: #N/A | AO17: #N/A | AP17: #N/A | AQ17: 2.06 | AR17: 2.94 | AS17: 3.19 | AT17: 3.03 | AU17: 2.65 | AV17: 2.59 | AW17: 2.36 | AX17: 2.46 | AY17: 2.28 | AZ17: 2.35 | BA17: 2 | BB17: 1.71 | BC17: 1.62 | BD17: 1.56 | BE17: 1.86 | BF17: 1.7 | BG17: 1.82 | BH17: 1.58 | BI17: 1.22 | BJ17: 1.41 | BK17: 1.7 | BL17: 1.58 | BM17: 1.99 | BN17: 1.64 | BO17: 1.44 | BP17: 1.42 | BQ17: -2.01 | BR17: -21.2 | BS17: -8.3 | BT17: -7.34
B18: 44409 | C18: UNGB213@UK | D18: UK: BoE MPC Backcasts of GDP Growth: Real GDP [Q3-21] (SA, Y/Y % Change) | E18: Q4-2013 | F18: Q1-2021 | G18: DISC | H18: Aug-05-2021 12:45 | I18: #N/A | J18: #N/A | K18: #N/A | L18: #N/A | M18: #N/A | N18: #N/A | O18: #N/A | P18: #N/A | Q18: #N/A | R18: #N/A | S18: #N/A | T18: #N/A | U18: #N/A | V18: #N/A | W18: #N/A | X18: #N/A | Y18: #N/A | Z18: #N/A | AA18: #N/A | AB18: #N/A | AC18: #N/A | AD18: #N/A | AE18: #N/A | AF18: #N/A | AG18: #N/A | AH18: #N/A | AI18: #N/A | AJ18: #N/A | AK18: #N/A | AL18: #N/A | AM18: #N/A | AN18: #N/A | AO18: #N/A | AP18: #N/A | AQ18: #N/A | AR18: 2.94 | AS18: 3.19 | AT18: 3.03 | AU18: 2.65 | AV18: 2.59 | AW18: 2.36 | AX18: 2.46 | AY18: 2.28 | AZ18: 2.35 | BA18: 2 | BB18: 1.71 | BC18: 1.62 | BD18: 1.56 | BE18: 1.86 | BF18: 1.7 | BG18: 1.82 | BH18: 1.58 | BI18: 1.22 | BJ18: 1.41 | BK18: 1.7 | BL18: 1.58 | BM18: 1.99 | BN18: 1.64 | BO18: 1.44 | BP18: 1.42 | BQ18: -2.01 | BR18: -21.2 | BS18: -8.3 | BT18: -7.34 | BU18: -6.14
B19: 44501 | C19: UNGB214@UK | D19: UK: BoE MPC Backcasts of GDP Growth: Real GDP [Q4-21] (SA, Y/Y % Change) | E19: Q1-2014 | F19: Q2-2021 | G19: DISC | H19: Nov-04-2021 12:38 | I19: #N/A | J19: #N/A | K19: #N/A | L19: #N/A | M19: #N/A | N19: #N/A | O19: #N/A | P19: #N/A | Q19: #N/A | R19: #N/A | S19: #N/A | T19: #N/A | U19: #N/A | V19: #N/A | W19: #N/A | X19: #N/A | Y19: #N/A | Z19: #N/A | AA19: #N/A | AB19: #N/A | AC19: #N/A | AD19: #N/A | AE19: #N/A | AF19: #N/A | AG19: #N/A | AH19: #N/A | AI19: #N/A | AJ19: #N/A | AK19: #N/A | AL19: #N/A | AM19: #N/A | AN19: #N/A | AO19: #N/A | AP19: #N/A | AQ19: #N/A | AR19: #N/A | AS19: 2.91 | AT19: 3.07 | AU19: 2.97 | AV19: 3.01 | AW19: 2.72 | AX19: 2.65 | AY19: 2.5 | AZ19: 2.63 | BA19: 2.42 | BB19: 2.25 | BC19: 2.16 | BD19: 2.22 | BE19: 2.43 | BF19: 2.16 | BG19: 2.14 | BH19: 1.8 | BI19: 1.39 | BJ19: 1.62 | BK19: 1.83 | BL19: 1.76 | BM19: 2.17 | BN19: 1.75 | BO19: 1.58 | BP19: 1.19 | BQ19: -2.17 | BR19: -21.41 | BS19: -8.13 | BT19: -7.07 | BU19: -5.79 | BV19: 23.58
B20: 44593 | C20: UNGB221@UK | D20: UK: BoE MPC Backcasts of GDP Growth: Real GDP [Q1-22] (SA, Y/Y % Change) | E20: Q2-2014 | F20: Q3-2021 | G20: DISC | H20: Feb-03-2022 15:12 | I20: #N/A | J20: #N/A | K20: #N/A | L20: #N/A | M20: #N/A | N20: #N/A | O20: #N/A | P20: #N/A | Q20: #N/A | R20: #N/A | S20: #N/A | T20: #N/A | U20: #N/A | V20: #N/A | W20: #N/A | X20: #N/A | Y20: #N/A | Z20: #N/A | AA20: #N/A | AB20: #N/A | AC20: #N/A | AD20: #N/A | AE20: #N/A | AF20: #N/A | AG20: #N/A | AH20: #N/A | AI20: #N/A | AJ20: #N/A | AK20: #N/A | AL20: #N/A | AM20: #N/A | AN20: #N/A | AO20: #N/A | AP20: #N/A | AQ20: #N/A | AR20: #N/A | AS20: #N/A | AT20: 3.07 | AU20: 2.97 | AV20: 3.01 | AW20: 2.72 | AX20: 2.65 | AY20: 2.5 | AZ20: 2.63 | BA20: 2.42 | BB20: 2.25 | BC20: 2.16 | BD20: 2.22 | BE20: 2.43 | BF20: 2.16 | BG20: 2.14 | BH20: 1.8 | BI20: 1.39 | BJ20: 1.62 | BK20: 1.83 | BL20: 1.76 | BM20: 2.17 | BN20: 1.75 | BO20: 1.58 | BP20: 1.19 | BQ20: -2.1 | BR20: -21.25 | BS20: -7.83 | BT20: -6.41 | BU20: -5.09 | BV20: 24.23 | BW20: 6.79
B21: 44682 | C21: UNGB222@UK | D21: UK: BoE MPC Backcasts of GDP Growth: Real GDP [Q2-22] (SA, Y/Y % Change) | E21: Q3-2014 | F21: Q4-2021 | G21: DISC | H21: May-05-2022 13:43 | I21: #N/A | J21: #N/A | K21: #N/A | L21: #N/A | M21: #N/A | N21: #N/A | O21: #N/A | P21: #N/A | Q21: #N/A | R21: #N/A | S21: #N/A | T21: #N/A | U21: #N/A | V21: #N/A | W21: #N/A | X21: #N/A | Y21: #N/A | Z21: #N/A | AA21: #N/A | AB21: #N/A | AC21: #N/A | AD21: #N/A | AE21: #N/A | AF21: #N/A | AG21: #N/A | AH21: #N/A | AI21: #N/A | AJ21: #N/A | AK21: #N/A | AL21: #N/A | AM21: #N/A | AN21: #N/A | AO21: #N/A | AP21: #N/A | AQ21: #N/A | AR21: #N/A | AS21: #N/A | AT21: #N/A | AU21: 2.97 | AV21: 3.01 | AW21: 2.72 | AX21: 2.65 | AY21: 2.5 | AZ21: 2.63 | BA21: 2.42 | BB21: 2.25 | BC21: 2.16 | BD21: 2.22 | BE21: 2.43 | BF21: 2.16 | BG21: 2.14 | BH21: 1.8 | BI21: 1.39 | BJ21: 1.62 | BK21: 1.83 | BL21: 1.76 | BM21: 2.17 | BN21: 1.75 | BO21: 1.58 | BP21: 1.19 | BQ21: -1.99 | BR21: -21.14 | BS21: -7.69 | BT21: -6.28 | BU21: -4.97 | BV21: 24.49 | BW21: 6.86 | BX21: 6.64
B22: 44774 | C22: UNGB223@UK | D22: UK: BoE MPC Backcasts of GDP Growth: Real GDP [Q3-22] (SA, Y/Y % Change) | E22: Q4-2014 | F22: Q1-2022 | G22: DISC | H22: Aug-04-2022 12:54 | I22: #N/A | J22: #N/A | K22: #N/A | L22: #N/A | M22: #N/A | N22: #N/A | O22: #N/A | P22: #N/A | Q22: #N/A | R22: #N/A | S22: #N/A | T22: #N/A | U22: #N/A | V22: #N/A | W22: #N/A | X22: #N/A | Y22: #N/A | Z22: #N/A | AA22: #N/A | AB22: #N/A | AC22: #N/A | AD22: #N/A | AE22: #N/A | AF22: #N/A | AG22: #N/A | AH22: #N/A | AI22: #N/A | AJ22: #N/A | AK22: #N/A | AL22: #N/A | AM22: #N/A | AN22: #N/A | AO22: #N/A | AP22: #N/A | AQ22: #N/A | AR22: #N/A | AS22: #N/A | AT22: #N/A | AU22: #N/A | AV22: 3.01 | AW22: 2.72 | AX22: 2.65 | AY22: 2.5 | AZ22: 2.63 | BA22: 2.42 | BB22: 2.25 | BC22: 2.16 | BD22: 2.22 | BE22: 2.43 | BF22: 2.16 | BG22: 2.14 | BH22: 1.8 | BI22: 1.39 | BJ22: 1.62 | BK22: 1.83 | BL22: 1.76 | BM22: 2.17 | BN22: 1.75 | BO22: 1.58 | BP22: 1.19 | BQ22: -1.99 | BR22: -21.14 | BS22: -7.69 | BT22: -6.28 | BU22: -4.97 | BV22: 24.49 | BW22: 6.86 | BX22: 6.64 | BY22: 8.74
B23: 44866 | C23: UNGB224@UK | D23: UK: BoE MPC Backcasts of GDP Growth: Real GDP [Q4-22] (SA, Y/Y % Change) | E23: Q1-2015 | F23: Q2-2022 | G23: DISC | H23: Nov-03-2022 12:37 | I23: #N/A | J23: #N/A | K23: #N/A | L23: #N/A | M23: #N/A | N23: #N/A | O23: #N/A | P23: #N/A | Q23: #N/A | R23: #N/A | S23: #N/A | T23: #N/A | U23: #N/A | V23: #N/A | W23: #N/A | X23: #N/A | Y23: #N/A | Z23: #N/A | AA23: #N/A | AB23: #N/A | AC23: #N/A | AD23: #N/A | AE23: #N/A | AF23: #N/A | AG23: #N/A | AH23: #N/A | AI23: #N/A | AJ23: #N/A | AK23: #N/A | AL23: #N/A | AM23: #N/A | AN23: #N/A | AO23: #N/A | AP23: #N/A | AQ23: #N/A | AR23: #N/A | AS23: #N/A | AT23: #N/A | AU23: #N/A | AV23: #N/A | AW23: 2.72 | AX23: 2.48 | AY23: 2.14 | AZ23: 2.23 | BA23: 2.19 | BB23: 2.18 | BC23: 2.19 | BD23: 2.1 | BE23: 2.48 | BF23: 2.39 | BG23: 2.46 | BH23: 2.44 | BI23: 1.84 | BJ23: 1.76 | BK23: 1.8 | BL23: 1.42 | BM23: 1.91 | BN23: 1.56 | BO23: 1.62 | BP23: 1.33 | BQ23: -1.96 | BR23: -22.63 | BS23: -10.32 | BT23: -9.21 | BU23: -7.84 | BV23: 24.27 | BW23: 8.46 | BX23: 8.89 | BY23: 10.94 | BZ23: 4.38
B24: 44958 | C24: UNGB231@UK | D24: UK: BoE MPC Backcasts of GDP Growth: Real GDP [Q1-23] (SA, Y/Y % Change) | E24: Q2-2015 | F24: Q3-2022 | G24: DISC | H24: Feb-02-2023 13:16 | I24: #N/A | J24: #N/A | K24: #N/A | L24: #N/A | M24: #N/A | N24: #N/A | O24: #N/A | P24: #N/A | Q24: #N/A | R24: #N/A | S24: #N/A | T24: #N/A | U24: #N/A | V24: #N/A | W24: #N/A | X24: #N/A | Y24: #N/A | Z24: #N/A | AA24: #N/A | AB24: #N/A | AC24: #N/A | AD24: #N/A | AE24: #N/A | AF24: #N/A | AG24: #N/A | AH24: #N/A | AI24: #N/A | AJ24: #N/A | AK24: #N/A | AL24: #N/A | AM24: #N/A | AN24: #N/A | AO24: #N/A | AP24: #N/A | AQ24: #N/A | AR24: #N/A | AS24: #N/A | AT24: #N/A | AU24: #N/A | AV24: #N/A | AW24: #N/A | AX24: 2.48 | AY24: 2.14 | AZ24: 2.23 | BA24: 2.19 | BB24: 2.18 | BC24: 2.19 | BD24: 2.1 | BE24: 2.48 | BF24: 2.39 | BG24: 2.46 | BH24: 2.44 | BI24: 1.84 | BJ24: 1.76 | BK24: 1.8 | BL24: 1.42 | BM24: 1.91 | BN24: 1.56 | BO24: 1.62 | BP24: 1.33 | BQ24: -1.96 | BR24: -22.63 | BS24: -10.32 | BT24: -9.21 | BU24: -7.73 | BV24: 24.41 | BW24: 8.54 | BX24: 8.87 | BY24: 10.71 | BZ24: 3.99 | CA24: 1.9
B25: 45047 | C25: UNGB232@UK | D25: UK: BoE MPC Backcasts of GDP Growth: Real GDP [Q2-23] (SA, Y/Y % Change) | E25: Q3-2015 | F25: Q4-2022 | G25: DISC | H25: May-11-2023 13:13 | I25: #N/A | J25: #N/A | K25: #N/A | L25: #N/A | M25: #N/A | N25: #N/A | O25: #N/A | P25: #N/A | Q25: #N/A | R25: #N/A | S25: #N/A | T25: #N/A | U25: #N/A | V25: #N/A | W25: #N/A | X25: #N/A | Y25: #N/A | Z25: #N/A | AA25: #N/A | AB25: #N/A | AC25: #N/A | AD25: #N/A | AE25: #N/A | AF25: #N/A | AG25: #N/A | AH25: #N/A | AI25: #N/A | AJ25: #N/A | AK25: #N/A | AL25: #N/A | AM25: #N/A | AN25: #N/A | AO25: #N/A | AP25: #N/A | AQ25: #N/A | AR25: #N/A | AS25: #N/A | AT25: #N/A | AU25: #N/A | AV25: #N/A | AW25: #N/A | AX25: #N/A | AY25: 2.14 | AZ25: 2.23 | BA25: 2.19 | BB25: 2.18 | BC25: 2.19 | BD25: 2.1 | BE25: 2.48 | BF25: 2.39 | BG25: 2.46 | BH25: 2.44 | BI25: 1.84 | BJ25: 1.76 | BK25: 1.8 | BL25: 1.42 | BM25: 1.91 | BN25: 1.56 | BO25: 1.62 | BP25: 1.33 | BQ25: -1.96 | BR25: -22.63 | BS25: -10.32 | BT25: -9.21 | BU25: -7.73 | BV25: 24.41 | BW25: 8.54 | BX25: 8.87 | BY25: 10.56 | BZ25: 3.84 | CA25: 1.98 | CB25: 0.57
B26: 45139 | C26: UNGB233@UK | D26: UK: BoE MPC Backcasts of GDP Growth: Real GDP [Q3-23] (SA, Y/Y % Change) | E26: Q4-2015 | F26: Q1-2023 | G26: DISC | H26: Aug-03-2023 13:21 | I26: #N/A | J26: #N/A | K26: #N/A | L26: #N/A | M26: #N/A | N26: #N/A | O26: #N/A | P26: #N/A | Q26: #N/A | R26: #N/A | S26: #N/A | T26: #N/A | U26: #N/A | V26: #N/A | W26: #N/A | X26: #N/A | Y26: #N/A | Z26: #N/A | AA26: #N/A | AB26: #N/A | AC26: #N/A | AD26: #N/A | AE26: #N/A | AF26: #N/A | AG26: #N/A | AH26: #N/A | AI26: #N/A | AJ26: #N/A | AK26: #N/A | AL26: #N/A | AM26: #N/A | AN26: #N/A | AO26: #N/A | AP26: #N/A | AQ26: #N/A | AR26: #N/A | AS26: #N/A | AT26: #N/A | AU26: #N/A | AV26: #N/A | AW26: #N/A | AX26: #N/A | AY26: #N/A | AZ26: 2.23 | BA26: 2.19 | BB26: 2.18 | BC26: 2.19 | BD26: 2.1 | BE26: 2.48 | BF26: 2.39 | BG26: 2.46 | BH26: 2.44 | BI26: 1.84 | BJ26: 1.76 | BK26: 1.8 | BL26: 1.42 | BM26: 1.91 | BN26: 1.56 | BO26: 1.62 | BP26: 1.33 | BQ26: -1.96 | BR26: -22.63 | BS26: -10.32 | BT26: -9.21 | BU26: -7.73 | BV26: 24.41 | BW26: 8.54 | BX26: 8.87 | BY26: 10.56 | BZ26: 3.84 | CA26: 1.98 | CB26: 0.57 | CC26: 0.23
B27: 45231 | C27: UNGB234@UK | D27: UK: BoE MPC Backcasts of GDP Growth: Real GDP [Q4-23](SA, Y/Y % Change) | E27: Q1-2016 | F27: Q2-2023 | G27: DISC | H27: Nov-02-2023 12:51 | I27: #N/A | J27: #N/A | K27: #N/A | L27: #N/A | M27: #N/A | N27: #N/A | O27: #N/A | P27: #N/A | Q27: #N/A | R27: #N/A | S27: #N/A | T27: #N/A | U27: #N/A | V27: #N/A | W27: #N/A | X27: #N/A | Y27: #N/A | Z27: #N/A | AA27: #N/A | AB27: #N/A | AC27: #N/A | AD27: #N/A | AE27: #N/A | AF27: #N/A | AG27: #N/A | AH27: #N/A | AI27: #N/A | AJ27: #N/A | AK27: #N/A | AL27: #N/A | AM27: #N/A | AN27: #N/A | AO27: #N/A | AP27: #N/A | AQ27: #N/A | AR27: #N/A | AS27: #N/A | AT27: #N/A | AU27: #N/A | AV27: #N/A | AW27: #N/A | AX27: #N/A | AY27: #N/A | AZ27: #N/A | BA27: 1.9 | BB27: 1.9 | BC27: 1.9 | BD27: 1.9 | BE27: 2.4 | BF27: 2.5 | BG27: 2.8 | BH27: 2.9 | BI27: 2.1 | BJ27: 1.6 | BK27: 1.3 | BL27: 0.7 | BM27: 1.4 | BN27: 1.5 | BO27: 1.9 | BP27: 1.8 | BQ27: -1.7 | BR27: -21.9 | BS27: -9.5 | BT27: -8.3 | BU27: -6.7 | BV27: 25.7 | BW27: 9.5 | BX27: 9.7 | BY27: 11.4 | BZ27: 3.9 | CA27: 2.1 | CB27: 0.7 | CC27: 0.5 | CD27: 0.6
B28: 45323 | C28: UNGB241@UK | D28: UK: BoE MPC Backcasts of GDP Growth: Real GDP [Q1-24](SA, Y/Y % Change) | E28: Q2-2016 | F28: Q3-2023 | G28: DISC | H28: Feb-01-2024 12:59 | I28: #N/A | J28: #N/A | K28: #N/A | L28: #N/A | M28: #N/A | N28: #N/A | O28: #N/A | P28: #N/A | Q28: #N/A | R28: #N/A | S28: #N/A | T28: #N/A | U28: #N/A | V28: #N/A | W28: #N/A | X28: #N/A | Y28: #N/A | Z28: #N/A | AA28: #N/A | AB28: #N/A | AC28: #N/A | AD28: #N/A | AE28: #N/A | AF28: #N/A | AG28: #N/A | AH28: #N/A | AI28: #N/A | AJ28: #N/A | AK28: #N/A | AL28: #N/A | AM28: #N/A | AN28: #N/A | AO28: #N/A | AP28: #N/A | AQ28: #N/A | AR28: #N/A | AS28: #N/A | AT28: #N/A | AU28: #N/A | AV28: #N/A | AW28: #N/A | AX28: #N/A | AY28: #N/A | AZ28: #N/A | BA28: #N/A | BB28: 1.9 | BC28: 1.9 | BD28: 1.9 | BE28: 2.4 | BF28: 2.5 | BG28: 2.8 | BH28: 2.9 | BI28: 2.1 | BJ28: 1.6 | BK28: 1.3 | BL28: 0.7 | BM28: 1.4 | BN28: 1.5 | BO28: 1.9 | BP28: 1.8 | BQ28: -1.7 | BR28: -21.9 | BS28: -9.5 | BT28: -8.3 | BU28: -6.7 | BV28: 25.7 | BW28: 9.5 | BX28: 9.7 | BY28: 11.4 | BZ28: 3.9 | CA28: 2.1 | CB28: 0.6 | CC28: 0.4 | CD28: 0.3 | CE28: 0.3
B29: 45413 | C29: UNGB242@UK | D29: UK: BoE MPC Backcasts of GDP Growth: Real GDP [Q2-24] (SA, Y/Y % Change) | E29: Q3-2016 | F29: Q4-2023 | G29: DISC | H29: May-09-2024 12:57 | I29: #N/A | J29: #N/A | K29: #N/A | L29: #N/A | M29: #N/A | N29: #N/A | O29: #N/A | P29: #N/A | Q29: #N/A | R29: #N/A | S29: #N/A | T29: #N/A | U29: #N/A | V29: #N/A | W29: #N/A | X29: #N/A | Y29: #N/A | Z29: #N/A | AA29: #N/A | AB29: #N/A | AC29: #N/A | AD29: #N/A | AE29: #N/A | AF29: #N/A | AG29: #N/A | AH29: #N/A | AI29: #N/A | AJ29: #N/A | AK29: #N/A | AL29: #N/A | AM29: #N/A | AN29: #N/A | AO29: #N/A | AP29: #N/A | AQ29: #N/A | AR29: #N/A | AS29: #N/A | AT29: #N/A | AU29: #N/A | AV29: #N/A | AW29: #N/A | AX29: #N/A | AY29: #N/A | AZ29: #N/A | BA29: #N/A | BB29: #N/A | BC29: 1.9 | BD29: 1.9 | BE29: 2.4 | BF29: 2.5 | BG29: 2.8 | BH29: 2.9 | BI29: 2.1 | BJ29: 1.6 | BK29: 1.3 | BL29: 0.7 | BM29: 1.4 | BN29: 1.5 | BO29: 1.9 | BP29: 1.8 | BQ29: -1.7 | BR29: -21.9 | BS29: -9.5 | BT29: -8.3 | BU29: -6.7 | BV29: 25.7 | BW29: 9.5 | BX29: 9.7 | BY29: 11.4 | BZ29: 3.9 | CA29: 2.1 | CB29: 0.6 | CC29: 0.3 | CD29: 0.2 | CE29: 0.2 | CF29: -0.2
B30: 45505 | D30: UK: BoE MPC Backcasts of GDP Growth: Real GDP (SA, Y/Y % Change) | E30: Q1-2024 | F30: Q4-2023 | G30: BoE | H30: Aug-01-2024 12:57 | I30: #N/A | J30: #N/A | K30: #N/A | L30: #N/A | M30: #N/A | N30: #N/A | O30: #N/A | P30: #N/A | Q30: #N/A | R30: #N/A | S30: #N/A | T30: #N/A | U30: #N/A | V30: #N/A | W30: #N/A | X30: #N/A | Y30: #N/A | Z30: #N/A | AA30: #N/A | AB30: #N/A | AC30: #N/A | AD30: #N/A | AE30: #N/A | AF30: #N/A | AG30: #N/A | AH30: #N/A | AI30: #N/A | AJ30: #N/A | AK30: #N/A | AL30: #N/A | AM30: #N/A | AN30: #N/A | AO30: #N/A | AP30: #N/A | AQ30: #N/A | AR30: #N/A | AS30: #N/A | AT30: #N/A | AU30: #N/A | AV30: #N/A | AW30: #N/A | AX30: #N/A | AY30: #N/A | AZ30: #N/A | BA30: #N/A | BB30: #N/A | BC30: #N/A | BD30: #N/A | BE30: #N/A | BF30: #N/A | BG30: #N/A | BH30: #N/A | BI30: #N/A | BJ30: #N/A | BK30: #N/A | BL30: #N/A | BM30: #N/A | BN30: #N/A | BO30: #N/A | BP30: #N/A | BQ30: #N/A | BR30: #N/A | BS30: #N/A | BT30: #N/A | BU30: #N/A | BV30: #N/A | BW30: #N/A | BX30: #N/A | BY30: #N/A | BZ30: #N/A | CA30: #N/A | CB30: #N/A | CC30: #N/A | CD30: #N/A | CE30: #N/A | CF30: #N/A
B31: 45597 | D31: UK: BoE MPC Backcasts of GDP Growth: Real GDP (SA, Y/Y % Change) | E31: Q1-2024 | F31: Q4-2023 | G31: BoE | H31: Aug-01-2024 12:57 | I31: #N/A | J31: #N/A | K31: #N/A | L31: #N/A | M31: #N/A | N31: #N/A | O31: #N/A | P31: #N/A | Q31: #N/A | R31: #N/A | S31: #N/A | T31: #N/A | U31: #N/A | V31: #N/A | W31: #N/A | X31: #N/A | Y31: #N/A | Z31: #N/A | AA31: #N/A | AB31: #N/A | AC31: #N/A | AD31: #N/A | AE31: #N/A | AF31: #N/A | AG31: #N/A | AH31: #N/A | AI31: #N/A | AJ31: #N/A | AK31: #N/A | AL31: #N/A | AM31: #N/A | AN31: #N/A | AO31: #N/A | AP31: #N/A | AQ31: #N/A | AR31: #N/A | AS31: #N/A | AT31: #N/A | AU31: #N/A | AV31: #N/A | AW31: #N/A | AX31: #N/A | AY31: #N/A | AZ31: #N/A | BA31: #N/A | BB31: #N/A | BC31: #N/A | BD31: #N/A | BE31: #N/A | BF31: #N/A | BG31: #N/A | BH31: #N/A | BI31: #N/A | BJ31: #N/A | BK31: #N/A | BL31: #N/A | BM31: #N/A | BN31: #N/A | BO31: #N/A | BP31: #N/A | BQ31: #N/A | BR31: #N/A | BS31: #N/A | BT31: #N/A | BU31: #N/A | BV31: #N/A | BW31: #N/A | BX31: #N/A | BY31: #N/A | BZ31: #N/A | CA31: #N/A | CB31: #N/A | CC31: #N/A | CD31: #N/A | CE31: #N/A | CF31: #N/A
A32: GDP fcst | B32: 42856 | C32: UNGD172@UK | D32: UK: BoE GDP Proj Based on Expected Interest Rate [Q2-17]: Mode-DISC(Y/Y % Chg) | E32: Q2-2017 | F32: Q2-2020 | G32: DISC | H32: May-11-2017 13:48 | I32: #N/A | J32: #N/A | K32: #N/A | L32: #N/A | M32: #N/A | N32: #N/A | O32: #N/A | P32: #N/A | Q32: #N/A | R32: #N/A | S32: #N/A | T32: #N/A | U32: #N/A | V32: #N/A | W32: #N/A | X32: #N/A | Y32: #N/A | Z32: #N/A | AA32: #N/A | AB32: #N/A | AC32: #N/A | AD32: #N/A | AE32: #N/A | AF32: #N/A | AG32: #N/A | AH32: #N/A | AI32: #N/A | AJ32: #N/A | AK32: #N/A | AL32: #N/A | AM32: #N/A | AN32: #N/A | AO32: #N/A | AP32: #N/A | AQ32: #N/A | AR32: #N/A | AS32: #N/A | AT32: #N/A | AU32: #N/A | AV32: #N/A | AW32: #N/A | AX32: #N/A | AY32: #N/A | AZ32: #N/A | BA32: #N/A | BB32: #N/A | BC32: #N/A | BD32: #N/A | BE32: #N/A | BF32: 2.05 | BG32: 1.9 | BH32: 1.64 | BI32: 1.65 | BJ32: 1.7 | BK32: 1.75 | BL32: 1.79 | BM32: 1.8 | BN32: 1.79 | BO32: 1.79 | BP32: 1.79 | BQ32: 1.78 | BR32: 1.78
B33: 42948 | C33: UNGD173@UK | D33: UK: BoE GDP Proj Based on Expected Interest Rate [Q3-17]: Mode-DISC(Y/Y % Chg) | E33: Q3-2017 | F33: Q3-2020 | G33: DISC | H33: Aug-03-2017 15:42 | I33: #N/A | J33: #N/A | K33: #N/A | L33: #N/A | M33: #N/A | N33: #N/A | O33: #N/A | P33: #N/A | Q33: #N/A | R33: #N/A | S33: #N/A | T33: #N/A | U33: #N/A | V33: #N/A | W33: #N/A | X33: #N/A | Y33: #N/A | Z33: #N/A | AA33: #N/A | AB33: #N/A | AC33: #N/A | AD33: #N/A | AE33: #N/A | AF33: #N/A | AG33: #N/A | AH33: #N/A | AI33: #N/A | AJ33: #N/A | AK33: #N/A | AL33: #N/A | AM33: #N/A | AN33: #N/A | AO33: #N/A | AP33: #N/A | AQ33: #N/A | AR33: #N/A | AS33: #N/A | AT33: #N/A | AU33: #N/A | AV33: #N/A | AW33: #N/A | AX33: #N/A | AY33: #N/A | AZ33: #N/A | BA33: #N/A | BB33: #N/A | BC33: #N/A | BD33: #N/A | BE33: #N/A | BF33: #N/A | BG33: 1.57 | BH33: 1.32 | BI33: 1.39 | BJ33: 1.54 | BK33: 1.69 | BL33: 1.78 | BM33: 1.79 | BN33: 1.77 | BO33: 1.76 | BP33: 1.75 | BQ33: 1.76 | BR33: 1.77 | BS33: 1.79
B34: 43040 | C34: UNGD174@UK | D34: UK: BoE GDP Proj Based on Expected Interest Rate [Q4-17]: Mode(Y/Y % Chg) | E34: Q4-2017 | F34: Q4-2020 | G34: DISC | H34: Nov-02-2017 14:11 | I34: #N/A | J34: #N/A | K34: #N/A | L34: #N/A | M34: #N/A | N34: #N/A | O34: #N/A | P34: #N/A | Q34: #N/A | R34: #N/A | S34: #N/A | T34: #N/A | U34: #N/A | V34: #N/A | W34: #N/A | X34: #N/A | Y34: #N/A | Z34: #N/A | AA34: #N/A | AB34: #N/A | AC34: #N/A | AD34: #N/A | AE34: #N/A | AF34: #N/A | AG34: #N/A | AH34: #N/A | AI34: #N/A | AJ34: #N/A | AK34: #N/A | AL34: #N/A | AM34: #N/A | AN34: #N/A | AO34: #N/A | AP34: #N/A | AQ34: #N/A | AR34: #N/A | AS34: #N/A | AT34: #N/A | AU34: #N/A | AV34: #N/A | AW34: #N/A | AX34: #N/A | AY34: #N/A | AZ34: #N/A | BA34: #N/A | BB34: #N/A | BC34: #N/A | BD34: #N/A | BE34: #N/A | BF34: #N/A | BG34: #N/A | BH34: 1.46 | BI34: 1.51 | BJ34: 1.65 | BK34: 1.68 | BL34: 1.71 | BM34: 1.72 | BN34: 1.71 | BO34: 1.69 | BP34: 1.67 | BQ34: 1.67 | BR34: 1.69 | BS34: 1.72 | BT34: 1.75
B35: 43132 | C35: UNGD181@UK | D35: UK: BoE GDP Proj Based on Expected Interest Rate [Q1-18]: Mode(Y/Y % Chg) | E35: Q1-2018 | F35: Q1-2021 | G35: DISC | H35: Feb-08-2018 15:57 | I35: #N/A | J35: #N/A | K35: #N/A | L35: #N/A | M35: #N/A | N35: #N/A | O35: #N/A | P35: #N/A | Q35: #N/A | R35: #N/A | S35: #N/A | T35: #N/A | U35: #N/A | V35: #N/A | W35: #N/A | X35: #N/A | Y35: #N/A | Z35: #N/A | AA35: #N/A | AB35: #N/A | AC35: #N/A | AD35: #N/A | AE35: #N/A | AF35: #N/A | AG35: #N/A | AH35: #N/A | AI35: #N/A | AJ35: #N/A | AK35: #N/A | AL35: #N/A | AM35: #N/A | AN35: #N/A | AO35: #N/A | AP35: #N/A | AQ35: #N/A | AR35: #N/A | AS35: #N/A | AT35: #N/A | AU35: #N/A | AV35: #N/A | AW35: #N/A | AX35: #N/A | AY35: #N/A | AZ35: #N/A | BA35: #N/A | BB35: #N/A | BC35: #N/A | BD35: #N/A | BE35: #N/A | BF35: #N/A | BG35: #N/A | BH35: #N/A | BI35: 1.65 | BJ35: 1.8 | BK35: 1.86 | BL35: 1.79 | BM35: 1.77 | BN35: 1.73 | BO35: 1.69 | BP35: 1.67 | BQ35: 1.66 | BR35: 1.66 | BS35: 1.67 | BT35: 1.67 | BU35: 1.68
B36: 43221 | C36: UNGD182@UK | D36: UK: BoE GDP Proj Based on Expected Interest Rate [Q2-18]: Mode(Y/Y % Chg) | E36: Q2-2018 | F36: Q2-2021 | G36: DISC | H36: May-10-2018 15:03 | I36: #N/A | J36: #N/A | K36: #N/A | L36: #N/A | M36: #N/A | N36: #N/A | O36: #N/A | P36: #N/A | Q36: #N/A | R36: #N/A | S36: #N/A | T36: #N/A | U36: #N/A | V36: #N/A | W36: #N/A | X36: #N/A | Y36: #N/A | Z36: #N/A | AA36: #N/A | AB36: #N/A | AC36: #N/A | AD36: #N/A | AE36: #N/A | AF36: #N/A | AG36: #N/A | AH36: #N/A | AI36: #N/A | AJ36: #N/A | AK36: #N/A | AL36: #N/A | AM36: #N/A | AN36: #N/A | AO36: #N/A | AP36: #N/A | AQ36: #N/A | AR36: #N/A | AS36: #N/A | AT36: #N/A | AU36: #N/A | AV36: #N/A | AW36: #N/A | AX36: #N/A | AY36: #N/A | AZ36: #N/A | BA36: #N/A | BB36: #N/A | BC36: #N/A | BD36: #N/A | BE36: #N/A | BF36: #N/A | BG36: #N/A | BH36: #N/A | BI36: #N/A | BJ36: 1.41 | BK36: 1.39 | BL36: 1.44 | BM36: 1.77 | BN36: 1.74 | BO36: 1.71 | BP36: 1.7 | BQ36: 1.71 | BR36: 1.72 | BS36: 1.71 | BT36: 1.7 | BU36: 1.71 | BV36: 1.72
B37: 43313 | C37: UNGD183@UK | D37: UK: BoE GDP Proj Based on Expected Interest Rate [Q3-18]: Mode(Y/Y % Chg) | E37: Q3-2018 | F37: Q3-2021 | G37: DISC | H37: Aug-02-2018 14:57 | I37: #N/A | J37: #N/A | K37: #N/A | L37: #N/A | M37: #N/A | N37: #N/A | O37: #N/A | P37: #N/A | Q37: #N/A | R37: #N/A | S37: #N/A | T37: #N/A | U37: #N/A | V37: #N/A | W37: #N/A | X37: #N/A | Y37: #N/A | Z37: #N/A | AA37: #N/A | AB37: #N/A | AC37: #N/A | AD37: #N/A | AE37: #N/A | AF37: #N/A | AG37: #N/A | AH37: #N/A | AI37: #N/A | AJ37: #N/A | AK37: #N/A | AL37: #N/A | AM37: #N/A | AN37: #N/A | AO37: #N/A | AP37: #N/A | AQ37: #N/A | AR37: #N/A | AS37: #N/A | AT37: #N/A | AU37: #N/A | AV37: #N/A | AW37: #N/A | AX37: #N/A | AY37: #N/A | AZ37: #N/A | BA37: #N/A | BB37: #N/A | BC37: #N/A | BD37: #N/A | BE37: #N/A | BF37: #N/A | BG37: #N/A | BH37: #N/A | BI37: #N/A | BJ37: #N/A | BK37: 1.46 | BL37: 1.54 | BM37: 1.75 | BN37: 1.78 | BO37: 1.77 | BP37: 1.77 | BQ37: 1.75 | BR37: 1.72 | BS37: 1.7 | BT37: 1.68 | BU37: 1.67 | BV37: 1.67 | BW37: 1.68
B38: 43405 | C38: UNGD184@UK | D38: UK: BoE GDP Projections Based on Expected Int Rate [Q4-18]: Mode (Y/Y % Chg) | E38: Q4-2018 | F38: Q4-2021 | G38: DISC | H38: Nov-01-2018 15:04 | I38: #N/A | J38: #N/A | K38: #N/A | L38: #N/A | M38: #N/A | N38: #N/A | O38: #N/A | P38: #N/A | Q38: #N/A | R38: #N/A | S38: #N/A | T38: #N/A | U38: #N/A | V38: #N/A | W38: #N/A | X38: #N/A | Y38: #N/A | Z38: #N/A | AA38: #N/A | AB38: #N/A | AC38: #N/A | AD38: #N/A | AE38: #N/A | AF38: #N/A | AG38: #N/A | AH38: #N/A | AI38: #N/A | AJ38: #N/A | AK38: #N/A | AL38: #N/A | AM38: #N/A | AN38: #N/A | AO38: #N/A | AP38: #N/A | AQ38: #N/A | AR38: #N/A | AS38: #N/A | AT38: #N/A | AU38: #N/A | AV38: #N/A | AW38: #N/A | AX38: #N/A | AY38: #N/A | AZ38: #N/A | BA38: #N/A | BB38: #N/A | BC38: #N/A | BD38: #N/A | BE38: #N/A | BF38: #N/A | BG38: #N/A | BH38: #N/A | BI38: #N/A | BJ38: #N/A | BK38: #N/A | BL38: 1.47 | BM38: 1.8 | BN38: 1.83 | BO38: 1.63 | BP38: 1.72 | BQ38: 1.72 | BR38: 1.72 | BS38: 1.71 | BT38: 1.7 | BU38: 1.7 | BV38: 1.71 | BW38: 1.7 | BX38: 1.7
B39: 43497 | C39: UNGD191@UK | D39: UK: BoE GDP Projects Bsd on Expected Interest Rate[Q1-19]: Mode(Y/Y % Chg) | E39: Q1-2019 | F39: Q1-2022 | G39: DISC | H39: Feb-07-2019 12:39 | I39: #N/A | J39: #N/A | K39: #N/A | L39: #N/A | M39: #N/A | N39: #N/A | O39: #N/A | P39: #N/A | Q39: #N/A | R39: #N/A | S39: #N/A | T39: #N/A | U39: #N/A | V39: #N/A | W39: #N/A | X39: #N/A | Y39: #N/A | Z39: #N/A | AA39: #N/A | AB39: #N/A | AC39: #N/A | AD39: #N/A | AE39: #N/A | AF39: #N/A | AG39: #N/A | AH39: #N/A | AI39: #N/A | AJ39: #N/A | AK39: #N/A | AL39: #N/A | AM39: #N/A | AN39: #N/A | AO39: #N/A | AP39: #N/A | AQ39: #N/A | AR39: #N/A | AS39: #N/A | AT39: #N/A | AU39: #N/A | AV39: #N/A | AW39: #N/A | AX39: #N/A | AY39: #N/A | AZ39: #N/A | BA39: #N/A | BB39: #N/A | BC39: #N/A | BD39: #N/A | BE39: #N/A | BF39: #N/A | BG39: #N/A | BH39: #N/A | BI39: #N/A | BJ39: #N/A | BK39: #N/A | BL39: #N/A | BM39: 1.49 | BN39: 1.3 | BO39: 0.99 | BP39: 1.1 | BQ39: 1.28 | BR39: 1.46 | BS39: 1.58 | BT39: 1.66 | BU39: 1.74 | BV39: 1.83 | BW39: 1.92 | BX39: 1.99 | BY39: 2.05
B40: 43586 | C40: UNGD192@UK | D40: UK: BoE GDP Projections Based on Expected Interest Rate: Mode [Q2-19](Y/Y % Chg) | E40: Q2-2019 | F40: Q2-2022 | G40: DISC | H40: May-02-2019 12:20 | I40: #N/A | J40: #N/A | K40: #N/A | L40: #N/A | M40: #N/A | N40: #N/A | O40: #N/A | P40: #N/A | Q40: #N/A | R40: #N/A | S40: #N/A | T40: #N/A | U40: #N/A | V40: #N/A | W40: #N/A | X40: #N/A | Y40: #N/A | Z40: #N/A | AA40: #N/A | AB40: #N/A | AC40: #N/A | AD40: #N/A | AE40: #N/A | AF40: #N/A | AG40: #N/A | AH40: #N/A | AI40: #N/A | AJ40: #N/A | AK40: #N/A | AL40: #N/A | AM40: #N/A | AN40: #N/A | AO40: #N/A | AP40: #N/A | AQ40: #N/A | AR40: #N/A | AS40: #N/A | AT40: #N/A | AU40: #N/A | AV40: #N/A | AW40: #N/A | AX40: #N/A | AY40: #N/A | AZ40: #N/A | BA40: #N/A | BB40: #N/A | BC40: #N/A | BD40: #N/A | BE40: #N/A | BF40: #N/A | BG40: #N/A | BH40: #N/A | BI40: #N/A | BJ40: #N/A | BK40: #N/A | BL40: #N/A | BM40: #N/A | BN40: 1.59 | BO40: 1.17 | BP40: 1.29 | BQ40: 1.23 | BR40: 1.48 | BS40: 1.7 | BT40: 1.87 | BU40: 1.99 | BV40: 2.08 | BW40: 2.14 | BX40: 2.18 | BY40: 2.2 | BZ40: 2.21
...

Sheet HAVERW
A1: 20200101W !W | B1: M112B9R9@INTWKLY | C1: M112B9T9@INTWKLY | D1: M112ZJ5J@INTWKLY | E1: M112B9T8@INTWKLY
A2: .DESC | B2: UK: Central Bank Reserves Supplied via Asset Purchase Facility(EOP,NSA, Mil.GBP) | C2: UK: Asset Purchase Facility: Gilt Holdings(EOP, NSA, Mil.GBP) | D2: UK: Asset Purchase Facility: Weekly Holdings of Corporate Bonds (EOP, Mil.GBP) | E2: UK: Asset Purchase Facility: Weekly Purchases of Gilts(NSA, Mil.GBP)
A3: .T1 | B3: 11-Mar-2009W | C3: 11-Mar-2009W | D3: 05-Oct-2016W | E3: 11-Mar-2009W
A4: .TN | B4: 29-Jan-2025W | C4: 29-Jan-2025W | D4: 29-Jan-2025W | E4: 29-Jan-2025W
A5: .LSOURCE | B5: Bank of England | C5: Bank of England | D5: Bank of England | E5: Bank of England
A6: .DTLM | B6: Jan-31-2025 10:01 | C6: Jan-31-2025 10:01 | D6: Jan-31-2025 10:01 | E6: Jan-31-2025 10:01
A7: 20200101W | B7: 444810 | C7: 434990 | D7: 9820 | E7: 0
A8: 20200108W | B8: 444810 | C8: 434990 | D8: 9820 | E8: 0
A9: 20200115W | B9: 444810 | C9: 434990 | D9: 9820 | E9: 0
A10: 20200122W | B10: 444810 | C10: 434990 | D10: 9820 | E10: 0
A11: 20200129W | B11: 444810 | C11: 434990 | D11: 9820 | E11: 0
A12: 20200205W | B12: 444810 | C12: 434990 | D12: 9820 | E12: 0
A13: 20200212W | B13: 444810 | C13: 434990 | D13: 9820 | E13: 0
A14: 20200219W | B14: 444810 | C14: 434990 | D14: 9820 | E14: 0
A15: 20200226W | B15: 444810 | C15: 434990 | D15: 9820 | E15: 0
A16: 20200304W | B16: 444810 | C16: 434990 | D16: 9820 | E16: 0
A17: 20200311W | B17: 444810 | C17: 420432 | D17: 9820 | E17: 0
A18: 20200318W | B18: 444810 | C18: 423344 | D18: 9820 | E18: 2912
... A272: 20250129W | B272: 651734 | C272: 651734 | D272: 0 | E272: 0

Sheet OE_FCST
A1: Location | B1: Indicator | C1: Scenario | D1: Units | E1: Scale | F1: Measurement | G1: 1973 Q1 | H1: 1973 Q2 | I1: 1973 Q3 | J1: 1973 Q4 | K1: 1974 Q1 | L1: 1974 Q2 | M1: 1974 Q3 | N1: 1974 Q4 | O1: 1975 Q1 | P1: 1975 Q2 | Q1: 1975 Q3 | R1: 1975 Q4 | S1: 1976 Q1 | T1: 1976 Q2 | U1: 1976 Q3 | V1: 1976 Q4 | W1: 1977 Q1 | X1: 1977 Q2 | Y1: 1977 Q3 | Z1: 1977 Q4 | AA1: 1978 Q1 | AB1: 1978 Q2 | AC1: 1978 Q3 | AD1: 1978 Q4 | AE1: 1979 Q1 | AF1: 1979 Q2 | AG1: 1979 Q3 | AH1: 1979 Q4 | AI1: 1980 Q1 | AJ1: 1980 Q2 | AK1: 1980 Q3 | AL1: 1980 Q4 | AM1: 1981 Q1 | AN1: 1981 Q2 | AO1: 1981 Q3 | AP1: 1981 Q4 | AQ1: 1982 Q1 | AR1: 1982 Q2 | AS1: 1982 Q3 | AT1: 1982 Q4 | AU1: 1983 Q1 | AV1: 1983 Q2 | AW1: 1983 Q3 | AX1: 1983 Q4 | AY1: 1984 Q1 | AZ1: 1984 Q2 | BA1: 1984 Q3 | BB1: 1984 Q4 | BC1: 1985 Q1 | BD1: 1985 Q2 | BE1: 1985 Q3 | BF1: 1985 Q4 | BG1: 1986 Q1 | BH1: 1986 Q2 | BI1: 1986 Q3 | BJ1: 1986 Q4 | BK1: 1987 Q1 | BL1: 1987 Q2 | BM1: 1987 Q3 | BN1: 1987 Q4 | BO1: 1988 Q1 | BP1: 1988 Q2 | BQ1: 1988 Q3 | BR1: 1988 Q4 | BS1: 1989 Q1 | BT1: 1989 Q2 | BU1: 1989 Q3 | BV1: 1989 Q4 | BW1: 1990 Q1 | BX1: 1990 Q2 | BY1: 1990 Q3 | BZ1: 1990 Q4 | CA1: 1991 Q1 | CB1: 1991 Q2 | CC1: 1991 Q3 | CD1: 1991 Q4 | CE1: 1992 Q1 | CF1: 1992 Q2 | CG1: 1992 Q3 | CH1: 1992 Q4 | CI1: 1993 Q1 | CJ1: 1993 Q2 | CK1: 1993 Q3 | CL1: 1993 Q4 | CM1: 1994 Q1 | CN1: 1994 Q2 | CO1: 1994 Q3 | CP1: 1994 Q4 | CQ1: 1995 Q1 | CR1: 1995 Q2 | CS1: 1995 Q3 | CT1: 1995 Q4 | CU1: 1996 Q1 | CV1: 1996 Q2 | CW1: 1996 Q3 | CX1: 1996 Q4 | CY1: 1997 Q1 | CZ1: 1997 Q2 | DA1: 1997 Q3 | DB1: 1997 Q4 | DC1: 1998 Q1 | DD1: 1998 Q2 | DE1: 1998 Q3 | DF1: 1998 Q4 | DG1: 1999 Q1 | DH1: 1999 Q2 | DI1: 1999 Q3 | DJ1: 1999 Q4 | DK1: 2000 Q1 | DL1: 2000 Q2 | DM1: 2000 Q3 | DN1: 2000 Q4 | DO1: 2001 Q1 | DP1: 2001 Q2 | DQ1: 2001 Q3 | DR1: 2001 Q4 | DS1: 2002 Q1 | DT1: 2002 Q2 | DU1: 2002 Q3 | DV1: 2002 Q4 | DW1: 2003 Q1 | DX1: 2003 Q2 | DY1: 2003 Q3 | DZ1: 2003 Q4 | EA1: 2004 Q1 | EB1: 2004 Q2 | EC1: 2004 Q3 | ED1: 2004 Q4 | EE1: 2005 Q1 | EF1: 2005 Q2 | EG1: 2005 Q3 | EH1: 2005 Q4 | EI1: 2006 Q1 | EJ1: 2006 Q2 | EK1: 2006 Q3 | EL1: 2006 Q4 | EM1: 2007 Q1 | EN1: 2007 Q2 | EO1: 2007 Q3 | EP1: 2007 Q4 | EQ1: 2008 Q1 | ER1: 2008 Q2 | ES1: 2008 Q3 | ET1: 2008 Q4 | EU1: 2009 Q1 | EV1: 2009 Q2 | EW1: 2009 Q3 | EX1: 2009 Q4 | EY1: 2010 Q1 | EZ1: 2010 Q2 | FA1: 2010 Q3 | FB1: 2010 Q4 | FC1: 2011 Q1 | FD1: 2011 Q2 | FE1: 2011 Q3 | FF1: 2011 Q4 | FG1: 2012 Q1 | FH1: 2012 Q2 | FI1: 2012 Q3 | FJ1: 2012 Q4 | FK1: 2013 Q1 | FL1: 2013 Q2 | FM1: 2013 Q3 | FN1: 2013 Q4 | FO1: 2014 Q1 | FP1: 2014 Q2 | FQ1: 2014 Q3 | FR1: 2014 Q4 | FS1: 2015 Q1 | FT1: 2015 Q2 | FU1: 2015 Q3 | FV1: 2015 Q4 | FW1: 2016 Q1 | FX1: 2016 Q2 | FY1: 2016 Q3 | FZ1: 2016 Q4 | GA1: 2017 Q1 | GB1: 2017 Q2 | GC1: 2017 Q3 | GD1: 2017 Q4 | GE1: 2018 Q1 | GF1: 2018 Q2 | GG1: 2018 Q3 | GH1: 2018 Q4 | GI1: 2019 Q1 | GJ1: 2019 Q2 | GK1: 2019 Q3 | GL1: 2019 Q4 | GM1: 2020 Q1 | GN1: 2020 Q2 | GO1: 2020 Q3 | GP1: 2020 Q4 | GQ1: 2021 Q1 | GR1: 2021 Q2 | GS1: 2021 Q3 | GT1: 2021 Q4 | GU1: 2022 Q1 | GV1: 2022 Q2 | GW1: 2022 Q3 | GX1: 2022 Q4 | GY1: 2023 Q1 | GZ1: 2023 Q2 | HA1: 2023 Q3 | HB1: 2023 Q4 | HC1: 2024 Q1 | HD1: 2024 Q2 | HE1: 2024 Q3 | HF1: 2024 Q4 | HG1: 2025 Q1 | HH1: 2025 Q2 | HI1: 2025 Q3 | HJ1: 2025 Q4 | HK1: 2026 Q1 | HL1: 2026 Q2 | HM1: 2026 Q3 | HN1: 2026 Q4 | HO1: 2027 Q1 | HP1: 2027 Q2 | HQ1: 2027 Q3 | HR1: 2027 Q4 | HS1: 2028 Q1 | HT1: 2028 Q2 | HU1: 2028 Q3 | HV1: 2028 Q4 | HW1: 2029 Q1 | HX1: 2029 Q2 | HY1: 2029 Q3 | HZ1: 2029 Q4 | IA1: 2030 Q1 | IB1: 2030 Q2 | IC1: 2030 Q3 | ID1: 2030 Q4 | IE1: 2031 Q1 | IF1: 2031 Q2 | IG1: 2031 Q3 | IH1: 2031 Q4 | II1: 2032 Q1 | IJ1: 2032 Q2 | IK1: 2032 Q3 | IL1: 2032 Q4 | IM1: 2033 Q1 | IN1: 2033 Q2 | IO1: 2033 Q3 | IP1: 2033 Q4 | IQ1: 2034 Q1 | IR1: 2034 Q2 | IS1: 2034 Q3 | IT1: 2034 Q4 | IU1: 2035 Q1 | IV1: 2035 Q2 | IW1: 2035 Q3 | IX1: 2035 Q4 | IY1: 2036 Q1 | IZ1: 2036 Q2 | JA1: 2036 Q3 | JB1: 2036 Q4 | JC1: 2037 Q1 | JD1: 2037 Q2 | JE1: 2037 Q3 | JF1: 2037 Q4 | JG1: 2038 Q1 | JH1: 2038 Q2 | JI1: 2038 Q3 | JJ1: 2038 Q4 | JK1: 2039 Q1 | JL1: 2039 Q2 | JM1: 2039 Q3 | JN1: 2039 Q4 | JO1: 2040 Q1 | JP1: 2040 Q2 | JQ1: 2040 Q3 | JR1: 2040 Q4 | JS1: 2041 Q1 | JT1: 2041 Q2 | JU1: 2041 Q3 | JV1: 2041 Q4 | JW1: 2042 Q1 | JX1: 2042 Q2 | JY1: 2042 Q3 | JZ1: 2042 Q4 | KA1: 2043 Q1 | KB1: 2043 Q2 | KC1: 2043 Q3 | KD1: 2043 Q4 | KE1: 2044 Q1 | KF1: 2044 Q2 | KG1: 2044 Q3 | KH1: 2044 Q4 | KI1: 2045 Q1 | KJ1: 2045 Q2 | KK1: 2045 Q3 | KL1: 2045 Q4 | KM1: 2046 Q1 | KN1: 2046 Q2 | KO1: 2046 Q3 | KP1: 2046 Q4 | KQ1: 2047 Q1 | KR1: 2047 Q2 | KS1: 2047 Q3 | KT1: 2047 Q4 | KU1: 2048 Q1 | KV1: 2048 Q2 | KW1: 2048 Q3 | KX1: 2048 Q4 | KY1: 2049 Q1 | KZ1: 2049 Q2 | LA1: 2049 Q3 | LB1: 2049 Q4 | LC1: 2050 Q1 | LD1: 2050 Q2 | LE1: 2050 Q3 | LF1: 2050 Q4 | LG1: Source | LH1: Seasonally adjusted | LI1: Base year price | LJ1: Base year index | LK1: Historical end year | LL1: Historical end quarter | LM1: Date of last update | LN1: Source details | LO1: Additional source details | LP1: Location code | LQ1: Indicator code | LR1: Databank code
