Workbook
Name _DLX1.INC: OBR!#REF!
Name _DLX2.INC: HAVERM!$A$4:$G$8
Name Data: [1]sheet0!$C$2

Sheet Data--->

Sheet GMW
A1: Location | B1: Indicator | C1: Scenario | D1: Units | E1: Scale | F1: Measurement | G1: 1973 Q1 | H1: 1973 Q2 | I1: 1973 Q3 | J1: 1973 Q4 | K1: 1974 Q1 | L1: 1974 Q2 | M1: 1974 Q3 | N1: 1974 Q4 | O1: 1975 Q1 | P1: 1975 Q2 | Q1: 1975 Q3 | R1: 1975 Q4 | S1: 1976 Q1 | T1: 1976 Q2 | U1: 1976 Q3 | V1: 1976 Q4 | W1: 1977 Q1 | X1: 1977 Q2 | Y1: 1977 Q3 | Z1: 1977 Q4 | AA1: 1978 Q1 | AB1: 1978 Q2 | AC1: 1978 Q3 | AD1: 1978 Q4 | AE1: 1979 Q1 | AF1: 1979 Q2 | AG1: 1979 Q3 | AH1: 1979 Q4 | AI1: 1980 Q1 | AJ1: 1980 Q2 | AK1: 1980 Q3 | AL1: 1980 Q4 | AM1: 1981 Q1 | AN1: 1981 Q2 | AO1: 1981 Q3 | AP1: 1981 Q4 | AQ1: 1982 Q1 | AR1: 1982 Q2 | AS1: 1982 Q3 | AT1: 1982 Q4 | AU1: 1983 Q1 | AV1: 1983 Q2 | AW1: 1983 Q3 | AX1: 1983 Q4 | AY1: 1984 Q1 | AZ1: 1984 Q2 | BA1: 1984 Q3 | BB1: 1984 Q4 | BC1: 1985 Q1 | BD1: 1985 Q2 | BE1: 1985 Q3 | BF1: 1985 Q4 | BG1: 1986 Q1 | BH1: 1986 Q2 | BI1: 1986 Q3 | BJ1: 1986 Q4 | BK1: 1987 Q1 | BL1: 1987 Q2 | BM1: 1987 Q3 | BN1: 1987 Q4 | BO1: 1988 Q1 | BP1: 1988 Q2 | BQ1: 1988 Q3 | BR1: 1988 Q4 | BS1: 1989 Q1 | BT1: 1989 Q2 | BU1: 1989 Q3 | BV1: 1989 Q4 | BW1: 1990 Q1 | BX1: 1990 Q2 | BY1: 1990 Q3 | BZ1: 1990 Q4 | CA1: 1991 Q1 | CB1: 1991 Q2 | CC1: 1991 Q3 | CD1: 1991 Q4 | CE1: 1992 Q1 | CF1: 1992 Q2 | CG1: 1992 Q3 | CH1: 1992 Q4 | CI1: 1993 Q1 | CJ1: 1993 Q2 | CK1: 1993 Q3 | CL1: 1993 Q4 | CM1: 1994 Q1 | CN1: 1994 Q2 | CO1: 1994 Q3 | CP1: 1994 Q4 | CQ1: 1995 Q1 | CR1: 1995 Q2 | CS1: 1995 Q3 | CT1: 1995 Q4 | CU1: 1996 Q1 | CV1: 1996 Q2 | CW1: 1996 Q3 | CX1: 1996 Q4 | CY1: 1997 Q1 | CZ1: 1997 Q2 | DA1: 1997 Q3 | DB1: 1997 Q4 | DC1: 1998 Q1 | DD1: 1998 Q2 | DE1: 1998 Q3 | DF1: 1998 Q4 | DG1: 1999 Q1 | DH1: 1999 Q2 | DI1: 1999 Q3 | DJ1: 1999 Q4 | DK1: 2000 Q1 | DL1: 2000 Q2 | DM1: 2000 Q3 | DN1: 2000 Q4 | DO1: 2001 Q1 | DP1: 2001 Q2 | DQ1: 2001 Q3 | DR1: 2001 Q4 | DS1: 2002 Q1 | DT1: 2002 Q2 | DU1: 2002 Q3 | DV1: 2002 Q4 | DW1: 2003 Q1 | DX1: 2003 Q2 | DY1: 2003 Q3 | DZ1: 2003 Q4 | EA1: 2004 Q1 | EB1: 2004 Q2 | EC1: 2004 Q3 | ED1: 2004 Q4 | EE1: 2005 Q1 | EF1: 2005 Q2 | EG1: 2005 Q3 | EH1: 2005 Q4 | EI1: 2006 Q1 | EJ1: 2006 Q2 | EK1: 2006 Q3 | EL1: 2006 Q4 | EM1: 2007 Q1 | EN1: 2007 Q2 | EO1: 2007 Q3 | EP1: 2007 Q4 | EQ1: 2008 Q1 | ER1: 2008 Q2 | ES1: 2008 Q3 | ET1: 2008 Q4 | EU1: 2009 Q1 | EV1: 2009 Q2 | EW1: 2009 Q3 | EX1: 2009 Q4 | EY1: 2010 Q1 | EZ1: 2010 Q2 | FA1: 2010 Q3 | FB1: 2010 Q4 | FC1: 2011 Q1 | FD1: 2011 Q2 | FE1: 2011 Q3 | FF1: 2011 Q4 | FG1: 2012 Q1 | FH1: 2012 Q2 | FI1: 2012 Q3 | FJ1: 2012 Q4 | FK1: 2013 Q1 | FL1: 2013 Q2 | FM1: 2013 Q3 | FN1: 2013 Q4 | FO1: 2014 Q1 | FP1: 2014 Q2 | FQ1: 2014 Q3 | FR1: 2014 Q4 | FS1: 2015 Q1 | FT1: 2015 Q2 | FU1: 2015 Q3 | FV1: 2015 Q4 | FW1: 2016 Q1 | FX1: 2016 Q2 | FY1: 2016 Q3 | FZ1: 2016 Q4 | GA1: 2017 Q1 | GB1: 2017 Q2 | GC1: 2017 Q3 | GD1: 2017 Q4 | GE1: 2018 Q1 | GF1: 2018 Q2 | GG1: 2018 Q3 | GH1: 2018 Q4 | GI1: 2019 Q1 | GJ1: 2019 Q2 | GK1: 2019 Q3 | GL1: 2019 Q4 | GM1: 2020 Q1 | GN1: 2020 Q2 | GO1: 2020 Q3 | GP1: 2020 Q4 | GQ1: 2021 Q1 | GR1: 2021 Q2 | GS1: 2021 Q3 | GT1: 2021 Q4 | GU1: 2022 Q1 | GV1: 2022 Q2 | GW1: 2022 Q3 | GX1: 2022 Q4 | GY1: 2023 Q1 | GZ1: 2023 Q2 | HA1: 2023 Q3 | HB1: 2023 Q4 | HC1: 2024 Q1 | HD1: 2024 Q2 | HE1: 2024 Q3 | HF1: 2024 Q4 | HG1: 2025 Q1 | HH1: 2025 Q2 | HI1: 2025 Q3 | HJ1: 2025 Q4 | HK1: 2026 Q1 | HL1: 2026 Q2 | HM1: 2026 Q3 | HN1: 2026 Q4 | HO1: 2027 Q1 | HP1: 2027 Q2 | HQ1: 2027 Q3 | HR1: 2027 Q4 | HS1: 2028 Q1 | HT1: 2028 Q2 | HU1: 2028 Q3 | HV1: 2028 Q4 | HW1: 2029 Q1 | HX1: 2029 Q2 | HY1: 2029 Q3 | HZ1: 2029 Q4 | IA1: 2030 Q1 | IB1: 2030 Q2 | IC1: 2030 Q3 | ID1: 2030 Q4 | IE1: 2031 Q1 | IF1: 2031 Q2 | IG1: 2031 Q3 | IH1: 2031 Q4 | II1: 2032 Q1 | IJ1: 2032 Q2 | IK1: 2032 Q3 | IL1: 2032 Q4 | IM1: 2033 Q1 | IN1: 2033 Q2 | IO1: 2033 Q3 | IP1: 2033 Q4 | IQ1: 2034 Q1 | IR1: 2034 Q2 | IS1: 2034 Q3 | IT1: 2034 Q4 | IU1: 2035 Q1 | IV1: 2035 Q2 | IW1: 2035 Q3 | IX1: 2035 Q4 | IY1: 2036 Q1 | IZ1: 2036 Q2 | JA1: 2036 Q3 | JB1: 2036 Q4 | JC1: 2037 Q1 | JD1: 2037 Q2 | JE1: 2037 Q3 | JF1: 2037 Q4 | JG1: 2038 Q1 | JH1: 2038 Q2 | JI1: 2038 Q3 | JJ1: 2038 Q4 | JK1: 2039 Q1 | JL1: 2039 Q2 | JM1: 2039 Q3 | JN1: 2039 Q4 | JO1: 2040 Q1 | JP1: 2040 Q2 | JQ1: 2040 Q3 | JR1: 2040 Q4 | JS1: 2041 Q1 | JT1: 2041 Q2 | JU1: 2041 Q3 | JV1: 2041 Q4 | JW1: 2042 Q1 | JX1: 2042 Q2 | JY1: 2042 Q3 | JZ1: 2042 Q4 | KA1: 2043 Q1 | KB1: 2043 Q2 | KC1: 2043 Q3 | KD1: 2043 Q4 | KE1: 2044 Q1 | KF1: 2044 Q2 | KG1: 2044 Q3 | KH1: 2044 Q4 | KI1: 2045 Q1 | KJ1: 2045 Q2 | KK1: 2045 Q3 | KL1: 2045 Q4 | KM1: 2046 Q1 | KN1: 2046 Q2 | KO1: 2046 Q3 | KP1: 2046 Q4 | KQ1: 2047 Q1 | KR1: 2047 Q2 | KS1: 2047 Q3 | KT1: 2047 Q4 | KU1: 2048 Q1 | KV1: 2048 Q2 | KW1: 2048 Q3 | KX1: 2048 Q4 | KY1: 2049 Q1 | KZ1: 2049 Q2 | LA1: 2049 Q3 | LB1: 2049 Q4 | LC1: 2050 Q1 | LD1: 2050 Q2 | LE1: 2050 Q3 | LF1: 2050 Q4 | LG1: 2051 Q1 | LH1: 2051 Q2 | LI1: 2051 Q3 | LJ1: 2051 Q4 | LK1: 2052 Q1 | LL1: 2052 Q2 | LM1: 2052 Q3 | LN1: 2052 Q4 | LO1: 2053 Q1 | LP1: 2053 Q2 | LQ1: 2053 Q3 | LR1: 2053 Q4 | LS1: 2054 Q1 | LT1: 2054 Q2 | LU1: 2054 Q3 | LV1: 2054 Q4 | LW1: 2055 Q1 | LX1: 2055 Q2 | LY1: 2055 Q3 | LZ1: 2055 Q4 | MA1: 2056 Q1 | MB1: 2056 Q2 | MC1: 2056 Q3 | MD1: 2056 Q4 | ME1: 2057 Q1 | MF1: 2057 Q2 | MG1: 2057 Q3 | MH1: 2057 Q4 | MI1: 2058 Q1 | MJ1: 2058 Q2 | MK1: 2058 Q3 | ML1: 2058 Q4 | MM1: 2059 Q1 | MN1: 2059 Q2 | MO1: 2059 Q3 | MP1: 2059 Q4 | MQ1: 2060 Q1 | MR1: 2060 Q2 | MS1: 2060 Q3 | MT1: 2060 Q4 | MU1: Source | MV1: Seasonally adjusted | MW1: Base year price | MX1: Base year index | MY1: Historical end year | MZ1: Historical end quarter | NA1: Date of last update | NB1: Source details | NC1: Additional source details | ND1: Location code | NE1: Indicator code | NF1: Databank code
A2: United Kingdom | B2: GDP, nominal, LCU | C2: FEB021B | D2: Pound | E2: Millions | F2: Level | G2: 20046 | H2: 19874 | I2: 20558 | J2: 21315 | K2: 21132 | L2: 22651 | M2: 23896 | N2: 24994 | O2: 26814 | P2: 28129 | Q2: 29260 | R2: 30890 | S2: 32449 | T2: 33322 | U2: 34550 | V2: 36678 | W2: 38038 | X2: 39244 | Y2: 40339 | Z2: 42165 | AA2: 44140 | AB2: 45905 | AC2: 47207 | AD2: 48906 | AE2: 50459 | AF2: 53966 | AG2: 56767 | AH2: 59789 | AI2: 62107 | AJ2: 63704 | AK2: 66021 | AL2: 68138 | AM2: 69940 | AN2: 71334 | AO2: 73310 | AP2: 75596 | AQ2: 77468 | AR2: 78993 | AS2: 80430 | AT2: 82667 | AU2: 85727 | AV2: 86288 | AW2: 88637 | AX2: 90695 | AY2: 91663 | AZ2: 93433 | BA2: 94862 | BB2: 97962 | BC2: 99412 | BD2: 103208 | BE2: 105169 | BF2: 106841 | BG2: 108753 | BH2: 110079 | BI2: 111989 | BJ2: 115779 | BK2: 118136 | BL2: 121739 | BM2: 127119 | BN2: 129815 | BO2: 133283 | BP2: 136630 | BQ2: 140801 | BR2: 144969 | BS2: 148623 | BT2: 151262 | BU2: 155370 | BV2: 159376 | BW2: 163056 | BX2: 166719 | BY2: 170068 | BZ2: 170954 | CA2: 173192 | CB2: 175822 | CC2: 177280 | CD2: 179590 | CE2: 181438 | CF2: 181889 | CG2: 182558 | CH2: 184989 | CI2: 189580 | CJ2: 189802 | CK2: 193552 | CL2: 196921 | CM2: 199796 | CN2: 200691 | CO2: 203292 | CP2: 207015 | CQ2: 208657 | CR2: 210748 | CS2: 214616 | CT2: 217824 | CU2: 221433 | CV2: 226187 | CW2: 229912 | CX2: 232461 | CY2: 232749 | CZ2: 235998 | DA2: 243388 | DB2: 241270 | DC2: 245958 | DD2: 248081 | DE2: 250560 | DF2: 253902 | DG2: 255903 | DH2: 258404 | DI2: 261604 | DJ2: 267337 | DK2: 272305 | DL2: 273916 | DM2: 276174 | DN2: 278357 | DO2: 282889 | DP2: 286728 | DQ2: 288166 | DR2: 288352 | DS2: 292486 | DT2: 295516 | DU2: 299230 | DV2: 304207 | DW2: 307485 | DX2: 312948 | DY2: 317463 | DZ2: 320438 | EA2: 322778 | EB2: 329732 | EC2: 331592 | ED2: 338535 | EE2: 341254 | EF2: 348491 | EG2: 352001 | EH2: 357003 | EI2: 361213 | EJ2: 367042 | EK2: 370883 | EL2: 372900 | EM2: 376958 | EN2: 386144 | EO2: 389291 | EP2: 392244 | EQ2: 397800 | ER2: 400685 | ES2: 399994 | ET2: 395121 | EU2: 386874 | EV2: 386553 | EW2: 388596 | EX2: 386779 | EY2: 396176 | EZ2: 401223 | FA2: 404365 | FB2: 406789 | FC2: 414806 | FD2: 412364 | FE2: 416115 | FF2: 419305 | FG2: 424540 | FH2: 424939 | FI2: 430964 | FJ2: 433272 | FK2: 438283 | FL2: 442095 | FM2: 448800 | FN2: 452183 | FO2: 457683 | FP2: 461549 | FQ2: 470624 | FR2: 472658 | FS2: 474680 | FT2: 476591 | FU2: 479924 | FV2: 485256 | FW2: 489683 | FX2: 493710 | FY2: 500801 | FZ2: 507451 | GA2: 513814 | GB2: 517656 | GC2: 521257 | GD2: 529755 | GE2: 531131 | GF2: 535707 | GG2: 540205 | GH2: 545261 | GI2: 549060 | GJ2: 556104 | GK2: 562999 | GL2: 565758 | GM2: 555891 | GN2: 476160 | GO2: 533806 | GP2: 537629 | GQ2: 537992 | GR2: 568521 | GS2: 581805 | GT2: 597082 | GU2: 610346 | GV2: 625467 | GW2: 636553 | GX2: 654062 | GY2: 667103 | GZ2: 679433 | HA2: 685035 | HB2: 685749 | HC2: 698800 | HD2: 707433 | HE2: 717089 | HF2: 724724 | HG2: 733574 | HH2: 741462.2 | HI2: 749420.1 | HJ2: 757046 | HK2: 764825 | HL2: 772223.4 | HM2: 780042.6 | HN2: 787586.9 | HO2: 795007.8 | HP2: 802558.3 | HQ2: 810321.6 | HR2: 818281.9 | HS2: 826361.6 | HT2: 834479.4 | HU2: 842509.5 | HV2: 850405.3 | HW2: 858118.6 | HX2: 865730 | HY2: 873364.8 | HZ2: 881066.9 | IA2: 888925.7 | IB2: 896943.6 | IC2: 905169.5 | ID2: 913606.5 | IE2: 922076.6 | IF2: 930671.7 | IG2: 939252.8 | IH2: 947913.6 | II2: 956653.8 | IJ2: 965474.9 | IK2: 974435.3 | IL2: 983429.9 | IM2: 992677.4 | IN2: 1001858 | IO2: 1011113 | IP2: 1020283 | IQ2: 1029712 | IR2: 1039119 | IS2: 1048581 | IT2: 1058015 | IU2: 1067728 | IV2: 1077529 | IW2: 1087417 | IX2: 1097393 | IY2: 1107553 | IZ2: 1117809 | JA2: 1128162 | JB2: 1138612 | JC2: 1149161 | JD2: 1159808 | JE2: 1170555 | JF2: 1181403 | JG2: 1192481 | JH2: 1203665 | JI2: 1214958 | JJ2: 1226358 | JK2: 1237869 | JL2: 1249490 | JM2: 1261224 | JN2: 1273070 | JO2: 1285006 | JP2: 1297053 | JQ2: 1309215 | JR2: 1321490 | JS2: 1333999 | JT2: 1346627 | JU2: 1359390 | JV2: 1372276 | JW2: 1385284 | JX2: 1398417 | JY2: 1411557 | JZ2: 1424821 | KA2: 1438194 | KB2: 1451692 | KC2: 1465169 | KD2: 1478769 | KE2: 1492492 | KF2: 1506339 | KG2: 1520034 | KH2: 1533847 | KI2: 1547780 | KJ2: 1561835 | KK2: 1575877 | KL2: 1590040 | KM2: 1604323 | KN2: 1618727 | KO2: 1633247 | KP2: 1647891 | KQ2: 1662660 | KR2: 1677554 | KS2: 1692473 | KT2: 1707519 | KU2: 1722692 | KV2: 1737991 | KW2: 1753374 | KX2: 1768886 | KY2: 1784527 | KZ2: 1800299 | LA2: 1816059 | LB2: 1831947 | LC2: 1847964 | LD2: 1864110 | LE2: 1880337 | LF2: 1896694 | LG2: 1913183 | LH2: 1929805 | LI2: 1946484 | LJ2: 1963297 | LK2: 1980264 | LL2: 1997366 | LM2: 2014447 | LN2: 2031660 | LO2: 2049008 | LP2: 2066490 | LQ2: 2084106 | LR2: 2101859 | LS2: 2119750 | LT2: 2137783 | LU2: 2155879 | LV2: 2174118 | LW2: 2192496 | LX2: 2211017 | LY2: 2229607 | LZ2: 2248342 | MA2: 2267218 | MB2: 2286238 | MC2: 2305399 | MD2: 2324706 | ME2: 2344163 | MF2: 2363765 | MG2: 2383574 | MH2: 2403537 | MI2: 2423678 | MJ2: 2443972 | MK2: 2464374 | ML2: 2484933 | MM2: 2505650 | MN2: 2526527 | MO2: 2547615 | MP2: 2568869 | MQ2: 2590287 | MR2: 2611870 | MS2: 2633620 | MT2: 2655537 | MU2: Office for National Statistics\Haver Analytics | MV2: TRUE | MW2: NA | MX2: NA | MY2: 2024 | MZ2: 4 | NA2: NA | NB2: YBHAQ@UK | NC2: U.K.: Gross Domestic Product (SA, Mil.Pounds) | ND2: GBR | NE2: GDP! | NF2: FEB021B.db
A3: United Kingdom | B3: Public sector current balance | C3: FEB021B | D3: Pound | E3: Millions | F3: Level | G3: 1121 | H3: -291 | I3: 390 | J3: 274 | K3: 589 | L3: 296 | M3: -7 | N3: -160 | O3: -295 | P3: -381 | Q3: -347 | R3: 130 | S3: -333 | T3: -424 | U3: -855 | V3: 567 | W3: 107 | X3: -179 | Y3: -417 | Z3: -102 | AA3: -493 | AB3: -847 | AC3: -1432 | AD3: -272 | AE3: -891 | AF3: -1134 | AG3: -1442 | AH3: -396 | AI3: 302 | AJ3: -2364 | AK3: -1527 | AL3: -296 | AM3: -1332 | AN3: -2964 | AO3: -1973 | AP3: 1855 | AQ3: 1451 | AR3: -2280 | AS3: -1135 | AT3: -255 | AU3: 1465 | AV3: -2799 | AW3: -2262 | AX3: 1020 | AY3: 69 | AZ3: -4056 | BA3: -1335 | BB3: 174 | BC3: 150 | BD3: -4184 | BE3: 104 | BF3: 183 | BG3: 1194 | BH3: -2874 | BI3: -2900 | BJ3: 518 | BK3: 763 | BL3: -5113 | BM3: -1674 | BN3: 86 | BO3: 3124 | BP3: -2535 | BQ3: 694 | BR3: 2058 | BS3: 5628 | BT3: -2543 | BU3: -397 | BV3: 3753 | BW3: 3972 | BX3: -3236 | BY3: -143 | BZ3: 813 | CA3: 1925 | CB3: -6444 | CC3: -3959 | CD3: -2136 | CE3: -2159 | CF3: -12894 | CG3: -9933 | CH3: -7581 | CI3: -8120 | CJ3: -14864 | CK3: -11287 | CL3: -9777 | CM3: -9260.999 | CN3: -14303 | CO3: -9929 | CP3: -6402 | CQ3: -6570 | CR3: -11575 | CS3: -9162.999 | CT3: -5160 | CU3: -3027 | CV3: -14004 | CW3: -8226 | CX3: -1757 | CY3: -1638 | CZ3: -11102 | DA3: -5299 | DB3: 3039 | DC3: 7868 | DD3: -9253.999 | DE3: -415 | DF3: 3635 | DG3: 11249 | DH3: -6370 | DI3: 2440 | DJ3: 4960 | DK3: 15211 | DL3: 3302 | DM3: 4784 | DN3: -2602 | DO3: 15244 | DP3: 1081 | DQ3: 4081 | DR3: -6283 | DS3: 7971 | DT3: -7813 | DU3: -2787 | DV3: -9802 | DW3: 2586 | DX3: -10449 | DY3: -7428 | DZ3: -10401 | EA3: 5870 | EB3: -11665 | EC3: -7986 | ED3: -10568 | EE3: 5514 | EF3: -10247 | EG3: -5645 | EH3: -11313 | EI3: 7528 | EJ3: -9232 | EK3: -6581 | EL3: -10437 | EM3: 11644 | EN3: -10567 | EO3: -6310 | EP3: -11905 | EQ3: 11297 | ER3: -16414 | ES3: -14531 | ET3: -17851 | EU3: -7251 | EV3: -30795 | EW3: -23812 | EX3: -31417 | EY3: -10453 | EZ3: -25171 | FA3: -23031 | FB3: -33148 | FC3: -1993 | FD3: -20288 | FE3: -17060 | FF3: -26598 | FG3: -6785 | FH3: -26843 | FI3: -17618 | FJ3: -29196 | FK3: -5675 | FL3: -23539 | FM3: -17131 | FN3: -25837 | FO3: -1991 | FP3: -23604 | FQ3: -15659 | FR3: -21611 | FS3: 6949 | FT3: -18981 | FU3: -13391 | FV3: -19653 | FW3: 9828 | FX3: -15388 | FY3: -8601 | FZ3: -12041 | GA3: 25635 | GB3: -11559 | GC3: -2483 | GD3: -6285 | GE3: 18833 | GF3: -8435 | GG3: -1606 | GH3: -8140 | GI3: 27940 | GJ3: -14183 | GK3: -1830 | GL3: -13143 | GM3: 18011 | GN3: -109176 | GO3: -56264 | GP3: -48986 | GQ3: -18893 | GR3: -45685 | GS3: -21102 | GT3: -14465 | GU3: 20866 | GV3: -31204 | GW3: -11366 | GX3: -37400 | GY3: 12300 | GZ3: -41871 | HA3: -12423 | HB3: -22702 | HC3: 26421 | HD3: -36311 | HE3: -17529 | HF3: -30777 | HG3: 28421.19 | HH3: -17539.81 | HI3: -5719.73 | HJ3: -20273.9 | HK3: 28913.6 | HL3: -14130.56 | HM3: -1668.604 | HN3: -16936.55 | HO3: 34766.32 | HP3: -10081.88 | HQ3: 3001.801 | HR3: -12942.06 | HS3: 41165.02 | HT3: -10206.42 | HU3: 3362.025 | HV3: -13170.2 | HW3: 42936.62 | HX3: -10208.87 | HY3: 3874.625 | HZ3: -13281.67 | IA3: 44947.82 | IB3: -13199.38 | IC3: 1412.252 | ID3: -16297.28 | IE3: 43905.12 | IF3: -16360.32 | IG3: -1356.084 | IH3: -19768.83 | II3: 44156.52 | IJ3: -18324.46 | IK3: -2785.947 | IL3: -21881.87 | IM3: 44390.18 | IN3: -20419.99 | IO3: -4323.551 | IP3: -24127.73 | IQ3: 44561.49 | IR3: -22639.62 | IS3: -5972.461 | IT3: -26501.51 | IU3: 44664.32 | IV3: -24993.1 | IW3: -7740.035 | IX3: -29026.38 | IY3: 45218.25 | IZ3: -27070.36 | JA3: -9182.668 | JB3: -31278.97 | JC3: 45760.79 | JD3: -29275.84 | JE3: -10726.33 | JF3: -33663.46 | JG3: 46283.27 | JH3: -31618.96 | JI3: -12379.89 | JJ3: -36201.69 | JK3: 46793.91 | JL3: -34108.66 | JM3: -14148.35 | JN3: -38888.88 | JO3: 47274.06 | JP3: -36745.16 | JQ3: -16036.46 | JR3: -41729.37 | JS3: 48943.73 | JT3: -38149.57 | JU3: -16627.81 | JV3: -43288.4 | JW3: 50870.66 | JX3: -39616.78 | JY3: -17268.77 | JZ3: -44951.49 | KA3: 52804.89 | KB3: -41126.07 | KC3: -17928.53 | KD3: -46661.56 | KE3: 54786.64 | KF3: -42674.11 | KG3: -18606.98 | KH3: -48413.65 | KI3: 56794.82 | KJ3: -44246.35 | KK3: -19294.52 | KL3: -50195.07 | KM3: 58858.19 | KN3: -45858.23 | KO3: -19997.73 | KP3: -52022.89 | KQ3: 60995.89 | KR3: -47524.61 | KS3: -20725.98 | KT3: -53911.55 | KU3: 63188.76 | KV3: -49236.76 | KW3: -21473.55 | KX3: -55852.7 | KY3: 65451.55 | KZ3: -51001.95 | LA3: -22245.59 | LB3: -57852.38 | LC3: 67765.3 | LD3: -52809.66 | LE3: -23035.1 | LF3: -59901.64 | LG3: 70150.16 | LH3: -54670.95 | LI3: -23848.52 | LJ3: -62010.73 | LK3: 72601.59 | LL3: -56584.8 | LM3: -24685.45 | LN3: -64179.05 | LO3: 75108.08 | LP3: -58543.12 | LQ3: -25540.49 | LR3: -66399.45 | LS3: 77696.93 | LT3: -60562.76 | LU3: -26423.17 | LV3: -68688.13 | LW3: 80353.7 | LX3: -62637.57 | LY3: -27329.86 | LZ3: -71039.39 | MA3: 83083.22 | MB3: -64768.49 | MC3: -28260.45 | MD3: -73455.18 | ME3: 85898.71 | MF3: -66964.81 | MG3: -29218.88 | MH3: -75946.22 | MI3: 88812.87 | MJ3: -69237.05 | MK3: -30211.2 | ML3: -78521.56 | MM3: 91810.88 | MN3: -71575.98 | MO3: -31232.02 | MP3: -81174 | MQ3: 94910.95 | MR3: -73993.34 | MS3: -32287.4 | MT3: -83915.41 | MU3: Office for National Statistics\Haver Analytics | MV3: FALSE | MW3: NA | MX3: NA | MY3: 2024 | MZ3: 4 | NA3: NA | NB3: ANMUQ@UK | NC3: UK: Public Sector: Current Budget Surplus/Deficit (NSA, Mil.GBP) | ND3: GBR | NE3: PSCB | NF3: FEB021B.db

Sheet OBR
C1: £ billion
C3: Receipts and expenditure | K3: Deficit | Q3: Fiscal targets | T3: Financing | X3: Other Debt and Deficit measures | AE3: Economic indicators
C4: Public sector current receipts | D4: Total managed expenditure | E4: Public sector current expenditure | F4: Public sector net investment | G4: Depreciation | H4: Public sector gross investment | I4: National account taxes | K4: Cyclically-adjusted current budget deficit | L4: Primary balance | M4: Cyclically-adjusted primary balance | N4: Cyclically-adjusted net borrowing | O4: Public sector net borrowing | Q4: Current budget deficit | R4: Public sector net financial liabilities | T4: Central government net cash requirement | U4: Public sector net cash requirement | V4: Central government debt interest, net of APF | X4: Public sector net debt | Y4: Public Sector Net Debt ex BoE | Z4: Public sector net worth (inverted) | AA4: General government net borrowing | AB4: Cyclically-adjusted general government net borrowing | AC4: General Government Gross Debt | AE4: Nominal GDP (£ billion) | AF4: Nominal GDP, centred end-March (£ billion) | AG4: Output gap (per cent of GDP) | AH4: GDP Deflator (2023-24=100)
B5: ONS code | C5: JW2O | D5: KX5Q | E5: JW2Q | F5: -JW2Z | G5: -JW2S | L5: (J5II+JW2P-JW2L+JW2M) | O5: -J5II | Q5: -JW2T | T5: RUUW | U5: JW38 | V5: NMFX+MU74 | X5: HF6W | Y5: CPPH | AA5: -NNBK | AC5: BKPX | AE5: BKTL | AF5: BKTL | AH5: YBGB
B6: Derivation | C6: a | D6: b | E6: c | F6: d | G6: e
D7: (c+d+e) | H7: (d+e) | O7: (b-a) | Q7: (c+e-a)
B8: 1946-47 | C8: 3.648 | D8: 4.277 | E8: 3.734 | F8: 0.412 | G8: 0.131 | H8: 0.543 | I8: 3.547 | K8: - | L8: -0.066 | M8: - | N8: - | O8: 0.629 | Q8: 0.217 | T8: 0.439 | U8: 0.629 | V8: 0.504 | AA8: 0.632 | AB8: - | AC8: - | AE8: - | AF8: - | AG8: - | AH8: -
B9: 1947-48 | C9: 3.949 | D9: 4.028 | E9: 3.449 | F9: 0.371 | G9: 0.208 | H9: 0.579 | I9: 3.717 | K9: - | L9: 0.428 | M9: - | N9: - | O9: 0.079 | Q9: -0.292 | T9: -0.197 | U9: 0.079 | V9: 0.527 | AA9: 0.119 | AB9: - | AC9: - | AE9: - | AF9: - | AG9: - | AH9: -
B10: 1948-49 | C10: 4.906 | D10: 4.41 | E10: 3.797 | F10: 0.301 | G10: 0.312 | H10: 0.613 | I10: 4.251 | K10: - | L10: 0.879 | M10: - | N10: - | O10: -0.496 | Q10: -0.797 | T10: -0.677 | U10: -0.496 | V10: 0.52 | AA10: -0.434 | AB10: - | AC10: - | AE10: 11.425 | AF10: - | AG10: - | AH10: -
B11: 1949-50 | C11: 5.269 | D11: 4.682 | E11: 3.989 | F11: 0.364 | G11: 0.329 | H11: 0.693 | I11: 4.494 | K11: - | L11: 0.958 | M11: - | N11: - | O11: -0.587 | Q11: -0.951 | T11: -0.794 | U11: -0.587 | V11: 0.519 | AA11: -0.515 | AB11: - | AC11: - | AE11: 12.169 | AF11: - | AG11: - | AH11: -
B12: 1950-51 | C12: 5.458 | D12: 4.992 | E12: 4.157 | F12: 0.479 | G12: 0.356 | H12: 0.835 | I12: 4.596 | K12: - | L12: 0.824 | M12: - | N12: - | O12: -0.466 | Q12: -0.945 | T12: -0.745 | U12: -0.466 | V12: 0.531 | AA12: -0.417 | AB12: - | AC12: - | AE12: 12.74 | AF12: - | AG12: - | AH12: -
B13: 1951-52 | C13: 5.883 | D13: 5.814 | E13: 4.62 | F13: 0.778 | G13: 0.416 | H13: 1.194 | I13: 4.975 | K13: - | L13: 0.488 | M13: - | N13: - | O13: -0.069 | Q13: -0.847 | T13: -0.384 | U13: -0.069 | V13: 0.579 | AA13: -0.001 | AB13: - | AC13: - | AE13: 14.303 | AF13: - | AG13: - | AH13: -
B14: 1952-53 | C14: 6.203 | D14: 6.412 | E14: 5.055 | F14: 0.897 | G14: 0.46 | H14: 1.357 | I14: 5.275 | K14: - | L14: 0.297 | M14: - | N14: - | O14: 0.209 | Q14: -0.688 | T14: -0.3 | U14: 0.209 | V14: 0.634 | AA14: 0.154 | AB14: - | AC14: - | AE14: 15.536 | AF14: - | AG14: - | AH14: -
B15: 1953-54 | C15: 6.34 | D15: 6.758 | E15: 5.273 | F15: 1.011 | G15: 0.474 | H15: 1.485 | I15: 5.29 | K15: - | L15: 0.076 | M15: - | N15: - | O15: 0.418 | Q15: -0.593 | T15: -0.158 | U15: 0.418 | V15: 0.657 | AA15: 0.294 | AB15: - | AC15: - | AE15: 16.685 | AF15: - | AG15: - | AH15: -
B16: 1954-55 | C16: 6.594 | D16: 6.851 | E16: 5.478 | F16: 0.874 | G16: 0.499 | H16: 1.373 | I16: 5.441 | K16: - | L16: 0.19 | M16: - | N16: - | O16: 0.257 | Q16: -0.617 | T16: -0.307 | U16: 0.257 | V16: 0.656 | AA16: 0.113 | AB16: - | AC16: - | AE16: 17.601 | AF16: - | AG16: - | AH16: -
B17: 1955-56 | C17: 7.04 | D17: 7.002 | E17: 5.611 | F17: 0.844 | G17: 0.547 | H17: 1.391 | I17: 5.803 | K17: - | L17: 0.539 | M17: - | N17: - | O17: -0.038 | Q17: -0.882 | T17: -0.556 | U17: -0.038 | V17: 0.742 | AA17: -0.108 | AB17: - | AC17: - | AE17: 19.574 | AF17: - | AG17: - | AH17: 3.3033033
B18: 1956-57 | C18: 7.528 | D18: 7.61 | E18: 6.113 | F18: 0.899 | G18: 0.598 | H18: 1.497 | I18: 6.19 | K18: - | L18: 0.391 | M18: - | N18: - | O18: 0.082 | Q18: -0.817 | T18: -0.38 | U18: 0.082 | V18: 0.731 | AA18: 0.032 | AB18: - | AC18: - | AE18: 21.162 | AF18: 21.81 | AG18: - | AH18: 3.5112035
B19: 1957-58 | C19: 7.916 | D19: 7.922 | E19: 6.388 | F19: 0.892 | G19: 0.642 | H19: 1.534 | I19: 6.509 | K19: - | L19: 0.501 | M19: - | N19: - | O19: 0.006 | Q19: -0.886 | T19: -0.468 | U19: 0.006 | V19: 0.769 | AA19: -0.098 | AB19: - | AC19: - | AE19: 22.509 | AF19: 23.004 | AG19: - | AH19: 3.6729037
B20: 1958-59 | C20: 8.319 | D20: 8.39 | E20: 6.766 | F20: 0.951 | G20: 0.673 | H20: 1.624 | I20: 6.892 | K20: - | L20: 0.546 | M20: - | N20: - | O20: 0.071 | Q20: -0.88 | T20: -0.52 | U20: 0.071 | V20: 0.793 | AA20: -0.17 | AB20: - | AC20: - | AE20: 23.335 | AF20: 23.957 | AG20: - | AH20: 3.7884038
B21: 1959-60 | C21: 8.372 | D21: 8.941 | E21: 7.232 | F21: 1.024 | G21: 0.685 | H21: 1.709 | I21: 7.072 | K21: - | L21: 0.363 | M21: - | N21: - | O21: 0.569 | Q21: -0.455 | T21: -0.282 | U21: 0.569 | V21: 0.819 | AA21: 0.057 | AB21: - | AC21: - | AE21: 24.873 | AF21: 25.789 | AG21: - | AH21: 3.7884038
B22: 1960-61 | C22: 8.913 | D22: 9.575 | E22: 7.767 | F22: 1.066 | G22: 0.742 | H22: 1.808 | I22: 7.429 | K22: - | L22: 0.367 | M22: - | N22: - | O22: 0.662 | Q22: -0.404 | T22: -0.211 | U22: 0.662 | V22: 0.887 | AA22: 0.168 | AB22: - | AC22: - | AE22: 26.639 | AF22: 27.583 | AG22: - | AH22: 3.8346038
B23: 1961-62 | C23: 9.98 | D23: 10.59 | E23: 8.486 | F23: 1.239 | G23: 0.865 | H23: 2.104 | I23: 8.4 | K23: - | L23: 0.508 | M23: - | N23: - | O23: 0.61 | Q23: -0.629 | T23: -0.47 | U23: 0.61 | V23: 0.949 | AA23: 0.047 | AB23: - | AC23: - | AE23: 28.141 | AF23: 28.843 | AG23: - | AH23: 3.996304
B24: 1962-63 | C24: 10.449 | D24: 10.987 | E24: 8.808 | F24: 1.258 | G24: 0.921 | H24: 2.179 | I24: 8.731 | K24: - | L24: 0.55 | M24: - | N24: - | O24: 0.538 | Q24: -0.72 | T24: -0.384 | U24: 0.646 | V24: 0.935 | AA24: 0.067 | AB24: - | AC24: - | AE24: 29.45 | AF24: 30.383 | AG24: - | AH24: 4.1118041
B25: 1963-64 | C25: 11.056 | D25: 11.919 | E25: 9.15 | F25: 1.767 | G25: 1.002 | H25: 2.769 | I25: 9.16 | K25: - | L25: 0.289 | M25: - | N25: - | O25: 0.863 | Q25: -0.904 | T25: 0.303 | U25: 0.989 | V25: 0.984 | AA25: 0.773 | AB25: - | AC25: - | AE25: 31.921 | AF25: 33.341 | AG25: - | AH25: 4.2042042
B26: 1964-65 | C26: 12.257 | D26: 12.908 | E26: 9.724 | F26: 2.096 | G26: 1.088 | H26: 3.184 | I26: 10.137 | K26: - | L26: 0.539 | M26: - | N26: - | O26: 0.651 | Q26: -1.445 | T26: 0.326 | U26: 0.914 | V26: 0.986 | AA26: 0.031 | AB26: - | AC26: - | AE26: 34.855 | AF26: 36.162 | AG26: - | AH26: 4.3890044
B27: 1965-66 | C27: 13.846 | D27: 14.417 | E27: 10.966 | F27: 2.251 | G27: 1.2 | H27: 3.451 | I27: 11.498 | K27: - | L27: 0.662 | M27: - | N27: - | O27: 0.571 | Q27: -1.68 | T27: 0.469 | U27: 0.922 | V27: 1.014 | AA27: 0.457 | AB27: - | AC27: - | AE27: 37.461 | AF27: 38.754 | AG27: - | AH27: 4.6200046
B28: 1966-67 | C28: 15.037 | D28: 15.994 | E28: 11.958 | F28: 2.697 | G28: 1.339 | H28: 4.036 | I28: 12.541 | K28: - | L28: 0.38 | M28: - | N28: - | O28: 0.957 | Q28: -1.74 | T28: 0.743 | U28: 1.166 | V28: 1.115 | AA28: 0.032 | AB28: - | AC28: - | AE28: 39.949 | AF28: 41.146 | AG28: - | AH28: 4.8510049
B29: 1967-68 | C29: 16.615 | D29: 18.252 | E29: 13.419 | F29: 3.386 | G29: 1.447 | H29: 4.833 | I29: 13.861 | K29: - | L29: -0.078 | M29: - | N29: - | O29: 1.637 | Q29: -1.749 | T29: 1.374 | U29: 2.021 | V29: 1.224 | AA29: 0.631 | AB29: - | AC29: - | AE29: 42.504 | AF29: 44.387 | AG29: - | AH29: 5.012705
... B33: 1971-72 | C33: 24.78 | D33: 25.414 | E33: 19.495 | F33: 3.47 | G33: 2.449 | H33: 5.919 | I33: 20.708 | K33: - | L33: 1.276 | M33: - | N33: - | O33: 0.634 | Q33: -2.836 | T33: 0.488 | U33: 0.85 | V33: 1.544 | AA33: -0.407 | AB33: - | AC33: - | AE33: 64.575 | AF33: 68.129 | AG33: - | AH33: 6.6297066
B34: 1972-73 | C34: 26.524 | D34: 28.437 | E34: 22.036 | F34: 3.634 | G34: 2.767 | H34: 6.401 | I34: 22.053 | K34: - | L34: 0.11 | M34: - | N34: - | O34: 1.913 | Q34: -1.721 | T34: 1.908 | U34: 2.449 | V34: 1.726 | AA34: 1.453 | AB34: - | AC34: - | AE34: 73.925 | AF34: 79.218 | AG34: 2.5446864 | AH34: 7.2072072
B35: 1973-74 | C35: 29.974 | D35: 33.357 | E35: 25.684 | F35: 4.345 | G35: 3.328 | H35: 7.673 | I35: 24.688 | K35: - | L35: -0.871 | M35: - | N35: - | O35: 3.383 | Q35: -0.962 | T35: 2.135 | U35: 4.371 | V35: 2.017 | AA35: 3.034 | AB35: - | AC35: - | AE35: 82.855 | AF35: 88.827 | AG35: 6.5394316 | AH35: 7.8540079
B36: 1974-75 | C36: 38.303 | D36: 43.895 | E36: 34.139 | F36: 5.426 | G36: 4.33 | H36: 9.756 | I36: 31.902 | K36: - | L36: -2.255 | M36: - | N36: - | O36: 5.592 | Q36: 0.166 | T36: 5.094 | U36: 7.987 | V36: 2.372 | X36: 52.1 | AA36: 3.371 | AB36: - | AC36: 53.67 | AE36: 98.182 | AF36: 109.112 | AG36: 3.1047807 | AH36: 9.4248094
B37: 1975-76 | C37: 48.482 | D37: 56.133 | E37: 43.92 | F37: 6.72 | G37: 5.493 | H37: 12.213 | I37: 40.306 | K37: 0.63181964 | L37: -3.622 | M37: -3.3228196 | N37: 7.3518196 | O37: 7.651 | Q37: 0.931 | T37: 8.753 | U37: 10.281 | V37: 3.109 | X37: 64.7 | AA37: 5.09 | AB37: 4.7908196 | AC37: 65.638 | AE37: 120.844 | AF37: 131.16 | AG37: -1.7370637 | AH37: 11.711712
B38: 1976-77 | C38: 57.128 | D38: 64.132 | E38: 51.266 | F38: 6.399 | G38: 6.467 | H38: 12.866 | I38: 46.543 | K38: -0.3429857 | L38: -1.857 | M38: -0.9090143 | N38: 6.0560143 | O38: 7.004 | Q38: 0.605 | T38: 5.839 | U38: 8.246 | V38: 4.079 | X38: 73.6 | AA38: 5.14 | AB38: 4.1920143 | AC38: 75.991 | AE38: 142.077 | AF38: 154.006 | AG38: -0.63964205 | AH38: 13.351813
B39: 1977-78 | C39: 63.759 | D39: 70.183 | E39: 57.555 | F39: 5.233 | G39: 7.395 | H39: 12.628 | I39: 52.516 | K39: 0.58894731 | L39: -0.536 | M39: 0.066052692 | N39: 5.8219473 | O39: 6.424 | Q39: 1.191 | T39: 4.678 | U39: 5.568 | V39: 4.907 | X39: 79.5 | AA39: 5.349 | AB39: 4.7469473 | AC39: 86.357 | AE39: 166.1 | AF39: 179.374 | AG39: -0.46907117 | AH39: 15.199815
B40: 1978-79 | C40: 70.984 | D40: 79.669 | E40: 66.071 | F40: 5.243 | G40: 8.355 | H40: 13.598 | I40: 58.432 | K40: 4.7632098 | L40: -2.027 | M40: -3.3482098 | N40: 10.00621 | O40: 8.685 | Q40: 3.442 | T40: 7.755 | U40: 9.029 | V40: 5.856 | X40: 88.6 | AA40: 7.24 | AB40: 8.5612098 | AC40: 96.731 | AE40: 192.358 | AF40: 210.054 | AG40: 1.5613273 | AH40: 16.932317
B41: 1979-80 | C41: 86.677 | D41: 95.223 | E41: 79.491 | F41: 5.876 | G41: 9.856 | H41: 15.732 | I41: 72.543 | K41: 3.2823756 | L41: -0.162 | M41: -0.77437558 | N41: 9.1583756 | O41: 8.546 | Q41: 2.67 | T41: 8.064 | U41: 9.723 | V41: 7.587 | X41: 98.2 | AA41: 6.072 | AB41: 6.6843756 | AC41: 107.499 | AE41: 232.592 | AF41: 251.309 | AG41: -0.097964602 | AH41: 19.79672
B42: 1980-81 | C42: 102.984 | D42: 114.521 | E42: 96.636 | F42: 6.018 | G42: 11.867 | H42: 17.885 | I42: 85.908 | K42: 1.6991212 | L42: -1.489 | M42: 2.3308788 | N42: 7.7171212 | O42: 11.537 | Q42: 5.519 | T42: 12.497 | U42: 12.267 | V42: 9.163 | X42: 113.8 | AA42: 8.953 | AB42: 5.1331212 | AC42: 126.222 | AE42: 267.518 | AF42: 282.161 | AG42: -2.8166062 | AH42: 23.562024
B43: 1981-82 | C43: 121.922 | D43: 127.921 | E43: 110.587 | F43: 4.368 | G43: 12.966 | H43: 17.334 | I43: 101.48 | K43: -4.7661805 | L43: 5.746 | M43: 12.14318 | N43: -0.39818047 | O43: 5.999 | Q43: 1.631 | T43: 7.635 | U43: 8.672 | V43: 11.232 | X43: 125.2 | AA43: 8.318 | AB43: 1.9208195 | AC43: 133.648 | AE43: 298.261 | AF43: 312.84 | AG43: -3.1630102 | AH43: 26.033726
B44: 1982-83 | C44: 132.879 | D44: 141.421 | E44: 121.436 | F44: 6.337 | G44: 13.648 | H44: 19.985 | I44: 110.421 | K44: -4.3070356 | L44: 3.366 | M44: 9.8780356 | N44: 2.0299644 | O44: 8.542 | Q44: 2.205 | T44: 12.819 | U44: 8.998 | V44: 12.087 | X44: 132.5 | AA44: 8.705 | AB44: 2.1929644 | AC44: 142.889 | AE44: 327.449 | AF44: 342.722 | AG44: -2.7122309 | AH44: 27.951028
...

Sheet NATO1
B4: Table 1 : Defence expenditure
B6: Million national currency units
D8: 2014 | E8: 2015 | F8: 2016 | G8: 2017 | H8: 2018 | I8: 2019 | J8: 2020 | K8: 2021 | L8: 2022 | M8: 2023e | N8: 2024e
B10: Current prices
C11: Albania (Leks) | D11: 18788.017 | E11: 16671.141 | F11: 16250.363 | G11: 17198.659 | H11: 18994.754 | I11: 21669.923 | J11: 21348.084 | K11: 23072.112 | L11: 25847.998 | M11: 40256.139 | N11: 49842.376
C12: Belgium (Euros) | D12: 3913.2223 | E12: 3789.0632 | F12: 3847.9231 | G12: 3932.3423 | H12: 4100.7013 | I12: 4252.662 | J12: 4664.5128 | K12: 5276.2397 | L12: 6550.8405 | M12: 7047.2425 | N12: 7900
C13: Bulgaria (Leva) | D13: 1101.5635 | E13: 1116.3743 | F13: 1185.7616 | G13: 1254.7224 | H13: 1592.8802 | I13: 3770.8195 | J13: 1920.2466 | K13: 2108.5208 | L13: 2672.006 | M13: 3601.61 | N13: 4217
C14: Canada (Canadian dollars) | D14: 20075.96 | E14: 23899.715 | F14: 23474.297 | G14: 30760.938 | H14: 29024.953 | I14: 29948.502 | J14: 31288.988 | K14: 31976.321 | L14: 33707.178 | M14: 37785.15 | N14: 41012.108
C15: Croatia (Euros) | D15: 811.37141 | E15: 803.9609 | F15: 755.93964 | G15: 812.32891 | H15: 805.4112 | I15: 880.53571 | J15: 861.00378 | K15: 1150.3649 | L15: 1218.8437 | M15: 1332.4151 | N15: 1506
C16: Czechia* (Koruny) | D16: 41002.523 | E16: 47263.954 | F16: 45598.417 | G16: 52805.325 | H16: 59752.298 | I16: 68373.103 | J16: 74257.489 | K16: 84863.619 | L16: 90968.608 | M16: 100735.23 | N16: 159691.47
C17: Denmark (Kroner) | D17: 22769.095 | E17: 22632.601 | F17: 24189.8 | G17: 24961.08 | H17: 28787 | I17: 29928.8 | J17: 31962.3 | K17: 33160.72 | L17: 38726.275 | M17: 56084.03 | N17: 68670.44
C18: Estonia* (Euros) | D18: 386.446 | E18: 417.642 | F18: 449.516 | G18: 479.23823 | H18: 520.71708 | I18: 569.0215 | J18: 630.4205 | K18: 633.08703 | L18: 777.72978 | M18: 1144.3816 | N18: 1332.8513
C19: Finland (Euros) | D19: 3003.544 | E19: 3064.864 | F19: 3088.512 | G19: 3130.789 | H19: 3237.841 | I19: 3482.9985 | J19: 3641.7246 | K19: 3502.5453 | L19: 4484.6077 | M19: 5793.7214 | N19: 6776.7382
C20: France (Euros) | D20: 39148.595 | E20: 39198.88 | F20: 39950.378 | G20: 40852.04 | H20: 42748.476 | I20: 44206.235 | J20: 46017.995 | K20: 47702.367 | L20: 49567.126 | M20: 54900 | N20: 59600
C21: Germany (Euros) | D21: 34748.818 | E21: 35898.052 | F21: 37598.398 | G21: 40264.885 | H21: 42126.678 | I21: 46935.812 | J21: 51391.501 | K21: 52431.448 | L21: 58266.247 | M21: 67621.073 | N21: 90585.847
C22: Greece (Euros) | D22: 3938.6272 | E22: 4073.101 | F22: 4190.018 | G22: 4208.1974 | H22: 4560.3845 | I22: 4482.937 | J22: 4812.079 | K22: 6764.15 | L22: 8053.819 | M22: 6223.533 | N22: 7125.609
... C41: United States (US dollars) | D41: 653942 | E41: 641253 | F41: 656059 | G41: 642933 | H41: 672255 | I41: 750886 | J41: 770650 | K41: 824094 | L41: 834977 | M41: 875603 | N41: 967707
D42: #REF! | E42: #REF! | F42: #REF! | G42: #REF! | H42: #REF! | I42: #REF!
B43: Constant 2015 prices
C44: Albania (Leks) | D44: 18893.952 | E44: 16671.141 | F44: 16353.828 | G44: 17060.611 | H44: 18568.762 | I44: 20920.967 | J44: 20467.665 | K44: 21381.971 | L44: 21800.872 | M44: 32542.519 | N44: 38973.374
C45: Belgium (Euros) | D45: 3965.2884 | E45: 3789.0632 | F45: 3775.4083 | G45: 3788.8763 | H45: 3890.8034 | I45: 3964.8838 | J45: 4280.3758 | K45: 4692.8835 | L45: 5502.3641 | M45: 5706.2113 | N45: 6213.5907
C46: Bulgaria (Leva) | D46: 1134.0354 | E46: 1116.3743 | F46: 1147.6205 | G46: 1158.5975 | H46: 1411.0944 | I46: 3174.1757 | J46: 1550.3662 | K46: 1589.0074 | L46: 1733.1918 | M46: 2172.9738 | N46: 2461.8678
C47: Canada (Canadian dollars) | D47: 19901.751 | E47: 23899.715 | F47: 23307.155 | G47: 29776.388 | H47: 27639.566 | I47: 28084.86 | J47: 29031.049 | K47: 27556.618 | L47: 26983.008 | M47: 29769.6 | N47: 31395.97
C48: Croatia (Euros) | D48: 812.35765 | E48: 803.9609 | F48: 756.0645 | G48: 802.58314 | H48: 779.99784 | I48: 836.09323 | J48: 810.83684 | K48: 1060.6984 | L48: 1035.2855 | M48: 1042.8725 | N48: 1116.9801
C49: Czechia* (Koruny) | D49: 41409.636 | E49: 47263.954 | F49: 45083.419 | G49: 51539.45 | H49: 56861.005 | I49: 62629.1 | J49: 65201.72 | K49: 72115.976 | L49: 71212.604 | M49: 72643.479 | N49: 112343.19
C50: Denmark (Kroner) | D50: 22867.645 | E50: 22632.601 | F50: 24130.495 | G50: 24607.186 | H50: 28167.94 | I50: 28978.819 | J50: 30069.154 | K50: 30331.604 | L50: 32778.402 | M50: 49181.028 | N50: 59340.439
C51: Estonia* (Euros) | D51: 388.80852 | E51: 417.642 | F51: 439.52954 | G51: 451.31183 | H51: 468.16374 | I51: 493.14295 | J51: 552.5517 | K51: 524.8419 | L51: 555.01996 | M51: 755.4788 | N51: 850.33302
C52: Finland (Euros) | D52: 3052.0601 | E52: 3064.864 | F52: 3085.8142 | G52: 3102.677 | H52: 3145.7659 | I52: 3334.0267 | J52: 3429.8651 | K52: 3221.5424 | L52: 3914.0865 | M52: 4825.1343 | N52: 5560.5822
C53: France (Euros) | D53: 39594.659 | E53: 39198.88 | F53: 39740.69 | G53: 40429.685 | H53: 41888.327 | I53: 42771.297 | J53: 43293.267 | K53: 44245.891 | L53: 44658.311 | M53: 46902.262 | N53: 49741.782
C54: Germany (Euros) | D54: 35394.249 | E54: 35898.052 | F54: 37105.051 | G54: 39146.665 | H54: 40152.434 | I54: 43801.192 | J54: 47076.793 | K54: 46625.659 | L54: 49217.228 | M54: 53567.324 | N54: 69341.348
C55: Greece (Euros) | D55: 3927.0582 | E55: 4073.101 | F55: 4214.4002 | G55: 4220.6409 | H55: 4581.4393 | I55: 4492.4704 | J55: 4863.0445 | K55: 6696.627 | L55: 7427.5673 | M55: 5472.488 | N55: 6121.2378
... C74: United States (US dollars) | D74: 660020.64 | E74: 641253 | F74: 651245.93 | G74: 626409.19 | H74: 640086.9 | I74: 699062.39 | J74: 704413.51 | K74: 734748.93 | L74: 703361.63 | M74: 703901.8 | N74: 754684.14
D75: #REF! | E75: #REF! | F75: #REF! | G75: #REF! | H75: #REF! | I75: #REF!
C78: Notes: Figures for 2023 and 2024 are estimates.
C79: * These Allies have national laws or political agreements which call for 2% of GDP or more to be spent on defence annually, consequently future estimates are expected to change accordingly. For past years Allies defence spending was based on the then available GDP data and Allies may, therefore, have met the 2% guideline when using those figures. (In 2018 and 2021, Lithuania met 2% using November 2018 and June 2021 OECD figures respectively).
B81: -7-

Sheet NATO2
A3: Table 3 : Defence expenditure as a share of GDP and annual real change
A5: Based on 2015 prices
C7: 2014 | D7: 2015 | E7: 2016 | F7: 2017 | G7: 2018 | H7: 2019 | I7: 2020 | J7: 2021 | K7: 2022 | L7: 2023e | M7: 2024e
X8: 38.4
A9: Share of real GDP (%) | V9: 23000 | X9: 21.4
B10: Albania | C10: 1.3465169 | D10: 1.1623133 | E10: 1.1036058 | F10: 1.1091294 | G10: 1.1605307 | H10: 1.2808017 | I10: 1.2958409 | J10: 1.2429943 | K10: 1.2087886 | L10: 1.7467931 | M10: 2.0294681 | P10: Poland* | Q10: 4.120191 | V10: =V9*1.05 -> 24150
B11: Belgium | C11: 0.97101568 | D11: 0.90930025 | E11: 0.89469106 | F11: 0.88357315 | G11: 0.89135991 | H11: 0.88842181 | I11: 1.0123783 | J11: 1.038775 | K11: 1.1823661 | L11: 1.2085158 | M11: 1.2991611 | P11: Estonia* | Q11: 3.4314626 | V11: =V10-V9 -> 1150
B12: Bulgaria | C12: 1.3090834 | D12: 1.2463513 | E12: 1.2435962 | F12: 1.2219378 | G12: 1.4491848 | H12: 3.1334193 | I12: 1.5936662 | J12: 1.5171463 | K12: 1.5922901 | L12: 1.9601292 | M12: 2.1786672 | P12: United States | Q12: 3.3790207
B13: Canada | C13: 1.0063653 | D13: 1.2007246 | E13: 1.1589184 | F13: 1.4369966 | G13: 1.2982635 | H13: 1.2944753 | I13: 1.4090794 | J13: 1.270352 | K13: 1.1981413 | L13: 1.3079334 | M13: 1.3651551 | P13: Latvia* | Q13: 3.1480259
B14: Croatia | C14: 1.8119293 | D14: 1.748626 | E14: 1.5865539 | F14: 1.6293461 | G14: 1.5376221 | H14: 1.5933488 | I14: 1.6891396 | J14: 1.9547331 | K14: 1.7826308 | L14: 1.7423632 | M14: 1.8065857 | P14: Greece | Q14: 3.0759535
B15: Czechia* | C15: 0.94374764 | D15: 1.0214013 | E15: 0.9509705 | F15: 1.0319857 | G15: 1.103168 | H15: 1.1800798 | I15: 1.3003054 | J15: 1.3896161 | K15: 1.3406999 | L15: 1.3700774 | M15: 2.0955745 | P15: Lithuania* | Q15: 2.8495516
B16: Denmark | C16: 1.1493158 | D16: 1.1114025 | E16: 1.1476871 | F16: 1.138268 | G16: 1.2775485 | H16: 1.2950584 | I16: 1.3771511 | J16: 1.3001145 | K16: 1.3676464 | L16: 2.0140062 | M16: 2.3745769 | P16: Finland | Q16: 2.4140773
B17: Estonia* | C17: 1.928738 | D17: 2.025411 | E17: 2.0678305 | F17: 2.0133276 | G17: 2.0110316 | H17: 2.0380487 | I17: 2.2993229 | J17: 2.0340629 | K17: 2.1612933 | L17: 3.0369167 | M17: 3.4314626 | P17: Denmark | Q17: 2.3745769
B18: Finland | C18: 1.4517098 | D18: 1.4498966 | E18: 1.419888 | F18: 1.3834623 | G18: 1.3868814 | H18: 1.4521085 | I18: 1.5298921 | J18: 1.3973292 | K18: 1.6753427 | L18: 2.0868875 | M18: 2.4140773 | P18: United Kingdom | Q18: 2.3322602
B19: France | C19: 1.8189454 | D19: 1.7820667 | E19: 1.7891325 | F19: 1.7764374 | G19: 1.807669 | H19: 1.8115643 | I19: 2 | J19: 1.9084307 | K19: 1.8787598 | L19: 1.9561661 | M19: 2.0597449 | P19: Romania* | Q19: 2.2516278
B20: Germany | C20: 1.1851482 | D20: 1.1872804 | E20: 1.2014671 | F20: 1.2308501 | G20: 1.2499267 | H20: 1.3486151 | I20: 1.5129752 | J20: 1.4530777 | K20: 1.5055177 | L20: 1.6403681 | M20: 2.1189771 | P20: North Macedonia | Q20: 2.2213001
B21: Greece | C21: 2.2222501 | D21: 2.3094213 | E21: 2.4012363 | F21: 2.3788109 | G21: 2.5397877 | H21: 2.446345 | I21: 2.9106537 | J21: 3.6996897 | K21: 3.8810226 | L21: 2.8038345 | M21: 3.0759535 | P21: Norway | Q21: 2.1976529
B22: Hungary | C22: 0.85780963 | D22: 0.90472126 | E22: 1.0020207 | F22: 1.193553 | G22: 1.006068 | H22: 1.3352421 | I22: 1.7593761 | J22: 1.3235963 | K22: 1.8390929 | L22: 2.0520955 | M22: 2.1107658 | P22: Bulgaria | Q22: 2.1786672
B23: Italy | C23: 1.1396982 | D23: 1.0665243 | E23: 1.1782533 | F23: 1.2015006 | G23: 1.2252612 | H23: 1.1713127 | I23: 1.5882986 | J23: 1.5388288 | K23: 1.5229579 | L23: 1.4992085 | M23: 1.4910941 | P23: Sweden | Q23: 2.1432102
... B40: United States | C40: 3.7139173 | D40: 3.5050688 | E40: 3.4960803 | F40: 3.282088 | G40: 3.25713 | H40: 3.4715858 | I40: 3.5773431 | J40: 3.5268368 | K40: 3.3120711 | L40: 3.2324237 | M40: 3.3790207 | P40: Spain | Q40: 1.2825496
A41: NATO Europe and Canada | C41: 1.4278083 | D41: 1.4235905 | E41: 1.4385267 | F41: 1.4777917 | G41: 1.5116959 | H41: 1.5406884 | I41: 1.7213964 | J41: 1.6580388 | K41: 1.6586735 | L41: 1.7754775 | M41: 2.0154549
A42: NATO Total | C42: 2.5785806 | D42: 2.476506 | E42: 2.4789266 | F42: 2.3874315 | G42: 2.3961537 | H42: 2.5229166 | I42: 2.6851883 | J42: 2.6255994 | K42: 2.5076564 | L42: 2.5252497 | M42: 2.7127497
A43: Annual real change (%)
B44: Albania | C44: -2.7368169 | D44: -11.764668 | E44: -1.9033643 | F44: 4.3218159 | G44: 8.8399572 | H44: 12.667541 | I44: -2.1667338 | J44: 4.4670724 | K44: 1.9591316 | L44: 49.271643 | M44: 19.761391
B45: Belgium | C45: -2.2522512 | D45: -4.4441946 | E45: -0.3603787 | F45: 0.35673014 | G45: 2.6901681 | H45: 1.9039859 | I45: 7.9571576 | J45: 9.6371843 | K45: 17.249109 | L45: 3.7047201 | M45: 8.8917043
B46: Bulgaria | C46: -9.0840544 | D46: -1.5573648 | E46: 2.7988982 | F46: 0.95650082 | G46: 21.793331 | H46: 124.94424 | I46: -51.156887 | J46: 2.492389 | K46: 9.0738664 | L46: 25.374106 | M46: 13.294873
B47: Canada | C47: 4.9522691 | D47: 20.088503 | E47: -2.4793584 | F47: 27.756425 | G47: -7.1762297 | H47: 1.6110734 | I47: 3.3690359 | J47: -5.0788084 | K47: -2.0815686 | L47: 10.327213 | M47: 5.4631908
B48: Croatia | C48: 25.917065 | D48: -1.0336266 | E48: -5.9575535 | F48: 6.1527339 | G48: -2.8140755 | H48: 7.191736 | I48: -3.0207616 | J48: 30.815264 | K48: -2.3958622 | L48: 0.73284178 | M48: 7.1061074
B49: Czechia* | C49: -4.9073911 | D49: 14.137573 | E49: -4.6135264 | F49: 14.32019 | G49: 10.325207 | H49: 10.144201 | I49: 4.1077073 | J49: 10.604407 | K49: -1.2526657 | L49: 2.0093009 | M49: 54.650072
B50: Denmark | C50: -4.8398654 | D50: -1.0278473 | E50: 6.6183047 | F50: 1.9754692 | G50: 14.470383 | H50: 2.8787328 | I50: 3.7625236 | J50: 0.87281994 | K50: 8.0668286 | L50: 50.040956 | M50: 20.657174
B51: Estonia* | C51: 3.7417059 | D51: 7.4158573 | E51: 5.2407427 | F51: 2.6806591 | G51: 3.7339826 | H51: 5.3355714 | I51: 12.046964 | J51: -5.0148784 | K51: 5.7499335 | L51: 36.11741 | M51: 12.555511
B52: Finland | C52: -6.0346103 | D52: 0.41951529 | E52: 0.68356093 | F52: 0.54646302 | G52: 1.3887652 | H52: 5.984576 | I52: 2.8745548 | J52: -6.0737875 | K52: 21.497283 | L52: 23.276129 | M52: 15.24202
B53: France | C53: -1.2131587 | D53: -0.99957684 | E53: 1.3822079 | F53: 1.7337258 | G53: 3.6078497 | H53: 2.1079133 | I53: 1.2203739 | J53: 2.2003974 | K53: 0.93210939 | L53: 5.0247112 | M53: 6.0541227
B54: Germany | C54: -1.3940129 | D54: 1.4234037 | E54: 3.3622957 | F54: 5.5022539 | G54: 2.5692322 | H54: 9.0872666 | I54: 7.4783358 | J54: -0.95829229 | K54: 5.558246 | L54: 8.838564 | M54: 29.447101
B55: Greece | C55: 0.44036097 | D55: 3.7188861 | E55: 3.4690805 | F55: 0.14808221 | G55: 8.5484261 | H55: -1.941942 | I55: 8.2487831 | J55: 37.704413 | K55: 10.915052 | L55: -26.321933 | M55: 11.854749
... B74: United States | C74: -5.1874461 | D74: -2.8434935 | E74: 1.5583438 | F74: -3.8137265 | G74: 2.1835114 | H74: 9.2136683 | I74: 0.76547081 | J74: 4.30648 | K74: -4.2718402 | L74: 0.076797668 | M74: 7.2144066
A75: NATO Europe and Canada | C75: -0.88265697 | D75: 1.630658 | E75: 2.970455 | F75: 5.8863848 | G75: 4.24959 | H75: 3.6150637 | I75: 4.712781 | J75: 2.5425964 | K75: 3.7317687 | L75: 9.263441 | M75: 17.946747
A76: NATO Total | C76: -4.0413974 | D76: -1.6131464 | E76: 1.959463 | F76: -1.0310262 | G76: 2.8176404 | H76: 7.4713909 | I76: 1.94979 | J76: 3.7629159 | K76: -1.8344285 | L76: 3.0331246 | M76: 10.876994
B79: Notes: Figures for 2023 and 2024 are estimates. The NATO Europe and Canada and NATO Total aggregates from 2017 onwards include Montenegro, which became an Ally on 5 June 2017, from 2020 onwards include North Macedonia, which became an Ally on 27 March 2020, from 2023 onwards include Finland, which became an Ally on 4 April 2023 and from 2024 onwards include Sweden, which became an Ally on 7 March 2024.
B80: * These Allies have national laws or political agreements which call for 2% of GDP or more to be spent on defence annually, consequently future estimates are expected to change accordingly. For past years Allies defence spending was based on the then available GDP data and Allies may, therefore, have met the 2% guideline when using those figures. (In 2018 and 2021, Lithuania met 2% using November 2018 and June 2021 OECD figures respectively).
...

Sheet Sheet2
B4: Table 2 : Defence expenditure
B6: Million US dollars
D8: 2014 | E8: 2015 | F8: 2016 | G8: 2017 | H8: 2018 | I8: 2019 | J8: 2020 | K8: 2021 | L8: 2022 | M8: 2023e | N8: 2024e
B10: Current prices and exchange rates
C11: Albania | D11: 178.35898 | E11: 132.37558 | F11: 130.90963 | G11: 144.77419 | H11: 175.89413 | I11: 197.22583 | J11: 196.86414 | K11: 223.54009 | L11: 230.67313 | M11: 397.27315 | N11: 516.11402
C12: Belgium | D12: 5200.065 | E12: 4204.4456 | F12: 4258.1077 | G12: 4440.7219 | H12: 4844.9439 | I12: 4761.2725 | J12: 5323.5234 | K12: 6244.5696 | L12: 6903.7803 | M12: 7622.1596 | N12: 8519.1692
C13: Bulgaria | D13: 747.22738 | E13: 632.7187 | F13: 670.61571 | G13: 724.46443 | H13: 962.23357 | I13: 2158.5905 | J13: 1120.5263 | K13: 1275.9237 | L13: 1439.7805 | M13: 1991.7123 | N13: 2325.0942
C14: Canada | D14: 18172.422 | E14: 18689.408 | F14: 17708.229 | G14: 23699.965 | H14: 22398.896 | I14: 22572.158 | J14: 23329.916 | K14: 25501.96 | L14: 25897.621 | M14: 27990.9 | N14: 30495.235
C15: Croatia | D15: 1063.8005 | E15: 882.7259 | F15: 836.88627 | G15: 926.37808 | H15: 966.07152 | I15: 1001.2231 | J15: 982.64792 | K15: 1361.4874 | L15: 1284.5114 | M15: 1441.1141 | N15: 1624.034
C16: Czechia* | D16: 1975.311 | E16: 1921.3952 | F16: 1865.7359 | G16: 2258.9244 | H16: 2749.7675 | I16: 2981.5179 | J16: 3199.3461 | K16: 3914.7016 | L16: 3894.7089 | M16: 4538.0208 | N16: 6834.2901
C17: Denmark | D17: 4056.8723 | E17: 3363.9814 | F17: 3593.4043 | G17: 3780.3237 | H17: 4558.789 | I17: 4487.4486 | J17: 4885.5973 | K17: 5274.3981 | L17: 5472.7844 | M17: 8140.2646 | N17: 9939.6068
C18: Estonia* | D18: 513.52674 | E18: 463.4267 | F18: 497.43393 | G18: 541.19493 | H18: 615.22282 | I18: 637.07542 | J18: 719.48742 | K18: 749.27529 | L18: 819.63154 | M18: 1237.7407 | N18: 1437.3147
C19: Finland | D19: 3991.2437 | E19: 3400.8548 | F19: 3417.7441 | G19: 3535.5425 | H19: 3825.4817 | I19: 3899.5587 | J19: 4156.2339 | K19: 4145.3552 | L19: 4726.225 | M19: 6266.3757 | N19: 7307.8709
C20: France | D20: 52022.406 | E20: 43496.123 | F20: 44209.046 | G20: 46133.458 | H20: 50506.962 | I20: 49493.219 | J20: 52519.499 | K20: 56457.017 | L20: 52237.655 | M20: 59378.766 | N20: 64271.201
C21: Germany | D21: 46175.785 | E21: 39833.436 | F21: 41606.347 | G21: 45470.395 | H21: 49772.314 | I21: 52549.248 | J21: 58652.184 | K21: 62054.008 | L21: 61405.459 | M21: 73137.629 | N21: 97685.59
C22: Greece | D22: 5233.8241 | E22: 4519.6215 | F22: 4636.6695 | G22: 4752.24 | H22: 5388.0556 | I22: 5019.088 | J22: 5491.938 | K22: 8005.5509 | L22: 8487.7348 | M22: 6731.2515 | N22: 7684.0847
... C41: United States | D41: 653942 | E41: 641253 | F41: 656059 | G41: 642933 | H41: 672255 | I41: 750886 | J41: 770650 | K41: 824094 | L41: 834977 | M41: 875603 | N41: 967707
B42: NATO Europe and Canada | D42: 289275.58 | E42: 254422.34 | F42: 255594.75 | G42: 275102.41 | H42: 300167.06 | I42: 301674.24 | J42: 325952.59 | K42: 358835.9 | L42: 355382.35 | M42: 419204.62 | N42: 506692.48
B43: NATO Total | D43: 943217.58 | E43: 895675.34 | F43: 911653.75 | G43: 918035.41 | H43: 972422.06 | I43: 1052560.2 | J43: 1096602.6 | K43: 1182929.9 | L43: 1190359.4 | M43: 1294807.6 | N43: 1474399.5
B44: Constant 2015 prices and exchange rates
C45: Albania | D45: 150.0256 | E45: 132.37558 | F45: 129.856 | G45: 135.46813 | H45: 147.44346 | I45: 166.12092 | J45: 162.52152 | K45: 169.78147 | L45: 173.10772 | M45: 258.40073 | N45: 309.46431
C46: Belgium | D46: 4399.9897 | E46: 4204.4456 | F46: 4189.2937 | G46: 4204.2381 | H46: 4317.3392 | I46: 4399.5407 | J46: 4749.6191 | K46: 5207.3487 | L46: 6105.5699 | M46: 6331.7642 | N46: 6894.7659
C47: Bulgaria | D47: 642.72832 | E47: 632.7187 | F47: 650.42785 | G47: 656.6492 | H47: 799.75493 | I47: 1799.0027 | J47: 878.68892 | K47: 900.58927 | L47: 982.30753 | M47: 1231.5593 | N47: 1395.2935
C48: Canada | D48: 15563.029 | E48: 18689.408 | F48: 18226.031 | G48: 23284.925 | H48: 21613.945 | I48: 21962.162 | J48: 22702.075 | K48: 21549.08 | L48: 21100.521 | M48: 23279.617 | N48: 24551.427
C49: Croatia | D49: 891.94528 | E49: 882.7259 | F49: 830.13703 | G49: 881.21315 | H49: 856.41515 | I49: 918.00627 | J49: 890.27549 | K49: 1164.6162 | L49: 1136.7136 | M49: 1145.0439 | N49: 1226.412
C50: Czechia* | D50: 1683.4029 | E50: 1921.3952 | F50: 1832.7512 | G50: 2095.2046 | H50: 2311.5388 | I50: 2546.026 | J50: 2650.6093 | K50: 2931.6906 | L50: 2894.9664 | M50: 2953.1349 | N50: 4567.0253
C51: Denmark | D51: 3398.917 | E51: 3363.9814 | F51: 3586.6199 | G51: 3657.4725 | H51: 4186.7228 | I51: 4307.2473 | J51: 4469.3085 | K51: 4508.3175 | L51: 4871.9958 | M51: 7309.9891 | N51: 8820.0262
C52: Estonia* | D52: 431.43229 | E52: 463.4267 | F52: 487.7137 | G52: 500.78764 | H52: 519.48696 | I52: 547.20456 | J52: 613.12609 | K52: 582.37857 | L52: 615.86495 | M52: 838.29942 | N52: 943.55219
C53: Finland | D53: 3386.6473 | E53: 3400.8548 | F53: 3424.1017 | G53: 3442.8132 | H53: 3490.6258 | I53: 3699.5249 | J53: 3805.8698 | K53: 3574.7093 | L53: 4343.1747 | M53: 5354.0976 | N53: 6170.1703
C54: France | D54: 43935.29 | E54: 43496.123 | F54: 44097.329 | G54: 44861.856 | H54: 46480.405 | I54: 47460.171 | J54: 48039.363 | K54: 49096.42 | L54: 49554.052 | M54: 52044 | N54: 55194.808
C55: Germany | D55: 39274.402 | E55: 39833.436 | F55: 41172.754 | G55: 43438.183 | H55: 44554.211 | I55: 48602.971 | J55: 52237.664 | K55: 51737.075 | L55: 54612.748 | M55: 59439.731 | N55: 76943.009
C56: Greece | D56: 4357.5684 | E56: 4519.6215 | F56: 4676.4108 | G56: 4683.3357 | H56: 5083.6872 | I56: 4984.9649 | J56: 5396.1639 | K56: 7430.7558 | L56: 8241.8267 | M56: 6072.4186 | N56: 6792.2886
... C75: United States | D75: 660020.64 | E75: 641253 | F75: 651245.93 | G75: 626409.19 | H75: 640086.9 | I75: 699062.39 | J75: 704413.51 | K75: 734748.93 | L75: 703361.63 | M75: 703901.8 | N75: 754684.14
B76: NATO Europe and Canada | D76: 250340.15 | E76: 254422.34 | F76: 261979.84 | G76: 277400.98 | H76: 289189.39 | I76: 299643.77 | J76: 313765.32 | K76: 321743.11 | L76: 333749.81 | M76: 364666.53 | N76: 430112.31
B77: NATO Total | D77: 910360.79 | E77: 895675.34 | F77: 913225.77 | G77: 903810.17 | H77: 929276.29 | I77: 998706.15 | J77: 1018178.8 | K77: 1056492 | L77: 1037111.4 | M77: 1068568.3 | N77: 1184796.4
C80: Notes: Figures for 2023 and 2024 are estimates. The NATO Europe and Canada and NATO Total aggregates from 2017 onwards include Montenegro, which became an Ally on 5 June 2017, from 2020 onwards include North Macedonia, which became an Ally on 27 March 2020, from 2023 onwards include Finland, which became an Ally on 4 April 2023 and from 2024 onwards include Sweden, which became an Ally on 7 March 2024.
C81: * These Allies have national laws or political agreements which call for 2% of GDP or more to be spent on defence annually, consequently future estimates are expected to change accordingly. For past years Allies defence spending was based on the then available GDP data and Allies may, therefore, have met the 2% guideline when using those figures. (In 2018 and 2021, Lithuania met 2% using November 2018 and June 2021 OECD figures respectively).
B83: -8-

Sheet HAVERM
A4: 201001 !M | B4: K23K@UK | C4: K23W@UK | D4: K23X@UK | E4: S2LF@UK | F4: ECY9@UK | G4: ECY2@UK
A5: .DESC | B5: UK: Industrial Production: Fabricated Metal Products (SA, 2022=100) | C5: UK: Industrial Production: Building of Ships & Boats(SA, 2022=100) | D5: UK: Industrial Production: Air & Spacecraft & Related Machinery(SA, 2022=100) | E5: UK: Idx of Svcs: Comp Programming/Consultancy & Related Activities(SA, 2022=100) | F5: UK: Gross Value Added Chained Volume Index: Construction (SA, 2022=100) | G5: UK: Gross Value Added Chained Volume Index (SA, 2022=100)
A6: .T1 | B6: Jan-1997 | C6: Jan-1997 | D6: Jan-1997 | E6: Jan-1997 | F6: Jan-1997 | G6: Jan-1997
A7: .TN | B7: Dec-2024 | C7: Dec-2024 | D7: Dec-2024 | E7: Dec-2024 | F7: Dec-2024 | G7: Dec-2024
A8: .DTLM | B8: Feb-13-2025 07:05 | C8: Feb-13-2025 07:05 | D8: Feb-13-2025 07:05 | E8: Feb-13-2025 07:03 | F8: Feb-13-2025 07:02 | G8: Feb-13-2025 07:02
A9: 201001 | B9: 76 | C9: 53.7 | D9: 94.5 | E9: 63.1 | F9: 73.8 | G9: 80
A10: 201002 | B10: 77.2 | C10: 54.3 | D10: 93.7 | E10: 64.4 | F10: 77.1 | G10: 81.3
A11: 201003 | B11: 79.9 | C11: 54.3 | D11: 92.2 | E11: 64.3 | F11: 77.6 | G11: 81.9
A12: 201004 | B12: 81.6 | C12: 53.8 | D12: 92.8 | E12: 60.9 | F12: 78.6 | G12: 81.6
A13: 201005 | B13: 81 | C13: 53.2 | D13: 94.7 | E13: 61.1 | F13: 80.2 | G13: 82.2
A14: 201006 | B14: 83.1 | C14: 52.1 | D14: 97.3 | E14: 62.5 | F14: 81.3 | G14: 82.2
A15: 201007 | B15: 89.5 | C15: 50.8 | D15: 101.1 | E15: 63.2 | F15: 80.3 | G15: 82.3
A16: 201008 | B16: 85 | C16: 49.2 | D16: 105.2 | E16: 63.2 | F16: 83.5 | G16: 82.4
A17: 201009 | B17: 84.6 | C17: 47.5 | D17: 110.9 | E17: 64.8 | F17: 82 | G17: 82.6
A18: 201010 | B18: 85.8 | C18: 46.1 | D18: 118.9 | E18: 62.9 | F18: 81.6 | G18: 82.9
A19: 201011 | B19: 89.5 | C19: 44.6 | D19: 123.5 | E19: 62.5 | F19: 81.4 | G19: 82.7
A20: 201012 | B20: 88.8 | C20: 43.3 | D20: 133.6 | E20: 68.3 | F20: 79 | G20: 82
... A188: 202412 | B188: 107.3 | C188: 122.2 | D188: 100.9 | E188: 96.3 | F188: 103.4 | G188: 101.6

Sheet Charts--->

Sheet Analysis--->

Sheet International Comparison
B4: UK | C4: US | D4: NATO Europe and Canada | E4: NATO | H4: UK | I4: US | J4: NATO Europe and Canada | K4: NATO
A5: 2014 | B5: =OFFSET(NATO2!$C$39,0,ROW()-ROW('International Comparison'!$A$5)) -> 2.1423757 | C5: =OFFSET(NATO2!$C$40,0,ROW()-ROW('International Comparison'!$A$5)) -> 3.7139173 | D5: =OFFSET(NATO2!$C$41,0,ROW()-ROW('International Comparison'!$A$5)) -> 1.4278083 | E5: =OFFSET(NATO2!$C$42,0,ROW()-ROW('International Comparison'!$A$5)) -> 2.5785806 | G5: 2014-2021 average | H5: =AVERAGE(B5:B12) -> 2.145362 | I5: =AVERAGE(C5:C11) -> 3.4718876 | J5: =AVERAGE(D5:D11) -> 1.5059283 | K5: =AVERAGE(E5:E11) -> 2.5036719 | L5: 2
A6: =A5+1 -> 2015 | B6: =OFFSET(NATO2!$C$39,0,ROW()-ROW('International Comparison'!$A$5)) -> 2.0318996 | C6: =OFFSET(NATO2!$C$40,0,ROW()-ROW('International Comparison'!$A$5)) -> 3.5050688 | D6: =OFFSET(NATO2!$C$41,0,ROW()-ROW('International Comparison'!$A$5)) -> 1.4235905 | E6: =OFFSET(NATO2!$C$42,0,ROW()-ROW('International Comparison'!$A$5)) -> 2.476506 | G6: 2022 | H6: =B13 -> 2.2852877 | I6: =C13 -> 3.3120711 | J6: =D13 -> 1.6586735 | K6: =E13 -> 2.5076564 | L6: 2
A7: =A6+1 -> 2016 | B7: =OFFSET(NATO2!$C$39,0,ROW()-ROW('International Comparison'!$A$5)) -> 2.0882049 | C7: =OFFSET(NATO2!$C$40,0,ROW()-ROW('International Comparison'!$A$5)) -> 3.4960803 | D7: =OFFSET(NATO2!$C$41,0,ROW()-ROW('International Comparison'!$A$5)) -> 1.4385267 | E7: =OFFSET(NATO2!$C$42,0,ROW()-ROW('International Comparison'!$A$5)) -> 2.4789266 | G7: 2023 | H7: =B14 -> 2.3026834 | I7: =C14 -> 3.2324237 | J7: =D14 -> 1.7754775 | K7: =E14 -> 2.5252497 | L7: 2
A8: =A7+1 -> 2017 | B8: =OFFSET(NATO2!$C$39,0,ROW()-ROW('International Comparison'!$A$5)) -> 2.077205 | C8: =OFFSET(NATO2!$C$40,0,ROW()-ROW('International Comparison'!$A$5)) -> 3.282088 | D8: =OFFSET(NATO2!$C$41,0,ROW()-ROW('International Comparison'!$A$5)) -> 1.4777917 | E8: =OFFSET(NATO2!$C$42,0,ROW()-ROW('International Comparison'!$A$5)) -> 2.3874315 | G8: 2024 | H8: =B15 -> 2.3322602 | I8: =C15 -> 3.3790207 | J8: =D15 -> 2.0154549 | K8: =E15 -> 2.7127497 | L8: 2
A9: =A8+1 -> 2018 | B9: =OFFSET(NATO2!$C$39,0,ROW()-ROW('International Comparison'!$A$5)) -> 2.1001679 | C9: =OFFSET(NATO2!$C$40,0,ROW()-ROW('International Comparison'!$A$5)) -> 3.25713 | D9: =OFFSET(NATO2!$C$41,0,ROW()-ROW('International Comparison'!$A$5)) -> 1.5116959 | E9: =OFFSET(NATO2!$C$42,0,ROW()-ROW('International Comparison'!$A$5)) -> 2.3961537
A10: =A9+1 -> 2019 | B10: =OFFSET(NATO2!$C$39,0,ROW()-ROW('International Comparison'!$A$5)) -> 2.0819422 | C10: =OFFSET(NATO2!$C$40,0,ROW()-ROW('International Comparison'!$A$5)) -> 3.4715858 | D10: =OFFSET(NATO2!$C$41,0,ROW()-ROW('International Comparison'!$A$5)) -> 1.5406884 | E10: =OFFSET(NATO2!$C$42,0,ROW()-ROW('International Comparison'!$A$5)) -> 2.5229166
A11: =A10+1 -> 2020 | B11: =OFFSET(NATO2!$C$39,0,ROW()-ROW('International Comparison'!$A$5)) -> 2.352082 | C11: =OFFSET(NATO2!$C$40,0,ROW()-ROW('International Comparison'!$A$5)) -> 3.5773431 | D11: =OFFSET(NATO2!$C$41,0,ROW()-ROW('International Comparison'!$A$5)) -> 1.7213964 | E11: =OFFSET(NATO2!$C$42,0,ROW()-ROW('International Comparison'!$A$5)) -> 2.6851883
A12: =A11+1 -> 2021 | B12: =OFFSET(NATO2!$C$39,0,ROW()-ROW('International Comparison'!$A$5)) -> 2.2890189 | C12: =OFFSET(NATO2!$C$40,0,ROW()-ROW('International Comparison'!$A$5)) -> 3.5268368 | D12: =OFFSET(NATO2!$C$41,0,ROW()-ROW('International Comparison'!$A$5)) -> 1.6580388 | E12: =OFFSET(NATO2!$C$42,0,ROW()-ROW('International Comparison'!$A$5)) -> 2.6255994
A13: =A12+1 -> 2022 | B13: =OFFSET(NATO2!$C$39,0,ROW()-ROW('International Comparison'!$A$5)) -> 2.2852877 | C13: =OFFSET(NATO2!$C$40,0,ROW()-ROW('International Comparison'!$A$5)) -> 3.3120711 | D13: =OFFSET(NATO2!$C$41,0,ROW()-ROW('International Comparison'!$A$5)) -> 1.6586735 | E13: =OFFSET(NATO2!$C$42,0,ROW()-ROW('International Comparison'!$A$5)) -> 2.5076564
A14: =A13+1 -> 2023 | B14: =OFFSET(NATO2!$C$39,0,ROW()-ROW('International Comparison'!$A$5)) -> 2.3026834 | C14: =OFFSET(NATO2!$C$40,0,ROW()-ROW('International Comparison'!$A$5)) -> 3.2324237 | D14: =OFFSET(NATO2!$C$41,0,ROW()-ROW('International Comparison'!$A$5)) -> 1.7754775 | E14: =OFFSET(NATO2!$C$42,0,ROW()-ROW('International Comparison'!$A$5)) -> 2.5252497
A15: =A14+1 -> 2024 | B15: =OFFSET(NATO2!$C$39,0,ROW()-ROW('International Comparison'!$A$5)) -> 2.3322602 | C15: =OFFSET(NATO2!$C$40,0,ROW()-ROW('International Comparison'!$A$5)) -> 3.3790207 | D15: =OFFSET(NATO2!$C$41,0,ROW()-ROW('International Comparison'!$A$5)) -> 2.0154549 | E15: =OFFSET(NATO2!$C$42,0,ROW()-ROW('International Comparison'!$A$5)) -> 2.7127497

Sheet Fiscal position
H2: OE | L2: OBR | P2: Red Book | S2: % of GDP | W2: NATO spending | Z2: % of GDP | AD2: To hit 3% | AI2: OBR headroom calculation | AM2: 3% headroom calculation | AQ2: Debt rule calculation>>> | AX2: Headroom chart>>> | AY2: Borrowing to invest | AZ2: Debt-to-GDP falling in 5 years' time | BF2: Waterfall chart>>>
D3: Nominal GDP | E3: Current balance | H3: Nominal GDP | I3: Current balance | J3: % of GDP | L3: Nominal GDP | M3: Current balance | N3: % of GDP | P3: DEL | Q3: RDEL | R3: CDEL | S3: DEL | T3: RDEL | U3: CDEL | W3: DEL | X3: RDEL | Y3: CDEL | Z3: DEL | AA3: RDEL | AB3: CDEL | AI3: Total defence | AJ3: RDEL | AK3: CDEL | AM3: Total defence | AN3: RDEL | AO3: CDEL | AX3: Increasing defence spending to 2.5% | AY3: =AJ35 -> 3.5054372 | AZ3: =AI35 -> 10.205437 | BB3: 1.5 | BC3: 0 | BG3: Autumn budget headroom | BH3: 9.9 | BI3: 0
A4: CY | B4: FY | D4: GDP! | E4: PSCB | AX4: Increasing defence spending to 3% | AY4: =AN35 -> 13.805437 | AZ4: =AM35 -> 27.205437 | BB4: 1.5 | BC4: 35 | BG4: Reduced aid spending | BH4: 9.9 | BI4: =AQ34 -> 6.7945628
A5: 2000 | B5: 2000 | C5: 2000 Q1 | D5: =INDEX(GMW!$A:$NF,MATCH('Fiscal position'!D$4,GMW!$NE:$NE,0),MATCH('Fiscal position'!$C5,GMW!$1:$1,0)) -> 272305 | E5: =INDEX(GMW!$A:$NF,MATCH('Fiscal position'!E$4,GMW!$NE:$NE,0),MATCH('Fiscal position'!$C5,GMW!$1:$1,0)) -> 15211 | G5: 2000-01 | H5: =SUMIFS(D:D,$B:$B,"=20"&RIGHT($G5,2))/1000 -> 1111.336 | I5: =SUMIFS(E:E,$B:$B,"=20"&RIGHT($G5,2))/1000 -> 20.728 | J5: =I5/H5*100 -> 1.8651425 | L5: =OBR!AE62 -> 1114.688 | M5: =-OBR!Q62 -> 20.728 | N5: =M5/L5*100 -> 1.8595338 | AX5: Headroom in Autumn Budget | AY5: 9.9 | AZ5: 15.7 | BG5: Increased current defence spending* | BH5: =SUM(BH4:BI4)-BI5 -> 12.331499 | BI5: =AR34 -> 4.3630638
A6: 2000 | B6: 2001 | C6: 2000 Q2 | D6: =INDEX(GMW!$A:$NF,MATCH('Fiscal position'!D$4,GMW!$NE:$NE,0),MATCH('Fiscal position'!$C6,GMW!$1:$1,0)) -> 273916 | E6: =INDEX(GMW!$A:$NF,MATCH('Fiscal position'!E$4,GMW!$NE:$NE,0),MATCH('Fiscal position'!$C6,GMW!$1:$1,0)) -> 3302 | G6: 2001-02 | H6: =SUMIFS(D:D,$B:$B,"=20"&RIGHT($G6,2))/1000 -> 1155.732 | I6: =SUMIFS(E:E,$B:$B,"=20"&RIGHT($G6,2))/1000 -> 6.85 | J6: =I6/H6*100 -> 0.59269796 | L6: =OBR!AE63 -> 1152.363 | M6: =-OBR!Q63 -> 6.85 | N6: =M6/L6*100 -> 0.59443075 | BG6: Higher market interest rates | BH6: =BH5-BI6 -> 6.2314991 | BI6: 6.1
