Workbook
Name _DLX1.INC: HAVERD!$B$3:$L$8
Name _DLX2.INC: HAVERM!$A$1:$E$6
Name Data: [1]sheet0!$C$2
Name KPSA_Table: 'KPSA - Jul'!$A$10:$K$458
Name KPSA_Table2: 'KPSA - Jul'!$A$464:$K$911
Name KPSA3_Table1: 'KPSA3 - Jul'!$A$9:$K$457
Name KPSA3_Table2: 'KPSA3 - Jul'!$A$463:$K$910

Sheet Chart Data
A1: Retail sales level | F1: Retail sales m/m change
B2: New | C2: Old | D2: revision | G2: New | H2: Old
A3: 44927 | B3: =HAVERM!B43 -> 98 | C3: ='KPSA - Jul'!B430 -> 98 | D3: =100*((B3/C3)-1) -> 0 | F3: 44927 | G3: =HAVERM!C43 -> 0.6 | H3: ='KPSA3 - Jul'!B429 -> 0.6
A4: 44958 | B4: =HAVERM!B44 -> 98.2 | C4: ='KPSA - Jul'!B431 -> 98.2 | D4: =100*((B4/C4)-1) -> 0 | F4: 44958 | G4: =HAVERM!C44 -> 0.2 | H4: ='KPSA3 - Jul'!B430 -> 0.3
A5: 44986 | B5: =HAVERM!B45 -> 97 | C5: ='KPSA - Jul'!B432 -> 97.3 | D5: =100*((B5/C5)-1) -> -0.30832477 | F5: 44986 | G5: =HAVERM!C45 -> -1.2 | H5: ='KPSA3 - Jul'!B431 -> -0.9
A6: 45017 | B6: =HAVERM!B46 -> 98.4 | C6: ='KPSA - Jul'!B433 -> 97.9 | D6: =100*((B6/C6)-1) -> 0.51072523 | F6: 45017 | G6: =HAVERM!C46 -> 1.4 | H6: ='KPSA3 - Jul'!B432 -> 0.6
A7: 45047 | B7: =HAVERM!B47 -> 97.5 | C7: ='KPSA - Jul'!B434 -> 97.7 | D7: =100*((B7/C7)-1) -> -0.20470829 | F7: 45047 | G7: =HAVERM!C47 -> -1 | H7: ='KPSA3 - Jul'!B433 -> -0.3
A8: 45078 | B8: =HAVERM!B48 -> 98.4 | C8: ='KPSA - Jul'!B435 -> 98.1 | D8: =100*((B8/C8)-1) -> 0.3058104 | F8: 45078 | G8: =HAVERM!C48 -> 0.9 | H8: ='KPSA3 - Jul'!B434 -> 0.4
A9: 45108 | B9: =HAVERM!B49 -> 96.9 | C9: ='KPSA - Jul'!B436 -> 97 | D9: =100*((B9/C9)-1) -> -0.10309278 | F9: 45108 | G9: =HAVERM!C49 -> -1.5 | H9: ='KPSA3 - Jul'!B435 -> -1.1
A10: 45139 | B10: =HAVERM!B50 -> 97 | C10: ='KPSA - Jul'!B437 -> 97.2 | D10: =100*((B10/C10)-1) -> -0.20576132 | F10: 45139 | G10: =HAVERM!C50 -> 0.2 | H10: ='KPSA3 - Jul'!B436 -> 0.2
A11: 45170 | B11: =HAVERM!B51 -> 96.1 | C11: ='KPSA - Jul'!B438 -> 96.2 | D11: =100*((B11/C11)-1) -> -0.1039501 | F11: 45170 | G11: =HAVERM!C51 -> -1 | H11: ='KPSA3 - Jul'!B437 -> -1
A12: 45200 | B12: =HAVERM!B52 -> 96.2 | C12: ='KPSA - Jul'!B439 -> 96.3 | D12: =100*((B12/C12)-1) -> -0.10384216 | F12: 45200 | G12: =HAVERM!C52 -> 0.2 | H12: ='KPSA3 - Jul'!B438 -> 0.1
A13: 45231 | B13: =HAVERM!B53 -> 97.6 | C13: ='KPSA - Jul'!B440 -> 97.8 | D13: =100*((B13/C13)-1) -> -0.20449898 | F13: 45231 | G13: =HAVERM!C53 -> 1.5 | H13: ='KPSA3 - Jul'!B439 -> 1.7
A14: 45261 | B14: =HAVERM!B54 -> 94.3 | C14: ='KPSA - Jul'!B441 -> 94.4 | D14: =100*((B14/C14)-1) -> -0.1059322 | F14: 45261 | G14: =HAVERM!C54 -> -3.4 | H14: ='KPSA3 - Jul'!B440 -> -3.5
... A32: 45809 | B32: =HAVERM!B72 -> 97.9 | C32: ='KPSA - Jul'!B459 -> 98.4 | D32: =100*((B32/C32)-1) -> -0.50813008 | F32: 45809 | G32: =HAVERM!C72 -> 0.3 | H32: ='KPSA3 - Jul'!B458 -> 0.9
A33: 45839 | B33: =HAVERM!B73 -> 98.4 | F33: 45839 | G33: =HAVERM!C73 -> 0.6

Sheet HAVERD
M1: June average
C2: UK | D2: US | E2: Germany | F2: $/£ | G2: €/£ | J2: Spread: UK-US | K2: Spread: UK-Germany | M2: Spread: UK-US | N2: Spread: UK-Germany
B3: 20240101 !D | C3: T112GA@INTDAILY | D3: R111GA@INTDAILY | E3: T134GA@INTDAILY | F3: X112USB@INTDAILY | G3: X112EUB@INTDAILY
B4: .DESC | C4: UK: 10-Yr Government Bond Yield (%) | D4: U.S.: 10-Year Treasury Note Yield at Constant Maturity ( % p.a.) | E4: Germany: 10-Yr Government Bond Yield (%) | F4: UK: Spot Exchange Rate: US Dollar (US$/GBP) | G4: UK: Spot Exchange Rate: Euro (Euros/GBP)
B5: .T1 | C5: 26-Jan-1994 | D5: 02-Jan-1962 | E5: 10-Jan-1994 | F5: 02-Jan-1975 | G5: 04-Jan-1999
B6: .TN | C6: 03-Jul-2025 | D6: 03-Jul-2025 | E6: 03-Jul-2025 | F6: 02-Jul-2025 | G6: 02-Jul-2025
B7: .LSOURCE | C7: London Stock Exchange Group | D7: U.S. Treasury | E7: London Stock Exchange Group | F7: Bank of England | G7: Bank of England
B8: .DTLM | C8: Jul-03-2025 20:51 | D8: Jul-03-2025 19:52 | E8: Jul-03-2025 20:51 | F8: Jul-03-2025 09:30 | G8: Jul-03-2025 09:30
A9: 45292 | B9: 20240101 | C9: #N/A | D9: #N/A | E9: 2.02 | F9: #N/A | G9: #N/A | J9: =C9-D9 -> #N/A | K9: =C9-E9 -> #N/A
A10: 45293 | B10: 20240102 | C10: 3.65 | D10: 3.95 | E10: 2.07 | F10: 1.2625 | G10: 1.1536 | J10: =C10-D10 -> -0.3 | K10: =C10-E10 -> 1.58
A11: 45294 | B11: 20240103 | C11: 3.61 | D11: 3.91 | E11: 2 | F11: 1.2628 | G11: 1.158 | J11: =C11-D11 -> -0.3 | K11: =C11-E11 -> 1.61
A12: 45295 | B12: 20240104 | C12: 3.74 | D12: 3.99 | E12: 2.13 | F12: 1.2699 | G12: 1.1591 | J12: =C12-D12 -> -0.25 | K12: =C12-E12 -> 1.61
A13: 45296 | B13: 20240105 | C13: 3.81 | D13: 4.05 | E13: 2.18 | F13: 1.2752 | G13: 1.1615 | J13: =C13-D13 -> -0.24 | K13: =C13-E13 -> 1.63
A14: =+A9+7 -> 45299 | B14: 20240108 | C14: 3.77 | D14: 4.01 | E14: 2.14 | F14: 1.275 | G14: 1.1623 | J14: =C14-D14 -> -0.24 | K14: =C14-E14 -> 1.63
A15: =+A10+7 -> 45300 | B15: 20240109 | C15: 3.79 | D15: 4.02 | E15: 2.19 | F15: 1.2704 | G15: 1.1636 | J15: =C15-D15 -> -0.23 | K15: =C15-E15 -> 1.6
A16: =+A11+7 -> 45301 | B16: 20240110 | C16: 3.82 | D16: 4.04 | E16: 2.23 | F16: 1.2736 | G16: 1.1612 | J16: =C16-D16 -> -0.22 | K16: =C16-E16 -> 1.59
A17: =+A12+7 -> 45302 | B17: 20240111 | C17: 3.85 | D17: 3.98 | E17: 2.19 | F17: 1.2714 | G17: 1.1615 | J17: =C17-D17 -> -0.13 | K17: =C17-E17 -> 1.66
A18: =+A13+7 -> 45303 | B18: 20240112 | C18: 3.8 | D18: 3.96 | E18: 2.16 | F18: 1.2761 | G18: 1.1637 | J18: =C18-D18 -> -0.16 | K18: =C18-E18 -> 1.64
A19: =+A14+7 -> 45306 | B19: 20240115 | C19: 3.8 | D19: #N/A | E19: 2.2 | F19: 1.2731 | G19: 1.1626 | J19: =C19-D19 -> #N/A | K19: =C19-E19 -> 1.6
A20: =+A15+7 -> 45307 | B20: 20240116 | C20: 3.83 | D20: 4.07 | E20: 2.25 | F20: 1.2665 | G20: 1.1635 | J20: =C20-D20 -> -0.24 | K20: =C20-E20 -> 1.58
A21: =+A16+7 -> 45308 | B21: 20240117 | C21: 3.98 | D21: 4.1 | E21: 2.28 | F21: 1.2658 | G21: 1.1667 | J21: =C21-D21 -> -0.12 | K21: =C21-E21 -> 1.7
A22: =+A17+7 -> 45309 | B22: 20240118 | C22: 3.94 | D22: 4.14 | E22: 2.32 | F22: 1.2672 | G22: 1.1677 | J22: =C22-D22 -> -0.2 | K22: =C22-E22 -> 1.62
A23: =+A18+7 -> 45310 | B23: 20240119 | C23: 3.92 | D23: 4.15 | E23: 2.3 | F23: 1.268 | G23: 1.1652 | J23: =C23-D23 -> -0.23 | K23: =C23-E23 -> 1.62
A24: =+A19+7 -> 45313 | B24: 20240122 | C24: 3.91 | D24: 4.11 | E24: 2.26 | F24: 1.2721 | G24: 1.1687 | J24: =C24-D24 -> -0.2 | K24: =C24-E24 -> 1.65
A25: =+A20+7 -> 45314 | B25: 20240123 | C25: 4 | D25: 4.14 | E25: 2.35 | F25: 1.2666 | G25: 1.1694 | J25: =C25-D25 -> -0.14 | K25: =C25-E25 -> 1.65
A26: =+A21+7 -> 45315 | B26: 20240124 | C26: 4 | D26: 4.18 | E26: 2.35 | F26: 1.2753 | G26: 1.1699 | J26: =C26-D26 -> -0.18 | K26: =C26-E26 -> 1.65
A27: =+A22+7 -> 45316 | B27: 20240125 | C27: 3.99 | D27: 4.14 | E27: 2.29 | F27: 1.27 | G27: 1.1725 | J27: =C27-D27 -> -0.15 | K27: =C27-E27 -> 1.7
A28: =+A23+7 -> 45317 | B28: 20240126 | C28: 3.97 | D28: 4.15 | E28: 2.3 | F28: 1.2723 | G28: 1.1711 | J28: =C28-D28 -> -0.18 | K28: =C28-E28 -> 1.67
A29: =+A24+7 -> 45320 | B29: 20240129 | C29: 3.88 | D29: 4.08 | E29: 2.23 | F29: 1.2678 | G29: 1.1742 | J29: =C29-D29 -> -0.2 | K29: =C29-E29 -> 1.65
A30: =+A25+7 -> 45321 | B30: 20240130 | C30: 3.9 | D30: 4.06 | E30: 2.27 | F30: 1.2666 | G30: 1.1688 | J30: =C30-D30 -> -0.16 | K30: =C30-E30 -> 1.63
A31: =+A26+7 -> 45322 | B31: 20240131 | C31: 3.79 | D31: 3.99 | E31: 2.17 | F31: 1.2733 | G31: 1.1723 | J31: =C31-D31 -> -0.2 | K31: =C31-E31 -> 1.62
... A43: =+A38+7 -> 45338 | B43: 20240216 | C43: 4.11 | D43: 4.3 | E43: 2.4 | F43: 1.2584 | G43: 1.1683 | J43: =C43-D43 -> -0.19 | K43: =C43-E43 -> 1.71
A44: =+A39+7 -> 45341 | B44: 20240219 | C44: 4.12 | D44: #N/A | E44: 2.42 | F44: 1.2587 | G44: 1.1689 | J44: =C44-D44 -> #N/A | K44: =C44-E44 -> 1.7
A45: =+A40+7 -> 45342 | B45: 20240220 | C45: 4.05 | D45: 4.27 | E45: 2.38 | F45: 1.2662 | G45: 1.17 | J45: =C45-D45 -> -0.22 | K45: =C45-E45 -> 1.67
A46: =+A41+7 -> 45343 | B46: 20240221 | C46: 4.1 | D46: 4.32 | E46: 2.45 | F46: 1.2612 | G46: 1.1672 | J46: =C46-D46 -> -0.22 | K46: =C46-E46 -> 1.65
A47: =+A42+7 -> 45344 | B47: 20240222 | C47: 4.11 | D47: 4.33 | E47: 2.44 | F47: 1.2621 | G47: 1.1675 | J47: =C47-D47 -> -0.22 | K47: =C47-E47 -> 1.67
A48: =+A43+7 -> 45345 | B48: 20240223 | C48: 4.11 | D48: 4.26 | E48: 2.37 | F48: 1.2677 | G48: 1.1715 | J48: =C48-D48 -> -0.15 | K48: =C48-E48 -> 1.74
A49: =+A44+7 -> 45348 | B49: 20240226 | C49: 4.15 | D49: 4.28 | E49: 2.43 | F49: 1.2684 | G49: 1.1689 | J49: =C49-D49 -> -0.13 | K49: =C49-E49 -> 1.72
A50: =+A45+7 -> 45349 | B50: 20240227 | C50: 4.19 | D50: 4.31 | E50: 2.47 | F50: 1.2683 | G50: 1.1692 | J50: =C50-D50 -> -0.12 | K50: =C50-E50 -> 1.72
A51: =+A46+7 -> 45350 | B51: 20240228 | C51: 4.18 | D51: 4.27 | E51: 2.46 | F51: 1.2653 | G51: 1.168 | J51: =C51-D51 -> -0.09 | K51: =C51-E51 -> 1.72
...

Sheet HAVERM
A1: 202001 !M | B1: J5EK@UK | C1: J5EC@UK
A2: .DESC | B2: Great Britain: Retail Sales Volume: Retailing including Auto Fuel(SA,2022=100) | C2: Great Britain: Retail Sales Volume: Retailing Inc Auto Fuel(SA, Mo/Mo %Chg)
A3: .T1 | B3: Jan-1996 | C3: Feb-1996
A4: .TN | B4: Jul-2025 | C4: Jul-2025
A5: .LSOURCE | B5: Office for National Statistics | C5: Office for National Statistics
A6: .DTLM | B6: Sep-05-2025 07:03 | C6: Sep-05-2025 07:03
A7: 202001 | B7: 101.1 | C7: 0
A8: 202002 | B8: 100.6 | C8: -0.5
A9: 202003 | B9: 94.5 | C9: -6.1
A10: 202004 | B10: 77.8 | C10: -17.7
A11: 202005 | B11: 88.3 | C11: 13.5
A12: 202006 | B12: 99.3 | C12: 12.6
A13: 202007 | B13: 104.1 | C13: 4.8
A14: 202008 | B14: 105.6 | C14: 1.4
A15: 202009 | B15: 107.2 | C15: 1.5
A16: 202010 | B16: 108 | C16: 0.8
A17: 202011 | B17: 103 | C17: -4.7
A18: 202012 | B18: 103.8 | C18: 0.8
... A73: 202507 | B73: 98.4 | C73: 0.6

Sheet KPSA - Jul
A1: KPSA - RETAIL SALES INDEX: CHAINED VOLUME OF RETAIL SALES SEASONALLY ADJUSTED
A2: This worksheet contains two tables presented vertically with one above the other and a blank row between the two tables
A3: Source: Retail Sales Index
A4: Index 2022=100
A5: Some cells in this table are empty because data was not collected for these variables at these time points.
A6: Index numbers of sales per week
A7: Time Period | B7: All retailing including automotive fuel [note1] | C7: All retailing excluding automotive fuel [Note 1] | D7: Predominantly food stores | E7: Total of predominantly non-food stores [Note 2] | F7: Non-specialised stores [Note 2] | G7: Textile, clothing and footwear stores [Note 2] | H7: Household goods stores [Note 2] | I7: Other stores [Note 2] | J7: Non-store retailing | K7: Predominantly automotive fuel [Note 1]
A8: Agg/SIC | B8: Agg 21 | C8: Agg 21X | D8: Agg 1 | E8: Agg 12 | F8: 47.19 | G8: Agg 5 | H8: Agg 7 | I8: Agg 13 | J8: Agg 14 | K8: 47.30
A9: Dataset identifier code | B9: J5EK | C9: J467 | D9: EAPT | E9: EAPV | F9: EAPU | G9: EAPX | H9: EAPY | I9: EAPW | J9: J5DZ | K9: JO5A
A10: 1988 Jan | C10: 50 | D10: 61.7 | E10: 47.7 | F10: 50.2 | G10: 37.8 | H10: 64 | I10: 46.7 | J10: 27.5
A11: 1988 Feb | C11: 48.9 | D11: 61.6 | E11: 46.2 | F11: 49.8 | G11: 36.3 | H11: 61.5 | I11: 45.3 | J11: 26.1
A12: 1988 Mar | C12: 49.1 | D12: 61.7 | E12: 46.3 | F12: 50.1 | G12: 35.7 | H12: 62.5 | I12: 45.5 | J12: 27.1
A13: 1988 Apr | C13: 49.8 | D13: 62.1 | E13: 47.1 | F13: 50.3 | G13: 36.3 | H13: 63.9 | I13: 46.5 | J13: 27.7
A14: 1988 May | C14: 49.7 | D14: 61.6 | E14: 47.2 | F14: 50.8 | G14: 36.3 | H14: 63.7 | I14: 46.5 | J14: 27.8
A15: 1988 Jun | C15: 50.2 | D15: 61.8 | E15: 48 | F15: 51.1 | G15: 37.3 | H15: 64.5 | I15: 47.4 | J15: 28
A16: 1988 Jul | C16: 50.9 | D16: 61.5 | E16: 49.2 | F16: 50.9 | G16: 37.4 | H16: 69.1 | I16: 48.3 | J16: 28.3
A17: 1988 Aug | C17: 50.9 | D17: 62.1 | E17: 48.9 | F17: 51.2 | G17: 37.5 | H17: 67 | I17: 48.6 | J17: 28.1
A18: 1988 Sep | C18: 50.6 | D18: 61.9 | E18: 48.7 | F18: 51.4 | G18: 37.6 | H18: 66.5 | I18: 48.1 | J18: 27.3
A19: 1988 Oct | C19: 51.5 | D19: 62.6 | E19: 49.6 | F19: 52.2 | G19: 38.2 | H19: 67.6 | I19: 49.1 | J19: 28.3
A20: 1988 Nov | C20: 51.7 | D20: 62.9 | E20: 49.9 | F20: 52.3 | G20: 38.8 | H20: 67.4 | I20: 49.7 | J20: 28.4
A21: 1988 Dec | C21: 51.8 | D21: 63.5 | E21: 49.7 | F21: 51.2 | G21: 38.2 | H21: 67.1 | I21: 50.2 | J21: 28.3
... A105: 1995 Dec | C105: 55.1 | D105: 70.5 | E105: 53.2 | F105: 56.5 | G105: 43 | H105: 68.7 | I105: 52.8 | J105: 22.7
A106: 1996 Jan | B106: 56.6 | C106: 54.3 | D106: 69.9 | E106: 51.7 | F106: 53.6 | G106: 40.9 | H106: 66.8 | I106: 52.9 | J106: 24 | K106: 85.8
A107: 1996 Feb | B107: 58.1 | C107: 55.7 | D107: 71.7 | E107: 53.1 | F107: 56.5 | G107: 42.1 | H107: 69.5 | I107: 52.8 | J107: 24.4 | K107: 88.8
A108: 1996 Mar | B108: 58.3 | C108: 55.6 | D108: 71.4 | E108: 53.1 | F108: 55.8 | G108: 42.1 | H108: 69.7 | I108: 53.2 | J108: 24.3 | K108: 94.1
A109: 1996 Apr | B109: 58.9 | C109: 56.2 | D109: 71.6 | E109: 54.2 | F109: 58.5 | G109: 42.8 | H109: 70.3 | I109: 54.2 | J109: 24.2 | K109: 92.7
A110: 1996 May | B110: 58.7 | C110: 56.2 | D110: 71.3 | E110: 54.3 | F110: 56.6 | G110: 41.9 | H110: 73.2 | I110: 54.6 | J110: 24.2 | K110: 90.4
A111: 1996 Jun | B111: 58.9 | C111: 56.5 | D111: 71.9 | E111: 54.4 | F111: 57.2 | G111: 43.7 | H111: 70.2 | I111: 54.5 | J111: 24.3 | K111: 88.5
A112: 1996 Jul | B112: 58.7 | C112: 56.2 | D112: 72.1 | E112: 53.7 | F112: 57.3 | G112: 42.1 | H112: 70.7 | I112: 53.5 | J112: 24.6 | K112: 89.7
A113: 1996 Aug | B113: 58.9 | C113: 56.4 | D113: 71.6 | E113: 54.6 | F113: 57.9 | G113: 43.4 | H113: 72 | I113: 54 | J113: 24.3 | K113: 89.8
A114: 1996 Sep | B114: 59.5 | C114: 57.2 | D114: 72.5 | E114: 55.3 | F114: 59 | G114: 43.6 | H114: 73.2 | I114: 54.6 | J114: 24.9 | K114: 86.8
A115: 1996 Oct | B115: 59.4 | C115: 57.1 | D115: 72.8 | E115: 55.1 | F115: 58.2 | G115: 42.7 | H115: 74.8 | I115: 54.4 | J115: 24.5 | K115: 85
A116: 1996 Nov | B116: 59.6 | C116: 57.4 | D116: 73.2 | E116: 55.5 | F116: 59.4 | G116: 44.6 | H116: 74.4 | I116: 53.3 | J116: 23.8 | K116: 84.3
A117: 1996 Dec | B117: 59.3 | C117: 57.2 | D117: 72.6 | E117: 55.5 | F117: 59.6 | G117: 43.7 | H117: 73.5 | I117: 54.6 | J117: 23.8 | K117: 82.7
... A459: 2025 Jun | B459: 98.4 | C459: 98 | D459: 93.9 | E459: 99.7 | F459: 105 | G459: 98.5 | H459: 95.5 | I459: 100.4 | J459: 104.8 | K459: 101.3
A461: Revision to index numbers
A462: Time Period | B462: All retailing including automotive fuel [note1] | C462: All retailing excluding automotive fuel [Note 1] | D462: Predominantly food stores | E462: Total of predominantly non-food stores [Note 2] | F462: Non-specialised stores [Note 2] | G462: Textile, clothing and footwear stores [Note 2] | H462: Household goods stores [Note 2] | I462: Other stores [Note 2] | J462: Non-store retailing | K462: Predominantly automotive fuel [Note 1]
A463: Agg/SIC | B463: Agg 21 | C463: Agg 21X | D463: Agg 1 | E463: Agg 12 | F463: 47.19 | G463: Agg 5 | H463: Agg 7 | I463: Agg 13 | J463: Agg 14 | K463: 47.30
A464: Dataset identifier code | B464: J5EK | C464: J467 | D464: EAPT | E464: EAPV | F464: EAPU | G464: EAPX | H464: EAPY | I464: EAPW | J464: J5DZ | K464: JO5A
A465: 1988 Jan | C465: 0 | D465: 0 | E465: 0 | F465: 0 | G465: 0 | H465: 0 | I465: 0 | J465: 0
...

Sheet KPSA3 - Jul
A1: KPSA3 - RETAIL SALES INDEX: VOLUME SEASONALLY ADJUSTED, PERCENTAGE CHANGE ON PREVIOUS MONTH
A2: This worksheet contains two tables presented vertically with one above the other and a blank row between the two tables
A3: Source: Retail Sales Index
A4: Some cells in this table are empty because data was not collected for these variables at these time points.
A5: Percentage change on previous month
A6: Time Period | B6: All retailing including automotive fuel [note1] | C6: All retailing excluding automotive fuel [Note 1] | D6: Predominantly food stores | E6: Total of predominantly non-food stores [Note 2] | F6: Non-specialised stores [Note 2] | G6: Textile, clothing and footwear stores [Note 2] | H6: Household goods stores [Note 2] | I6: Other stores [Note 2] | J6: Non-store retailing | K6: Predominantly automotive fuel [Note 1]
A7: Agg/SIC | B7: Agg 21 | C7: Agg 21X | D7: Agg 1 | E7: Agg 12 | F7: 47.19 | G7: Agg 5 | H7: Agg 7 | I7: Agg 13 | J7: Agg 14 | K7: 47.30
A8: Dataset identifier code | B8: J5EC | C8: J45W | D8: IEEZ | E8: IEFC | F8: IEEW | G8: IEFO | H8: IEFR | I8: IEFF | J8: J5DL | K8: JO6C
A9: 1988 Jan
A10: 1988 Feb | C10: -2.2 | D10: -0.2 | E10: -3.2 | F10: -0.8 | G10: -3.9 | H10: -4 | I10: -3 | J10: -4.9
A11: 1988 Mar | C11: 0.4 | D11: 0 | E11: 0.2 | F11: 0.5 | G11: -1.7 | H11: 1.7 | I11: 0.4 | J11: 3.7
A12: 1988 Apr | C12: 1.4 | D12: 0.7 | E12: 1.8 | F12: 0.5 | G12: 1.7 | H12: 2.2 | I12: 2.2 | J12: 2.2
A13: 1988 May | C13: -0.3 | D13: -0.8 | E13: 0 | F13: 1.1 | G13: -0.1 | H13: -0.3 | I13: -0.1 | J13: 0.3
A14: 1988 Jun | C14: 1.1 | D14: 0.3 | E14: 1.7 | F14: 0.5 | G14: 2.7 | H14: 1.3 | I14: 2.1 | J14: 0.7
A15: 1988 Jul | C15: 1.3 | D15: -0.4 | E15: 2.5 | F15: -0.3 | G15: 0.3 | H15: 7.1 | I15: 1.9 | J15: 1.2
A16: 1988 Aug | C16: 0 | D16: 1 | E16: -0.5 | F16: 0.5 | G16: 0.4 | H16: -2.9 | I16: 0.5 | J16: -0.7
A17: 1988 Sep | C17: -0.6 | D17: -0.4 | E17: -0.4 | F17: 0.4 | G17: 0.2 | H17: -0.8 | I17: -1 | J17: -3
A18: 1988 Oct | C18: 1.7 | D18: 1.1 | E18: 1.8 | F18: 1.6 | G18: 1.5 | H18: 1.7 | I18: 2.1 | J18: 3.8
A19: 1988 Nov | C19: 0.5 | D19: 0.4 | E19: 0.7 | F19: 0.2 | G19: 1.5 | H19: -0.3 | I19: 1.2 | J19: 0.2
A20: 1988 Dec | C20: 0 | D20: 0.9 | E20: -0.5 | F20: -2.1 | G20: -1.4 | H20: -0.4 | I20: 1 | J20: -0.2
A21: 1989 Jan | C21: -1.4 | D21: -3.2 | E21: -0.2 | F21: 0.8 | G21: -0.8 | H21: -1.8 | I21: 1.1 | J21: -1.7
... A105: 1996 Jan | C105: -1.5 | D105: -0.8 | E105: -2.8 | F105: -5.2 | G105: -5 | H105: -2.7 | I105: 0.2 | J105: 5.6
A106: 1996 Feb | B106: 2.6 | C106: 2.5 | D106: 2.6 | E106: 2.6 | F106: 5.4 | G106: 2.9 | H106: 4 | I106: -0.2 | J106: 1.8 | K106: 3.5
A107: 1996 Mar | B107: 0.4 | C107: -0.1 | D107: -0.4 | E107: 0.1 | F107: -1.2 | G107: 0.2 | H107: 0.3 | I107: 0.8 | J107: -0.4 | K107: 6
A108: 1996 Apr | B108: 0.9 | C108: 1.1 | D108: 0.2 | E108: 2 | F108: 4.9 | G108: 1.5 | H108: 0.9 | I108: 1.8 | J108: -0.4 | K108: -1.5
A109: 1996 May | B109: -0.2 | C109: -0.1 | D109: -0.3 | E109: 0.1 | F109: -3.3 | G109: -1.9 | H109: 4.1 | I109: 0.6 | J109: 0.2 | K109: -2.5
A110: 1996 Jun | B110: 0.3 | C110: 0.5 | D110: 0.8 | E110: 0.2 | F110: 1.1 | G110: 4.4 | H110: -4.1 | I110: -0.2 | J110: 0.4 | K110: -2
A111: 1996 Jul | B111: -0.4 | C111: -0.5 | D111: 0.2 | E111: -1.3 | F111: 0 | G111: -3.7 | H111: 0.8 | I111: -1.7 | J111: 0.9 | K111: 1.3
A112: 1996 Aug | B112: 0.4 | C112: 0.5 | D112: -0.8 | E112: 1.6 | F112: 1.2 | G112: 2.9 | H112: 1.7 | I112: 0.8 | J112: -1.1 | K112: 0.1
A113: 1996 Sep | B113: 1 | C113: 1.4 | D113: 1.3 | E113: 1.3 | F113: 1.8 | G113: 0.6 | H113: 1.7 | I113: 1.2 | J113: 2.5 | K113: -3.4
A114: 1996 Oct | B114: -0.3 | C114: -0.1 | D114: 0.4 | E114: -0.4 | F114: -1.4 | G114: -2 | H114: 2.2 | I114: -0.5 | J114: -1.7 | K114: -2.1
A115: 1996 Nov | B115: 0.3 | C115: 0.5 | D115: 0.5 | E115: 0.7 | F115: 2.2 | G115: 4.4 | H115: -0.5 | I115: -1.9 | J115: -2.6 | K115: -0.8
A116: 1996 Dec | B116: -0.4 | C116: -0.3 | D116: -0.7 | E116: 0 | F116: 0.2 | G116: -2.1 | H116: -1.2 | I116: 2.5 | J116: -0.2 | K116: -1.9
A117: 1997 Jan | B117: -0.1 | C117: -0.1 | D117: -0.4 | E117: -0.2 | F117: -2 | G117: 0.9 | H117: -0.2 | I117: -0.2 | J117: 2.6 | K117: 0.6
... A458: 2025 Jun | B458: 0.9 | C458: 0.6 | D458: 0.7 | E458: 0.2 | F458: 2.1 | G458: 1 | H458: -0.1 | I458: -1.5 | J458: 1.7 | K458: 2.8
A460: Revision to index numbers
A461: Time Period | B461: All retailing including automotive fuel [note1] | C461: All retailing excluding automotive fuel [Note 1] | D461: Predominantly food stores | E461: Total of predominantly non-food stores [Note 2] | F461: Non-specialised stores [Note 2] | G461: Textile, clothing and footwear stores [Note 2] | H461: Household goods stores [Note 2] | I461: Other stores [Note 2] | J461: Non-store retailing | K461: Predominantly automotive fuel [Note 1]
A462: Agg/SIC | B462: Agg 21 | C462: Agg 21X | D462: Agg 1 | E462: Agg 12 | F462: 47.19 | G462: Agg 5 | H462: Agg 7 | I462: Agg 13 | J462: Agg 14 | K462: 47.30
A463: Dataset identifier code | B463: J5EC | C463: J45W | D463: IEEZ | E463: IEFC | F463: IEEW | G463: IEFO | H463: IEFR | I463: IEFF | J463: J5DL | K463: JO6C
A464: 1988 Jan
...
