Workbook
Name _DLX1.INC: HAVERM!$A$1:$M$6

Sheet Chart Data
A1: HMRC RTI vs AWE
B2: Average Weekly Earnings total pay | C2: HMRC median pay | D2: HMRC median of pay growth | E2: Decision Marker Panel realised pay growth | F2: Indeed wage tracker | G2: ZERO LINE
A3: 42005 | B3: =100*((HAVERM!E67/HAVERM!E55)-1) -> 1.8561485 | C3: =100*((HAVERM!C67/HAVERM!C55)-1) -> #N/A | D3: =NA() -> #N/A | E3: =NA() -> #N/A | G3: 0
A4: 42036 | B4: =100*((HAVERM!E68/HAVERM!E56)-1) -> 2.8037383 | C4: =100*((HAVERM!C68/HAVERM!C56)-1) -> #N/A | D4: =NA() -> #N/A | E4: =NA() -> #N/A | G4: 0
A5: 42064 | B5: =100*((HAVERM!E69/HAVERM!E57)-1) -> 3.5046729 | C5: =100*((HAVERM!C69/HAVERM!C57)-1) -> #N/A | D5: =NA() -> #N/A | E5: =NA() -> #N/A | G5: 0
A6: 42095 | B6: =100*((HAVERM!E70/HAVERM!E58)-1) -> 3.030303 | C6: =100*((HAVERM!C70/HAVERM!C58)-1) -> #N/A | D6: =NA() -> #N/A | E6: =NA() -> #N/A | G6: 0
A7: 42125 | B7: =100*((HAVERM!E71/HAVERM!E59)-1) -> 3.0232558 | C7: =100*((HAVERM!C71/HAVERM!C59)-1) -> #N/A | D7: =NA() -> #N/A | E7: =NA() -> #N/A | G7: 0
A8: 42156 | B8: =100*((HAVERM!E72/HAVERM!E60)-1) -> 3.255814 | C8: =100*((HAVERM!C72/HAVERM!C60)-1) -> #N/A | D8: =NA() -> #N/A | E8: =NA() -> #N/A | G8: 0
A9: 42186 | B9: =100*((HAVERM!E73/HAVERM!E61)-1) -> 3.4883721 | C9: =100*((HAVERM!C73/HAVERM!C61)-1) -> 1.3767209 | D9: =100*'27. Median of pay growth (UK)'!B8 -> 2.4891032 | E9: =NA() -> #N/A | G9: 0
A10: 42217 | B10: =100*((HAVERM!E74/HAVERM!E62)-1) -> 3.0092593 | C10: =100*((HAVERM!C74/HAVERM!C62)-1) -> 0.93632959 | D10: =100*'27. Median of pay growth (UK)'!B9 -> 2.3465307 | E10: =NA() -> #N/A | G10: 0
A11: 42248 | B11: =100*((HAVERM!E75/HAVERM!E63)-1) -> 2.0689655 | C11: =100*((HAVERM!C75/HAVERM!C63)-1) -> 1.1242973 | D11: =100*'27. Median of pay growth (UK)'!B10 -> 2.3742267 | E11: =NA() -> #N/A | G11: 0
A12: 42278 | B12: =100*((HAVERM!E76/HAVERM!E64)-1) -> 1.8306636 | C12: =100*((HAVERM!C76/HAVERM!C64)-1) -> 1.3084112 | D12: =100*'27. Median of pay growth (UK)'!B11 -> 2.5145709 | E12: =NA() -> #N/A | G12: 0
A13: 42309 | B13: =100*((HAVERM!E77/HAVERM!E65)-1) -> 2.5287356 | C13: =100*((HAVERM!C77/HAVERM!C65)-1) -> 1.3690106 | D13: =100*'27. Median of pay growth (UK)'!B12 -> 2.5684418 | E13: =NA() -> #N/A | G13: 0
A14: 42339 | B14: =100*((HAVERM!E78/HAVERM!E66)-1) -> 2.2883295 | C14: =100*((HAVERM!C78/HAVERM!C66)-1) -> 0.92821782 | D14: =100*'27. Median of pay growth (UK)'!B13 -> 2.2359978 | E14: =NA() -> #N/A | G14: 0
A15: 42370 | B15: =100*((HAVERM!E79/HAVERM!E67)-1) -> 2.5056948 | C15: =100*((HAVERM!C79/HAVERM!C67)-1) -> 1.1111111 | D15: =100*'27. Median of pay growth (UK)'!B14 -> 2.3816298 | E15: =NA() -> #N/A | G15: 0
A16: 42401 | B16: =100*((HAVERM!E80/HAVERM!E68)-1) -> 2.7272727 | C16: =100*((HAVERM!C80/HAVERM!C68)-1) -> 1.2345679 | D16: =100*'27. Median of pay growth (UK)'!B15 -> 2.424679 | E16: =NA() -> #N/A | G16: 0
A17: 42430 | B17: =100*((HAVERM!E81/HAVERM!E69)-1) -> 2.2573363 | C17: =100*((HAVERM!C81/HAVERM!C69)-1) -> 1.6687268 | D17: =100*'27. Median of pay growth (UK)'!B16 -> 2.4861846 | E17: =NA() -> #N/A | G17: 0
A18: 42461 | B18: =100*((HAVERM!E82/HAVERM!E70)-1) -> 2.7149321 | C18: =100*((HAVERM!C82/HAVERM!C70)-1) -> 2.3558586 | D18: =100*'27. Median of pay growth (UK)'!B17 -> 2.5579236 | E18: =NA() -> #N/A | G18: 0
A19: 42491 | B19: =100*((HAVERM!E83/HAVERM!E71)-1) -> 2.2573363 | C19: =100*((HAVERM!C83/HAVERM!C71)-1) -> 2.2277228 | D19: =100*'27. Median of pay growth (UK)'!B18 -> 2.4988917 | E19: =NA() -> #N/A | G19: 0
A20: 42522 | B20: =100*((HAVERM!E84/HAVERM!E72)-1) -> 2.4774775 | C20: =100*((HAVERM!C84/HAVERM!C72)-1) -> 2.288188 | D20: =100*'27. Median of pay growth (UK)'!B19 -> 2.8202449 | E20: =NA() -> #N/A | G20: 0
... A52: 43497 | B52: =100*((HAVERM!E116/HAVERM!E104)-1) -> 3.3684211 | C52: =100*((HAVERM!C116/HAVERM!C104)-1) -> 3.6458333 | D52: =100*'27. Median of pay growth (UK)'!B51 -> 3.2956303 | E52: =NA() -> #N/A | G52: 0
A53: 43525 | B53: =100*((HAVERM!E117/HAVERM!E105)-1) -> 3.3542977 | C53: =100*((HAVERM!C117/HAVERM!C105)-1) -> 4.048583 | D53: =100*'27. Median of pay growth (UK)'!B52 -> 3.5604166 | E53: =NA() -> #N/A | F53: =Indeed!F4 -> 4.39 | G53: 0
A54: 43556 | B54: =100*((HAVERM!E118/HAVERM!E106)-1) -> 3.7815126 | C54: =100*((HAVERM!C118/HAVERM!C106)-1) -> 4.5691151 | D54: =100*'27. Median of pay growth (UK)'!B53 -> 3.9437213 | E54: =NA() -> #N/A | F54: =Indeed!F5 -> 4.27 | G54: 0
A55: 43586 | B55: =100*((HAVERM!E119/HAVERM!E107)-1) -> 3.7656904 | C55: =100*((HAVERM!C119/HAVERM!C107)-1) -> 3.7735849 | D55: =100*'27. Median of pay growth (UK)'!B54 -> 3.4304788 | E55: =NA() -> #N/A | F55: =Indeed!F6 -> 4.04 | G55: 0
A56: 43617 | B56: =100*((HAVERM!E120/HAVERM!E108)-1) -> 4.1753653 | C56: =100*((HAVERM!C120/HAVERM!C108)-1) -> 3.1890661 | D56: =100*'27. Median of pay growth (UK)'!B55 -> 3.3022698 | E56: =NA() -> #N/A | F56: =Indeed!F7 -> 3.72 | G56: 0
A57: 43647 | B57: =100*((HAVERM!E121/HAVERM!E109)-1) -> 3.7422037 | C57: =100*((HAVERM!C121/HAVERM!C109)-1) -> 3.8834951 | D57: =100*'27. Median of pay growth (UK)'!B56 -> 3.1816174 | E57: =NA() -> #N/A | F57: =Indeed!F8 -> 3.58 | G57: 0
A58: 43678 | B58: =100*((HAVERM!E122/HAVERM!E110)-1) -> 3.5196687 | C58: =100*((HAVERM!C122/HAVERM!C110)-1) -> 3.0474041 | D58: =100*'27. Median of pay growth (UK)'!B57 -> 3.0124824 | E58: =NA() -> #N/A | F58: =Indeed!F9 -> 3.53 | G58: 0
A59: 43709 | B59: =100*((HAVERM!E123/HAVERM!E111)-1) -> 3.7267081 | C59: =100*((HAVERM!C123/HAVERM!C111)-1) -> 3.3503691 | D59: =100*'27. Median of pay growth (UK)'!B58 -> 3.2912637 | E59: =NA() -> #N/A | F59: =Indeed!F10 -> 3.53 | G59: 0
A60: 43739 | B60: =100*((HAVERM!E124/HAVERM!E112)-1) -> 3.0864198 | C60: =100*((HAVERM!C124/HAVERM!C112)-1) -> 3.2823995 | D60: =100*'27. Median of pay growth (UK)'!B59 -> 3.1225701 | E60: =NA() -> #N/A | F60: =Indeed!F11 -> 3.42 | G60: 0
A61: 43770 | B61: =100*((HAVERM!E125/HAVERM!E113)-1) -> 3.0800821 | C61: =100*((HAVERM!C125/HAVERM!C113)-1) -> 2.9246344 | D61: =100*'27. Median of pay growth (UK)'!B60 -> 3.0667338 | E61: =NA() -> #N/A | F61: =Indeed!F12 -> 3.35 | G61: 0
A62: 43800 | B62: =100*((HAVERM!E126/HAVERM!E114)-1) -> 3.2786885 | C62: =100*((HAVERM!C126/HAVERM!C114)-1) -> 3.6117381 | D62: =100*'27. Median of pay growth (UK)'!B61 -> 3.2001961 | E62: =NA() -> #N/A | F62: =Indeed!F13 -> 3.34 | G62: 0
A63: 43831 | B63: =100*((HAVERM!E127/HAVERM!E115)-1) -> 2.8513238 | C63: =100*((HAVERM!C127/HAVERM!C115)-1) -> 3.8116592 | D63: =100*'27. Median of pay growth (UK)'!B62 -> 3.204623 | E63: =NA() -> #N/A | F63: =Indeed!F14 -> 2.8 | G63: 0
A64: 43862 | B64: =100*((HAVERM!E128/HAVERM!E116)-1) -> 2.8513238 | C64: =100*((HAVERM!C128/HAVERM!C116)-1) -> 3.908431 | D64: =100*'27. Median of pay growth (UK)'!B63 -> 3.2803678 | E64: =NA() -> #N/A | F64: =Indeed!F15 -> 2.29 | G64: 0
... A90: 44652 | B90: =100*((HAVERM!E154/HAVERM!E142)-1) -> 5.0847458 | C90: =100*((HAVERM!C154/HAVERM!C142)-1) -> 5.8074376 | D90: =100*'27. Median of pay growth (UK)'!B89 -> 4.9233427 | E90: =NA() -> #N/A | F90: =Indeed!F41 -> 5.51 | G90: 0
A91: 44682 | B91: =100*((HAVERM!E155/HAVERM!E143)-1) -> 5.8380414 | C91: =100*((HAVERM!C155/HAVERM!C143)-1) -> 6.2181448 | D91: =100*'27. Median of pay growth (UK)'!B90 -> 5.0766499 | E91: =HAVERM!G155 -> 5.465 | F91: =Indeed!F42 -> 6.27 | G91: 0
A92: 44713 | B92: =100*((HAVERM!E156/HAVERM!E144)-1) -> 6.0150376 | C92: =100*((HAVERM!C156/HAVERM!C144)-1) -> 6.4810127 | D92: =100*'27. Median of pay growth (UK)'!B91 -> 5.0930826 | E92: =HAVERM!G156 -> 5.578 | F92: =Indeed!F43 -> 6.61 | G92: 0
A93: 44743 | B93: =100*((HAVERM!E157/HAVERM!E145)-1) -> 6.3670412 | C93: =100*((HAVERM!C157/HAVERM!C145)-1) -> 6.6195048 | D93: =100*'27. Median of pay growth (UK)'!B92 -> 5.3218451 | E93: =HAVERM!G157 -> 5.541 | F93: =Indeed!F44 -> 6.5 | G93: 0
A94: 44774 | B94: =100*((HAVERM!E158/HAVERM!E146)-1) -> 6.728972 | C94: =100*((HAVERM!C158/HAVERM!C146)-1) -> 6.6431807 | D94: =100*'27. Median of pay growth (UK)'!B93 -> 5.6491181 | E94: =HAVERM!G158 -> 5.844 | F94: =Indeed!F45 -> 6.49 | G94: 0
A95: 44805 | B95: =100*((HAVERM!E159/HAVERM!E147)-1) -> 7.0763501 | C95: =100*((HAVERM!C159/HAVERM!C147)-1) -> 6.9257598 | D95: =100*'27. Median of pay growth (UK)'!B94 -> 6.0514281 | E95: =HAVERM!G159 -> 6.098 | F95: =Indeed!F46 -> 6.39 | G95: 0
A96: 44835 | B96: =100*((HAVERM!E160/HAVERM!E148)-1) -> 7.2222222 | C96: =100*((HAVERM!C160/HAVERM!C148)-1) -> 6.8690891 | D96: =100*'27. Median of pay growth (UK)'!B95 -> 6.310001 | E96: =HAVERM!G160 -> 6.306 | F96: =Indeed!F47 -> 6.42 | G96: 0
...

Sheet HAVERM
A1: 201001 !M | B1: UKSEPPM@UK | C1: UKSEPPD@UK | D1: KAB9@UK | E1: KAJ2@UK | F1: KAJ4@UK | G1: UNVDWR3@UK
A2: .DESC | B2: UK: Mean Monthly Pay: Pay As You Earn Real Time Information [RTI] (SA, GBP) | C2: UK: Median Monthly Pay: PAYE Real Time Information [RTI] (SA, GBP) | D2: Great Britain: AWE, Total Pay: Whole Economy (SA, GBP) | E2: Great Britain: Average Weekly Earnings, Regular Pay: Private Sector (SA, GBP) | F2: Great Britain: AWE, Regular Pay: Private Sector [3Mo Mvg Avg vs Yr Ago] (SA, %) | G2: UK: BoE DMP: Realized Wage Growth Over the Past Year: 3 Month Average (%)
A3: .T1 | B3: Jul-2014 | C3: Jul-2014 | D3: Jan-2000 | E3: Jan-2000 | F3: Mar-2001 | G3: Aug-2017
A4: .TN | B4: Mar-2025 | C4: Apr-2025 | D4: Mar-2025 | E4: Mar-2025 | F4: Mar-2025 | G4: Apr-2025
A5: .LSOURCE | B5: Office for National Statistics | C5: Office for National Statistics | D5: Office for National Statistics | E5: Office for National Statistics | F5: Office for National Statistics | G5: Bank of England
A6: .DTLM | B6: May-13-2025 07:03 | C6: May-13-2025 07:03 | D6: May-13-2025 07:03 | E6: May-13-2025 07:03 | F6: May-13-2025 07:03 | G6: May-08-2025 14:06
A7: 201001 | B7: #N/A | C7: #N/A | D7: 439 | E7: 405 | F7: 0.5 | G7: #N/A
A8: 201002 | B8: #N/A | C8: #N/A | D8: 446 | E8: 404 | F8: 0.7 | G8: #N/A
A9: 201003 | B9: #N/A | C9: #N/A | D9: 441 | E9: 407 | F9: 1 | G9: #N/A
A10: 201004 | B10: #N/A | C10: #N/A | D10: 442 | E10: 405 | F10: 0.9 | G10: #N/A
A11: 201005 | B11: #N/A | C11: #N/A | D11: 443 | E11: 404 | F11: 0.8 | G11: #N/A
A12: 201006 | B12: #N/A | C12: #N/A | D12: 442 | E12: 405 | F12: 0.6 | G12: #N/A
A13: 201007 | B13: #N/A | C13: #N/A | D13: 443 | E13: 407 | F13: 1 | G13: #N/A
A14: 201008 | B14: #N/A | C14: #N/A | D14: 445 | E14: 409 | F14: 1.6 | G14: #N/A
A15: 201009 | B15: #N/A | C15: #N/A | D15: 446 | E15: 409 | F15: 2 | G15: #N/A
A16: 201010 | B16: #N/A | C16: #N/A | D16: 447 | E16: 409 | F16: 2 | G16: #N/A
A17: 201011 | B17: #N/A | C17: #N/A | D17: 448 | E17: 409 | F17: 2 | G17: #N/A
A18: 201012 | B18: #N/A | C18: #N/A | D18: 449 | E18: 409 | F18: 1.9 | G18: #N/A
... A60: 201406 | B60: #N/A | C60: #N/A | D60: 470 | E60: 430 | F60: 0.9 | G60: #N/A
A61: 201407 | B61: 2188 | C61: 1598 | D61: 468 | E61: 430 | F61: 0.9 | G61: #N/A
A62: 201408 | B62: 2195 | C62: 1602 | D62: 469 | E62: 432 | F62: 1 | G62: #N/A
A63: 201409 | B63: 2199 | C63: 1601 | D63: 473 | E63: 435 | F63: 1.4 | G63: #N/A
A64: 201410 | B64: 2198 | C64: 1605 | D64: 475 | E64: 437 | F64: 1.9 | G64: #N/A
A65: 201411 | B65: 2215 | C65: 1607 | D65: 475 | E65: 435 | F65: 2.1 | G65: #N/A
A66: 201412 | B66: 2237 | C66: 1616 | D66: 478 | E66: 437 | F66: 2 | G66: #N/A
A67: 201501 | B67: 2236 | C67: 1620 | D67: 476 | E67: 439 | F67: 1.9 | G67: #N/A
A68: 201502 | B68: 2234 | C68: 1620 | D68: 478 | E68: 440 | F68: 2.1 | G68: #N/A
A69: 201503 | B69: 2219 | C69: 1618 | D69: 480 | E69: 443 | F69: 2.7 | G69: #N/A
A70: 201504 | B70: 2228 | C70: 1613 | D70: 481 | E70: 442 | F70: 3.1 | G70: #N/A
A71: 201505 | B71: 2222 | C71: 1616 | D71: 482 | E71: 443 | F71: 3.3 | G71: #N/A
A72: 201506 | B72: 2222 | C72: 1617 | D72: 481 | E72: 444 | F72: 3.2 | G72: #N/A
... A97: 201707 | B97: 2330 | C97: 1693 | D97: 504 | E97: 465 | F97: 2.3 | G97: #N/A
A98: 201708 | B98: 2337 | C98: 1700 | D98: 507 | E98: 467 | F98: 2.3 | G98: 2.634
A99: 201709 | B99: 2346 | C99: 1704 | D99: 509 | E99: 468 | F99: 2.4 | G99: 2.556
A100: 201710 | B100: 2345 | C100: 1706 | D100: 509 | E100: 469 | F100: 2.4 | G100: 2.619
A101: 201711 | B101: 2351 | C101: 1713 | D101: 510 | E101: 470 | F101: 2.4 | G101: #N/A
A102: 201712 | B102: 2360 | C102: 1721 | D102: 512 | E102: 472 | F102: 2.6 | G102: #N/A
A103: 201801 | B103: 2367 | C103: 1725 | D103: 510 | E103: 473 | F103: 2.7 | G103: #N/A
A104: 201802 | B104: 2380 | C104: 1728 | D104: 513 | E104: 475 | F104: 2.9 | G104: #N/A
A105: 201803 | B105: 2388 | C105: 1729 | D105: 513 | E105: 477 | F105: 3 | G105: #N/A
...

Sheet 27. Median of pay growth (UK)
A1: 27. Median of pay growth from PAYE RTI
A2: UK, all industries, seasonally adjusted
A4: Units | B4: %
A5: Additional notes | B5: Median of pay growth is calculated by producing the annual growth in pay for all individuals in our dataset and then selecting the median of those values. Our growth in median pay figures look at the growth in pay over the past year and so compare this month to the same month last year. This means that the median pay growth only considers those employed in both months.
A7: Date | B7: Median of pay growth
A8: July 2015 | B8: 0.024891032
A9: August 2015 | B9: 0.023465307
A10: September 2015 | B10: 0.023742267
A11: October 2015 | B11: 0.025145709
A12: November 2015 | B12: 0.025684418
A13: December 2015 | B13: 0.022359978
A14: January 2016 | B14: 0.023816298
A15: February 2016 | B15: 0.02424679
A16: March 2016 | B16: 0.024861846
A17: April 2016 | B17: 0.025579236
A18: May 2016 | B18: 0.024988917
A19: June 2016 | B19: 0.028202449
... A125: April 2025 | B125: 0.050292029

Sheet Indeed
A1: __typename | B1: id | C1: dateString | D1: countryCode | E1: countryName | F1: value
A2: HiringLabNationalWage | B2: aXJpOi8vYXBpcy5pbmRlZWQuY29tL0hpcmluZ0xhYk5hdGlvbmFsV2FnZS8yMDE5LTAxLTAxX0dC | C2: 43466 | D2: GB | E2: United Kingdom | F2: NaN
A3: HiringLabNationalWage | B3: aXJpOi8vYXBpcy5pbmRlZWQuY29tL0hpcmluZ0xhYk5hdGlvbmFsV2FnZS8yMDE5LTAyLTAxX0dC | C3: 43497 | D3: GB | E3: United Kingdom | F3: NaN
A4: HiringLabNationalWage | B4: aXJpOi8vYXBpcy5pbmRlZWQuY29tL0hpcmluZ0xhYk5hdGlvbmFsV2FnZS8yMDE5LTAzLTAxX0dC | C4: 43525 | D4: GB | E4: United Kingdom | F4: 4.39
A5: HiringLabNationalWage | B5: aXJpOi8vYXBpcy5pbmRlZWQuY29tL0hpcmluZ0xhYk5hdGlvbmFsV2FnZS8yMDE5LTA0LTAxX0dC | C5: 43556 | D5: GB | E5: United Kingdom | F5: 4.27
A6: HiringLabNationalWage | B6: aXJpOi8vYXBpcy5pbmRlZWQuY29tL0hpcmluZ0xhYk5hdGlvbmFsV2FnZS8yMDE5LTA1LTAxX0dC | C6: 43586 | D6: GB | E6: United Kingdom | F6: 4.04
A7: HiringLabNationalWage | B7: aXJpOi8vYXBpcy5pbmRlZWQuY29tL0hpcmluZ0xhYk5hdGlvbmFsV2FnZS8yMDE5LTA2LTAxX0dC | C7: 43617 | D7: GB | E7: United Kingdom | F7: 3.72
A8: HiringLabNationalWage | B8: aXJpOi8vYXBpcy5pbmRlZWQuY29tL0hpcmluZ0xhYk5hdGlvbmFsV2FnZS8yMDE5LTA3LTAxX0dC | C8: 43647 | D8: GB | E8: United Kingdom | F8: 3.58
A9: HiringLabNationalWage | B9: aXJpOi8vYXBpcy5pbmRlZWQuY29tL0hpcmluZ0xhYk5hdGlvbmFsV2FnZS8yMDE5LTA4LTAxX0dC | C9: 43678 | D9: GB | E9: United Kingdom | F9: 3.53
A10: HiringLabNationalWage | B10: aXJpOi8vYXBpcy5pbmRlZWQuY29tL0hpcmluZ0xhYk5hdGlvbmFsV2FnZS8yMDE5LTA5LTAxX0dC | C10: 43709 | D10: GB | E10: United Kingdom | F10: 3.53
A11: HiringLabNationalWage | B11: aXJpOi8vYXBpcy5pbmRlZWQuY29tL0hpcmluZ0xhYk5hdGlvbmFsV2FnZS8yMDE5LTEwLTAxX0dC | C11: 43739 | D11: GB | E11: United Kingdom | F11: 3.42
A12: HiringLabNationalWage | B12: aXJpOi8vYXBpcy5pbmRlZWQuY29tL0hpcmluZ0xhYk5hdGlvbmFsV2FnZS8yMDE5LTExLTAxX0dC | C12: 43770 | D12: GB | E12: United Kingdom | F12: 3.35
A13: HiringLabNationalWage | B13: aXJpOi8vYXBpcy5pbmRlZWQuY29tL0hpcmluZ0xhYk5hdGlvbmFsV2FnZS8yMDE5LTEyLTAxX0dC | C13: 43800 | D13: GB | E13: United Kingdom | F13: 3.34
A14: HiringLabNationalWage | B14: aXJpOi8vYXBpcy5pbmRlZWQuY29tL0hpcmluZ0xhYk5hdGlvbmFsV2FnZS8yMDIwLTAxLTAxX0dC | C14: 43831 | D14: GB | E14: United Kingdom | F14: 2.8
A15: HiringLabNationalWage | B15: aXJpOi8vYXBpcy5pbmRlZWQuY29tL0hpcmluZ0xhYk5hdGlvbmFsV2FnZS8yMDIwLTAyLTAxX0dC | C15: 43862 | D15: GB | E15: United Kingdom | F15: 2.29
... A76: HiringLabNationalWage | B76: aXJpOi8vYXBpcy5pbmRlZWQuY29tL0hpcmluZ0xhYk5hdGlvbmFsV2FnZS8yMDI1LTAzLTAxX0dC | C76: 45717 | D76: GB | E76: United Kingdom | F76: 5.84
