Workbook
Name Astartpg: #REF!
Name Astartpg: #REF!
Name Row_A: #REF!
Name Row_A: #REF!
Name Row_B: #REF!
Name Row_B: #REF!
Name Row_C: #REF!
Name Row_C: #REF!
Name Row_D: #REF!
Name Row_D: #REF!
Name Row_E: #REF!
Name Row_E: #REF!
Name Row_F: #REF!
Name Row_F: #REF!
Name Row_G: #REF!
Name Row_G: #REF!
Name toolong: #REF!
Name toolong: #REF!

Sheet Chart Data
A1: Total population | F1: Migration | K1: Natural change | P1: Births
B2: 2020-based (published Jan 2022) | C2: 2021-based (published Jan 2024) | D2: 2022-based (published Jan 2025) | G2: 2020-based (published Jan 2022) | H2: 2021-based (published Jan 2024) | I2: 2022-based (published Jan 2025) | L2: 2020-based (published Jan 2022) | M2: 2021-based (published Jan 2024) | N2: 2022-based (published Jan 2025) | Q2: 2020-based (published Jan 2022) | R2: 2021-based (published Jan 2024) | S2: 2022-based (published Jan 2025)
A3: 2020 | B3: 67081.234 | C3: 67081.234 | D3: 66744.067 | F3: 2020 | G3: 247 | H3: 111 | I3: 111 | K3: 2020 | L3: 37.427 | M3: =-L3 -> -37.427 | N3: 2.36 | P3: 2020
A4: 2021 | B4: {=TRANSPOSE('2020-based principal'!C26:AP26)} -> 67350.695 | C4: 67026.292 | D4: 66983.488 | F4: 2021 | G4: 244.498 | H4: 221 | I4: 221 | K4: 2021 | L4: 24.963 | M4: =-L4 -> -24.963 | N4: 18.421 | P4: 2021
A5: 2022 | B5: 67595.824 | C5: 67661.747 | D5: {=TRANSPOSE('2022-based principal'!B34:AN34)} -> 67602.761 | F5: 2022 | G5: {=TRANSPOSE('2020-based principal'!C19:AP19)} -> 244.498 | H5: 595.84 | I5: 607 | K5: 2022 | L5: {=TRANSPOSE('2020-based principal'!C13:AP13)} -> 24.963 | M5: 39.615455 | N5: 12.973 | P5: 2022 | Q5: {=TRANSPOSE('2020-based principal'!C10:AP10)} -> 671.374
A6: 2023 | B6: 67844.315 | C6: {=TRANSPOSE('2021-based principal'!D26:AO26)} -> 68350.236 | D6: 68492.495 | F6: 2023 | G6: 236.989 | H6: {=TRANSPOSE('2021-based principal'!D19:AO19)} -> 670.128 | I6: {=TRANSPOSE('2022-based principal'!C18:AN18)} -> 906 | K6: 2023 | L6: 8.14 | M6: {=TRANSPOSE('2021-based principal'!D13:AO13)} -> 0.916 | N6: {=TRANSPOSE('2022-based principal'!C11:AN11)} -> -16.263 | P6: 2023 | Q6: 663.443 | R6: {=TRANSPOSE('2021-based principal'!D10:AO10)} -> 665.539 | S6: {=TRANSPOSE('2022-based principal'!C9:AN9)} -> 664.464
A7: 2024 | B7: 68081.792 | C7: 69025.203 | D7: 69226.231 | F7: 2024 | G7: 231.015 | H7: 598.974 | I7: 728 | K7: 2024 | L7: 17.476 | M7: 75.987 | N7: 5.744 | P7: 2024 | Q7: 659.316 | R7: 713.92 | S7: 667.909
A8: 2025 | B8: 68304.932 | C8: 69630.376 | D8: 69867.979 | F8: 2025 | G8: 224.004 | H8: 528.461 | I8: 630.9 | K8: 2025 | L8: 13.473 | M8: 76.729 | N8: 10.849 | P8: 2025 | Q8: 662.485 | R8: 723.176 | S8: 674.821
A9: 2026 | B9: 68512.086 | C9: 70160.187 | D9: 70414.3 | F9: 2026 | G9: 217 | H9: 457.457 | I9: 533.8 | K9: 2026 | L9: 6.14 | M9: 72.355 | N9: 12.519 | P9: 2026 | Q9: 662.632 | R9: 727.449 | S9: 679.536
A10: 2027 | B10: 68701.986 | C10: 70612.833 | D10: 70861.913 | F10: 2027 | G10: 211.514 | H10: 386.476 | I10: 436.7 | K10: 2027 | L10: -4.36 | M10: 66.148 | N10: 10.892 | P10: 2027 | Q10: 659.855 | R10: 730 | S10: 682.033
A11: 2028 | B11: 68881.062 | C11: 70985.959 | D11: 71208.101 | F11: 2028 | G11: 205.011 | H11: 315.005 | I11: 340 | K11: 2028 | L11: -15.111 | M11: 58.144 | N11: 6.185 | P11: 2028 | Q11: 657.135 | R11: 730.916 | S11: 683.078
A12: 2029 | B12: 69049.389 | C12: 71350.151 | D12: 71547.662 | F12: 2029 | G12: 205.011 | H12: 315.005 | I12: 340 | K12: 2029 | L12: -25.935 | M12: 49.195 | N12: -0.434 | P12: 2029 | Q12: 654.598 | R12: 731.015 | S12: 683.712
A13: 2030 | B13: 69207.197 | C13: 71705.282 | D13: 71879.988 | F13: 2030 | G13: 205.011 | H13: 315.005 | I13: 340 | K13: 2030 | L13: -36.684 | M13: 40.142 | N13: -7.67 | P13: 2030 | Q13: 652.408 | R13: 731.12 | S13: 684.296
A14: 2031 | B14: 69355.074 | C14: 72051.458 | D14: 72204.574 | F14: 2031 | G14: 205.011 | H14: 315.005 | I14: 340 | K14: 2031 | L14: -47.203 | M14: 31.166 | N14: -15.409 | P14: 2031 | Q14: 650.624 | R14: 731.346 | S14: 684.842
A15: 2032 | B15: 69493.866 | C15: 72388.988 | D15: 72521.173 | F15: 2032 | G15: 205.011 | H15: 315.005 | I15: 340 | K15: 2032 | L15: -57.134 | M15: 22.516 | N15: -23.387 | P15: 2032 | Q15: 649.516 | R15: 731.85 | S15: 685.388
A16: 2033 | B16: 69624.16 | C16: 72717.937 | D16: 72830.021 | F16: 2033 | G16: 205.011 | H16: 315.005 | I16: 340 | K16: 2033 | L16: -66.219 | M16: 13.951 | N16: -31.139 | P16: 2033 | Q16: 649.252 | R16: 732.327 | S16: 686.341
A17: 2034 | B17: 69746.769 | C17: 73038.609 | D17: 73131.597 | F17: 2034 | G17: 205.011 | H17: 315.005 | I17: 340 | K17: 2034 | L17: -74.717 | M17: 5.64 | N17: -38.414 | P17: 2034 | Q17: 649.451 | R17: 732.815 | S17: 687.824
A18: 2035 | B18: 69862.985 | C18: 73351.615 | D18: 73426.168 | F18: 2035 | G18: 205.011 | H18: 315.005 | I18: 340 | K18: 2035 | L18: -82.402 | M18: -1.995 | N18: -45.439 | P18: 2035 | Q18: 650.273 | R18: 733.656 | S18: 689.489
... A43: 2060 | B43: 71613.724 | C43: 79672.491 | D43: 78805.317 | F43: 2060 | G43: 205.011 | H43: 315.005 | I43: 340 | K43: 2060 | L43: -207.589 | M43: -119.607 | N43: -206.717 | P43: 2060 | Q43: 632.346 | R43: 735.7 | S43: 661.617
G44: 205.011 | L44: -210.121 | Q44: 629.526

Sheet Calculations
B1: Population | J1: Migration | R1: Natural change | Z1: Total population | AF1: Working age population
B2: OE current | C2: ONS 2022-based principal | D2: ONS 2022-based migration category variant | E2: ONS 2022-based low migration | F2: OE old low variant + new natural change | G2: OE 80% of new migration + new natural change | J2: =B2 -> OE current | K2: =C2 -> ONS 2022-based principal | L2: =D2 -> ONS 2022-based migration category variant | M2: =E2 -> ONS 2022-based low migration | N2: =F2 -> OE old low variant + new natural change | O2: =G2 -> OE 80% of new migration + new natural change | R2: =B2 -> OE current | S2: =C2 -> ONS 2022-based principal | T2: =D2 -> ONS 2022-based migration category variant | U2: =E2 -> ONS 2022-based low migration | V2: =F2 -> OE old low variant + new natural change | W2: =G2 -> OE 80% of new migration + new natural change | Z2: OE (new) | AA2: ONS (new) | AB2: OE (old) | AC2: ONS (old) | AF2: OE (new) | AG2: ONS (new) | AH2: OE (old) | AI2: ONS (old)
A3: 2020 | B3: 66744.067 | I3: 2020 | J3: 111 | Q3: 2020 | R3: 2.36 | Y3: 2020 | Z3: ='[1]2022-based'!Q27 -> 66744.067 | AB3: ='[1]2021-based'!Q27 -> 66744.067 | AC3: ='[1]2021-based'!D27 -> 66744.067 | AE3: 2020 | AF3: ='[1]2022-based'!R27 -> 42614.901 | AH3: ='[1]2021-based'!R27 -> 42614.901 | AI3: ='[1]2021-based'!E27 -> 42614.901
A4: 2021 | B4: 66983.488 | I4: 2021 | J4: 221 | Q4: 2021 | R4: 18.421 | Y4: 2021 | Z4: ='[1]2022-based'!Q28 -> 66983.488 | AB4: ='[1]2021-based'!Q28 -> 66983.488 | AC4: ='[1]2021-based'!D28 -> 66983.488 | AE4: 2021 | AF4: ='[1]2022-based'!R28 -> 42845.915 | AH4: ='[1]2021-based'!R28 -> 42845.915 | AI4: ='[1]2021-based'!E28 -> 42845.915
A5: 2022 | B5: 67603.461 | C5: {=TRANSPOSE('2022-based principal'!B34:AN34)} -> 67602.761 | D5: =C5 -> 67602.761 | E5: {=TRANSPOSE('2022-based low'!B34:AN34)} -> 67602.761 | F5: =E5 -> 67602.761 | G5: =F5 -> 67602.761 | I5: 2022 | J5: 607 | Q5: 2022 | R5: 12.973 | Y5: 2022 | Z5: ='[1]2022-based'!Q29 -> 67603.461 | AA5: ='[1]2022-based'!B29 -> 67602.761 | AB5: ='[1]2021-based'!Q29 -> 67603.461 | AC5: ='[1]2021-based'!D29 -> 67603.461 | AE5: 2022 | AF5: ='[1]2022-based'!R29 -> 43199.2 | AG5: ='[1]2022-based'!C29 -> 43198.556 | AH5: ='[1]2021-based'!R29 -> 43199.2 | AI5: ='[1]2021-based'!E29 -> 43199.2
A6: 2023 | B6: 68265.209 | C6: 68492.495 | D6: =D5+L6+T6 -> 68492.498 | E6: 68492.495 | F6: =F5+N6+V6 -> 68492.498 | G6: =G5+O6+W6 -> 68492.498 | I6: 2023 | J6: 677.3 | K6: {=TRANSPOSE('2022-based principal'!C16:AN16)} -> 906 | L6: ='Migration variants'!F17 -> 906 | M6: {=TRANSPOSE('2022-based low'!C16:AN16)} -> 906 | N6: =K6 -> 906 | O6: =K6 -> 906 | Q6: 2023 | R6: -15.552 | S6: {=TRANSPOSE('2022-based principal'!C11:AN11)} -> -16.263 | T6: =S6 -> -16.263 | U6: {=TRANSPOSE('2022-based low'!C11:AN11)} -> -16.263 | V6: =S6 -> -16.263 | W6: =S6 -> -16.263 | Y6: 2023 | Z6: ='[1]2022-based'!Q30 -> 68265.209 | AA6: ='[1]2022-based'!B30 -> 68492.495 | AB6: ='[1]2021-based'!Q30 -> 68265.209 | AC6: ='[1]2021-based'!D30 -> 68265.209 | AE6: 2023 | AF6: ='[1]2022-based'!R30 -> 43617.552 | AG6: ='[1]2022-based'!C30 -> 43917.531 | AH6: ='[1]2021-based'!R30 -> 43617.552 | AI6: ='[1]2021-based'!E30 -> 43617.552
A7: 2024 | B7: 69154.229 | C7: 69226.231 | D7: =D6+L7+T7 -> 69226.242 | E7: 69226.231 | F7: =F6+N7+V7 -> 69226.242 | G7: =G6+O7+W7 -> 69226.242 | I7: 2024 | J7: 728 | K7: 728 | L7: ='Migration variants'!F18 -> 728 | M7: 728 | N7: =K7 -> 728 | O7: =K7 -> 728 | Q7: 2024 | R7: 161.02 | S7: 5.744 | T7: =S7 -> 5.744 | U7: 5.744 | V7: =S7 -> 5.744 | W7: =S7 -> 5.744 | Y7: 2024 | Z7: ='[1]2022-based'!Q31 -> 69226.209 | AA7: ='[1]2022-based'!B31 -> 69226.231 | AB7: ='[1]2021-based'!Q31 -> 69154.229 | AC7: ='[1]2021-based'!D31 -> 69025.203 | AE7: 2024 | AF7: ='[1]2022-based'!R31 -> 44199.397 | AG7: ='[1]2022-based'!C31 -> 44500.02 | AH7: ='[1]2021-based'!R31 -> 44484.053 | AI7: ='[1]2021-based'!E31 -> 44364.506
A8: 2025 | B8: 69734.141 | C8: 69867.979 | D8: =D7+L8+T8 -> 69587.391 | E8: 69812.631 | F8: =F7+N8+V8 -> 69740.291 | G8: =G7+O8+W8 -> 69867.991 | I8: 2025 | J8: 503.2 | K8: 630.9 | L8: ='Migration variants'!F19 -> 350.3 | M8: 576.1 | N8: =J8 -> 503.2 | O8: =K8 -> 630.9 | Q8: 2025 | R8: 76.712 | S8: 10.849 | T8: =S8 -> 10.849 | U8: 10.288 | V8: =S8 -> 10.849 | W8: =S8 -> 10.849 | Y8: 2025 | Z8: ='[1]2022-based'!Q32 -> 69867.957 | AA8: ='[1]2022-based'!B32 -> 69867.979 | AB8: ='[1]2021-based'!Q32 -> 69734.141 | AC8: ='[1]2021-based'!D32 -> 69630.376 | AE8: 2025 | AF8: ='[1]2022-based'!R32 -> 44681.33 | AG8: ='[1]2022-based'!C32 -> 44981.953 | AH8: ='[1]2021-based'!R32 -> 44862.592 | AI8: ='[1]2021-based'!E32 -> 44764.26
A9: 2026 | B9: 70226.295 | C9: 70414.3 | D9: =D8+L9+T9 -> 69861.81 | E9: 70247.113 | F9: =F8+N9+V9 -> 70172.61 | G9: =G8+O9+W9 -> 70307.55 | I9: 2026 | J9: 419.8 | K9: 533.8 | L9: ='Migration variants'!F20 -> 261.9 | M9: 424.2 | N9: =J9 -> 419.8 | O9: =K9*0.8 -> 427.04 | Q9: 2026 | R9: 72.354 | S9: 12.519 | T9: =S9 -> 12.519 | U9: 10.279 | V9: =S9 -> 12.519 | W9: =S9 -> 12.519 | Y9: 2026 | Z9: ='[1]2022-based'!Q33 -> 70307.518 | AA9: ='[1]2022-based'!B33 -> 70414.3 | AB9: ='[1]2021-based'!Q33 -> 70226.295 | AC9: ='[1]2021-based'!D33 -> 70160.187 | AE9: 2026 | AF9: ='[1]2022-based'!R33 -> 45105.29 | AG9: ='[1]2022-based'!C33 -> 45495.34 | AH9: ='[1]2021-based'!R33 -> 45281.521 | AI9: ='[1]2021-based'!E33 -> 45214.791 | AJ9: 100000
A10: 2027 | B10: 70628.865 | C10: 70861.913 | D10: =D9+L10+T10 -> 70131.202 | E10: 70525.251 | F10: =F9+N10+V10 -> 70519.902 | G10: =G9+O10+W10 -> 70667.802 | I10: 2027 | J10: 336.4 | K10: 436.7 | L10: ='Migration variants'!F21 -> 258.5 | M10: 272.3 | N10: =J10 -> 336.4 | O10: =K10*0.8 -> 349.36 | Q10: 2027 | R10: 66.17 | S10: 10.892 | T10: =S10 -> 10.892 | U10: 5.827 | V10: =S10 -> 10.892 | W10: =S10 -> 10.892 | Y10: 2027 | Z10: ='[1]2022-based'!Q34 -> 70667.791 | AA10: ='[1]2022-based'!B34 -> 70861.913 | AB10: ='[1]2021-based'!Q34 -> 70628.865 | AC10: ='[1]2021-based'!D34 -> 70612.833 | AE10: 2027 | AF10: ='[1]2022-based'!R34 -> 45736.222 | AG10: ='[1]2022-based'!C34 -> 46199.299 | AH10: ='[1]2021-based'!R34 -> 45904.155 | AI10: ='[1]2021-based'!E34 -> 45879.422 | AJ10: 100000
A11: 2028 | B11: 70939.986 | C11: 71208.101 | D11: =D10+L11+T11 -> 70427.687 | E11: 70642.366 | F11: =F10+N11+V11 -> 70779.087 | G11: =G10+O11+W11 -> 70945.987 | I11: 2028 | J11: 253 | K11: 340 | L11: ='Migration variants'!F22 -> 290.3 | M11: 120 | N11: =J11 -> 253 | O11: =K11*0.8 -> 272 | Q11: 2028 | R11: 58.121 | S11: 6.185 | T11: =S11 -> 6.185 | U11: -2.895 | V11: =S11 -> 6.185 | W11: =S11 -> 6.185 | Y11: 2028 | Z11: ='[1]2022-based'!Q35 -> 70945.979 | AA11: ='[1]2022-based'!B35 -> 71208.101 | AB11: ='[1]2021-based'!Q35 -> 70939.986 | AC11: ='[1]2021-based'!D35 -> 70985.959 | AE11: 2028 | AF11: ='[1]2022-based'!R35 -> 46180.929 | AG11: ='[1]2022-based'!C35 -> 46700.663 | AH11: ='[1]2021-based'!R35 -> 46332.655 | AI11: ='[1]2021-based'!E35 -> 46359.85 | AJ11: 100000
A12: 2029 | B12: 71242.173 | C12: 71547.662 | D12: =D11+L12+T12 -> 70754.053 | E12: 70748.184 | F12: =F11+N12+V12 -> 71031.653 | G12: =G11+O12+W12 -> 71217.553 | I12: 2029 | J12: 253 | K12: 340 | L12: ='Migration variants'!F23 -> 326.8 | M12: 120 | N12: =J12 -> 253 | O12: =K12*0.8 -> 272 | Q12: 2029 | R12: 49.187 | S12: -0.434 | T12: =S12 -> -0.434 | U12: -14.186 | V12: =S12 -> -0.434 | W12: =S12 -> -0.434 | Y12: 2029 | Z12: ='[1]2022-based'!Q36 -> 71217.54 | AA12: ='[1]2022-based'!B36 -> 71547.662 | AB12: ='[1]2021-based'!Q36 -> 71242.173 | AC12: ='[1]2021-based'!D36 -> 71350.151 | AE12: 2029 | AF12: ='[1]2022-based'!R36 -> 46296.628 | AG12: ='[1]2022-based'!C36 -> 46873.019 | AH12: ='[1]2021-based'!R36 -> 46430.746 | AI12: ='[1]2021-based'!E36 -> 46509.867
A13: 2030 | B13: 71535.299 | C13: 71879.988 | D13: =D12+L13+T13 -> 71086.383 | E13: 70841.942 | F13: =F12+N13+V13 -> 71276.983 | G13: =G12+O13+W13 -> 71481.883 | I13: 2030 | J13: 253 | K13: 340 | L13: ='Migration variants'!F24 -> 340 | M13: 120 | N13: =J13 -> 253 | O13: =K13*0.8 -> 272 | Q13: 2030 | R13: 40.126 | S13: -7.67 | T13: =S13 -> -7.67 | U13: -26.232 | V13: =S13 -> -7.67 | W13: =S13 -> -7.67 | Y13: 2030 | Z13: ='[1]2022-based'!Q37 -> 71481.866 | AA13: ='[1]2022-based'!B37 -> 71879.988 | AB13: ='[1]2021-based'!Q37 -> 71535.299 | AC13: ='[1]2021-based'!D37 -> 71705.282 | AE13: 2030 | AF13: ='[1]2022-based'!R37 -> 46378.976 | AG13: ='[1]2022-based'!C37 -> 47012.023 | AH13: ='[1]2021-based'!R37 -> 46495.167 | AI13: ='[1]2021-based'!E37 -> 46626.215
A14: 2031 | B14: 71819.47 | C14: 72204.574 | D14: =D13+L14+T14 -> 71410.974 | E14: 70923.131 | F14: =F13+N14+V14 -> 71514.574 | G14: =G13+O14+W14 -> 71738.474 | I14: 2031 | J14: 253 | K14: 340 | L14: =L13 -> 340 | M14: 120 | N14: =J14 -> 253 | O14: =K14*0.8 -> 272 | Q14: 2031 | R14: 31.171 | S14: -15.409 | T14: =S14 -> -15.409 | U14: -38.813 | V14: =S14 -> -15.409 | W14: =S14 -> -15.409 | Y14: 2031 | Z14: ='[1]2022-based'!Q38 -> 71738.452 | AA14: ='[1]2022-based'!B38 -> 72204.574 | AB14: ='[1]2021-based'!Q38 -> 71819.47 | AC14: ='[1]2021-based'!D38 -> 72051.458 | AE14: 2031 | AF14: ='[1]2022-based'!R38 -> 46444.25 | AG14: ='[1]2022-based'!C38 -> 47133.954 | AH14: ='[1]2021-based'!R38 -> 46541.49 | AI14: ='[1]2021-based'!E38 -> 46724.465
A15: 2032 | B15: 72094.995 | C15: 72521.173 | D15: =D14+L15+T15 -> 71727.587 | E15: 70991.456 | F15: =F14+N15+V15 -> 71744.187 | G15: =G14+O15+W15 -> 71987.087 | I15: 2032 | J15: 253 | K15: 340 | L15: =L14 -> 340 | M15: 120 | N15: =J15 -> 253 | O15: =K15*0.8 -> 272 | Q15: 2032 | R15: 22.525 | S15: -23.387 | T15: =S15 -> -23.387 | U15: -51.678 | V15: =S15 -> -23.387 | W15: =S15 -> -23.387 | Y15: 2032 | Z15: ='[1]2022-based'!Q39 -> 71987.051 | AA15: ='[1]2022-based'!B39 -> 72521.173 | AB15: ='[1]2021-based'!Q39 -> 72094.995 | AC15: ='[1]2021-based'!D39 -> 72388.988 | AE15: 2032 | AF15: ='[1]2022-based'!R39 -> 46511.147 | AG15: ='[1]2022-based'!C39 -> 47257.508 | AH15: ='[1]2021-based'!R39 -> 46587.436 | AI15: ='[1]2021-based'!E39 -> 46822.337
A16: 2033 | B16: 72361.939 | C16: 72830.021 | D16: =D15+L16+T16 -> 72036.448 | E16: 71047.18 | F16: =F15+N16+V16 -> 71966.048 | G16: =G15+O16+W16 -> 72227.948 | I16: 2033 | J16: 253 | K16: 340 | L16: =L15 -> 340 | M16: 120 | N16: =J16 -> 253 | O16: =K16*0.8 -> 272 | Q16: 2033 | R16: 13.944 | S16: -31.139 | T16: =S16 -> -31.139 | U16: -64.268 | V16: =S16 -> -31.139 | W16: =S16 -> -31.139 | Y16: 2033 | Z16: ='[1]2022-based'!Q40 -> 72227.899 | AA16: ='[1]2022-based'!B40 -> 72830.021 | AB16: ='[1]2021-based'!Q40 -> 72361.939 | AC16: ='[1]2021-based'!D40 -> 72717.937 | AE16: 2033 | AF16: ='[1]2022-based'!R40 -> 46567.098 | AG16: ='[1]2022-based'!C40 -> 47370.116 | AH16: ='[1]2021-based'!R40 -> 46621.511 | AI16: ='[1]2021-based'!E40 -> 46908.339
A17: 2034 | B17: 72620.606 | C17: 73131.597 | D17: =D16+L17+T17 -> 72338.034 | E17: 71090.845 | F17: =F16+N17+V17 -> 72180.634 | G17: =G16+O17+W17 -> 72461.534 | I17: 2034 | J17: 253 | K17: 340 | L17: =L16 -> 340 | M17: 120 | N17: =J17 -> 253 | O17: =K17*0.8 -> 272 | Q17: 2034 | R17: 5.667 | S17: -38.414 | T17: =S17 -> -38.414 | U17: -76.339 | V17: =S17 -> -38.414 | W17: =S17 -> -38.414 | Y17: 2034 | Z17: ='[1]2022-based'!Q41 -> 72461.475 | AA17: ='[1]2022-based'!B41 -> 73131.597 | AB17: ='[1]2021-based'!Q41 -> 72620.606 | AC17: ='[1]2021-based'!D41 -> 73038.609 | AE17: 2034 | AF17: ='[1]2022-based'!R41 -> 46608.568 | AG17: ='[1]2022-based'!C41 -> 47468.243 | AH17: ='[1]2021-based'!R41 -> 46639.529 | AI17: ='[1]2021-based'!E41 -> 46978.284
A18: 2035 | B18: 72871.607 | C18: 73426.168 | D18: =D17+L18+T18 -> 72632.595 | E18: 71122.832 | F18: =F17+N18+V18 -> 72388.195 | G18: =G17+O18+W18 -> 72688.095 | I18: 2035 | J18: 253 | K18: 340 | L18: =L17 -> 340 | M18: 120 | N18: =J18 -> 253 | O18: =K18*0.8 -> 272 | Q18: 2035 | R18: -1.999 | S18: -45.439 | T18: =S18 -> -45.439 | U18: -88.018 | V18: =S18 -> -45.439 | W18: =S18 -> -45.439 | Y18: 2035 | Z18: ='[1]2022-based'!Q42 -> 72688.046 | AA18: ='[1]2022-based'!B42 -> 73426.168 | AB18: ='[1]2021-based'!Q42 -> 72871.607 | AC18: ='[1]2021-based'!D42 -> 73351.615 | AE18: 2035 | AF18: ='[1]2022-based'!R42 -> 46652.419 | AG18: ='[1]2022-based'!C42 -> 47568.751 | AH18: ='[1]2021-based'!R42 -> 46656.565 | AI18: ='[1]2021-based'!E42 -> 47047.246
A19: 2036 | B19: 73116.782 | C19: 73714.089 | D19: =D18+L19+T19 -> 72920.528 | E19: 71143.8 | F19: =F18+N19+V19 -> 72589.128 | G19: =G18+O19+W19 -> 72908.028 | I19: 2036 | J19: 253 | K19: 340 | L19: =L18 -> 340 | M19: 120 | N19: =J19 -> 253 | O19: =K19*0.8 -> 272 | Q19: 2036 | R19: -7.825 | S19: -52.067 | T19: =S19 -> -52.067 | U19: -99.03 | V19: =S19 -> -52.067 | W19: =S19 -> -52.067 | Y19: 2036 | Z19: ='[1]2022-based'!Q43 -> 72907.967 | AA19: ='[1]2022-based'!B43 -> 73714.089 | AB19: ='[1]2021-based'!Q43 -> 73116.782 | AC19: ='[1]2021-based'!D43 -> 73658.795 | AE19: 2036 | AF19: ='[1]2022-based'!R43 -> 46686.085 | AG19: ='[1]2022-based'!C43 -> 47659.073 | AH19: ='[1]2021-based'!R43 -> 46664.337 | AI19: ='[1]2021-based'!E43 -> 47106.945
A20: 2037 | B20: 73358.104 | C20: 73995.941 | D20: =D19+L20+T20 -> 73202.396 | E20: 71154.555 | F20: =F19+N20+V20 -> 72783.996 | G20: =G19+O20+W20 -> 73121.896 | I20: 2037 | J20: 253 | K20: 340 | L20: =L19 -> 340 | M20: 120 | N20: =J20 -> 253 | O20: =K20*0.8 -> 272 | Q20: 2037 | R20: -11.678 | S20: -58.132 | T20: =S20 -> -58.132 | U20: -109.24 | V20: =S20 -> -58.132 | W20: =S20 -> -58.132 | Y20: 2037 | Z20: ='[1]2022-based'!Q44 -> 73121.819 | AA20: ='[1]2022-based'!B44 -> 73995.941 | AB20: ='[1]2021-based'!Q44 -> 73358.104 | AC20: ='[1]2021-based'!D44 -> 73962.122 | AE20: 2037 | AF20: ='[1]2022-based'!R44 -> 46722.46 | AG20: ='[1]2022-based'!C44 -> 47752.105 | AH20: ='[1]2021-based'!R44 -> 46670.41 | AI20: ='[1]2021-based'!E44 -> 47164.945
A21: 2038 | B21: 73596.385 | C21: 74272.334 | D21: =D20+L21+T21 -> 73478.793 | E21: 71156.042 | F21: =F20+N21+V21 -> 72973.393 | G21: =G20+O21+W21 -> 73330.293 | I21: 2038 | J21: 253 | K21: 340 | L21: =L20 -> 340 | M21: 120 | N21: =J21 -> 253 | O21: =K21*0.8 -> 272 | Q21: 2038 | R21: -14.719 | S21: -63.603 | T21: =S21 -> -63.603 | U21: -118.523 | V21: =S21 -> -63.603 | W21: =S21 -> -63.603 | Y21: 2038 | Z21: ='[1]2022-based'!Q45 -> 73330.212 | AA21: ='[1]2022-based'!B45 -> 74272.334 | AB21: ='[1]2021-based'!Q45 -> 73596.385 | AC21: ='[1]2021-based'!D45 -> 74262.408 | AE21: 2038 | AF21: ='[1]2022-based'!R45 -> 46748.213 | AG21: ='[1]2022-based'!C45 -> 47834.515 | AH21: ='[1]2021-based'!R45 -> 46671.475 | AI21: ='[1]2021-based'!E45 -> 47217.936
A22: 2039 | B22: 73832.183 | C22: 74543.738 | D22: =D21+L22+T22 -> 73750.189 | E22: 71149.096 | F22: =F21+N22+V22 -> 73157.789 | G22: =G21+O22+W22 -> 73533.689 | I22: 2039 | J22: 253 | K22: 340 | L22: =L21 -> 340 | M22: 120 | N22: =J22 -> 253 | O22: =K22*0.8 -> 272 | Q22: 2039 | R22: -17.202 | S22: -68.604 | T22: =S22 -> -68.604 | U22: -126.958 | V22: =S22 -> -68.604 | W22: =S22 -> -68.604 | Y22: 2039 | Z22: ='[1]2022-based'!Q46 -> 73533.616 | AA22: ='[1]2022-based'!B46 -> 74543.738 | AB22: ='[1]2021-based'!Q46 -> 73832.183 | AC22: ='[1]2021-based'!D46 -> 74560.211 | AE22: 2039 | AF22: ='[1]2022-based'!R46 -> 46772.661 | AG22: ='[1]2022-based'!C46 -> 47915.62 | AH22: ='[1]2021-based'!R46 -> 46673.662 | AI22: ='[1]2021-based'!E46 -> 47272.05
A23: 2040 | B23: 74065.817 | C23: 74810.478 | D23: =D22+L23+T23 -> 74016.941 | E23: 71134.408 | F23: =F22+N23+V23 -> 73337.541 | G23: =G22+O23+W23 -> 73732.441 | I23: 2040 | J23: 253 | K23: 340 | L23: =L22 -> 340 | M23: 120 | N23: =J23 -> 253 | O23: =K23*0.8 -> 272 | Q23: 2040 | R23: -19.366 | S23: -73.248 | T23: =S23 -> -73.248 | U23: -134.682 | V23: =S23 -> -73.248 | W23: =S23 -> -73.248 | Y23: 2040 | Z23: ='[1]2022-based'!Q47 -> 73732.356 | AA23: ='[1]2022-based'!B47 -> 74810.478 | AB23: ='[1]2021-based'!Q47 -> 74065.817 | AC23: ='[1]2021-based'!D47 -> 74855.85 | AE23: 2040 | AF23: ='[1]2022-based'!R47 -> 46827.023 | AG23: ='[1]2022-based'!C47 -> 48026.639 | AH23: ='[1]2021-based'!R47 -> 46752.706 | AI23: ='[1]2021-based'!E47 -> 47403.021
A24: 2041 | B24: 74296.873 | C24: 75072.892 | D24: =D23+L24+T24 -> 74279.362 | E24: 71112.67 | F24: =F23+N24+V24 -> 73512.962 | G24: =G23+O24+W24 -> 73926.862 | I24: 2041 | J24: 253 | K24: 340 | L24: =L23 -> 340 | M24: 120 | N24: =J24 -> 253 | O24: =K24*0.8 -> 272 | Q24: 2041 | R24: -21.944 | S24: -77.579 | T24: =S24 -> -77.579 | U24: -141.739 | V24: =S24 -> -77.579 | W24: =S24 -> -77.579 | Y24: 2041 | Z24: ='[1]2022-based'!Q48 -> 73926.77 | AA24: ='[1]2022-based'!B48 -> 75072.892 | AB24: ='[1]2021-based'!Q48 -> 74296.873 | AC24: ='[1]2021-based'!D48 -> 75148.911 | AE24: 2041 | AF24: ='[1]2022-based'!R48 -> 46914.979 | AG24: ='[1]2022-based'!C48 -> 48171.252 | AH24: ='[1]2021-based'!R48 -> 46869.518 | AI24: ='[1]2021-based'!E48 -> 47571.759
A25: 2042 | B25: 74524.852 | C25: 75331.209 | D25: =D24+L25+T25 -> 74537.682 | E25: 71084.426 | F25: =F24+N25+V25 -> 73684.282 | G25: =G24+O25+W25 -> 74117.182 | I25: 2042 | J25: 253 | K25: 340 | L25: =L24 -> 340 | M25: 120 | N25: =J25 -> 253 | O25: =K25*0.8 -> 272 | Q25: 2042 | R25: -25.021 | S25: -81.68 | T25: =S25 -> -81.68 | U25: -148.251 | V25: =S25 -> -81.68 | W25: =S25 -> -81.68 | Y25: 2042 | Z25: ='[1]2022-based'!Q49 -> 74117.087 | AA25: ='[1]2022-based'!B49 -> 75331.209 | AB25: ='[1]2021-based'!Q49 -> 74524.852 | AC25: ='[1]2021-based'!D49 -> 75438.895 | AE25: 2042 | AF25: ='[1]2022-based'!R49 -> 47014.811 | AG25: ='[1]2022-based'!C49 -> 48327.74 | AH25: ='[1]2021-based'!R49 -> 46998.436 | AI25: ='[1]2021-based'!E49 -> 47752.604
A26: 2043 | B26: 74749.709 | C26: 75585.236 | D26: =D25+L26+T26 -> 74791.724 | E26: 71049.754 | F26: =F25+N26+V26 -> 73851.324 | G26: =G25+O26+W26 -> 74303.224 | I26: 2043 | J26: 253 | K26: 340 | L26: =L25 -> 340 | M26: 120 | N26: =J26 -> 253 | O26: =K26*0.8 -> 272 | Q26: 2043 | R26: -28.143 | S26: -85.958 | T26: =S26 -> -85.958 | U26: -154.657 | V26: =S26 -> -85.958 | W26: =S26 -> -85.958 | Y26: 2043 | Z26: ='[1]2022-based'!Q50 -> 74303.114 | AA26: ='[1]2022-based'!B50 -> 75585.236 | AB26: ='[1]2021-based'!Q50 -> 74749.709 | AC26: ='[1]2021-based'!D50 -> 75725.757 | AE26: 2043 | AF26: ='[1]2022-based'!R50 -> 47128.745 | AG26: ='[1]2022-based'!C50 -> 48498.331 | AH26: ='[1]2021-based'!R50 -> 47142.266 | AI26: ='[1]2021-based'!E50 -> 47948.361
A27: 2044 | B27: 74971.281 | C27: 75834.507 | D27: =D26+L27+T27 -> 75040.989 | E27: 71008.509 | F27: =F26+N27+V27 -> 74013.589 | G27: =G26+O27+W27 -> 74484.489 | I27: 2044 | J27: 253 | K27: 340 | L27: =L26 -> 340 | M27: 120 | N27: =J27 -> 253 | O27: =K27*0.8 -> 272 | Q27: 2044 | R27: -31.428 | S27: -90.735 | T27: =S27 -> -90.735 | U27: -161.252 | V27: =S27 -> -90.735 | W27: =S27 -> -90.735 | Y27: 2044 | Z27: ='[1]2022-based'!Q51 -> 74484.385 | AA27: ='[1]2022-based'!B51 -> 75834.507 | AB27: ='[1]2021-based'!Q51 -> 74971.281 | AC27: ='[1]2021-based'!D51 -> 76009.334 | AE27: 2044 | AF27: ='[1]2022-based'!R51 -> 47370.251 | AG27: ='[1]2022-based'!C51 -> 48796.494 | AH27: ='[1]2021-based'!R51 -> 47414.701 | AI27: ='[1]2021-based'!E51 -> 48272.722 | AJ27: 100000
A28: 2045 | B28: 75188.12 | C28: 76078.686 | D28: =D27+L28+T28 -> 75285.169 | E28: 70960.588 | F28: =F27+N28+V28 -> 74170.769 | G28: =G27+O28+W28 -> 74660.669 | I28: 2045 | J28: 253 | K28: 340 | L28: =L27 -> 340 | M28: 120 | N28: =J28 -> 253 | O28: =K28*0.8 -> 272 | Q28: 2045 | R28: -36.161 | S28: -95.82 | T28: =S28 -> -95.82 | U28: -167.915 | V28: =S28 -> -95.82 | W28: =S28 -> -95.82 | Y28: 2045 | Z28: ='[1]2022-based'!Q52 -> 74660.564 | AA28: ='[1]2022-based'!B52 -> 76078.686 | AB28: ='[1]2021-based'!Q52 -> 75188.12 | AC28: ='[1]2021-based'!D52 -> 76288.178 | AE28: 2045 | AF28: ='[1]2022-based'!R52 -> 47856.559 | AG28: ='[1]2022-based'!C52 -> 49339.459 | AH28: ='[1]2021-based'!R52 -> 47932.917 | AI28: ='[1]2021-based'!E52 -> 48842.866 | AJ28: 100000
A29: 2046 | B29: 75398.568 | C29: 76317.48 | D29: =D28+L29+T29 -> 75523.984 | E29: 70905.848 | F29: =F28+N29+V29 -> 74322.584 | G29: =G28+O29+W29 -> 74831.484 | I29: 2046 | J29: 253 | K29: 340 | L29: =L28 -> 340 | M29: 120 | N29: =J29 -> 253 | O29: =K29*0.8 -> 272 | Q29: 2046 | R29: -42.552 | S29: -101.185 | T29: =S29 -> -101.185 | U29: -174.727 | V29: =S29 -> -101.185 | W29: =S29 -> -101.185 | Y29: 2046 | Z29: ='[1]2022-based'!Q53 -> 74831.358 | AA29: ='[1]2022-based'!B53 -> 76317.48 | AB29: ='[1]2021-based'!Q53 -> 75398.568 | AC29: ='[1]2021-based'!D53 -> 76560.631 | AE29: 2046 | AF29: ='[1]2022-based'!R53 -> 48232.802 | AG29: ='[1]2022-based'!C53 -> 49772.297 | AH29: ='[1]2021-based'!R53 -> 48340.089 | AI29: ='[1]2021-based'!E53 -> 49301.91 | AJ29: 100000
A30: 2047 | B30: 75602.145 | C30: 76550.535 | D30: =D29+L30+T30 -> 75757.036 | E30: 70844.131 | F30: =F29+N30+V30 -> 74468.636 | G30: =G29+O30+W30 -> 74996.536 | I30: 2047 | J30: 253 | K30: 340 | L30: =L29 -> 340 | M30: 120 | N30: =J30 -> 253 | O30: =K30*0.8 -> 272 | Q30: 2047 | R30: -49.423 | S30: -106.948 | T30: =S30 -> -106.948 | U30: -181.729 | V30: =S30 -> -106.948 | W30: =S30 -> -106.948 | Y30: 2047 | Z30: ='[1]2022-based'!Q54 -> 74996.413 | AA30: ='[1]2022-based'!B54 -> 76550.535 | AB30: ='[1]2021-based'!Q54 -> 75602.145 | AC30: ='[1]2021-based'!D54 -> 76826.213 | AE30: 2047 | AF30: ='[1]2022-based'!R54 -> 48291.625 | AG30: ='[1]2022-based'!C54 -> 49887.751 | AH30: ='[1]2021-based'!R54 -> 48428.709 | AI30: ='[1]2021-based'!E54 -> 49442.435
A31: 2048 | B31: 75798.418 | C31: 76776.46 | D31: =D30+L31+T31 -> 75982.957 | E31: 70774.277 | F31: =F30+N31+V31 -> 74607.557 | G31: =G30+O31+W31 -> 75154.457 | I31: 2048 | J31: 253 | K31: 340 | L31: =L30 -> 340 | M31: 120 | N31: =J31 -> 253 | O31: =K31*0.8 -> 272 | Q31: 2048 | R31: -56.727 | S31: -114.079 | T31: =S31 -> -114.079 | U31: -189.857 | V31: =S31 -> -114.079 | W31: =S31 -> -114.079 | Y31: 2048 | Z31: ='[1]2022-based'!Q55 -> 75154.338 | AA31: ='[1]2022-based'!B55 -> 76776.46 | AB31: ='[1]2021-based'!Q55 -> 75798.418 | AC31: ='[1]2021-based'!D55 -> 77084.491 | AE31: 2048 | AF31: ='[1]2022-based'!R55 -> 48315.945 | AG31: ='[1]2022-based'!C55 -> 49968.728 | AH31: ='[1]2021-based'!R55 -> 48482.09 | AI31: ='[1]2021-based'!E55 -> 49547.743
A32: 2049 | B32: 75986.883 | C32: 76993.637 | D32: =D31+L32+T32 -> 76200.13 | E32: 70694.92 | F32: =F31+N32+V32 -> 74737.73 | G32: =G31+O32+W32 -> 75303.63 | I32: 2049 | J32: 253 | K32: 340 | L32: =L31 -> 340 | M32: 120 | N32: =J32 -> 253 | O32: =K32*0.8 -> 272 | Q32: 2049 | R32: -64.535 | S32: -122.827 | T32: =S32 -> -122.827 | U32: -199.356 | V32: =S32 -> -122.827 | W32: =S32 -> -122.827 | Y32: 2049 | Z32: ='[1]2022-based'!Q56 -> 75303.515 | AA32: ='[1]2022-based'!B56 -> 76993.637 | AB32: ='[1]2021-based'!Q56 -> 75986.883 | AC32: ='[1]2021-based'!D56 -> 77334.961 | AE32: 2049 | AF32: ='[1]2022-based'!R56 -> 48340.137 | AG32: ='[1]2022-based'!C56 -> 50049.577 | AH32: ='[1]2021-based'!R56 -> 48535.572 | AI32: ='[1]2021-based'!E56 -> 49653.151
A33: 2050 | B33: 76167.384 | C33: 77201.483 | D33: =D32+L33+T33 -> 76407.98 | E33: 70605.494 | F33: =F32+N33+V33 -> 74858.58 | G33: =G32+O33+W33 -> 75443.48 | I33: 2050 | J33: 253 | K33: 340 | L33: =L32 -> 340 | M33: 120 | N33: =J33 -> 253 | O33: =K33*0.8 -> 272 | Q33: 2050 | R33: -72.499 | S33: -132.15 | T33: =S33 -> -132.15 | U33: -209.429 | V33: =S33 -> -132.15 | W33: =S33 -> -132.15 | Y33: 2050 | Z33: ='[1]2022-based'!Q57 -> 75443.361 | AA33: ='[1]2022-based'!B57 -> 77201.483 | AB33: ='[1]2021-based'!Q57 -> 76167.384 | AC33: ='[1]2021-based'!D57 -> 77577.467 | AE33: 2050 | AF33: ='[1]2022-based'!R57 -> 48370.682 | AG33: ='[1]2022-based'!C57 -> 50136.779 | AH33: ='[1]2021-based'!R57 -> 48593.634 | AI33: ='[1]2021-based'!E57 -> 49763.14
A34: 2051 | B34: 76340.093 | C34: 77399.645 | D34: =D33+L34+T34 -> 76606.133 | E34: 70505.698 | F34: =F33+N34+V34 -> 74969.733 | G34: =G33+O34+W34 -> 75573.633 | I34: 2051 | J34: 253 | K34: 340 | L34: =L33 -> 340 | M34: 120 | N34: =J34 -> 253 | O34: =K34*0.8 -> 272 | Q34: 2051 | R34: -80.291 | S34: -141.847 | T34: =S34 -> -141.847 | U34: -219.798 | V34: =S34 -> -141.847 | W34: =S34 -> -141.847 | Y34: 2051 | Z34: ='[1]2022-based'!Q58 -> 75573.523 | AA34: ='[1]2022-based'!B58 -> 77399.645 | AB34: ='[1]2021-based'!Q58 -> 76340.093 | AC34: ='[1]2021-based'!D58 -> 77812.181 | AE34: 2051 | AF34: ='[1]2022-based'!R58 -> 48394.392 | AG34: ='[1]2022-based'!C58 -> 50217.146 | AH34: ='[1]2021-based'!R58 -> 48645.648 | AI34: ='[1]2021-based'!E58 -> 49867.081
A35: 2052 | B35: 76505.255 | C35: 77588.049 | D35: =D34+L35+T35 -> 76794.549 | E35: 70395.487 | F35: =F34+N35+V35 -> 75071.149 | G35: =G34+O35+W35 -> 75694.049 | I35: 2052 | J35: 253 | K35: 340 | L35: =L34 -> 340 | M35: 120 | N35: =J35 -> 253 | O35: =K35*0.8 -> 272 | Q35: 2052 | R35: -87.838 | S35: -151.584 | T35: =S35 -> -151.584 | U35: -230.208 | V35: =S35 -> -151.584 | W35: =S35 -> -151.584 | Y35: 2052 | Z35: ='[1]2022-based'!Q59 -> 75693.927 | AA35: ='[1]2022-based'!B59 -> 77588.049 | AB35: ='[1]2021-based'!Q59 -> 76505.255 | AC35: ='[1]2021-based'!D59 -> 78039.348 | AE35: 2052 | AF35: ='[1]2022-based'!R59 -> 48415.723 | AG35: ='[1]2022-based'!C59 -> 50295.133 | AH35: ='[1]2021-based'!R59 -> 48696.22 | AI35: ='[1]2021-based'!E59 -> 49969.579
A36: 2053 | B36: 76663.196 | C36: 77766.71 | D36: =D35+L36+T36 -> 76973.212 | E36: 70274.803 | F36: =F35+N36+V36 -> 75162.812 | G36: =G35+O36+W36 -> 75804.712 | I36: 2053 | J36: 253 | K36: 340 | L36: =L35 -> 340 | M36: 120 | N36: =J36 -> 253 | O36: =K36*0.8 -> 272 | Q36: 2053 | R36: -95.059 | S36: -161.337 | T36: =S36 -> -161.337 | U36: -240.684 | V36: =S36 -> -161.337 | W36: =S36 -> -161.337 | Y36: 2053 | Z36: ='[1]2022-based'!Q60 -> 75804.588 | AA36: ='[1]2022-based'!B60 -> 77766.71 | AB36: ='[1]2021-based'!Q60 -> 76663.196 | AC36: ='[1]2021-based'!D60 -> 78259.294 | AE36: 2053 | AF36: ='[1]2022-based'!R60 -> 48408.043 | AG36: ='[1]2022-based'!C60 -> 50344.11 | AH36: ='[1]2021-based'!R60 -> 48719.279 | AI36: ='[1]2021-based'!E60 -> 50044.565
A37: 2054 | B37: 76814.554 | C37: 77935.834 | D37: =D36+L37+T37 -> 77142.342 | E37: 70143.805 | F37: =F36+N37+V37 -> 75244.942 | G37: =G36+O37+W37 -> 75905.842 | I37: 2054 | J37: 253 | K37: 340 | L37: =L36 -> 340 | M37: 120 | N37: =J37 -> 253 | O37: =K37*0.8 -> 272 | Q37: 2054 | R37: -101.642 | S37: -170.87 | T37: =S37 -> -170.87 | U37: -250.986 | V37: =S37 -> -170.87 | W37: =S37 -> -170.87 | Y37: 2054 | Z37: ='[1]2022-based'!Q61 -> 75905.712 | AA37: ='[1]2022-based'!B61 -> 77935.834 | AB37: ='[1]2021-based'!Q61 -> 76814.554 | AC37: ='[1]2021-based'!D61 -> 78472.657 | AE37: 2054 | AF37: ='[1]2022-based'!R61 -> 48393.247 | AG37: ='[1]2022-based'!C61 -> 50385.971 | AH37: ='[1]2021-based'!R61 -> 48736.911 | AI37: ='[1]2021-based'!E61 -> 50114.124
A38: 2055 | B38: 76960.345 | C38: 78096.133 | D38: =D37+L38+T38 -> 77302.651 | E38: 70003.176 | F38: =F37+N38+V38 -> 75318.251 | G38: =G37+O38+W38 -> 75998.151 | I38: 2055 | J38: 253 | K38: 340 | L38: =L37 -> 340 | M38: 120 | N38: =J38 -> 253 | O38: =K38*0.8 -> 272 | Q38: 2055 | R38: -107.209 | S38: -179.691 | T38: =S38 -> -179.691 | U38: -260.623 | V38: =S38 -> -179.691 | W38: =S38 -> -179.691 | Y38: 2055 | Z38: ='[1]2022-based'!Q62 -> 75998.011 | AA38: ='[1]2022-based'!B62 -> 78096.133 | AB38: ='[1]2021-based'!Q62 -> 76960.345 | AC38: ='[1]2021-based'!D62 -> 78680.453 | AE38: 2055 | AF38: ='[1]2022-based'!R62 -> 48367.98 | AG38: ='[1]2022-based'!C62 -> 50417.361 | AH38: ='[1]2021-based'!R62 -> 48744.978 | AI38: ='[1]2021-based'!E62 -> 50174.117
A39: 2056 | B39: 77101.628 | C39: 78248.758 | D39: =D38+L39+T39 -> 77455.27 | E39: 69853.972 | F39: =F38+N39+V39 -> 75383.87 | G39: =G38+O39+W39 -> 76082.77 | I39: 2056 | J39: 253 | K39: 340 | L39: =L38 -> 340 | M39: 120 | N39: =J39 -> 253 | O39: =K39*0.8 -> 272 | Q39: 2056 | R39: -111.717 | S39: -187.381 | T39: =S39 -> -187.381 | U39: -269.204 | V39: =S39 -> -187.381 | W39: =S39 -> -187.381 | Y39: 2056 | Z39: ='[1]2022-based'!Q63 -> 76082.636 | AA39: ='[1]2022-based'!B63 -> 78248.758 | AB39: ='[1]2021-based'!Q63 -> 77101.628 | AC39: ='[1]2021-based'!D63 -> 78883.741 | AE39: 2056 | AF39: ='[1]2022-based'!R63 -> 48317.418 | AG39: ='[1]2022-based'!C63 -> 50423.456 | AH39: ='[1]2021-based'!R63 -> 48729.948 | AI39: ='[1]2021-based'!E63 -> 50211.014
A40: 2057 | B40: 77239.584 | C40: 78394.896 | D40: =D39+L40+T40 -> 77601.409 | E40: 69697.317 | F40: =F39+N40+V40 -> 75443.009 | G40: =G39+O40+W40 -> 76160.909 | I40: 2057 | J40: 253 | K40: 340 | L40: =L39 -> 340 | M40: 120 | N40: =J40 -> 253 | O40: =K40*0.8 -> 272 | Q40: 2057 | R40: -115.044 | S40: -193.861 | T40: =S40 -> -193.861 | U40: -276.651 | V40: =S40 -> -193.861 | W40: =S40 -> -193.861 | Y40: 2057 | Z40: ='[1]2022-based'!Q64 -> 76160.774 | AA40: ='[1]2022-based'!B64 -> 78394.896 | AB40: ='[1]2021-based'!Q64 -> 77239.584 | AC40: ='[1]2021-based'!D64 -> 79083.702 | AE40: 2057 | AF40: ='[1]2022-based'!R64 -> 48270.877 | AG40: ='[1]2022-based'!C64 -> 50433.572 | AH40: ='[1]2021-based'!R64 -> 48719.333 | AI40: ='[1]2021-based'!E64 -> 50252.326
...

Sheet Migration variants
A1: Figure 2: The variant international migration assumptions provide a range of alternative migration scenarios
A2: Net international migration estimates, principal and variant migration assumptions, UK, year ending (YE) mid-2014 to YE mid-2030
A4: Notes | B4: 1. Long-term assumptions are rounded to the nearest 5,000 (UK) and 500 (UK countries). 2. Our international migration statistics are [official statistics in development](https://osr.statisticsauthority.gov.uk/policies/official-statistics-policies/official-statistics-in-development/). This means estimates may be updated as improvements are introduced.
A5: Unit | B5: Persons, thousands
A7: Year ending mid- | B7: Estimated Net Migration | C7: Principal Projection: Projected Net Migration | D7: High Variant Projection: Projected Net Migration | E7: Low Variant Projection: Projected Net Migration | F7: Migration Category Variant Projection: Projected Net Migration | G7: Zero net migration Variant Projection: Projected Net Migration
A8: 2014 | B8: 248.1
A9: 2015 | B9: 297.5
A10: 2016 | B10: 328.2
A11: 2017 | B11: 204.1
A12: 2018 | B12: 217.6
A13: 2019 | B13: 228.2
A14: 2020 | B14: 101.9
A15: 2021 | B15: 254
A16: 2022 | B16: 634
A17: 2023 | B17: 906 | C17: 906 | D17: 906 | E17: 906 | F17: 906 | G17: 0
A18: 2024 | B18: 728 | C18: 728 | D18: 728 | E18: 728 | F18: 728 | G18: 0
A19: 2025 | C19: 630.9 | D19: 677.2 | E19: 576.1 | F19: 350.3 | G19: 0
A20: 2026 | C20: 533.8 | D20: 626.4 | E20: 424.2 | F20: 261.9 | G20: 0
A21: 2027 | C21: 436.7 | D21: 575.6 | E21: 272.3 | F21: 258.5 | G21: 0
A22: 2028 | C22: 340 | D22: 525 | E22: 120 | F22: 290.3 | G22: 0
A23: 2029 | C23: 340 | D23: 525 | E23: 120 | F23: 326.8 | G23: 0
A24: 2030 | C24: 340 | D24: 525 | E24: 120 | F24: 340 | G24: 0

Sheet 2022-based principal
A1: Persons, thousands - population by broad age group, components of change and summary statistics [note 1]
A2: United Kingdom (UK)
A3: Principal projection
A4: This worksheet contains three tables presented vertically with one blank row between each table. Some cells refer to notes which can be found on the notes worksheet.
A5: Shorthand is used, z = not applicable
A6: Table 1: Projected population, components of change (to mid-year ending), Total Fertility Rate (TFR) and Expectation Of Life At Birth (EOLB) based on the mortality rates for the year
A7: Components | B7: 2022 [note 2] | C7: 2023 | D7: 2024 | E7: 2025 | F7: 2026 | G7: 2027 | H7: 2028 | I7: 2029 | J7: 2030 | K7: 2031 | L7: 2032 | M7: 2033 | N7: 2034 | O7: 2035 | P7: 2036 | Q7: 2037 | R7: 2038 | S7: 2039 | T7: 2040 | U7: 2041 | V7: 2042 | W7: 2043 | X7: 2044 | Y7: 2045 | Z7: 2046 | AA7: 2047 | AB7: 2048 | AC7: 2049 | AD7: 2050 | AE7: 2051 | AF7: 2052 | AG7: 2053 | AH7: 2054 | AI7: 2055 | AJ7: 2056 | AK7: 2057 | AL7: 2058 | AM7: 2059 | AN7: 2060 | AO7: 2061 | AP7: 2062 | AQ7: 2063 | AR7: 2064 | AS7: 2065 | AT7: 2066 | AU7: 2067 | AV7: 2068 | AW7: 2069 | AX7: 2070 | AY7: 2071 | AZ7: 2072 | BA7: 2073 | BB7: 2074 | BC7: 2075 | BD7: 2076 | BE7: 2077 | BF7: 2078 | BG7: 2079 | BH7: 2080 | BI7: 2081 | BJ7: 2082 | BK7: 2083 | BL7: 2084 | BM7: 2085 | BN7: 2086 | BO7: 2087 | BP7: 2088 | BQ7: 2089 | BR7: 2090 | BS7: 2091 | BT7: 2092 | BU7: 2093 | BV7: 2094 | BW7: 2095 | BX7: 2096 | BY7: 2097 | BZ7: 2098 | CA7: 2099 | CB7: 2100 | CC7: 2101 | CD7: 2102 | CE7: 2103 | CF7: 2104 | CG7: 2105 | CH7: 2106 | CI7: 2107 | CJ7: 2108 | CK7: 2109 | CL7: 2110 | CM7: 2111 | CN7: 2112 | CO7: 2113 | CP7: 2114 | CQ7: 2115 | CR7: 2116 | CS7: 2117 | CT7: 2118 | CU7: 2119 | CV7: 2120 | CW7: 2121 | CX7: 2122
A8: Population at start | B8: [z] | C8: 67602.761 | D8: 68492.495 | E8: 69226.231 | F8: 69867.979 | G8: 70414.3 | H8: 70861.913 | I8: 71208.101 | J8: 71547.662 | K8: 71879.988 | L8: 72204.574 | M8: 72521.173 | N8: 72830.021 | O8: 73131.597 | P8: 73426.168 | Q8: 73714.089 | R8: 73995.941 | S8: 74272.334 | T8: 74543.738 | U8: 74810.478 | V8: 75072.892 | W8: 75331.209 | X8: 75585.236 | Y8: 75834.507 | Z8: 76078.686 | AA8: 76317.48 | AB8: 76550.535 | AC8: 76776.46 | AD8: 76993.637 | AE8: 77201.483 | AF8: 77399.645 | AG8: 77588.049 | AH8: 77766.71 | AI8: 77935.834 | AJ8: 78096.133 | AK8: 78248.758 | AL8: 78394.896 | AM8: 78535.61 | AN8: 78672.036 | AO8: 78805.317 | AP8: 78936.487 | AQ8: 79066.48 | AR8: 79195.863 | AS8: 79325.004 | AT8: 79454.27 | AU8: 79583.857 | AV8: 79713.62 | AW8: 79843.214 | AX8: 79972.1 | AY8: 80099.544 | AZ8: 80224.705 | BA8: 80346.626 | BB8: 80464.328 | BC8: 80576.958 | BD8: 80683.666 | BE8: 80783.805 | BF8: 80876.875 | BG8: 80962.574 | BH8: 81040.744 | BI8: 81111.28 | BJ8: 81174.269 | BK8: 81229.882 | BL8: 81278.373 | BM8: 81320.103 | BN8: 81355.442 | BO8: 81384.875 | BP8: 81408.957 | BQ8: 81428.186 | BR8: 81443.111 | BS8: 81454.243 | BT8: 81462.068 | BU8: 81467.091 | BV8: 81469.704 | BW8: 81470.32 | BX8: 81469.232 | BY8: 81466.731 | BZ8: 81463.093 | CA8: 81458.489 | CB8: 81453.12 | CC8: 81447.095 | CD8: 81440.608 | CE8: 81433.781 | CF8: 81426.783 | CG8: 81419.829 | CH8: 81413.183 | CI8: 81407.2 | CJ8: 81402.25 | CK8: 81398.709 | CL8: 81396.967 | CM8: 81397.436 | CN8: 81400.459 | CO8: 81406.276 | CP8: 81415.084 | CQ8: 81426.996 | CR8: 81442.03 | CS8: 81460.095 | CT8: 81480.985 | CU8: 81504.456 | CV8: 81530.145 | CW8: 81557.639 | CX8: 81586.535
A9: Births | B9: [z] | C9: 664.464 | D9: 667.909 | E9: 674.821 | F9: 679.536 | G9: 682.033 | H9: 683.078 | I9: 683.712 | J9: 684.296 | K9: 684.842 | L9: 685.388 | M9: 686.341 | N9: 687.824 | O9: 689.489 | P9: 691.363 | Q9: 693.541 | R9: 696.057 | S9: 698.697 | T9: 701.18 | U9: 703.429 | V9: 705.443 | W9: 706.766 | X9: 707.187 | Y9: 707.052 | Z9: 706.476 | AA9: 705.561 | AB9: 703.392 | AC9: 699.815 | AD9: 695.821 | AE9: 691.576 | AF9: 687.291 | AG9: 682.886 | AH9: 678.412 | AI9: 674.276 | AJ9: 670.711 | AK9: 667.758 | AL9: 665.234 | AM9: 663.165 | AN9: 661.617 | AO9: 660.582 | AP9: 660.03 | AQ9: 659.744 | AR9: 659.66 | AS9: 659.953 | AT9: 660.535 | AU9: 661.282 | AV9: 662.134 | AW9: 662.999 | AX9: 663.833 | AY9: 664.673 | AZ9: 665.418 | BA9: 666.027 | BB9: 666.469 | BC9: 666.715 | BD9: 666.758 | BE9: 666.554 | BF9: 666.115 | BG9: 665.435 | BH9: 664.498 | BI9: 663.336 | BJ9: 661.957 | BK9: 660.421 | BL9: 658.743 | BM9: 656.976 | BN9: 655.182 | BO9: 653.387 | BP9: 651.671 | BQ9: 650.031 | BR9: 648.514 | BS9: 647.138 | BT9: 645.944 | BU9: 644.941 | BV9: 644.117 | BW9: 643.472 | BX9: 642.999 | BY9: 642.684 | BZ9: 642.513 | CA9: 642.452 | CB9: 642.491 | CC9: 642.589 | CD9: 642.723 | CE9: 642.878 | CF9: 643.028 | CG9: 643.138 | CH9: 643.208 | CI9: 643.209 | CJ9: 643.128 | CK9: 642.964 | CL9: 642.707 | CM9: 642.348 | CN9: 641.901 | CO9: 641.359 | CP9: 640.734 | CQ9: 640.034 | CR9: 639.269 | CS9: 638.464 | CT9: 637.628 | CU9: 636.771 | CV9: 635.916 | CW9: 635.074 | CX9: 634.267
A10: Deaths | B10: [z] | C10: 680.727 | D10: 662.165 | E10: 663.972 | F10: 667.017 | G10: 671.141 | H10: 676.893 | I10: 684.146 | J10: 691.966 | K10: 700.251 | L10: 708.775 | M10: 717.48 | N10: 726.238 | O10: 734.928 | P10: 743.43 | Q10: 751.673 | R10: 759.66 | S10: 767.301 | T10: 774.428 | U10: 781.008 | V10: 787.123 | W10: 792.724 | X10: 797.922 | Y10: 802.872 | Z10: 807.661 | AA10: 812.509 | AB10: 817.471 | AC10: 822.642 | AD10: 827.971 | AE10: 833.423 | AF10: 838.875 | AG10: 844.223 | AH10: 849.282 | AI10: 853.967 | AJ10: 858.092 | AK10: 861.619 | AL10: 864.525 | AM10: 866.729 | AN10: 868.334 | AO10: 869.393 | AP10: 870.025 | AQ10: 870.358 | AR10: 870.515 | AS10: 870.672 | AT10: 870.944 | AU10: 871.519 | AV10: 872.533 | AW10: 874.107 | AX10: 876.379 | AY10: 879.509 | AZ10: 883.49 | BA10: 888.312 | BB10: 893.842 | BC10: 900.001 | BD10: 906.602 | BE10: 913.48 | BF10: 920.421 | BG10: 927.267 | BH10: 933.959 | BI10: 940.342 | BJ10: 946.35 | BK10: 951.927 | BL10: 957.03 | BM10: 961.627 | BN10: 965.737 | BO10: 969.312 | BP10: 972.441 | BQ10: 975.097 | BR10: 977.368 | BS10: 979.317 | BT10: 980.928 | BU10: 982.323 | BV10: 983.499 | BW10: 984.564 | BX10: 985.498 | BY10: 986.324 | BZ10: 987.109 | CA10: 987.824 | CB10: 988.499 | CC10: 989.073 | CD10: 989.552 | CE10: 989.875 | CF10: 989.985 | CG10: 989.778 | CH10: 989.183 | CI10: 988.158 | CJ10: 986.672 | CK10: 984.706 | CL10: 982.241 | CM10: 979.329 | CN10: 976.069 | CO10: 972.545 | CP10: 968.82 | CQ10: 964.992 | CR10: 961.212 | CS10: 957.564 | CT10: 954.156 | CU10: 951.083 | CV10: 948.41 | CW10: 946.163 | CX10: 944.429
A11: Natural Change | B11: [z] | C11: -16.263 | D11: 5.744 | E11: 10.849 | F11: 12.519 | G11: 10.892 | H11: 6.185 | I11: -0.434 | J11: -7.67 | K11: -15.409 | L11: -23.387 | M11: -31.139 | N11: -38.414 | O11: -45.439 | P11: -52.067 | Q11: -58.132 | R11: -63.603 | S11: -68.604 | T11: -73.248 | U11: -77.579 | V11: -81.68 | W11: -85.958 | X11: -90.735 | Y11: -95.82 | Z11: -101.185 | AA11: -106.948 | AB11: -114.079 | AC11: -122.827 | AD11: -132.15 | AE11: -141.847 | AF11: -151.584 | AG11: -161.337 | AH11: -170.87 | AI11: -179.691 | AJ11: -187.381 | AK11: -193.861 | AL11: -199.291 | AM11: -203.564 | AN11: -206.717 | AO11: -208.811 | AP11: -209.995 | AQ11: -210.614 | AR11: -210.855 | AS11: -210.719 | AT11: -210.409 | AU11: -210.237 | AV11: -210.399 | AW11: -211.108 | AX11: -212.546 | AY11: -214.836 | AZ11: -218.072 | BA11: -222.285 | BB11: -227.373 | BC11: -233.286 | BD11: -239.844 | BE11: -246.926 | BF11: -254.306 | BG11: -261.832 | BH11: -269.461 | BI11: -277.006 | BJ11: -284.393 | BK11: -291.506 | BL11: -298.287 | BM11: -304.651 | BN11: -310.555 | BO11: -315.925 | BP11: -320.77 | BQ11: -325.066 | BR11: -328.854 | BS11: -332.179 | BT11: -334.984 | BU11: -337.382 | BV11: -339.382 | BW11: -341.092 | BX11: -342.499 | BY11: -343.64 | BZ11: -344.596 | CA11: -345.372 | CB11: -346.008 | CC11: -346.484 | CD11: -346.829 | CE11: -346.997 | CF11: -346.957 | CG11: -346.64 | CH11: -345.975 | CI11: -344.949 | CJ11: -343.544 | CK11: -341.742 | CL11: -339.534 | CM11: -336.981 | CN11: -334.168 | CO11: -331.186 | CP11: -328.086 | CQ11: -324.958 | CR11: -321.943 | CS11: -319.1 | CT11: -316.528 | CU11: -314.312 | CV11: -312.494 | CW11: -311.089 | CX11: -310.162
A12: International migration inflows | B12: [z] | C12: 1319.5 | D12: 1207 | E12: 1119.7 | F12: 1032.4 | G12: 945.1 | H12: 858 | I12: 858 | J12: 858 | K12: 858 | L12: 858 | M12: 858 | N12: 858 | O12: 858 | P12: 858 | Q12: 858 | R12: 858 | S12: 858 | T12: 858 | U12: 858 | V12: 858 | W12: 858 | X12: 858 | Y12: 858 | Z12: 858 | AA12: 858 | AB12: 858 | AC12: 858 | AD12: 858 | AE12: 858 | AF12: 858 | AG12: 858 | AH12: 858 | AI12: 858 | AJ12: 858 | AK12: 858 | AL12: 858 | AM12: 858 | AN12: 858 | AO12: 858 | AP12: 858 | AQ12: 858 | AR12: 858 | AS12: 858 | AT12: 858 | AU12: 858 | AV12: 858 | AW12: 858 | AX12: 858 | AY12: 858 | AZ12: 858 | BA12: 858 | BB12: 858 | BC12: 858 | BD12: 858 | BE12: 858 | BF12: 858 | BG12: 858 | BH12: 858 | BI12: 858 | BJ12: 858 | BK12: 858 | BL12: 858 | BM12: 858 | BN12: 858 | BO12: 858 | BP12: 858 | BQ12: 858 | BR12: 858 | BS12: 858 | BT12: 858 | BU12: 858 | BV12: 858 | BW12: 858 | BX12: 858 | BY12: 858 | BZ12: 858 | CA12: 858 | CB12: 858 | CC12: 858 | CD12: 858 | CE12: 858 | CF12: 858 | CG12: 858 | CH12: 858 | CI12: 858 | CJ12: 858 | CK12: 858 | CL12: 858 | CM12: 858 | CN12: 858 | CO12: 858 | CP12: 858 | CQ12: 858 | CR12: 858 | CS12: 858 | CT12: 858 | CU12: 858 | CV12: 858 | CW12: 858 | CX12: 858
A13: Cross border migration inflows [note 3] | B13: [z] | C13: [z] | D13: [z] | E13: [z] | F13: [z] | G13: [z] | H13: [z] | I13: [z] | J13: [z] | K13: [z] | L13: [z] | M13: [z] | N13: [z] | O13: [z] | P13: [z] | Q13: [z] | R13: [z] | S13: [z] | T13: [z] | U13: [z] | V13: [z] | W13: [z] | X13: [z] | Y13: [z] | Z13: [z] | AA13: [z] | AB13: [z] | AC13: [z] | AD13: [z] | AE13: [z] | AF13: [z] | AG13: [z] | AH13: [z] | AI13: [z] | AJ13: [z] | AK13: [z] | AL13: [z] | AM13: [z] | AN13: [z] | AO13: [z] | AP13: [z] | AQ13: [z] | AR13: [z] | AS13: [z] | AT13: [z] | AU13: [z] | AV13: [z] | AW13: [z] | AX13: [z] | AY13: [z] | AZ13: [z] | BA13: [z] | BB13: [z] | BC13: [z] | BD13: [z] | BE13: [z] | BF13: [z] | BG13: [z] | BH13: [z] | BI13: [z] | BJ13: [z] | BK13: [z] | BL13: [z] | BM13: [z] | BN13: [z] | BO13: [z] | BP13: [z] | BQ13: [z] | BR13: [z] | BS13: [z] | BT13: [z] | BU13: [z] | BV13: [z] | BW13: [z] | BX13: [z] | BY13: [z] | BZ13: [z] | CA13: [z] | CB13: [z] | CC13: [z] | CD13: [z] | CE13: [z] | CF13: [z] | CG13: [z] | CH13: [z] | CI13: [z] | CJ13: [z] | CK13: [z] | CL13: [z] | CM13: [z] | CN13: [z] | CO13: [z] | CP13: [z] | CQ13: [z] | CR13: [z] | CS13: [z] | CT13: [z] | CU13: [z] | CV13: [z] | CW13: [z] | CX13: [z]
A14: International migration outflows | B14: [z] | C14: 413.5 | D14: 479 | E14: 488.8 | F14: 498.6 | G14: 508.4 | H14: 518 | I14: 518 | J14: 518 | K14: 518 | L14: 518 | M14: 518 | N14: 518 | O14: 518 | P14: 518 | Q14: 518 | R14: 518 | S14: 518 | T14: 518 | U14: 518 | V14: 518 | W14: 518 | X14: 518 | Y14: 518 | Z14: 518 | AA14: 518 | AB14: 518 | AC14: 518 | AD14: 518 | AE14: 518 | AF14: 518 | AG14: 518 | AH14: 518 | AI14: 518 | AJ14: 518 | AK14: 518 | AL14: 518 | AM14: 518 | AN14: 518 | AO14: 518 | AP14: 518 | AQ14: 518 | AR14: 518 | AS14: 518 | AT14: 518 | AU14: 518 | AV14: 518 | AW14: 518 | AX14: 518 | AY14: 518 | AZ14: 518 | BA14: 518 | BB14: 518 | BC14: 518 | BD14: 518 | BE14: 518 | BF14: 518 | BG14: 518 | BH14: 518 | BI14: 518 | BJ14: 518 | BK14: 518 | BL14: 518 | BM14: 518 | BN14: 518 | BO14: 518 | BP14: 518 | BQ14: 518 | BR14: 518 | BS14: 518 | BT14: 518 | BU14: 518 | BV14: 518 | BW14: 518 | BX14: 518 | BY14: 518 | BZ14: 518 | CA14: 518 | CB14: 518 | CC14: 518 | CD14: 518 | CE14: 518 | CF14: 518 | CG14: 518 | CH14: 518 | CI14: 518 | CJ14: 518 | CK14: 518 | CL14: 518 | CM14: 518 | CN14: 518 | CO14: 518 | CP14: 518 | CQ14: 518 | CR14: 518 | CS14: 518 | CT14: 518 | CU14: 518 | CV14: 518 | CW14: 518 | CX14: 518
A15: Cross border migration outflows [note 3] | B15: [z] | C15: [z] | D15: [z] | E15: [z] | F15: [z] | G15: [z] | H15: [z] | I15: [z] | J15: [z] | K15: [z] | L15: [z] | M15: [z] | N15: [z] | O15: [z] | P15: [z] | Q15: [z] | R15: [z] | S15: [z] | T15: [z] | U15: [z] | V15: [z] | W15: [z] | X15: [z] | Y15: [z] | Z15: [z] | AA15: [z] | AB15: [z] | AC15: [z] | AD15: [z] | AE15: [z] | AF15: [z] | AG15: [z] | AH15: [z] | AI15: [z] | AJ15: [z] | AK15: [z] | AL15: [z] | AM15: [z] | AN15: [z] | AO15: [z] | AP15: [z] | AQ15: [z] | AR15: [z] | AS15: [z] | AT15: [z] | AU15: [z] | AV15: [z] | AW15: [z] | AX15: [z] | AY15: [z] | AZ15: [z] | BA15: [z] | BB15: [z] | BC15: [z] | BD15: [z] | BE15: [z] | BF15: [z] | BG15: [z] | BH15: [z] | BI15: [z] | BJ15: [z] | BK15: [z] | BL15: [z] | BM15: [z] | BN15: [z] | BO15: [z] | BP15: [z] | BQ15: [z] | BR15: [z] | BS15: [z] | BT15: [z] | BU15: [z] | BV15: [z] | BW15: [z] | BX15: [z] | BY15: [z] | BZ15: [z] | CA15: [z] | CB15: [z] | CC15: [z] | CD15: [z] | CE15: [z] | CF15: [z] | CG15: [z] | CH15: [z] | CI15: [z] | CJ15: [z] | CK15: [z] | CL15: [z] | CM15: [z] | CN15: [z] | CO15: [z] | CP15: [z] | CQ15: [z] | CR15: [z] | CS15: [z] | CT15: [z] | CU15: [z] | CV15: [z] | CW15: [z] | CX15: [z]
A16: Net international migration | B16: [z] | C16: 906 | D16: 728 | E16: 630.9 | F16: 533.8 | G16: 436.7 | H16: 340 | I16: 340 | J16: 340 | K16: 340 | L16: 340 | M16: 340 | N16: 340 | O16: 340 | P16: 340 | Q16: 340 | R16: 340 | S16: 340 | T16: 340 | U16: 340 | V16: 340 | W16: 340 | X16: 340 | Y16: 340 | Z16: 340 | AA16: 340 | AB16: 340 | AC16: 340 | AD16: 340 | AE16: 340 | AF16: 340 | AG16: 340 | AH16: 340 | AI16: 340 | AJ16: 340 | AK16: 340 | AL16: 340 | AM16: 340 | AN16: 340 | AO16: 340 | AP16: 340 | AQ16: 340 | AR16: 340 | AS16: 340 | AT16: 340 | AU16: 340 | AV16: 340 | AW16: 340 | AX16: 340 | AY16: 340 | AZ16: 340 | BA16: 340 | BB16: 340 | BC16: 340 | BD16: 340 | BE16: 340 | BF16: 340 | BG16: 340 | BH16: 340 | BI16: 340 | BJ16: 340 | BK16: 340 | BL16: 340 | BM16: 340 | BN16: 340 | BO16: 340 | BP16: 340 | BQ16: 340 | BR16: 340 | BS16: 340 | BT16: 340 | BU16: 340 | BV16: 340 | BW16: 340 | BX16: 340 | BY16: 340 | BZ16: 340 | CA16: 340 | CB16: 340 | CC16: 340 | CD16: 340 | CE16: 340 | CF16: 340 | CG16: 340 | CH16: 340 | CI16: 340 | CJ16: 340 | CK16: 340 | CL16: 340 | CM16: 340 | CN16: 340 | CO16: 340 | CP16: 340 | CQ16: 340 | CR16: 340 | CS16: 340 | CT16: 340 | CU16: 340 | CV16: 340 | CW16: 340 | CX16: 340
A17: Net cross border migration [note 3] | B17: [z] | C17: [z] | D17: [z] | E17: [z] | F17: [z] | G17: [z] | H17: [z] | I17: [z] | J17: [z] | K17: [z] | L17: [z] | M17: [z] | N17: [z] | O17: [z] | P17: [z] | Q17: [z] | R17: [z] | S17: [z] | T17: [z] | U17: [z] | V17: [z] | W17: [z] | X17: [z] | Y17: [z] | Z17: [z] | AA17: [z] | AB17: [z] | AC17: [z] | AD17: [z] | AE17: [z] | AF17: [z] | AG17: [z] | AH17: [z] | AI17: [z] | AJ17: [z] | AK17: [z] | AL17: [z] | AM17: [z] | AN17: [z] | AO17: [z] | AP17: [z] | AQ17: [z] | AR17: [z] | AS17: [z] | AT17: [z] | AU17: [z] | AV17: [z] | AW17: [z] | AX17: [z] | AY17: [z] | AZ17: [z] | BA17: [z] | BB17: [z] | BC17: [z] | BD17: [z] | BE17: [z] | BF17: [z] | BG17: [z] | BH17: [z] | BI17: [z] | BJ17: [z] | BK17: [z] | BL17: [z] | BM17: [z] | BN17: [z] | BO17: [z] | BP17: [z] | BQ17: [z] | BR17: [z] | BS17: [z] | BT17: [z] | BU17: [z] | BV17: [z] | BW17: [z] | BX17: [z] | BY17: [z] | BZ17: [z] | CA17: [z] | CB17: [z] | CC17: [z] | CD17: [z] | CE17: [z] | CF17: [z] | CG17: [z] | CH17: [z] | CI17: [z] | CJ17: [z] | CK17: [z] | CL17: [z] | CM17: [z] | CN17: [z] | CO17: [z] | CP17: [z] | CQ17: [z] | CR17: [z] | CS17: [z] | CT17: [z] | CU17: [z] | CV17: [z] | CW17: [z] | CX17: [z]
A18: Net migration | B18: [z] | C18: 906 | D18: 728 | E18: 630.9 | F18: 533.8 | G18: 436.7 | H18: 340 | I18: 340 | J18: 340 | K18: 340 | L18: 340 | M18: 340 | N18: 340 | O18: 340 | P18: 340 | Q18: 340 | R18: 340 | S18: 340 | T18: 340 | U18: 340 | V18: 340 | W18: 340 | X18: 340 | Y18: 340 | Z18: 340 | AA18: 340 | AB18: 340 | AC18: 340 | AD18: 340 | AE18: 340 | AF18: 340 | AG18: 340 | AH18: 340 | AI18: 340 | AJ18: 340 | AK18: 340 | AL18: 340 | AM18: 340 | AN18: 340 | AO18: 340 | AP18: 340 | AQ18: 340 | AR18: 340 | AS18: 340 | AT18: 340 | AU18: 340 | AV18: 340 | AW18: 340 | AX18: 340 | AY18: 340 | AZ18: 340 | BA18: 340 | BB18: 340 | BC18: 340 | BD18: 340 | BE18: 340 | BF18: 340 | BG18: 340 | BH18: 340 | BI18: 340 | BJ18: 340 | BK18: 340 | BL18: 340 | BM18: 340 | BN18: 340 | BO18: 340 | BP18: 340 | BQ18: 340 | BR18: 340 | BS18: 340 | BT18: 340 | BU18: 340 | BV18: 340 | BW18: 340 | BX18: 340 | BY18: 340 | BZ18: 340 | CA18: 340 | CB18: 340 | CC18: 340 | CD18: 340 | CE18: 340 | CF18: 340 | CG18: 340 | CH18: 340 | CI18: 340 | CJ18: 340 | CK18: 340 | CL18: 340 | CM18: 340 | CN18: 340 | CO18: 340 | CP18: 340 | CQ18: 340 | CR18: 340 | CS18: 340 | CT18: 340 | CU18: 340 | CV18: 340 | CW18: 340 | CX18: 340
A19: Total change | B19: [z] | C19: 889.737 | D19: 733.744 | E19: 641.749 | F19: 546.319 | G19: 447.592 | H19: 346.185 | I19: 339.566 | J19: 332.33 | K19: 324.591 | L19: 316.613 | M19: 308.861 | N19: 301.586 | O19: 294.561 | P19: 287.933 | Q19: 281.868 | R19: 276.397 | S19: 271.396 | T19: 266.752 | U19: 262.421 | V19: 258.32 | W19: 254.042 | X19: 249.265 | Y19: 244.18 | Z19: 238.815 | AA19: 233.052 | AB19: 225.921 | AC19: 217.173 | AD19: 207.85 | AE19: 198.153 | AF19: 188.416 | AG19: 178.663 | AH19: 169.13 | AI19: 160.309 | AJ19: 152.619 | AK19: 146.139 | AL19: 140.709 | AM19: 136.436 | AN19: 133.283 | AO19: 131.189 | AP19: 130.005 | AQ19: 129.386 | AR19: 129.145 | AS19: 129.281 | AT19: 129.591 | AU19: 129.763 | AV19: 129.601 | AW19: 128.892 | AX19: 127.454 | AY19: 125.164 | AZ19: 121.928 | BA19: 117.715 | BB19: 112.627 | BC19: 106.714 | BD19: 100.156 | BE19: 93.074 | BF19: 85.694 | BG19: 78.168 | BH19: 70.539 | BI19: 62.994 | BJ19: 55.607 | BK19: 48.494 | BL19: 41.713 | BM19: 35.349 | BN19: 29.445 | BO19: 24.075 | BP19: 19.23 | BQ19: 14.934 | BR19: 11.146 | BS19: 7.821 | BT19: 5.016 | BU19: 2.618 | BV19: 0.618 | BW19: -1.092 | BX19: -2.499 | BY19: -3.64 | BZ19: -4.596 | CA19: -5.372 | CB19: -6.008 | CC19: -6.484 | CD19: -6.829 | CE19: -6.997 | CF19: -6.957 | CG19: -6.64 | CH19: -5.975 | CI19: -4.949 | CJ19: -3.544 | CK19: -1.742 | CL19: 0.466 | CM19: 3.019 | CN19: 5.832 | CO19: 8.814 | CP19: 11.914 | CQ19: 15.042 | CR19: 18.057 | CS19: 20.9 | CT19: 23.472 | CU19: 25.688 | CV19: 27.506 | CW19: 28.911 | CX19: 29.838
A20: Population at end | B20: [z] | C20: 68492.495 | D20: 69226.231 | E20: 69867.979 | F20: 70414.3 | G20: 70861.913 | H20: 71208.101 | I20: 71547.662 | J20: 71879.988 | K20: 72204.574 | L20: 72521.173 | M20: 72830.021 | N20: 73131.597 | O20: 73426.168 | P20: 73714.089 | Q20: 73995.941 | R20: 74272.334 | S20: 74543.738 | T20: 74810.478 | U20: 75072.892 | V20: 75331.209 | W20: 75585.236 | X20: 75834.507 | Y20: 76078.686 | Z20: 76317.48 | AA20: 76550.535 | AB20: 76776.46 | AC20: 76993.637 | AD20: 77201.483 | AE20: 77399.645 | AF20: 77588.049 | AG20: 77766.71 | AH20: 77935.834 | AI20: 78096.133 | AJ20: 78248.758 | AK20: 78394.896 | AL20: 78535.61 | AM20: 78672.036 | AN20: 78805.317 | AO20: 78936.487 | AP20: 79066.48 | AQ20: 79195.863 | AR20: 79325.004 | AS20: 79454.27 | AT20: 79583.857 | AU20: 79713.62 | AV20: 79843.214 | AW20: 79972.1 | AX20: 80099.544 | AY20: 80224.705 | AZ20: 80346.626 | BA20: 80464.328 | BB20: 80576.958 | BC20: 80683.666 | BD20: 80783.805 | BE20: 80876.875 | BF20: 80962.574 | BG20: 81040.744 | BH20: 81111.28 | BI20: 81174.269 | BJ20: 81229.882 | BK20: 81278.373 | BL20: 81320.103 | BM20: 81355.442 | BN20: 81384.875 | BO20: 81408.957 | BP20: 81428.186 | BQ20: 81443.111 | BR20: 81454.243 | BS20: 81462.068 | BT20: 81467.091 | BU20: 81469.704 | BV20: 81470.32 | BW20: 81469.232 | BX20: 81466.731 | BY20: 81463.093 | BZ20: 81458.489 | CA20: 81453.12 | CB20: 81447.095 | CC20: 81440.608 | CD20: 81433.781 | CE20: 81426.783 | CF20: 81419.829 | CG20: 81413.183 | CH20: 81407.2 | CI20: 81402.25 | CJ20: 81398.709 | CK20: 81396.967 | CL20: 81397.436 | CM20: 81400.459 | CN20: 81406.276 | CO20: 81415.084 | CP20: 81426.996 | CQ20: 81442.03 | CR20: 81460.095 | CS20: 81480.985 | CT20: 81504.456 | CU20: 81530.145 | CV20: 81557.639 | CW20: 81586.535 | CX20: 81616.369
A21: Annual growth value | B21: [z] | C21: 0.013161208 | D21: 0.010712648 | E21: 0.009270301 | F21: 0.0078193331 | G21: 0.006356848 | H21: 0.0048853889 | I21: 0.0047685726 | J21: 0.0046448198 | K21: 0.0045156658 | L21: 0.0043847499 | M21: 0.0042587287 | N21: 0.0041408199 | O21: 0.004027958 | P21: 0.0039212315 | Q21: 0.0038235838 | R21: 0.0037352454 | S21: 0.0036541736 | T21: 0.0035783019 | U21: 0.0035077172 | V21: 0.0034408825 | W21: 0.0033721349 | X21: 0.0032978795 | Y21: 0.003219893 | Z21: 0.0031387766 | AA21: 0.0030537565 | AB21: 0.0029513184 | AC21: 0.0028286925 | AD21: 0.0026995218 | AE21: 0.002566816 | AF21: 0.0024341714 | AG21: 0.0023026871 | AH21: 0.0021747609 | AI21: 0.0020568074 | AJ21: 0.0019543221 | AK21: 0.0018676079 | AL21: 0.0017949383 | AM21: 0.0017371228 | AN21: 0.0016941344 | AO21: 0.0016644816 | AP21: 0.001646805 | AQ21: 0.0016363824 | AR21: 0.0016306534 | AS21: 0.0016295745 | AT21: 0.0016309633 | AU21: 0.0016305191 | AV21: 0.0016257448 | AW21: 0.0016142386 | AX21: 0.0015936058 | AY21: 0.0015625682 | AZ21: 0.0015197438 | BA21: 0.0014649277 | BB21: 0.0013997507 | BC21: 0.0013242992 | BD21: 0.001241131 | BE21: 0.0011520874 | BF21: 0.001059623 | BG21: 0.00096550784 | BH21: 0.000870377 | BI21: 0.0007765751 | BJ21: 0.00068510626 | BK21: 0.00059696012 | BL21: 0.00051342071 | BM21: 0.00043456659 | BN21: 0.0003617828 | BO21: 0.00029590265 | BP21: 0.00023620251 | BQ21: 0.00018329034 | BR21: 0.00013668437 | BS21: 9.6066205e-05 | BT21: 6.16606e-05 | BU21: 3.2074301e-05 | BV21: 7.5610929e-06 | BW21: -1.3354557e-05 | BX21: -3.0698706e-05 | BY21: -4.4656266e-05 | BZ21: -5.6516391e-05 | CA21: -6.5910871e-05 | CB21: -7.3968928e-05 | CC21: -7.9646794e-05 | CD21: -8.382796e-05 | CE21: -8.5934853e-05 | CF21: -8.5401876e-05 | CG21: -8.1626308e-05 | CH21: -7.3489327e-05 | CI21: -6.0805432e-05 | CJ21: -4.3500026e-05 | CK21: -2.1400831e-05 | CL21: 5.7618855e-06 | CM21: 3.7138762e-05 | CN21: 7.1461514e-05 | CO21: 0.00010819805 | CP21: 0.00014631195 | CQ21: 0.00018463164 | CR21: 0.00022181422 | CS21: 0.00025644458 | CT21: 0.00028805494 | CU21: 0.00031518522 | CV21: 0.00033722496 | CW21: 0.00035430158 | CX21: 0.00036567309
A22: Total Fertility Rate (TFR) | B22: [z] | C22: 1.4474239 | D22: 1.4281624 | E22: 1.4233952 | F22: 1.4188951 | G22: 1.4146367 | H22: 1.4121362 | I22: 1.4113406 | J22: 1.4107551 | K22: 1.4103276 | L22: 1.4100494 | M22: 1.410637 | N22: 1.4121015 | O22: 1.4137446 | P22: 1.4156267 | Q22: 1.4177247 | R22: 1.4201874 | S22: 1.4230398 | T22: 1.4260455 | U22: 1.4291702 | V22: 1.4324689 | W22: 1.4352698 | X22: 1.4375888 | Y22: 1.4400939 | Z22: 1.4427302 | AA22: 1.4455258 | AB22: 1.4469498 | AC22: 1.4469342 | AD22: 1.4469355 | AE22: 1.4469162 | AF22: 1.4469107 | AG22: 1.4468911 | AH22: 1.4468819 | AI22: 1.4468735 | AJ22: 1.4468477 | AK22: 1.4468376 | AL22: 1.446812 | AM22: 1.4468243 | AN22: 1.4467953 | AO22: 1.4468078 | AP22: 1.4467985 | AQ22: 1.4467719 | AR22: 1.4467643 | AS22: 1.4467584 | AT22: 1.4467508 | AU22: 1.4467623 | AV22: 1.4467586 | AW22: 1.4467808 | AX22: 1.4467839 | AY22: 1.4467966 | AZ22: 1.4468148 | BA22: 1.4468342 | BB22: 1.4468496 | BC22: 1.446857 | BD22: 1.4468954 | BE22: 1.4468903 | BF22: 1.4468991 | BG22: 1.4469236 | BH22: 1.4469293 | BI22: 1.446949 | BJ22: 1.4469323 | BK22: 1.4469397 | BL22: 1.4469295 | BM22: 1.4469186 | BN22: 1.446934 | BO22: 1.4469096 | BP22: 1.4469295 | BQ22: 1.4469198 | BR22: 1.4469164 | BS22: 1.4468913 | BT22: 1.4468856 | BU22: 1.4468903 | BV22: 1.446885 | BW22: 1.446883 | BX22: 1.4468827 | BY22: 1.4468775 | BZ22: 1.4468826 | CA22: 1.44687 | CB22: 1.4468861 | CC22: 1.4468854 | CD22: 1.4468733 | CE22: 1.4468765 | CF22: 1.4468911 | CG22: 1.4468861 | CH22: 1.4469034 | CI22: 1.4469091 | CJ22: 1.4469046 | CK22: 1.4469094 | CL22: 1.4469226 | CM22: 1.4469192 | CN22: 1.446932 | CO22: 1.4469349 | CP22: 1.4469405 | CQ22: 1.4469417 | CR22: 1.4469329 | CS22: 1.4469416 | CT22: 1.4469511 | CU22: 1.4469458 | CV22: 1.4469461 | CW22: 1.4469364 | CX22: 1.446942
