Workbook
Name Data: [1]sheet0!$C$2

Sheet Chart Data
A1: GDP growth | F1: CPI inflation | K1: Bank Rate
B2: Baseline | C2: $100 for two months | D2: Worst-case scenario | G2: Baseline | H2: $100 for two months | I2: Worst-case scenario | L2: Baseline | M2: $100 for two months | N2: Worst-case scenario
A3: 2025 | B3: =100*(('GEM data - Baseline'!$F187/'GEM data - Baseline'!$F183)-1) -> 1.7614345 | C3: =100*(('GEM data - $100 oil'!$F187/'GEM data - $100 oil'!$F183)-1) -> 1.7614345 | D3: =100*(('GEM data - Worst case'!$F187/'GEM data - Worst case'!$F183)-1) -> 1.7614345 | F3: 2025 | G3: =100*(('GEM data - Baseline'!$H187/'GEM data - Baseline'!$H183)-1) -> 2.7973783 | H3: =100*(('GEM data - $100 oil'!$H187/'GEM data - $100 oil'!$H183)-1) -> 2.7973783 | I3: =100*(('GEM data - Worst case'!$H187/'GEM data - Worst case'!$H183)-1) -> 2.7973783 | K3: 2025 | L3: ='GEM data - Baseline'!$I187 -> 4.601563 | M3: ='GEM data - $100 oil'!$I187 -> 4.601563 | N3: ='GEM data - Worst case'!$I187 -> 4.601563
B4: =100*(('GEM data - Baseline'!$F188/'GEM data - Baseline'!$F184)-1) -> 1.3689449 | C4: =100*(('GEM data - $100 oil'!$F188/'GEM data - $100 oil'!$F184)-1) -> 1.3689449 | D4: =100*(('GEM data - Worst case'!$F188/'GEM data - Worst case'!$F184)-1) -> 1.3689449 | G4: =100*(('GEM data - Baseline'!$H188/'GEM data - Baseline'!$H184)-1) -> 3.4869498 | H4: =100*(('GEM data - $100 oil'!$H188/'GEM data - $100 oil'!$H184)-1) -> 3.4869498 | I4: =100*(('GEM data - Worst case'!$H188/'GEM data - Worst case'!$H184)-1) -> 3.4869498 | L4: ='GEM data - Baseline'!$I188 -> 4.353846 | M4: ='GEM data - $100 oil'!$I188 -> 4.353846 | N4: ='GEM data - Worst case'!$I188 -> 4.353846
B5: =100*(('GEM data - Baseline'!$F189/'GEM data - Baseline'!$F185)-1) -> 1.1959481 | C5: =100*(('GEM data - $100 oil'!$F189/'GEM data - $100 oil'!$F185)-1) -> 1.1959481 | D5: =100*(('GEM data - Worst case'!$F189/'GEM data - Worst case'!$F185)-1) -> 1.1959481 | G5: =100*(('GEM data - Baseline'!$H189/'GEM data - Baseline'!$H185)-1) -> 3.803132 | H5: =100*(('GEM data - $100 oil'!$H189/'GEM data - $100 oil'!$H185)-1) -> 3.803132 | I5: =100*(('GEM data - Worst case'!$H189/'GEM data - Worst case'!$H185)-1) -> 3.803132 | L5: ='GEM data - Baseline'!$I189 -> 4.102273 | M5: ='GEM data - $100 oil'!$I189 -> 4.102273 | N5: ='GEM data - Worst case'!$I189 -> 4.102273
B6: =100*(('GEM data - Baseline'!$F190/'GEM data - Baseline'!$F186)-1) -> 0.97183663 | C6: =100*(('GEM data - $100 oil'!$F190/'GEM data - $100 oil'!$F186)-1) -> 0.97183663 | D6: =100*(('GEM data - Worst case'!$F190/'GEM data - Worst case'!$F186)-1) -> 0.97183663 | G6: =100*(('GEM data - Baseline'!$H190/'GEM data - Baseline'!$H186)-1) -> 3.3769049 | H6: =100*(('GEM data - $100 oil'!$H190/'GEM data - $100 oil'!$H186)-1) -> 3.3769049 | I6: =100*(('GEM data - Worst case'!$H190/'GEM data - Worst case'!$H186)-1) -> 3.3769049 | L6: ='GEM data - Baseline'!$I190 -> 3.962121 | M6: ='GEM data - $100 oil'!$I190 -> 3.962121 | N6: ='GEM data - Worst case'!$I190 -> 3.962121
A7: 2026 | B7: =100*(('GEM data - Baseline'!$F191/'GEM data - Baseline'!$F187)-1) -> 0.6893924 | C7: =100*(('GEM data - $100 oil'!$F191/'GEM data - $100 oil'!$F187)-1) -> 0.6504799 | D7: =100*(('GEM data - Worst case'!$F191/'GEM data - Worst case'!$F187)-1) -> 0.63007821 | F7: 2026 | G7: =100*(('GEM data - Baseline'!$H191/'GEM data - Baseline'!$H187)-1) -> 2.8921052 | H7: =100*(('GEM data - $100 oil'!$H191/'GEM data - $100 oil'!$H187)-1) -> 2.9968367 | I7: =100*(('GEM data - Worst case'!$H191/'GEM data - Worst case'!$H187)-1) -> 3.0805337 | K7: 2026 | L7: ='GEM data - Baseline'!$I191 -> 3.75 | M7: ='GEM data - $100 oil'!$I191 -> 3.75905 | N7: ='GEM data - Worst case'!$I191 -> 3.75
B8: =100*(('GEM data - Baseline'!$F192/'GEM data - Baseline'!$F188)-1) -> 0.7173261 | C8: =100*(('GEM data - $100 oil'!$F192/'GEM data - $100 oil'!$F188)-1) -> 0.53941697 | D8: =100*(('GEM data - Worst case'!$F192/'GEM data - Worst case'!$F188)-1) -> 0.3207302 | G8: =100*(('GEM data - Baseline'!$H192/'GEM data - Baseline'!$H188)-1) -> 2.4896751 | H8: =100*(('GEM data - $100 oil'!$H192/'GEM data - $100 oil'!$H188)-1) -> 3.0145126 | I8: =100*(('GEM data - Worst case'!$H192/'GEM data - Worst case'!$H188)-1) -> 3.7470758 | L8: ='GEM data - Baseline'!$I192 -> 3.580767 | M8: ='GEM data - $100 oil'!$I192 -> 3.627709 | N8: ='GEM data - Worst case'!$I192 -> 3.75
B9: =100*(('GEM data - Baseline'!$F193/'GEM data - Baseline'!$F189)-1) -> 0.86762802 | C9: =100*(('GEM data - $100 oil'!$F193/'GEM data - $100 oil'!$F189)-1) -> 0.53506375 | D9: =100*(('GEM data - Worst case'!$F193/'GEM data - Worst case'!$F189)-1) -> 0.12514411 | G9: =100*(('GEM data - Baseline'!$H193/'GEM data - Baseline'!$H189)-1) -> 2.85 | H9: =100*(('GEM data - $100 oil'!$H193/'GEM data - $100 oil'!$H189)-1) -> 3.809842 | I9: =100*(('GEM data - Worst case'!$H193/'GEM data - Worst case'!$H189)-1) -> 4.8531609 | L9: ='GEM data - Baseline'!$I193 -> 3.499992 | M9: ='GEM data - $100 oil'!$I193 -> 3.613537 | N9: ='GEM data - Worst case'!$I193 -> 3.75
B10: =100*(('GEM data - Baseline'!$F194/'GEM data - Baseline'!$F190)-1) -> 1.0903226 | C10: =100*(('GEM data - $100 oil'!$F194/'GEM data - $100 oil'!$F190)-1) -> 0.72619198 | D10: =100*(('GEM data - Worst case'!$F194/'GEM data - Worst case'!$F190)-1) -> -0.013662693 | G10: =100*(('GEM data - Baseline'!$H194/'GEM data - Baseline'!$H190)-1) -> 2.6402718 | H10: =100*(('GEM data - $100 oil'!$H194/'GEM data - $100 oil'!$H190)-1) -> 3.3717454 | I10: =100*(('GEM data - Worst case'!$H194/'GEM data - Worst case'!$H190)-1) -> 5.4763948 | L10: ='GEM data - Baseline'!$I194 -> 3.344676 | M10: ='GEM data - $100 oil'!$I194 -> 3.550428 | N10: ='GEM data - Worst case'!$I194 -> 3.9
A11: 2027 | B11: =100*(('GEM data - Baseline'!$F195/'GEM data - Baseline'!$F191)-1) -> 1.0644544 | C11: =100*(('GEM data - $100 oil'!$F195/'GEM data - $100 oil'!$F191)-1) -> 0.80959302 | D11: =100*(('GEM data - Worst case'!$F195/'GEM data - Worst case'!$F191)-1) -> -0.083257418 | F11: 2027 | G11: =100*(('GEM data - Baseline'!$H195/'GEM data - Baseline'!$H191)-1) -> 2.5834352 | H11: =100*(('GEM data - $100 oil'!$H195/'GEM data - $100 oil'!$H191)-1) -> 2.8448016 | I11: =100*(('GEM data - Worst case'!$H195/'GEM data - Worst case'!$H191)-1) -> 4.6434239 | K11: 2027 | L11: ='GEM data - Baseline'!$I195 -> 3.249961 | M11: ='GEM data - $100 oil'!$I195 -> 3.547556 | N11: ='GEM data - Worst case'!$I195 -> 4
B12: =100*(('GEM data - Baseline'!$F196/'GEM data - Baseline'!$F192)-1) -> 1.1827226 | C12: =100*(('GEM data - $100 oil'!$F196/'GEM data - $100 oil'!$F192)-1) -> 1.1491395 | D12: =100*(('GEM data - Worst case'!$F196/'GEM data - Worst case'!$F192)-1) -> 0.39548354 | G12: =100*(('GEM data - Baseline'!$H196/'GEM data - Baseline'!$H192)-1) -> 2.1828385 | H12: =100*(('GEM data - $100 oil'!$H196/'GEM data - $100 oil'!$H192)-1) -> 1.9355164 | I12: =100*(('GEM data - Worst case'!$H196/'GEM data - Worst case'!$H192)-1) -> 3.0215805 | L12: ='GEM data - Baseline'!$I196 -> 3.076869 | M12: ='GEM data - $100 oil'!$I196 -> 3.413372 | N12: ='GEM data - Worst case'!$I196 -> 4
B13: =100*(('GEM data - Baseline'!$F197/'GEM data - Baseline'!$F193)-1) -> 1.3700444 | C13: =100*(('GEM data - $100 oil'!$F197/'GEM data - $100 oil'!$F193)-1) -> 1.5367717 | D13: =100*(('GEM data - Worst case'!$F197/'GEM data - Worst case'!$F193)-1) -> 0.94560096 | G13: =100*(('GEM data - Baseline'!$H197/'GEM data - Baseline'!$H193)-1) -> 1.811658 | H13: =100*(('GEM data - $100 oil'!$H197/'GEM data - $100 oil'!$H193)-1) -> 0.98945837 | I13: =100*(('GEM data - Worst case'!$H197/'GEM data - Worst case'!$H193)-1) -> 1.5790418 | L13: ='GEM data - Baseline'!$I197 -> 2.99994 | M13: ='GEM data - $100 oil'!$I197 -> 3.316199 | N13: ='GEM data - Worst case'!$I197 -> 3.96
B14: =100*(('GEM data - Baseline'!$F198/'GEM data - Baseline'!$F194)-1) -> 1.475835 | C14: =100*(('GEM data - $100 oil'!$F198/'GEM data - $100 oil'!$F194)-1) -> 1.6861528 | D14: =100*(('GEM data - Worst case'!$F198/'GEM data - Worst case'!$F194)-1) -> 1.4986082 | G14: =100*(('GEM data - Baseline'!$H198/'GEM data - Baseline'!$H194)-1) -> 2.0344119 | H14: =100*(('GEM data - $100 oil'!$H198/'GEM data - $100 oil'!$H194)-1) -> 1.3515674 | I14: =100*(('GEM data - Worst case'!$H198/'GEM data - Worst case'!$H194)-1) -> 0.73377821 | L14: ='GEM data - Baseline'!$I198 -> 2.999938 | M14: ='GEM data - $100 oil'!$I198 -> 3.248416 | N14: ='GEM data - Worst case'!$I198 -> 3.71
A15: 2028 | B15: =100*(('GEM data - Baseline'!$F199/'GEM data - Baseline'!$F195)-1) -> 1.4959609 | C15: =100*(('GEM data - $100 oil'!$F199/'GEM data - $100 oil'!$F195)-1) -> 1.6661253 | D15: =100*(('GEM data - Worst case'!$F199/'GEM data - Worst case'!$F195)-1) -> 1.6955228 | F15: 2028 | G15: =100*(('GEM data - Baseline'!$H199/'GEM data - Baseline'!$H195)-1) -> 2.1590348 | H15: =100*(('GEM data - $100 oil'!$H199/'GEM data - $100 oil'!$H195)-1) -> 1.8400934 | I15: =100*(('GEM data - Worst case'!$H199/'GEM data - Worst case'!$H195)-1) -> 1.3070763 | K15: 2028 | L15: ='GEM data - Baseline'!$I199 -> 2.999943 | M15: ='GEM data - $100 oil'!$I199 -> 3.160861 | N15: ='GEM data - Worst case'!$I199 -> 3.5
B16: =100*(('GEM data - Baseline'!$F200/'GEM data - Baseline'!$F196)-1) -> 1.5234682 | C16: =100*(('GEM data - $100 oil'!$F200/'GEM data - $100 oil'!$F196)-1) -> 1.6604706 | D16: =100*(('GEM data - Worst case'!$F200/'GEM data - Worst case'!$F196)-1) -> 1.8348823 | G16: =100*(('GEM data - Baseline'!$H200/'GEM data - Baseline'!$H196)-1) -> 1.9743296 | H16: =100*(('GEM data - $100 oil'!$H200/'GEM data - $100 oil'!$H196)-1) -> 1.7307198 | I16: =100*(('GEM data - Worst case'!$H200/'GEM data - Worst case'!$H196)-1) -> 1.1416497 | L16: ='GEM data - Baseline'!$I200 -> 2.838416 | M16: ='GEM data - $100 oil'!$I200 -> 2.92939 | N16: ='GEM data - Worst case'!$I200 -> 3.46
B17: =100*(('GEM data - Baseline'!$F201/'GEM data - Baseline'!$F197)-1) -> 1.5082714 | C17: =100*(('GEM data - $100 oil'!$F201/'GEM data - $100 oil'!$F197)-1) -> 1.6374958 | D17: =100*(('GEM data - Worst case'!$F201/'GEM data - Worst case'!$F197)-1) -> 1.9501475 | G17: =100*(('GEM data - Baseline'!$H201/'GEM data - Baseline'!$H197)-1) -> 1.9798862 | H17: =100*(('GEM data - $100 oil'!$H201/'GEM data - $100 oil'!$H197)-1) -> 1.8691441 | I17: =100*(('GEM data - Worst case'!$H201/'GEM data - Worst case'!$H197)-1) -> 1.3324538 | L17: ='GEM data - Baseline'!$I201 -> 2.749965 | M17: ='GEM data - $100 oil'!$I201 -> 2.794754 | N17: ='GEM data - Worst case'!$I201 -> 3.21
B18: =100*(('GEM data - Baseline'!$F202/'GEM data - Baseline'!$F198)-1) -> 1.4982372 | C18: =100*(('GEM data - $100 oil'!$F202/'GEM data - $100 oil'!$F198)-1) -> 1.6534192 | D18: =100*(('GEM data - Worst case'!$F202/'GEM data - Worst case'!$F198)-1) -> 2.0386514 | G18: =100*(('GEM data - Baseline'!$H202/'GEM data - Baseline'!$H198)-1) -> 1.9713777 | H18: =100*(('GEM data - $100 oil'!$H202/'GEM data - $100 oil'!$H198)-1) -> 1.9223456 | I18: =100*(('GEM data - Worst case'!$H202/'GEM data - Worst case'!$H198)-1) -> 1.4865556 | L18: ='GEM data - Baseline'!$I202 -> 2.749983 | M18: ='GEM data - $100 oil'!$I202 -> 2.765643 | N18: ='GEM data - Worst case'!$I202 -> 2.96
A20: 2025 | B20: =SUMIF('GEM data - Baseline'!$B:$B,'Chart Data'!$A20,'GEM data - Baseline'!$F:$F) -> 2818929 | C20: =SUMIF('GEM data - $100 oil'!$B:$B,'Chart Data'!$A20,'GEM data - $100 oil'!$F:$F) -> 2818929 | D20: =SUMIF('GEM data - Worst case'!$B:$B,'Chart Data'!$A20,'GEM data - Worst case'!$F:$F) -> 2818929
A21: 2026 | B21: =SUMIF('GEM data - Baseline'!$B:$B,'Chart Data'!$A21,'GEM data - Baseline'!$F:$F) -> 2842645.1 | C21: =SUMIF('GEM data - $100 oil'!$B:$B,'Chart Data'!$A21,'GEM data - $100 oil'!$F:$F) -> 2836203.1 | D21: =SUMIF('GEM data - Worst case'!$B:$B,'Chart Data'!$A21,'GEM data - Worst case'!$F:$F) -> 2826407.4
A22: 2027 | B22: =SUMIF('GEM data - Baseline'!$B:$B,'Chart Data'!$A22,'GEM data - Baseline'!$F:$F) -> 2878851.2 | C22: =SUMIF('GEM data - $100 oil'!$B:$B,'Chart Data'!$A22,'GEM data - $100 oil'!$F:$F) -> 2872955.9 | D22: =SUMIF('GEM data - Worst case'!$B:$B,'Chart Data'!$A22,'GEM data - Worst case'!$F:$F) -> 2845863.3
A23: 2028 | B23: =SUMIF('GEM data - Baseline'!$B:$B,'Chart Data'!$A23,'GEM data - Baseline'!$F:$F) -> 2922220.5 | C23: =SUMIF('GEM data - $100 oil'!$B:$B,'Chart Data'!$A23,'GEM data - $100 oil'!$F:$F) -> 2920484.5 | D23: =SUMIF('GEM data - Worst case'!$B:$B,'Chart Data'!$A23,'GEM data - Worst case'!$F:$F) -> 2899376.6
A25: 2026 | B25: =100*((B21/B20)-1) -> 0.84131597 | C25: =100*((C21/C20)-1) -> 0.61278947 | D25: =100*((D21/D20)-1) -> 0.26529224
A26: 2027 | B26: =100*((B22/B21)-1) -> 1.2736764 | C26: =100*((C22/C21)-1) -> 1.2958451 | D26: =100*((D22/D21)-1) -> 0.68836149
A27: 2028 | B27: =100*((B23/B22)-1) -> 1.5064794 | C27: =100*((C23/C22)-1) -> 1.6543449 | D27: =100*((D23/D22)-1) -> 1.880389

Sheet GEM data - Baseline
B1: lookups | C1: lookups | D1: lookups | F1: ='GMW - Baseline'!C2 -> Mar26_1 | G1: =$F$1 -> Mar26_1 | H1: =$F$1 -> Mar26_1 | I1: =$F$1 -> Mar26_1 | J1: =$F$1 -> Mar26_1 | K1: =$F$1 -> Mar26_1 | L1: =$F$1 -> Mar26_1 | M1: =$F$1 -> Mar26_1 | N1: =$F$1 -> Mar26_1 | ... T1: =$F$1 -> Mar26_1
F2: UK | G2: UK | H2: UK | I2: UK | J2: UK | K2: UK | L2: UK | M2: UK | N2: UK | O2: UK | P2: UK | Q2: UK | R2: UK | S2: UK | T2: UK
F3: GDP | G3: C | H3: CPI | I3: RCB
F4: GBR | G4: GBR | H4: GBR | I4: GBR | J4: GBR | K4: GBR | L4: GBR | M4: GBR | N4: GBR | O4: GBR | P4: GBR | Q4: GBR | R4: GBR | S4: GBR | T4: GBR
F5: L | G5: L | H5: L | I5: L | J5: L | K5: L | L5: L | M5: L | N5: L | O5: L | P5: L | Q5: L | R5: L | S5: L | T5: L
B6: CY total | C6: FY total | D6: FY end | E6: =E330+5 -> 2308 | F6: {=_xlfn.CONCAT(INDEX('GMW - Baseline'!$A$2:$MC$200,MATCH(1,('GMW - Baseline'!$MC$2:$MC$200=F$3)*('GMW - Baseline'!$MB$2:$MB$200=F$4),0),$E6-1973),"0",(INDEX('GMW - Baseline'!$A$2:$MC$200,MATCH(1,('GMW - Baseline'!$MC$2:$MC$200=F$3)*('GMW - Baseline'!$MB$2:$MB$200=F$4),0),$E6-1972)))} -> 202504 | G6: {=_xlfn.CONCAT(INDEX('GMW - Baseline'!$A$2:$MC$200,MATCH(1,('GMW - Baseline'!$MC$2:$MC$200=G$3)*('GMW - Baseline'!$MB$2:$MB$200=G$4),0),$E6-1973),"0",(INDEX('GMW - Baseline'!$A$2:$MC$200,MATCH(1,('GMW - Baseline'!$MC$2:$MC$200=G$3)*('GMW - Baseline'!$MB$2:$MB$200=G$4),0),$E6-1972)))} -> 202504 | H6: {=_xlfn.CONCAT(INDEX('GMW - Baseline'!$A$2:$MC$200,MATCH(1,('GMW - Baseline'!$MC$2:$MC$200=H$3)*('GMW - Baseline'!$MB$2:$MB$200=H$4),0),$E6-1973),"0",(INDEX('GMW - Baseline'!$A$2:$MC$200,MATCH(1,('GMW - Baseline'!$MC$2:$MC$200=H$3)*('GMW - Baseline'!$MB$2:$MB$200=H$4),0),$E6-1972)))} -> 202504 | I6: {=_xlfn.CONCAT(INDEX('GMW - Baseline'!$A$2:$MC$200,MATCH(1,('GMW - Baseline'!$MC$2:$MC$200=I$3)*('GMW - Baseline'!$MB$2:$MB$200=I$4),0),$E6-1973),"0",(INDEX('GMW - Baseline'!$A$2:$MC$200,MATCH(1,('GMW - Baseline'!$MC$2:$MC$200=I$3)*('GMW - Baseline'!$MB$2:$MB$200=I$4),0),$E6-1972)))} -> 202504 | J6: {=_xlfn.CONCAT(INDEX('GMW - Baseline'!$A$2:$MC$200,MATCH(1,('GMW - Baseline'!$MC$2:$MC$200=J$3)*('GMW - Baseline'!$MB$2:$MB$200=J$4),0),$E6-1973),"0",(INDEX('GMW - Baseline'!$A$2:$MC$200,MATCH(1,('GMW - Baseline'!$MC$2:$MC$200=J$3)*('GMW - Baseline'!$MB$2:$MB$200=J$4),0),$E6-1972)))} -> #N/A | K6: {=_xlfn.CONCAT(INDEX('GMW - Baseline'!$A$2:$MC$200,MATCH(1,('GMW - Baseline'!$MC$2:$MC$200=K$3)*('GMW - Baseline'!$MB$2:$MB$200=K$4),0),$E6-1973),"0",(INDEX('GMW - Baseline'!$A$2:$MC$200,MATCH(1,('GMW - Baseline'!$MC$2:$MC$200=K$3)*('GMW - Baseline'!$MB$2:$MB$200=K$4),0),$E6-1972)))} -> #N/A | L6: {=_xlfn.CONCAT(INDEX('GMW - Baseline'!$A$2:$MC$200,MATCH(1,('GMW - Baseline'!$MC$2:$MC$200=L$3)*('GMW - Baseline'!$MB$2:$MB$200=L$4),0),$E6-1973),"0",(INDEX('GMW - Baseline'!$A$2:$MC$200,MATCH(1,('GMW - Baseline'!$MC$2:$MC$200=L$3)*('GMW - Baseline'!$MB$2:$MB$200=L$4),0),$E6-1972)))} -> #N/A | M6: {=_xlfn.CONCAT(INDEX('GMW - Baseline'!$A$2:$MC$200,MATCH(1,('GMW - Baseline'!$MC$2:$MC$200=M$3)*('GMW - Baseline'!$MB$2:$MB$200=M$4),0),$E6-1973),"0",(INDEX('GMW - Baseline'!$A$2:$MC$200,MATCH(1,('GMW - Baseline'!$MC$2:$MC$200=M$3)*('GMW - Baseline'!$MB$2:$MB$200=M$4),0),$E6-1972)))} -> #N/A | ... T6: {=_xlfn.CONCAT(INDEX('GMW - Baseline'!$A$2:$MC$200,MATCH(1,('GMW - Baseline'!$MC$2:$MC$200=T$3)*('GMW - Baseline'!$MB$2:$MB$200=T$4),0),$E6-1973),"0",(INDEX('GMW - Baseline'!$A$2:$MC$200,MATCH(1,('GMW - Baseline'!$MC$2:$MC$200=T$3)*('GMW - Baseline'!$MB$2:$MB$200=T$4),0),$E6-1972)))} -> #N/A
A7: 1980 | B7: 1980 | E7: 1980 | F7: {=INDEX('GMW - Baseline'!$A$2:$MC$200,MATCH(1,('GMW - Baseline'!$MC$2:$MC$200=F$3)*('GMW - Baseline'!$MB$2:$MB$200=F$4),0),$E7-1973)} -> 290378 | G7: {=INDEX('GMW - Baseline'!$A$2:$MC$200,MATCH(1,('GMW - Baseline'!$MC$2:$MC$200=G$3)*('GMW - Baseline'!$MB$2:$MB$200=G$4),0),$E7-1973)} -> 153439 | H7: {=INDEX('GMW - Baseline'!$A$2:$MC$200,MATCH(1,('GMW - Baseline'!$MC$2:$MC$200=H$3)*('GMW - Baseline'!$MB$2:$MB$200=H$4),0),$E7-1973)} -> 30.60508 | I7: {=INDEX('GMW - Baseline'!$A$2:$MC$200,MATCH(1,('GMW - Baseline'!$MC$2:$MC$200=I$3)*('GMW - Baseline'!$MB$2:$MB$200=I$4),0),$E7-1973)} -> 17 | J7: {=INDEX('GMW - Baseline'!$A$2:$MC$200,MATCH(1,('GMW - Baseline'!$MC$2:$MC$200=J$3)*('GMW - Baseline'!$MB$2:$MB$200=J$4),0),$E7-1973)} -> #N/A | K7: {=INDEX('GMW - Baseline'!$A$2:$MC$200,MATCH(1,('GMW - Baseline'!$MC$2:$MC$200=K$3)*('GMW - Baseline'!$MB$2:$MB$200=K$4),0),$E7-1973)} -> #N/A | L7: {=INDEX('GMW - Baseline'!$A$2:$MC$200,MATCH(1,('GMW - Baseline'!$MC$2:$MC$200=L$3)*('GMW - Baseline'!$MB$2:$MB$200=L$4),0),$E7-1973)} -> #N/A | M7: {=INDEX('GMW - Baseline'!$A$2:$MC$200,MATCH(1,('GMW - Baseline'!$MC$2:$MC$200=M$3)*('GMW - Baseline'!$MB$2:$MB$200=M$4),0),$E7-1973)} -> #N/A | ... T7: {=INDEX('GMW - Baseline'!$A$2:$MC$200,MATCH(1,('GMW - Baseline'!$MC$2:$MC$200=T$3)*('GMW - Baseline'!$MB$2:$MB$200=T$4),0),$E7-1973)} -> #N/A
B8: 1980 | C8: 1980 | E8: =+E7+1 -> 1981 | F8: {=INDEX('GMW - Baseline'!$A$2:$MC$200,MATCH(1,('GMW - Baseline'!$MC$2:$MC$200=F$3)*('GMW - Baseline'!$MB$2:$MB$200=F$4),0),$E8-1973)} -> 284713 | G8: {=INDEX('GMW - Baseline'!$A$2:$MC$200,MATCH(1,('GMW - Baseline'!$MC$2:$MC$200=G$3)*('GMW - Baseline'!$MB$2:$MB$200=G$4),0),$E8-1973)} -> 149443 | H8: {=INDEX('GMW - Baseline'!$A$2:$MC$200,MATCH(1,('GMW - Baseline'!$MC$2:$MC$200=H$3)*('GMW - Baseline'!$MB$2:$MB$200=H$4),0),$E8-1973)} -> 32.24743 | I8: {=INDEX('GMW - Baseline'!$A$2:$MC$200,MATCH(1,('GMW - Baseline'!$MC$2:$MC$200=I$3)*('GMW - Baseline'!$MB$2:$MB$200=I$4),0),$E8-1973)} -> 17 | J8: {=INDEX('GMW - Baseline'!$A$2:$MC$200,MATCH(1,('GMW - Baseline'!$MC$2:$MC$200=J$3)*('GMW - Baseline'!$MB$2:$MB$200=J$4),0),$E8-1973)} -> #N/A | K8: {=INDEX('GMW - Baseline'!$A$2:$MC$200,MATCH(1,('GMW - Baseline'!$MC$2:$MC$200=K$3)*('GMW - Baseline'!$MB$2:$MB$200=K$4),0),$E8-1973)} -> #N/A | L8: {=INDEX('GMW - Baseline'!$A$2:$MC$200,MATCH(1,('GMW - Baseline'!$MC$2:$MC$200=L$3)*('GMW - Baseline'!$MB$2:$MB$200=L$4),0),$E8-1973)} -> #N/A | M8: {=INDEX('GMW - Baseline'!$A$2:$MC$200,MATCH(1,('GMW - Baseline'!$MC$2:$MC$200=M$3)*('GMW - Baseline'!$MB$2:$MB$200=M$4),0),$E8-1973)} -> #N/A | ... T8: {=INDEX('GMW - Baseline'!$A$2:$MC$200,MATCH(1,('GMW - Baseline'!$MC$2:$MC$200=T$3)*('GMW - Baseline'!$MB$2:$MB$200=T$4),0),$E8-1973)} -> #N/A
B9: 1980 | C9: 1980 | E9: =+E8+1 -> 1982 | F9: {=INDEX('GMW - Baseline'!$A$2:$MC$200,MATCH(1,('GMW - Baseline'!$MC$2:$MC$200=F$3)*('GMW - Baseline'!$MB$2:$MB$200=F$4),0),$E9-1973)} -> 284402 | G9: {=INDEX('GMW - Baseline'!$A$2:$MC$200,MATCH(1,('GMW - Baseline'!$MC$2:$MC$200=G$3)*('GMW - Baseline'!$MB$2:$MB$200=G$4),0),$E9-1973)} -> 151403 | H9: {=INDEX('GMW - Baseline'!$A$2:$MC$200,MATCH(1,('GMW - Baseline'!$MC$2:$MC$200=H$3)*('GMW - Baseline'!$MB$2:$MB$200=H$4),0),$E9-1973)} -> 32.9513 | I9: {=INDEX('GMW - Baseline'!$A$2:$MC$200,MATCH(1,('GMW - Baseline'!$MC$2:$MC$200=I$3)*('GMW - Baseline'!$MB$2:$MB$200=I$4),0),$E9-1973)} -> 16.0303 | J9: {=INDEX('GMW - Baseline'!$A$2:$MC$200,MATCH(1,('GMW - Baseline'!$MC$2:$MC$200=J$3)*('GMW - Baseline'!$MB$2:$MB$200=J$4),0),$E9-1973)} -> #N/A | K9: {=INDEX('GMW - Baseline'!$A$2:$MC$200,MATCH(1,('GMW - Baseline'!$MC$2:$MC$200=K$3)*('GMW - Baseline'!$MB$2:$MB$200=K$4),0),$E9-1973)} -> #N/A | L9: {=INDEX('GMW - Baseline'!$A$2:$MC$200,MATCH(1,('GMW - Baseline'!$MC$2:$MC$200=L$3)*('GMW - Baseline'!$MB$2:$MB$200=L$4),0),$E9-1973)} -> #N/A | M9: {=INDEX('GMW - Baseline'!$A$2:$MC$200,MATCH(1,('GMW - Baseline'!$MC$2:$MC$200=M$3)*('GMW - Baseline'!$MB$2:$MB$200=M$4),0),$E9-1973)} -> #N/A | ... T9: {=INDEX('GMW - Baseline'!$A$2:$MC$200,MATCH(1,('GMW - Baseline'!$MC$2:$MC$200=T$3)*('GMW - Baseline'!$MB$2:$MB$200=T$4),0),$E9-1973)} -> #N/A
B10: 1980 | C10: 1980 | E10: =+E9+1 -> 1983 | F10: {=INDEX('GMW - Baseline'!$A$2:$MC$200,MATCH(1,('GMW - Baseline'!$MC$2:$MC$200=F$3)*('GMW - Baseline'!$MB$2:$MB$200=F$4),0),$E10-1973)} -> 281496 | G10: {=INDEX('GMW - Baseline'!$A$2:$MC$200,MATCH(1,('GMW - Baseline'!$MC$2:$MC$200=G$3)*('GMW - Baseline'!$MB$2:$MB$200=G$4),0),$E10-1973)} -> 148523 | H10: {=INDEX('GMW - Baseline'!$A$2:$MC$200,MATCH(1,('GMW - Baseline'!$MC$2:$MC$200=H$3)*('GMW - Baseline'!$MB$2:$MB$200=H$4),0),$E10-1973)} -> 33.55088 | I10: {=INDEX('GMW - Baseline'!$A$2:$MC$200,MATCH(1,('GMW - Baseline'!$MC$2:$MC$200=I$3)*('GMW - Baseline'!$MB$2:$MB$200=I$4),0),$E10-1973)} -> 15.18182 | J10: {=INDEX('GMW - Baseline'!$A$2:$MC$200,MATCH(1,('GMW - Baseline'!$MC$2:$MC$200=J$3)*('GMW - Baseline'!$MB$2:$MB$200=J$4),0),$E10-1973)} -> #N/A | K10: {=INDEX('GMW - Baseline'!$A$2:$MC$200,MATCH(1,('GMW - Baseline'!$MC$2:$MC$200=K$3)*('GMW - Baseline'!$MB$2:$MB$200=K$4),0),$E10-1973)} -> #N/A | L10: {=INDEX('GMW - Baseline'!$A$2:$MC$200,MATCH(1,('GMW - Baseline'!$MC$2:$MC$200=L$3)*('GMW - Baseline'!$MB$2:$MB$200=L$4),0),$E10-1973)} -> #N/A | M10: {=INDEX('GMW - Baseline'!$A$2:$MC$200,MATCH(1,('GMW - Baseline'!$MC$2:$MC$200=M$3)*('GMW - Baseline'!$MB$2:$MB$200=M$4),0),$E10-1973)} -> #N/A | ... T10: {=INDEX('GMW - Baseline'!$A$2:$MC$200,MATCH(1,('GMW - Baseline'!$MC$2:$MC$200=T$3)*('GMW - Baseline'!$MB$2:$MB$200=T$4),0),$E10-1973)} -> #N/A
A11: 1981 | B11: =+B7+1 -> 1981 | C11: 1980 | D11: 1980 | E11: =+E10+1 -> 1984 | F11: {=INDEX('GMW - Baseline'!$A$2:$MC$200,MATCH(1,('GMW - Baseline'!$MC$2:$MC$200=F$3)*('GMW - Baseline'!$MB$2:$MB$200=F$4),0),$E11-1973)} -> 281257 | G11: {=INDEX('GMW - Baseline'!$A$2:$MC$200,MATCH(1,('GMW - Baseline'!$MC$2:$MC$200=G$3)*('GMW - Baseline'!$MB$2:$MB$200=G$4),0),$E11-1973)} -> 151234 | H11: {=INDEX('GMW - Baseline'!$A$2:$MC$200,MATCH(1,('GMW - Baseline'!$MC$2:$MC$200=H$3)*('GMW - Baseline'!$MB$2:$MB$200=H$4),0),$E11-1973)} -> 34.3851 | I11: {=INDEX('GMW - Baseline'!$A$2:$MC$200,MATCH(1,('GMW - Baseline'!$MC$2:$MC$200=I$3)*('GMW - Baseline'!$MB$2:$MB$200=I$4),0),$E11-1973)} -> 13.53125 | J11: {=INDEX('GMW - Baseline'!$A$2:$MC$200,MATCH(1,('GMW - Baseline'!$MC$2:$MC$200=J$3)*('GMW - Baseline'!$MB$2:$MB$200=J$4),0),$E11-1973)} -> #N/A | K11: {=INDEX('GMW - Baseline'!$A$2:$MC$200,MATCH(1,('GMW - Baseline'!$MC$2:$MC$200=K$3)*('GMW - Baseline'!$MB$2:$MB$200=K$4),0),$E11-1973)} -> #N/A | L11: {=INDEX('GMW - Baseline'!$A$2:$MC$200,MATCH(1,('GMW - Baseline'!$MC$2:$MC$200=L$3)*('GMW - Baseline'!$MB$2:$MB$200=L$4),0),$E11-1973)} -> #N/A | M11: {=INDEX('GMW - Baseline'!$A$2:$MC$200,MATCH(1,('GMW - Baseline'!$MC$2:$MC$200=M$3)*('GMW - Baseline'!$MB$2:$MB$200=M$4),0),$E11-1973)} -> #N/A | ... T11: {=INDEX('GMW - Baseline'!$A$2:$MC$200,MATCH(1,('GMW - Baseline'!$MC$2:$MC$200=T$3)*('GMW - Baseline'!$MB$2:$MB$200=T$4),0),$E11-1973)} -> #N/A
B12: =+B8+1 -> 1981 | C12: =+C8+1 -> 1981 | E12: =+E11+1 -> 1985 | F12: {=INDEX('GMW - Baseline'!$A$2:$MC$200,MATCH(1,('GMW - Baseline'!$MC$2:$MC$200=F$3)*('GMW - Baseline'!$MB$2:$MB$200=F$4),0),$E12-1973)} -> 282155 | G12: {=INDEX('GMW - Baseline'!$A$2:$MC$200,MATCH(1,('GMW - Baseline'!$MC$2:$MC$200=G$3)*('GMW - Baseline'!$MB$2:$MB$200=G$4),0),$E12-1973)} -> 151164 | H12: {=INDEX('GMW - Baseline'!$A$2:$MC$200,MATCH(1,('GMW - Baseline'!$MC$2:$MC$200=H$3)*('GMW - Baseline'!$MB$2:$MB$200=H$4),0),$E12-1973)} -> 36.07959 | I12: {=INDEX('GMW - Baseline'!$A$2:$MC$200,MATCH(1,('GMW - Baseline'!$MC$2:$MC$200=I$3)*('GMW - Baseline'!$MB$2:$MB$200=I$4),0),$E12-1973)} -> 12 | J12: {=INDEX('GMW - Baseline'!$A$2:$MC$200,MATCH(1,('GMW - Baseline'!$MC$2:$MC$200=J$3)*('GMW - Baseline'!$MB$2:$MB$200=J$4),0),$E12-1973)} -> #N/A | K12: {=INDEX('GMW - Baseline'!$A$2:$MC$200,MATCH(1,('GMW - Baseline'!$MC$2:$MC$200=K$3)*('GMW - Baseline'!$MB$2:$MB$200=K$4),0),$E12-1973)} -> #N/A | L12: {=INDEX('GMW - Baseline'!$A$2:$MC$200,MATCH(1,('GMW - Baseline'!$MC$2:$MC$200=L$3)*('GMW - Baseline'!$MB$2:$MB$200=L$4),0),$E12-1973)} -> #N/A | M12: {=INDEX('GMW - Baseline'!$A$2:$MC$200,MATCH(1,('GMW - Baseline'!$MC$2:$MC$200=M$3)*('GMW - Baseline'!$MB$2:$MB$200=M$4),0),$E12-1973)} -> #N/A | ... T12: {=INDEX('GMW - Baseline'!$A$2:$MC$200,MATCH(1,('GMW - Baseline'!$MC$2:$MC$200=T$3)*('GMW - Baseline'!$MB$2:$MB$200=T$4),0),$E12-1973)} -> #N/A
B13: =+B9+1 -> 1981 | C13: =+C9+1 -> 1981 | E13: =+E12+1 -> 1986 | F13: {=INDEX('GMW - Baseline'!$A$2:$MC$200,MATCH(1,('GMW - Baseline'!$MC$2:$MC$200=F$3)*('GMW - Baseline'!$MB$2:$MB$200=F$4),0),$E13-1973)} -> 285437 | G13: {=INDEX('GMW - Baseline'!$A$2:$MC$200,MATCH(1,('GMW - Baseline'!$MC$2:$MC$200=G$3)*('GMW - Baseline'!$MB$2:$MB$200=G$4),0),$E13-1973)} -> 151269 | H13: {=INDEX('GMW - Baseline'!$A$2:$MC$200,MATCH(1,('GMW - Baseline'!$MC$2:$MC$200=H$3)*('GMW - Baseline'!$MB$2:$MB$200=H$4),0),$E13-1973)} -> 36.73131 | I13: {=INDEX('GMW - Baseline'!$A$2:$MC$200,MATCH(1,('GMW - Baseline'!$MC$2:$MC$200=I$3)*('GMW - Baseline'!$MB$2:$MB$200=I$4),0),$E13-1973)} -> 12.51989 | J13: {=INDEX('GMW - Baseline'!$A$2:$MC$200,MATCH(1,('GMW - Baseline'!$MC$2:$MC$200=J$3)*('GMW - Baseline'!$MB$2:$MB$200=J$4),0),$E13-1973)} -> #N/A | K13: {=INDEX('GMW - Baseline'!$A$2:$MC$200,MATCH(1,('GMW - Baseline'!$MC$2:$MC$200=K$3)*('GMW - Baseline'!$MB$2:$MB$200=K$4),0),$E13-1973)} -> #N/A | L13: {=INDEX('GMW - Baseline'!$A$2:$MC$200,MATCH(1,('GMW - Baseline'!$MC$2:$MC$200=L$3)*('GMW - Baseline'!$MB$2:$MB$200=L$4),0),$E13-1973)} -> #N/A | M13: {=INDEX('GMW - Baseline'!$A$2:$MC$200,MATCH(1,('GMW - Baseline'!$MC$2:$MC$200=M$3)*('GMW - Baseline'!$MB$2:$MB$200=M$4),0),$E13-1973)} -> #N/A | ... T13: {=INDEX('GMW - Baseline'!$A$2:$MC$200,MATCH(1,('GMW - Baseline'!$MC$2:$MC$200=T$3)*('GMW - Baseline'!$MB$2:$MB$200=T$4),0),$E13-1973)} -> #N/A
B14: =+B10+1 -> 1981 | C14: =+C10+1 -> 1981 | E14: =+E13+1 -> 1987 | F14: {=INDEX('GMW - Baseline'!$A$2:$MC$200,MATCH(1,('GMW - Baseline'!$MC$2:$MC$200=F$3)*('GMW - Baseline'!$MB$2:$MB$200=F$4),0),$E14-1973)} -> 285814 | G14: {=INDEX('GMW - Baseline'!$A$2:$MC$200,MATCH(1,('GMW - Baseline'!$MC$2:$MC$200=G$3)*('GMW - Baseline'!$MB$2:$MB$200=G$4),0),$E14-1973)} -> 150853 | H14: {=INDEX('GMW - Baseline'!$A$2:$MC$200,MATCH(1,('GMW - Baseline'!$MC$2:$MC$200=H$3)*('GMW - Baseline'!$MB$2:$MB$200=H$4),0),$E14-1973)} -> 37.43518 | I14: {=INDEX('GMW - Baseline'!$A$2:$MC$200,MATCH(1,('GMW - Baseline'!$MC$2:$MC$200=I$3)*('GMW - Baseline'!$MB$2:$MB$200=I$4),0),$E14-1973)} -> 14.60417 | J14: {=INDEX('GMW - Baseline'!$A$2:$MC$200,MATCH(1,('GMW - Baseline'!$MC$2:$MC$200=J$3)*('GMW - Baseline'!$MB$2:$MB$200=J$4),0),$E14-1973)} -> #N/A | K14: {=INDEX('GMW - Baseline'!$A$2:$MC$200,MATCH(1,('GMW - Baseline'!$MC$2:$MC$200=K$3)*('GMW - Baseline'!$MB$2:$MB$200=K$4),0),$E14-1973)} -> #N/A | L14: {=INDEX('GMW - Baseline'!$A$2:$MC$200,MATCH(1,('GMW - Baseline'!$MC$2:$MC$200=L$3)*('GMW - Baseline'!$MB$2:$MB$200=L$4),0),$E14-1973)} -> #N/A | M14: {=INDEX('GMW - Baseline'!$A$2:$MC$200,MATCH(1,('GMW - Baseline'!$MC$2:$MC$200=M$3)*('GMW - Baseline'!$MB$2:$MB$200=M$4),0),$E14-1973)} -> #N/A | ... T14: {=INDEX('GMW - Baseline'!$A$2:$MC$200,MATCH(1,('GMW - Baseline'!$MC$2:$MC$200=T$3)*('GMW - Baseline'!$MB$2:$MB$200=T$4),0),$E14-1973)} -> #N/A
A15: 1982 | B15: =+B11+1 -> 1982 | C15: =+C11+1 -> 1981 | D15: =+D11+1 -> 1981 | E15: =+E14+1 -> 1988 | F15: {=INDEX('GMW - Baseline'!$A$2:$MC$200,MATCH(1,('GMW - Baseline'!$MC$2:$MC$200=F$3)*('GMW - Baseline'!$MB$2:$MB$200=F$4),0),$E15-1973)} -> 286275 | G15: {=INDEX('GMW - Baseline'!$A$2:$MC$200,MATCH(1,('GMW - Baseline'!$MC$2:$MC$200=G$3)*('GMW - Baseline'!$MB$2:$MB$200=G$4),0),$E15-1973)} -> 151361 | H15: {=INDEX('GMW - Baseline'!$A$2:$MC$200,MATCH(1,('GMW - Baseline'!$MC$2:$MC$200=H$3)*('GMW - Baseline'!$MB$2:$MB$200=H$4),0),$E15-1973)} -> 37.87835 | I15: {=INDEX('GMW - Baseline'!$A$2:$MC$200,MATCH(1,('GMW - Baseline'!$MC$2:$MC$200=I$3)*('GMW - Baseline'!$MB$2:$MB$200=I$4),0),$E15-1973)} -> 13.78516 | J15: {=INDEX('GMW - Baseline'!$A$2:$MC$200,MATCH(1,('GMW - Baseline'!$MC$2:$MC$200=J$3)*('GMW - Baseline'!$MB$2:$MB$200=J$4),0),$E15-1973)} -> #N/A | K15: {=INDEX('GMW - Baseline'!$A$2:$MC$200,MATCH(1,('GMW - Baseline'!$MC$2:$MC$200=K$3)*('GMW - Baseline'!$MB$2:$MB$200=K$4),0),$E15-1973)} -> #N/A | L15: {=INDEX('GMW - Baseline'!$A$2:$MC$200,MATCH(1,('GMW - Baseline'!$MC$2:$MC$200=L$3)*('GMW - Baseline'!$MB$2:$MB$200=L$4),0),$E15-1973)} -> #N/A | M15: {=INDEX('GMW - Baseline'!$A$2:$MC$200,MATCH(1,('GMW - Baseline'!$MC$2:$MC$200=M$3)*('GMW - Baseline'!$MB$2:$MB$200=M$4),0),$E15-1973)} -> #N/A | ... T15: {=INDEX('GMW - Baseline'!$A$2:$MC$200,MATCH(1,('GMW - Baseline'!$MC$2:$MC$200=T$3)*('GMW - Baseline'!$MB$2:$MB$200=T$4),0),$E15-1973)} -> #N/A
B16: =+B12+1 -> 1982 | C16: =+C12+1 -> 1982 | E16: =+E15+1 -> 1989 | F16: {=INDEX('GMW - Baseline'!$A$2:$MC$200,MATCH(1,('GMW - Baseline'!$MC$2:$MC$200=F$3)*('GMW - Baseline'!$MB$2:$MB$200=F$4),0),$E16-1973)} -> 289232 | G16: {=INDEX('GMW - Baseline'!$A$2:$MC$200,MATCH(1,('GMW - Baseline'!$MC$2:$MC$200=G$3)*('GMW - Baseline'!$MB$2:$MB$200=G$4),0),$E16-1973)} -> 151251 | H16: {=INDEX('GMW - Baseline'!$A$2:$MC$200,MATCH(1,('GMW - Baseline'!$MC$2:$MC$200=H$3)*('GMW - Baseline'!$MB$2:$MB$200=H$4),0),$E16-1973)} -> 39.1818 | I16: {=INDEX('GMW - Baseline'!$A$2:$MC$200,MATCH(1,('GMW - Baseline'!$MC$2:$MC$200=I$3)*('GMW - Baseline'!$MB$2:$MB$200=I$4),0),$E16-1973)} -> 13.01346 | J16: {=INDEX('GMW - Baseline'!$A$2:$MC$200,MATCH(1,('GMW - Baseline'!$MC$2:$MC$200=J$3)*('GMW - Baseline'!$MB$2:$MB$200=J$4),0),$E16-1973)} -> #N/A | K16: {=INDEX('GMW - Baseline'!$A$2:$MC$200,MATCH(1,('GMW - Baseline'!$MC$2:$MC$200=K$3)*('GMW - Baseline'!$MB$2:$MB$200=K$4),0),$E16-1973)} -> #N/A | L16: {=INDEX('GMW - Baseline'!$A$2:$MC$200,MATCH(1,('GMW - Baseline'!$MC$2:$MC$200=L$3)*('GMW - Baseline'!$MB$2:$MB$200=L$4),0),$E16-1973)} -> #N/A | M16: {=INDEX('GMW - Baseline'!$A$2:$MC$200,MATCH(1,('GMW - Baseline'!$MC$2:$MC$200=M$3)*('GMW - Baseline'!$MB$2:$MB$200=M$4),0),$E16-1973)} -> #N/A | ... T16: {=INDEX('GMW - Baseline'!$A$2:$MC$200,MATCH(1,('GMW - Baseline'!$MC$2:$MC$200=T$3)*('GMW - Baseline'!$MB$2:$MB$200=T$4),0),$E16-1973)} -> #N/A
B17: =+B13+1 -> 1982 | C17: =+C13+1 -> 1982 | E17: =+E16+1 -> 1990 | F17: {=INDEX('GMW - Baseline'!$A$2:$MC$200,MATCH(1,('GMW - Baseline'!$MC$2:$MC$200=F$3)*('GMW - Baseline'!$MB$2:$MB$200=F$4),0),$E17-1973)} -> 289852 | G17: {=INDEX('GMW - Baseline'!$A$2:$MC$200,MATCH(1,('GMW - Baseline'!$MC$2:$MC$200=G$3)*('GMW - Baseline'!$MB$2:$MB$200=G$4),0),$E17-1973)} -> 153796 | H17: {=INDEX('GMW - Baseline'!$A$2:$MC$200,MATCH(1,('GMW - Baseline'!$MC$2:$MC$200=H$3)*('GMW - Baseline'!$MB$2:$MB$200=H$4),0),$E17-1973)} -> 39.41642 | I17: {=INDEX('GMW - Baseline'!$A$2:$MC$200,MATCH(1,('GMW - Baseline'!$MC$2:$MC$200=I$3)*('GMW - Baseline'!$MB$2:$MB$200=I$4),0),$E17-1973)} -> 11.3428 | J17: {=INDEX('GMW - Baseline'!$A$2:$MC$200,MATCH(1,('GMW - Baseline'!$MC$2:$MC$200=J$3)*('GMW - Baseline'!$MB$2:$MB$200=J$4),0),$E17-1973)} -> #N/A | K17: {=INDEX('GMW - Baseline'!$A$2:$MC$200,MATCH(1,('GMW - Baseline'!$MC$2:$MC$200=K$3)*('GMW - Baseline'!$MB$2:$MB$200=K$4),0),$E17-1973)} -> #N/A | L17: {=INDEX('GMW - Baseline'!$A$2:$MC$200,MATCH(1,('GMW - Baseline'!$MC$2:$MC$200=L$3)*('GMW - Baseline'!$MB$2:$MB$200=L$4),0),$E17-1973)} -> #N/A | M17: {=INDEX('GMW - Baseline'!$A$2:$MC$200,MATCH(1,('GMW - Baseline'!$MC$2:$MC$200=M$3)*('GMW - Baseline'!$MB$2:$MB$200=M$4),0),$E17-1973)} -> #N/A | ... T17: {=INDEX('GMW - Baseline'!$A$2:$MC$200,MATCH(1,('GMW - Baseline'!$MC$2:$MC$200=T$3)*('GMW - Baseline'!$MB$2:$MB$200=T$4),0),$E17-1973)} -> #N/A
B18: =+B14+1 -> 1982 | C18: =+C14+1 -> 1982 | E18: =+E17+1 -> 1991 | F18: {=INDEX('GMW - Baseline'!$A$2:$MC$200,MATCH(1,('GMW - Baseline'!$MC$2:$MC$200=F$3)*('GMW - Baseline'!$MB$2:$MB$200=F$4),0),$E18-1973)} -> 291832 | G18: {=INDEX('GMW - Baseline'!$A$2:$MC$200,MATCH(1,('GMW - Baseline'!$MC$2:$MC$200=G$3)*('GMW - Baseline'!$MB$2:$MB$200=G$4),0),$E18-1973)} -> 155106 | H18: {=INDEX('GMW - Baseline'!$A$2:$MC$200,MATCH(1,('GMW - Baseline'!$MC$2:$MC$200=H$3)*('GMW - Baseline'!$MB$2:$MB$200=H$4),0),$E18-1973)} -> 39.88567 | I18: {=INDEX('GMW - Baseline'!$A$2:$MC$200,MATCH(1,('GMW - Baseline'!$MC$2:$MC$200=I$3)*('GMW - Baseline'!$MB$2:$MB$200=I$4),0),$E18-1973)} -> 9.685606 | J18: {=INDEX('GMW - Baseline'!$A$2:$MC$200,MATCH(1,('GMW - Baseline'!$MC$2:$MC$200=J$3)*('GMW - Baseline'!$MB$2:$MB$200=J$4),0),$E18-1973)} -> #N/A | K18: {=INDEX('GMW - Baseline'!$A$2:$MC$200,MATCH(1,('GMW - Baseline'!$MC$2:$MC$200=K$3)*('GMW - Baseline'!$MB$2:$MB$200=K$4),0),$E18-1973)} -> #N/A | L18: {=INDEX('GMW - Baseline'!$A$2:$MC$200,MATCH(1,('GMW - Baseline'!$MC$2:$MC$200=L$3)*('GMW - Baseline'!$MB$2:$MB$200=L$4),0),$E18-1973)} -> #N/A | M18: {=INDEX('GMW - Baseline'!$A$2:$MC$200,MATCH(1,('GMW - Baseline'!$MC$2:$MC$200=M$3)*('GMW - Baseline'!$MB$2:$MB$200=M$4),0),$E18-1973)} -> #N/A | ... T18: {=INDEX('GMW - Baseline'!$A$2:$MC$200,MATCH(1,('GMW - Baseline'!$MC$2:$MC$200=T$3)*('GMW - Baseline'!$MB$2:$MB$200=T$4),0),$E18-1973)} -> #N/A
A19: 1983 | B19: =+B15+1 -> 1983 | C19: =+C15+1 -> 1982 | D19: =+D15+1 -> 1982 | E19: =+E18+1 -> 1992 | F19: {=INDEX('GMW - Baseline'!$A$2:$MC$200,MATCH(1,('GMW - Baseline'!$MC$2:$MC$200=F$3)*('GMW - Baseline'!$MB$2:$MB$200=F$4),0),$E19-1973)} -> 297563 | G19: {=INDEX('GMW - Baseline'!$A$2:$MC$200,MATCH(1,('GMW - Baseline'!$MC$2:$MC$200=G$3)*('GMW - Baseline'!$MB$2:$MB$200=G$4),0),$E19-1973)} -> 157443 | H19: {=INDEX('GMW - Baseline'!$A$2:$MC$200,MATCH(1,('GMW - Baseline'!$MC$2:$MC$200=H$3)*('GMW - Baseline'!$MB$2:$MB$200=H$4),0),$E19-1973)} -> 40.17243 | I19: {=INDEX('GMW - Baseline'!$A$2:$MC$200,MATCH(1,('GMW - Baseline'!$MC$2:$MC$200=I$3)*('GMW - Baseline'!$MB$2:$MB$200=I$4),0),$E19-1973)} -> 10.80176 | J19: {=INDEX('GMW - Baseline'!$A$2:$MC$200,MATCH(1,('GMW - Baseline'!$MC$2:$MC$200=J$3)*('GMW - Baseline'!$MB$2:$MB$200=J$4),0),$E19-1973)} -> #N/A | K19: {=INDEX('GMW - Baseline'!$A$2:$MC$200,MATCH(1,('GMW - Baseline'!$MC$2:$MC$200=K$3)*('GMW - Baseline'!$MB$2:$MB$200=K$4),0),$E19-1973)} -> #N/A | L19: {=INDEX('GMW - Baseline'!$A$2:$MC$200,MATCH(1,('GMW - Baseline'!$MC$2:$MC$200=L$3)*('GMW - Baseline'!$MB$2:$MB$200=L$4),0),$E19-1973)} -> #N/A | M19: {=INDEX('GMW - Baseline'!$A$2:$MC$200,MATCH(1,('GMW - Baseline'!$MC$2:$MC$200=M$3)*('GMW - Baseline'!$MB$2:$MB$200=M$4),0),$E19-1973)} -> #N/A | ... T19: {=INDEX('GMW - Baseline'!$A$2:$MC$200,MATCH(1,('GMW - Baseline'!$MC$2:$MC$200=T$3)*('GMW - Baseline'!$MB$2:$MB$200=T$4),0),$E19-1973)} -> #N/A
B20: =+B16+1 -> 1983 | C20: =+C16+1 -> 1983 | E20: =+E19+1 -> 1993 | F20: {=INDEX('GMW - Baseline'!$A$2:$MC$200,MATCH(1,('GMW - Baseline'!$MC$2:$MC$200=F$3)*('GMW - Baseline'!$MB$2:$MB$200=F$4),0),$E20-1973)} -> 299623 | G20: {=INDEX('GMW - Baseline'!$A$2:$MC$200,MATCH(1,('GMW - Baseline'!$MC$2:$MC$200=G$3)*('GMW - Baseline'!$MB$2:$MB$200=G$4),0),$E20-1973)} -> 158445 | H20: {=INDEX('GMW - Baseline'!$A$2:$MC$200,MATCH(1,('GMW - Baseline'!$MC$2:$MC$200=H$3)*('GMW - Baseline'!$MB$2:$MB$200=H$4),0),$E20-1973)} -> 40.85022 | I20: {=INDEX('GMW - Baseline'!$A$2:$MC$200,MATCH(1,('GMW - Baseline'!$MC$2:$MC$200=I$3)*('GMW - Baseline'!$MB$2:$MB$200=I$4),0),$E20-1973)} -> 10.02404 | J20: {=INDEX('GMW - Baseline'!$A$2:$MC$200,MATCH(1,('GMW - Baseline'!$MC$2:$MC$200=J$3)*('GMW - Baseline'!$MB$2:$MB$200=J$4),0),$E20-1973)} -> #N/A | K20: {=INDEX('GMW - Baseline'!$A$2:$MC$200,MATCH(1,('GMW - Baseline'!$MC$2:$MC$200=K$3)*('GMW - Baseline'!$MB$2:$MB$200=K$4),0),$E20-1973)} -> #N/A | L20: {=INDEX('GMW - Baseline'!$A$2:$MC$200,MATCH(1,('GMW - Baseline'!$MC$2:$MC$200=L$3)*('GMW - Baseline'!$MB$2:$MB$200=L$4),0),$E20-1973)} -> #N/A | M20: {=INDEX('GMW - Baseline'!$A$2:$MC$200,MATCH(1,('GMW - Baseline'!$MC$2:$MC$200=M$3)*('GMW - Baseline'!$MB$2:$MB$200=M$4),0),$E20-1973)} -> #N/A | ... T20: {=INDEX('GMW - Baseline'!$A$2:$MC$200,MATCH(1,('GMW - Baseline'!$MC$2:$MC$200=T$3)*('GMW - Baseline'!$MB$2:$MB$200=T$4),0),$E20-1973)} -> #N/A
B21: =+B17+1 -> 1983 | C21: =+C17+1 -> 1983 | E21: =+E20+1 -> 1994 | F21: {=INDEX('GMW - Baseline'!$A$2:$MC$200,MATCH(1,('GMW - Baseline'!$MC$2:$MC$200=F$3)*('GMW - Baseline'!$MB$2:$MB$200=F$4),0),$E21-1973)} -> 303085 | G21: {=INDEX('GMW - Baseline'!$A$2:$MC$200,MATCH(1,('GMW - Baseline'!$MC$2:$MC$200=G$3)*('GMW - Baseline'!$MB$2:$MB$200=G$4),0),$E21-1973)} -> 161027 | H21: {=INDEX('GMW - Baseline'!$A$2:$MC$200,MATCH(1,('GMW - Baseline'!$MC$2:$MC$200=H$3)*('GMW - Baseline'!$MB$2:$MB$200=H$4),0),$E21-1973)} -> 41.2934 | I21: {=INDEX('GMW - Baseline'!$A$2:$MC$200,MATCH(1,('GMW - Baseline'!$MC$2:$MC$200=I$3)*('GMW - Baseline'!$MB$2:$MB$200=I$4),0),$E21-1973)} -> 9.560606 | J21: {=INDEX('GMW - Baseline'!$A$2:$MC$200,MATCH(1,('GMW - Baseline'!$MC$2:$MC$200=J$3)*('GMW - Baseline'!$MB$2:$MB$200=J$4),0),$E21-1973)} -> #N/A | K21: {=INDEX('GMW - Baseline'!$A$2:$MC$200,MATCH(1,('GMW - Baseline'!$MC$2:$MC$200=K$3)*('GMW - Baseline'!$MB$2:$MB$200=K$4),0),$E21-1973)} -> #N/A | L21: {=INDEX('GMW - Baseline'!$A$2:$MC$200,MATCH(1,('GMW - Baseline'!$MC$2:$MC$200=L$3)*('GMW - Baseline'!$MB$2:$MB$200=L$4),0),$E21-1973)} -> #N/A | M21: {=INDEX('GMW - Baseline'!$A$2:$MC$200,MATCH(1,('GMW - Baseline'!$MC$2:$MC$200=M$3)*('GMW - Baseline'!$MB$2:$MB$200=M$4),0),$E21-1973)} -> #N/A | ... T21: {=INDEX('GMW - Baseline'!$A$2:$MC$200,MATCH(1,('GMW - Baseline'!$MC$2:$MC$200=T$3)*('GMW - Baseline'!$MB$2:$MB$200=T$4),0),$E21-1973)} -> #N/A
B22: =+B18+1 -> 1983 | C22: =+C18+1 -> 1983 | E22: =+E21+1 -> 1995 | F22: {=INDEX('GMW - Baseline'!$A$2:$MC$200,MATCH(1,('GMW - Baseline'!$MC$2:$MC$200=F$3)*('GMW - Baseline'!$MB$2:$MB$200=F$4),0),$E22-1973)} -> 305361 | G22: {=INDEX('GMW - Baseline'!$A$2:$MC$200,MATCH(1,('GMW - Baseline'!$MC$2:$MC$200=G$3)*('GMW - Baseline'!$MB$2:$MB$200=G$4),0),$E22-1973)} -> 161090 | H22: {=INDEX('GMW - Baseline'!$A$2:$MC$200,MATCH(1,('GMW - Baseline'!$MC$2:$MC$200=H$3)*('GMW - Baseline'!$MB$2:$MB$200=H$4),0),$E22-1973)} -> 41.76264 | I22: {=INDEX('GMW - Baseline'!$A$2:$MC$200,MATCH(1,('GMW - Baseline'!$MC$2:$MC$200=I$3)*('GMW - Baseline'!$MB$2:$MB$200=I$4),0),$E22-1973)} -> 9.0625 | J22: {=INDEX('GMW - Baseline'!$A$2:$MC$200,MATCH(1,('GMW - Baseline'!$MC$2:$MC$200=J$3)*('GMW - Baseline'!$MB$2:$MB$200=J$4),0),$E22-1973)} -> #N/A | K22: {=INDEX('GMW - Baseline'!$A$2:$MC$200,MATCH(1,('GMW - Baseline'!$MC$2:$MC$200=K$3)*('GMW - Baseline'!$MB$2:$MB$200=K$4),0),$E22-1973)} -> #N/A | L22: {=INDEX('GMW - Baseline'!$A$2:$MC$200,MATCH(1,('GMW - Baseline'!$MC$2:$MC$200=L$3)*('GMW - Baseline'!$MB$2:$MB$200=L$4),0),$E22-1973)} -> #N/A | M22: {=INDEX('GMW - Baseline'!$A$2:$MC$200,MATCH(1,('GMW - Baseline'!$MC$2:$MC$200=M$3)*('GMW - Baseline'!$MB$2:$MB$200=M$4),0),$E22-1973)} -> #N/A | ... T22: {=INDEX('GMW - Baseline'!$A$2:$MC$200,MATCH(1,('GMW - Baseline'!$MC$2:$MC$200=T$3)*('GMW - Baseline'!$MB$2:$MB$200=T$4),0),$E22-1973)} -> #N/A
A23: 1984 | B23: =+B19+1 -> 1984 | C23: =+C19+1 -> 1983 | D23: =+D19+1 -> 1983 | E23: =+E22+1 -> 1996 | F23: {=INDEX('GMW - Baseline'!$A$2:$MC$200,MATCH(1,('GMW - Baseline'!$MC$2:$MC$200=F$3)*('GMW - Baseline'!$MB$2:$MB$200=F$4),0),$E23-1973)} -> 307964 | G23: {=INDEX('GMW - Baseline'!$A$2:$MC$200,MATCH(1,('GMW - Baseline'!$MC$2:$MC$200=G$3)*('GMW - Baseline'!$MB$2:$MB$200=G$4),0),$E23-1973)} -> 162074 | H23: {=INDEX('GMW - Baseline'!$A$2:$MC$200,MATCH(1,('GMW - Baseline'!$MC$2:$MC$200=H$3)*('GMW - Baseline'!$MB$2:$MB$200=H$4),0),$E23-1973)} -> 41.86692 | I23: {=INDEX('GMW - Baseline'!$A$2:$MC$200,MATCH(1,('GMW - Baseline'!$MC$2:$MC$200=I$3)*('GMW - Baseline'!$MB$2:$MB$200=I$4),0),$E23-1973)} -> 8.943269 | J23: {=INDEX('GMW - Baseline'!$A$2:$MC$200,MATCH(1,('GMW - Baseline'!$MC$2:$MC$200=J$3)*('GMW - Baseline'!$MB$2:$MB$200=J$4),0),$E23-1973)} -> #N/A | K23: {=INDEX('GMW - Baseline'!$A$2:$MC$200,MATCH(1,('GMW - Baseline'!$MC$2:$MC$200=K$3)*('GMW - Baseline'!$MB$2:$MB$200=K$4),0),$E23-1973)} -> #N/A | L23: {=INDEX('GMW - Baseline'!$A$2:$MC$200,MATCH(1,('GMW - Baseline'!$MC$2:$MC$200=L$3)*('GMW - Baseline'!$MB$2:$MB$200=L$4),0),$E23-1973)} -> #N/A | M23: {=INDEX('GMW - Baseline'!$A$2:$MC$200,MATCH(1,('GMW - Baseline'!$MC$2:$MC$200=M$3)*('GMW - Baseline'!$MB$2:$MB$200=M$4),0),$E23-1973)} -> #N/A | ... T23: {=INDEX('GMW - Baseline'!$A$2:$MC$200,MATCH(1,('GMW - Baseline'!$MC$2:$MC$200=T$3)*('GMW - Baseline'!$MB$2:$MB$200=T$4),0),$E23-1973)} -> #N/A
B24: =+B20+1 -> 1984 | C24: =+C20+1 -> 1984 | E24: =+E23+1 -> 1997 | F24: {=INDEX('GMW - Baseline'!$A$2:$MC$200,MATCH(1,('GMW - Baseline'!$MC$2:$MC$200=F$3)*('GMW - Baseline'!$MB$2:$MB$200=F$4),0),$E24-1973)} -> 304892 | G24: {=INDEX('GMW - Baseline'!$A$2:$MC$200,MATCH(1,('GMW - Baseline'!$MC$2:$MC$200=G$3)*('GMW - Baseline'!$MB$2:$MB$200=G$4),0),$E24-1973)} -> 163369 | H24: {=INDEX('GMW - Baseline'!$A$2:$MC$200,MATCH(1,('GMW - Baseline'!$MC$2:$MC$200=H$3)*('GMW - Baseline'!$MB$2:$MB$200=H$4),0),$E24-1973)} -> 42.77934 | I24: {=INDEX('GMW - Baseline'!$A$2:$MC$200,MATCH(1,('GMW - Baseline'!$MC$2:$MC$200=I$3)*('GMW - Baseline'!$MB$2:$MB$200=I$4),0),$E24-1973)} -> 8.844231 | J24: {=INDEX('GMW - Baseline'!$A$2:$MC$200,MATCH(1,('GMW - Baseline'!$MC$2:$MC$200=J$3)*('GMW - Baseline'!$MB$2:$MB$200=J$4),0),$E24-1973)} -> #N/A | K24: {=INDEX('GMW - Baseline'!$A$2:$MC$200,MATCH(1,('GMW - Baseline'!$MC$2:$MC$200=K$3)*('GMW - Baseline'!$MB$2:$MB$200=K$4),0),$E24-1973)} -> #N/A | L24: {=INDEX('GMW - Baseline'!$A$2:$MC$200,MATCH(1,('GMW - Baseline'!$MC$2:$MC$200=L$3)*('GMW - Baseline'!$MB$2:$MB$200=L$4),0),$E24-1973)} -> #N/A | M24: {=INDEX('GMW - Baseline'!$A$2:$MC$200,MATCH(1,('GMW - Baseline'!$MC$2:$MC$200=M$3)*('GMW - Baseline'!$MB$2:$MB$200=M$4),0),$E24-1973)} -> #N/A | ... T24: {=INDEX('GMW - Baseline'!$A$2:$MC$200,MATCH(1,('GMW - Baseline'!$MC$2:$MC$200=T$3)*('GMW - Baseline'!$MB$2:$MB$200=T$4),0),$E24-1973)} -> #N/A
B25: =+B21+1 -> 1984 | C25: =+C21+1 -> 1984 | E25: =+E24+1 -> 1998 | F25: {=INDEX('GMW - Baseline'!$A$2:$MC$200,MATCH(1,('GMW - Baseline'!$MC$2:$MC$200=F$3)*('GMW - Baseline'!$MB$2:$MB$200=F$4),0),$E25-1973)} -> 307122 | G25: {=INDEX('GMW - Baseline'!$A$2:$MC$200,MATCH(1,('GMW - Baseline'!$MC$2:$MC$200=G$3)*('GMW - Baseline'!$MB$2:$MB$200=G$4),0),$E25-1973)} -> 162507 | H25: {=INDEX('GMW - Baseline'!$A$2:$MC$200,MATCH(1,('GMW - Baseline'!$MC$2:$MC$200=H$3)*('GMW - Baseline'!$MB$2:$MB$200=H$4),0),$E25-1973)} -> 42.98789 | I25: {=INDEX('GMW - Baseline'!$A$2:$MC$200,MATCH(1,('GMW - Baseline'!$MC$2:$MC$200=I$3)*('GMW - Baseline'!$MB$2:$MB$200=I$4),0),$E25-1973)} -> 10.89615 | J25: {=INDEX('GMW - Baseline'!$A$2:$MC$200,MATCH(1,('GMW - Baseline'!$MC$2:$MC$200=J$3)*('GMW - Baseline'!$MB$2:$MB$200=J$4),0),$E25-1973)} -> #N/A | K25: {=INDEX('GMW - Baseline'!$A$2:$MC$200,MATCH(1,('GMW - Baseline'!$MC$2:$MC$200=K$3)*('GMW - Baseline'!$MB$2:$MB$200=K$4),0),$E25-1973)} -> #N/A | L25: {=INDEX('GMW - Baseline'!$A$2:$MC$200,MATCH(1,('GMW - Baseline'!$MC$2:$MC$200=L$3)*('GMW - Baseline'!$MB$2:$MB$200=L$4),0),$E25-1973)} -> #N/A | M25: {=INDEX('GMW - Baseline'!$A$2:$MC$200,MATCH(1,('GMW - Baseline'!$MC$2:$MC$200=M$3)*('GMW - Baseline'!$MB$2:$MB$200=M$4),0),$E25-1973)} -> #N/A | ... T25: {=INDEX('GMW - Baseline'!$A$2:$MC$200,MATCH(1,('GMW - Baseline'!$MC$2:$MC$200=T$3)*('GMW - Baseline'!$MB$2:$MB$200=T$4),0),$E25-1973)} -> #N/A
B26: =+B22+1 -> 1984 | C26: =+C22+1 -> 1984 | E26: =+E25+1 -> 1999 | F26: {=INDEX('GMW - Baseline'!$A$2:$MC$200,MATCH(1,('GMW - Baseline'!$MC$2:$MC$200=F$3)*('GMW - Baseline'!$MB$2:$MB$200=F$4),0),$E26-1973)} -> 312697 | G26: {=INDEX('GMW - Baseline'!$A$2:$MC$200,MATCH(1,('GMW - Baseline'!$MC$2:$MC$200=G$3)*('GMW - Baseline'!$MB$2:$MB$200=G$4),0),$E26-1973)} -> 165575 | H26: {=INDEX('GMW - Baseline'!$A$2:$MC$200,MATCH(1,('GMW - Baseline'!$MC$2:$MC$200=H$3)*('GMW - Baseline'!$MB$2:$MB$200=H$4),0),$E26-1973)} -> 43.43106 | I26: {=INDEX('GMW - Baseline'!$A$2:$MC$200,MATCH(1,('GMW - Baseline'!$MC$2:$MC$200=I$3)*('GMW - Baseline'!$MB$2:$MB$200=I$4),0),$E26-1973)} -> 9.969697 | J26: {=INDEX('GMW - Baseline'!$A$2:$MC$200,MATCH(1,('GMW - Baseline'!$MC$2:$MC$200=J$3)*('GMW - Baseline'!$MB$2:$MB$200=J$4),0),$E26-1973)} -> #N/A | K26: {=INDEX('GMW - Baseline'!$A$2:$MC$200,MATCH(1,('GMW - Baseline'!$MC$2:$MC$200=K$3)*('GMW - Baseline'!$MB$2:$MB$200=K$4),0),$E26-1973)} -> #N/A | L26: {=INDEX('GMW - Baseline'!$A$2:$MC$200,MATCH(1,('GMW - Baseline'!$MC$2:$MC$200=L$3)*('GMW - Baseline'!$MB$2:$MB$200=L$4),0),$E26-1973)} -> #N/A | M26: {=INDEX('GMW - Baseline'!$A$2:$MC$200,MATCH(1,('GMW - Baseline'!$MC$2:$MC$200=M$3)*('GMW - Baseline'!$MB$2:$MB$200=M$4),0),$E26-1973)} -> #N/A | ... T26: {=INDEX('GMW - Baseline'!$A$2:$MC$200,MATCH(1,('GMW - Baseline'!$MC$2:$MC$200=T$3)*('GMW - Baseline'!$MB$2:$MB$200=T$4),0),$E26-1973)} -> #N/A
A27: 1985 | B27: =+B23+1 -> 1985 | C27: =+C23+1 -> 1984 | D27: =+D23+1 -> 1984 | E27: =+E26+1 -> 2000 | F27: {=INDEX('GMW - Baseline'!$A$2:$MC$200,MATCH(1,('GMW - Baseline'!$MC$2:$MC$200=F$3)*('GMW - Baseline'!$MB$2:$MB$200=F$4),0),$E27-1973)} -> 315753 | G27: {=INDEX('GMW - Baseline'!$A$2:$MC$200,MATCH(1,('GMW - Baseline'!$MC$2:$MC$200=G$3)*('GMW - Baseline'!$MB$2:$MB$200=G$4),0),$E27-1973)} -> 169390 | H27: {=INDEX('GMW - Baseline'!$A$2:$MC$200,MATCH(1,('GMW - Baseline'!$MC$2:$MC$200=H$3)*('GMW - Baseline'!$MB$2:$MB$200=H$4),0),$E27-1973)} -> 43.87423 | I27: {=INDEX('GMW - Baseline'!$A$2:$MC$200,MATCH(1,('GMW - Baseline'!$MC$2:$MC$200=I$3)*('GMW - Baseline'!$MB$2:$MB$200=I$4),0),$E27-1973)} -> 12.86914 | J27: {=INDEX('GMW - Baseline'!$A$2:$MC$200,MATCH(1,('GMW - Baseline'!$MC$2:$MC$200=J$3)*('GMW - Baseline'!$MB$2:$MB$200=J$4),0),$E27-1973)} -> #N/A | K27: {=INDEX('GMW - Baseline'!$A$2:$MC$200,MATCH(1,('GMW - Baseline'!$MC$2:$MC$200=K$3)*('GMW - Baseline'!$MB$2:$MB$200=K$4),0),$E27-1973)} -> #N/A | L27: {=INDEX('GMW - Baseline'!$A$2:$MC$200,MATCH(1,('GMW - Baseline'!$MC$2:$MC$200=L$3)*('GMW - Baseline'!$MB$2:$MB$200=L$4),0),$E27-1973)} -> #N/A | M27: {=INDEX('GMW - Baseline'!$A$2:$MC$200,MATCH(1,('GMW - Baseline'!$MC$2:$MC$200=M$3)*('GMW - Baseline'!$MB$2:$MB$200=M$4),0),$E27-1973)} -> #N/A | ... T27: {=INDEX('GMW - Baseline'!$A$2:$MC$200,MATCH(1,('GMW - Baseline'!$MC$2:$MC$200=T$3)*('GMW - Baseline'!$MB$2:$MB$200=T$4),0),$E27-1973)} -> #N/A
B28: =+B24+1 -> 1985 | C28: =+C24+1 -> 1985 | E28: =+E27+1 -> 2001 | F28: {=INDEX('GMW - Baseline'!$A$2:$MC$200,MATCH(1,('GMW - Baseline'!$MC$2:$MC$200=F$3)*('GMW - Baseline'!$MB$2:$MB$200=F$4),0),$E28-1973)} -> 322451 | G28: {=INDEX('GMW - Baseline'!$A$2:$MC$200,MATCH(1,('GMW - Baseline'!$MC$2:$MC$200=G$3)*('GMW - Baseline'!$MB$2:$MB$200=G$4),0),$E28-1973)} -> 170284 | H28: {=INDEX('GMW - Baseline'!$A$2:$MC$200,MATCH(1,('GMW - Baseline'!$MC$2:$MC$200=H$3)*('GMW - Baseline'!$MB$2:$MB$200=H$4),0),$E28-1973)} -> 44.9952 | I28: {=INDEX('GMW - Baseline'!$A$2:$MC$200,MATCH(1,('GMW - Baseline'!$MC$2:$MC$200=I$3)*('GMW - Baseline'!$MB$2:$MB$200=I$4),0),$E28-1973)} -> 12.48269 | J28: {=INDEX('GMW - Baseline'!$A$2:$MC$200,MATCH(1,('GMW - Baseline'!$MC$2:$MC$200=J$3)*('GMW - Baseline'!$MB$2:$MB$200=J$4),0),$E28-1973)} -> #N/A | K28: {=INDEX('GMW - Baseline'!$A$2:$MC$200,MATCH(1,('GMW - Baseline'!$MC$2:$MC$200=K$3)*('GMW - Baseline'!$MB$2:$MB$200=K$4),0),$E28-1973)} -> #N/A | L28: {=INDEX('GMW - Baseline'!$A$2:$MC$200,MATCH(1,('GMW - Baseline'!$MC$2:$MC$200=L$3)*('GMW - Baseline'!$MB$2:$MB$200=L$4),0),$E28-1973)} -> #N/A | M28: {=INDEX('GMW - Baseline'!$A$2:$MC$200,MATCH(1,('GMW - Baseline'!$MC$2:$MC$200=M$3)*('GMW - Baseline'!$MB$2:$MB$200=M$4),0),$E28-1973)} -> #N/A | ... T28: {=INDEX('GMW - Baseline'!$A$2:$MC$200,MATCH(1,('GMW - Baseline'!$MC$2:$MC$200=T$3)*('GMW - Baseline'!$MB$2:$MB$200=T$4),0),$E28-1973)} -> #N/A
B29: =+B25+1 -> 1985 | C29: =+C25+1 -> 1985 | E29: =+E28+1 -> 2002 | F29: {=INDEX('GMW - Baseline'!$A$2:$MC$200,MATCH(1,('GMW - Baseline'!$MC$2:$MC$200=F$3)*('GMW - Baseline'!$MB$2:$MB$200=F$4),0),$E29-1973)} -> 322392 | G29: {=INDEX('GMW - Baseline'!$A$2:$MC$200,MATCH(1,('GMW - Baseline'!$MC$2:$MC$200=G$3)*('GMW - Baseline'!$MB$2:$MB$200=G$4),0),$E29-1973)} -> 172709 | H29: {=INDEX('GMW - Baseline'!$A$2:$MC$200,MATCH(1,('GMW - Baseline'!$MC$2:$MC$200=H$3)*('GMW - Baseline'!$MB$2:$MB$200=H$4),0),$E29-1973)} -> 45.12555 | I29: {=INDEX('GMW - Baseline'!$A$2:$MC$200,MATCH(1,('GMW - Baseline'!$MC$2:$MC$200=I$3)*('GMW - Baseline'!$MB$2:$MB$200=I$4),0),$E29-1973)} -> 11.57955 | J29: {=INDEX('GMW - Baseline'!$A$2:$MC$200,MATCH(1,('GMW - Baseline'!$MC$2:$MC$200=J$3)*('GMW - Baseline'!$MB$2:$MB$200=J$4),0),$E29-1973)} -> #N/A | K29: {=INDEX('GMW - Baseline'!$A$2:$MC$200,MATCH(1,('GMW - Baseline'!$MC$2:$MC$200=K$3)*('GMW - Baseline'!$MB$2:$MB$200=K$4),0),$E29-1973)} -> #N/A | L29: {=INDEX('GMW - Baseline'!$A$2:$MC$200,MATCH(1,('GMW - Baseline'!$MC$2:$MC$200=L$3)*('GMW - Baseline'!$MB$2:$MB$200=L$4),0),$E29-1973)} -> #N/A | M29: {=INDEX('GMW - Baseline'!$A$2:$MC$200,MATCH(1,('GMW - Baseline'!$MC$2:$MC$200=M$3)*('GMW - Baseline'!$MB$2:$MB$200=M$4),0),$E29-1973)} -> #N/A | ... T29: {=INDEX('GMW - Baseline'!$A$2:$MC$200,MATCH(1,('GMW - Baseline'!$MC$2:$MC$200=T$3)*('GMW - Baseline'!$MB$2:$MB$200=T$4),0),$E29-1973)} -> #N/A
B30: =+B26+1 -> 1985 | C30: =+C26+1 -> 1985 | E30: =+E29+1 -> 2003 | F30: {=INDEX('GMW - Baseline'!$A$2:$MC$200,MATCH(1,('GMW - Baseline'!$MC$2:$MC$200=F$3)*('GMW - Baseline'!$MB$2:$MB$200=F$4),0),$E30-1973)} -> 322604 | G30: {=INDEX('GMW - Baseline'!$A$2:$MC$200,MATCH(1,('GMW - Baseline'!$MC$2:$MC$200=G$3)*('GMW - Baseline'!$MB$2:$MB$200=G$4),0),$E30-1973)} -> 174066 | H30: {=INDEX('GMW - Baseline'!$A$2:$MC$200,MATCH(1,('GMW - Baseline'!$MC$2:$MC$200=H$3)*('GMW - Baseline'!$MB$2:$MB$200=H$4),0),$E30-1973)} -> 45.49052 | I30: {=INDEX('GMW - Baseline'!$A$2:$MC$200,MATCH(1,('GMW - Baseline'!$MC$2:$MC$200=I$3)*('GMW - Baseline'!$MB$2:$MB$200=I$4),0),$E30-1973)} -> 11.375 | J30: {=INDEX('GMW - Baseline'!$A$2:$MC$200,MATCH(1,('GMW - Baseline'!$MC$2:$MC$200=J$3)*('GMW - Baseline'!$MB$2:$MB$200=J$4),0),$E30-1973)} -> #N/A | K30: {=INDEX('GMW - Baseline'!$A$2:$MC$200,MATCH(1,('GMW - Baseline'!$MC$2:$MC$200=K$3)*('GMW - Baseline'!$MB$2:$MB$200=K$4),0),$E30-1973)} -> #N/A | L30: {=INDEX('GMW - Baseline'!$A$2:$MC$200,MATCH(1,('GMW - Baseline'!$MC$2:$MC$200=L$3)*('GMW - Baseline'!$MB$2:$MB$200=L$4),0),$E30-1973)} -> #N/A | M30: {=INDEX('GMW - Baseline'!$A$2:$MC$200,MATCH(1,('GMW - Baseline'!$MC$2:$MC$200=M$3)*('GMW - Baseline'!$MB$2:$MB$200=M$4),0),$E30-1973)} -> #N/A | ... T30: {=INDEX('GMW - Baseline'!$A$2:$MC$200,MATCH(1,('GMW - Baseline'!$MC$2:$MC$200=T$3)*('GMW - Baseline'!$MB$2:$MB$200=T$4),0),$E30-1973)} -> #N/A
A31: 1986 | B31: =+B27+1 -> 1986 | C31: =+C27+1 -> 1985 | D31: =+D27+1 -> 1985 | E31: =+E30+1 -> 2004 | F31: {=INDEX('GMW - Baseline'!$A$2:$MC$200,MATCH(1,('GMW - Baseline'!$MC$2:$MC$200=F$3)*('GMW - Baseline'!$MB$2:$MB$200=F$4),0),$E31-1973)} -> 325968 | G31: {=INDEX('GMW - Baseline'!$A$2:$MC$200,MATCH(1,('GMW - Baseline'!$MC$2:$MC$200=G$3)*('GMW - Baseline'!$MB$2:$MB$200=G$4),0),$E31-1973)} -> 178852 | H31: {=INDEX('GMW - Baseline'!$A$2:$MC$200,MATCH(1,('GMW - Baseline'!$MC$2:$MC$200=H$3)*('GMW - Baseline'!$MB$2:$MB$200=H$4),0),$E31-1973)} -> 45.64693 | I31: {=INDEX('GMW - Baseline'!$A$2:$MC$200,MATCH(1,('GMW - Baseline'!$MC$2:$MC$200=I$3)*('GMW - Baseline'!$MB$2:$MB$200=I$4),0),$E31-1973)} -> 12.07813 | J31: {=INDEX('GMW - Baseline'!$A$2:$MC$200,MATCH(1,('GMW - Baseline'!$MC$2:$MC$200=J$3)*('GMW - Baseline'!$MB$2:$MB$200=J$4),0),$E31-1973)} -> #N/A | K31: {=INDEX('GMW - Baseline'!$A$2:$MC$200,MATCH(1,('GMW - Baseline'!$MC$2:$MC$200=K$3)*('GMW - Baseline'!$MB$2:$MB$200=K$4),0),$E31-1973)} -> #N/A | L31: {=INDEX('GMW - Baseline'!$A$2:$MC$200,MATCH(1,('GMW - Baseline'!$MC$2:$MC$200=L$3)*('GMW - Baseline'!$MB$2:$MB$200=L$4),0),$E31-1973)} -> #N/A | M31: {=INDEX('GMW - Baseline'!$A$2:$MC$200,MATCH(1,('GMW - Baseline'!$MC$2:$MC$200=M$3)*('GMW - Baseline'!$MB$2:$MB$200=M$4),0),$E31-1973)} -> #N/A | ... T31: {=INDEX('GMW - Baseline'!$A$2:$MC$200,MATCH(1,('GMW - Baseline'!$MC$2:$MC$200=T$3)*('GMW - Baseline'!$MB$2:$MB$200=T$4),0),$E31-1973)} -> #N/A
B32: =+B28+1 -> 1986 | C32: =+C28+1 -> 1986 | E32: =+E31+1 -> 2005 | F32: {=INDEX('GMW - Baseline'!$A$2:$MC$200,MATCH(1,('GMW - Baseline'!$MC$2:$MC$200=F$3)*('GMW - Baseline'!$MB$2:$MB$200=F$4),0),$E32-1973)} -> 328872 | G32: {=INDEX('GMW - Baseline'!$A$2:$MC$200,MATCH(1,('GMW - Baseline'!$MC$2:$MC$200=G$3)*('GMW - Baseline'!$MB$2:$MB$200=G$4),0),$E32-1973)} -> 181672 | H32: {=INDEX('GMW - Baseline'!$A$2:$MC$200,MATCH(1,('GMW - Baseline'!$MC$2:$MC$200=H$3)*('GMW - Baseline'!$MB$2:$MB$200=H$4),0),$E32-1973)} -> 46.3508 | I32: {=INDEX('GMW - Baseline'!$A$2:$MC$200,MATCH(1,('GMW - Baseline'!$MC$2:$MC$200=I$3)*('GMW - Baseline'!$MB$2:$MB$200=I$4),0),$E32-1973)} -> 10.32885 | J32: {=INDEX('GMW - Baseline'!$A$2:$MC$200,MATCH(1,('GMW - Baseline'!$MC$2:$MC$200=J$3)*('GMW - Baseline'!$MB$2:$MB$200=J$4),0),$E32-1973)} -> #N/A | K32: {=INDEX('GMW - Baseline'!$A$2:$MC$200,MATCH(1,('GMW - Baseline'!$MC$2:$MC$200=K$3)*('GMW - Baseline'!$MB$2:$MB$200=K$4),0),$E32-1973)} -> #N/A | L32: {=INDEX('GMW - Baseline'!$A$2:$MC$200,MATCH(1,('GMW - Baseline'!$MC$2:$MC$200=L$3)*('GMW - Baseline'!$MB$2:$MB$200=L$4),0),$E32-1973)} -> #N/A | M32: {=INDEX('GMW - Baseline'!$A$2:$MC$200,MATCH(1,('GMW - Baseline'!$MC$2:$MC$200=M$3)*('GMW - Baseline'!$MB$2:$MB$200=M$4),0),$E32-1973)} -> #N/A | ... T32: {=INDEX('GMW - Baseline'!$A$2:$MC$200,MATCH(1,('GMW - Baseline'!$MC$2:$MC$200=T$3)*('GMW - Baseline'!$MB$2:$MB$200=T$4),0),$E32-1973)} -> #N/A
B33: =+B29+1 -> 1986 | C33: =+C29+1 -> 1986 | E33: =+E32+1 -> 2006 | F33: {=INDEX('GMW - Baseline'!$A$2:$MC$200,MATCH(1,('GMW - Baseline'!$MC$2:$MC$200=F$3)*('GMW - Baseline'!$MB$2:$MB$200=F$4),0),$E33-1973)} -> 330966 | G33: {=INDEX('GMW - Baseline'!$A$2:$MC$200,MATCH(1,('GMW - Baseline'!$MC$2:$MC$200=G$3)*('GMW - Baseline'!$MB$2:$MB$200=G$4),0),$E33-1973)} -> 182857 | H33: {=INDEX('GMW - Baseline'!$A$2:$MC$200,MATCH(1,('GMW - Baseline'!$MC$2:$MC$200=H$3)*('GMW - Baseline'!$MB$2:$MB$200=H$4),0),$E33-1973)} -> 46.53328 | I33: {=INDEX('GMW - Baseline'!$A$2:$MC$200,MATCH(1,('GMW - Baseline'!$MC$2:$MC$200=I$3)*('GMW - Baseline'!$MB$2:$MB$200=I$4),0),$E33-1973)} -> 9.875 | J33: {=INDEX('GMW - Baseline'!$A$2:$MC$200,MATCH(1,('GMW - Baseline'!$MC$2:$MC$200=J$3)*('GMW - Baseline'!$MB$2:$MB$200=J$4),0),$E33-1973)} -> #N/A | K33: {=INDEX('GMW - Baseline'!$A$2:$MC$200,MATCH(1,('GMW - Baseline'!$MC$2:$MC$200=K$3)*('GMW - Baseline'!$MB$2:$MB$200=K$4),0),$E33-1973)} -> #N/A | L33: {=INDEX('GMW - Baseline'!$A$2:$MC$200,MATCH(1,('GMW - Baseline'!$MC$2:$MC$200=L$3)*('GMW - Baseline'!$MB$2:$MB$200=L$4),0),$E33-1973)} -> #N/A | M33: {=INDEX('GMW - Baseline'!$A$2:$MC$200,MATCH(1,('GMW - Baseline'!$MC$2:$MC$200=M$3)*('GMW - Baseline'!$MB$2:$MB$200=M$4),0),$E33-1973)} -> #N/A | ... T33: {=INDEX('GMW - Baseline'!$A$2:$MC$200,MATCH(1,('GMW - Baseline'!$MC$2:$MC$200=T$3)*('GMW - Baseline'!$MB$2:$MB$200=T$4),0),$E33-1973)} -> #N/A
B34: =+B30+1 -> 1986 | C34: =+C30+1 -> 1986 | E34: =+E33+1 -> 2007 | F34: {=INDEX('GMW - Baseline'!$A$2:$MC$200,MATCH(1,('GMW - Baseline'!$MC$2:$MC$200=F$3)*('GMW - Baseline'!$MB$2:$MB$200=F$4),0),$E34-1973)} -> 337367 | G34: {=INDEX('GMW - Baseline'!$A$2:$MC$200,MATCH(1,('GMW - Baseline'!$MC$2:$MC$200=G$3)*('GMW - Baseline'!$MB$2:$MB$200=G$4),0),$E34-1973)} -> 183752 | H34: {=INDEX('GMW - Baseline'!$A$2:$MC$200,MATCH(1,('GMW - Baseline'!$MC$2:$MC$200=H$3)*('GMW - Baseline'!$MB$2:$MB$200=H$4),0),$E34-1973)} -> 46.92432 | I34: {=INDEX('GMW - Baseline'!$A$2:$MC$200,MATCH(1,('GMW - Baseline'!$MC$2:$MC$200=I$3)*('GMW - Baseline'!$MB$2:$MB$200=I$4),0),$E34-1973)} -> 10.72348 | J34: {=INDEX('GMW - Baseline'!$A$2:$MC$200,MATCH(1,('GMW - Baseline'!$MC$2:$MC$200=J$3)*('GMW - Baseline'!$MB$2:$MB$200=J$4),0),$E34-1973)} -> #N/A | K34: {=INDEX('GMW - Baseline'!$A$2:$MC$200,MATCH(1,('GMW - Baseline'!$MC$2:$MC$200=K$3)*('GMW - Baseline'!$MB$2:$MB$200=K$4),0),$E34-1973)} -> #N/A | L34: {=INDEX('GMW - Baseline'!$A$2:$MC$200,MATCH(1,('GMW - Baseline'!$MC$2:$MC$200=L$3)*('GMW - Baseline'!$MB$2:$MB$200=L$4),0),$E34-1973)} -> #N/A | M34: {=INDEX('GMW - Baseline'!$A$2:$MC$200,MATCH(1,('GMW - Baseline'!$MC$2:$MC$200=M$3)*('GMW - Baseline'!$MB$2:$MB$200=M$4),0),$E34-1973)} -> #N/A | ... T34: {=INDEX('GMW - Baseline'!$A$2:$MC$200,MATCH(1,('GMW - Baseline'!$MC$2:$MC$200=T$3)*('GMW - Baseline'!$MB$2:$MB$200=T$4),0),$E34-1973)} -> #N/A
A35: 1987 | B35: =+B31+1 -> 1987 | C35: =+C31+1 -> 1986 | D35: =+D31+1 -> 1986 | E35: =+E34+1 -> 2008 | F35: {=INDEX('GMW - Baseline'!$A$2:$MC$200,MATCH(1,('GMW - Baseline'!$MC$2:$MC$200=F$3)*('GMW - Baseline'!$MB$2:$MB$200=F$4),0),$E35-1973)} -> 339754 | G35: {=INDEX('GMW - Baseline'!$A$2:$MC$200,MATCH(1,('GMW - Baseline'!$MC$2:$MC$200=G$3)*('GMW - Baseline'!$MB$2:$MB$200=G$4),0),$E35-1973)} -> 185943 | H35: {=INDEX('GMW - Baseline'!$A$2:$MC$200,MATCH(1,('GMW - Baseline'!$MC$2:$MC$200=H$3)*('GMW - Baseline'!$MB$2:$MB$200=H$4),0),$E35-1973)} -> 47.23714 | I35: {=INDEX('GMW - Baseline'!$A$2:$MC$200,MATCH(1,('GMW - Baseline'!$MC$2:$MC$200=I$3)*('GMW - Baseline'!$MB$2:$MB$200=I$4),0),$E35-1973)} -> 10.66406 | J35: {=INDEX('GMW - Baseline'!$A$2:$MC$200,MATCH(1,('GMW - Baseline'!$MC$2:$MC$200=J$3)*('GMW - Baseline'!$MB$2:$MB$200=J$4),0),$E35-1973)} -> #N/A | K35: {=INDEX('GMW - Baseline'!$A$2:$MC$200,MATCH(1,('GMW - Baseline'!$MC$2:$MC$200=K$3)*('GMW - Baseline'!$MB$2:$MB$200=K$4),0),$E35-1973)} -> #N/A | L35: {=INDEX('GMW - Baseline'!$A$2:$MC$200,MATCH(1,('GMW - Baseline'!$MC$2:$MC$200=L$3)*('GMW - Baseline'!$MB$2:$MB$200=L$4),0),$E35-1973)} -> #N/A | M35: {=INDEX('GMW - Baseline'!$A$2:$MC$200,MATCH(1,('GMW - Baseline'!$MC$2:$MC$200=M$3)*('GMW - Baseline'!$MB$2:$MB$200=M$4),0),$E35-1973)} -> #N/A | ... T35: {=INDEX('GMW - Baseline'!$A$2:$MC$200,MATCH(1,('GMW - Baseline'!$MC$2:$MC$200=T$3)*('GMW - Baseline'!$MB$2:$MB$200=T$4),0),$E35-1973)} -> #N/A
B36: =+B32+1 -> 1987 | C36: =+C32+1 -> 1987 | E36: =+E35+1 -> 2009 | F36: {=INDEX('GMW - Baseline'!$A$2:$MC$200,MATCH(1,('GMW - Baseline'!$MC$2:$MC$200=F$3)*('GMW - Baseline'!$MB$2:$MB$200=F$4),0),$E36-1973)} -> 344795 | G36: {=INDEX('GMW - Baseline'!$A$2:$MC$200,MATCH(1,('GMW - Baseline'!$MC$2:$MC$200=G$3)*('GMW - Baseline'!$MB$2:$MB$200=G$4),0),$E36-1973)} -> 189091 | H36: {=INDEX('GMW - Baseline'!$A$2:$MC$200,MATCH(1,('GMW - Baseline'!$MC$2:$MC$200=H$3)*('GMW - Baseline'!$MB$2:$MB$200=H$4),0),$E36-1973)} -> 47.83673 | I36: {=INDEX('GMW - Baseline'!$A$2:$MC$200,MATCH(1,('GMW - Baseline'!$MC$2:$MC$200=I$3)*('GMW - Baseline'!$MB$2:$MB$200=I$4),0),$E36-1973)} -> 9.228847 | J36: {=INDEX('GMW - Baseline'!$A$2:$MC$200,MATCH(1,('GMW - Baseline'!$MC$2:$MC$200=J$3)*('GMW - Baseline'!$MB$2:$MB$200=J$4),0),$E36-1973)} -> #N/A | K36: {=INDEX('GMW - Baseline'!$A$2:$MC$200,MATCH(1,('GMW - Baseline'!$MC$2:$MC$200=K$3)*('GMW - Baseline'!$MB$2:$MB$200=K$4),0),$E36-1973)} -> #N/A | L36: {=INDEX('GMW - Baseline'!$A$2:$MC$200,MATCH(1,('GMW - Baseline'!$MC$2:$MC$200=L$3)*('GMW - Baseline'!$MB$2:$MB$200=L$4),0),$E36-1973)} -> #N/A | M36: {=INDEX('GMW - Baseline'!$A$2:$MC$200,MATCH(1,('GMW - Baseline'!$MC$2:$MC$200=M$3)*('GMW - Baseline'!$MB$2:$MB$200=M$4),0),$E36-1973)} -> #N/A | ... T36: {=INDEX('GMW - Baseline'!$A$2:$MC$200,MATCH(1,('GMW - Baseline'!$MC$2:$MC$200=T$3)*('GMW - Baseline'!$MB$2:$MB$200=T$4),0),$E36-1973)} -> #N/A
