Workbook
Name _DLX1.INC: HAVER!$A$1:$B$6

Sheet Chart Data
B1: Current data | C1: Data under new methodology | D1: Difference | G1: Date | I1: Monthly number of total sterling approvals for house purchase to individuals not seasonally adjusted LPMVTVU | J1: Monthly number of total sterling approvals for house purchase to individuals seasonally adjusted [c] LPMVTVX
A2: 43831 | B2: =100*((HAVER!B127/HAVER!B115)-1) -> 1.7692706 | C2: =data!C8 -> 1.6 | D2: =C2-B2 -> -0.16927056 | I2: Non seasonally adjusted | J2: Seasonally adjusted
A3: 43862 | B3: =100*((HAVER!B128/HAVER!B116)-1) -> 1.7095297 | C3: =data!C9 -> 1.6 | D3: =C3-B3 -> -0.10952974 | G3: 31 Jan 16 | H3: 42370 | I3: 49700 | J3: 72479 | K3: =100*((J3/I3)-1) -> 45.832998
A4: 43891 | B4: =100*((HAVER!B129/HAVER!B117)-1) -> 1.5233075 | C4: =data!C10 -> 1.4 | D4: =C4-B4 -> -0.12330754 | G4: 29 Feb 16 | H4: 42401 | I4: 66250 | J4: 71870 | K4: =100*((J4/I4)-1) -> 8.4830189
A5: 43922 | B5: =100*((HAVER!B130/HAVER!B118)-1) -> 0.76742263 | C5: =data!C11 -> 0.9 | D5: =C5-B5 -> 0.13257737 | G5: 31 Mar 16 | H5: 42430 | I5: 77609 | J5: 70738 | K5: =100*((J5/I5)-1) -> -8.8533546
A6: 43952 | B6: =100*((HAVER!B131/HAVER!B119)-1) -> 0.47986067 | C6: =data!C12 -> 0.5 | D6: =C6-B6 -> 0.020139326 | G6: 30 Apr 16 | H6: 42461 | I6: 72660 | J6: 68694 | K6: =100*((J6/I6)-1) -> -5.4582989
A7: 43983 | B7: =100*((HAVER!B132/HAVER!B120)-1) -> 0.60315196 | C7: =data!C13 -> 0.5 | D7: =C7-B7 -> -0.10315196 | G7: 31 May 16 | H7: 42491 | I7: 74217 | J7: 67879 | K7: =100*((J7/I7)-1) -> -8.5398224
A8: 44013 | B8: =100*((HAVER!B133/HAVER!B121)-1) -> 1.0403061 | C8: =data!C14 -> 1 | D8: =C8-B8 -> -0.04030607 | G8: 30 Jun 16 | H8: 42522 | I8: 78557 | J8: 65596 | K8: =100*((J8/I8)-1) -> -16.498848
A9: 44044 | B9: =100*((HAVER!B134/HAVER!B122)-1) -> 0.21960784 | C9: =data!C15 -> -0.1 | D9: =C9-B9 -> -0.31960784 | G9: 31 Jul 16 | H9: 42552 | I9: 67727 | J9: 62635 | K9: =100*((J9/I9)-1) -> -7.5184195
A10: 44075 | B10: =100*((HAVER!B135/HAVER!B123)-1) -> 0.53190018 | C10: =data!C16 -> 0.2 | D10: =C10-B10 -> -0.33190018 | G10: 31 Aug 16 | H10: 42583 | I10: 64389 | J10: 61444 | K10: =100*((J10/I10)-1) -> -4.5737626
A11: 44105 | B11: =100*((HAVER!B136/HAVER!B124)-1) -> 0.69715046 | C11: =data!C17 -> 0.3 | D11: =C11-B11 -> -0.39715046 | G11: 30 Sep 16 | H11: 42614 | I11: 66905 | J11: 64230 | K11: =100*((J11/I11)-1) -> -3.9982064
A12: 44136 | B12: =100*((HAVER!B137/HAVER!B125)-1) -> 0.31506509 | C12: =data!C18 -> -0.1 | D12: =C12-B12 -> -0.41506509 | G12: 31 Oct 16 | H12: 42644 | I12: 68175 | J12: 67903 | K12: =100*((J12/I12)-1) -> -0.39897323
A13: 44166 | B13: =100*((HAVER!B138/HAVER!B126)-1) -> 0.58876645 | C13: =data!C19 -> 0.3 | D13: =C13-B13 -> -0.28876645 | G13: 30 Nov 16 | H13: 42675 | I13: 71336 | J13: 68382 | K13: =100*((J13/I13)-1) -> -4.1409667
A14: 44197 | B14: =100*((HAVER!B139/HAVER!B127)-1) -> 0.70058043 | C14: =data!C20 -> 0.4 | D14: =C14-B14 -> -0.30058043 | G14: 31 Dec 16 | H14: 42705 | I14: 50460 | J14: 68328 | K14: =100*((J14/I14)-1) -> 35.410226 | L14: =K14 -> 35.410226
A15: 44228 | B15: =100*((HAVER!B140/HAVER!B128)-1) -> 0.41421589 | C15: =data!C21 -> 0.1 | D15: =C15-B15 -> -0.31421589 | G15: 31 Jan 17 | H15: 42736 | I15: 48505 | J15: 67977 | K15: =100*((J15/I15)-1) -> 40.144315
A16: 44256 | B16: =100*((HAVER!B141/HAVER!B129)-1) -> 0.71432517 | C16: =data!C22 -> 0.3 | D16: =C16-B16 -> -0.41432517 | G16: 28 Feb 17 | H16: 42767 | I16: 61064 | J16: 68133 | K16: =100*((J16/I16)-1) -> 11.576379
A17: 44287 | B17: =100*((HAVER!B142/HAVER!B130)-1) -> 1.5259222 | C17: =data!C23 -> 0.8 | D17: =C17-B17 -> -0.72592224 | G17: 31 Mar 17 | H17: 42795 | I17: 80339 | J17: 68052 | K17: =100*((J17/I17)-1) -> -15.293942
A18: 44317 | B18: =100*((HAVER!B143/HAVER!B131)-1) -> 2.1149485 | C18: =data!C24 -> 1.5 | D18: =C18-B18 -> -0.61494846 | G18: 30 Apr 17 | H18: 42826 | I18: 63293 | J18: 67131 | K18: =100*((J18/I18)-1) -> 6.0638617
A19: 44348 | B19: =100*((HAVER!B144/HAVER!B132)-1) -> 2.5141826 | C19: =data!C25 -> 1.9 | D19: =C19-B19 -> -0.61418257 | G19: 31 May 17 | H19: 42856 | I19: 75135 | J19: 66046 | K19: =100*((J19/I19)-1) -> -12.096892
A20: 44378 | B20: =100*((HAVER!B145/HAVER!B133)-1) -> 2.0399369 | C20: =data!C26 -> 1.4 | D20: =C20-B20 -> -0.63993692 | G20: 30 Jun 17 | H20: 42887 | I20: 78891 | J20: 65374 | K20: =100*((J20/I20)-1) -> -17.133767
A21: 44409 | B21: =100*((HAVER!B146/HAVER!B134)-1) -> 3.1966707 | C21: =data!C27 -> 2.8 | D21: =C21-B21 -> -0.39667075 | G21: 31 Jul 17 | H21: 42917 | I21: 73221 | J21: 68551 | K21: =100*((J21/I21)-1) -> -6.3779517
A22: 44440 | B22: =100*((HAVER!B147/HAVER!B135)-1) -> 3.080069 | C22: =data!C28 -> 2.7 | D22: =C22-B22 -> -0.38006896 | G22: 31 Aug 17 | H22: 42948 | I22: 70491 | J22: 66897 | K22: =100*((J22/I22)-1) -> -5.0985232
A23: 44470 | B23: =100*((HAVER!B148/HAVER!B136)-1) -> 4.2062117 | C23: =data!C29 -> 3.8 | D23: =C23-B23 -> -0.40621166 | G23: 30 Sep 17 | H23: 42979 | I23: 66228 | J23: 66313 | K23: =100*((J23/I23)-1) -> 0.12834451
A24: 44501 | B24: =100*((HAVER!B149/HAVER!B137)-1) -> 5.1299005 | C24: =data!C30 -> 4.8 | D24: =C24-B24 -> -0.32990054 | G24: 31 Oct 17 | H24: 43009 | I24: 67946 | J24: 65175 | K24: =100*((J24/I24)-1) -> -4.0782386
A25: 44531 | B25: =100*((HAVER!B150/HAVER!B138)-1) -> 5.3860457 | C25: =data!C31 -> 4.8 | D25: =C25-B25 -> -0.58604574 | G25: 30 Nov 17 | H25: 43040 | I25: 67872 | J25: 65671 | K25: =100*((J25/I25)-1) -> -3.2428689
A26: 44562 | B26: =100*((HAVER!B151/HAVER!B139)-1) -> 5.4555133 | C26: =data!C32 -> 5 | D26: =C26-B26 -> -0.45551334 | G26: 31 Dec 17 | H26: 43070 | I26: 43818 | J26: 62277 | K26: =100*((J26/I26)-1) -> 42.126523 | L26: =K26 -> 42.126523
A27: 44593 | B27: =100*((HAVER!B152/HAVER!B140)-1) -> 6.1766081 | C27: =data!C33 -> 5.6 | D27: =C27-B27 -> -0.57660809 | G27: 31 Jan 18 | H27: 43101 | I27: 49411 | J27: 65827 | K27: =100*((J27/I27)-1) -> 33.223371
A28: 44621 | B28: =100*((HAVER!B153/HAVER!B141)-1) -> 7.023124 | C28: =data!C34 -> 6.6 | D28: =C28-B28 -> -0.42312403 | G28: 28 Feb 18 | H28: 43132 | I28: 57019 | J28: 63000 | K28: =100*((J28/I28)-1) -> 10.489486
A29: 44652 | B29: =100*((HAVER!B154/HAVER!B142)-1) -> 9.0106617 | C29: =data!C35 -> 8.5 | D29: =C29-B29 -> -0.51066168 | G29: 31 Mar 18 | H29: 43160 | I29: 67004 | J29: 63111 | K29: =100*((J29/I29)-1) -> -5.8101009
A30: 44682 | B30: =100*((HAVER!B155/HAVER!B143)-1) -> 9.0827013 | C30: =data!C36 -> 8.7 | D30: =C30-B30 -> -0.38270134 | G30: 30 Apr 18 | H30: 43191 | I30: 66254 | J30: 63329 | K30: =100*((J30/I30)-1) -> -4.4148278
A31: 44713 | B31: =100*((HAVER!B156/HAVER!B144)-1) -> 9.4121135 | C31: =data!C37 -> 9.1 | D31: =C31-B31 -> -0.31211348 | G31: 31 May 18 | H31: 43221 | I31: 74586 | J31: 65112 | K31: =100*((J31/I31)-1) -> -12.702116
A32: 44743 | B32: =100*((HAVER!B157/HAVER!B145)-1) -> 10.100901 | C32: =data!C38 -> 9.8 | D32: =C32-B32 -> -0.30090119 | G32: 30 Jun 18 | H32: 43252 | I32: 76455 | J32: 65910 | K32: =100*((J32/I32)-1) -> -13.792427
A33: 44774 | B33: =100*((HAVER!B158/HAVER!B146)-1) -> 9.8701878 | C33: =data!C39 -> 9.6 | D33: =C33-B33 -> -0.2701878 | G33: 31 Jul 18 | H33: 43282 | I33: 72160 | J33: 64761 | K33: =100*((J33/I33)-1) -> -10.253603
A34: 44805 | B34: =100*((HAVER!B159/HAVER!B147)-1) -> 10.095628 | C34: =data!C40 -> 9.8 | D34: =C34-B34 -> -0.29562781 | G34: 31 Aug 18 | H34: 43313 | I34: 70507 | J34: 66809 | K34: =100*((J34/I34)-1) -> -5.2448693
A35: 44835 | B35: =100*((HAVER!B160/HAVER!B148)-1) -> 11.051566 | C35: =data!C41 -> 10.7 | D35: =C35-B35 -> -0.35156635 | G35: 30 Sep 18 | H35: 43344 | I35: 62852 | J35: 66005 | K35: =100*((J35/I35)-1) -> 5.0165468
A36: 44866 | B36: =100*((HAVER!B161/HAVER!B149)-1) -> 10.672013 | C36: =data!C42 -> 10.4 | D36: =C36-B36 -> -0.27201272 | G36: 31 Oct 18 | H36: 43374 | I36: 73674 | J36: 68210 | K36: =100*((J36/I36)-1) -> -7.4164563
A37: 44896 | B37: =100*((HAVER!B162/HAVER!B150)-1) -> 10.528374 | C37: =data!C43 -> 10.3 | D37: =C37-B37 -> -0.22837437 | G37: 30 Nov 18 | H37: 43405 | I37: 66947 | J37: 64924 | K37: =100*((J37/I37)-1) -> -3.0217934
A38: 44927 | B38: =100*((HAVER!B163/HAVER!B151)-1) -> 10.051524 | C38: =data!C44 -> 9.9 | D38: =C38-B38 -> -0.15152396 | G38: 31 Dec 18 | H38: 43435 | I38: 44510 | J38: 64365 | K38: =100*((J38/I38)-1) -> 44.607953 | L38: =K38 -> 44.607953
A39: 44958 | B39: =100*((HAVER!B164/HAVER!B152)-1) -> 10.416397 | C39: =data!C45 -> 10.3 | D39: =C39-B39 -> -0.11639687 | G39: 31 Jan 19 | H39: 43466 | I39: 49669 | J39: 65055 | K39: =100*((J39/I39)-1) -> 30.977068
A40: 44986 | B40: =100*((HAVER!B165/HAVER!B153)-1) -> 10.056877 | C40: =data!C46 -> 9.9 | D40: =C40-B40 -> -0.15687738 | G40: 28 Feb 19 | H40: 43497 | I40: 58628 | J40: 64164 | K40: =100*((J40/I40)-1) -> 9.4425872
...

Sheet data
A1: Figure 2: The CPI annual inflation rate was 0.03 percentage points lower on average when groceries scanner data were included
A2: Indicative impact of implementing groceries scanner data on the Consumer Prices Index (CPI) 12-month rate (including 2025 methods improvements), UK, January 2020 to June 2025
A4: Notes | B4: 1. The data in this chart have been rounded to one decimal place to clearly show which periods the headline annual inflation rate would have been unchanged or different at the one decimal place level commonly used when reporting annual inflation rates.
A5: Unit | B5: Percentage (%), percentage (%) and percentage point (pp)
A7: period | B7: CPI (2025 improvements) | C7: CPI (introducing groceries scanner data) | D7: Impact of introducing groceries scanner data
A8: Jan 2020 | B8: 1.6 | C8: 1.6 | D8: 0.0
A9: Feb 2020 | B9: 1.6 | C9: 1.6 | D9: 0
A10: Mar 2020 | B10: 1.4 | C10: 1.4 | D10: 0
A11: Apr 2020 | B11: 0.8 | C11: 0.9 | D11: 0.1
A12: May 2020 | B12: 0.4 | C12: 0.5 | D12: 0.1
A13: June 2020 | B13: 0.4 | C13: 0.5 | D13: 0.1
A14: July 2020 | B14: 0.9 | C14: 1 | D14: 0.1
A15: Aug 2020 | B15: -0.1 | C15: -0.1 | D15: 0
A16: Sep 2020 | B16: 0.2 | C16: 0.2 | D16: 0
A17: Oct 2020 | B17: 0.4 | C17: 0.3 | D17: -0.1
A18: Nov 2020 | B18: -0.1 | C18: -0.1 | D18: 0
A19: Dec 2020 | B19: 0.2 | C19: 0.3 | D19: 0.1
A20: Jan 2021 | B20: 0.3 | C20: 0.4 | D20: 0.1
... A73: June 2025 | B73: 3.4 | C73: 3.5 | D73: 0.1

Sheet HAVER
A1: 201001 !M | B1: D7BT3@UK
A2: .DESC | B2: UK: Consumer Price Index [3-digit]: All Items (NSA, 2015=100)
A3: .T1 | B3: Jan-1988
A4: .TN | B4: Dec-2025
A5: .LSOURCE | B5: Office for National Statistics
A6: .DTLM | B6: Jan-21-2026 07:02
A7: 201001 | B7: 87.828
A8: 201002 | B8: 88.152
A9: 201003 | B9: 88.661
A10: 201004 | B10: 89.17
A11: 201005 | B11: 89.373
A12: 201006 | B12: 89.506
A13: 201007 | B13: 89.305
A14: 201008 | B14: 89.764
A15: 201009 | B15: 89.765
A16: 201010 | B16: 89.995
A17: 201011 | B17: 90.331
A18: 201012 | B18: 91.23
... A198: 202512 | B198: 140.125
