Workbook
Name _DLX1.INC: HAVERM!$B$2:$AH$7
Name _DLX2.INC: HAVERD!$G$3:$IS$8
Name _DLX3.INC: HAVERQ!$B$2:$H$7
Name Data: [1]sheet0!$C$2

Sheet >> MARKET PRICING CHARTS

Sheet >> DATA
C5: ='Market expectations - Oil'!$N$53:$AL$53,'Market expectations - Oil'!$N$55:$AL$56 -> #VALUE!

Sheet Bloom - Monthly US data
A1: Year | B1: Month | C1: 1. Economic Policy Uncertainty | D1: 2. Monetary policy | E1: Fiscal Policy (Taxes OR Spending) | F1: 3. Taxes | G1: 4. Government spending | H1: 5. Health care | I1: 6. National security | J1: 7. Entitlement programs | K1: 8. Regulation | L1: Financial Regulation | M1: 9. Trade policy | N1: 10. Sovereign debt, currency crises | R1: Source: “Measuring Economic Policy Uncertainty” by Scott Baker, Nicholas Bloom and Steven J. Davis at www.PolicyUncertainty.com. These data can be used freely with attribution to the authors, the paper, and the website.
A2: 1985 | B2: 1 | C2: 213.67883 | D2: 270.46923 | E2: 292.61456 | F2: 295.79079 | G2: 394.09975 | H2: 107.84824 | I2: 179.69985 | J2: 258.34622 | K2: 129.63282 | L2: 113.24718 | M2: 122.61396 | N2: 0
A3: 1985 | B3: 2 | C3: 155.42602 | D3: 219.83568 | E3: 164.23554 | F3: 139.1256 | G3: 225.03278 | H3: 36.73303 | I3: 124.8595 | J3: 82.492997 | K3: 55.191052 | L3: 0 | M3: 41.762223 | N3: 128.389
A4: 1985 | B4: 3 | C4: 121.13737 | D4: 119.03452 | E4: 108.82881 | F4: 115.71434 | G4: 102.02634 | H4: 31.642944 | I4: 63.269264 | J4: 113.69914 | K4: 85.577836 | L4: 149.52152 | M4: 107.92573 | N4: 110.59817
A5: 1985 | B5: 4 | C5: 104.98235 | D5: 122.04476 | E5: 104.73733 | F5: 85.760217 | G5: 138.08053 | H5: 38.066636 | I5: 85.627432 | J5: 51.29276 | K5: 60.054521 | L5: 44.968804 | M5: 194.75287 | N5: 0
A6: 1985 | B6: 5 | C6: 115.73678 | D6: 107.57358 | E6: 134.83997 | F6: 132.17777 | G6: 167.56891 | H6: 54.705931 | I6: 109.38312 | J6: 98.284429 | K6: 65.75614 | L6: 129.25021 | M6: 124.39166 | N6: 95.603868
A7: 1985 | B7: 6 | C7: 139.79243 | D7: 156.64302 | E7: 197.6899 | F7: 190.02239 | G7: 182.43723 | H7: 26.943794 | I7: 161.6203 | J7: 108.91597 | K7: 89.062184 | L7: 42.43892 | M7: 153.16361 | N7: 0
A8: 1985 | B8: 7 | C8: 120.50515 | D8: 173.40758 | E8: 134.14929 | F8: 122.26014 | G8: 201.22261 | H8: 26.003398 | I8: 155.97941 | J8: 116.79397 | K8: 39.069875 | L8: 0 | M8: 59.127152 | N8: 181.77374
A9: 1985 | B9: 8 | C9: 122.68383 | D9: 111.33082 | E9: 118.87554 | F9: 122.82737 | G9: 217.70667 | H9: 56.267169 | I9: 106.07593 | J9: 151.63401 | K9: 57.970918 | L9: 37.982527 | M9: 109.66426 | N9: 168.56963
A10: 1985 | B10: 9 | C10: 91.711134 | D10: 113.58992 | E10: 81.798704 | F10: 67.479869 | G10: 126.92818 | H10: 24.603827 | I10: 83.631037 | J10: 11.050781 | K10: 51.753844 | L10: 77.506519 | M10: 279.72386 | N10: 85.9951
A11: 1985 | B11: 10 | C11: 86.338619 | D11: 69.607238 | E11: 108.07516 | F11: 89.542597 | G11: 103.62251 | H11: 7.1417751 | I11: 42.839395 | J11: 67.362126 | K11: 64.382722 | L11: 33.746831 | M11: 121.79355 | N11: 74.885628
A12: 1985 | B12: 11 | C12: 115.88343 | D12: 70.245579 | E12: 96.548438 | F12: 83.162896 | G12: 99.344154 | H12: 34.234531 | I12: 114.99781 | J12: 36.903362 | K12: 117.27654 | L12: 32.353495 | M12: 93.411958 | N12: 287.17503
A13: 1985 | B13: 12 | C13: 126.42213 | D13: 112.56385 | E13: 150.93895 | F13: 137.02444 | G13: 225.52253 | H13: 6.8573188 | I13: 119.28601 | J13: 55.439227 | K13: 98.909382 | L13: 64.805396 | M13: 70.165513 | N13: 0
... A481: 2024 | B481: 12 | C481: 178.71316 | D481: 155.29582 | E481: 182.71297 | F481: 184.80943 | G481: 144.52786 | H481: 310.54932 | I481: 154.64808 | J481: 277.64988 | K481: 258.82961 | L481: 46.145599 | M481: 1319.0059 | N481: 51.199505
A482: 2025 | B482: 1 | C482: 236.44342 | D482: 222.12527 | E482: 291.74046 | F482: 293.14729 | G482: 208.06876 | H482: 415.24587 | I482: 159.32277 | J482: 448.62547 | K482: 345.67612 | L482: 97.223638 | M482: 1725.7097 | N482: 9.8065141
A483: 2025 | B483: 2 | C483: 318.83708 | D483: 228.812 | E483: 366.30341 | F483: 387.18067 | G483: 324.81819 | H483: 508.7607 | I483: 302.74939 | J483: 517.89384 | K483: 339.19675 | L483: 258.08702 | M483: 2583.8988 | N483: 137.87364
A484: 2025 | B484: 3 | C484: 494.24966 | D484: 448.73962 | E484: 625.94934 | F484: 642.23055 | G484: 526.66807 | H484: 602.54292 | I484: 646.92115 | J484: 749.04636 | K484: 385.29537 | L484: 409.31014 | M484: 5912.1077 | N484: 119.7727
A485: 2025 | B485: 4 | C485: 536.89983 | D485: 452.76532 | E485: 688.94801 | F485: 738.80059 | G485: 370.92482 | H485: 713.75444 | I485: 765.61537 | J485: 688.93701 | K485: 443.26268 | L485: 401.19509 | M485: 7955.647 | N485: 508.72495
A486: 2025 | B486: 5 | C486: 488.92356 | D486: 422.14241 | E486: 618.66266 | F486: 634.2017 | G486: 622.65226 | H486: 912.07601 | I486: 537.53321 | J486: 984.94913 | K486: 466.94638 | L486: 133.01875 | M486: 5780.0371 | N486: 98.391385
A487: 2025 | B487: 6 | C487: 379.36265 | D487: 288.22908 | E487: 494.28389 | F487: 529.56941 | G487: 533.52789 | H487: 677.34828 | I487: 293.7497 | J487: 821.00483 | K487: 400.578 | L487: 170.50673 | M487: 3537.4699 | N487: 378.36156
A488: 2025 | B488: 7 | C488: 364.90501 | D488: 342.21048 | E488: 447.40446 | F488: 483.94887 | G488: 256.16082 | H488: 530.65718 | I488: 277.08186 | J488: 521.63303 | K488: 467.45012 | L488: 243.58568 | M488: 3371.6439 | N488: 63.591386
A489: 2025 | B489: 8 | C489: 291.42825 | D489: 288.02986 | E489: 322.08127 | F489: 344.37666 | G489: 185.19977 | H489: 459.31163 | I489: 270.15901 | J489: 395.66691 | K489: 269.18826 | L489: 159.3794 | M489: 2727.1536 | N489: 10.402046
A490: 2025 | B490: 9 | C490: 331.642 | D490: 374.76442 | E490: 375.56345 | F490: 406.96841 | G490: 228.68564 | H490: 547.44542 | I490: 235.96934 | J490: 526.1493 | K490: 230.60009 | L490: 109.88299 | M490: 3767.4313 | N490: 30.479367
A491: 2025 | B491: 10 | C491: 340.44588 | D491: 244.72468 | E491: 391.26275 | F491: 413.1186 | G491: 244.1528 | H491: 765.28296 | I491: 292.61029 | J491: 726.04576 | K491: 325.18023 | L491: 126.88317 | M491: 2558.2799 | N491: 65.697111
A492: 2025 | B492: 11 | C492: 336.51804 | D492: 261.6806 | E492: 396.77829 | F492: 417.42352 | G492: 294.16563 | H492: 565.06192 | I492: 274.21843 | J492: 633.17046 | K492: 311.30019 | L492: 101.98189 | M492: 3178.6687 | N492: 30.859374
A493: 2025 | B493: 12 | C493: 359.15685 | D493: 247.6231 | E493: 358.45486 | F493: 384.91154 | G493: 222.85369 | H493: 653.26963 | I493: 250.07174 | J493: 467.67266 | K493: 379.42573 | L493: 344.0336 | M493: 3115.9806 | N493: 62.747253
... A496: 2026 | B496: 3 | C496: 388.70268 | D496: 271.2267 | E496: 366.15029 | F496: 397.92815 | G496: 221.16314 | H496: 458.30479 | I496: 643.49907 | J496: 343.84256 | K496: 435.24356 | L496: 491.96596 | M496: 2144.5534 | N496: 214.05745

Sheet Market pricing dates
A2: April 2026 MPR | B2: 46134 | D2: Current market curve | E2: 46191 | I2: * Final date for Feb 2026 MPR forecast will be January 27, ahead of the MPR release on February 5
A4: Last 5 working days | D4: Last 5 working days | I4: * Final date for Apr 2026 MPR forecast will be April 21, ahead of the MPR release on April 30
A5: =TEXT(B5,"dddd") -> Thursday | B5: =IF(A6="Monday",B6-3,B6-1) -> 46128 | D5: =TEXT(E5,"dddd") -> Friday | E5: =IF(D6="Monday",E6-3,E6-1) -> 46185
A6: =TEXT(B6,"dddd") -> Friday | B6: =IF(A7="Monday",B7-3,B7-1) -> 46129 | D6: =TEXT(E6,"dddd") -> Monday | E6: =IF(D7="Monday",E7-3,E7-1) -> 46188
A7: =TEXT(B7,"dddd") -> Monday | B7: =IF(A8="Monday",B8-3,B8-1) -> 46132 | D7: =TEXT(E7,"dddd") -> Tuesday | E7: =IF(D8="Monday",E8-3,E8-1) -> 46189
A8: =TEXT(B8,"dddd") -> Tuesday | B8: =IF(A9="Monday",B9-3,B9-1) -> 46133 | D8: =TEXT(E8,"dddd") -> Wednesday | E8: =IF(D9="Monday",E9-3,E9-1) -> 46190
A9: =TEXT(B9,"dddd") -> Wednesday | B9: =B2 -> 46134 | D9: =TEXT(E9,"dddd") -> Thursday | E9: =E2 -> 46191
B11: =TEXT(B9,"dd mmm yyyy") -> 22 Apr 2026 | E11: =TEXT(E9,"dd mmm yyyy") -> 18 Jun 2026
A12: ="15 working days to "&B11 -> 15 working days to 22 Apr 2026 | D12: ="15 working days to "&E11 -> 15 working days to 18 Jun 2026

Sheet Market expectations - RCB
A1: ='Market pricing dates'!A2 -> April 2026 MPR | C1: ='Market pricing dates'!A12 -> 15 working days to 22 Apr 2026 | BA1: ='Market pricing dates'!D2 -> Current market curve | BC1: ='Market pricing dates'!D12 -> 15 working days to 18 Jun 2026
A2: Column # | B2: =HAVERD!I$1 -> 9 | C2: =+B2+1 -> 10 | D2: =+C2+1 -> 11 | E2: =+D2+1 -> 12 | F2: =+E2+1 -> 13 | G2: =+F2+1 -> 14 | H2: =+G2+1 -> 15 | I2: =+H2+1 -> 16 | J2: =+I2+1 -> 17 | ... AX2: =+AW2+1 -> 57 | BA2: Column # | BB2: =HAVERD!I$1 -> 9 | BC2: =+BB2+1 -> 10 | BD2: =+BC2+1 -> 11 | BE2: =+BD2+1 -> 12 | BF2: =+BE2+1 -> 13 | BG2: =+BF2+1 -> 14 | BH2: =+BG2+1 -> 15 | BI2: =+BH2+1 -> 16 | BJ2: =+BI2+1 -> 17 | ... CX2: =+CW2+1 -> 57
A3: Months | B3: =HAVERD!I$2 -> Overnight | C3: =HAVERD!J$2 -> 1 | D3: =HAVERD!K$2 -> 2 | E3: =HAVERD!L$2 -> 3 | F3: =HAVERD!M$2 -> 4 | G3: =HAVERD!N$2 -> 5 | H3: =HAVERD!O$2 -> 6 | I3: =HAVERD!P$2 -> 7 | ... AX3: =HAVERD!BE$2 -> 48 | BA3: Months | BB3: =HAVERD!I$2 -> Overnight | BC3: =HAVERD!J$2 -> 1 | BD3: =HAVERD!K$2 -> 2 | BE3: =HAVERD!L$2 -> 3 | BF3: =HAVERD!M$2 -> 4 | BG3: =HAVERD!N$2 -> 5 | BH3: =HAVERD!O$2 -> 6 | BI3: =HAVERD!P$2 -> 7 | ... CX3: =HAVERD!BE$2 -> 48
A4: Days | C4: 30.416667 | D4: =+C4+30.4166667 -> 60.833333 | E4: =+D4+30.4166667 -> 91.25 | F4: =+E4+30.4166667 -> 121.66667 | G4: =+F4+30.4166667 -> 152.08333 | H4: =+G4+30.4166667 -> 182.5 | I4: =+H4+30.4166667 -> 212.91667 | J4: =+I4+30.4166667 -> 243.33333 | K4: =+J4+30.4166667 -> 273.75 | ... AX4: =+AW4+30.4166667 -> 1460 | BA4: Days | BC4: 30.416667 | BD4: =+BC4+30.4166667 -> 60.833333 | BE4: =+BD4+30.4166667 -> 91.25 | BF4: =+BE4+30.4166667 -> 121.66667 | BG4: =+BF4+30.4166667 -> 152.08333 | BH4: =+BG4+30.4166667 -> 182.5 | BI4: =+BH4+30.4166667 -> 212.91667 | BJ4: =+BI4+30.4166667 -> 243.33333 | BK4: =+BJ4+30.4166667 -> 273.75 | ... CX4: =+CW4+30.4166667 -> 1460
A5: Dates | BA5: Dates
A6: =A11-7 -> 46114 | B6: =A6 -> 46114 | C6: =$B6+C$4 -> 46144.417 | D6: =$B6+D$4 -> 46174.833 | E6: =$B6+E$4 -> 46205.25 | F6: =$B6+F$4 -> 46235.667 | G6: =$B6+G$4 -> 46266.083 | H6: =$B6+H$4 -> 46296.5 | I6: =$B6+I$4 -> 46326.917 | J6: =$B6+J$4 -> 46357.333 | ... AX6: =$B6+AX$4 -> 47574 | BA6: =BA11-7 -> 46171 | BB6: =BA6 -> 46171 | BC6: =$BA6+BC$4 -> 46201.417 | BD6: =$BA6+BD$4 -> 46231.833 | BE6: =$BA6+BE$4 -> 46262.25 | BF6: =$BA6+BF$4 -> 46292.667 | BG6: =$BA6+BG$4 -> 46323.083 | BH6: =$BA6+BH$4 -> 46353.5 | BI6: =$BA6+BI$4 -> 46383.917 | BJ6: =$BA6+BJ$4 -> 46414.333 | ... CX6: =$BA6+CX$4 -> 47631
A7: =A12-7 -> 46115 | B7: =A7 -> 46115 | C7: =$B7+C$4 -> 46145.417 | D7: =$B7+D$4 -> 46175.833 | E7: =$B7+E$4 -> 46206.25 | F7: =$B7+F$4 -> 46236.667 | G7: =$B7+G$4 -> 46267.083 | H7: =$B7+H$4 -> 46297.5 | I7: =$B7+I$4 -> 46327.917 | J7: =$B7+J$4 -> 46358.333 | ... AX7: =$B7+AX$4 -> 47575 | BA7: =BA12-7 -> 46174 | BB7: =BA7 -> 46174 | BC7: =$BA7+BC$4 -> 46204.417 | BD7: =$BA7+BD$4 -> 46234.833 | BE7: =$BA7+BE$4 -> 46265.25 | BF7: =$BA7+BF$4 -> 46295.667 | BG7: =$BA7+BG$4 -> 46326.083 | BH7: =$BA7+BH$4 -> 46356.5 | BI7: =$BA7+BI$4 -> 46386.917 | BJ7: =$BA7+BJ$4 -> 46417.333 | ... CX7: =$BA7+CX$4 -> 47634
A8: =A13-7 -> 46118 | B8: =A8 -> 46118 | C8: =$B8+C$4 -> 46148.417 | D8: =$B8+D$4 -> 46178.833 | E8: =$B8+E$4 -> 46209.25 | F8: =$B8+F$4 -> 46239.667 | G8: =$B8+G$4 -> 46270.083 | H8: =$B8+H$4 -> 46300.5 | I8: =$B8+I$4 -> 46330.917 | J8: =$B8+J$4 -> 46361.333 | ... AX8: =$B8+AX$4 -> 47578 | BA8: =BA13-7 -> 46175 | BB8: =BA8 -> 46175 | BC8: =$BA8+BC$4 -> 46205.417 | BD8: =$BA8+BD$4 -> 46235.833 | BE8: =$BA8+BE$4 -> 46266.25 | BF8: =$BA8+BF$4 -> 46296.667 | BG8: =$BA8+BG$4 -> 46327.083 | BH8: =$BA8+BH$4 -> 46357.5 | BI8: =$BA8+BI$4 -> 46387.917 | BJ8: =$BA8+BJ$4 -> 46418.333 | ... CX8: =$BA8+CX$4 -> 47635
A9: =A14-7 -> 46119 | B9: =A9 -> 46119 | C9: =$B9+C$4 -> 46149.417 | D9: =$B9+D$4 -> 46179.833 | E9: =$B9+E$4 -> 46210.25 | F9: =$B9+F$4 -> 46240.667 | G9: =$B9+G$4 -> 46271.083 | H9: =$B9+H$4 -> 46301.5 | I9: =$B9+I$4 -> 46331.917 | J9: =$B9+J$4 -> 46362.333 | ... AX9: =$B9+AX$4 -> 47579 | BA9: =BA14-7 -> 46176 | BB9: =BA9 -> 46176 | BC9: =$BA9+BC$4 -> 46206.417 | BD9: =$BA9+BD$4 -> 46236.833 | BE9: =$BA9+BE$4 -> 46267.25 | BF9: =$BA9+BF$4 -> 46297.667 | BG9: =$BA9+BG$4 -> 46328.083 | BH9: =$BA9+BH$4 -> 46358.5 | BI9: =$BA9+BI$4 -> 46388.917 | BJ9: =$BA9+BJ$4 -> 46419.333 | ... CX9: =$BA9+CX$4 -> 47636
A10: =A15-7 -> 46120 | B10: =A10 -> 46120 | C10: =$B10+C$4 -> 46150.417 | D10: =$B10+D$4 -> 46180.833 | E10: =$B10+E$4 -> 46211.25 | F10: =$B10+F$4 -> 46241.667 | G10: =$B10+G$4 -> 46272.083 | H10: =$B10+H$4 -> 46302.5 | I10: =$B10+I$4 -> 46332.917 | J10: =$B10+J$4 -> 46363.333 | ... AX10: =$B10+AX$4 -> 47580 | BA10: =BA15-7 -> 46177 | BB10: =BA10 -> 46177 | BC10: =$BA10+BC$4 -> 46207.417 | BD10: =$BA10+BD$4 -> 46237.833 | BE10: =$BA10+BE$4 -> 46268.25 | BF10: =$BA10+BF$4 -> 46298.667 | BG10: =$BA10+BG$4 -> 46329.083 | BH10: =$BA10+BH$4 -> 46359.5 | BI10: =$BA10+BI$4 -> 46389.917 | BJ10: =$BA10+BJ$4 -> 46420.333 | ... CX10: =$BA10+CX$4 -> 47637
A11: =A16-7 -> 46121 | B11: =A11 -> 46121 | C11: =$B11+C$4 -> 46151.417 | D11: =$B11+D$4 -> 46181.833 | E11: =$B11+E$4 -> 46212.25 | F11: =$B11+F$4 -> 46242.667 | G11: =$B11+G$4 -> 46273.083 | H11: =$B11+H$4 -> 46303.5 | I11: =$B11+I$4 -> 46333.917 | J11: =$B11+J$4 -> 46364.333 | ... AX11: =$B11+AX$4 -> 47581 | BA11: =BA16-7 -> 46178 | BB11: =BA11 -> 46178 | BC11: =$BA11+BC$4 -> 46208.417 | BD11: =$BA11+BD$4 -> 46238.833 | BE11: =$BA11+BE$4 -> 46269.25 | BF11: =$BA11+BF$4 -> 46299.667 | BG11: =$BA11+BG$4 -> 46330.083 | BH11: =$BA11+BH$4 -> 46360.5 | BI11: =$BA11+BI$4 -> 46390.917 | BJ11: =$BA11+BJ$4 -> 46421.333 | ... CX11: =$BA11+CX$4 -> 47638
A12: =A17-7 -> 46122 | B12: =A12 -> 46122 | C12: =$B12+C$4 -> 46152.417 | D12: =$B12+D$4 -> 46182.833 | E12: =$B12+E$4 -> 46213.25 | F12: =$B12+F$4 -> 46243.667 | G12: =$B12+G$4 -> 46274.083 | H12: =$B12+H$4 -> 46304.5 | I12: =$B12+I$4 -> 46334.917 | J12: =$B12+J$4 -> 46365.333 | ... AX12: =$B12+AX$4 -> 47582 | BA12: =BA17-7 -> 46181 | BB12: =BA12 -> 46181 | BC12: =$BA12+BC$4 -> 46211.417 | BD12: =$BA12+BD$4 -> 46241.833 | BE12: =$BA12+BE$4 -> 46272.25 | BF12: =$BA12+BF$4 -> 46302.667 | BG12: =$BA12+BG$4 -> 46333.083 | BH12: =$BA12+BH$4 -> 46363.5 | BI12: =$BA12+BI$4 -> 46393.917 | BJ12: =$BA12+BJ$4 -> 46424.333 | ... CX12: =$BA12+CX$4 -> 47641
A13: =A18-7 -> 46125 | B13: =A13 -> 46125 | C13: =$B13+C$4 -> 46155.417 | D13: =$B13+D$4 -> 46185.833 | E13: =$B13+E$4 -> 46216.25 | F13: =$B13+F$4 -> 46246.667 | G13: =$B13+G$4 -> 46277.083 | H13: =$B13+H$4 -> 46307.5 | I13: =$B13+I$4 -> 46337.917 | J13: =$B13+J$4 -> 46368.333 | ... AX13: =$B13+AX$4 -> 47585 | BA13: =BA18-7 -> 46182 | BB13: =BA13 -> 46182 | BC13: =$BA13+BC$4 -> 46212.417 | BD13: =$BA13+BD$4 -> 46242.833 | BE13: =$BA13+BE$4 -> 46273.25 | BF13: =$BA13+BF$4 -> 46303.667 | BG13: =$BA13+BG$4 -> 46334.083 | BH13: =$BA13+BH$4 -> 46364.5 | BI13: =$BA13+BI$4 -> 46394.917 | BJ13: =$BA13+BJ$4 -> 46425.333 | ... CX13: =$BA13+CX$4 -> 47642
A14: =A19-7 -> 46126 | B14: =A14 -> 46126 | C14: =$B14+C$4 -> 46156.417 | D14: =$B14+D$4 -> 46186.833 | E14: =$B14+E$4 -> 46217.25 | F14: =$B14+F$4 -> 46247.667 | G14: =$B14+G$4 -> 46278.083 | H14: =$B14+H$4 -> 46308.5 | I14: =$B14+I$4 -> 46338.917 | J14: =$B14+J$4 -> 46369.333 | ... AX14: =$B14+AX$4 -> 47586 | BA14: =BA19-7 -> 46183 | BB14: =BA14 -> 46183 | BC14: =$BA14+BC$4 -> 46213.417 | BD14: =$BA14+BD$4 -> 46243.833 | BE14: =$BA14+BE$4 -> 46274.25 | BF14: =$BA14+BF$4 -> 46304.667 | BG14: =$BA14+BG$4 -> 46335.083 | BH14: =$BA14+BH$4 -> 46365.5 | BI14: =$BA14+BI$4 -> 46395.917 | BJ14: =$BA14+BJ$4 -> 46426.333 | ... CX14: =$BA14+CX$4 -> 47643
A15: =A20-7 -> 46127 | B15: =A15 -> 46127 | C15: =$B15+C$4 -> 46157.417 | D15: =$B15+D$4 -> 46187.833 | E15: =$B15+E$4 -> 46218.25 | F15: =$B15+F$4 -> 46248.667 | G15: =$B15+G$4 -> 46279.083 | H15: =$B15+H$4 -> 46309.5 | I15: =$B15+I$4 -> 46339.917 | J15: =$B15+J$4 -> 46370.333 | ... AX15: =$B15+AX$4 -> 47587 | BA15: =BA20-7 -> 46184 | BB15: =BA15 -> 46184 | BC15: =$BA15+BC$4 -> 46214.417 | BD15: =$BA15+BD$4 -> 46244.833 | BE15: =$BA15+BE$4 -> 46275.25 | BF15: =$BA15+BF$4 -> 46305.667 | BG15: =$BA15+BG$4 -> 46336.083 | BH15: =$BA15+BH$4 -> 46366.5 | BI15: =$BA15+BI$4 -> 46396.917 | BJ15: =$BA15+BJ$4 -> 46427.333 | ... CX15: =$BA15+CX$4 -> 47644
A16: ='Market pricing dates'!B5 -> 46128 | B16: =A16 -> 46128 | C16: =$B16+C$4 -> 46158.417 | D16: =$B16+D$4 -> 46188.833 | E16: =$B16+E$4 -> 46219.25 | F16: =$B16+F$4 -> 46249.667 | G16: =$B16+G$4 -> 46280.083 | H16: =$B16+H$4 -> 46310.5 | I16: =$B16+I$4 -> 46340.917 | J16: =$B16+J$4 -> 46371.333 | ... AX16: =$B16+AX$4 -> 47588 | BA16: ='Market pricing dates'!E5 -> 46185 | BB16: =BA16 -> 46185 | BC16: =$BA16+BC$4 -> 46215.417 | BD16: =$BA16+BD$4 -> 46245.833 | BE16: =$BA16+BE$4 -> 46276.25 | BF16: =$BA16+BF$4 -> 46306.667 | BG16: =$BA16+BG$4 -> 46337.083 | BH16: =$BA16+BH$4 -> 46367.5 | BI16: =$BA16+BI$4 -> 46397.917 | BJ16: =$BA16+BJ$4 -> 46428.333 | ... CX16: =$BA16+CX$4 -> 47645
A17: ='Market pricing dates'!B6 -> 46129 | B17: =A17 -> 46129 | C17: =$B17+C$4 -> 46159.417 | D17: =$B17+D$4 -> 46189.833 | E17: =$B17+E$4 -> 46220.25 | F17: =$B17+F$4 -> 46250.667 | G17: =$B17+G$4 -> 46281.083 | H17: =$B17+H$4 -> 46311.5 | I17: =$B17+I$4 -> 46341.917 | J17: =$B17+J$4 -> 46372.333 | ... AX17: =$B17+AX$4 -> 47589 | BA17: ='Market pricing dates'!E6 -> 46188 | BB17: =BA17 -> 46188 | BC17: =$BA17+BC$4 -> 46218.417 | BD17: =$BA17+BD$4 -> 46248.833 | BE17: =$BA17+BE$4 -> 46279.25 | BF17: =$BA17+BF$4 -> 46309.667 | BG17: =$BA17+BG$4 -> 46340.083 | BH17: =$BA17+BH$4 -> 46370.5 | BI17: =$BA17+BI$4 -> 46400.917 | BJ17: =$BA17+BJ$4 -> 46431.333 | ... CX17: =$BA17+CX$4 -> 47648
A18: ='Market pricing dates'!B7 -> 46132 | B18: =A18 -> 46132 | C18: =$B18+C$4 -> 46162.417 | D18: =$B18+D$4 -> 46192.833 | E18: =$B18+E$4 -> 46223.25 | F18: =$B18+F$4 -> 46253.667 | G18: =$B18+G$4 -> 46284.083 | H18: =$B18+H$4 -> 46314.5 | I18: =$B18+I$4 -> 46344.917 | J18: =$B18+J$4 -> 46375.333 | ... AX18: =$B18+AX$4 -> 47592 | BA18: ='Market pricing dates'!E7 -> 46189 | BB18: =BA18 -> 46189 | BC18: =$BA18+BC$4 -> 46219.417 | BD18: =$BA18+BD$4 -> 46249.833 | BE18: =$BA18+BE$4 -> 46280.25 | BF18: =$BA18+BF$4 -> 46310.667 | BG18: =$BA18+BG$4 -> 46341.083 | BH18: =$BA18+BH$4 -> 46371.5 | BI18: =$BA18+BI$4 -> 46401.917 | BJ18: =$BA18+BJ$4 -> 46432.333 | ... CX18: =$BA18+CX$4 -> 47649
A19: ='Market pricing dates'!B8 -> 46133 | B19: =A19 -> 46133 | C19: =$B19+C$4 -> 46163.417 | D19: =$B19+D$4 -> 46193.833 | E19: =$B19+E$4 -> 46224.25 | F19: =$B19+F$4 -> 46254.667 | G19: =$B19+G$4 -> 46285.083 | H19: =$B19+H$4 -> 46315.5 | I19: =$B19+I$4 -> 46345.917 | J19: =$B19+J$4 -> 46376.333 | ... AX19: =$B19+AX$4 -> 47593 | BA19: ='Market pricing dates'!E8 -> 46190 | BB19: =BA19 -> 46190 | BC19: =$BA19+BC$4 -> 46220.417 | BD19: =$BA19+BD$4 -> 46250.833 | BE19: =$BA19+BE$4 -> 46281.25 | BF19: =$BA19+BF$4 -> 46311.667 | BG19: =$BA19+BG$4 -> 46342.083 | BH19: =$BA19+BH$4 -> 46372.5 | BI19: =$BA19+BI$4 -> 46402.917 | BJ19: =$BA19+BJ$4 -> 46433.333 | ... CX19: =$BA19+CX$4 -> 47650
A20: ='Market pricing dates'!B9 -> 46134 | B20: =A20 -> 46134 | C20: =$B20+C$4 -> 46164.417 | D20: =$B20+D$4 -> 46194.833 | E20: =$B20+E$4 -> 46225.25 | F20: =$B20+F$4 -> 46255.667 | G20: =$B20+G$4 -> 46286.083 | H20: =$B20+H$4 -> 46316.5 | I20: =$B20+I$4 -> 46346.917 | J20: =$B20+J$4 -> 46377.333 | ... AX20: =$B20+AX$4 -> 47594 | BA20: ='Market pricing dates'!E9 -> 46191 | BB20: =BA20 -> 46191 | BC20: =$BA20+BC$4 -> 46221.417 | BD20: =$BA20+BD$4 -> 46251.833 | BE20: =$BA20+BE$4 -> 46282.25 | BF20: =$BA20+BF$4 -> 46312.667 | BG20: =$BA20+BG$4 -> 46343.083 | BH20: =$BA20+BH$4 -> 46373.5 | BI20: =$BA20+BI$4 -> 46403.917 | BJ20: =$BA20+BJ$4 -> 46434.333 | ... CX20: =$BA20+CX$4 -> 47651
A22: Market expectations | BA22: Market expectations
A23: =A6 -> 46114 | B23: =VLOOKUP($A23,HAVERD!$A:$BS,B$2,FALSE) -> 3.73 | C23: =VLOOKUP($A23,HAVERD!$A:$BS,C$2,FALSE) -> 3.753596 | D23: =VLOOKUP($A23,HAVERD!$A:$BS,D$2,FALSE) -> 3.8469902 | E23: =VLOOKUP($A23,HAVERD!$A:$BS,E$2,FALSE) -> 3.9435361 | F23: =VLOOKUP($A23,HAVERD!$A:$BS,F$2,FALSE) -> 4.0349473 | G23: =VLOOKUP($A23,HAVERD!$A:$BS,G$2,FALSE) -> 4.1107531 | H23: =VLOOKUP($A23,HAVERD!$A:$BS,H$2,FALSE) -> 4.1657421 | I23: =VLOOKUP($A23,HAVERD!$A:$BS,I$2,FALSE) -> 4.2050498 | ... AX23: =VLOOKUP($A23,HAVERD!$A:$BS,AX$2,FALSE) -> 4.0545917 | BA23: =BA6 -> 46171 | BB23: =_xlfn.IFNA(VLOOKUP($BA23,HAVERD!$A:$BS,BB$2,FALSE),"") -> 3.7302 | BC23: =_xlfn.IFNA(VLOOKUP($BA23,HAVERD!$A:$BS,BC$2,FALSE),"") -> 3.7243672 | BD23: =_xlfn.IFNA(VLOOKUP($BA23,HAVERD!$A:$BS,BD$2,FALSE),"") -> 3.7749219 | BE23: =_xlfn.IFNA(VLOOKUP($BA23,HAVERD!$A:$BS,BE$2,FALSE),"") -> 3.8312141 | BF23: =_xlfn.IFNA(VLOOKUP($BA23,HAVERD!$A:$BS,BF$2,FALSE),"") -> 3.8889022 | BG23: =_xlfn.IFNA(VLOOKUP($BA23,HAVERD!$A:$BS,BG$2,FALSE),"") -> 3.943111 | BH23: =_xlfn.IFNA(VLOOKUP($BA23,HAVERD!$A:$BS,BH$2,FALSE),"") -> 3.9896254 | BI23: =_xlfn.IFNA(VLOOKUP($BA23,HAVERD!$A:$BS,BI$2,FALSE),"") -> 4.0277688 | ... CX23: =_xlfn.IFNA(VLOOKUP($BA23,HAVERD!$A:$BS,CX$2,FALSE),"") -> 4.1525559
A24: =A7 -> 46115 | B24: =VLOOKUP($A24,HAVERD!$A:$BS,B$2,FALSE) -> #N/A | C24: =VLOOKUP($A24,HAVERD!$A:$BS,C$2,FALSE) -> #N/A | D24: =VLOOKUP($A24,HAVERD!$A:$BS,D$2,FALSE) -> #N/A | E24: =VLOOKUP($A24,HAVERD!$A:$BS,E$2,FALSE) -> #N/A | F24: =VLOOKUP($A24,HAVERD!$A:$BS,F$2,FALSE) -> #N/A | G24: =VLOOKUP($A24,HAVERD!$A:$BS,G$2,FALSE) -> #N/A | H24: =VLOOKUP($A24,HAVERD!$A:$BS,H$2,FALSE) -> #N/A | I24: =VLOOKUP($A24,HAVERD!$A:$BS,I$2,FALSE) -> #N/A | ... AX24: =VLOOKUP($A24,HAVERD!$A:$BS,AX$2,FALSE) -> #N/A | BA24: =BA7 -> 46174 | BB24: =_xlfn.IFNA(VLOOKUP($BA24,HAVERD!$A:$BS,BB$2,FALSE),"") -> 3.7291 | BC24: =_xlfn.IFNA(VLOOKUP($BA24,HAVERD!$A:$BS,BC$2,FALSE),"") -> 3.7269077 | BD24: =_xlfn.IFNA(VLOOKUP($BA24,HAVERD!$A:$BS,BD$2,FALSE),"") -> 3.7962168 | BE24: =_xlfn.IFNA(VLOOKUP($BA24,HAVERD!$A:$BS,BE$2,FALSE),"") -> 3.8711315 | BF24: =_xlfn.IFNA(VLOOKUP($BA24,HAVERD!$A:$BS,BF$2,FALSE),"") -> 3.9489032 | BG24: =_xlfn.IFNA(VLOOKUP($BA24,HAVERD!$A:$BS,BG$2,FALSE),"") -> 4.0255473 | BH24: =_xlfn.IFNA(VLOOKUP($BA24,HAVERD!$A:$BS,BH$2,FALSE),"") -> 4.0943756 | BI24: =_xlfn.IFNA(VLOOKUP($BA24,HAVERD!$A:$BS,BI$2,FALSE),"") -> 4.1529887 | ... CX24: =_xlfn.IFNA(VLOOKUP($BA24,HAVERD!$A:$BS,CX$2,FALSE),"") -> 4.1730915
A25: =A8 -> 46118 | B25: =VLOOKUP($A25,HAVERD!$A:$BS,B$2,FALSE) -> #N/A | C25: =VLOOKUP($A25,HAVERD!$A:$BS,C$2,FALSE) -> #N/A | D25: =VLOOKUP($A25,HAVERD!$A:$BS,D$2,FALSE) -> #N/A | E25: =VLOOKUP($A25,HAVERD!$A:$BS,E$2,FALSE) -> #N/A | F25: =VLOOKUP($A25,HAVERD!$A:$BS,F$2,FALSE) -> #N/A | G25: =VLOOKUP($A25,HAVERD!$A:$BS,G$2,FALSE) -> #N/A | H25: =VLOOKUP($A25,HAVERD!$A:$BS,H$2,FALSE) -> #N/A | I25: =VLOOKUP($A25,HAVERD!$A:$BS,I$2,FALSE) -> #N/A | ... AX25: =VLOOKUP($A25,HAVERD!$A:$BS,AX$2,FALSE) -> #N/A | BA25: =BA8 -> 46175 | BB25: =_xlfn.IFNA(VLOOKUP($BA25,HAVERD!$A:$BS,BB$2,FALSE),"") -> 3.7308 | BC25: =_xlfn.IFNA(VLOOKUP($BA25,HAVERD!$A:$BS,BC$2,FALSE),"") -> 3.7471876 | BD25: =_xlfn.IFNA(VLOOKUP($BA25,HAVERD!$A:$BS,BD$2,FALSE),"") -> 3.8232402 | BE25: =_xlfn.IFNA(VLOOKUP($BA25,HAVERD!$A:$BS,BE$2,FALSE),"") -> 3.9025245 | BF25: =_xlfn.IFNA(VLOOKUP($BA25,HAVERD!$A:$BS,BF$2,FALSE),"") -> 3.9810069 | BG25: =_xlfn.IFNA(VLOOKUP($BA25,HAVERD!$A:$BS,BG$2,FALSE),"") -> 4.0551904 | BH25: =_xlfn.IFNA(VLOOKUP($BA25,HAVERD!$A:$BS,BH$2,FALSE),"") -> 4.1202376 | BI25: =_xlfn.IFNA(VLOOKUP($BA25,HAVERD!$A:$BS,BI$2,FALSE),"") -> 4.1750159 | ... CX25: =_xlfn.IFNA(VLOOKUP($BA25,HAVERD!$A:$BS,CX$2,FALSE),"") -> 4.1599836
A26: =A9 -> 46119 | B26: =VLOOKUP($A26,HAVERD!$A:$BS,B$2,FALSE) -> 3.7294 | C26: =VLOOKUP($A26,HAVERD!$A:$BS,C$2,FALSE) -> 3.776504 | D26: =VLOOKUP($A26,HAVERD!$A:$BS,D$2,FALSE) -> 3.8867149 | E26: =VLOOKUP($A26,HAVERD!$A:$BS,E$2,FALSE) -> 3.9978867 | F26: =VLOOKUP($A26,HAVERD!$A:$BS,F$2,FALSE) -> 4.1000884 | G26: =VLOOKUP($A26,HAVERD!$A:$BS,G$2,FALSE) -> 4.1832075 | H26: =VLOOKUP($A26,HAVERD!$A:$BS,H$2,FALSE) -> 4.2431025 | I26: =VLOOKUP($A26,HAVERD!$A:$BS,I$2,FALSE) -> 4.2850013 | ... AX26: =VLOOKUP($A26,HAVERD!$A:$BS,AX$2,FALSE) -> 4.0950511 | BA26: =BA9 -> 46176 | BB26: =_xlfn.IFNA(VLOOKUP($BA26,HAVERD!$A:$BS,BB$2,FALSE),"") -> 3.7306 | BC26: =_xlfn.IFNA(VLOOKUP($BA26,HAVERD!$A:$BS,BC$2,FALSE),"") -> 3.7352615 | BD26: =_xlfn.IFNA(VLOOKUP($BA26,HAVERD!$A:$BS,BD$2,FALSE),"") -> 3.8189074 | BE26: =_xlfn.IFNA(VLOOKUP($BA26,HAVERD!$A:$BS,BE$2,FALSE),"") -> 3.9058851 | BF26: =_xlfn.IFNA(VLOOKUP($BA26,HAVERD!$A:$BS,BF$2,FALSE),"") -> 3.9920061 | BG26: =_xlfn.IFNA(VLOOKUP($BA26,HAVERD!$A:$BS,BG$2,FALSE),"") -> 4.0733447 | BH26: =_xlfn.IFNA(VLOOKUP($BA26,HAVERD!$A:$BS,BH$2,FALSE),"") -> 4.1445301 | BI26: =_xlfn.IFNA(VLOOKUP($BA26,HAVERD!$A:$BS,BI$2,FALSE),"") -> 4.2046457 | ... CX26: =_xlfn.IFNA(VLOOKUP($BA26,HAVERD!$A:$BS,CX$2,FALSE),"") -> 4.2353862
A27: =A10 -> 46120 | B27: =VLOOKUP($A27,HAVERD!$A:$BS,B$2,FALSE) -> 3.7287 | C27: =VLOOKUP($A27,HAVERD!$A:$BS,C$2,FALSE) -> 3.7402463 | D27: =VLOOKUP($A27,HAVERD!$A:$BS,D$2,FALSE) -> 3.8095213 | E27: =VLOOKUP($A27,HAVERD!$A:$BS,E$2,FALSE) -> 3.8771332 | F27: =VLOOKUP($A27,HAVERD!$A:$BS,F$2,FALSE) -> 3.9363881 | G27: =VLOOKUP($A27,HAVERD!$A:$BS,G$2,FALSE) -> 3.9822784 | H27: =VLOOKUP($A27,HAVERD!$A:$BS,H$2,FALSE) -> 4.0134826 | I27: =VLOOKUP($A27,HAVERD!$A:$BS,I$2,FALSE) -> 4.0343722 | ... AX27: =VLOOKUP($A27,HAVERD!$A:$BS,AX$2,FALSE) -> 3.9784106 | BA27: =BA10 -> 46177 | BB27: =_xlfn.IFNA(VLOOKUP($BA27,HAVERD!$A:$BS,BB$2,FALSE),"") -> 3.7308 | BC27: =_xlfn.IFNA(VLOOKUP($BA27,HAVERD!$A:$BS,BC$2,FALSE),"") -> 3.7353573 | BD27: =_xlfn.IFNA(VLOOKUP($BA27,HAVERD!$A:$BS,BD$2,FALSE),"") -> 3.8070084 | BE27: =_xlfn.IFNA(VLOOKUP($BA27,HAVERD!$A:$BS,BE$2,FALSE),"") -> 3.8816702 | BF27: =_xlfn.IFNA(VLOOKUP($BA27,HAVERD!$A:$BS,BF$2,FALSE),"") -> 3.956035 | BG27: =_xlfn.IFNA(VLOOKUP($BA27,HAVERD!$A:$BS,BG$2,FALSE),"") -> 4.0268347 | BH27: =_xlfn.IFNA(VLOOKUP($BA27,HAVERD!$A:$BS,BH$2,FALSE),"") -> 4.0893185 | BI27: =_xlfn.IFNA(VLOOKUP($BA27,HAVERD!$A:$BS,BI$2,FALSE),"") -> 4.1425209 | ... CX27: =_xlfn.IFNA(VLOOKUP($BA27,HAVERD!$A:$BS,CX$2,FALSE),"") -> 4.2138887
A28: =A11 -> 46121 | B28: =VLOOKUP($A28,HAVERD!$A:$BS,B$2,FALSE) -> 3.7294 | C28: =VLOOKUP($A28,HAVERD!$A:$BS,C$2,FALSE) -> 3.7487877 | D28: =VLOOKUP($A28,HAVERD!$A:$BS,D$2,FALSE) -> 3.811008 | E28: =VLOOKUP($A28,HAVERD!$A:$BS,E$2,FALSE) -> 3.8765784 | F28: =VLOOKUP($A28,HAVERD!$A:$BS,F$2,FALSE) -> 3.9370481 | G28: =VLOOKUP($A28,HAVERD!$A:$BS,G$2,FALSE) -> 3.985479 | H28: =VLOOKUP($A28,HAVERD!$A:$BS,H$2,FALSE) -> 4.0194081 | I28: =VLOOKUP($A28,HAVERD!$A:$BS,I$2,FALSE) -> 4.0426574 | ... AX28: =VLOOKUP($A28,HAVERD!$A:$BS,AX$2,FALSE) -> 4.0423239 | BA28: =BA11 -> 46178 | BB28: =_xlfn.IFNA(VLOOKUP($BA28,HAVERD!$A:$BS,BB$2,FALSE),"") -> 3.7312 | BC28: =_xlfn.IFNA(VLOOKUP($BA28,HAVERD!$A:$BS,BC$2,FALSE),"") -> 3.7290185 | BD28: =_xlfn.IFNA(VLOOKUP($BA28,HAVERD!$A:$BS,BD$2,FALSE),"") -> 3.8007483 | BE28: =_xlfn.IFNA(VLOOKUP($BA28,HAVERD!$A:$BS,BE$2,FALSE),"") -> 3.8776733 | BF28: =_xlfn.IFNA(VLOOKUP($BA28,HAVERD!$A:$BS,BF$2,FALSE),"") -> 3.9566784 | BG28: =_xlfn.IFNA(VLOOKUP($BA28,HAVERD!$A:$BS,BG$2,FALSE),"") -> 4.0331583 | BH28: =_xlfn.IFNA(VLOOKUP($BA28,HAVERD!$A:$BS,BH$2,FALSE),"") -> 4.1013572 | BI28: =_xlfn.IFNA(VLOOKUP($BA28,HAVERD!$A:$BS,BI$2,FALSE),"") -> 4.1588616 | ... CX28: =_xlfn.IFNA(VLOOKUP($BA28,HAVERD!$A:$BS,CX$2,FALSE),"") -> 4.1971503
A29: =A12 -> 46122 | B29: =VLOOKUP($A29,HAVERD!$A:$BS,B$2,FALSE) -> 3.7295 | C29: =VLOOKUP($A29,HAVERD!$A:$BS,C$2,FALSE) -> 3.7502304 | D29: =VLOOKUP($A29,HAVERD!$A:$BS,D$2,FALSE) -> 3.830629 | E29: =VLOOKUP($A29,HAVERD!$A:$BS,E$2,FALSE) -> 3.9132973 | F29: =VLOOKUP($A29,HAVERD!$A:$BS,F$2,FALSE) -> 3.9903314 | G29: =VLOOKUP($A29,HAVERD!$A:$BS,G$2,FALSE) -> 4.0546617 | H29: =VLOOKUP($A29,HAVERD!$A:$BS,H$2,FALSE) -> 4.103157 | I29: =VLOOKUP($A29,HAVERD!$A:$BS,I$2,FALSE) -> 4.1378236 | ... AX29: =VLOOKUP($A29,HAVERD!$A:$BS,AX$2,FALSE) -> 4.1206281 | BA29: =BA12 -> 46181 | BB29: =_xlfn.IFNA(VLOOKUP($BA29,HAVERD!$A:$BS,BB$2,FALSE),"") -> 3.73 | BC29: =_xlfn.IFNA(VLOOKUP($BA29,HAVERD!$A:$BS,BC$2,FALSE),"") -> 3.7428238 | BD29: =_xlfn.IFNA(VLOOKUP($BA29,HAVERD!$A:$BS,BD$2,FALSE),"") -> 3.8224712 | BE29: =_xlfn.IFNA(VLOOKUP($BA29,HAVERD!$A:$BS,BE$2,FALSE),"") -> 3.9089257 | BF29: =_xlfn.IFNA(VLOOKUP($BA29,HAVERD!$A:$BS,BF$2,FALSE),"") -> 3.9978099 | BG29: =_xlfn.IFNA(VLOOKUP($BA29,HAVERD!$A:$BS,BG$2,FALSE),"") -> 4.0822041 | BH29: =_xlfn.IFNA(VLOOKUP($BA29,HAVERD!$A:$BS,BH$2,FALSE),"") -> 4.1553974 | BI29: =_xlfn.IFNA(VLOOKUP($BA29,HAVERD!$A:$BS,BI$2,FALSE),"") -> 4.2169744 | ... CX29: =_xlfn.IFNA(VLOOKUP($BA29,HAVERD!$A:$BS,CX$2,FALSE),"") -> 4.2555311
A30: =A13 -> 46125 | B30: =VLOOKUP($A30,HAVERD!$A:$BS,B$2,FALSE) -> 3.729 | C30: =VLOOKUP($A30,HAVERD!$A:$BS,C$2,FALSE) -> 3.7481536 | D30: =VLOOKUP($A30,HAVERD!$A:$BS,D$2,FALSE) -> 3.8370223 | E30: =VLOOKUP($A30,HAVERD!$A:$BS,E$2,FALSE) -> 3.9245377 | F30: =VLOOKUP($A30,HAVERD!$A:$BS,F$2,FALSE) -> 4.0031863 | G30: =VLOOKUP($A30,HAVERD!$A:$BS,G$2,FALSE) -> 4.0679999 | H30: =VLOOKUP($A30,HAVERD!$A:$BS,H$2,FALSE) -> 4.1168948 | I30: =VLOOKUP($A30,HAVERD!$A:$BS,I$2,FALSE) -> 4.1529051 | ... AX30: =VLOOKUP($A30,HAVERD!$A:$BS,AX$2,FALSE) -> 4.0898479 | BA30: =BA13 -> 46182 | BB30: =_xlfn.IFNA(VLOOKUP($BA30,HAVERD!$A:$BS,BB$2,FALSE),"") -> 3.7271 | BC30: =_xlfn.IFNA(VLOOKUP($BA30,HAVERD!$A:$BS,BC$2,FALSE),"") -> 3.7368599 | BD30: =_xlfn.IFNA(VLOOKUP($BA30,HAVERD!$A:$BS,BD$2,FALSE),"") -> 3.8179602 | BE30: =_xlfn.IFNA(VLOOKUP($BA30,HAVERD!$A:$BS,BE$2,FALSE),"") -> 3.9003138 | BF30: =_xlfn.IFNA(VLOOKUP($BA30,HAVERD!$A:$BS,BF$2,FALSE),"") -> 3.9822958 | BG30: =_xlfn.IFNA(VLOOKUP($BA30,HAVERD!$A:$BS,BG$2,FALSE),"") -> 4.0596042 | BH30: =_xlfn.IFNA(VLOOKUP($BA30,HAVERD!$A:$BS,BH$2,FALSE),"") -> 4.1271486 | BI30: =_xlfn.IFNA(VLOOKUP($BA30,HAVERD!$A:$BS,BI$2,FALSE),"") -> 4.1841679 | ... CX30: =_xlfn.IFNA(VLOOKUP($BA30,HAVERD!$A:$BS,CX$2,FALSE),"") -> 4.2316097
A31: =A14 -> 46126 | B31: =VLOOKUP($A31,HAVERD!$A:$BS,B$2,FALSE) -> 3.7293 | C31: =VLOOKUP($A31,HAVERD!$A:$BS,C$2,FALSE) -> 3.7358759 | D31: =VLOOKUP($A31,HAVERD!$A:$BS,D$2,FALSE) -> 3.8031379 | E31: =VLOOKUP($A31,HAVERD!$A:$BS,E$2,FALSE) -> 3.8711445 | F31: =VLOOKUP($A31,HAVERD!$A:$BS,F$2,FALSE) -> 3.9338191 | G31: =VLOOKUP($A31,HAVERD!$A:$BS,G$2,FALSE) -> 3.9861966 | H31: =VLOOKUP($A31,HAVERD!$A:$BS,H$2,FALSE) -> 4.0254154 | I31: =VLOOKUP($A31,HAVERD!$A:$BS,I$2,FALSE) -> 4.0534884 | ... AX31: =VLOOKUP($A31,HAVERD!$A:$BS,AX$2,FALSE) -> 4.0330978 | BA31: =BA14 -> 46183 | BB31: =_xlfn.IFNA(VLOOKUP($BA31,HAVERD!$A:$BS,BB$2,FALSE),"") -> 3.7296 | BC31: =_xlfn.IFNA(VLOOKUP($BA31,HAVERD!$A:$BS,BC$2,FALSE),"") -> 3.7446605 | BD31: =_xlfn.IFNA(VLOOKUP($BA31,HAVERD!$A:$BS,BD$2,FALSE),"") -> 3.8247854 | BE31: =_xlfn.IFNA(VLOOKUP($BA31,HAVERD!$A:$BS,BE$2,FALSE),"") -> 3.9106343 | BF31: =_xlfn.IFNA(VLOOKUP($BA31,HAVERD!$A:$BS,BF$2,FALSE),"") -> 3.9984229 | BG31: =_xlfn.IFNA(VLOOKUP($BA31,HAVERD!$A:$BS,BG$2,FALSE),"") -> 4.0819715 | BH31: =_xlfn.IFNA(VLOOKUP($BA31,HAVERD!$A:$BS,BH$2,FALSE),"") -> 4.1549832 | BI31: =_xlfn.IFNA(VLOOKUP($BA31,HAVERD!$A:$BS,BI$2,FALSE),"") -> 4.2166663 | ... CX31: =_xlfn.IFNA(VLOOKUP($BA31,HAVERD!$A:$BS,CX$2,FALSE),"") -> 4.2737163
A32: =A15 -> 46127 | B32: =VLOOKUP($A32,HAVERD!$A:$BS,B$2,FALSE) -> 3.7301 | C32: =VLOOKUP($A32,HAVERD!$A:$BS,C$2,FALSE) -> 3.7369514 | D32: =VLOOKUP($A32,HAVERD!$A:$BS,D$2,FALSE) -> 3.8144355 | E32: =VLOOKUP($A32,HAVERD!$A:$BS,E$2,FALSE) -> 3.8916902 | F32: =VLOOKUP($A32,HAVERD!$A:$BS,F$2,FALSE) -> 3.9615144 | G32: =VLOOKUP($A32,HAVERD!$A:$BS,G$2,FALSE) -> 4.0188087 | H32: =VLOOKUP($A32,HAVERD!$A:$BS,H$2,FALSE) -> 4.060609 | I32: =VLOOKUP($A32,HAVERD!$A:$BS,I$2,FALSE) -> 4.0900153 | ... AX32: =VLOOKUP($A32,HAVERD!$A:$BS,AX$2,FALSE) -> 4.0897155 | BA32: =BA15 -> 46184 | BB32: =_xlfn.IFNA(VLOOKUP($BA32,HAVERD!$A:$BS,BB$2,FALSE),"") -> 3.7305 | BC32: =_xlfn.IFNA(VLOOKUP($BA32,HAVERD!$A:$BS,BC$2,FALSE),"") -> 3.7443846 | BD32: =_xlfn.IFNA(VLOOKUP($BA32,HAVERD!$A:$BS,BD$2,FALSE),"") -> 3.8200067 | BE32: =_xlfn.IFNA(VLOOKUP($BA32,HAVERD!$A:$BS,BE$2,FALSE),"") -> 3.8992982 | BF32: =_xlfn.IFNA(VLOOKUP($BA32,HAVERD!$A:$BS,BF$2,FALSE),"") -> 3.9800015 | BG32: =_xlfn.IFNA(VLOOKUP($BA32,HAVERD!$A:$BS,BG$2,FALSE),"") -> 4.0575952 | BH32: =_xlfn.IFNA(VLOOKUP($BA32,HAVERD!$A:$BS,BH$2,FALSE),"") -> 4.1269763 | BI32: =_xlfn.IFNA(VLOOKUP($BA32,HAVERD!$A:$BS,BI$2,FALSE),"") -> 4.1870788 | ... CX32: =_xlfn.IFNA(VLOOKUP($BA32,HAVERD!$A:$BS,CX$2,FALSE),"") -> 4.2422921
A33: =A16 -> 46128 | B33: =VLOOKUP($A33,HAVERD!$A:$BS,B$2,FALSE) -> 3.7301 | C33: =VLOOKUP($A33,HAVERD!$A:$BS,C$2,FALSE) -> 3.7265955 | D33: =VLOOKUP($A33,HAVERD!$A:$BS,D$2,FALSE) -> 3.7954942 | E33: =VLOOKUP($A33,HAVERD!$A:$BS,E$2,FALSE) -> 3.8670279 | F33: =VLOOKUP($A33,HAVERD!$A:$BS,F$2,FALSE) -> 3.9349254 | G33: =VLOOKUP($A33,HAVERD!$A:$BS,G$2,FALSE) -> 3.9935864 | H33: =VLOOKUP($A33,HAVERD!$A:$BS,H$2,FALSE) -> 4.0383784 | I33: =VLOOKUP($A33,HAVERD!$A:$BS,I$2,FALSE) -> 4.0707072 | ... AX33: =VLOOKUP($A33,HAVERD!$A:$BS,AX$2,FALSE) -> 4.1356946 | BA33: =BA16 -> 46185 | BB33: =_xlfn.IFNA(VLOOKUP($BA33,HAVERD!$A:$BS,BB$2,FALSE),"") -> 3.7301 | BC33: =_xlfn.IFNA(VLOOKUP($BA33,HAVERD!$A:$BS,BC$2,FALSE),"") -> 3.7380222 | BD33: =_xlfn.IFNA(VLOOKUP($BA33,HAVERD!$A:$BS,BD$2,FALSE),"") -> 3.7882469 | BE33: =_xlfn.IFNA(VLOOKUP($BA33,HAVERD!$A:$BS,BE$2,FALSE),"") -> 3.8427507 | BF33: =_xlfn.IFNA(VLOOKUP($BA33,HAVERD!$A:$BS,BF$2,FALSE),"") -> 3.9008583 | BG33: =_xlfn.IFNA(VLOOKUP($BA33,HAVERD!$A:$BS,BG$2,FALSE),"") -> 3.9590341 | BH33: =_xlfn.IFNA(VLOOKUP($BA33,HAVERD!$A:$BS,BH$2,FALSE),"") -> 4.0123088 | BI33: =_xlfn.IFNA(VLOOKUP($BA33,HAVERD!$A:$BS,BI$2,FALSE),"") -> 4.0579865 | ... CX33: =_xlfn.IFNA(VLOOKUP($BA33,HAVERD!$A:$BS,CX$2,FALSE),"") -> 4.1855202
A34: =A17 -> 46129 | B34: =VLOOKUP($A34,HAVERD!$A:$BS,B$2,FALSE) -> 3.73 | C34: =VLOOKUP($A34,HAVERD!$A:$BS,C$2,FALSE) -> 3.7258284 | D34: =VLOOKUP($A34,HAVERD!$A:$BS,D$2,FALSE) -> 3.7756703 | E34: =VLOOKUP($A34,HAVERD!$A:$BS,E$2,FALSE) -> 3.8267915 | F34: =VLOOKUP($A34,HAVERD!$A:$BS,F$2,FALSE) -> 3.8741249 | G34: =VLOOKUP($A34,HAVERD!$A:$BS,G$2,FALSE) -> 3.9129916 | H34: =VLOOKUP($A34,HAVERD!$A:$BS,H$2,FALSE) -> 3.940405 | I34: =VLOOKUP($A34,HAVERD!$A:$BS,I$2,FALSE) -> 3.9573621 | ... AX34: =VLOOKUP($A34,HAVERD!$A:$BS,AX$2,FALSE) -> 4.037443 | BA34: =BA17 -> 46188 | BB34: =_xlfn.IFNA(VLOOKUP($BA34,HAVERD!$A:$BS,BB$2,FALSE),"") -> 3.7296 | BC34: =_xlfn.IFNA(VLOOKUP($BA34,HAVERD!$A:$BS,BC$2,FALSE),"") -> 3.7425937 | BD34: =_xlfn.IFNA(VLOOKUP($BA34,HAVERD!$A:$BS,BD$2,FALSE),"") -> 3.7901022 | BE34: =_xlfn.IFNA(VLOOKUP($BA34,HAVERD!$A:$BS,BE$2,FALSE),"") -> 3.8404664 | BF34: =_xlfn.IFNA(VLOOKUP($BA34,HAVERD!$A:$BS,BF$2,FALSE),"") -> 3.892434 | BG34: =_xlfn.IFNA(VLOOKUP($BA34,HAVERD!$A:$BS,BG$2,FALSE),"") -> 3.9423885 | BH34: =_xlfn.IFNA(VLOOKUP($BA34,HAVERD!$A:$BS,BH$2,FALSE),"") -> 3.9865195 | BI34: =_xlfn.IFNA(VLOOKUP($BA34,HAVERD!$A:$BS,BI$2,FALSE),"") -> 4.0241474 | ... CX34: =_xlfn.IFNA(VLOOKUP($BA34,HAVERD!$A:$BS,CX$2,FALSE),"") -> 4.1586547
... A37: =A20 -> 46134 | B37: =VLOOKUP($A37,HAVERD!$A:$BS,B$2,FALSE) -> 3.7304 | C37: =VLOOKUP($A37,HAVERD!$A:$BS,C$2,FALSE) -> 3.7335917 | D37: =VLOOKUP($A37,HAVERD!$A:$BS,D$2,FALSE) -> 3.837642 | E37: =VLOOKUP($A37,HAVERD!$A:$BS,E$2,FALSE) -> 3.9403256 | F37: =VLOOKUP($A37,HAVERD!$A:$BS,F$2,FALSE) -> 4.0325264 | G37: =VLOOKUP($A37,HAVERD!$A:$BS,G$2,FALSE) -> 4.108257 | H37: =VLOOKUP($A37,HAVERD!$A:$BS,H$2,FALSE) -> 4.1645157 | I37: =VLOOKUP($A37,HAVERD!$A:$BS,I$2,FALSE) -> 4.2049943 | ... AX37: =VLOOKUP($A37,HAVERD!$A:$BS,AX$2,FALSE) -> 4.1491665 | BA37: =BA20 -> 46191 | BB37: =_xlfn.IFNA(VLOOKUP($BA37,HAVERD!$A:$BS,BB$2,FALSE),"") -> 3.7303 | BC37: =_xlfn.IFNA(VLOOKUP($BA37,HAVERD!$A:$BS,BC$2,FALSE),"") -> 3.7843215 | BD37: =_xlfn.IFNA(VLOOKUP($BA37,HAVERD!$A:$BS,BD$2,FALSE),"") -> 3.8144992 | BE37: =_xlfn.IFNA(VLOOKUP($BA37,HAVERD!$A:$BS,BE$2,FALSE),"") -> 3.831662 | BF37: =_xlfn.IFNA(VLOOKUP($BA37,HAVERD!$A:$BS,BF$2,FALSE),"") -> 3.8526144 | BG37: =_xlfn.IFNA(VLOOKUP($BA37,HAVERD!$A:$BS,BG$2,FALSE),"") -> 3.8943094 | BH37: =_xlfn.IFNA(VLOOKUP($BA37,HAVERD!$A:$BS,BH$2,FALSE),"") -> 3.9492534 | BI37: =_xlfn.IFNA(VLOOKUP($BA37,HAVERD!$A:$BS,BI$2,FALSE),"") -> 4.0036593 | ... CX37: =_xlfn.IFNA(VLOOKUP($BA37,HAVERD!$A:$BS,CX$2,FALSE),"") -> 4.0937068
A39: Average | BA39: Average
A40: Month | B40: =MONTH(B20) -> 4 | C40: =MONTH(C20) -> 5 | D40: =MONTH(D20) -> 6 | E40: =MONTH(E20) -> 7 | F40: =MONTH(F20) -> 8 | G40: =MONTH(G20) -> 9 | H40: =MONTH(H20) -> 10 | I40: =MONTH(I20) -> 11 | ... AX40: =MONTH(AX20) -> 4 | BA40: Month | BB40: =MONTH(BB18) -> 6 | BC40: =MONTH(BC18) -> 7 | BD40: =MONTH(BD18) -> 8 | BE40: =MONTH(BE18) -> 9 | BF40: =MONTH(BF18) -> 10 | BG40: =MONTH(BG18) -> 11 | BH40: =MONTH(BH18) -> 12 | BI40: =MONTH(BI18) -> 1 | ... CX40: =MONTH(CX18) -> 6
A41: Year | B41: =YEAR(B20) -> 2026 | C41: =YEAR(C20) -> 2026 | D41: =YEAR(D20) -> 2026 | E41: =YEAR(E20) -> 2026 | F41: =YEAR(F20) -> 2026 | G41: =YEAR(G20) -> 2026 | H41: =YEAR(H20) -> 2026 | I41: =YEAR(I20) -> 2026 | ... AX41: =YEAR(AX20) -> 2030 | BA41: Year | BB41: =YEAR(BB20) -> 2026 | BC41: =YEAR(BC20) -> 2026 | BD41: =YEAR(BD20) -> 2026 | BE41: =YEAR(BE20) -> 2026 | BF41: =YEAR(BF20) -> 2026 | BG41: =YEAR(BG20) -> 2026 | BH41: =YEAR(BH20) -> 2026 | BI41: =YEAR(BI20) -> 2027 | ... CX41: =YEAR(CX20) -> 2030
A42: YYYYMM | B42: =B41*100+B40 -> 202604 | C42: =C41*100+C40 -> 202605 | D42: =D41*100+D40 -> 202606 | E42: =E41*100+E40 -> 202607 | F42: =F41*100+F40 -> 202608 | G42: =G41*100+G40 -> 202609 | H42: =H41*100+H40 -> 202610 | I42: =I41*100+I40 -> 202611 | ... AX42: =AX41*100+AX40 -> 203004 | BA42: YYYYMM | BB42: =BB41*100+BB40 -> 202606 | BC42: =BC41*100+BC40 -> 202607 | BD42: =BD41*100+BD40 -> 202608 | BE42: =BE41*100+BE40 -> 202609 | BF42: =BF41*100+BF40 -> 202610 | BG42: =BG41*100+BG40 -> 202611 | BH42: =BH41*100+BH40 -> 202612 | BI42: =BI41*100+BI40 -> 202701 | ... CX42: =CX41*100+CX40 -> 203006
A43: Quarter | B43: =IF(B40<4,1,IF(B40<7,2,IF(B40<10,3,4))) -> 2 | C43: =IF(C40<4,1,IF(C40<7,2,IF(C40<10,3,4))) -> 2 | D43: =IF(D40<4,1,IF(D40<7,2,IF(D40<10,3,4))) -> 2 | E43: =IF(E40<4,1,IF(E40<7,2,IF(E40<10,3,4))) -> 3 | F43: =IF(F40<4,1,IF(F40<7,2,IF(F40<10,3,4))) -> 3 | G43: =IF(G40<4,1,IF(G40<7,2,IF(G40<10,3,4))) -> 3 | H43: =IF(H40<4,1,IF(H40<7,2,IF(H40<10,3,4))) -> 4 | I43: =IF(I40<4,1,IF(I40<7,2,IF(I40<10,3,4))) -> 4 | ... AX43: =IF(AX40<4,1,IF(AX40<7,2,IF(AX40<10,3,4))) -> 2 | BA43: Quarter | BB43: =IF(BB40<4,1,IF(BB40<7,2,IF(BB40<10,3,4))) -> 2 | BC43: =IF(BC40<4,1,IF(BC40<7,2,IF(BC40<10,3,4))) -> 3 | BD43: =IF(BD40<4,1,IF(BD40<7,2,IF(BD40<10,3,4))) -> 3 | BE43: =IF(BE40<4,1,IF(BE40<7,2,IF(BE40<10,3,4))) -> 3 | BF43: =IF(BF40<4,1,IF(BF40<7,2,IF(BF40<10,3,4))) -> 4 | BG43: =IF(BG40<4,1,IF(BG40<7,2,IF(BG40<10,3,4))) -> 4 | BH43: =IF(BH40<4,1,IF(BH40<7,2,IF(BH40<10,3,4))) -> 4 | BI43: =IF(BI40<4,1,IF(BI40<7,2,IF(BI40<10,3,4))) -> 1 | ... CX43: =IF(CX40<4,1,IF(CX40<7,2,IF(CX40<10,3,4))) -> 2
A44: YYYYQQ | B44: =B41*100+B43 -> 202602 | C44: =C41*100+C43 -> 202602 | D44: =D41*100+D43 -> 202602 | E44: =E41*100+E43 -> 202603 | F44: =F41*100+F43 -> 202603 | G44: =G41*100+G43 -> 202603 | H44: =H41*100+H43 -> 202604 | I44: =I41*100+I43 -> 202604 | ... AX44: =AX41*100+AX43 -> 203002 | BA44: YYYYQQ | BB44: =BB41*100+BB43 -> 202602 | BC44: =BC41*100+BC43 -> 202603 | BD44: =BD41*100+BD43 -> 202603 | BE44: =BE41*100+BE43 -> 202603 | BF44: =BF41*100+BF43 -> 202604 | BG44: =BG41*100+BG43 -> 202604 | BH44: =BH41*100+BH43 -> 202604 | BI44: =BI41*100+BI43 -> 202701 | ... CX44: =CX41*100+CX43 -> 203002
...

Sheet Market expectations - Electrici
A1: ='Market pricing dates'!A2 -> April 2026 MPR | C1: ='Market pricing dates'!A12 -> 15 working days to 22 Apr 2026 | AZ1: ='Market pricing dates'!D2 -> Current market curve | BB1: ='Market pricing dates'!D12 -> 15 working days to 18 Jun 2026
A2: Column # | B2: =HAVERD!DR$1 -> 122 | C2: =+B2+1 -> 123 | D2: =+C2+1 -> 124 | E2: =+D2+1 -> 125 | F2: =+E2+1 -> 126 | G2: =+F2+1 -> 127 | H2: =+G2+1 -> 128 | I2: =+H2+1 -> 129 | J2: =+I2+1 -> 130 | ... AW2: =+AV2+1 -> 169 | AZ2: Column # | BA2: =HAVERD!DR$1 -> 122 | BB2: =+BA2+1 -> 123 | BC2: =+BB2+1 -> 124 | BD2: =+BC2+1 -> 125 | BE2: =+BD2+1 -> 126 | BF2: =+BE2+1 -> 127 | BG2: =+BF2+1 -> 128 | BH2: =+BG2+1 -> 129 | BI2: =+BH2+1 -> 130 | ... CV2: =+CU2+1 -> 169
A3: Months | B3: =HAVERD!DR$2 -> Electricity - 1 | C3: =HAVERD!DS$2 -> Electricity - 2 | D3: =HAVERD!DT$2 -> Electricity - 3 | E3: =HAVERD!DU$2 -> Electricity - 4 | F3: =HAVERD!DV$2 -> Electricity - 5 | G3: =HAVERD!DW$2 -> Electricity - 6 | H3: =HAVERD!DX$2 -> Electricity - 7 | I3: =HAVERD!DY$2 -> Electricity - 8 | ... AW3: =HAVERD!FM$2 -> Electricity - 48 | AZ3: Months | BA3: =HAVERD!DR$2 -> Electricity - 1 | BB3: =HAVERD!DS$2 -> Electricity - 2 | BC3: =HAVERD!DT$2 -> Electricity - 3 | BD3: =HAVERD!DU$2 -> Electricity - 4 | BE3: =HAVERD!DV$2 -> Electricity - 5 | BF3: =HAVERD!DW$2 -> Electricity - 6 | BG3: =HAVERD!DX$2 -> Electricity - 7 | BH3: =HAVERD!DY$2 -> Electricity - 8 | ... CV3: =HAVERD!FM$2 -> Electricity - 48
A4: Days | C4: 30.416667 | D4: =+C4+30.4166667 -> 60.833333 | E4: =+D4+30.4166667 -> 91.25 | F4: =+E4+30.4166667 -> 121.66667 | G4: =+F4+30.4166667 -> 152.08333 | H4: =+G4+30.4166667 -> 182.5 | I4: =+H4+30.4166667 -> 212.91667 | J4: =+I4+30.4166667 -> 243.33333 | K4: =+J4+30.4166667 -> 273.75 | ... AW4: =+AV4+30.4166667 -> 1429.5833 | AZ4: Days | BB4: 30.416667 | BC4: =+BB4+30.4166667 -> 60.833333 | BD4: =+BC4+30.4166667 -> 91.25 | BE4: =+BD4+30.4166667 -> 121.66667 | BF4: =+BE4+30.4166667 -> 152.08333 | BG4: =+BF4+30.4166667 -> 182.5 | BH4: =+BG4+30.4166667 -> 212.91667 | BI4: =+BH4+30.4166667 -> 243.33333 | BJ4: =+BI4+30.4166667 -> 273.75 | ... CV4: =+CU4+30.4166667 -> 1429.5833
A5: Dates | AZ5: Dates
A6: =A11-7 -> 46114 | B6: =A6 -> 46114 | C6: =$B6+C$4 -> 46144.417 | D6: =$B6+D$4 -> 46174.833 | E6: =$B6+E$4 -> 46205.25 | F6: =$B6+F$4 -> 46235.667 | G6: =$B6+G$4 -> 46266.083 | H6: =$B6+H$4 -> 46296.5 | I6: =$B6+I$4 -> 46326.917 | J6: =$B6+J$4 -> 46357.333 | ... AW6: =$B6+AW$4 -> 47543.583 | AZ6: =AZ11-7 -> 46171 | BA6: =AZ6 -> 46171 | BB6: =$AZ6+BB$4 -> 46201.417 | BC6: =$AZ6+BC$4 -> 46231.833 | BD6: =$AZ6+BD$4 -> 46262.25 | BE6: =$AZ6+BE$4 -> 46292.667 | BF6: =$AZ6+BF$4 -> 46323.083 | BG6: =$AZ6+BG$4 -> 46353.5 | BH6: =$AZ6+BH$4 -> 46383.917 | BI6: =$AZ6+BI$4 -> 46414.333 | ... CV6: =$AZ6+CV$4 -> 47600.583
A7: =A12-7 -> 46115 | B7: =A7 -> 46115 | C7: =$B7+C$4 -> 46145.417 | D7: =$B7+D$4 -> 46175.833 | E7: =$B7+E$4 -> 46206.25 | F7: =$B7+F$4 -> 46236.667 | G7: =$B7+G$4 -> 46267.083 | H7: =$B7+H$4 -> 46297.5 | I7: =$B7+I$4 -> 46327.917 | J7: =$B7+J$4 -> 46358.333 | ... AW7: =$B7+AW$4 -> 47544.583 | AZ7: =AZ12-7 -> 46174 | BA7: =AZ7 -> 46174 | BB7: =$AZ7+BB$4 -> 46204.417 | BC7: =$AZ7+BC$4 -> 46234.833 | BD7: =$AZ7+BD$4 -> 46265.25 | BE7: =$AZ7+BE$4 -> 46295.667 | BF7: =$AZ7+BF$4 -> 46326.083 | BG7: =$AZ7+BG$4 -> 46356.5 | BH7: =$AZ7+BH$4 -> 46386.917 | BI7: =$AZ7+BI$4 -> 46417.333 | ... CV7: =$AZ7+CV$4 -> 47603.583
A8: =A13-7 -> 46118 | B8: =A8 -> 46118 | C8: =$B8+C$4 -> 46148.417 | D8: =$B8+D$4 -> 46178.833 | E8: =$B8+E$4 -> 46209.25 | F8: =$B8+F$4 -> 46239.667 | G8: =$B8+G$4 -> 46270.083 | H8: =$B8+H$4 -> 46300.5 | I8: =$B8+I$4 -> 46330.917 | J8: =$B8+J$4 -> 46361.333 | ... AW8: =$B8+AW$4 -> 47547.583 | AZ8: =AZ13-7 -> 46175 | BA8: =AZ8 -> 46175 | BB8: =$AZ8+BB$4 -> 46205.417 | BC8: =$AZ8+BC$4 -> 46235.833 | BD8: =$AZ8+BD$4 -> 46266.25 | BE8: =$AZ8+BE$4 -> 46296.667 | BF8: =$AZ8+BF$4 -> 46327.083 | BG8: =$AZ8+BG$4 -> 46357.5 | BH8: =$AZ8+BH$4 -> 46387.917 | BI8: =$AZ8+BI$4 -> 46418.333 | ... CV8: =$AZ8+CV$4 -> 47604.583
A9: =A14-7 -> 46119 | B9: =A9 -> 46119 | C9: =$B9+C$4 -> 46149.417 | D9: =$B9+D$4 -> 46179.833 | E9: =$B9+E$4 -> 46210.25 | F9: =$B9+F$4 -> 46240.667 | G9: =$B9+G$4 -> 46271.083 | H9: =$B9+H$4 -> 46301.5 | I9: =$B9+I$4 -> 46331.917 | J9: =$B9+J$4 -> 46362.333 | ... AW9: =$B9+AW$4 -> 47548.583 | AZ9: =AZ14-7 -> 46176 | BA9: =AZ9 -> 46176 | BB9: =$AZ9+BB$4 -> 46206.417 | BC9: =$AZ9+BC$4 -> 46236.833 | BD9: =$AZ9+BD$4 -> 46267.25 | BE9: =$AZ9+BE$4 -> 46297.667 | BF9: =$AZ9+BF$4 -> 46328.083 | BG9: =$AZ9+BG$4 -> 46358.5 | BH9: =$AZ9+BH$4 -> 46388.917 | BI9: =$AZ9+BI$4 -> 46419.333 | ... CV9: =$AZ9+CV$4 -> 47605.583
A10: =A15-7 -> 46120 | B10: =A10 -> 46120 | C10: =$B10+C$4 -> 46150.417 | D10: =$B10+D$4 -> 46180.833 | E10: =$B10+E$4 -> 46211.25 | F10: =$B10+F$4 -> 46241.667 | G10: =$B10+G$4 -> 46272.083 | H10: =$B10+H$4 -> 46302.5 | I10: =$B10+I$4 -> 46332.917 | J10: =$B10+J$4 -> 46363.333 | ... AW10: =$B10+AW$4 -> 47549.583 | AZ10: =AZ15-7 -> 46177 | BA10: =AZ10 -> 46177 | BB10: =$AZ10+BB$4 -> 46207.417 | BC10: =$AZ10+BC$4 -> 46237.833 | BD10: =$AZ10+BD$4 -> 46268.25 | BE10: =$AZ10+BE$4 -> 46298.667 | BF10: =$AZ10+BF$4 -> 46329.083 | BG10: =$AZ10+BG$4 -> 46359.5 | BH10: =$AZ10+BH$4 -> 46389.917 | BI10: =$AZ10+BI$4 -> 46420.333 | ... CV10: =$AZ10+CV$4 -> 47606.583
A11: =A16-7 -> 46121 | B11: =A11 -> 46121 | C11: =$B11+C$4 -> 46151.417 | D11: =$B11+D$4 -> 46181.833 | E11: =$B11+E$4 -> 46212.25 | F11: =$B11+F$4 -> 46242.667 | G11: =$B11+G$4 -> 46273.083 | H11: =$B11+H$4 -> 46303.5 | I11: =$B11+I$4 -> 46333.917 | J11: =$B11+J$4 -> 46364.333 | ... AW11: =$B11+AW$4 -> 47550.583 | AZ11: =AZ16-7 -> 46178 | BA11: =AZ11 -> 46178 | BB11: =$AZ11+BB$4 -> 46208.417 | BC11: =$AZ11+BC$4 -> 46238.833 | BD11: =$AZ11+BD$4 -> 46269.25 | BE11: =$AZ11+BE$4 -> 46299.667 | BF11: =$AZ11+BF$4 -> 46330.083 | BG11: =$AZ11+BG$4 -> 46360.5 | BH11: =$AZ11+BH$4 -> 46390.917 | BI11: =$AZ11+BI$4 -> 46421.333 | ... CV11: =$AZ11+CV$4 -> 47607.583
A12: =A17-7 -> 46122 | B12: =A12 -> 46122 | C12: =$B12+C$4 -> 46152.417 | D12: =$B12+D$4 -> 46182.833 | E12: =$B12+E$4 -> 46213.25 | F12: =$B12+F$4 -> 46243.667 | G12: =$B12+G$4 -> 46274.083 | H12: =$B12+H$4 -> 46304.5 | I12: =$B12+I$4 -> 46334.917 | J12: =$B12+J$4 -> 46365.333 | ... AW12: =$B12+AW$4 -> 47551.583 | AZ12: =AZ17-7 -> 46181 | BA12: =AZ12 -> 46181 | BB12: =$AZ12+BB$4 -> 46211.417 | BC12: =$AZ12+BC$4 -> 46241.833 | BD12: =$AZ12+BD$4 -> 46272.25 | BE12: =$AZ12+BE$4 -> 46302.667 | BF12: =$AZ12+BF$4 -> 46333.083 | BG12: =$AZ12+BG$4 -> 46363.5 | BH12: =$AZ12+BH$4 -> 46393.917 | BI12: =$AZ12+BI$4 -> 46424.333 | ... CV12: =$AZ12+CV$4 -> 47610.583
A13: =A18-7 -> 46125 | B13: =A13 -> 46125 | C13: =$B13+C$4 -> 46155.417 | D13: =$B13+D$4 -> 46185.833 | E13: =$B13+E$4 -> 46216.25 | F13: =$B13+F$4 -> 46246.667 | G13: =$B13+G$4 -> 46277.083 | H13: =$B13+H$4 -> 46307.5 | I13: =$B13+I$4 -> 46337.917 | J13: =$B13+J$4 -> 46368.333 | ... AW13: =$B13+AW$4 -> 47554.583 | AZ13: =AZ18-7 -> 46182 | BA13: =AZ13 -> 46182 | BB13: =$AZ13+BB$4 -> 46212.417 | BC13: =$AZ13+BC$4 -> 46242.833 | BD13: =$AZ13+BD$4 -> 46273.25 | BE13: =$AZ13+BE$4 -> 46303.667 | BF13: =$AZ13+BF$4 -> 46334.083 | BG13: =$AZ13+BG$4 -> 46364.5 | BH13: =$AZ13+BH$4 -> 46394.917 | BI13: =$AZ13+BI$4 -> 46425.333 | ... CV13: =$AZ13+CV$4 -> 47611.583
A14: =A19-7 -> 46126 | B14: =A14 -> 46126 | C14: =$B14+C$4 -> 46156.417 | D14: =$B14+D$4 -> 46186.833 | E14: =$B14+E$4 -> 46217.25 | F14: =$B14+F$4 -> 46247.667 | G14: =$B14+G$4 -> 46278.083 | H14: =$B14+H$4 -> 46308.5 | I14: =$B14+I$4 -> 46338.917 | J14: =$B14+J$4 -> 46369.333 | ... AW14: =$B14+AW$4 -> 47555.583 | AZ14: =AZ19-7 -> 46183 | BA14: =AZ14 -> 46183 | BB14: =$AZ14+BB$4 -> 46213.417 | BC14: =$AZ14+BC$4 -> 46243.833 | BD14: =$AZ14+BD$4 -> 46274.25 | BE14: =$AZ14+BE$4 -> 46304.667 | BF14: =$AZ14+BF$4 -> 46335.083 | BG14: =$AZ14+BG$4 -> 46365.5 | BH14: =$AZ14+BH$4 -> 46395.917 | BI14: =$AZ14+BI$4 -> 46426.333 | ... CV14: =$AZ14+CV$4 -> 47612.583
A15: =A20-7 -> 46127 | B15: =A15 -> 46127 | C15: =$B15+C$4 -> 46157.417 | D15: =$B15+D$4 -> 46187.833 | E15: =$B15+E$4 -> 46218.25 | F15: =$B15+F$4 -> 46248.667 | G15: =$B15+G$4 -> 46279.083 | H15: =$B15+H$4 -> 46309.5 | I15: =$B15+I$4 -> 46339.917 | J15: =$B15+J$4 -> 46370.333 | ... AW15: =$B15+AW$4 -> 47556.583 | AZ15: =AZ20-7 -> 46184 | BA15: =AZ15 -> 46184 | BB15: =$AZ15+BB$4 -> 46214.417 | BC15: =$AZ15+BC$4 -> 46244.833 | BD15: =$AZ15+BD$4 -> 46275.25 | BE15: =$AZ15+BE$4 -> 46305.667 | BF15: =$AZ15+BF$4 -> 46336.083 | BG15: =$AZ15+BG$4 -> 46366.5 | BH15: =$AZ15+BH$4 -> 46396.917 | BI15: =$AZ15+BI$4 -> 46427.333 | ... CV15: =$AZ15+CV$4 -> 47613.583
A16: ='Market pricing dates'!B5 -> 46128 | B16: =A16 -> 46128 | C16: =$B16+C$4 -> 46158.417 | D16: =$B16+D$4 -> 46188.833 | E16: =$B16+E$4 -> 46219.25 | F16: =$B16+F$4 -> 46249.667 | G16: =$B16+G$4 -> 46280.083 | H16: =$B16+H$4 -> 46310.5 | I16: =$B16+I$4 -> 46340.917 | J16: =$B16+J$4 -> 46371.333 | ... AW16: =$B16+AW$4 -> 47557.583 | AZ16: ='Market pricing dates'!E5 -> 46185 | BA16: =AZ16 -> 46185 | BB16: =$AZ16+BB$4 -> 46215.417 | BC16: =$AZ16+BC$4 -> 46245.833 | BD16: =$AZ16+BD$4 -> 46276.25 | BE16: =$AZ16+BE$4 -> 46306.667 | BF16: =$AZ16+BF$4 -> 46337.083 | BG16: =$AZ16+BG$4 -> 46367.5 | BH16: =$AZ16+BH$4 -> 46397.917 | BI16: =$AZ16+BI$4 -> 46428.333 | ... CV16: =$AZ16+CV$4 -> 47614.583
A17: ='Market pricing dates'!B6 -> 46129 | B17: =A17 -> 46129 | C17: =$B17+C$4 -> 46159.417 | D17: =$B17+D$4 -> 46189.833 | E17: =$B17+E$4 -> 46220.25 | F17: =$B17+F$4 -> 46250.667 | G17: =$B17+G$4 -> 46281.083 | H17: =$B17+H$4 -> 46311.5 | I17: =$B17+I$4 -> 46341.917 | J17: =$B17+J$4 -> 46372.333 | ... AW17: =$B17+AW$4 -> 47558.583 | AZ17: ='Market pricing dates'!E6 -> 46188 | BA17: =AZ17 -> 46188 | BB17: =$AZ17+BB$4 -> 46218.417 | BC17: =$AZ17+BC$4 -> 46248.833 | BD17: =$AZ17+BD$4 -> 46279.25 | BE17: =$AZ17+BE$4 -> 46309.667 | BF17: =$AZ17+BF$4 -> 46340.083 | BG17: =$AZ17+BG$4 -> 46370.5 | BH17: =$AZ17+BH$4 -> 46400.917 | BI17: =$AZ17+BI$4 -> 46431.333 | ... CV17: =$AZ17+CV$4 -> 47617.583
A18: ='Market pricing dates'!B7 -> 46132 | B18: =A18 -> 46132 | C18: =$B18+C$4 -> 46162.417 | D18: =$B18+D$4 -> 46192.833 | E18: =$B18+E$4 -> 46223.25 | F18: =$B18+F$4 -> 46253.667 | G18: =$B18+G$4 -> 46284.083 | H18: =$B18+H$4 -> 46314.5 | I18: =$B18+I$4 -> 46344.917 | J18: =$B18+J$4 -> 46375.333 | ... AW18: =$B18+AW$4 -> 47561.583 | AZ18: ='Market pricing dates'!E7 -> 46189 | BA18: =AZ18 -> 46189 | BB18: =$AZ18+BB$4 -> 46219.417 | BC18: =$AZ18+BC$4 -> 46249.833 | BD18: =$AZ18+BD$4 -> 46280.25 | BE18: =$AZ18+BE$4 -> 46310.667 | BF18: =$AZ18+BF$4 -> 46341.083 | BG18: =$AZ18+BG$4 -> 46371.5 | BH18: =$AZ18+BH$4 -> 46401.917 | BI18: =$AZ18+BI$4 -> 46432.333 | ... CV18: =$AZ18+CV$4 -> 47618.583
A19: ='Market pricing dates'!B8 -> 46133 | B19: =A19 -> 46133 | C19: =$B19+C$4 -> 46163.417 | D19: =$B19+D$4 -> 46193.833 | E19: =$B19+E$4 -> 46224.25 | F19: =$B19+F$4 -> 46254.667 | G19: =$B19+G$4 -> 46285.083 | H19: =$B19+H$4 -> 46315.5 | I19: =$B19+I$4 -> 46345.917 | J19: =$B19+J$4 -> 46376.333 | ... AW19: =$B19+AW$4 -> 47562.583 | AZ19: ='Market pricing dates'!E8 -> 46190 | BA19: =AZ19 -> 46190 | BB19: =$AZ19+BB$4 -> 46220.417 | BC19: =$AZ19+BC$4 -> 46250.833 | BD19: =$AZ19+BD$4 -> 46281.25 | BE19: =$AZ19+BE$4 -> 46311.667 | BF19: =$AZ19+BF$4 -> 46342.083 | BG19: =$AZ19+BG$4 -> 46372.5 | BH19: =$AZ19+BH$4 -> 46402.917 | BI19: =$AZ19+BI$4 -> 46433.333 | ... CV19: =$AZ19+CV$4 -> 47619.583
A20: ='Market pricing dates'!B9 -> 46134 | B20: =A20 -> 46134 | C20: =$B20+C$4 -> 46164.417 | D20: =$B20+D$4 -> 46194.833 | E20: =$B20+E$4 -> 46225.25 | F20: =$B20+F$4 -> 46255.667 | G20: =$B20+G$4 -> 46286.083 | H20: =$B20+H$4 -> 46316.5 | I20: =$B20+I$4 -> 46346.917 | J20: =$B20+J$4 -> 46377.333 | ... AW20: =$B20+AW$4 -> 47563.583 | AZ20: ='Market pricing dates'!E9 -> 46191 | BA20: =AZ20 -> 46191 | BB20: =$AZ20+BB$4 -> 46221.417 | BC20: =$AZ20+BC$4 -> 46251.833 | BD20: =$AZ20+BD$4 -> 46282.25 | BE20: =$AZ20+BE$4 -> 46312.667 | BF20: =$AZ20+BF$4 -> 46343.083 | BG20: =$AZ20+BG$4 -> 46373.5 | BH20: =$AZ20+BH$4 -> 46403.917 | BI20: =$AZ20+BI$4 -> 46434.333 | ... CV20: =$AZ20+CV$4 -> 47620.583
A22: Electricity futures | AZ22: Electricity futures
A23: =A6 -> 46114 | B23: =VLOOKUP($A23,HAVERD!$A:$FM,B$2,FALSE) -> 96.26 | C23: =VLOOKUP($A23,HAVERD!$A:$FM,C$2,FALSE) -> 100.21 | D23: =VLOOKUP($A23,HAVERD!$A:$FM,D$2,FALSE) -> 98.12 | E23: =VLOOKUP($A23,HAVERD!$A:$FM,E$2,FALSE) -> 98.47 | F23: =VLOOKUP($A23,HAVERD!$A:$FM,F$2,FALSE) -> 99.18 | G23: =VLOOKUP($A23,HAVERD!$A:$FM,G$2,FALSE) -> 98.37 | H23: =VLOOKUP($A23,HAVERD!$A:$FM,H$2,FALSE) -> 99.39 | I23: =VLOOKUP($A23,HAVERD!$A:$FM,I$2,FALSE) -> 100.9 | ... AW23: =VLOOKUP($A23,HAVERD!$A:$FM,AW$2,FALSE) -> 66.59 | AZ23: =AZ6 -> 46171 | BA23: =_xlfn.IFNA(VLOOKUP($AZ23,HAVERD!$A:$FM,BA$2,FALSE),"") -> 99.18 | BB23: =_xlfn.IFNA(VLOOKUP($AZ23,HAVERD!$A:$FM,BB$2,FALSE),"") -> 96.76 | BC23: =_xlfn.IFNA(VLOOKUP($AZ23,HAVERD!$A:$FM,BC$2,FALSE),"") -> 99.48 | BD23: =_xlfn.IFNA(VLOOKUP($AZ23,HAVERD!$A:$FM,BD$2,FALSE),"") -> 100.41 | BE23: =_xlfn.IFNA(VLOOKUP($AZ23,HAVERD!$A:$FM,BE$2,FALSE),"") -> 102.12 | BF23: =_xlfn.IFNA(VLOOKUP($AZ23,HAVERD!$A:$FM,BF$2,FALSE),"") -> 103.57 | BG23: =_xlfn.IFNA(VLOOKUP($AZ23,HAVERD!$A:$FM,BG$2,FALSE),"") -> 99.2 | BH23: =_xlfn.IFNA(VLOOKUP($AZ23,HAVERD!$A:$FM,BH$2,FALSE),"") -> 99.93 | ... CV23: =_xlfn.IFNA(VLOOKUP($AZ23,HAVERD!$A:$FM,CV$2,FALSE),"") -> 61.48
A24: =A7 -> 46115 | B24: =VLOOKUP($A24,HAVERD!$A:$FM,B$2,FALSE) -> #N/A | C24: =VLOOKUP($A24,HAVERD!$A:$FM,C$2,FALSE) -> #N/A | D24: =VLOOKUP($A24,HAVERD!$A:$FM,D$2,FALSE) -> #N/A | E24: =VLOOKUP($A24,HAVERD!$A:$FM,E$2,FALSE) -> #N/A | F24: =VLOOKUP($A24,HAVERD!$A:$FM,F$2,FALSE) -> #N/A | G24: =VLOOKUP($A24,HAVERD!$A:$FM,G$2,FALSE) -> #N/A | H24: =VLOOKUP($A24,HAVERD!$A:$FM,H$2,FALSE) -> #N/A | I24: =VLOOKUP($A24,HAVERD!$A:$FM,I$2,FALSE) -> #N/A | ... AW24: =VLOOKUP($A24,HAVERD!$A:$FM,AW$2,FALSE) -> #N/A | AZ24: =AZ7 -> 46174 | BA24: =_xlfn.IFNA(VLOOKUP($AZ24,HAVERD!$A:$FM,BA$2,FALSE),"") -> 103.46 | BB24: =_xlfn.IFNA(VLOOKUP($AZ24,HAVERD!$A:$FM,BB$2,FALSE),"") -> 100.68 | BC24: =_xlfn.IFNA(VLOOKUP($AZ24,HAVERD!$A:$FM,BC$2,FALSE),"") -> 102.79 | BD24: =_xlfn.IFNA(VLOOKUP($AZ24,HAVERD!$A:$FM,BD$2,FALSE),"") -> 103.78 | BE24: =_xlfn.IFNA(VLOOKUP($AZ24,HAVERD!$A:$FM,BE$2,FALSE),"") -> 105.53 | BF24: =_xlfn.IFNA(VLOOKUP($AZ24,HAVERD!$A:$FM,BF$2,FALSE),"") -> 106.78 | BG24: =_xlfn.IFNA(VLOOKUP($AZ24,HAVERD!$A:$FM,BG$2,FALSE),"") -> 101.65 | BH24: =_xlfn.IFNA(VLOOKUP($AZ24,HAVERD!$A:$FM,BH$2,FALSE),"") -> 102.39 | ... CV24: =_xlfn.IFNA(VLOOKUP($AZ24,HAVERD!$A:$FM,CV$2,FALSE),"") -> 61.66
A25: =A8 -> 46118 | B25: =VLOOKUP($A25,HAVERD!$A:$FM,B$2,FALSE) -> 96.26 | C25: =VLOOKUP($A25,HAVERD!$A:$FM,C$2,FALSE) -> 100.21 | D25: =VLOOKUP($A25,HAVERD!$A:$FM,D$2,FALSE) -> 98.12 | E25: =VLOOKUP($A25,HAVERD!$A:$FM,E$2,FALSE) -> 98.47 | F25: =VLOOKUP($A25,HAVERD!$A:$FM,F$2,FALSE) -> 99.18 | G25: =VLOOKUP($A25,HAVERD!$A:$FM,G$2,FALSE) -> 98.37 | H25: =VLOOKUP($A25,HAVERD!$A:$FM,H$2,FALSE) -> 99.39 | I25: =VLOOKUP($A25,HAVERD!$A:$FM,I$2,FALSE) -> 100.9 | ... AW25: =VLOOKUP($A25,HAVERD!$A:$FM,AW$2,FALSE) -> 66.59 | AZ25: =AZ8 -> 46175 | BA25: =_xlfn.IFNA(VLOOKUP($AZ25,HAVERD!$A:$FM,BA$2,FALSE),"") -> 101.13 | BB25: =_xlfn.IFNA(VLOOKUP($AZ25,HAVERD!$A:$FM,BB$2,FALSE),"") -> 98.88 | BC25: =_xlfn.IFNA(VLOOKUP($AZ25,HAVERD!$A:$FM,BC$2,FALSE),"") -> 101.42 | BD25: =_xlfn.IFNA(VLOOKUP($AZ25,HAVERD!$A:$FM,BD$2,FALSE),"") -> 102.28 | BE25: =_xlfn.IFNA(VLOOKUP($AZ25,HAVERD!$A:$FM,BE$2,FALSE),"") -> 104.08 | BF25: =_xlfn.IFNA(VLOOKUP($AZ25,HAVERD!$A:$FM,BF$2,FALSE),"") -> 105.22 | BG25: =_xlfn.IFNA(VLOOKUP($AZ25,HAVERD!$A:$FM,BG$2,FALSE),"") -> 100.96 | BH25: =_xlfn.IFNA(VLOOKUP($AZ25,HAVERD!$A:$FM,BH$2,FALSE),"") -> 101.7 | ... CV25: =_xlfn.IFNA(VLOOKUP($AZ25,HAVERD!$A:$FM,CV$2,FALSE),"") -> 61.66
A26: =A9 -> 46119 | B26: =VLOOKUP($A26,HAVERD!$A:$FM,B$2,FALSE) -> 100.36 | C26: =VLOOKUP($A26,HAVERD!$A:$FM,C$2,FALSE) -> 104.14 | D26: =VLOOKUP($A26,HAVERD!$A:$FM,D$2,FALSE) -> 102.62 | E26: =VLOOKUP($A26,HAVERD!$A:$FM,E$2,FALSE) -> 102.94 | F26: =VLOOKUP($A26,HAVERD!$A:$FM,F$2,FALSE) -> 103.59 | G26: =VLOOKUP($A26,HAVERD!$A:$FM,G$2,FALSE) -> 100.81 | H26: =VLOOKUP($A26,HAVERD!$A:$FM,H$2,FALSE) -> 101.84 | I26: =VLOOKUP($A26,HAVERD!$A:$FM,I$2,FALSE) -> 103.36 | ... AW26: =VLOOKUP($A26,HAVERD!$A:$FM,AW$2,FALSE) -> 66.93 | AZ26: =AZ9 -> 46176 | BA26: =_xlfn.IFNA(VLOOKUP($AZ26,HAVERD!$A:$FM,BA$2,FALSE),"") -> 103.4 | BB26: =_xlfn.IFNA(VLOOKUP($AZ26,HAVERD!$A:$FM,BB$2,FALSE),"") -> 101.02 | BC26: =_xlfn.IFNA(VLOOKUP($AZ26,HAVERD!$A:$FM,BC$2,FALSE),"") -> 103.1 | BD26: =_xlfn.IFNA(VLOOKUP($AZ26,HAVERD!$A:$FM,BD$2,FALSE),"") -> 103.67 | BE26: =_xlfn.IFNA(VLOOKUP($AZ26,HAVERD!$A:$FM,BE$2,FALSE),"") -> 105.54 | BF26: =_xlfn.IFNA(VLOOKUP($AZ26,HAVERD!$A:$FM,BF$2,FALSE),"") -> 106.56 | BG26: =_xlfn.IFNA(VLOOKUP($AZ26,HAVERD!$A:$FM,BG$2,FALSE),"") -> 102.58 | BH26: =_xlfn.IFNA(VLOOKUP($AZ26,HAVERD!$A:$FM,BH$2,FALSE),"") -> 103.32 | ... CV26: =_xlfn.IFNA(VLOOKUP($AZ26,HAVERD!$A:$FM,CV$2,FALSE),"") -> 61.71
A27: =A10 -> 46120 | B27: =VLOOKUP($A27,HAVERD!$A:$FM,B$2,FALSE) -> 89.1 | C27: =VLOOKUP($A27,HAVERD!$A:$FM,C$2,FALSE) -> 92.46 | D27: =VLOOKUP($A27,HAVERD!$A:$FM,D$2,FALSE) -> 91.46 | E27: =VLOOKUP($A27,HAVERD!$A:$FM,E$2,FALSE) -> 91.91 | F27: =VLOOKUP($A27,HAVERD!$A:$FM,F$2,FALSE) -> 92.6 | G27: =VLOOKUP($A27,HAVERD!$A:$FM,G$2,FALSE) -> 89.9 | H27: =VLOOKUP($A27,HAVERD!$A:$FM,H$2,FALSE) -> 90.88 | I27: =VLOOKUP($A27,HAVERD!$A:$FM,I$2,FALSE) -> 92.33 | ... AW27: =VLOOKUP($A27,HAVERD!$A:$FM,AW$2,FALSE) -> 65.16 | AZ27: =AZ10 -> 46177 | BA27: =_xlfn.IFNA(VLOOKUP($AZ27,HAVERD!$A:$FM,BA$2,FALSE),"") -> 102.91 | BB27: =_xlfn.IFNA(VLOOKUP($AZ27,HAVERD!$A:$FM,BB$2,FALSE),"") -> 100.4 | BC27: =_xlfn.IFNA(VLOOKUP($AZ27,HAVERD!$A:$FM,BC$2,FALSE),"") -> 102.16 | BD27: =_xlfn.IFNA(VLOOKUP($AZ27,HAVERD!$A:$FM,BD$2,FALSE),"") -> 103.18 | BE27: =_xlfn.IFNA(VLOOKUP($AZ27,HAVERD!$A:$FM,BE$2,FALSE),"") -> 105.13 | BF27: =_xlfn.IFNA(VLOOKUP($AZ27,HAVERD!$A:$FM,BF$2,FALSE),"") -> 106.1 | BG27: =_xlfn.IFNA(VLOOKUP($AZ27,HAVERD!$A:$FM,BG$2,FALSE),"") -> 101.88 | BH27: =_xlfn.IFNA(VLOOKUP($AZ27,HAVERD!$A:$FM,BH$2,FALSE),"") -> 102.62 | ... CV27: =_xlfn.IFNA(VLOOKUP($AZ27,HAVERD!$A:$FM,CV$2,FALSE),"") -> 60.91
A28: =A11 -> 46121 | B28: =VLOOKUP($A28,HAVERD!$A:$FM,B$2,FALSE) -> 91.5 | C28: =VLOOKUP($A28,HAVERD!$A:$FM,C$2,FALSE) -> 93.68 | D28: =VLOOKUP($A28,HAVERD!$A:$FM,D$2,FALSE) -> 93.2 | E28: =VLOOKUP($A28,HAVERD!$A:$FM,E$2,FALSE) -> 93.48 | F28: =VLOOKUP($A28,HAVERD!$A:$FM,F$2,FALSE) -> 94.24 | G28: =VLOOKUP($A28,HAVERD!$A:$FM,G$2,FALSE) -> 92.01 | H28: =VLOOKUP($A28,HAVERD!$A:$FM,H$2,FALSE) -> 93 | I28: =VLOOKUP($A28,HAVERD!$A:$FM,I$2,FALSE) -> 94.44 | ... AW28: =VLOOKUP($A28,HAVERD!$A:$FM,AW$2,FALSE) -> 65.03 | AZ28: =AZ11 -> 46178 | BA28: =_xlfn.IFNA(VLOOKUP($AZ28,HAVERD!$A:$FM,BA$2,FALSE),"") -> 102.98 | BB28: =_xlfn.IFNA(VLOOKUP($AZ28,HAVERD!$A:$FM,BB$2,FALSE),"") -> 100.2 | BC28: =_xlfn.IFNA(VLOOKUP($AZ28,HAVERD!$A:$FM,BC$2,FALSE),"") -> 101.91 | BD28: =_xlfn.IFNA(VLOOKUP($AZ28,HAVERD!$A:$FM,BD$2,FALSE),"") -> 103.26 | BE28: =_xlfn.IFNA(VLOOKUP($AZ28,HAVERD!$A:$FM,BE$2,FALSE),"") -> 105.26 | BF28: =_xlfn.IFNA(VLOOKUP($AZ28,HAVERD!$A:$FM,BF$2,FALSE),"") -> 105.89 | BG28: =_xlfn.IFNA(VLOOKUP($AZ28,HAVERD!$A:$FM,BG$2,FALSE),"") -> 101.9 | BH28: =_xlfn.IFNA(VLOOKUP($AZ28,HAVERD!$A:$FM,BH$2,FALSE),"") -> 102.64 | ... CV28: =_xlfn.IFNA(VLOOKUP($AZ28,HAVERD!$A:$FM,CV$2,FALSE),"") -> 61.1
